File: Tension/Section_2_Group_4/f8a.is_tens_RawData/Specimen_RawData_1.csv
Time,Extension,Load,Tensile strain (Extension),Tensile stress,Strain-by-clip-gage
(s),(mm),(N),(mm/mm),(MPa),(mm/mm)
"0.00000","0.00000","-0.16278","0.00000","-0.01628","0.00000"
"0.20000","0.00193","9.87416","0.00002","0.98742","-0.00001"
"0.40000","0.01053","61.23170","0.00011","6.12317","0.00000"
"0.60000","0.01721","96.50385","0.00017","9.65038","-0.00001"
"0.80000","0.02396","129.59740","0.00024","12.95974","-0.00005"
"1.00000","0.03068","160.59193","0.00031","16.05919","0.00003"
"1.20000","0.03722","188.64420","0.00037","18.86442","-0.00001"
"1.40000","0.04384","214.17931","0.00044","21.41793","0.00001"
"1.60000","0.05048","239.17293","0.00050","23.91729","0.00003"
"1.80000","0.05729","267.71988","0.00057","26.77199","-0.00001"
"2.00000","0.06393","295.18210","0.00064","29.51821","-0.00001"
"2.20000","0.07053","322.03082","0.00071","32.20308","-0.00001"
"2.40000","0.07733","349.88889","0.00077","34.98889","-0.00001"
"2.60000","0.08382","375.49225","0.00084","37.54922","0.00001"
"2.80000","0.09062","402.50830","0.00091","40.25083","0.00000"
"3.00000","0.09723","428.07468","0.00097","42.80747","0.00000"
"3.20000","0.10392","453.53519","0.00104","45.35352","0.00000"
"3.40000","0.11060","478.97775","0.00111","47.89777","0.00000"
"3.60000","0.11718","502.99246","0.00117","50.29925","0.00000"
"3.80000","0.12394","527.86169","0.00124","52.78617","0.00000"
"4.00000","0.13043","551.19568","0.00130","55.11957","-0.00001"
"4.20000","0.13730","575.94537","0.00137","57.59454","0.00000"
"4.40000","0.14389","598.99036","0.00144","59.89904","0.00000"
"4.60000","0.15052","621.44421","0.00151","62.14442","0.00001"
"4.80000","0.15736","645.17188","0.00157","64.51719","0.00000"
"5.00000","0.16383","666.19489","0.00164","66.61949","-0.00001"
"5.20000","0.17050","688.33313","0.00171","68.83331","0.00000"
"5.40000","0.17716","709.89929","0.00177","70.98993","0.00000"
"5.60000","0.18406","732.51923","0.00184","73.25192","0.00000"
"5.80000","0.19051","752.48486","0.00191","75.24849","0.00000"
"6.00000","0.19718","772.95764","0.00197","77.29576","0.00000"
"6.20000","0.20391","793.53180","0.00204","79.35318","0.00000"
"6.40000","0.21047","812.80328","0.00210","81.28033","0.00001"
"6.60000","0.21735","833.61694","0.00217","83.36169","0.00000"
"6.80000","0.22385","852.00305","0.00224","85.20030","0.00000"
"7.00000","0.23056","871.32642","0.00231","87.13264","0.00000"
"7.20000","0.23728","890.56995","0.00237","89.05699","0.00000"
"7.40000","0.24391","909.12506","0.00244","90.91251","0.00000"
"7.60000","0.25051","926.92303","0.00251","92.69231","0.00000"
"7.80000","0.25719","945.09619","0.00257","94.50962","0.00000"
"8.00000","0.26399","963.51672","0.00264","96.35167","0.00000"
"8.20000","0.27055","980.65668","0.00271","98.06567","0.00000"
"8.40000","0.27721","997.85046","0.00277","99.78505","0.00000"
"8.60000","0.28402","1015.60767","0.00284","101.56077","0.00000"
"8.80000","0.29050","1031.26880","0.00291","103.12688","0.00000"
"9.00000","0.29724","1047.89148","0.00297","104.78915","0.00000"
"9.20000","0.30391","1064.19312","0.00304","106.41931","0.00000"
"9.40000","0.31058","1080.01013","0.00311","108.00101","0.00001"
"9.60000","0.31724","1095.79883","0.00317","109.57988","0.00000"
"9.80000","0.32383","1110.73901","0.00324","111.07390","-0.00001"
"10.00000","0.33060","1126.10352","0.00331","112.61035","0.00000"
"10.20000","0.33721","1140.42261","0.00337","114.04226","0.00000"
"10.40000","0.34403","1155.45325","0.00344","115.54533","0.00000"
"10.60000","0.35055","1169.18701","0.00351","116.91870","0.00000"
"10.80000","0.35719","1182.97205","0.00357","118.29720","0.00000"
"11.00000","0.36404","1197.74536","0.00364","119.77454","0.00000"
"11.20000","0.37047","1209.75183","0.00370","120.97518","0.00000"
"11.40000","0.37717","1223.33313","0.00377","122.33331","0.00000"
"11.60000","0.38381","1235.92810","0.00384","123.59281","0.00000"
"11.80000","0.39070","1249.46326","0.00391","124.94633","0.00000"
"12.00000","0.39727","1261.27197","0.00397","126.12720","0.00000"
"12.20000","0.40390","1272.92444","0.00404","127.29244","0.00001"
"12.40000","0.41063","1284.99292","0.00411","128.49930","0.00000"
"12.60000","0.41715","1295.59082","0.00417","129.55908","0.00000"
"12.80000","0.42400","1307.50977","0.00424","130.75098","0.00000"
"13.00000","0.43052","1317.53125","0.00431","131.75313","0.00000"
"13.20000","0.43717","1327.75854","0.00437","132.77585","0.00000"
"13.40000","0.44395","1339.05334","0.00444","133.90533","0.00000"
"13.60000","0.45055","1349.08167","0.00451","134.90817","-0.00001"
"13.80000","0.45728","1359.25232","0.00457","135.92523","0.00000"
"14.00000","0.46387","1368.59436","0.00464","136.85944","0.00000"
"14.20000","0.47076","1379.03809","0.00471","137.90381","0.00000"
"14.40000","0.47723","1387.48108","0.00477","138.74811","0.00000"
"14.60000","0.48389","1396.55334","0.00484","139.65533","0.00000"
"14.80000","0.49057","1406.10034","0.00491","140.61003","-0.00001"
"15.00000","0.49716","1414.90918","0.00497","141.49092","0.00001"
"15.20000","0.50392","1424.74341","0.00504","142.47433","0.00000"
"15.40000","0.51059","1434.09607","0.00511","143.40961","0.00000"
"15.60000","0.51728","1443.52527","0.00517","144.35252","0.00001"
"15.80000","0.52402","1453.50989","0.00524","145.35098","0.00000"
"16.00000","0.53058","1462.73340","0.00531","146.27335","0.00000"
"16.20000","0.53723","1472.63550","0.00537","147.26355","0.00000"
"16.40000","0.54384","1482.37573","0.00544","148.23758","-0.00001"
"16.60000","0.55061","1493.19690","0.00551","149.31969","0.00000"
"16.80000","0.55724","1503.19458","0.00557","150.31946","0.00001"
"17.00000","0.56383","1512.71008","0.00564","151.27101","0.00000"
"17.20000","0.57067","1523.78992","0.00571","152.37900","0.00000"
"17.40000","0.57722","1533.25867","0.00577","153.32587","0.00001"
"17.60000","0.58397","1543.95312","0.00584","154.39531","0.00000"
"17.80000","0.59058","1554.11487","0.00591","155.41148","0.00001"
"18.00000","0.59733","1564.65393","0.00597","156.46539","0.00001"
"18.20000","0.60397","1574.67053","0.00604","157.46706","0.00000"
"18.40000","0.61049","1583.94446","0.00610","158.39444","0.00000"
"18.60000","0.61724","1594.62708","0.00617","159.46271","0.00000"
"18.80000","0.62374","1603.97546","0.00624","160.39755","0.00000"
"19.00000","0.63065","1615.33020","0.00631","161.53302","0.00000"
"19.20000","0.63728","1625.33704","0.00637","162.53371","0.00000"
"19.40000","0.64400","1635.42847","0.00644","163.54285","0.00000"
"19.60000","0.65069","1645.70117","0.00651","164.57011","0.00000"
"19.80000","0.65720","1654.76282","0.00657","165.47629","0.00000"
"20.00000","0.66386","1664.87378","0.00664","166.48738","0.00000"
"20.20000","0.67044","1674.51953","0.00670","167.45195","0.00000"
"20.40000","0.67734","1685.53857","0.00677","168.55386","0.00000"
"20.60000","0.68387","1695.34424","0.00684","169.53442","0.00000"
"20.80000","0.69054","1705.22034","0.00691","170.52203","0.00000"
"21.00000","0.69737","1716.34290","0.00697","171.63429","0.00000"
"21.20000","0.70390","1725.80542","0.00704","172.58054","0.00000"
"21.40000","0.71067","1736.82288","0.00711","173.68228","-0.00001"
"21.60000","0.71722","1746.57324","0.00717","174.65732","0.00000"
"21.80000","0.72392","1756.93591","0.00724","175.69359","0.00000"
"22.00000","0.73057","1767.25122","0.00731","176.72513","0.00000"
"22.20000","0.73722","1777.54797","0.00737","177.75479","0.00000"
"22.40000","0.74386","1787.37439","0.00744","178.73744","0.00000"
"22.60000","0.75053","1797.65491","0.00751","179.76549","0.00000"
"22.80000","0.75739","1808.59021","0.00757","180.85902","0.00001"
"23.00000","0.76396","1818.20020","0.00764","181.82002","0.00000"
"23.20000","0.77057","1827.88184","0.00771","182.78818","-0.00001"
"23.40000","0.77732","1838.50171","0.00777","183.85017","0.00000"
"23.60000","0.78387","1847.62354","0.00784","184.76236","0.00000"
"23.80000","0.79053","1857.31763","0.00791","185.73177","0.00000"
"24.00000","0.79718","1866.96313","0.00797","186.69632","0.00000"
"24.20000","0.80391","1876.93445","0.00804","187.69345","0.00000"
"24.40000","0.81062","1887.07837","0.00811","188.70784","0.00000"
"24.60000","0.81724","1896.50317","0.00817","189.65031","0.00001"
"24.80000","0.82403","1906.62866","0.00824","190.66287","0.00000"
"25.00000","0.83052","1915.11658","0.00831","191.51166","0.00000"
"25.20000","0.83733","1925.47424","0.00837","192.54742","0.00000"
"25.40000","0.84389","1934.50671","0.00844","193.45067","0.00000"
"25.60000","0.85047","1943.26880","0.00850","194.32687","0.00000"
"25.80000","0.85735","1953.86609","0.00857","195.38661","0.00001"
"26.00000","0.86383","1962.13428","0.00864","196.21342","0.00000"
"26.20000","0.87047","1971.01892","0.00870","197.10190","0.00000"
"26.40000","0.87724","1980.84265","0.00877","198.08426","0.00000"
"26.60000","0.88410","1990.69470","0.00884","199.06947","0.00000"
"26.80000","0.89063","1999.18359","0.00891","199.91837","0.00000"
"27.00000","0.89716","2007.34570","0.00897","200.73457","0.00000"
"27.20000","0.90398","2017.02588","0.00904","201.70259","0.00000"
"27.40000","0.91046","2024.52014","0.00910","202.45201","0.00000"
"27.60000","0.91735","2034.26257","0.00917","203.42625","0.00000"
"27.80000","0.92386","2041.93054","0.00924","204.19305","0.00000"
"28.00000","0.93059","2050.53857","0.00931","205.05386","0.00000"
"28.20000","0.93736","2059.52979","0.00937","205.95297","-0.00001"
"28.40000","0.94398","2067.41943","0.00944","206.74194","0.00000"
"28.60000","0.95057","2075.11401","0.00951","207.51140","0.00000"
"28.80000","0.95713","2082.65967","0.00957","208.26596","0.00000"
"29.00000","0.96403","2091.75317","0.00964","209.17532","0.00000"
"29.20000","0.97056","2098.83325","0.00971","209.88333","0.00000"
"29.40000","0.97717","2106.37524","0.00977","210.63753","0.00000"
"29.60000","0.98393","2114.80469","0.00984","211.48047","0.00001"
"29.80000","0.99053","2122.28027","0.00991","212.22803","0.00000"
"30.00000","0.99730","2130.64551","0.00997","213.06454","0.00000"
"30.20000","1.00394","2138.50244","0.01004","213.85025","0.00000"
"30.40000","1.01063","2146.20776","0.01011","214.62077","0.00000"
"30.60000","1.01723","2153.88794","0.01017","215.38879","0.00000"
"30.80000","1.02386","2161.44043","0.01024","216.14404","0.00000"
"31.00000","1.03057","2169.84717","0.01031","216.98471","0.00000"
"31.20000","1.03712","2177.13940","0.01037","217.71394","0.00000"
"31.40000","1.04397","2185.93579","0.01044","218.59358","0.00000"
"31.60000","1.05062","2193.60547","0.01051","219.36055","0.00000"
"31.80000","1.05724","2200.92407","0.01057","220.09241","0.00000"
"32.00000","1.06401","2209.39917","0.01064","220.93991","0.00000"
"32.20000","1.07053","2216.25195","0.01071","221.62520","0.00000"
"32.40000","1.07722","2224.16699","0.01077","222.41670","0.00000"
"32.60000","1.08380","2231.53174","0.01084","223.15317","0.00000"
"32.80000","1.09067","2240.04834","0.01091","224.00484","0.00000"
"33.00000","1.09726","2247.15869","0.01097","224.71587","0.00000"
"33.20000","1.10386","2254.21265","0.01104","225.42126","0.00000"
"33.40000","1.11070","2262.63379","0.01111","226.26338","0.00000"
"33.60000","1.11718","2269.00903","0.01117","226.90091","0.00000"
"33.80000","1.12392","2276.66016","0.01124","227.66602","0.00000"
"34.00000","1.13055","2283.85132","0.01131","228.38513","0.00000"
"34.20000","1.13726","2291.23804","0.01137","229.12381","0.00001"
"34.40000","1.14395","2298.70752","0.01144","229.87076","0.00000"
"34.60000","1.15053","2305.20654","0.01151","230.52066","0.00000"
"34.80000","1.15727","2312.74048","0.01157","231.27405","0.00000"
"35.00000","1.16378","2318.97754","0.01164","231.89775","0.00000"
"35.20000","1.17074","2327.47021","0.01171","232.74702","0.00000"
"35.40000","1.17722","2333.47656","0.01177","233.34766","0.00000"
"35.60000","1.18389","2339.99634","0.01184","233.99963","0.00000"
"35.80000","1.19065","2347.24585","0.01191","234.72458","0.00000"
"36.00000","1.19714","2353.11035","0.01197","235.31104","0.00000"
"36.20000","1.20391","2360.14258","0.01204","236.01425","0.00000"
"36.40000","1.21054","2366.77246","0.01211","236.67725","0.00000"
"36.60000","1.21729","2373.69849","0.01217","237.36984","0.00000"
"36.80000","1.22392","2380.02661","0.01224","238.00266","0.00000"
"37.00000","1.23058","2386.25586","0.01231","238.62558","0.00000"
"37.20000","1.23730","2392.60742","0.01237","239.26074","0.00000"
"37.40000","1.24383","2398.19727","0.01244","239.81973","0.00000"
"37.60000","1.25063","2405.25391","0.01251","240.52539","0.00000"
"37.80000","1.25721","2410.86792","0.01257","241.08679","-0.00001"
"38.00000","1.26382","2416.48022","0.01264","241.64803","0.00000"
"38.20000","1.27069","2423.52026","0.01271","242.35202","0.00001"
"38.40000","1.27720","2428.49561","0.01277","242.84956","-0.00001"
"38.60000","1.28389","2434.24170","0.01284","243.42416","0.00000"
"38.80000","1.29057","2440.21362","0.01291","244.02136","0.00000"
"39.00000","1.29734","2446.24512","0.01297","244.62451","0.00000"
"39.20000","1.30386","2451.34351","0.01304","245.13435","0.00001"
"39.40000","1.31048","2456.62378","0.01310","245.66238","0.00000"
"39.60000","1.31731","2462.92676","0.01317","246.29268","-0.00001"
"39.80000","1.32379","2467.16895","0.01324","246.71689","0.00000"
"40.00000","1.33062","2473.27197","0.01331","247.32719","0.00000"
"40.20000","1.33725","2478.31787","0.01337","247.83179","0.00000"
"40.40000","1.34390","2483.34106","0.01344","248.33411","0.00000"
"40.60000","1.35071","2489.36377","0.01351","248.93637","-0.00001"
"40.80000","1.35718","2493.43188","0.01357","249.34319","0.00000"
"41.00000","1.36386","2498.31641","0.01364","249.83163","0.00000"
"41.20000","1.37047","2502.90112","0.01370","250.29012","0.00000"
"41.40000","1.37734","2508.96167","0.01377","250.89616","0.00000"
"41.60000","1.38383","2512.74023","0.01384","251.27402","-0.00001"
"41.80000","1.39056","2517.76147","0.01391","251.77615","0.00000"
"42.00000","1.39732","2523.19141","0.01397","252.31914","0.00001"
"42.20000","1.40385","2527.03442","0.01404","252.70345","0.00000"
"42.40000","1.41061","2532.02075","0.01411","253.20207","0.00000"
"42.60000","1.41719","2535.90942","0.01417","253.59094","0.00000"
"42.80000","1.42396","2540.72388","0.01424","254.07239","0.00000"
"43.00000","1.43055","2544.70630","0.01431","254.47063","0.00000"
"43.20000","1.43718","2548.67651","0.01437","254.86765","0.00000"
"43.40000","1.44389","2553.18945","0.01444","255.31894","-0.00001"
"43.60000","1.45052","2557.12354","0.01451","255.71236","0.00000"
"43.80000","1.45734","2561.86865","0.01457","256.18686","0.00000"
"44.00000","1.46388","2565.24927","0.01464","256.52493","0.00000"
"44.20000","1.47055","2569.16919","0.01471","256.91693","0.00000"
"44.40000","1.47733","2573.89209","0.01477","257.38922","0.00000"
"44.60000","1.48387","2576.88354","0.01484","257.68835","0.00000"
"44.80000","1.49050","2580.49512","0.01491","258.04950","0.00000"
"45.00000","1.49720","2584.26245","0.01497","258.42624","0.00000"
"45.20000","1.50396","2588.32495","0.01504","258.83249","-0.00001"
"45.40000","1.51061","2591.88062","0.01511","259.18805","0.00000"
"45.60000","1.51717","2594.87427","0.01517","259.48743","0.00000"
"45.80000","1.52399","2599.31958","0.01524","259.93195","0.00001"
"46.00000","1.53048","2601.90332","0.01530","260.19034","0.00000"
"46.20000","1.53731","2606.04614","0.01537","260.60461","-0.00001"
"46.40000","1.54392","2608.95801","0.01544","260.89581","-0.00001"
"46.60000","1.55055","2611.74365","0.01551","261.17438","0.00000"
"46.80000","1.55727","2615.34277","0.01557","261.53427","0.00001"
"47.00000","1.56383","2618.01416","0.01564","261.80142","0.00001"
"47.20000","1.57058","2621.54102","0.01571","262.15411","-0.00001"
"47.40000","1.57714","2624.37134","0.01577","262.43713","-0.00001"
"47.60000","1.58404","2628.59521","0.01584","262.85953","0.00001"
"47.80000","1.59057","2630.86133","0.01591","263.08612","0.00000"
"48.00000","1.59716","2633.10522","0.01597","263.31052","0.00000"
"48.20000","1.60402","2636.89746","0.01604","263.68976","0.00000"
"48.40000","1.61045","2638.66675","0.01610","263.86667","0.00000"
"48.60000","1.61720","2641.94214","0.01617","264.19421","0.00001"
"48.80000","1.62384","2644.69385","0.01624","264.46939","0.00000"
"49.00000","1.63071","2648.24023","0.01631","264.82404","0.00000"
"49.20000","1.63722","2650.28271","0.01637","265.02826","0.00000"
"49.40000","1.64386","2652.65283","0.01644","265.26529","0.00000"
"49.60000","1.65056","2655.53735","0.01651","265.55374","0.00000"
"49.80000","1.65710","2657.29810","0.01657","265.72980","0.00000"
"50.00000","1.66406","2661.40283","0.01664","266.14029","0.00000"
"50.20000","1.67054","2663.01636","0.01671","266.30164","0.00000"
"50.40000","1.67718","2665.20483","0.01677","266.52048","0.00000"
"50.60000","1.68396","2668.14697","0.01684","266.81470","0.00000"
"50.80000","1.69057","2670.26904","0.01691","267.02692","0.00000"
"51.00000","1.69715","2672.17700","0.01697","267.21771","-0.00001"
"51.20000","1.70387","2674.73926","0.01704","267.47394","0.00000"
"51.40000","1.71065","2677.28784","0.01711","267.72879","0.00000"
"51.60000","1.71725","2679.34058","0.01717","267.93405","0.00000"
"51.80000","1.72390","2681.34814","0.01724","268.13483","0.00000"
"52.00000","1.73061","2683.55981","0.01731","268.35599","0.00000"
"52.20000","1.73715","2685.06885","0.01737","268.50690","0.00000"
"52.40000","1.74391","2687.81104","0.01744","268.78110","0.00000"
"52.60000","1.75060","2689.94116","0.01751","268.99411","0.00000"
"52.80000","1.75722","2691.65869","0.01757","269.16586","-0.00001"
"53.00000","1.76396","2694.09058","0.01764","269.40906","-0.00001"
"53.20000","1.77050","2695.39014","0.01771","269.53900","0.00000"
"53.40000","1.77725","2697.53735","0.01777","269.75372","0.00001"
"53.60000","1.78387","2699.22339","0.01784","269.92233","0.00000"
"53.80000","1.79070","2701.96045","0.01791","270.19604","0.00000"
"54.00000","1.79726","2703.40601","0.01797","270.34061","0.00000"
"54.20000","1.80382","2704.49731","0.01804","270.44974","0.00000"
"54.40000","1.81070","2707.50269","0.01811","270.75027","0.00000"
"54.60000","1.81713","2708.26904","0.01817","270.82690","0.00000"
"54.80000","1.82386","2710.08716","0.01824","271.00873","0.00000"
"55.00000","1.83048","2711.89746","0.01830","271.18976","0.00000"
"55.20000","1.83732","2714.11694","0.01837","271.41168","0.00000"
"55.40000","1.84400","2716.09106","0.01844","271.60910","0.00000"
"55.60000","1.85056","2717.28027","0.01851","271.72803","0.00000"
"55.80000","1.85726","2719.02417","0.01857","271.90240","-0.00001"
"56.00000","1.86382","2720.26489","0.01864","272.02649","0.00000"
"56.20000","1.87070","2722.88330","0.01871","272.28833","0.00000"
"56.40000","1.87715","2723.54663","0.01877","272.35468","-0.00001"
"56.60000","1.88383","2725.09448","0.01884","272.50946","0.00000"
"56.80000","1.89063","2727.43311","0.01891","272.74332","-0.00001"
"57.00000","1.89721","2728.55884","0.01897","272.85590","0.00000"
"57.20000","1.90396","2730.25488","0.01904","273.02548","0.00000"
"57.40000","1.91055","2731.27026","0.01911","273.12701","0.00000"
"57.60000","1.91739","2733.60181","0.01917","273.36017","0.00000"
"57.80000","1.92388","2734.45459","0.01924","273.44547","0.00000"
"58.00000","1.93055","2735.93896","0.01931","273.59390","0.00000"
"58.20000","1.93722","2737.34985","0.01937","273.73499","0.00000"
"58.40000","1.94383","2738.41992","0.01944","273.84198","0.00000"
"58.60000","1.95059","2740.33838","0.01951","274.03384","0.00000"
"58.80000","1.95724","2741.48315","0.01957","274.14832","0.00000"
"59.00000","1.96391","2742.75732","0.01964","274.27573","0.00000"
"59.20000","1.97070","2744.71069","0.01971","274.47107","0.00000"
"59.40000","1.97724","2745.38745","0.01977","274.53876","0.00000"
"59.60000","1.98388","2746.50684","0.01984","274.65070","0.00000"
"59.80000","1.99053","2747.77856","0.01991","274.77786","0.00000"
"60.00000","1.99730","2749.37964","0.01997","274.93796","0.00000"
"60.20000","2.00388","2750.32520","0.02004","275.03253","-0.00001"
"60.40000","2.01044","2751.15918","0.02010","275.11591","0.00000"
"60.60000","2.01733","2753.37280","0.02017","275.33728","0.00000"
"60.80000","2.02389","2753.79956","0.02024","275.37994","0.00000"
"61.00000","2.03069","2755.48853","0.02031","275.54886","0.00000"
"61.20000","2.03729","2756.50708","0.02037","275.65070","0.00000"
"61.40000","2.04395","2757.68701","0.02044","275.76871","0.00000"
"61.60000","2.05065","2758.97559","0.02051","275.89755","0.00000"
"61.80000","2.05714","2759.24756","0.02057","275.92474","0.00000"
"62.00000","2.06389","2760.79395","0.02064","276.07941","0.00000"
"62.20000","2.07039","2761.29980","0.02070","276.12997","0.00000"
"62.40000","2.07738","2763.75928","0.02077","276.37592","0.00000"
"62.60000","2.08394","2764.24609","0.02084","276.42462","0.00000"
"62.80000","2.09063","2765.44775","0.02091","276.54477","0.00000"
"63.00000","2.09738","2767.04688","0.02097","276.70468","0.00000"
"63.20000","2.10387","2767.25806","0.02104","276.72580","0.00000"
"63.40000","2.11056","2768.34814","0.02111","276.83481","0.00000"
"63.60000","2.11714","2768.92603","0.02117","276.89261","-0.00001"
"63.80000","2.12398","2770.60889","0.02124","277.06088","0.00000"
"64.00000","2.13053","2771.08618","0.02131","277.10861","0.00000"
"64.20000","2.13722","2772.10425","0.02137","277.21042","0.00000"
"64.40000","2.14400","2773.70752","0.02144","277.37076","0.00000"
"64.60000","2.15055","2774.08130","0.02151","277.40814","0.00000"
"64.80000","2.15736","2775.78271","0.02157","277.57828","0.00000"
"65.00000","2.16391","2775.99146","0.02164","277.59915","0.00000"
"65.20000","2.17059","2776.82617","0.02171","277.68262","0.00000"
"65.40000","2.17725","2777.74438","0.02177","277.77444","-0.00001"
"65.60000","2.18383","2778.13159","0.02184","277.81317","0.00000"
"65.80000","2.19051","2779.12134","0.02191","277.91214","0.00000"
"66.00000","2.19721","2780.32886","0.02197","278.03290","0.00001"
"66.20000","2.20405","2781.80713","0.02204","278.18073","0.00000"
"66.40000","2.21064","2782.23706","0.02211","278.22369","0.00000"
"66.60000","2.21724","2782.51636","0.02217","278.25165","0.00000"
"66.80000","2.22400","2783.88354","0.02224","278.38837","0.00000"
"67.00000","2.23049","2783.84668","0.02230","278.38467","0.00000"
"67.20000","2.23720","2784.86597","0.02237","278.48660","0.00000"
"67.40000","2.24387","2785.64087","0.02244","278.56409","0.00000"
"67.60000","2.25056","2786.49390","0.02251","278.64938","-0.00001"
"67.80000","2.25727","2787.45825","0.02257","278.74582","0.00000"
"68.00000","2.26393","2787.92188","0.02264","278.79218","0.00000"
"68.20000","2.27069","2789.01611","0.02271","278.90161","0.00000"
"68.40000","2.27714","2788.77246","0.02277","278.87726","-0.00001"
"68.60000","2.28402","2790.63794","0.02284","279.06378","0.00000"
"68.80000","2.29059","2791.07397","0.02291","279.10739","0.00000"
"69.00000","2.29713","2790.99634","0.02297","279.09964","0.00000"
"69.20000","2.30404","2792.78125","0.02304","279.27814","-0.00001"
"69.40000","2.31047","2792.37329","0.02310","279.23734","0.00000"
"69.60000","2.31721","2793.34912","0.02317","279.33490","-0.00001"
"69.80000","2.32394","2794.51196","0.02324","279.45120","0.00000"
"70.00000","2.33079","2795.76025","0.02331","279.57602","0.00000"
"70.20000","2.33735","2796.00488","0.02337","279.60049","0.00000"
"70.40000","2.34387","2796.06055","0.02344","279.60605","-0.00001"
"70.60000","2.35063","2797.17480","0.02351","279.71747","0.00000"
"70.80000","2.35707","2796.65527","0.02357","279.66553","0.00000"
"71.00000","2.36402","2798.55664","0.02364","279.85565","0.00000"
"71.20000","2.37050","2798.48071","0.02371","279.84808","0.00000"
"71.40000","2.37724","2799.36499","0.02377","279.93649","-0.00001"
"71.60000","2.38402","2800.62500","0.02384","280.06250","0.00000"
"71.80000","2.39063","2800.77246","0.02391","280.07724","0.00000"
"72.00000","2.39727","2801.20850","0.02397","280.12085","0.00000"
"72.20000","2.40383","2801.21851","0.02404","280.12186","0.00000"
"72.40000","2.41068","2802.58740","0.02411","280.25873","0.00000"
"72.60000","2.41720","2802.48218","0.02417","280.24823","0.00000"
"72.80000","2.42384","2802.90356","0.02424","280.29034","0.00001"
"73.00000","2.43062","2804.04663","0.02431","280.40466","0.00000"
"73.20000","2.43718","2803.92456","0.02437","280.39246","0.00000"
"73.40000","2.44401","2804.98682","0.02444","280.49869","0.00000"
"73.60000","2.45061","2805.08960","0.02451","280.50897","0.00000"
"73.80000","2.45727","2805.56787","0.02457","280.55679","0.00000"
"74.00000","2.46394","2806.15991","0.02464","280.61600","0.00000"
"74.20000","2.47054","2806.55029","0.02471","280.65503","0.00000"
"74.40000","2.47721","2806.70825","0.02477","280.67084","-0.00001"
"74.60000","2.48382","2807.02124","0.02484","280.70212","0.00001"
"74.80000","2.49065","2808.07080","0.02491","280.80707","0.00000"
"75.00000","2.49729","2808.47021","0.02497","280.84702","0.00000"
"75.20000","2.50385","2808.25684","0.02504","280.82568","-0.00001"
"75.40000","2.51072","2809.68018","0.02511","280.96802","0.00000"
"75.60000","2.51721","2809.30615","0.02517","280.93060","0.00001"
"75.80000","2.52388","2809.65503","0.02524","280.96552","0.00000"
"76.00000","2.53050","2809.90479","0.02530","280.99048","-0.00001"
"76.20000","2.53729","2810.77930","0.02537","281.07794","0.00000"
"76.40000","2.54395","2811.21704","0.02544","281.12170","0.00000"
"76.60000","2.55054","2811.26489","0.02551","281.12650","0.00000"
"76.80000","2.55731","2812.12793","0.02557","281.21280","0.00000"
"77.00000","2.56381","2811.76611","0.02564","281.17661","-0.00001"
"77.20000","2.57070","2813.04077","0.02571","281.30408","0.00000"
"77.40000","2.57727","2813.03662","0.02577","281.30365","0.00000"
"77.60000","2.58390","2813.13330","0.02584","281.31332","0.00000"
"77.80000","2.59061","2813.75952","0.02591","281.37595","-0.00001"
"78.00000","2.59717","2813.44458","0.02597","281.34445","0.00000"
"78.20000","2.60396","2814.44507","0.02604","281.44452","-0.00001"
"78.40000","2.61045","2813.94775","0.02610","281.39478","0.00001"
"78.60000","2.61741","2815.56714","0.02617","281.55670","0.00000"
"78.80000","2.62395","2815.26343","0.02624","281.52634","-0.00001"
"79.00000","2.63055","2815.16821","0.02631","281.51682","-0.00001"
"79.20000","2.63728","2815.79346","0.02637","281.57935","0.00000"
"79.40000","2.64379","2815.37964","0.02644","281.53796","0.00000"
"79.60000","2.65056","2816.15503","0.02651","281.61551","0.00000"
"79.80000","2.65723","2816.28052","0.02657","281.62805","-0.00001"
"80.00000","2.66395","2816.78174","0.02664","281.67816","0.00000"
"80.20000","2.67063","2816.98340","0.02671","281.69833","0.00000"
"80.40000","2.67720","2816.81616","0.02677","281.68161","0.00000"
"80.60000","2.68394","2817.40381","0.02684","281.74039","0.00000"
"80.80000","2.69054","2817.38965","0.02691","281.73895","-0.00001"
"81.00000","2.69733","2818.09009","0.02697","281.80902","0.00000"
"81.20000","2.70386","2817.57007","0.02704","281.75702","0.00000"
"81.40000","2.71050","2817.63940","0.02710","281.76395","0.00000"
"81.60000","2.71736","2818.67041","0.02717","281.86703","-0.00001"
"81.80000","2.72384","2818.08008","0.02724","281.80801","-0.00001"
"82.00000","2.73055","2818.32495","0.02731","281.83249","-0.00001"
"82.20000","2.73725","2818.96826","0.02737","281.89682","0.00001"
"82.40000","2.74401","2819.22998","0.02744","281.92300","0.00000"
"82.60000","2.75060","2819.21753","0.02751","281.92175","0.00000"
"82.80000","2.75718","2818.75293","0.02757","281.87531","-0.00001"
"83.00000","2.76393","2819.33862","0.02764","281.93387","0.00000"
"83.20000","2.77041","2818.87500","0.02770","281.88751","0.00001"
"83.40000","2.77731","2820.07300","0.02777","282.00729","0.00000"
"83.60000","2.78391","2820.06201","0.02784","282.00620","0.00000"
"83.80000","2.79056","2819.96362","0.02791","281.99637","0.00000"
"84.00000","2.79739","2820.88208","0.02797","282.08820","0.00001"
"84.20000","2.80383","2819.85327","0.02804","281.98532","0.00000"
"84.40000","2.81053","2820.10669","0.02811","282.01068","0.00000"
"84.60000","2.81712","2820.00220","0.02817","282.00021","-0.00001"
"84.80000","2.82399","2821.07080","0.02824","282.10709","0.00000"
"85.00000","2.83049","2820.49805","0.02830","282.04980","0.00000"
"85.20000","2.83724","2820.89966","0.02837","282.08997","0.00000"
"85.40000","2.84400","2821.37915","0.02844","282.13791","0.00000"
"85.60000","2.85050","2820.55688","0.02850","282.05569","0.00000"
"85.80000","2.85730","2821.41162","0.02857","282.14117","0.00000"
"86.00000","2.86386","2821.09155","0.02864","282.10916","0.00000"
"86.20000","2.87059","2821.34814","0.02871","282.13483","0.00000"
"86.40000","2.87725","2821.49072","0.02877","282.14908","-0.00001"
"86.60000","2.88386","2821.12305","0.02884","282.11230","0.00000"
"86.80000","2.89054","2821.16675","0.02891","282.11667","0.00000"
"87.00000","2.89720","2821.29907","0.02897","282.12991","0.00001"
"87.20000","2.90400","2821.85718","0.02904","282.18573","0.00000"
"87.40000","2.91055","2821.38159","0.02911","282.13815","0.00000"
"87.60000","2.91718","2821.11499","0.02917","282.11151","-0.00001"
"87.80000","2.92404","2822.04761","0.02924","282.20477","0.00001"
"88.00000","2.93054","2821.15723","0.02931","282.11572","0.00000"
"88.20000","2.93720","2821.06616","0.02937","282.10663","0.00000"
"88.40000","2.94388","2821.24756","0.02944","282.12476","0.00000"
"88.60000","2.95056","2821.44238","0.02951","282.14423","0.00000"
"88.80000","2.95732","2821.77515","0.02957","282.17752","0.00000"
"89.00000","2.96384","2821.16406","0.02964","282.11639","0.00000"
"89.20000","2.97064","2821.57495","0.02971","282.15750","0.00000"
"89.40000","2.97716","2820.93628","0.02977","282.09363","-0.00001"
"89.60000","2.98400","2821.52295","0.02984","282.15228","0.00000"
"89.80000","2.99055","2821.06250","0.02991","282.10626","0.00000"
"90.00000","2.99717","2820.76904","0.02997","282.07690","0.00000"
"90.20000","3.00397","2821.40552","0.03004","282.14056","-0.00001"
"90.40000","3.01050","2820.75659","0.03011","282.07565","0.00000"
"90.60000","3.01726","2820.98364","0.03017","282.09836","0.00000"
"90.80000","3.02383","2820.51221","0.03024","282.05121","0.00001"
"91.00000","3.03067","2821.16602","0.03031","282.11661","0.00000"
"91.20000","3.03724","2820.78027","0.03037","282.07803","0.00000"
"91.40000","3.04383","2820.34863","0.03044","282.03485","0.00000"
"91.60000","3.05066","2820.94727","0.03051","282.09473","0.00000"
"91.80000","3.05713","2819.97559","0.03057","281.99756","0.00000"
"92.00000","3.06391","2820.28076","0.03064","282.02808","0.00000"
"92.20000","3.07050","2819.83765","0.03070","281.98376","-0.00001"
"92.40000","3.07733","2820.49414","0.03077","282.04941","0.00000"
"92.60000","3.08390","2820.33472","0.03084","282.03348","0.00000"
"92.80000","3.09053","2819.79028","0.03091","281.97903","0.00000"
"93.00000","3.09724","2819.95703","0.03097","281.99570","0.00000"
"93.20000","3.10379","2819.23218","0.03104","281.92322","-0.00001"
"93.40000","3.11075","2820.23999","0.03111","282.02399","0.00000"
"93.60000","3.11718","2819.16455","0.03117","281.91644","0.00000"
"93.80000","3.12382","2818.88940","0.03124","281.88895","0.00001"
"94.00000","3.13062","2819.30518","0.03131","281.93051","0.00000"
"94.20000","3.13721","2818.86621","0.03137","281.88663","0.00000"
"94.40000","3.14385","2818.60449","0.03144","281.86044","-0.00001"
"94.60000","3.15056","2818.59424","0.03151","281.85944","0.00000"
"94.80000","3.15731","2818.68823","0.03157","281.86884","0.00000"
"95.00000","3.16396","2818.50684","0.03164","281.85068","-0.00001"
"95.20000","3.17056","2817.92432","0.03171","281.79242","0.00000"
"95.40000","3.17724","2817.84961","0.03177","281.78497","0.00000"
"95.60000","3.18382","2817.43945","0.03184","281.74396","0.00000"
"95.80000","3.19062","2817.68188","0.03191","281.76819","0.00000"
"96.00000","3.19729","2817.37817","0.03197","281.73782","0.00000"
"96.20000","3.20383","2816.60791","0.03204","281.66080","-0.00001"
"96.40000","3.21065","2817.19849","0.03211","281.71985","0.00000"
"96.60000","3.21717","2816.40601","0.03217","281.64059","0.00000"
"96.80000","3.22391","2816.48926","0.03224","281.64893","0.00000"
"97.00000","3.23055","2816.07397","0.03231","281.60739","0.00000"
"97.20000","3.23736","2816.31030","0.03237","281.63104","0.00000"
"97.40000","3.24391","2815.47095","0.03244","281.54709","0.00000"
"97.60000","3.25048","2814.81812","0.03250","281.48181","0.00000"
"97.80000","3.25735","2815.61963","0.03257","281.56195","-0.00001"
"98.00000","3.26377","2814.35059","0.03264","281.43506","-0.00001"
"98.20000","3.27056","2814.71924","0.03271","281.47192","0.00000"
"98.40000","3.27720","2814.35522","0.03277","281.43552","0.00000"
"98.60000","3.28395","2814.18677","0.03284","281.41867","0.00001"
"98.80000","3.29071","2814.42969","0.03291","281.44296","0.00000"
"99.00000","3.29721","2813.25610","0.03297","281.32562","0.00000"
"99.20000","3.30388","2813.05249","0.03304","281.30524","0.00000"
"99.40000","3.31045","2812.54297","0.03310","281.25430","0.00000"
"99.60000","3.31740","2813.36743","0.03317","281.33673","0.00000"
"99.80000","3.32384","2812.19922","0.03324","281.21991","0.00000"
"100.00000","3.33049","2811.50562","0.03330","281.15057","0.00000"
"100.20000","3.33731","2811.80786","0.03337","281.18079","0.00000"
"100.40000","3.34382","2811.04980","0.03344","281.10498","0.00000"
"100.60000","3.35062","2811.31421","0.03351","281.13141","0.00000"
"100.80000","3.35724","2810.72144","0.03357","281.07214","0.00000"
"101.00000","3.36402","2810.77515","0.03364","281.07751","0.00000"
"101.20000","3.37057","2810.10205","0.03371","281.01019","0.00000"
"101.40000","3.37724","2809.57715","0.03377","280.95770","0.00000"
"101.60000","3.38385","2809.03662","0.03384","280.90366","0.00000"
"101.80000","3.39049","2808.52197","0.03390","280.85220","0.00000"
"102.00000","3.39729","2808.84277","0.03397","280.88428","0.00000"
"102.20000","3.40392","2808.28931","0.03404","280.82892","-0.00001"
"102.40000","3.41056","2807.59863","0.03411","280.75986","0.00000"
"102.60000","3.41736","2807.85718","0.03417","280.78571","-0.00001"
"102.80000","3.42389","2806.74365","0.03424","280.67438","0.00000"
"103.00000","3.43053","2806.10376","0.03431","280.61038","0.00000"
"103.20000","3.43722","2805.89429","0.03437","280.58942","0.00000"
"103.40000","3.44397","2805.81177","0.03444","280.58118","0.00000"
"103.60000","3.45056","2805.06543","0.03451","280.50653","0.00001"
"103.80000","3.45712","2804.25903","0.03457","280.42590","0.00000"
"104.00000","3.46401","2804.47021","0.03464","280.44702","0.00000"
"104.20000","3.47054","2803.26001","0.03471","280.32599","0.00000"
"104.40000","3.47736","2803.55298","0.03477","280.35529","0.00000"
"104.60000","3.48393","2802.59595","0.03484","280.25958","0.00000"
"104.80000","3.49058","2801.91943","0.03491","280.19196","0.00000"
"105.00000","3.49735","2801.77417","0.03497","280.17743","0.00000"
"105.20000","3.50381","2800.41626","0.03504","280.04163","0.00000"
"105.40000","3.51052","2799.70801","0.03511","279.97079","0.00000"
"105.60000","3.51706","2798.73486","0.03517","279.87347","-0.00001"
"105.80000","3.52407","2799.44556","0.03524","279.94455","0.00000"
"106.00000","3.53061","2798.31470","0.03531","279.83148","-0.00001"
"106.20000","3.53727","2797.61377","0.03537","279.76138","0.00000"
"106.40000","3.54408","2797.44922","0.03544","279.74493","0.00000"
"106.60000","3.55052","2795.75073","0.03551","279.57507","0.00000"
"106.80000","3.55721","2794.97852","0.03557","279.49786","-0.00001"
"107.00000","3.56380","2793.97852","0.03564","279.39786","0.00000"
"107.20000","3.57061","2793.68677","0.03571","279.36868","0.00000"
"107.40000","3.57721","2792.70020","0.03577","279.27002","0.00000"
"107.60000","3.58389","2791.80176","0.03584","279.18018","0.00000"
"107.80000","3.59064","2791.17334","0.03591","279.11734","0.00000"
"108.00000","3.59721","2789.86182","0.03597","278.98618","0.00000"
"108.20000","3.60410","2789.60645","0.03604","278.96063","0.00000"
"108.40000","3.61054","2787.88965","0.03611","278.78897","0.00000"
"108.60000","3.61720","2786.75757","0.03617","278.67575","0.00000"
"108.80000","3.62392","2785.85132","0.03624","278.58514","0.00000"
"109.00000","3.63053","2784.20386","0.03631","278.42038","0.00000"
"109.20000","3.63719","2782.67554","0.03637","278.26755","0.00001"
"109.40000","3.64389","2781.60620","0.03644","278.16061","-0.00001"
"109.60000","3.65070","2780.86646","0.03651","278.08664","0.00000"
"109.80000","3.65732","2779.24878","0.03657","277.92487","0.00000"
"110.00000","3.66389","2777.41113","0.03664","277.74112","0.00000"
"110.20000","3.67064","2776.20044","0.03671","277.62006","0.00001"
"110.40000","3.67716","2774.01733","0.03677","277.40173","0.00000"
"110.60000","3.68391","2772.28027","0.03684","277.22803","0.00000"
"110.80000","3.69058","2770.23267","0.03691","277.02325","0.00000"
"111.00000","3.69717","2767.68726","0.03697","276.76874","0.00000"
"111.20000","3.70397","2766.28857","0.03704","276.62885","0.00000"
"111.40000","3.71059","2763.91162","0.03711","276.39117","0.00000"
"111.60000","3.71735","2762.07666","0.03717","276.20767","-0.00001"
"111.80000","3.72389","2759.31226","0.03724","275.93121","0.00000"
"112.00000","3.73068","2757.00513","0.03731","275.70050","0.00000"
"112.20000","3.73726","2753.91235","0.03737","275.39124","0.00000"
"112.40000","3.74380","2749.48438","0.03744","274.94843","0.00000"
"112.60000","3.75067","2746.40991","0.03751","274.64099","0.00000"
"112.80000","3.75711","2741.49243","0.03757","274.14923","0.00000"
"113.00000","3.76390","2737.06592","0.03764","273.70660","0.00001"
"113.20000","3.77062","2732.19922","0.03771","273.21991","0.00000"
"113.40000","3.77744","2726.02783","0.03777","272.60278","-0.00001"
"113.60000","3.78395","2716.72705","0.03784","271.67270","0.00000"
"113.80000","3.79055","2707.49487","0.03791","270.74948","0.00000"
"114.00000","3.79726","2699.82568","0.03797","269.98257","0.00001"
"114.20000","3.80375","2690.44946","0.03804","269.04495","-0.00001"
"114.40000","3.81070","2680.58594","0.03811","268.05859","-0.00001"
"114.60000","3.81719","2651.34302","0.03817","265.13431","0.00000"
"114.80000","3.82391","2599.67847","0.03824","259.96783","0.00000"
"115.00000","3.83071","2504.45874","0.03831","250.44588","0.00000"
"115.04000","3.83195","2241.00659","0.03832","224.10066","0.00000"
"115.04500","3.83211","1938.38660","0.03832","193.83865","0.00000"
"115.04900","3.83226","1663.71875","0.03832","166.37187","0.00001"
"115.05200","3.83238","1454.08289","0.03832","145.40829","0.00001"