File: Tension/Section_2_Group_2/rivet_high_Sample2.is_tens_RawData/Specimen_RawData_1.csv
Time,Extension,Load,Tensile strain (Extension),Tensile stress,Strain-by-clip-gage
(s),(mm),(N),(mm/mm),(MPa),(mm/mm)
"0.00000","0.00000","-147.03484","0.00000","-14.70348","-0.00018"
"0.50000","0.01369","-70.84129","0.00014","-7.08413","-0.00018"
"1.00000","0.03032","11.57946","0.00030","1.15795","-0.00018"
"1.50000","0.04712","84.76555","0.00047","8.47655","-0.00018"
"2.00000","0.06370","146.61414","0.00064","14.66141","-0.00019"
"2.50000","0.08043","201.08705","0.00080","20.10871","-0.00019"
"3.00000","0.09703","249.29050","0.00097","24.92905","-0.00020"
"3.50000","0.11371","296.18036","0.00114","29.61804","-0.00020"
"4.00000","0.13045","341.14737","0.00130","34.11474","-0.00020"
"4.50000","0.14705","383.46042","0.00147","38.34604","0.00017"
"5.00000","0.16369","424.11093","0.00164","42.41109","-0.00011"
"5.50000","0.18025","462.86783","0.00180","46.28678","-0.00017"
"6.00000","0.19708","501.61984","0.00197","50.16198","-0.00021"
"6.50000","0.21367","537.63940","0.00214","53.76394","-0.00022"
"7.00000","0.23048","573.57562","0.00230","57.35756","-0.00022"
"7.50000","0.24698","606.17828","0.00247","60.61783","-0.00022"
"8.00000","0.26377","639.36182","0.00264","63.93618","-0.00021"
"8.50000","0.28044","670.72015","0.00280","67.07201","-0.00020"
"9.00000","0.29701","700.42834","0.00297","70.04283","-0.00020"
"9.50000","0.31386","730.25964","0.00314","73.02596","-0.00019"
"10.00000","0.33034","756.59869","0.00330","75.65987","-0.00019"
"10.50000","0.34693","780.52191","0.00347","78.05219","-0.00019"
"11.00000","0.36362","801.28741","0.00364","80.12874","-0.00019"
"11.50000","0.38045","816.18152","0.00380","81.61815","-0.00018"
"12.00000","0.39705","826.97833","0.00397","82.69783","-0.00019"
"12.50000","0.41382","838.47510","0.00414","83.84751","-0.00019"
"13.00000","0.43029","846.51404","0.00430","84.65141","-0.00019"
"13.50000","0.44700","849.86414","0.00447","84.98641","-0.00019"
"14.00000","0.46378","860.89911","0.00464","86.08991","-0.00019"
"14.50000","0.48035","876.49615","0.00480","87.64961","-0.00020"
"15.00000","0.49710","893.82593","0.00497","89.38259","-0.00020"
"15.50000","0.51355","906.69739","0.00514","90.66974","-0.00020"
"16.00000","0.53033","914.88092","0.00530","91.48809","-0.00020"
"16.50000","0.54699","924.03864","0.00547","92.40386","-0.00020"
"17.00000","0.56386","937.66516","0.00564","93.76652","-0.00020"
"17.50000","0.58033","948.70331","0.00580","94.87033","-0.00020"
"18.00000","0.59703","959.31415","0.00597","95.93141","-0.00020"
"18.50000","0.61368","969.82465","0.00614","96.98247","-0.00020"
"19.00000","0.63047","981.73749","0.00630","98.17375","-0.00020"
"19.50000","0.64709","990.65692","0.00647","99.06569","-0.00019"
"20.00000","0.66366","998.14777","0.00664","99.81477","-0.00019"
"20.50000","0.68044","1003.85205","0.00680","100.38521","-0.00019"
"21.00000","0.69700","1005.31232","0.00697","100.53123","-0.00019"
"21.50000","0.71370","1007.07532","0.00714","100.70753","-0.00019"
"22.00000","0.73030","1005.30072","0.00730","100.53008","-0.00019"
"22.50000","0.74717","993.07404","0.00747","99.30740","-0.00019"
"23.00000","0.76365","993.51471","0.00764","99.35147","-0.00019"
"23.50000","0.78037","996.41840","0.00780","99.64184","-0.00019"
"24.00000","0.79711","996.49408","0.00797","99.64941","-0.00020"
"24.50000","0.81370","1000.92133","0.00814","100.09213","-0.00020"
"25.00000","0.83049","1009.13464","0.00830","100.91347","-0.00020"
"25.50000","0.84698","1018.70459","0.00847","101.87046","-0.00020"
"26.00000","0.86372","1030.94458","0.00864","103.09446","-0.00020"
"26.50000","0.88031","1040.11487","0.00880","104.01149","-0.00020"
"27.00000","0.89707","1051.43518","0.00897","105.14352","-0.00020"
"27.50000","0.91361","1044.38452","0.00914","104.43845","-0.00020"
"28.00000","0.93048","1044.24976","0.00930","104.42497","-0.00020"
"28.50000","0.94698","1023.83923","0.00947","102.38393","-0.00020"
"29.00000","0.96372","1002.49005","0.00964","100.24901","-0.00019"
"29.50000","0.98046","995.59601","0.00980","99.55960","-0.00019"
"30.00000","0.99702","994.55408","0.00997","99.45541","-0.00019"
"30.50000","1.01379","995.12793","0.01014","99.51279","-0.00018"
"31.00000","1.03024","998.05017","0.01030","99.80502","-0.00018"
"31.50000","1.04707","1008.82574","0.01047","100.88258","-0.00018"
"32.00000","1.06365","1018.41370","0.01064","101.84137","-0.00018"
"32.50000","1.08038","1028.87500","0.01080","102.88750","-0.00018"
"33.00000","1.09706","1000.28735","0.01097","100.02873","-0.00018"
"33.50000","1.11385","989.87396","0.01114","98.98740","-0.00019"
"34.00000","1.13030","987.23218","0.01130","98.72322","-0.00019"
"34.50000","1.14703","993.31635","0.01147","99.33163","-0.00019"
"35.00000","1.16379","1000.32111","0.01164","100.03211","-0.00019"
"35.50000","1.18038","1003.70776","0.01180","100.37077","-0.00020"
"36.00000","1.19706","1005.91473","0.01197","100.59148","-0.00020"
"36.50000","1.21352","1007.50781","0.01214","100.75078","-0.00021"
"37.00000","1.23033","1011.72058","0.01230","101.17206","-0.00021"
"37.50000","1.24703","1012.69177","0.01247","101.26918","-0.00021"
"38.00000","1.26377","1012.49188","0.01264","101.24919","-0.00020"
"38.50000","1.28033","1009.60834","0.01280","100.96083","-0.00020"
"39.00000","1.29702","1009.32373","0.01297","100.93237","-0.00019"
"39.50000","1.31374","1006.80432","0.01314","100.68044","-0.00019"
"40.00000","1.33036","1001.59698","0.01330","100.15970","-0.00019"
"40.50000","1.34716","997.43500","0.01347","99.74350","-0.00019"
"41.00000","1.36364","994.74609","0.01364","99.47461","-0.00020"
"41.50000","1.38031","995.50012","0.01380","99.55001","-0.00018"
"42.00000","1.39697","994.06390","0.01397","99.40639","-0.00018"
"42.50000","1.41386","996.21014","0.01414","99.62102","-0.00018"
"43.00000","1.43031","997.15747","0.01430","99.71574","-0.00018"
"43.50000","1.44714","1002.40668","0.01447","100.24067","-0.00018"
"44.00000","1.46363","1006.74445","0.01464","100.67445","-0.00018"
"44.50000","1.48041","1013.01538","0.01480","101.30154","-0.00018"
"45.00000","1.49717","1019.17908","0.01497","101.91791","-0.00018"
"45.50000","1.51366","1026.39368","0.01514","102.63937","-0.00018"
"46.00000","1.53051","1033.27905","0.01531","103.32790","-0.00019"
"46.50000","1.54695","1037.04272","0.01547","103.70427","-0.00019"
"47.00000","1.56361","1043.59851","0.01564","104.35985","-0.00020"
"47.50000","1.58032","1051.41650","0.01580","105.14165","-0.00020"
"48.00000","1.59710","1059.98328","0.01597","105.99833","-0.00020"
"48.50000","1.61365","1067.15149","0.01614","106.71515","-0.00021"
"49.00000","1.63044","1074.60706","0.01630","107.46071","-0.00021"
"49.50000","1.64703","1074.81934","0.01647","107.48193","-0.00021"
"50.00000","1.66372","1078.34521","0.01664","107.83452","-0.00020"
"50.50000","1.68046","1081.54883","0.01680","108.15488","-0.00020"
"51.00000","1.69694","1084.32483","0.01697","108.43248","-0.00020"
"51.50000","1.71374","1088.95532","0.01714","108.89553","-0.00020"
"52.00000","1.73024","1092.47485","0.01730","109.24748","-0.00020"
"52.50000","1.74704","1098.79736","0.01747","109.87974","-0.00019"
"53.00000","1.76369","1103.19128","0.01764","110.31913","-0.00019"
"53.50000","1.78045","1108.89575","0.01780","110.88957","-0.00019"
"54.00000","1.79703","1113.50952","0.01797","111.35095","-0.00018"
"54.50000","1.81376","1120.40662","0.01814","112.04066","-0.00018"
"55.00000","1.83039","1126.85156","0.01830","112.68516","-0.00019"
"55.50000","1.84701","1122.30090","0.01847","112.23009","-0.00019"
"56.00000","1.86373","1112.28540","0.01864","111.22854","-0.00019"
"56.50000","1.88034","1107.95667","0.01880","110.79567","-0.00019"
"57.00000","1.89717","1105.85425","0.01897","110.58543","-0.00019"
"57.50000","1.91360","1105.92236","0.01914","110.59224","-0.00019"
"58.00000","1.93038","1107.13110","0.01930","110.71311","-0.00020"
"58.50000","1.94703","1105.60754","0.01947","110.56075","-0.00020"
"59.00000","1.96386","1109.00696","0.01964","110.90070","-0.00020"
"59.50000","1.98035","1112.92212","0.01980","111.29221","-0.00020"
"60.00000","1.99699","1118.45813","0.01997","111.84581","-0.00020"
"60.50000","2.01374","1124.84338","0.02014","112.48434","-0.00020"
"61.00000","2.03037","1131.37573","0.02030","113.13757","-0.00020"
"61.50000","2.04711","1135.79797","0.02047","113.57980","-0.00019"
"62.00000","2.06366","1139.85352","0.02064","113.98535","-0.00019"
"62.50000","2.08031","1138.95227","0.02080","113.89523","-0.00019"
"63.00000","2.09698","1136.15259","0.02097","113.61526","-0.00019"
"63.50000","2.11378","1139.20789","0.02114","113.92079","-0.00018"
"64.00000","2.13039","1140.51514","0.02130","114.05151","-0.00019"
"64.50000","2.14708","1144.02307","0.02147","114.40231","-0.00019"
"65.00000","2.16365","1146.83289","0.02164","114.68329","-0.00018"
"65.50000","2.18037","1152.11255","0.02180","115.21126","-0.00018"
"66.00000","2.19724","1157.07996","0.02197","115.70799","-0.00019"
"66.50000","2.21365","1157.62476","0.02214","115.76247","-0.00019"
"67.00000","2.23045","1159.78943","0.02230","115.97894","-0.00019"
"67.50000","2.24691","1162.04395","0.02247","116.20439","-0.00020"
"68.00000","2.26373","1167.20667","0.02264","116.72066","-0.00020"
"68.50000","2.28035","1171.90393","0.02280","117.19039","-0.00020"
"69.00000","2.29711","1178.20251","0.02297","117.82025","-0.00020"
"69.50000","2.31368","1179.45435","0.02314","117.94543","-0.00021"
"70.00000","2.33041","1183.91797","0.02330","118.39180","-0.00021"
"70.50000","2.34700","1187.21326","0.02347","118.72133","-0.00021"
"71.00000","2.36374","1179.62122","0.02364","117.96212","-0.00020"
"71.50000","2.38051","1180.70996","0.02381","118.07100","-0.00020"
"72.00000","2.39697","1182.39441","0.02397","118.23944","-0.00020"
"72.50000","2.41366","1187.64294","0.02414","118.76430","-0.00020"
"73.00000","2.43031","1192.47522","0.02430","119.24752","-0.00019"
"73.50000","2.44703","1197.41504","0.02447","119.74150","-0.00019"
"74.00000","2.46366","1203.30884","0.02464","120.33089","-0.00019"
"74.50000","2.48044","1209.68433","0.02480","120.96843","-0.00018"
"75.00000","2.49701","1212.68811","0.02497","121.26881","-0.00018"
"75.50000","2.51369","1211.08911","0.02514","121.10891","-0.00018"
"76.00000","2.53041","1210.84680","0.02530","121.08468","-0.00018"
"76.50000","2.54705","1212.17212","0.02547","121.21721","-0.00018"
"77.00000","2.56379","1214.38660","0.02564","121.43866","-0.00018"
"77.50000","2.58032","1216.20776","0.02580","121.62077","-0.00018"
"78.00000","2.59700","1195.58118","0.02597","119.55812","-0.00019"
"78.50000","2.61369","1196.66687","0.02614","119.66669","-0.00019"
"79.00000","2.63040","1201.02307","0.02630","120.10231","-0.00019"
"79.50000","2.64698","1208.13538","0.02647","120.81354","-0.00020"
"80.00000","2.66388","1214.54163","0.02664","121.45416","-0.00021"
"80.50000","2.68046","1198.15906","0.02680","119.81590","-0.00021"
"81.00000","2.69698","1199.18872","0.02697","119.91887","-0.00021"
"81.50000","2.71378","1204.80371","0.02714","120.48037","-0.00021"
"82.00000","2.73033","1208.75964","0.02730","120.87596","-0.00020"
"82.50000","2.74720","1216.30786","0.02747","121.63078","-0.00020"
"83.00000","2.76360","1224.22339","0.02764","122.42234","-0.00021"
"83.50000","2.78030","1232.40479","0.02780","123.24048","-0.00021"
"84.00000","2.79698","1237.11560","0.02797","123.71156","-0.00020"
"84.50000","2.81379","1242.73193","0.02814","124.27319","-0.00019"
"85.00000","2.83032","1244.29993","0.02830","124.42999","-0.00019"
"85.50000","2.84711","1243.70728","0.02847","124.37073","-0.00019"
"86.00000","2.86364","1247.92639","0.02864","124.79264","-0.00018"
"86.50000","2.88039","1254.24670","0.02880","125.42467","-0.00018"
"87.00000","2.89712","1259.80322","0.02897","125.98032","-0.00018"
"87.50000","2.91371","1265.17871","0.02914","126.51787","-0.00018"
"88.00000","2.93034","1271.59631","0.02930","127.15963","-0.00018"
"88.50000","2.94691","1277.71704","0.02947","127.77171","-0.00018"
"89.00000","2.96369","1284.94507","0.02964","128.49451","-0.00018"
"89.50000","2.98043","1291.05103","0.02980","129.10510","-0.00019"
"90.00000","2.99706","1296.83582","0.02997","129.68358","-0.00020"
"90.50000","3.01366","1295.93774","0.03014","129.59378","-0.00019"
"91.00000","3.03039","1298.02734","0.03030","129.80273","-0.00019"
"91.50000","3.04710","1297.79492","0.03047","129.77950","-0.00020"
"92.00000","3.06374","1296.02905","0.03064","129.60291","-0.00020"
"92.50000","3.08048","1267.82947","0.03080","126.78294","-0.00021"
"93.00000","3.09699","1223.64551","0.03097","122.36455","-0.00020"
"93.50000","3.11370","1217.18726","0.03114","121.71873","-0.00021"
"94.00000","3.13024","1215.39819","0.03130","121.53982","-0.00020"
"94.50000","3.14713","1216.53027","0.03147","121.65303","-0.00020"
"95.00000","3.16369","1214.84851","0.03164","121.48485","-0.00019"
"95.50000","3.18045","1219.42773","0.03180","121.94277","-0.00019"
"96.00000","3.19698","1223.51331","0.03197","122.35133","-0.00018"
"96.50000","3.21374","1231.03760","0.03214","123.10376","-0.00019"
"97.00000","3.23046","1237.15845","0.03230","123.71584","-0.00020"
"97.50000","3.24703","1243.24292","0.03247","124.32430","-0.00018"
"98.00000","3.26373","1249.90784","0.03264","124.99078","-0.00017"
"98.50000","3.28032","1255.32825","0.03280","125.53282","-0.00018"
"99.00000","3.29700","1261.55786","0.03297","126.15578","-0.00018"
"99.50000","3.31364","1265.19495","0.03314","126.51949","-0.00019"
"100.00000","3.33047","1254.99561","0.03330","125.49956","-0.00019"
"100.50000","3.34696","1231.16309","0.03347","123.11631","-0.00019"
"101.00000","3.36380","1234.04138","0.03364","123.40414","-0.00019"
"101.50000","3.38038","1237.78149","0.03380","123.77815","-0.00020"
"102.00000","3.39706","1244.92725","0.03397","124.49272","-0.00020"
"102.50000","3.41382","1252.83093","0.03414","125.28310","-0.00020"
"103.00000","3.43028","1259.01965","0.03430","125.90196","-0.00020"
"103.50000","3.44710","1267.99329","0.03447","126.79933","-0.00020"
"104.00000","3.46369","1275.92371","0.03464","127.59237","-0.00020"
"104.50000","3.48029","1283.36633","0.03480","128.33664","-0.00020"
"105.00000","3.49701","1290.57056","0.03497","129.05705","-0.00019"
"105.50000","3.51384","1297.02539","0.03514","129.70255","-0.00019"
"106.00000","3.53040","1300.48120","0.03530","130.04813","-0.00019"
"106.50000","3.54713","1302.70581","0.03547","130.27058","-0.00018"
"107.00000","3.56367","1301.13147","0.03564","130.11314","-0.00018"
"107.50000","3.58035","1304.25696","0.03580","130.42569","-0.00018"
"108.00000","3.59716","1308.65393","0.03597","130.86539","-0.00018"
"108.50000","3.61362","1310.74084","0.03614","131.07408","-0.00018"
"109.00000","3.63031","1313.49561","0.03630","131.34956","-0.00018"
"109.50000","3.64692","1316.18555","0.03647","131.61856","-0.00018"
"110.00000","3.66371","1319.80896","0.03664","131.98090","-0.00018"
"110.50000","3.68035","1314.44275","0.03680","131.44427","-0.00019"
"111.00000","3.69719","1309.63135","0.03697","130.96313","-0.00019"
"111.50000","3.71364","1306.03271","0.03714","130.60327","-0.00019"
"112.00000","3.73035","1305.02832","0.03730","130.50284","-0.00020"
"112.50000","3.74707","1303.80249","0.03747","130.38025","-0.00021"
"113.00000","3.76378","1302.16162","0.03764","130.21616","-0.00021"
"113.50000","3.78042","1298.43311","0.03780","129.84331","-0.00021"
"114.00000","3.79693","1296.74744","0.03797","129.67474","-0.00022"
"114.50000","3.81372","1297.55823","0.03814","129.75583","-0.00022"
"115.00000","3.83033","1296.46655","0.03830","129.64665","-0.00021"
"115.50000","3.84716","1296.54700","0.03847","129.65469","-0.00021"
"116.00000","3.86367","1297.53003","0.03864","129.75301","-0.00020"
"116.50000","3.88048","1301.37964","0.03880","130.13797","-0.00020"
"117.00000","3.89703","1301.67896","0.03897","130.16789","-0.00020"
"117.50000","3.91365","1305.79541","0.03914","130.57954","-0.00019"
"118.00000","3.93052","1311.86157","0.03931","131.18616","-0.00019"
"118.50000","3.94701","1315.70752","0.03947","131.57076","-0.00018"
"119.00000","3.96371","1320.13574","0.03964","132.01358","-0.00018"
"119.50000","3.98028","1323.86365","0.03980","132.38637","-0.00018"
"120.00000","3.99706","1326.88245","0.03997","132.68825","-0.00017"
"120.50000","4.01367","1329.91931","0.04014","132.99193","-0.00018"
"121.00000","4.03049","1333.09961","0.04030","133.30997","-0.00018"
"121.50000","4.04697","1329.73157","0.04047","132.97316","-0.00018"
"122.00000","4.06371","1324.54517","0.04064","132.45451","-0.00019"
"122.50000","4.08038","1316.41211","0.04080","131.64120","-0.00019"
"123.00000","4.09702","1310.94592","0.04097","131.09459","-0.00019"
"123.50000","4.11382","1306.88855","0.04114","130.68886","-0.00019"
"124.00000","4.13027","1291.88391","0.04130","129.18839","-0.00020"
"124.50000","4.14701","1286.63379","0.04147","128.66338","-0.00020"
"125.00000","4.16361","1285.20154","0.04164","128.52016","-0.00020"
"125.50000","4.18044","1284.76758","0.04180","128.47676","-0.00020"
"126.00000","4.19701","1282.15417","0.04197","128.21542","-0.00020"
"126.50000","4.21375","1277.78662","0.04214","127.77866","-0.00020"
"127.00000","4.23034","1272.39111","0.04230","127.23911","-0.00020"
"127.50000","4.24714","1270.41455","0.04247","127.04146","-0.00020"
"128.00000","4.26371","1269.07031","0.04264","126.90703","-0.00019"
"128.50000","4.28034","1268.43848","0.04280","126.84385","-0.00019"
"129.00000","4.29716","1266.82239","0.04297","126.68224","-0.00019"
"129.50000","4.31371","1265.25891","0.04314","126.52589","-0.00019"
"130.00000","4.33033","1265.11609","0.04330","126.51161","-0.00019"
"130.50000","4.34691","1263.26514","0.04347","126.32652","-0.00018"
"131.00000","4.36379","1263.27820","0.04364","126.32782","-0.00019"
"131.50000","4.38034","1262.81433","0.04380","126.28143","-0.00019"
"132.00000","4.39705","1264.32556","0.04397","126.43256","-0.00019"
"132.50000","4.41370","1264.34143","0.04414","126.43414","-0.00019"
"133.00000","4.43033","1265.60168","0.04430","126.56017","-0.00019"
"133.50000","4.44716","1267.14087","0.04447","126.71409","-0.00019"
"134.00000","4.46371","1266.57751","0.04464","126.65775","-0.00020"
"134.50000","4.48048","1266.75769","0.04480","126.67577","-0.00020"
"135.00000","4.49695","1265.11328","0.04497","126.51133","-0.00020"
"135.50000","4.51366","1263.58118","0.04514","126.35812","-0.00020"
"136.00000","4.53031","1261.51001","0.04530","126.15100","-0.00020"
"136.50000","4.54720","1262.04932","0.04547","126.20493","-0.00020"
"137.00000","4.56364","1260.49817","0.04564","126.04982","-0.00020"
"137.50000","4.58042","1259.04199","0.04580","125.90420","-0.00019"
"138.00000","4.59701","1257.57703","0.04597","125.75771","-0.00019"
"138.50000","4.61370","1256.71814","0.04614","125.67181","-0.00018"
"139.00000","4.63053","1256.66223","0.04631","125.66622","-0.00018"
"139.50000","4.64695","1256.90283","0.04647","125.69028","-0.00018"
"140.00000","4.66380","1257.06360","0.04664","125.70636","-0.00018"
"140.50000","4.68023","1251.79321","0.04680","125.17932","-0.00018"
"141.00000","4.69698","1251.34253","0.04697","125.13425","-0.00018"
"141.50000","4.71372","1252.52502","0.04714","125.25250","-0.00018"
"142.00000","4.73050","1253.43262","0.04730","125.34326","-0.00018"
"142.50000","4.74695","1250.53918","0.04747","125.05392","-0.00019"
"143.00000","4.76374","1249.59949","0.04764","124.95995","-0.00019"
"143.50000","4.78042","1249.39490","0.04780","124.93949","-0.00020"
"144.00000","4.79708","1249.03113","0.04797","124.90311","-0.00020"
"144.50000","4.81380","1247.17004","0.04814","124.71700","-0.00020"
"145.00000","4.83020","1243.90881","0.04830","124.39088","-0.00021"
"145.50000","4.84697","1240.62915","0.04847","124.06291","-0.00021"
"146.00000","4.86361","1234.00720","0.04864","123.40072","-0.00021"
"146.50000","4.88044","1238.25562","0.04880","123.82556","-0.00021"
"147.00000","4.89704","1241.04382","0.04897","124.10439","-0.00021"
"147.50000","4.91375","1245.22974","0.04914","124.52297","-0.00021"
"148.00000","4.93035","1248.18970","0.04930","124.81897","-0.00020"
"148.50000","4.94701","1251.42139","0.04947","125.14214","-0.00020"
"149.00000","4.96381","1253.32104","0.04964","125.33211","-0.00019"
"149.50000","4.98035","1254.39709","0.04980","125.43971","-0.00019"
"150.00000","4.99702","1256.66858","0.04997","125.66685","-0.00018"
"150.50000","5.01363","1258.15613","0.05014","125.81561","-0.00018"
"151.00000","5.03051","1259.80432","0.05031","125.98043","-0.00017"
"151.50000","5.04695","1260.82410","0.05047","126.08241","-0.00017"
"152.00000","5.06381","1264.01331","0.05064","126.40133","-0.00017"
"152.50000","5.08032","1264.98279","0.05080","126.49828","-0.00017"
"153.00000","5.09713","1267.05835","0.05097","126.70583","-0.00017"
"153.50000","5.11374","1266.42078","0.05114","126.64207","-0.00018"
"154.00000","5.13030","1266.08289","0.05130","126.60829","-0.00018"
"154.50000","5.14718","1266.42151","0.05147","126.64215","-0.00019"
"155.00000","5.16366","1264.37512","0.05164","126.43752","-0.00019"
"155.50000","5.18035","1265.68958","0.05180","126.56895","-0.00020"
"156.00000","5.19697","1267.46973","0.05197","126.74697","-0.00020"
"156.50000","5.21365","1268.41479","0.05214","126.84148","-0.00020"
"157.00000","5.23033","1270.49329","0.05230","127.04933","-0.00021"
"157.50000","5.24716","1273.34583","0.05247","127.33458","-0.00021"
"158.00000","5.26369","1273.60107","0.05264","127.36011","-0.00021"
"158.50000","5.28038","1275.45264","0.05280","127.54527","-0.00021"
"159.00000","5.29704","1277.85608","0.05297","127.78561","-0.00021"
"159.50000","5.31366","1278.17761","0.05314","127.81776","-0.00021"
"160.00000","5.33054","1281.29492","0.05331","128.12949","-0.00021"
"160.50000","5.34695","1281.12830","0.05347","128.11282","-0.00020"
"161.00000","5.36372","1281.15149","0.05364","128.11514","-0.00019"
"161.50000","5.38029","1279.09912","0.05380","127.90991","-0.00019"
"162.00000","5.39707","1276.97058","0.05397","127.69706","-0.00019"
"162.50000","5.41372","1276.40881","0.05414","127.64088","-0.00018"
"163.00000","5.43044","1276.78601","0.05430","127.67860","-0.00018"
"163.50000","5.44701","1275.09106","0.05447","127.50911","-0.00018"
"164.00000","5.46369","1275.06921","0.05464","127.50692","-0.00018"
"164.50000","5.48040","1274.69324","0.05480","127.46932","-0.00018"
"165.00000","5.49704","1273.87488","0.05497","127.38749","-0.00018"
"165.50000","5.51388","1267.38940","0.05514","126.73894","-0.00018"
"166.00000","5.53024","1255.91223","0.05530","125.59122","-0.00018"
"166.50000","5.54699","1250.52820","0.05547","125.05282","-0.00019"
"167.00000","5.56367","1246.37891","0.05564","124.63789","-0.00019"
"167.50000","5.58048","1243.40637","0.05580","124.34064","-0.00020"
"168.00000","5.59701","1239.34668","0.05597","123.93467","-0.00020"
"168.50000","5.61373","1238.20728","0.05614","123.82072","-0.00020"
"169.00000","5.63032","1235.57703","0.05630","123.55770","-0.00020"
"169.50000","5.64704","1232.65356","0.05647","123.26536","-0.00020"
"170.00000","5.66382","1228.21423","0.05664","122.82143","-0.00020"
"170.50000","5.68037","1199.48950","0.05680","119.94895","-0.00020"
"171.00000","5.69704","1185.18823","0.05697","118.51882","-0.00020"
"171.50000","5.71363","1163.94714","0.05714","116.39471","-0.00019"
"172.00000","5.73038","1151.52637","0.05730","115.15263","-0.00019"
"172.50000","5.74703","1146.38855","0.05747","114.63885","-0.00019"
"173.00000","5.76377","1145.02612","0.05764","114.50261","-0.00019"
"173.50000","5.78029","1127.73706","0.05780","112.77370","-0.00018"
"174.00000","5.79712","1113.76514","0.05797","111.37651","-0.00019"
"174.50000","5.81386","1107.16516","0.05814","110.71651","-0.00019"
"175.00000","5.83031","1102.67908","0.05830","110.26791","-0.00019"
"175.50000","5.84717","1101.75989","0.05847","110.17599","-0.00019"
"176.00000","5.86362","1099.86304","0.05864","109.98631","-0.00019"
"176.50000","5.88043","1100.96606","0.05880","110.09660","-0.00020"
"177.00000","5.89696","1079.61023","0.05897","107.96102","-0.00019"
"177.50000","5.91368","1063.75659","0.05914","106.37566","-0.00020"
"178.00000","5.93034","1052.59485","0.05930","105.25948","-0.00020"
"178.50000","5.94714","1052.86938","0.05947","105.28694","-0.00020"
"179.00000","5.96364","1053.06262","0.05964","105.30626","-0.00020"
"179.50000","5.98041","1052.37012","0.05980","105.23701","-0.00020"
"180.00000","5.99711","1051.32446","0.05997","105.13245","-0.00019"
"180.50000","6.01365","1048.66809","0.06014","104.86681","-0.00019"
"181.00000","6.03041","1044.43958","0.06030","104.44395","-0.00019"
"181.50000","6.04696","1035.54187","0.06047","103.55418","-0.00019"
"182.00000","6.06362","1017.69147","0.06064","101.76915","-0.00019"
"182.50000","6.08028","1008.88348","0.06080","100.88835","-0.00019"
"183.00000","6.09709","1003.87640","0.06097","100.38764","-0.00018"
"183.50000","6.11373","999.07379","0.06114","99.90738","-0.00017"
"184.00000","6.13041","995.34058","0.06130","99.53406","-0.00017"
"184.50000","6.14701","993.70142","0.06147","99.37014","-0.00018"
"185.00000","6.16368","993.69635","0.06164","99.36964","-0.00018"
"185.50000","6.18048","993.27948","0.06180","99.32795","-0.00018"
"186.00000","6.19705","992.48840","0.06197","99.24884","-0.00018"
"186.50000","6.21372","991.64154","0.06214","99.16415","-0.00018"
"187.00000","6.23034","990.72687","0.06230","99.07269","-0.00019"
"187.50000","6.24701","989.69647","0.06247","98.96965","-0.00019"
"188.00000","6.26364","987.84296","0.06264","98.78429","-0.00020"
"188.50000","6.28054","987.76080","0.06281","98.77608","-0.00020"
"189.00000","6.29705","984.59546","0.06297","98.45955","-0.00021"
"189.50000","6.31371","983.96625","0.06314","98.39662","-0.00021"
"190.00000","6.33034","980.58423","0.06330","98.05843","-0.00021"
"190.50000","6.34702","974.46655","0.06347","97.44666","-0.00021"
"191.00000","6.36388","971.39758","0.06364","97.13976","-0.00021"
"191.50000","6.38033","965.31061","0.06380","96.53106","-0.00021"
"192.00000","6.39699","960.80780","0.06397","96.08078","-0.00021"
"192.50000","6.41363","952.96045","0.06414","95.29604","-0.00020"
"193.00000","6.43037","943.44757","0.06430","94.34476","-0.00019"
"193.50000","6.44701","936.26788","0.06447","93.62679","-0.00019"
"194.00000","6.46378","918.06073","0.06464","91.80608","-0.00019"
"194.50000","6.48024","907.57983","0.06480","90.75798","-0.00018"
"195.00000","6.49712","899.68585","0.06497","89.96858","-0.00018"
"195.50000","6.51377","896.31555","0.06514","89.63155","-0.00017"
"196.00000","6.53040","893.81335","0.06530","89.38133","-0.00017"
"196.50000","6.54712","892.03558","0.06547","89.20356","-0.00017"
"197.00000","6.56358","885.73444","0.06564","88.57344","-0.00017"
"197.50000","6.58037","881.23663","0.06580","88.12366","-0.00018"
"198.00000","6.59706","875.79077","0.06597","87.57908","-0.00018"
"198.50000","6.61369","847.77802","0.06614","84.77780","-0.00018"
"199.00000","6.63036","836.05518","0.06630","83.60551","-0.00019"
"199.50000","6.64713","828.53864","0.06647","82.85387","-0.00019"
"200.00000","6.66374","824.94568","0.06664","82.49457","-0.00020"
"200.50000","6.68042","822.70441","0.06680","82.27044","-0.00020"
"201.00000","6.69707","822.45142","0.06697","82.24514","-0.00020"
"201.50000","6.71370","821.26447","0.06714","82.12645","-0.00020"
"202.00000","6.73040","819.88098","0.06730","81.98810","-0.00021"
"202.50000","6.74688","818.30231","0.06747","81.83023","-0.00021"
"203.00000","6.76370","811.68610","0.06764","81.16861","-0.00021"
"203.50000","6.78030","800.82428","0.06780","80.08243","-0.00020"
"204.00000","6.79712","797.44049","0.06797","79.74405","-0.00020"
"204.50000","6.81367","792.78674","0.06814","79.27867","-0.00020"
"205.00000","6.83045","791.36316","0.06830","79.13631","-0.00019"
"205.50000","6.84705","787.39636","0.06847","78.73964","-0.00019"
"206.00000","6.86370","787.08667","0.06864","78.70866","-0.00019"
"206.50000","6.88045","789.29968","0.06880","78.92997","-0.00019"
"207.00000","6.89705","789.08594","0.06897","78.90859","-0.00018"
"207.50000","6.91367","790.08630","0.06914","79.00863","-0.00018"
"208.00000","6.93026","790.88208","0.06930","79.08821","-0.00018"
"208.50000","6.94708","787.53412","0.06947","78.75341","-0.00018"
"209.00000","6.96367","782.54016","0.06964","78.25401","-0.00018"
"209.50000","6.98051","779.45398","0.06981","77.94540","-0.00018"
"210.00000","6.99699","776.98413","0.06997","77.69841","-0.00018"
"210.50000","7.01376","776.86572","0.07014","77.68657","-0.00019"
"211.00000","7.03045","775.90869","0.07030","77.59087","-0.00019"
"211.50000","7.04696","775.15881","0.07047","77.51588","-0.00019"
"212.00000","7.06387","775.47955","0.07064","77.54796","-0.00019"
"212.50000","7.08034","774.85449","0.07080","77.48545","-0.00019"
"213.00000","7.09696","771.82941","0.07097","77.18294","-0.00020"
"213.50000","7.11363","754.01129","0.07114","75.40113","-0.00019"
"214.00000","7.13044","732.93512","0.07130","73.29351","-0.00019"
"214.50000","7.14704","721.03406","0.07147","72.10341","-0.00019"
"215.00000","7.16384","712.68280","0.07164","71.26828","-0.00019"
"215.50000","7.18026","703.27490","0.07180","70.32749","-0.00019"
"216.00000","7.19699","695.20886","0.07197","69.52089","-0.00018"
"216.50000","7.21378","689.25366","0.07214","68.92537","-0.00018"
"217.00000","7.23035","685.25647","0.07230","68.52565","-0.00018"
"217.50000","7.24707","681.83691","0.07247","68.18369","-0.00018"
"218.00000","7.26358","675.34900","0.07264","67.53490","-0.00019"
"218.50000","7.28034","669.44568","0.07280","66.94456","-0.00018"
"219.00000","7.29701","642.05096","0.07297","64.20509","-0.00018"
"219.50000","7.31382","620.52203","0.07314","62.05220","-0.00019"
"220.00000","7.33033","611.26831","0.07330","61.12683","-0.00020"
"220.50000","7.34703","608.04449","0.07347","60.80445","-0.00020"
"221.00000","7.36369","606.87579","0.07364","60.68758","-0.00020"
"221.50000","7.38047","607.84778","0.07380","60.78478","-0.00020"
"222.00000","7.39708","607.26251","0.07397","60.72625","-0.00021"
"222.50000","7.41365","606.44318","0.07414","60.64432","-0.00021"
"223.00000","7.43040","607.80316","0.07430","60.78032","-0.00021"
"223.50000","7.44699","607.14569","0.07447","60.71457","-0.00021"
"224.00000","7.46373","606.85760","0.07464","60.68576","-0.00021"
"224.50000","7.48031","604.73828","0.07480","60.47383","-0.00020"
"225.00000","7.49716","603.95142","0.07497","60.39514","-0.00020"
"225.50000","7.51367","597.48389","0.07514","59.74839","-0.00019"
"226.00000","7.53036","586.89404","0.07530","58.68940","-0.00019"
"226.50000","7.54708","582.27545","0.07547","58.22755","-0.00018"
"227.00000","7.56371","467.47220","0.07564","46.74722","-0.00018"
"227.50000","7.58046","446.86639","0.07580","44.68664","-0.00018"
"228.00000","7.59701","437.74463","0.07597","43.77446","-0.00017"
"228.50000","7.61374","435.27271","0.07614","43.52727","-0.00017"
"229.00000","7.63032","434.28769","0.07630","43.42877","-0.00017"
"229.50000","7.64705","434.60223","0.07647","43.46022","-0.00018"
"230.00000","7.66364","436.52463","0.07664","43.65246","-0.00018"
"230.50000","7.68044","440.23761","0.07680","44.02376","-0.00018"
"231.00000","7.69697","442.61884","0.07697","44.26188","-0.00019"
"231.50000","7.71371","446.35455","0.07714","44.63546","-0.00019"
"232.00000","7.73049","447.76373","0.07730","44.77637","-0.00019"
"232.50000","7.74703","448.40472","0.07747","44.84047","-0.00020"
"233.00000","7.76378","449.44501","0.07764","44.94450","-0.00021"
"233.50000","7.78026","449.66364","0.07780","44.96636","-0.00021"
"234.00000","7.79709","450.36884","0.07797","45.03688","-0.00021"
"234.50000","7.81364","450.63034","0.07814","45.06303","-0.00021"
"235.00000","7.83037","452.52634","0.07830","45.25263","-0.00021"
"235.50000","7.84701","453.81705","0.07847","45.38171","-0.00021"
"236.00000","7.86383","455.94080","0.07864","45.59408","-0.00020"
"236.50000","7.88031","456.62634","0.07880","45.66264","-0.00020"
"237.00000","7.89701","458.62314","0.07897","45.86231","-0.00019"
"237.50000","7.91382","461.16324","0.07914","46.11633","-0.00019"
"238.00000","7.93041","460.32416","0.07930","46.03242","-0.00018"
"238.50000","7.94704","455.19131","0.07947","45.51913","-0.00018"
"239.00000","7.96352","449.57050","0.07964","44.95705","-0.00018"
"239.50000","7.98032","447.22702","0.07980","44.72270","-0.00018"
"240.00000","7.99700","445.86951","0.07997","44.58695","-0.00018"
"240.50000","8.01381","445.36005","0.08014","44.53600","-0.00018"
"241.00000","8.03036","441.67188","0.08030","44.16719","-0.00017"
"241.50000","8.04704","438.64166","0.08047","43.86417","-0.00018"
"242.00000","8.06375","434.95880","0.08064","43.49588","-0.00018"
"242.50000","8.08033","426.57739","0.08080","42.65774","-0.00018"
"243.00000","8.09717","420.45261","0.08097","42.04526","-0.00019"
"243.50000","8.11364","412.16327","0.08114","41.21633","-0.00019"
"244.00000","8.13031","405.03036","0.08130","40.50304","-0.00020"
"244.50000","8.14698","398.65448","0.08147","39.86545","-0.00020"
"245.00000","8.16382","394.82214","0.08164","39.48222","-0.00020"
"245.50000","8.18032","357.19040","0.08180","35.71904","-0.00020"
"246.00000","8.19714","349.26355","0.08197","34.92635","-0.00020"
"246.50000","8.21365","343.92468","0.08214","34.39247","-0.00020"
"247.00000","8.23042","343.69833","0.08230","34.36983","-0.00020"
"247.50000","8.24713","340.19681","0.08247","34.01968","-0.00020"
"248.00000","8.26363","338.29337","0.08264","33.82934","-0.00019"
"248.50000","8.28053","319.53360","0.08281","31.95336","-0.00019"
"249.00000","8.29696","309.30682","0.08297","30.93068","-0.00019"
"249.50000","8.31364","301.76993","0.08314","30.17699","-0.00019"
"250.00000","8.33035","297.52313","0.08330","29.75231","-0.00019"
"250.50000","8.34708","295.42224","0.08347","29.54222","-0.00018"
"251.00000","8.36366","292.10309","0.08364","29.21031","-0.00018"
"251.50000","8.38043","290.61115","0.08380","29.06112","-0.00019"
"252.00000","8.39703","289.38733","0.08397","28.93873","-0.00019"
"252.50000","8.41371","286.17209","0.08414","28.61721","-0.00018"
"253.00000","8.43045","284.40762","0.08430","28.44076","-0.00019"
"253.50000","8.44696","282.59311","0.08447","28.25931","-0.00019"
"254.00000","8.46377","279.73129","0.08464","27.97313","-0.00019"
"254.50000","8.48026","274.13113","0.08480","27.41311","-0.00020"
"255.00000","8.49706","270.65286","0.08497","27.06529","-0.00020"
"255.50000","8.51367","266.76559","0.08514","26.67656","-0.00020"
"256.00000","8.53043","263.46167","0.08530","26.34617","-0.00020"
"256.50000","8.54703","258.31836","0.08547","25.83184","-0.00020"
"257.00000","8.56372","253.45847","0.08564","25.34585","-0.00020"
"257.50000","8.58039","250.69888","0.08580","25.06989","-0.00020"
"258.00000","8.59703","248.89230","0.08597","24.88923","-0.00019"
"258.50000","8.61376","248.45650","0.08614","24.84565","-0.00020"
"259.00000","8.63036","247.27704","0.08630","24.72770","-0.00019"
"259.50000","8.64714","246.14981","0.08647","24.61498","-0.00018"
"260.00000","8.66357","244.79420","0.08664","24.47942","-0.00018"
"260.50000","8.68035","244.40605","0.08680","24.44061","-0.00018"
"261.00000","8.69700","243.78889","0.08697","24.37889","-0.00018"
"261.50000","8.71386","242.72650","0.08714","24.27265","-0.00018"
"262.00000","8.73038","239.74124","0.08730","23.97412","-0.00018"
"262.50000","8.74700","239.38008","0.08747","23.93801","-0.00018"
"263.00000","8.76374","239.12601","0.08764","23.91260","-0.00018"
"263.50000","8.78038","238.52551","0.08780","23.85255","-0.00019"
"264.00000","8.79711","237.75246","0.08797","23.77525","-0.00019"
"264.50000","8.81368","235.24237","0.08814","23.52424","-0.00019"
"265.00000","8.83031","234.62363","0.08830","23.46236","-0.00020"
"265.50000","8.84697","236.72148","0.08847","23.67215","-0.00020"
"266.00000","8.86376","238.29597","0.08864","23.82960","-0.00021"
"266.50000","8.88038","239.69414","0.08880","23.96941","-0.00020"
"267.00000","8.89709","241.05669","0.08897","24.10567","-0.00021"
"267.50000","8.91364","240.88188","0.08914","24.08819","-0.00020"
"268.00000","8.93036","241.72380","0.08930","24.17238","-0.00020"
"268.50000","8.94726","241.00221","0.08947","24.10022","-0.00019"
"269.00000","8.96362","239.93712","0.08964","23.99371","-0.00019"
"269.50000","8.98043","240.47925","0.08980","24.04792","-0.00019"
"270.00000","8.99693","239.80029","0.08997","23.98003","-0.00018"
"270.50000","9.01371","239.64413","0.09014","23.96441","-0.00018"
"271.00000","9.03035","236.24159","0.09030","23.62416","-0.00018"
"271.50000","9.04711","234.90970","0.09047","23.49097","-0.00017"
"272.00000","9.06369","232.32530","0.09064","23.23253","-0.00017"
"272.50000","9.08041","221.25531","0.09080","22.12553","-0.00017"
"273.00000","9.09699","217.82501","0.09097","21.78250","-0.00017"
"273.50000","9.11370","219.02074","0.09114","21.90207","-0.00017"
"274.00000","9.13053","219.37170","0.09131","21.93717","-0.00017"
"274.50000","9.14696","219.66016","0.09147","21.96601","-0.00018"
"275.00000","9.16365","218.98474","0.09164","21.89847","-0.00019"
"275.50000","9.18032","217.83643","0.09180","21.78364","-0.00019"
"276.00000","9.19705","212.63002","0.09197","21.26300","-0.00019"
"276.50000","9.21369","210.20479","0.09214","21.02048","-0.00019"
"277.00000","9.23044","209.77077","0.09230","20.97708","-0.00020"
"277.50000","9.24702","208.50217","0.09247","20.85022","-0.00020"
"278.00000","9.26370","207.44060","0.09264","20.74406","-0.00021"
"278.50000","9.28040","196.94362","0.09280","19.69436","-0.00021"
"279.00000","9.29702","182.84050","0.09297","18.28405","-0.00020"
"279.50000","9.31380","177.35883","0.09314","17.73588","-0.00020"
"280.00000","9.33032","174.60492","0.09330","17.46049","-0.00020"
"280.50000","9.34702","173.44771","0.09347","17.34477","-0.00019"
"281.00000","9.36368","119.10556","0.09364","11.91056","-0.00019"
"281.50000","9.38040","116.07188","0.09380","11.60719","-0.00019"
"282.00000","9.39697","116.55111","0.09397","11.65511","-0.00019"
"282.50000","9.41385","120.31578","0.09414","12.03158","-0.00018"
"283.00000","9.43047","122.44135","0.09430","12.24413","-0.00018"
"283.50000","9.44700","115.22504","0.09447","11.52250","-0.00018"
"284.00000","9.46377","112.02080","0.09464","11.20208","-0.00018"
"284.50000","9.48034","112.97951","0.09480","11.29795","-0.00018"
"285.00000","9.49720","115.95929","0.09497","11.59593","-0.00018"
"285.50000","9.51361","118.05453","0.09514","11.80545","-0.00018"
"286.00000","9.53031","120.59792","0.09530","12.05979","-0.00019"
"286.50000","9.54698","121.59188","0.09547","12.15919","-0.00019"
"287.00000","9.56379","121.35101","0.09564","12.13510","-0.00019"
"287.50000","9.58033","120.30726","0.09580","12.03073","-0.00019"
"288.00000","9.59709","116.15610","0.09597","11.61561","-0.00020"
"288.50000","9.61366","112.95267","0.09614","11.29527","-0.00020"
"289.00000","9.63036","108.60989","0.09630","10.86099","-0.00020"
"289.50000","9.64712","103.87761","0.09647","10.38776","-0.00020"
"290.00000","9.66373","103.64413","0.09664","10.36441","-0.00020"
"290.50000","9.68035","104.35539","0.09680","10.43554","-0.00020"
"291.00000","9.69690","106.48414","0.09697","10.64841","-0.00019"
"291.50000","9.71368","109.42331","0.09714","10.94233","-0.00019"
"292.00000","9.73042","108.37785","0.09730","10.83778","-0.00019"
"292.50000","9.74709","107.93599","0.09747","10.79360","-0.00019"
"293.00000","9.76365","107.34187","0.09764","10.73419","-0.00019"
"293.50000","9.78040","108.25211","0.09780","10.82521","-0.00018"
"294.00000","9.79709","108.78814","0.09797","10.87881","-0.00018"
"294.50000","9.81373","109.34810","0.09814","10.93481","-0.00017"
"295.00000","9.83043","106.27102","0.09830","10.62710","-0.00018"
"295.50000","9.84701","104.28920","0.09847","10.42892","-0.00018"
"296.00000","9.86369","103.76730","0.09864","10.37673","-0.00018"
"296.50000","9.88027","103.46248","0.09880","10.34625","-0.00018"
"297.00000","9.89712","104.45136","0.09897","10.44514","-0.00019"
"297.50000","9.91369","104.37234","0.09914","10.43723","-0.00019"
"298.00000","9.93046","103.93888","0.09930","10.39389","-0.00019"
"298.50000","9.94697","102.85989","0.09947","10.28599","-0.00020"
"299.00000","9.96372","104.84837","0.09964","10.48484","-0.00020"
"299.50000","9.98045","106.50705","0.09980","10.65071","-0.00020"
"300.00000","9.99702","108.25897","0.09997","10.82590","-0.00020"
"300.50000","10.01376","109.06643","0.10014","10.90664","-0.00020"
"301.00000","10.03031","107.74613","0.10030","10.77461","-0.00020"
"301.50000","10.04699","104.90517","0.10047","10.49052","-0.00020"
"302.00000","10.06365","100.94479","0.10064","10.09448","-0.00019"
"302.50000","10.08045","94.04332","0.10080","9.40433","-0.00019"
"303.00000","10.09698","87.16151","0.10097","8.71615","-0.00019"
"303.50000","10.11378","83.09083","0.10114","8.30908","-0.00018"
"304.00000","10.13036","80.07153","0.10130","8.00715","-0.00018"
"304.50000","10.14708","79.75848","0.10147","7.97585","-0.00018"
"305.00000","10.16384","80.74626","0.10164","8.07463","-0.00018"
"305.50000","10.18027","81.52162","0.10180","8.15216","-0.00018"
"306.00000","10.19712","84.27422","0.10197","8.42742","-0.00018"
"306.50000","10.21367","86.15190","0.10214","8.61519","-0.00018"
"307.00000","10.23031","88.17899","0.10230","8.81790","-0.00019"
"307.50000","10.24701","90.32679","0.10247","9.03268","-0.00019"
"308.00000","10.26380","93.79099","0.10264","9.37910","-0.00019"
"308.50000","10.28039","95.78799","0.10280","9.57880","-0.00019"
"309.00000","10.29712","98.06120","0.10297","9.80612","-0.00020"
"309.50000","10.31366","99.07211","0.10314","9.90721","-0.00020"
"310.00000","10.33036","100.67651","0.10330","10.06765","-0.00020"
"310.50000","10.34715","102.00724","0.10347","10.20072","-0.00021"
"311.00000","10.36362","101.14531","0.10364","10.11453","-0.00021"
"311.50000","10.38036","99.00577","0.10380","9.90058","-0.00021"
"312.00000","10.39691","91.31100","0.10397","9.13110","-0.00020"
"312.50000","10.41374","87.15865","0.10414","8.71586","-0.00020"
"313.00000","10.43035","14.23892","0.10430","1.42389","-0.00020"
"313.50000","10.44718","13.01757","0.10447","1.30176","-0.00019"
"314.00000","10.46364","14.36333","0.10464","1.43633","-0.00019"
"314.50000","10.48031","18.48272","0.10480","1.84827","-0.00018"
"315.00000","10.49706","22.87837","0.10497","2.28784","-0.00018"
"315.50000","10.51377","27.14883","0.10514","2.71488","-0.00018"
"316.00000","10.53040","26.58673","0.10530","2.65867","-0.00018"
"316.50000","10.54695","19.23527","0.10547","1.92353","-0.00018"
"317.00000","10.56374","15.25070","0.10564","1.52507","-0.00018"
"317.50000","10.58032","14.54528","0.10580","1.45453","-0.00018"
"318.00000","10.59717","16.69719","0.10597","1.66972","-0.00020"
"318.50000","10.61366","12.90606","0.10614","1.29061","-0.00019"
"319.00000","10.63049","12.18869","0.10630","1.21887","-0.00019"
"319.50000","10.64701","9.51857","0.10647","0.95186","-0.00019"
"320.00000","10.66363","5.86826","0.10664","0.58683","-0.00020"
"320.50000","10.68053","4.27688","0.10681","0.42769","-0.00020"
"321.00000","10.69702","1.63115","0.10697","0.16312","-0.00020"
"321.50000","10.71371","1.02501","0.10714","0.10250","-0.00021"
"322.00000","10.73029","0.65966","0.10730","0.06597","-0.00021"
"322.50000","10.74704","0.28760","0.10747","0.02876","-0.00021"
"323.00000","10.76368","-0.50028","0.10764","-0.05003","-0.00020"
"323.50000","10.78047","-1.01485","0.10780","-0.10149","-0.00019"
"324.00000","10.79691","-3.36769","0.10797","-0.33677","-0.00019"
"324.50000","10.81374","-3.70535","0.10814","-0.37053","-0.00019"
"324.65600","10.81890","-4.83344","0.10819","-0.48334","-0.00018"