File: Tension/Section_1_Group_4/control/Sample_11_0_days_tension.is_tens_RawData/Specimen_RawData_1.csv
Time,Extension,Load,Tensile strain (Extension),Axial Video,Tensile stress,Transverse Video
(s),(mm),(N),(mm/mm),(mm/mm),(MPa),(mm/mm)
"0.00000","0.00000","-0.44077","0.00000","0.00001","-0.04408","0.00000"
"0.20000","0.00179","7.64100","0.00002","0.00001","0.76410","0.00002"
"0.40000","0.01060","53.15013","0.00011","0.00003","5.31501","0.00000"
"0.60000","0.01706","85.61526","0.00017","0.00011","8.56153","-0.00002"
"0.80000","0.02387","118.85344","0.00024","0.00013","11.88534","-0.00007"
"1.00000","0.03049","150.52106","0.00030","0.00018","15.05211","-0.00001"
"1.20000","0.03728","182.12178","0.00037","0.00022","18.21218","0.00000"
"1.40000","0.04397","212.08818","0.00044","0.00026","21.20882","0.00000"
"1.60000","0.05050","240.37082","0.00051","0.00030","24.03708","0.00000"
"1.80000","0.05723","268.91745","0.00057","0.00033","26.89174","-0.00006"
"2.00000","0.06374","295.23715","0.00064","0.00037","29.52372","-0.00007"
"2.20000","0.07062","322.43588","0.00071","0.00041","32.24359","-0.00010"
"2.40000","0.07711","346.66299","0.00077","0.00045","34.66630","-0.00010"
"2.60000","0.08387","371.24414","0.00084","0.00049","37.12441","-0.00011"
"2.80000","0.09066","395.21829","0.00091","0.00053","39.52183","-0.00006"
"3.00000","0.09718","416.75870","0.00097","0.00056","41.67587","-0.00007"
"3.20000","0.10391","438.84964","0.00104","0.00060","43.88496","-0.00008"
"3.40000","0.11050","459.51181","0.00111","0.00063","45.95118","-0.00013"
"3.60000","0.11730","480.62378","0.00117","0.00066","48.06238","-0.00013"
"3.80000","0.12384","500.10831","0.00124","0.00069","50.01083","-0.00013"
"4.00000","0.13050","519.66522","0.00131","0.00072","51.96652","-0.00013"
"4.20000","0.13723","539.35583","0.00137","0.00075","53.93559","-0.00013"
"4.40000","0.14384","557.63098","0.00144","0.00078","55.76310","-0.00016"
"4.60000","0.15062","576.64404","0.00151","0.00081","57.66441","-0.00020"
"4.80000","0.15720","594.43793","0.00157","0.00083","59.44379","-0.00020"
"5.00000","0.16385","612.20123","0.00164","0.00084","61.22012","-0.00020"
"5.20000","0.17063","630.65546","0.00171","0.00087","63.06554","-0.00014"
"5.40000","0.17722","647.69836","0.00177","0.00090","64.76984","-0.00013"
"5.60000","0.18383","664.54602","0.00184","0.00093","66.45461","-0.00020"
"5.80000","0.19047","681.11310","0.00190","0.00096","68.11131","-0.00026"
"6.00000","0.19728","698.55188","0.00197","0.00099","69.85519","-0.00020"
"6.20000","0.20391","715.00604","0.00204","0.00101","71.50060","-0.00013"
"6.40000","0.21046","730.70355","0.00210","0.00103","73.07036","-0.00008"
"6.60000","0.21733","747.92389","0.00217","0.00106","74.79239","-0.00013"
"6.80000","0.22381","763.05676","0.00224","0.00108","76.30568","-0.00007"
"7.00000","0.23061","779.54022","0.00231","0.00111","77.95403","-0.00007"
"7.20000","0.23721","794.81732","0.00237","0.00114","79.48174","-0.00007"
"7.40000","0.24386","810.19073","0.00244","0.00116","81.01907","-0.00005"
"7.60000","0.25055","826.38153","0.00251","0.00118","82.63815","-0.00007"
"7.80000","0.25715","841.44788","0.00257","0.00121","84.14479","-0.00007"
"8.00000","0.26394","857.27637","0.00264","0.00123","85.72764","-0.00010"
"8.20000","0.27044","871.50763","0.00270","0.00126","87.15076","-0.00007"
"8.40000","0.27732","887.56659","0.00277","0.00128","88.75666","-0.00001"
"8.60000","0.28386","901.93665","0.00284","0.00131","90.19366","-0.00001"
"8.80000","0.29049","916.26074","0.00290","0.00133","91.62608","-0.00006"
"9.00000","0.29735","931.74493","0.00297","0.00136","93.17449","-0.00006"
"9.20000","0.30380","944.97327","0.00304","0.00138","94.49733","-0.00007"
"9.40000","0.31051","959.20795","0.00311","0.00140","95.92079","-0.00007"
"9.60000","0.31713","972.98578","0.00317","0.00142","97.29858","0.00005"
"9.80000","0.32403","988.18726","0.00324","0.00145","98.81873","0.00007"
"10.00000","0.33052","1001.30774","0.00331","0.00146","100.13078","0.00013"
"10.20000","0.33719","1014.64984","0.00337","0.00149","101.46498","0.00013"
"10.40000","0.34393","1028.61230","0.00344","0.00150","102.86123","0.00015"
"10.60000","0.35045","1040.83337","0.00350","0.00152","104.08334","0.00013"
"10.80000","0.35740","1054.90686","0.00357","0.00154","105.49068","0.00007"
"11.00000","0.36383","1066.35254","0.00364","0.00157","106.63525","0.00006"
"11.20000","0.37051","1078.84448","0.00371","0.00158","107.88445","0.00001"
"11.40000","0.37726","1091.75671","0.00377","0.00161","109.17567","0.00001"
"11.60000","0.38391","1103.60181","0.00384","0.00163","110.36018","0.00000"
"11.80000","0.39050","1114.91760","0.00390","0.00164","111.49176","0.00000"
"12.00000","0.39715","1126.25598","0.00397","0.00166","112.62560","0.00000"
"12.20000","0.40396","1138.10034","0.00404","0.00167","113.81004","0.00013"
"12.40000","0.41056","1149.11670","0.00411","0.00168","114.91167","0.00019"
"12.60000","0.41721","1160.69348","0.00417","0.00170","116.06935","0.00020"
"12.80000","0.42397","1172.75745","0.00424","0.00172","117.27574","0.00020"
"13.00000","0.43049","1183.54517","0.00430","0.00174","118.35452","0.00020"
"13.20000","0.43722","1195.47620","0.00437","0.00177","119.54762","0.00014"
"13.40000","0.44391","1207.38721","0.00444","0.00179","120.73872","0.00013"
"13.60000","0.45052","1218.46179","0.00451","0.00181","121.84618","0.00007"
"13.80000","0.45726","1230.55420","0.00457","0.00182","123.05542","0.00007"
"14.00000","0.46385","1241.59021","0.00464","0.00184","124.15902","0.00007"
"14.20000","0.47057","1253.40723","0.00471","0.00186","125.34072","0.00013"
"14.40000","0.47716","1264.22095","0.00477","0.00188","126.42210","0.00013"
"14.60000","0.48402","1275.81079","0.00484","0.00189","127.58108","0.00013"
"14.80000","0.49055","1285.58972","0.00491","0.00190","128.55898","0.00007"
"15.00000","0.49716","1295.34058","0.00497","0.00191","129.53406","0.00007"
"15.20000","0.50405","1306.52930","0.00504","0.00192","130.65292","0.00007"
"15.40000","0.51046","1315.06152","0.00510","0.00194","131.50615","0.00007"
"15.60000","0.51716","1324.66992","0.00517","0.00195","132.46700","0.00012"
"15.80000","0.52378","1334.13611","0.00524","0.00197","133.41360","0.00008"
"16.00000","0.53064","1344.47119","0.00531","0.00199","134.44711","0.00007"
"16.20000","0.53731","1354.38293","0.00537","0.00201","135.43829","0.00000"
"16.40000","0.54391","1364.17761","0.00544","0.00203","136.41776","0.00004"
"16.60000","0.55061","1374.05420","0.00551","0.00204","137.40543","0.00004"
"16.80000","0.55713","1382.78613","0.00557","0.00206","138.27861","0.00000"
"17.00000","0.56399","1393.16162","0.00564","0.00207","139.31616","0.00000"
"17.20000","0.57047","1400.95898","0.00570","0.00209","140.09590","0.00000"
"17.40000","0.57715","1409.37061","0.00577","0.00210","140.93706","0.00000"
"17.60000","0.58394","1418.62280","0.00584","0.00212","141.86227","0.00003"
"17.80000","0.59054","1426.74268","0.00591","0.00212","142.67427","0.00007"
"18.00000","0.59726","1434.80591","0.00597","0.00214","143.48059","0.00006"
"18.20000","0.60385","1441.90833","0.00604","0.00215","144.19083","0.00007"
"18.40000","0.61073","1450.37891","0.00611","0.00216","145.03789","0.00007"
"18.60000","0.61720","1457.07739","0.00617","0.00218","145.70773","0.00007"
"18.80000","0.62388","1464.90125","0.00624","0.00219","146.49013","0.00000"
"19.00000","0.63058","1472.08911","0.00631","0.00221","147.20891","0.00000"
"19.20000","0.63717","1478.33643","0.00637","0.00221","147.83365","0.00000"
"19.40000","0.64387","1485.20752","0.00644","0.00222","148.52075","0.00000"
"19.60000","0.65054","1492.00977","0.00651","0.00224","149.20097","0.00000"
"19.80000","0.65724","1498.48206","0.00657","0.00225","149.84821","0.00001"
"20.00000","0.66402","1504.98438","0.00664","0.00226","150.49844","0.00000"
"20.20000","0.67058","1510.05933","0.00671","0.00228","151.00594","0.00003"
"20.40000","0.67722","1515.07166","0.00677","0.00229","151.50717","0.00007"
"20.60000","0.68383","1518.28894","0.00684","0.00230","151.82889","0.00003"
"20.80000","0.69061","1521.98584","0.00691","0.00231","152.19858","0.00000"
"21.00000","0.69720","1525.77209","0.00697","0.00231","152.57721","0.00000"
"21.20000","0.70378","1530.53650","0.00704","0.00232","153.05365","0.00000"
"21.40000","0.71067","1537.72961","0.00711","0.00233","153.77296","0.00003"
"21.60000","0.71722","1542.48767","0.00717","0.00234","154.24876","0.00011"
"21.80000","0.72399","1548.60815","0.00724","0.00234","154.86081","0.00002"
"22.00000","0.73057","1553.10486","0.00731","0.00235","155.31049","0.00007"
"22.20000","0.73729","1555.91943","0.00737","0.00236","155.59195","0.00007"
"22.40000","0.74397","1558.84973","0.00744","0.00236","155.88498","0.00007"
"22.60000","0.75049","1561.27881","0.00750","0.00238","156.12788","0.00007"
"22.80000","0.75724","1564.20251","0.00757","0.00239","156.42026","0.00001"
"23.00000","0.76372","1564.39148","0.00764","0.00238","156.43915","0.00000"
"23.20000","0.77066","1567.03906","0.00771","0.00239","156.70390","-0.00004"
"23.40000","0.77725","1570.24036","0.00777","0.00240","157.02403","-0.00007"
"23.60000","0.78398","1575.04529","0.00784","0.00241","157.50453","-0.00007"
"23.80000","0.79070","1580.58594","0.00791","0.00243","158.05859","-0.00005"
"24.00000","0.79723","1584.99084","0.00797","0.00244","158.49908","-0.00007"
"24.20000","0.80387","1589.54785","0.00804","0.00244","158.95479","-0.00009"
"24.40000","0.81044","1593.16565","0.00810","0.00245","159.31656","-0.00013"
"24.60000","0.81730","1597.78943","0.00817","0.00246","159.77895","-0.00013"
"24.80000","0.82382","1601.27612","0.00824","0.00246","160.12761","-0.00014"
"25.00000","0.83052","1606.64673","0.00831","0.00247","160.66467","-0.00006"
"25.20000","0.83735","1612.67578","0.00837","0.00247","161.26758","-0.00007"
"25.40000","0.84390","1616.38501","0.00844","0.00248","161.63850","-0.00007"
"25.60000","0.85070","1621.71387","0.00851","0.00249","162.17139","-0.00007"
"25.80000","0.85721","1624.97876","0.00857","0.00250","162.49788","-0.00007"
"26.00000","0.86389","1629.21460","0.00864","0.00251","162.92146","-0.00007"
"26.20000","0.87052","1632.31897","0.00871","0.00252","163.23190","-0.00007"
"26.40000","0.87720","1636.48877","0.00877","0.00252","163.64888","-0.00009"
"26.60000","0.88387","1640.88647","0.00884","0.00252","164.08865","-0.00013"
"26.80000","0.89050","1645.40051","0.00891","0.00252","164.54005","-0.00013"
"27.00000","0.89735","1650.19519","0.00897","0.00253","165.01952","-0.00014"
"27.20000","0.90398","1653.48926","0.00904","0.00255","165.34892","-0.00013"
"27.40000","0.91056","1655.33289","0.00911","0.00256","165.53329","-0.00013"
"27.60000","0.91731","1657.86218","0.00917","0.00256","165.78622","-0.00013"
"27.80000","0.92385","1659.34949","0.00924","0.00256","165.93495","-0.00013"
"28.00000","0.93049","1662.81409","0.00930","0.00256","166.28140","-0.00018"
"28.20000","0.93719","1668.57544","0.00937","0.00258","166.85754","-0.00015"
"28.40000","0.94391","1674.86035","0.00944","0.00259","167.48604","-0.00018"
"28.60000","0.95058","1680.96106","0.00951","0.00260","168.09610","-0.00014"
"28.80000","0.95721","1687.65564","0.00957","0.00261","168.76556","-0.00016"
"29.00000","0.96405","1695.76050","0.00964","0.00261","169.57605","-0.00013"
"29.20000","0.97051","1702.46851","0.00971","0.00262","170.24686","-0.00007"
"29.40000","0.97731","1710.30811","0.00977","0.00263","171.03081","-0.00007"
"29.60000","0.98387","1717.68054","0.00984","0.00265","171.76805","0.00000"
"29.80000","0.99050","1724.29480","0.00990","0.00265","172.42947","-0.00001"
"30.00000","0.99731","1729.39380","0.00997","0.00267","172.93938","-0.00007"
"30.20000","1.00381","1730.22839","0.01004","0.00267","173.02284","-0.00007"
"30.40000","1.01053","1733.26697","0.01011","0.00268","173.32669","0.00000"
"30.60000","1.01721","1735.32983","0.01017","0.00268","173.53299","0.00000"
"30.80000","1.02409","1735.59265","0.01024","0.00268","173.55927","0.00000"
"31.00000","1.03058","1735.31702","0.01031","0.00269","173.53171","0.00000"
"31.20000","1.03722","1737.09241","0.01037","0.00268","173.70924","0.00000"
"31.40000","1.04395","1741.73474","0.01044","0.00269","174.17348","0.00002"
"31.60000","1.05041","1745.50171","0.01050","0.00270","174.55017","0.00000"
"31.80000","1.05725","1752.29834","0.01057","0.00270","175.22983","0.00000"
"32.00000","1.06382","1757.53870","0.01064","0.00272","175.75388","-0.00006"
"32.20000","1.07060","1762.80444","0.01071","0.00273","176.28044","0.00000"
"32.40000","1.07732","1768.73767","0.01077","0.00273","176.87376","0.00000"
"32.60000","1.08396","1775.18506","0.01084","0.00274","177.51851","0.00000"
"32.80000","1.09058","1781.04932","0.01091","0.00274","178.10493","-0.00003"
"33.00000","1.09713","1786.79260","0.01097","0.00275","178.67926","-0.00007"
"33.20000","1.10398","1793.48547","0.01104","0.00277","179.34854","-0.00006"
"33.40000","1.11053","1795.74829","0.01111","0.00276","179.57483","-0.00007"
"33.60000","1.11716","1796.35083","0.01117","0.00278","179.63509","-0.00007"
"33.80000","1.12397","1796.81177","0.01124","0.00278","179.68118","-0.00007"
"34.00000","1.13054","1796.11011","0.01131","0.00278","179.61101","-0.00007"
"34.20000","1.13727","1797.24829","0.01137","0.00279","179.72482","-0.00006"
"34.40000","1.14391","1800.02502","0.01144","0.00278","180.00250","-0.00008"
"34.60000","1.15063","1805.37158","0.01151","0.00278","180.53716","-0.00010"
"34.80000","1.15723","1811.16895","0.01157","0.00279","181.11690","-0.00007"
"35.00000","1.16386","1817.12878","0.01164","0.00279","181.71288","0.00000"
"35.20000","1.17057","1818.97278","0.01171","0.00280","181.89728","0.00000"
"35.40000","1.17713","1818.24060","0.01177","0.00279","181.82407","0.00000"
"35.60000","1.18393","1817.68591","0.01184","0.00280","181.76859","0.00000"
"35.80000","1.19060","1816.58044","0.01191","0.00280","181.65805","0.00000"
"36.00000","1.19720","1815.72778","0.01197","0.00281","181.57278","0.00005"
"36.20000","1.20401","1817.77808","0.01204","0.00281","181.77780","0.00000"
"36.40000","1.21055","1820.45178","0.01211","0.00282","182.04518","0.00002"
"36.60000","1.21721","1823.63110","0.01217","0.00281","182.36311","0.00006"
"36.80000","1.22377","1825.46289","0.01224","0.00282","182.54630","0.00002"
"37.00000","1.23060","1826.83301","0.01231","0.00282","182.68330","0.00005"
"37.20000","1.23721","1828.25269","0.01237","0.00283","182.82527","0.00007"
"37.40000","1.24387","1828.99194","0.01244","0.00283","182.89920","0.00000"
"37.60000","1.25068","1831.46521","0.01251","0.00283","183.14651","0.00007"
"37.80000","1.25714","1832.45227","0.01257","0.00283","183.24522","0.00007"
"38.00000","1.26392","1835.39563","0.01264","0.00283","183.53957","0.00007"
"38.20000","1.27053","1838.60181","0.01271","0.00284","183.86018","0.00007"
"38.40000","1.27722","1843.36304","0.01277","0.00284","184.33630","0.00007"
"38.60000","1.28392","1847.64917","0.01284","0.00284","184.76492","0.00008"
"38.80000","1.29056","1849.28125","0.01291","0.00285","184.92813","0.00012"
"39.00000","1.29724","1848.51660","0.01297","0.00286","184.85165","0.00009"
"39.20000","1.30379","1848.49817","0.01304","0.00286","184.84982","0.00011"
"39.40000","1.31070","1849.84949","0.01311","0.00286","184.98495","0.00009"
"39.60000","1.31722","1849.05457","0.01317","0.00286","184.90546","0.00013"
"39.80000","1.32386","1851.82935","0.01324","0.00286","185.18294","0.00014"
"40.00000","1.33064","1856.77930","0.01331","0.00286","185.67793","0.00013"
"40.20000","1.33715","1860.24756","0.01337","0.00287","186.02475","0.00013"
"40.40000","1.34386","1865.04797","0.01344","0.00288","186.50479","0.00013"
"40.60000","1.35055","1870.04846","0.01351","0.00289","187.00485","0.00007"
"40.80000","1.35726","1874.73340","0.01357","0.00290","187.47334","0.00013"
"41.00000","1.36390","1876.98914","0.01364","0.00289","187.69891","0.00007"
"41.20000","1.37057","1878.79871","0.01371","0.00290","187.87987","0.00013"
"41.40000","1.37728","1880.31812","0.01377","0.00291","188.03181","0.00008"
"41.60000","1.38381","1878.21729","0.01384","0.00292","187.82173","0.00010"
"41.80000","1.39062","1876.25195","0.01391","0.00291","187.62520","0.00011"
"42.00000","1.39719","1870.86072","0.01397","0.00290","187.08607","0.00007"
"42.20000","1.40381","1863.76587","0.01404","0.00290","186.37659","0.00013"
"42.40000","1.41067","1861.40552","0.01411","0.00288","186.14055","0.00013"
"42.60000","1.41718","1859.24902","0.01417","0.00288","185.92490","0.00013"
"42.80000","1.42388","1857.69177","0.01424","0.00288","185.76918","0.00013"
"43.00000","1.43056","1856.97620","0.01431","0.00288","185.69762","0.00019"
"43.20000","1.43734","1856.43774","0.01437","0.00288","185.64377","0.00013"
"43.40000","1.44385","1853.56177","0.01444","0.00288","185.35617","0.00015"
"43.60000","1.45044","1854.16467","0.01450","0.00288","185.41647","0.00013"
"43.80000","1.45730","1859.59058","0.01457","0.00289","185.95906","0.00013"
"44.00000","1.46374","1864.32446","0.01464","0.00290","186.43245","0.00013"
"44.20000","1.47058","1871.45459","0.01471","0.00290","187.14546","0.00019"
"44.40000","1.47719","1877.57349","0.01477","0.00291","187.75735","0.00013"
"44.60000","1.48391","1883.02832","0.01484","0.00292","188.30283","0.00013"
"44.80000","1.49068","1889.55103","0.01491","0.00292","188.95511","0.00013"
"45.00000","1.49717","1894.41553","0.01497","0.00292","189.44156","0.00007"
"45.20000","1.50385","1898.38892","0.01504","0.00294","189.83890","0.00013"
"45.40000","1.51042","1899.96069","0.01510","0.00294","189.99606","0.00013"
"45.60000","1.51732","1901.90967","0.01517","0.00294","190.19096","0.00010"
"45.80000","1.52383","1900.40027","0.01524","0.00294","190.04002","0.00013"
"46.00000","1.53056","1898.37756","0.01531","0.00293","189.83775","0.00007"
"46.20000","1.53732","1897.20935","0.01537","0.00293","189.72093","0.00000"
"46.40000","1.54383","1894.25671","0.01544","0.00292","189.42567","0.00011"
"46.60000","1.55060","1894.28516","0.01551","0.00292","189.42851","0.00013"
"46.80000","1.55717","1894.48706","0.01557","0.00292","189.44870","0.00013"
"47.00000","1.56392","1895.15320","0.01564","0.00292","189.51532","0.00012"
"47.20000","1.57051","1896.97327","0.01571","0.00293","189.69733","0.00007"
"47.40000","1.57719","1896.93420","0.01577","0.00293","189.69342","0.00008"
"47.60000","1.58390","1893.95142","0.01584","0.00292","189.39514","0.00007"
"47.80000","1.59047","1889.69397","0.01590","0.00292","188.96939","0.00007"
"48.00000","1.59729","1886.52429","0.01597","0.00292","188.65244","0.00007"
"48.20000","1.60387","1878.22803","0.01604","0.00291","187.82280","0.00007"
"48.40000","1.61050","1868.49219","0.01611","0.00290","186.84921","0.00013"
"48.60000","1.61733","1859.47327","0.01617","0.00289","185.94733","0.00013"
"48.80000","1.62386","1847.28540","0.01624","0.00288","184.72855","0.00013"
"49.00000","1.63049","1836.09387","0.01630","0.00286","183.60939","0.00020"
"49.20000","1.63714","1829.69031","0.01637","0.00285","182.96902","0.00020"
"49.40000","1.64393","1828.72058","0.01644","0.00285","182.87206","0.00017"
"49.60000","1.65059","1828.36694","0.01651","0.00284","182.83670","0.00015"
"49.80000","1.65716","1829.10974","0.01657","0.00284","182.91098","0.00013"
"50.00000","1.66398","1831.07593","0.01664","0.00285","183.10759","0.00017"
"50.20000","1.67048","1833.00427","0.01670","0.00285","183.30043","0.00014"
"50.40000","1.67730","1838.41748","0.01677","0.00286","183.84175","0.00020"
"50.60000","1.68385","1842.52820","0.01684","0.00286","184.25282","0.00013"
"50.80000","1.69048","1846.85229","0.01690","0.00287","184.68523","0.00015"
"51.00000","1.69730","1852.47144","0.01697","0.00288","185.24715","0.00013"
"51.20000","1.70382","1856.49475","0.01704","0.00288","185.64948","0.00013"
"51.40000","1.71058","1859.93481","0.01711","0.00288","185.99348","0.00013"
"51.60000","1.71713","1860.68616","0.01717","0.00289","186.06862","0.00013"
"51.80000","1.72398","1861.70862","0.01724","0.00288","186.17087","0.00013"
"52.00000","1.73055","1859.43677","0.01731","0.00288","185.94368","0.00013"
"52.20000","1.73716","1856.39709","0.01737","0.00288","185.63971","0.00013"
"52.40000","1.74402","1852.95496","0.01744","0.00288","185.29550","0.00013"
"52.60000","1.75045","1845.01526","0.01750","0.00287","184.50153","0.00013"
"52.80000","1.75719","1838.21973","0.01757","0.00286","183.82198","0.00013"
"53.00000","1.76381","1834.34473","0.01764","0.00285","183.43448","0.00013"
"53.20000","1.77067","1830.95471","0.01771","0.00284","183.09547","0.00020"
"53.40000","1.77722","1821.97949","0.01777","0.00283","182.19795","0.00020"
"53.60000","1.78386","1811.96594","0.01784","0.00283","181.19659","0.00020"
"53.80000","1.79059","1805.58972","0.01791","0.00283","180.55898","0.00020"
"54.00000","1.79711","1796.53186","0.01797","0.00282","179.65318","0.00020"
"54.20000","1.80404","1787.35242","0.01804","0.00280","178.73524","0.00020"
"54.40000","1.81050","1770.08154","0.01810","0.00278","177.00815","0.00013"
"54.60000","1.81716","1757.78088","0.01817","0.00277","175.77809","0.00020"
"54.80000","1.82395","1752.77014","0.01824","0.00275","175.27701","0.00022"
"55.00000","1.83056","1752.54663","0.01831","0.00275","175.25467","0.00020"
"55.20000","1.83718","1751.54773","0.01837","0.00275","175.15477","0.00020"
"55.40000","1.84384","1750.05127","0.01844","0.00275","175.00513","0.00025"
"55.60000","1.85062","1749.89160","0.01851","0.00274","174.98917","0.00028"
"55.80000","1.85720","1747.94714","0.01857","0.00275","174.79471","0.00025"
"56.00000","1.86387","1748.55774","0.01864","0.00275","174.85577","0.00027"
"56.20000","1.87060","1751.44641","0.01871","0.00275","175.14464","0.00020"
"56.40000","1.87714","1751.10815","0.01877","0.00275","175.11081","0.00027"
"56.60000","1.88392","1745.07910","0.01884","0.00275","174.50790","0.00027"
"56.80000","1.89059","1738.80200","0.01891","0.00275","173.88020","0.00020"
"57.00000","1.89717","1729.74426","0.01897","0.00274","172.97443","0.00022"
"57.20000","1.90396","1714.69763","0.01904","0.00273","171.46976","0.00027"
"57.40000","1.91050","1696.08569","0.01910","0.00270","169.60857","0.00027"
"57.60000","1.91726","1681.64880","0.01917","0.00269","168.16489","0.00026"
"57.80000","1.92386","1660.36304","0.01924","0.00266","166.03630","0.00025"
"58.00000","1.93066","1647.00891","0.01931","0.00264","164.70090","0.00027"
"58.20000","1.93723","1632.75024","0.01937","0.00263","163.27502","0.00027"
"58.40000","1.94381","1614.15808","0.01944","0.00261","161.41580","0.00032"
"58.60000","1.95069","1598.94751","0.01951","0.00260","159.89474","0.00027"
"58.80000","1.95712","1586.99023","0.01957","0.00258","158.69902","0.00027"
"59.00000","1.96389","1578.59741","0.01964","0.00257","157.85974","0.00027"
"59.20000","1.97047","1565.16492","0.01970","0.00254","156.51649","0.00027"
"59.40000","1.97727","1550.93115","0.01977","0.00253","155.09311","0.00027"
"59.60000","1.98401","1532.31567","0.01984","0.00253","153.23157","0.00028"
"59.80000","1.99058","1511.10278","0.01991","0.00251","151.11028","0.00033"
"60.00000","1.99724","1484.48621","0.01997","0.00248","148.44862","0.00037"
"60.20000","2.00379","1459.62744","0.02004","0.00246","145.96274","0.00033"
"60.40000","2.01070","1437.41431","0.02011","0.00243","143.74142","0.00033"
"60.60000","2.01717","1417.67639","0.02017","0.00241","141.76764","0.00037"
"60.80000","2.02382","1395.90125","0.02024","0.00239","139.59012","0.00034"
"61.00000","2.03062","1384.26953","0.02031","0.00237","138.42696","0.00040"
"61.20000","2.03719","1376.49573","0.02037","0.00235","137.64957","0.00040"
"61.40000","2.04397","1356.89612","0.02044","0.00235","135.68961","0.00039"
"61.60000","2.05053","1331.77466","0.02051","0.00233","133.17746","0.00033"
"61.80000","2.05733","1307.96045","0.02057","0.00230","130.79605","0.00033"
"62.00000","2.06390","1287.18652","0.02064","0.00228","128.71866","0.00028"
"62.20000","2.07056","1264.07458","0.02071","0.00226","126.40746","0.00027"
"62.40000","2.07721","1239.92834","0.02077","0.00222","123.99284","0.00020"
"62.60000","2.08382","1220.53198","0.02084","0.00220","122.05320","0.00013"
"62.80000","2.09057","1204.54016","0.02091","0.00219","120.45402","0.00013"
"63.00000","2.09723","1185.99805","0.02097","0.00217","118.59981","0.00013"
"63.20000","2.10389","1164.09229","0.02104","0.00216","116.40923","0.00013"
"63.40000","2.11068","1133.09534","0.02111","0.00214","113.30953","0.00012"
"63.60000","2.11723","1110.58582","0.02117","0.00211","111.05858","0.00013"
"63.80000","2.12386","1082.47095","0.02124","0.00208","108.24709","0.00020"
"64.00000","2.13051","1057.57605","0.02131","0.00205","105.75761","0.00013"
"64.20000","2.13729","1038.58728","0.02137","0.00203","103.85873","0.00017"
"64.40000","2.14389","1018.23236","0.02144","0.00201","101.82323","0.00021"
"64.60000","2.15046","991.17151","0.02150","0.00198","99.11715","0.00027"
"64.80000","2.15732","968.50098","0.02157","0.00195","96.85010","0.00027"
"65.00000","2.16387","950.65820","0.02164","0.00194","95.06582","0.00031"
"65.20000","2.17066","935.80975","0.02171","0.00192","93.58098","0.00036"
"65.40000","2.17724","912.94891","0.02177","0.00189","91.29489","0.00040"
"65.60000","2.18393","895.26178","0.02184","0.00188","89.52618","0.00049"
"65.80000","2.19065","877.27307","0.02191","0.00186","87.72731","0.00053"
"66.00000","2.19716","857.71008","0.02197","0.00185","85.77101","0.00053"
"66.20000","2.20388","841.10321","0.02204","0.00183","84.11032","0.00053"
"66.40000","2.21039","826.05872","0.02210","0.00181","82.60587","0.00059"
"66.60000","2.21734","811.35461","0.02217","0.00179","81.13546","0.00056"
"66.80000","2.22393","788.31549","0.02224","0.00177","78.83155","0.00059"
"67.00000","2.23065","768.24170","0.02231","0.00175","76.82417","0.00060"
"67.20000","2.23740","751.92957","0.02237","0.00173","75.19296","0.00059"
"67.40000","2.24387","737.22034","0.02244","0.00171","73.72203","0.00060"
"67.60000","2.25054","727.63239","0.02251","0.00170","72.76324","0.00060"
"67.80000","2.25709","718.90894","0.02257","0.00170","71.89089","0.00059"
"68.00000","2.26395","711.59808","0.02264","0.00168","71.15981","0.00053"
"68.20000","2.27053","706.32153","0.02271","0.00167","70.63216","0.00053"
"68.40000","2.27721","700.59894","0.02277","0.00167","70.05989","0.00048"
"68.60000","2.28401","694.26697","0.02284","0.00166","69.42670","0.00053"
"68.80000","2.29056","686.53644","0.02291","0.00166","68.65364","0.00049"
"69.00000","2.29741","679.89606","0.02297","0.00164","67.98961","0.00047"
"69.20000","2.30384","674.30194","0.02304","0.00163","67.43019","0.00047"
"69.40000","2.31054","669.32123","0.02311","0.00163","66.93212","0.00047"
"69.60000","2.31723","661.88385","0.02317","0.00162","66.18839","0.00047"
"69.80000","2.32389","651.17395","0.02324","0.00160","65.11739","0.00053"
"70.00000","2.33052","644.98834","0.02331","0.00158","64.49883","0.00060"
"70.20000","2.33717","640.46124","0.02337","0.00158","64.04613","0.00065"
"70.40000","2.34402","640.02368","0.02344","0.00158","64.00237","0.00067"
"70.60000","2.35064","638.37073","0.02351","0.00157","63.83707","0.00060"
"70.80000","2.35725","635.07080","0.02357","0.00157","63.50708","0.00060"
"71.00000","2.36399","632.81158","0.02364","0.00157","63.28116","0.00060"
"71.20000","2.37050","630.63483","0.02371","0.00156","63.06348","0.00055"
"71.40000","2.37719","629.70636","0.02377","0.00155","62.97063","0.00058"
"71.60000","2.38386","630.44910","0.02384","0.00155","63.04491","0.00060"
"71.80000","2.39051","630.71893","0.02391","0.00154","63.07189","0.00060"
"72.00000","2.39727","631.74469","0.02397","0.00154","63.17447","0.00060"
"72.20000","2.40390","630.18054","0.02404","0.00154","63.01805","0.00060"
"72.40000","2.41073","628.17523","0.02411","0.00154","62.81752","0.00060"
"72.60000","2.41721","623.03906","0.02417","0.00153","62.30391","0.00060"
"72.80000","2.42398","618.35547","0.02424","0.00152","61.83555","0.00060"
"73.00000","2.43053","613.25153","0.02431","0.00152","61.32515","0.00061"
"73.20000","2.43713","610.39038","0.02437","0.00152","61.03904","0.00060"
"73.40000","2.44399","610.07056","0.02444","0.00151","61.00706","0.00060"
"73.60000","2.45046","608.51117","0.02450","0.00151","60.85112","0.00062"
"73.80000","2.45723","608.37067","0.02457","0.00150","60.83707","0.00061"
"74.00000","2.46390","607.43762","0.02464","0.00150","60.74376","0.00066"
"74.20000","2.47075","606.80096","0.02471","0.00149","60.68010","0.00067"
"74.40000","2.47727","606.41266","0.02477","0.00149","60.64127","0.00067"
"74.60000","2.48386","606.21100","0.02484","0.00149","60.62110","0.00063"
"74.80000","2.49064","606.62878","0.02491","0.00149","60.66288","0.00060"
"75.00000","2.49708","601.99780","0.02497","0.00149","60.19978","0.00060"
"75.20000","2.50395","600.79248","0.02504","0.00149","60.07925","0.00060"
"75.40000","2.51047","599.40765","0.02510","0.00148","59.94077","0.00060"
"75.60000","2.51724","601.20898","0.02517","0.00148","60.12090","0.00061"
"75.80000","2.52402","601.05042","0.02524","0.00148","60.10504","0.00066"
"76.00000","2.53062","599.30566","0.02531","0.00147","59.93056","0.00067"
"76.20000","2.53727","597.88458","0.02537","0.00148","59.78846","0.00066"
"76.40000","2.54383","593.08533","0.02544","0.00148","59.30853","0.00065"
"76.60000","2.55067","591.96222","0.02551","0.00147","59.19622","0.00060"
"76.80000","2.55714","591.22180","0.02557","0.00147","59.12218","0.00060"
"77.00000","2.56382","589.82513","0.02564","0.00147","58.98251","0.00060"
"77.20000","2.57063","587.61469","0.02571","0.00147","58.76147","0.00053"
"77.40000","2.57720","585.01227","0.02577","0.00146","58.50123","0.00054"
"77.60000","2.58394","583.84412","0.02584","0.00146","58.38441","0.00059"
"77.80000","2.59061","582.35596","0.02591","0.00146","58.23560","0.00053"
"78.00000","2.59729","582.15668","0.02597","0.00145","58.21567","0.00053"
"78.20000","2.60392","581.89465","0.02604","0.00145","58.18946","0.00056"
"78.40000","2.61052","580.21381","0.02611","0.00145","58.02138","0.00060"
"78.60000","2.61720","575.87366","0.02617","0.00144","57.58736","0.00060"
"78.80000","2.62380","574.73059","0.02624","0.00145","57.47306","0.00059"
"79.00000","2.63063","575.56451","0.02631","0.00144","57.55645","0.00060"
"79.20000","2.63724","575.26636","0.02637","0.00144","57.52663","0.00057"
"79.40000","2.64386","575.46643","0.02644","0.00144","57.54664","0.00053"
"79.60000","2.65071","575.80273","0.02651","0.00144","57.58027","0.00053"
"79.80000","2.65720","572.03503","0.02657","0.00144","57.20350","0.00054"
"80.00000","2.66387","570.29169","0.02664","0.00144","57.02917","0.00053"
"80.20000","2.67048","569.86639","0.02670","0.00143","56.98664","0.00053"
"80.40000","2.67728","569.74976","0.02677","0.00143","56.97498","0.00053"
"80.60000","2.68390","570.19440","0.02684","0.00142","57.01944","0.00056"
"80.80000","2.69051","571.13477","0.02691","0.00142","57.11348","0.00053"
"81.00000","2.69731","572.91187","0.02697","0.00141","57.29119","0.00053"
"81.20000","2.70382","573.01001","0.02704","0.00141","57.30100","0.00053"
"81.40000","2.71065","572.67090","0.02711","0.00141","57.26709","0.00060"
"81.60000","2.71724","571.38531","0.02717","0.00140","57.13853","0.00060"
"81.80000","2.72387","571.15338","0.02724","0.00140","57.11534","0.00062"
"82.00000","2.73062","571.47632","0.02731","0.00140","57.14763","0.00060"
"82.20000","2.73718","571.11072","0.02737","0.00139","57.11107","0.00060"
"82.40000","2.74391","572.36047","0.02744","0.00139","57.23605","0.00057"
"82.60000","2.75046","573.55878","0.02750","0.00139","57.35588","0.00060"
"82.80000","2.75738","576.43176","0.02757","0.00139","57.64318","0.00066"
"83.00000","2.76388","575.83569","0.02764","0.00139","57.58357","0.00060"
"83.20000","2.77055","574.72943","0.02771","0.00138","57.47294","0.00060"
"83.40000","2.77730","572.88104","0.02777","0.00138","57.28811","0.00060"
"83.60000","2.78382","571.02441","0.02784","0.00138","57.10244","0.00060"
"83.80000","2.79053","570.33759","0.02791","0.00137","57.03376","0.00055"
"84.00000","2.79718","570.28027","0.02797","0.00137","57.02803","0.00060"
"84.20000","2.80391","571.16754","0.02804","0.00137","57.11675","0.00060"
"84.40000","2.81062","570.38422","0.02811","0.00136","57.03842","0.00060"
"84.60000","2.81725","568.67810","0.02817","0.00136","56.86781","0.00061"
"84.80000","2.82392","567.20294","0.02824","0.00136","56.72029","0.00058"
"85.00000","2.83048","565.14099","0.02830","0.00136","56.51410","0.00060"
"85.20000","2.83731","565.06396","0.02837","0.00136","56.50640","0.00059"
"85.40000","2.84386","564.43170","0.02844","0.00136","56.44317","0.00067"
"85.60000","2.85046","564.03687","0.02850","0.00136","56.40369","0.00067"
"85.80000","2.85733","564.82965","0.02857","0.00136","56.48296","0.00067"
"86.00000","2.86383","564.22101","0.02864","0.00136","56.42210","0.00069"
"86.20000","2.87057","563.11749","0.02871","0.00136","56.31175","0.00067"
"86.40000","2.87722","562.58948","0.02877","0.00136","56.25895","0.00068"
"86.60000","2.88394","561.20966","0.02884","0.00135","56.12096","0.00068"
"86.80000","2.89056","559.18915","0.02891","0.00135","55.91891","0.00067"
"87.00000","2.89718","557.70679","0.02897","0.00135","55.77068","0.00066"
"87.20000","2.90392","557.81152","0.02904","0.00135","55.78115","0.00060"
"87.40000","2.91039","554.51135","0.02910","0.00135","55.45113","0.00060"
"87.60000","2.91726","551.50861","0.02917","0.00135","55.15086","0.00065"
"87.80000","2.92388","550.24469","0.02924","0.00134","55.02447","0.00067"
"88.00000","2.93056","549.83154","0.02931","0.00134","54.98315","0.00067"
"88.20000","2.93737","550.48340","0.02937","0.00134","55.04834","0.00067"
"88.40000","2.94384","548.86615","0.02944","0.00133","54.88662","0.00067"
"88.60000","2.95051","548.65314","0.02951","0.00133","54.86531","0.00067"
"88.80000","2.95711","548.17560","0.02957","0.00133","54.81756","0.00073"
"89.00000","2.96397","547.45770","0.02964","0.00133","54.74577","0.00069"
"89.20000","2.97047","546.37500","0.02970","0.00133","54.63750","0.00067"
"89.40000","2.97724","546.22791","0.02977","0.00133","54.62279","0.00066"
"89.60000","2.98399","546.46484","0.02984","0.00132","54.64648","0.00067"
"89.80000","2.99047","546.63098","0.02990","0.00132","54.66310","0.00067"
"90.00000","2.99731","549.65045","0.02997","0.00132","54.96505","0.00067"
"90.20000","3.00384","550.98975","0.03004","0.00132","55.09898","0.00067"
"90.40000","3.01057","551.43860","0.03011","0.00133","55.14386","0.00063"
"90.60000","3.01721","551.70398","0.03017","0.00133","55.17040","0.00066"
"90.80000","3.02386","550.34906","0.03024","0.00133","55.03490","0.00061"
"91.00000","3.03051","548.38470","0.03031","0.00133","54.83847","0.00067"
"91.20000","3.03715","546.43018","0.03037","0.00133","54.64302","0.00060"
"91.40000","3.04400","545.55042","0.03044","0.00132","54.55504","0.00067"
"91.60000","3.05055","543.83167","0.03051","0.00133","54.38317","0.00066"
"91.80000","3.05716","543.04541","0.03057","0.00133","54.30454","0.00067"
"92.00000","3.06399","545.20203","0.03064","0.00132","54.52020","0.00067"
"92.02000","3.06462","545.17120","0.03065","0.00132","54.51712","0.00066"