File: Tension/Section_2_Group_4/f6a.is_tens_RawData/Specimen_RawData_1.csv
Time,Extension,Load,Tensile strain (Extension),Tensile stress,Strain-by-clip-gage
(s),(mm),(N),(mm/mm),(MPa),(mm/mm)
"0.00000","0.00000","-0.33666","0.00000","-0.03367","-0.00001"
"0.20000","0.00180","5.67447","0.00002","0.56745","0.00001"
"0.40000","0.01031","38.13298","0.00010","3.81330","-0.00002"
"0.60000","0.01722","63.11320","0.00017","6.31132","0.00002"
"0.80000","0.02379","85.95729","0.00024","8.59573","0.00000"
"1.00000","0.03049","108.60213","0.00030","10.86021","-0.00002"
"1.20000","0.03722","130.45331","0.00037","13.04533","0.00001"
"1.40000","0.04385","150.53401","0.00044","15.05340","-0.00001"
"1.60000","0.05049","170.32953","0.00050","17.03295","0.00000"
"1.80000","0.05716","190.02422","0.00057","19.00242","0.00001"
"2.00000","0.06393","209.86681","0.00064","20.98668","-0.00001"
"2.20000","0.07049","228.76080","0.00070","22.87608","0.00001"
"2.40000","0.07712","247.26799","0.00077","24.72680","0.00000"
"2.60000","0.08386","261.73413","0.00084","26.17341","-0.00001"
"2.80000","0.09039","277.20203","0.00090","27.72020","0.00000"
"3.00000","0.09722","295.98343","0.00097","29.59834","0.00000"
"3.20000","0.10389","314.06149","0.00104","31.40615","0.00000"
"3.40000","0.11049","331.68375","0.00110","33.16837","0.00000"
"3.60000","0.11725","349.37573","0.00117","34.93757","0.00000"
"3.80000","0.12383","366.26709","0.00124","36.62671","0.00000"
"4.00000","0.13048","383.37683","0.00130","38.33768","0.00000"
"4.20000","0.13700","399.71600","0.00137","39.97160","0.00000"
"4.40000","0.14393","417.28442","0.00144","41.72844","0.00000"
"4.60000","0.15053","433.43079","0.00151","43.34308","0.00000"
"4.80000","0.15713","449.40631","0.00157","44.94063","-0.00001"
"5.00000","0.16398","466.08719","0.00164","46.60872","0.00000"
"5.20000","0.17043","481.01321","0.00170","48.10132","0.00000"
"5.40000","0.17718","496.93561","0.00177","49.69356","0.00000"
"5.60000","0.18380","512.32452","0.00184","51.23245","0.00000"
"5.80000","0.19056","527.93683","0.00191","52.79368","0.00000"
"6.00000","0.19713","542.66547","0.00197","54.26655","0.00000"
"6.20000","0.20384","557.79871","0.00204","55.77987","0.00001"
"6.40000","0.21054","572.76117","0.00211","57.27612","0.00000"
"6.60000","0.21705","586.92737","0.00217","58.69274","-0.00001"
"6.80000","0.22400","602.33014","0.00224","60.23301","0.00000"
"7.00000","0.23049","616.05975","0.00230","61.60598","0.00000"
"7.20000","0.23714","630.21338","0.00237","63.02134","0.00000"
"7.40000","0.24388","644.61676","0.00244","64.46168","0.00001"
"7.60000","0.25044","658.16229","0.00250","65.81623","0.00000"
"7.80000","0.25711","671.89618","0.00257","67.18962","0.00000"
"8.00000","0.26380","685.84827","0.00264","68.58482","0.00000"
"8.20000","0.27061","699.66327","0.00271","69.96632","0.00000"
"8.40000","0.27714","712.63336","0.00277","71.26334","0.00000"
"8.60000","0.28380","725.99750","0.00284","72.59975","0.00000"
"8.80000","0.29057","739.41534","0.00291","73.94154","0.00000"
"9.00000","0.29709","751.99036","0.00297","75.19904","0.00000"
"9.20000","0.30387","765.30737","0.00304","76.53074","0.00000"
"9.40000","0.31047","777.83978","0.00310","77.78398","0.00000"
"9.60000","0.31713","790.29266","0.00317","79.02927","0.00000"
"9.80000","0.32392","803.30652","0.00324","80.33065","0.00000"
"10.00000","0.33045","815.35510","0.00330","81.53551","0.00000"
"10.20000","0.33715","827.64624","0.00337","82.76463","0.00000"
"10.40000","0.34378","839.75775","0.00344","83.97578","0.00000"
"10.60000","0.35064","852.44489","0.00351","85.24449","0.00000"
"10.80000","0.35715","863.73584","0.00357","86.37358","0.00000"
"11.00000","0.36373","874.98071","0.00364","87.49807","0.00000"
"11.20000","0.37057","887.26709","0.00371","88.72671","0.00000"
"11.40000","0.37703","898.15521","0.00377","89.81552","0.00000"
"11.60000","0.38385","909.99237","0.00384","90.99924","0.00000"
"11.80000","0.39050","921.28876","0.00390","92.12888","0.00000"
"12.00000","0.39724","932.60675","0.00397","93.26067","0.00000"
"12.20000","0.40391","943.53845","0.00404","94.35384","0.00000"
"12.40000","0.41043","953.87799","0.00410","95.38780","0.00000"
"12.60000","0.41719","964.94171","0.00417","96.49417","0.00000"
"12.80000","0.42369","975.05383","0.00424","97.50539","0.00000"
"13.00000","0.43059","986.21594","0.00431","98.62160","0.00001"
"13.20000","0.43711","996.04120","0.00437","99.60412","0.00000"
"13.40000","0.44385","1006.23834","0.00444","100.62383","0.00000"
"13.60000","0.45055","1016.42322","0.00451","101.64232","0.00000"
"13.80000","0.45710","1025.77039","0.00457","102.57704","0.00000"
"14.00000","0.46382","1035.67151","0.00464","103.56715","0.00000"
"14.20000","0.47043","1045.06213","0.00470","104.50621","0.00000"
"14.40000","0.47726","1054.87988","0.00477","105.48799","0.00000"
"14.60000","0.48381","1063.58130","0.00484","106.35813","0.00000"
"14.80000","0.49046","1072.38342","0.00490","107.23834","0.00000"
"15.00000","0.49718","1081.41382","0.00497","108.14138","0.00000"
"15.20000","0.50378","1089.72913","0.00504","108.97292","0.00000"
"15.40000","0.51054","1098.59070","0.00511","109.85907","0.00000"
"15.60000","0.51716","1106.82104","0.00517","110.68211","0.00000"
"15.80000","0.52381","1114.78088","0.00524","111.47809","0.00000"
"16.00000","0.53059","1123.00647","0.00531","112.30064","0.00000"
"16.20000","0.53716","1130.33667","0.00537","113.03367","-0.00001"
"16.40000","0.54378","1137.62585","0.00544","113.76259","0.00000"
"16.60000","0.55046","1144.88855","0.00550","114.48885","0.00000"
"16.80000","0.55721","1152.25000","0.00557","115.22500","0.00000"
"17.00000","0.56387","1159.25085","0.00564","115.92509","0.00000"
"17.20000","0.57042","1165.64270","0.00570","116.56427","0.00000"
"17.40000","0.57726","1172.73669","0.00577","117.27367","0.00000"
"17.60000","0.58377","1178.50757","0.00584","117.85075","0.00000"
"17.80000","0.59051","1184.90601","0.00591","118.49060","0.00000"
"18.00000","0.59715","1190.87866","0.00597","119.08787","0.00000"
"18.20000","0.60383","1196.54260","0.00604","119.65426","0.00000"
"18.40000","0.61054","1202.33972","0.00611","120.23397","0.00000"
"18.60000","0.61711","1207.42944","0.00617","120.74294","0.00000"
"18.80000","0.62387","1212.89746","0.00624","121.28975","0.00000"
"19.00000","0.63039","1217.62012","0.00630","121.76201","0.00000"
"19.20000","0.63725","1223.10925","0.00637","122.31093","0.00000"
"19.40000","0.64380","1227.76465","0.00644","122.77647","0.00000"
"19.60000","0.65044","1232.20923","0.00650","123.22092","0.00000"
"19.80000","0.65729","1237.25903","0.00657","123.72591","0.00000"
"20.00000","0.66375","1240.82129","0.00664","124.08213","0.00000"
"20.20000","0.67046","1245.14490","0.00670","124.51449","-0.00001"
"20.40000","0.67709","1249.36035","0.00677","124.93604","0.00000"
"20.60000","0.68400","1254.19531","0.00684","125.41953","0.00000"
"20.80000","0.69044","1257.39026","0.00690","125.73903","0.00000"
"21.00000","0.69712","1261.28088","0.00697","126.12809","0.00000"
"21.20000","0.70388","1265.28552","0.00704","126.52855","0.00000"
"21.40000","0.71040","1268.15881","0.00710","126.81588","0.00000"
"21.60000","0.71730","1272.18933","0.00717","127.21893","0.00000"
"21.80000","0.72380","1275.15979","0.00724","127.51598","0.00000"
"22.00000","0.73048","1278.35962","0.00730","127.83596","0.00000"
"22.20000","0.73720","1281.81091","0.00737","128.18109","0.00000"
"22.40000","0.74383","1284.86377","0.00744","128.48637","0.00000"
"22.60000","0.75042","1287.62292","0.00750","128.76230","0.00000"
"22.80000","0.75711","1290.51697","0.00757","129.05170","0.00000"
"23.00000","0.76392","1293.72009","0.00764","129.37201","0.00000"
"23.20000","0.77052","1296.34497","0.00771","129.63449","0.00000"
"23.40000","0.77715","1298.89795","0.00777","129.88980","0.00000"
"23.60000","0.78390","1301.73035","0.00784","130.17303","0.00000"
"23.80000","0.79043","1303.98438","0.00790","130.39844","0.00000"
"24.00000","0.79719","1306.90100","0.00797","130.69009","-0.00001"
"24.20000","0.80386","1309.34412","0.00804","130.93442","0.00000"
"24.40000","0.81047","1311.51001","0.00810","131.15100","0.00000"
"24.60000","0.81719","1314.04919","0.00817","131.40492","0.00000"
"24.80000","0.82377","1316.13196","0.00824","131.61319","0.00000"
"25.00000","0.83053","1318.71912","0.00831","131.87192","0.00000"
"25.20000","0.83712","1320.85193","0.00837","132.08519","0.00000"
"25.40000","0.84399","1323.43140","0.00844","132.34314","0.00001"
"25.60000","0.85054","1325.32422","0.00851","132.53242","0.00000"
"25.80000","0.85709","1327.09961","0.00857","132.70996","0.00000"
"26.00000","0.86393","1329.83081","0.00864","132.98308","0.00000"
"26.20000","0.87038","1331.15442","0.00870","133.11545","0.00000"
"26.40000","0.87712","1333.29773","0.00877","133.32977","0.00000"
"26.60000","0.88376","1335.21265","0.00884","133.52127","0.00000"
"26.80000","0.89060","1337.46411","0.00891","133.74641","0.00000"
"27.00000","0.89721","1339.15271","0.00897","133.91527","0.00000"
"27.20000","0.90382","1340.83508","0.00904","134.08351","0.00001"
"27.40000","0.91056","1343.01794","0.00911","134.30179","0.00000"
"27.60000","0.91705","1344.32446","0.00917","134.43245","0.00000"
"27.80000","0.92395","1346.81494","0.00924","134.68149","-0.00001"
"28.00000","0.93043","1348.00476","0.00930","134.80048","0.00000"
"28.20000","0.93712","1349.75635","0.00937","134.97563","0.00000"
"28.40000","0.94388","1351.81580","0.00944","135.18158","0.00001"
"28.60000","0.95049","1353.27075","0.00950","135.32707","0.00000"
"28.80000","0.95716","1354.86914","0.00957","135.48691","0.00000"
"29.00000","0.96381","1356.46692","0.00964","135.64670","0.00000"
"29.20000","0.97069","1358.72791","0.00971","135.87279","0.00000"
"29.40000","0.97715","1359.65295","0.00977","135.96530","0.00000"
"29.60000","0.98381","1361.11597","0.00984","136.11160","0.00000"
"29.80000","0.99050","1362.76672","0.00990","136.27667","0.00000"
"30.00000","0.99710","1364.02356","0.00997","136.40236","0.00000"
"30.20000","1.00382","1365.76929","0.01004","136.57693","0.00001"
"30.40000","1.01052","1367.37708","0.01011","136.73770","0.00000"
"30.60000","1.01720","1368.54321","0.01017","136.85432","0.00000"
"30.80000","1.02393","1370.13550","0.01024","137.01355","0.00000"
"31.00000","1.03050","1371.19604","0.01031","137.11960","0.00000"
"31.20000","1.03715","1372.40820","0.01037","137.24081","0.00000"
"31.40000","1.04377","1373.73035","0.01044","137.37303","0.00000"
"31.60000","1.05056","1375.33960","0.01051","137.53397","0.00000"
"31.80000","1.05714","1376.42151","0.01057","137.64215","0.00000"
"32.00000","1.06373","1377.35486","0.01064","137.73549","0.00000"
"32.20000","1.07061","1379.20044","0.01071","137.92004","0.00000"
"32.40000","1.07717","1380.04871","0.01077","138.00487","0.00000"
"32.60000","1.08392","1381.61499","0.01084","138.16150","0.00000"
"32.80000","1.09052","1382.61816","0.01091","138.26181","0.00000"
"33.00000","1.09725","1383.87549","0.01097","138.38754","0.00000"
"33.20000","1.10389","1385.07312","0.01104","138.50731","0.00000"
"33.40000","1.11042","1385.79333","0.01110","138.57933","0.00000"
"33.60000","1.11718","1387.10620","0.01117","138.71062","0.00000"
"33.80000","1.12367","1387.88770","0.01124","138.78877","0.00000"
"34.00000","1.13060","1389.77930","0.01131","138.97794","0.00000"
"34.20000","1.13721","1390.68677","0.01137","139.06868","0.00000"
"34.40000","1.14390","1391.78174","0.01144","139.17818","0.00000"
"34.60000","1.15067","1393.36182","0.01151","139.33618","0.00000"
"34.80000","1.15712","1393.67847","0.01157","139.36784","0.00000"
"35.00000","1.16377","1394.59900","0.01164","139.45990","0.00000"
"35.20000","1.17035","1395.48975","0.01170","139.54898","0.00000"
"35.40000","1.17727","1397.22876","0.01177","139.72287","0.00000"
"35.60000","1.18378","1397.78064","0.01184","139.77806","0.00000"
"35.80000","1.19048","1398.84326","0.01190","139.88432","0.00001"
"36.00000","1.19728","1400.07971","0.01197","140.00797","0.00000"
"36.20000","1.20382","1400.59082","0.01204","140.05908","0.00000"
"36.40000","1.21062","1401.89795","0.01211","140.18979","0.00000"
"36.60000","1.21715","1402.44434","0.01217","140.24443","0.00000"
"36.80000","1.22386","1403.40417","0.01224","140.34042","0.00001"
"37.00000","1.23047","1404.27075","0.01230","140.42708","0.00000"
"37.20000","1.23714","1405.14575","0.01237","140.51457","0.00000"
"37.40000","1.24380","1405.99109","0.01244","140.59911","0.00000"
"37.60000","1.25047","1406.91748","0.01250","140.69174","0.00000"
"37.80000","1.25729","1408.16370","0.01257","140.81638","0.00000"
"38.00000","1.26390","1408.72144","0.01264","140.87215","0.00000"
"38.20000","1.27051","1409.23108","0.01271","140.92311","-0.00001"
"38.40000","1.27724","1410.34253","0.01277","141.03426","0.00000"
"38.60000","1.28378","1410.85974","0.01284","141.08597","0.00000"
"38.80000","1.29046","1411.67920","0.01290","141.16792","0.00000"
"39.00000","1.29715","1412.43958","0.01297","141.24396","0.00000"
"39.20000","1.30385","1413.29944","0.01304","141.32994","0.00000"
"39.40000","1.31054","1414.12524","0.01311","141.41252","0.00000"
"39.60000","1.31716","1414.69604","0.01317","141.46960","0.00000"
"39.80000","1.32397","1415.82019","0.01324","141.58202","0.00000"
"40.00000","1.33045","1416.00549","0.01330","141.60056","0.00000"
"40.20000","1.33725","1417.13403","0.01337","141.71341","0.00000"
"40.40000","1.34384","1417.58179","0.01344","141.75818","0.00000"
"40.60000","1.35043","1418.04187","0.01350","141.80418","0.00000"
"40.80000","1.35726","1419.25024","0.01357","141.92502","0.00001"
"41.00000","1.36376","1419.40601","0.01364","141.94060","0.00000"
"41.20000","1.37048","1420.31018","0.01370","142.03102","0.00000"
"41.40000","1.37719","1421.02600","0.01377","142.10260","0.00000"
"41.60000","1.38407","1422.27344","0.01384","142.22734","0.00000"
"41.80000","1.39052","1422.38171","0.01391","142.23817","0.00000"
"42.00000","1.39711","1422.74255","0.01397","142.27426","0.00000"
"42.20000","1.40389","1423.62329","0.01404","142.36234","0.00000"
"42.40000","1.41036","1423.59534","0.01410","142.35953","0.00000"
"42.60000","1.41724","1424.91882","0.01417","142.49188","0.00001"
"42.80000","1.42379","1425.16760","0.01424","142.51675","0.00000"
"43.00000","1.43055","1426.00659","0.01431","142.60066","0.00000"
"43.20000","1.43727","1426.63135","0.01437","142.66313","0.00000"
"43.40000","1.44389","1427.06946","0.01444","142.70694","0.00000"
"43.60000","1.45050","1427.63831","0.01450","142.76382","0.00001"
"43.80000","1.45707","1427.82178","0.01457","142.78218","0.00000"
"44.00000","1.46396","1429.00037","0.01464","142.90004","0.00000"
"44.20000","1.47045","1428.94299","0.01470","142.89430","0.00000"
"44.40000","1.47710","1429.55408","0.01477","142.95541","0.00000"
"44.60000","1.48389","1430.33911","0.01484","143.03391","0.00000"
"44.80000","1.49046","1430.69006","0.01490","143.06900","0.00001"
"45.00000","1.49719","1431.25806","0.01497","143.12581","0.00000"
"45.20000","1.50389","1431.89734","0.01504","143.18973","0.00000"
"45.40000","1.51059","1432.49377","0.01511","143.24937","0.00000"
"45.60000","1.51718","1432.73254","0.01517","143.27325","0.00000"
"45.80000","1.52380","1432.92456","0.01524","143.29245","0.00000"
"46.00000","1.53049","1433.51599","0.01530","143.35159","0.00000"
"46.20000","1.53706","1433.73218","0.01537","143.37321","-0.00001"
"46.40000","1.54390","1434.67004","0.01544","143.46701","0.00000"
"46.60000","1.55057","1435.23303","0.01551","143.52330","0.00000"
"46.80000","1.55714","1435.30090","0.01557","143.53009","0.00000"
"47.00000","1.56394","1435.98804","0.01564","143.59880","0.00000"
"47.20000","1.57046","1435.98425","0.01570","143.59842","0.00000"
"47.40000","1.57716","1436.45984","0.01577","143.64598","0.00000"
"47.60000","1.58372","1436.68164","0.01584","143.66817","0.00000"
"47.80000","1.59058","1437.55457","0.01591","143.75546","0.00000"
"48.00000","1.59718","1437.75269","0.01597","143.77527","0.00000"
"48.20000","1.60378","1437.82886","0.01604","143.78288","0.00000"
"48.40000","1.61062","1438.77515","0.01611","143.87752","0.00000"
"48.60000","1.61711","1438.81836","0.01617","143.88184","0.00000"
"48.80000","1.62387","1439.32056","0.01624","143.93205","0.00000"
"49.00000","1.63048","1439.65076","0.01630","143.96507","0.00000"
"49.20000","1.63719","1440.10974","0.01637","144.01097","0.00000"
"49.40000","1.64385","1440.46875","0.01644","144.04688","0.00000"
"49.60000","1.65047","1440.47998","0.01650","144.04800","0.00000"
"49.80000","1.65721","1441.00977","0.01657","144.10098","0.00000"
"50.00000","1.66374","1440.97083","0.01664","144.09708","0.00000"
"50.20000","1.67065","1442.04358","0.01671","144.20436","0.00000"
"50.40000","1.67718","1441.78479","0.01677","144.17848","0.00000"
"50.60000","1.68382","1442.02454","0.01684","144.20245","0.00000"
"50.80000","1.69056","1442.45630","0.01691","144.24564","0.00000"
"51.00000","1.69709","1442.29138","0.01697","144.22914","0.00000"
"51.20000","1.70381","1442.85291","0.01704","144.28529","0.00001"
"51.40000","1.71048","1443.10815","0.01710","144.31082","0.00000"
"51.60000","1.71720","1443.50830","0.01717","144.35083","0.00000"
"51.80000","1.72387","1443.82996","0.01724","144.38300","0.00000"
"52.00000","1.73051","1443.99939","0.01731","144.39993","0.00000"
"52.20000","1.73721","1444.19653","0.01737","144.41965","0.00001"
"52.40000","1.74378","1444.24475","0.01744","144.42447","0.00000"
"52.60000","1.75057","1444.85461","0.01751","144.48546","0.00000"
"52.80000","1.75713","1444.74109","0.01757","144.47411","0.00000"
"53.00000","1.76375","1444.76013","0.01764","144.47601","0.00000"
"53.20000","1.77059","1445.46167","0.01771","144.54617","0.00000"
"53.40000","1.77713","1445.33630","0.01777","144.53363","0.00000"
"53.60000","1.78386","1445.54077","0.01784","144.55408","0.00000"
"53.80000","1.79048","1445.67871","0.01790","144.56787","0.00000"
"54.00000","1.79726","1446.07532","0.01797","144.60753","0.00000"
"54.20000","1.80381","1445.92554","0.01804","144.59256","0.00001"
"54.40000","1.81045","1446.05603","0.01810","144.60561","0.00000"
"54.60000","1.81720","1446.41272","0.01817","144.64127","0.00000"
"54.80000","1.82368","1446.12366","0.01824","144.61237","0.00000"
"55.00000","1.83054","1446.73767","0.01831","144.67377","0.00001"
"55.20000","1.83718","1446.86438","0.01837","144.68643","0.00001"
"55.40000","1.84384","1447.01990","0.01844","144.70200","0.00000"
"55.60000","1.85060","1447.43579","0.01851","144.74358","0.00000"
"55.80000","1.85711","1447.08936","0.01857","144.70894","0.00000"
"56.00000","1.86379","1447.29663","0.01864","144.72966","0.00000"
"56.20000","1.87040","1447.33105","0.01870","144.73311","0.00000"
"56.40000","1.87728","1447.87830","0.01877","144.78783","0.00000"
"56.60000","1.88378","1447.75537","0.01884","144.77554","0.00000"
"56.80000","1.89048","1447.72742","0.01890","144.77274","0.00000"
"57.00000","1.89724","1448.16138","0.01897","144.81613","0.00001"
"57.20000","1.90378","1447.93359","0.01904","144.79337","0.00001"
"57.40000","1.91054","1448.21692","0.01911","144.82169","0.00000"
"57.60000","1.91712","1447.98682","0.01917","144.79868","0.00000"
"57.80000","1.92390","1448.32678","0.01924","144.83267","0.00000"
"58.00000","1.93049","1448.24390","0.01930","144.82439","0.00001"
"58.20000","1.93713","1448.32874","0.01937","144.83287","0.00000"
"58.40000","1.94377","1448.19629","0.01944","144.81963","0.00000"
"58.60000","1.95045","1448.40210","0.01950","144.84021","0.00000"
"58.80000","1.95726","1448.82898","0.01957","144.88290","0.00000"
"59.00000","1.96384","1448.58923","0.01964","144.85892","0.00001"
"59.20000","1.97047","1448.50024","0.01970","144.85002","0.00000"
"59.40000","1.97725","1448.82593","0.01977","144.88260","0.00000"
"59.60000","1.98380","1448.63025","0.01984","144.86302","0.00000"
"59.80000","1.99045","1448.62219","0.01990","144.86221","0.00000"
"60.00000","1.99713","1448.69617","0.01997","144.86961","0.00001"
"60.20000","2.00387","1448.74451","0.02004","144.87445","0.00000"
"60.40000","2.01054","1448.78491","0.02011","144.87849","-0.00001"
"60.60000","2.01710","1448.53625","0.02017","144.85362","0.00000"
"60.80000","2.02393","1449.01929","0.02024","144.90193","0.00001"
"61.00000","2.03041","1448.59204","0.02030","144.85921","0.00000"
"61.20000","2.03720","1448.83484","0.02037","144.88348","0.00000"
"61.40000","2.04384","1448.81189","0.02044","144.88120","-0.00001"
"61.60000","2.05048","1448.65479","0.02050","144.86548","0.00000"
"61.80000","2.05721","1448.80725","0.02057","144.88072","0.00001"
"62.00000","2.06376","1448.49426","0.02064","144.84943","0.00000"
"62.20000","2.07050","1448.68884","0.02071","144.86888","0.00000"
"62.40000","2.07706","1448.48840","0.02077","144.84885","0.00000"
"62.60000","2.08393","1449.07507","0.02084","144.90750","0.00000"
"62.80000","2.09049","1448.74939","0.02090","144.87494","0.00000"
"63.00000","2.09710","1448.36475","0.02097","144.83647","0.00000"
"63.20000","2.10395","1448.69275","0.02104","144.86928","-0.00001"
"63.40000","2.11039","1448.08459","0.02110","144.80846","0.00000"
"63.60000","2.11714","1448.18384","0.02117","144.81839","0.00001"
"63.80000","2.12376","1448.11548","0.02124","144.81155","0.00001"
"64.00000","2.13060","1448.30701","0.02131","144.83070","0.00000"
"64.20000","2.13716","1448.18665","0.02137","144.81866","0.00000"
"64.40000","2.14381","1447.97949","0.02144","144.79794","0.00000"
"64.60000","2.15051","1447.85303","0.02151","144.78531","0.00000"
"64.80000","2.15706","1447.51843","0.02157","144.75185","0.00001"
"65.00000","2.16396","1448.08716","0.02164","144.80872","0.00000"
"65.20000","2.17047","1447.56274","0.02170","144.75627","0.00000"
"65.40000","2.17711","1447.39270","0.02177","144.73927","0.00000"
"65.60000","2.18389","1447.61597","0.02184","144.76160","0.00001"
"65.80000","2.19050","1447.29749","0.02190","144.72975","0.00001"
"66.00000","2.19707","1446.90540","0.02197","144.69054","0.00000"
"66.20000","2.20381","1446.99536","0.02204","144.69954","0.00000"
"66.40000","2.21057","1447.10693","0.02211","144.71069","0.00001"
"66.60000","2.21718","1446.89758","0.02217","144.68976","0.00001"
"66.80000","2.22384","1446.74194","0.02224","144.67419","0.00000"
"67.00000","2.23052","1446.52454","0.02231","144.65245","0.00000"
"67.20000","2.23708","1446.13159","0.02237","144.61316","-0.00001"
"67.40000","2.24387","1446.42261","0.02244","144.64226","0.00000"
"67.60000","2.25052","1446.27075","0.02251","144.62708","0.00001"
"67.80000","2.25712","1445.99792","0.02257","144.59979","0.00000"
"68.00000","2.26389","1446.03320","0.02264","144.60332","0.00000"
"68.20000","2.27045","1445.84863","0.02270","144.58487","0.00000"
"68.40000","2.27719","1445.56665","0.02277","144.55667","0.00000"
"68.60000","2.28380","1445.27625","0.02284","144.52762","0.00001"
"68.80000","2.29064","1445.33582","0.02291","144.53358","0.00000"
"69.00000","2.29717","1444.97632","0.02297","144.49763","0.00000"
"69.20000","2.30375","1444.48584","0.02304","144.44858","0.00001"
"69.40000","2.31061","1444.83386","0.02311","144.48338","0.00000"
"69.60000","2.31705","1444.16919","0.02317","144.41692","0.00000"
"69.80000","2.32380","1444.04663","0.02324","144.40466","0.00000"
"70.00000","2.33042","1443.84546","0.02330","144.38455","0.00000"
"70.20000","2.33724","1443.92273","0.02337","144.39227","0.00000"
"70.40000","2.34391","1443.73706","0.02344","144.37370","0.00001"
"70.60000","2.35049","1443.33215","0.02350","144.33322","0.00000"
"70.80000","2.35717","1443.15845","0.02357","144.31584","0.00000"
"71.00000","2.36373","1442.67676","0.02364","144.26767","0.00000"
"71.20000","2.37064","1443.08423","0.02371","144.30843","0.00000"
"71.40000","2.37709","1442.23901","0.02377","144.22391","0.00001"
"71.60000","2.38375","1441.92761","0.02384","144.19276","0.00000"
"71.80000","2.39056","1442.13806","0.02391","144.21381","0.00000"
"72.00000","2.39714","1441.63953","0.02397","144.16396","0.00000"
"72.20000","2.40388","1441.64429","0.02404","144.16443","0.00001"
"72.40000","2.41050","1441.21631","0.02410","144.12163","0.00000"
"72.60000","2.41731","1441.23315","0.02417","144.12332","0.00000"
"72.80000","2.42382","1440.63892","0.02424","144.06389","-0.00001"
"73.00000","2.43048","1440.34253","0.02430","144.03426","0.00000"
"73.20000","2.43714","1440.09436","0.02437","144.00943","0.00001"
"73.40000","2.44374","1439.85718","0.02444","143.98572","0.00000"
"73.60000","2.45055","1439.76367","0.02451","143.97636","0.00000"
"73.80000","2.45720","1439.50781","0.02457","143.95078","0.00000"
"74.00000","2.46383","1439.13635","0.02464","143.91364","0.00000"
"74.20000","2.47061","1439.10608","0.02471","143.91061","0.00001"
"74.40000","2.47716","1438.42273","0.02477","143.84227","0.00000"
"74.60000","2.48382","1438.19934","0.02484","143.81993","0.00000"
"74.80000","2.49047","1437.86829","0.02490","143.78683","0.00000"
"75.00000","2.49722","1437.71167","0.02497","143.77116","0.00000"
"75.20000","2.50381","1437.22192","0.02504","143.72220","0.00001"
"75.40000","2.51039","1436.73376","0.02510","143.67337","0.00000"
"75.60000","2.51727","1436.91199","0.02517","143.69119","0.00000"
"75.80000","2.52381","1436.24207","0.02524","143.62421","0.00000"
"76.00000","2.53061","1436.27283","0.02531","143.62729","0.00001"
"76.20000","2.53721","1435.43127","0.02537","143.54312","0.00001"
"76.40000","2.54389","1434.83923","0.02544","143.48392","0.00000"
"76.60000","2.55058","1434.48621","0.02551","143.44862","0.00000"
"76.80000","2.55707","1433.39453","0.02557","143.33945","0.00000"
"77.00000","2.56380","1433.10547","0.02564","143.31055","0.00000"
"77.20000","2.57032","1432.43872","0.02570","143.24387","0.00000"
"77.40000","2.57730","1432.64905","0.02577","143.26491","0.00001"
"77.60000","2.58388","1431.93799","0.02584","143.19380","0.00000"
"77.80000","2.59056","1431.25598","0.02591","143.12560","0.00000"
"78.00000","2.59732","1431.01721","0.02597","143.10172","0.00001"
"78.20000","2.60378","1429.96240","0.02604","142.99625","0.00001"
"78.40000","2.61046","1428.95557","0.02610","142.89555","0.00000"
"78.60000","2.61707","1427.70544","0.02617","142.77054","0.00000"
"78.80000","2.62390","1426.92114","0.02624","142.69211","0.00000"
"79.00000","2.63045","1425.32275","0.02630","142.53227","0.00000"
"79.20000","2.63716","1423.51282","0.02637","142.35129","0.00000"
"79.40000","2.64391","1421.62988","0.02644","142.16299","0.00000"
"79.60000","2.65048","1417.62378","0.02650","141.76237","0.00000"
"79.80000","2.65733","1412.29053","0.02657","141.22905","0.00000"
"80.00000","2.66382","1405.18091","0.02664","140.51810","0.00001"
"80.20000","2.67051","1398.99255","0.02671","139.89926","0.00000"
"80.40000","2.67719","1392.18262","0.02677","139.21826","0.00000"
"80.60000","2.68381","1384.37842","0.02684","138.43784","0.00000"
"80.80000","2.69043","1351.18201","0.02690","135.11819","0.00000"
"80.86200","2.69267","1073.27039","0.02693","107.32704","0.00000"
"80.87000","2.69293","802.69336","0.02693","80.26933","0.00001"