File: Tension/Section_2_Group_2/epoxy_low_Sample_2.is_tens_RawData/Specimen_RawData_1.csv
Time,Extension,Load,Tensile strain (Extension),Tensile stress,Strain-by-clip-gage
(s),(mm),(N),(mm/mm),(MPa),(mm/mm)
"0.00000","0.00000","984.05707","0.00000","98.40571","0.00015"
"0.20000","0.00196","999.78467","0.00002","99.97847","0.00014"
"0.40000","0.01068","1075.05725","0.00011","107.50572","0.00012"
"0.60000","0.01747","1132.15161","0.00017","113.21516","0.00014"
"0.80000","0.02408","1186.90991","0.00024","118.69099","0.00014"
"1.00000","0.03073","1241.12891","0.00031","124.11289","0.00014"
"1.20000","0.03748","1296.18713","0.00037","129.61871","0.00015"
"1.40000","0.04407","1348.80505","0.00044","134.88051","0.00014"
"1.60000","0.05085","1402.41663","0.00051","140.24167","0.00013"
"1.80000","0.05742","1453.13037","0.00057","145.31303","0.00014"
"2.00000","0.06429","1505.48267","0.00064","150.54826","0.00015"
"2.20000","0.07079","1553.49402","0.00071","155.34940","0.00015"
"2.40000","0.07737","1601.01355","0.00077","160.10135","0.00014"
"2.60000","0.08420","1649.22327","0.00084","164.92233","0.00014"
"2.80000","0.09070","1692.53479","0.00091","169.25348","0.00013"
"3.00000","0.09750","1736.32166","0.00098","173.63217","0.00014"
"3.20000","0.10408","1776.33313","0.00104","177.63332","0.00015"
"3.40000","0.11087","1816.09875","0.00111","181.60988","0.00015"
"3.60000","0.11749","1852.57996","0.00117","185.25800","0.00014"
"3.80000","0.12415","1887.63110","0.00124","188.76311","0.00013"
"4.00000","0.13087","1922.06592","0.00131","192.20659","0.00013"
"4.20000","0.13739","1953.73596","0.00137","195.37360","0.00014"
"4.40000","0.14418","1987.16968","0.00144","198.71696","0.00015"
"4.60000","0.15075","2018.08679","0.00151","201.80869","0.00015"
"4.80000","0.15743","2049.93384","0.00157","204.99338","0.00014"
"5.00000","0.16419","2083.27246","0.00164","208.32724","0.00013"
"5.20000","0.17077","2115.51074","0.00171","211.55107","0.00014"
"5.40000","0.17748","2149.46069","0.00177","214.94608","0.00015"
"5.60000","0.18412","2183.10498","0.00184","218.31050","0.00015"
"5.80000","0.19092","2218.80200","0.00191","221.88020","0.00014"
"6.00000","0.19742","2251.91528","0.00197","225.19153","0.00013"
"6.20000","0.20404","2286.11035","0.00204","228.61104","0.00013"
"6.40000","0.21085","2322.86963","0.00211","232.28696","0.00014"
"6.60000","0.21740","2357.24902","0.00217","235.72490","0.00015"
"6.80000","0.22415","2393.58496","0.00224","239.35849","0.00015"
"7.00000","0.23085","2429.15137","0.00231","242.91513","0.00014"
"7.20000","0.23746","2463.72900","0.00237","246.37289","0.00013"
"7.40000","0.24418","2500.03491","0.00244","250.00349","0.00014"
"7.60000","0.25074","2534.69775","0.00251","253.46977","0.00014"
"7.80000","0.25748","2571.68701","0.00257","257.16870","0.00014"
"8.00000","0.26401","2607.03369","0.00264","260.70337","0.00014"
"8.20000","0.27086","2645.48218","0.00271","264.54822","0.00014"
"8.40000","0.27743","2681.24854","0.00277","268.12485","0.00013"
"8.60000","0.28406","2717.53174","0.00284","271.75317","0.00014"
"8.80000","0.29097","2756.83203","0.00291","275.68320","0.00014"
"9.00000","0.29739","2791.05640","0.00297","279.10565","0.00014"
"9.20000","0.30409","2828.20239","0.00304","282.82025","0.00013"
"9.40000","0.31072","2865.15259","0.00311","286.51526","0.00013"
"9.60000","0.31752","2903.37891","0.00318","290.33789","0.00014"
"9.80000","0.32410","2939.29272","0.00324","293.92926","0.00015"
"10.00000","0.33074","2975.64185","0.00331","297.56418","0.00015"
"10.20000","0.33755","3013.76465","0.00338","301.37646","0.00014"
"10.40000","0.34404","3049.09009","0.00344","304.90900","0.00013"
"10.60000","0.35094","3088.33447","0.00351","308.83344","0.00013"
"10.80000","0.35744","3123.91675","0.00357","312.39166","0.00014"
"11.00000","0.36410","3160.26440","0.00364","316.02643","0.00015"
"11.20000","0.37087","3198.31934","0.00371","319.83194","0.00014"
"11.40000","0.37742","3234.09033","0.00377","323.40903","0.00013"
"11.60000","0.38406","3270.78247","0.00384","327.07825","0.00014"
"11.80000","0.39076","3308.12744","0.00391","330.81274","0.00014"
"12.00000","0.39757","3346.74609","0.00398","334.67462","0.00015"
"12.20000","0.40413","3383.11304","0.00404","338.31131","0.00014"
"12.40000","0.41072","3419.47534","0.00411","341.94754","0.00014"
"12.60000","0.41755","3458.27002","0.00418","345.82700","0.00013"
"12.80000","0.42407","3493.99756","0.00424","349.39975","0.00014"
"13.00000","0.43082","3532.27344","0.00431","353.22736","0.00015"
"13.20000","0.43737","3568.54321","0.00437","356.85431","0.00015"
"13.40000","0.44407","3606.78540","0.00444","360.67853","0.00014"
"13.60000","0.45091","3646.21948","0.00451","364.62195","0.00014"
"13.80000","0.45743","3682.00610","0.00457","368.20062","0.00013"
"14.00000","0.46414","3720.09082","0.00464","372.00909","0.00014"
"14.20000","0.47073","3756.89233","0.00471","375.68924","0.00014"
"14.40000","0.47755","3795.98364","0.00478","379.59836","0.00014"
"14.60000","0.48413","3832.52100","0.00484","383.25211","0.00014"
"14.80000","0.49067","3868.54590","0.00491","386.85458","0.00014"
"15.00000","0.49755","3908.33569","0.00498","390.83356","0.00013"
"15.20000","0.50403","3943.78052","0.00504","394.37805","0.00015"
"15.40000","0.51080","3982.31445","0.00511","398.23145","0.00015"
"15.60000","0.51743","4019.57471","0.00517","401.95746","0.00014"
"15.80000","0.52418","4057.83984","0.00524","405.78400","0.00014"
"16.00000","0.53084","4095.12695","0.00531","409.51270","0.00014"
"16.20000","0.53739","4130.98340","0.00537","413.09833","0.00013"
"16.40000","0.54417","4169.07666","0.00544","416.90765","0.00015"
"16.60000","0.55065","4204.18213","0.00551","420.41821","0.00015"
"16.80000","0.55753","4243.51709","0.00558","424.35172","0.00014"
"17.00000","0.56405","4278.89697","0.00564","427.88971","0.00012"
"17.20000","0.57079","4316.57861","0.00571","431.65787","0.00013"
"17.40000","0.57752","4354.15332","0.00578","435.41534","0.00014"
"17.60000","0.58409","4389.92676","0.00584","438.99268","0.00015"
"17.80000","0.59083","4427.01758","0.00591","442.70175","0.00015"
"18.00000","0.59741","4462.61572","0.00597","446.26157","0.00013"
"18.20000","0.60423","4500.65967","0.00604","450.06598","0.00013"
"18.40000","0.61074","4535.41748","0.00611","453.54175","0.00014"
"18.60000","0.61736","4571.04150","0.00617","457.10416","0.00014"
"18.80000","0.62416","4609.11377","0.00624","460.91138","0.00015"
"19.00000","0.63075","4644.31445","0.00631","464.43146","0.00014"
"19.20000","0.63751","4681.18701","0.00638","468.11871","0.00013"
"19.40000","0.64408","4716.14209","0.00644","471.61420","0.00013"
"19.60000","0.65076","4752.04297","0.00651","475.20428","0.00014"
"19.80000","0.65752","4788.86328","0.00658","478.88632","0.00014"
"20.00000","0.66412","4823.71045","0.00664","482.37103","0.00014"
"20.20000","0.67078","4859.06543","0.00671","485.90656","0.00014"
"20.40000","0.67738","4894.01025","0.00677","489.40103","0.00013"
"20.60000","0.68418","4930.77393","0.00684","493.07739","0.00014"
"20.80000","0.69082","4966.27930","0.00691","496.62793","0.00015"
"21.00000","0.69734","4999.85352","0.00697","499.98535","0.00014"
"21.20000","0.70422","5037.33936","0.00704","503.73395","0.00013"
"21.40000","0.71069","5070.53125","0.00711","507.05313","0.00014"
"21.60000","0.71753","5107.30078","0.00718","510.73007","0.00013"
"21.80000","0.72415","5141.47412","0.00724","514.14740","0.00014"
"22.00000","0.73080","5175.91895","0.00731","517.59192","0.00015"
"22.20000","0.73747","5210.83008","0.00737","521.08301","0.00014"
"22.40000","0.74401","5244.06641","0.00744","524.40662","0.00013"
"22.60000","0.75085","5280.52002","0.00751","528.05200","0.00014"
"22.80000","0.75732","5313.08203","0.00757","531.30823","0.00014"
"23.00000","0.76421","5349.63184","0.00764","534.96320","0.00015"
"23.20000","0.77077","5382.69092","0.00771","538.26910","0.00015"
"23.40000","0.77741","5416.33350","0.00777","541.63336","0.00014"
"23.60000","0.78428","5452.59375","0.00784","545.25940","0.00013"
"23.80000","0.79070","5483.95508","0.00791","548.39551","0.00013"
"24.00000","0.79741","5518.32520","0.00797","551.83252","0.00014"
"24.20000","0.80405","5552.03662","0.00804","555.20367","0.00016"
"24.40000","0.81098","5587.97559","0.00811","558.79755","0.00017"
"24.60000","0.81739","5618.83350","0.00817","561.88336","0.00014"
"24.80000","0.82404","5651.96387","0.00824","565.19641","0.00013"
"25.00000","0.83087","5686.86670","0.00831","568.68665","0.00013"
"25.20000","0.83737","5717.79785","0.00837","571.77979","0.00014"
"25.40000","0.84427","5753.06641","0.00844","575.30664","0.00015"
"25.60000","0.85077","5784.41309","0.00851","578.44128","0.00015"
"25.80000","0.85741","5816.38281","0.00857","581.63831","0.00014"
"26.00000","0.86415","5850.04346","0.00864","585.00433","0.00013"
"26.20000","0.87079","5882.28174","0.00871","588.22815","0.00014"
"26.40000","0.87741","5914.29102","0.00877","591.42908","0.00014"
"26.60000","0.88404","5945.89209","0.00884","594.58923","0.00014"
"26.80000","0.89088","5979.49805","0.00891","597.94983","0.00014"
"27.00000","0.89749","6010.62988","0.00897","601.06299","0.00014"
"27.20000","0.90407","6040.74316","0.00904","604.07434","0.00014"
"27.40000","0.91093","6074.18506","0.00911","607.41852","0.00014"
"27.60000","0.91738","6103.29834","0.00917","610.32983","0.00015"
"27.80000","0.92411","6135.13379","0.00924","613.51337","0.00014"
"28.00000","0.93080","6166.17529","0.00931","616.61755","0.00013"
"28.20000","0.93744","6196.57617","0.00937","619.65759","0.00014"
"28.40000","0.94416","6227.95947","0.00944","622.79596","0.00015"
"28.60000","0.95070","6256.96338","0.00951","625.69635","0.00014"
"28.80000","0.95754","6289.35693","0.00958","628.93567","0.00014"
"29.00000","0.96408","6318.25391","0.00964","631.82538","0.00014"
"29.20000","0.97093","6350.11719","0.00971","635.01172","0.00014"
"29.40000","0.97748","6378.80957","0.00977","637.88098","0.00013"
"29.60000","0.98404","6407.33105","0.00984","640.73309","0.00014"
"29.80000","0.99096","6439.67236","0.00991","643.96722","0.00015"
"30.00000","0.99734","6465.90967","0.00997","646.59094","0.00014"
"30.20000","1.00409","6496.03662","0.01004","649.60364","0.00013"
"30.40000","1.01068","6524.28125","0.01011","652.42810","0.00013"
"30.60000","1.01758","6555.41699","0.01018","655.54169","0.00014"
"30.80000","1.02420","6583.87305","0.01024","658.38733","0.00014"
"31.00000","1.03079","6611.29736","0.01031","661.12976","0.00014"
"31.20000","1.03757","6640.21680","0.01038","664.02167","0.00014"
"31.40000","1.04400","6660.59326","0.01044","666.05933","0.00013"
"31.60000","1.05087","6690.32129","0.01051","669.03210","0.00014"
"31.80000","1.05738","6716.71533","0.01057","671.67151","0.00014"
"32.00000","1.06404","6744.23145","0.01064","674.42316","0.00014"
"32.20000","1.07082","6773.20508","0.01071","677.32050","0.00014"
"32.40000","1.07747","6800.46973","0.01077","680.04700","0.00013"
"32.60000","1.08418","6827.99658","0.01084","682.79968","0.00013"
"32.80000","1.09075","6854.06689","0.01091","685.40668","0.00014"
"33.00000","1.09765","6883.32227","0.01098","688.33221","0.00015"
"33.20000","1.10410","6907.99072","0.01104","690.79907","0.00015"
"33.40000","1.11071","6933.76514","0.01111","693.37653","0.00014"
"33.60000","1.11748","6961.25244","0.01117","696.12524","0.00013"
"33.80000","1.12403","6985.99219","0.01124","698.59924","0.00013"
"34.00000","1.13081","7013.22119","0.01131","701.32214","0.00015"
"34.20000","1.13746","7038.91748","0.01137","703.89172","0.00015"
"34.40000","1.14418","7064.85645","0.01144","706.48566","0.00015"
"34.60000","1.15095","7091.69678","0.01151","709.16968","0.00014"
"34.80000","1.15745","7114.92676","0.01157","711.49268","0.00013"
"35.00000","1.16415","7140.55469","0.01164","714.05548","0.00014"
"35.20000","1.17071","7164.12207","0.01171","716.41223","0.00014"
"35.40000","1.17750","7186.56104","0.01177","718.65613","0.00014"
"35.60000","1.18411","7202.48096","0.01184","720.24811","0.00014"
"35.80000","1.19064","7225.43018","0.01191","722.54303","0.00013"
"36.00000","1.19757","7251.00781","0.01198","725.10077","0.00013"
"36.20000","1.20412","7273.30273","0.01204","727.33026","0.00015"
"36.40000","1.21092","7297.92188","0.01211","729.79218","0.00014"
"36.60000","1.21750","7320.33496","0.01217","732.03351","0.00014"
"36.80000","1.22419","7343.02490","0.01224","734.30249","0.00013"
"37.00000","1.23087","7366.41211","0.01231","736.64124","0.00013"
"37.20000","1.23731","7388.18506","0.01237","738.81848","0.00013"
"37.40000","1.24418","7414.02441","0.01244","741.40247","0.00015"
"37.60000","1.25061","7435.14893","0.01251","743.51489","0.00015"
"37.80000","1.25755","7461.55615","0.01258","746.15564","0.00014"
"38.00000","1.26414","7484.37402","0.01264","748.43738","0.00013"
"38.20000","1.27087","7508.40479","0.01271","750.84045","0.00013"
"38.40000","1.27766","7533.19922","0.01278","753.31995","0.00014"
"38.60000","1.28409","7553.81641","0.01284","755.38165","0.00014"
"38.80000","1.29079","7577.05713","0.01291","757.70569","0.00015"
"39.00000","1.29732","7595.92822","0.01297","759.59283","0.00015"
"39.20000","1.30422","7619.60693","0.01304","761.96069","0.00014"
"39.40000","1.31077","7639.98828","0.01311","763.99884","0.00013"
"39.60000","1.31737","7660.73389","0.01317","766.07336","0.00016"
"39.80000","1.32424","7684.68359","0.01324","768.46838","0.00014"
"40.00000","1.33080","7704.92334","0.01331","770.49231","0.00013"
"40.20000","1.33759","7728.24121","0.01338","772.82410","0.00013"
"40.40000","1.34410","7748.26611","0.01344","774.82660","0.00013"
"40.60000","1.35081","7769.82471","0.01351","776.98248","0.00014"
"40.80000","1.35745","7791.38525","0.01357","779.13855","0.00016"
"41.00000","1.36409","7812.29639","0.01364","781.22961","0.00015"
"41.20000","1.37077","7833.62402","0.01371","783.36243","0.00012"
"41.40000","1.37737","7853.47168","0.01377","785.34717","0.00014"
"41.60000","1.38428","7876.46680","0.01384","787.64667","0.00015"
"41.80000","1.39088","7896.32422","0.01391","789.63245","0.00016"
"42.00000","1.39742","7915.09766","0.01397","791.50977","0.00015"
"42.20000","1.40422","7936.96436","0.01404","793.69641","0.00013"
"42.40000","1.41074","7955.51221","0.01411","795.55121","0.00013"
"42.60000","1.41739","7975.32715","0.01417","797.53271","0.00014"
"42.80000","1.42408","7995.54443","0.01424","799.55444","0.00014"
"43.00000","1.43082","8015.89404","0.01431","801.58942","0.00015"
"43.20000","1.43749","8035.55713","0.01437","803.55573","0.00014"
"43.40000","1.44409","8054.19385","0.01444","805.41937","0.00013"
"43.60000","1.45096","8075.92188","0.01451","807.59216","0.00013"
"43.80000","1.45740","8092.99414","0.01457","809.29944","0.00014"
"44.00000","1.46422","8113.64209","0.01464","811.36420","0.00015"
"44.20000","1.47080","8131.84619","0.01471","813.18463","0.00015"
"44.40000","1.47737","8149.39746","0.01477","814.93976","0.00014"
"44.60000","1.48423","8170.31055","0.01484","817.03107","0.00013"
"44.80000","1.49069","8186.96680","0.01491","818.69666","0.00013"
"45.00000","1.49747","8206.90820","0.01497","820.69080","0.00014"
"45.20000","1.50405","8225.05371","0.01504","822.50537","0.00015"
"45.40000","1.51100","8246.40723","0.01511","824.64075","0.00014"
"45.60000","1.51749","8262.70996","0.01517","826.27100","0.00013"
"45.80000","1.52410","8280.23145","0.01524","828.02313","0.00013"
"46.00000","1.53093","8299.97754","0.01531","829.99774","0.00013"
"46.20000","1.53733","8314.92676","0.01537","831.49268","0.00015"
"46.40000","1.54418","8334.59473","0.01544","833.45947","0.00015"
"46.60000","1.55075","8351.36914","0.01551","835.13690","0.00014"
"46.80000","1.55747","8369.00879","0.01557","836.90088","0.00013"
"47.00000","1.56420","8386.80957","0.01564","838.68097","0.00013"
"47.20000","1.57083","8402.80078","0.01571","840.28009","0.00014"
"47.40000","1.57752","8419.72656","0.01578","841.97266","0.00015"
"47.60000","1.58399","8434.34961","0.01584","843.43494","0.00015"
"47.80000","1.59090","8453.23730","0.01591","845.32373","0.00013"
"48.00000","1.59743","8468.48145","0.01597","846.84814","0.00013"
"48.20000","1.60406","8484.46191","0.01604","848.44617","0.00014"
"48.40000","1.61093","8502.93457","0.01611","850.29346","0.00016"
"48.60000","1.61738","8516.40625","0.01617","851.64062","0.00015"
"48.80000","1.62419","8533.50293","0.01624","853.35028","0.00013"
"49.00000","1.63074","8548.50977","0.01631","854.85095","0.00012"
"49.20000","1.63755","8565.70215","0.01638","856.57019","0.00013"
"49.40000","1.64416","8580.82324","0.01644","858.08234","0.00014"
"49.60000","1.65065","8594.23242","0.01651","859.42322","0.00015"
"49.80000","1.65758","8612.16016","0.01658","861.21600","0.00016"
"50.00000","1.66403","8624.99707","0.01664","862.49969","0.00014"
"50.20000","1.67084","8641.22656","0.01671","864.12268","0.00013"
"50.40000","1.67754","8656.62793","0.01678","865.66278","0.00013"
"50.60000","1.68407","8669.95703","0.01684","866.99573","0.00014"
"50.80000","1.69090","8686.67383","0.01691","868.66736","0.00015"
"51.00000","1.69737","8698.87891","0.01697","869.88788","0.00015"
"51.20000","1.70416","8713.62109","0.01704","871.36212","0.00011"
"51.40000","1.71069","8726.66406","0.01711","872.66638","0.00013"
"51.60000","1.71754","8731.32617","0.01718","873.13263","0.00015"
"51.80000","1.72415","8731.70898","0.01724","873.17090","0.00015"
"52.00000","1.73070","8746.20508","0.01731","874.62048","0.00015"
"52.20000","1.73764","8764.67676","0.01738","876.46765","0.00014"
"52.40000","1.74401","8776.93262","0.01744","877.69324","0.00013"
"52.60000","1.75078","8792.92090","0.01751","879.29211","0.00013"
"52.80000","1.75743","8807.30273","0.01757","880.73029","0.00014"
"53.00000","1.76417","8822.77441","0.01764","882.27747","0.00015"
"53.20000","1.77080","8837.26562","0.01771","883.72656","0.00013"
"53.40000","1.77738","8850.65918","0.01777","885.06592","0.00013"
"53.60000","1.78423","8866.48926","0.01784","886.64893","0.00014"
"53.80000","1.79072","8878.02246","0.01791","887.80225","0.00014"
"54.00000","1.79767","8858.40137","0.01798","885.84015","0.00015"
"54.20000","1.80410","8872.37598","0.01804","887.23761","0.00015"
"54.40000","1.81067","8887.12988","0.01811","888.71301","0.00013"
"54.60000","1.81756","8905.38672","0.01818","890.53870","0.00013"
"54.80000","1.82405","8918.33691","0.01824","891.83368","0.00015"
"55.00000","1.83077","8933.03906","0.01831","893.30389","0.00015"
"55.20000","1.83746","8946.91895","0.01837","894.69189","0.00014"
"55.40000","1.84423","8961.24707","0.01844","896.12469","0.00014"
"55.60000","1.85080","8973.56348","0.01851","897.35632","0.00012"
"55.80000","1.85739","8981.24609","0.01857","898.12463","0.00014"
"56.00000","1.86425","8988.77051","0.01864","898.87708","0.00014"
"56.20000","1.87068","8998.64844","0.01871","899.86487","0.00015"
"56.40000","1.87748","9012.62988","0.01877","901.26300","0.00015"
"56.60000","1.88410","9024.44238","0.01884","902.44421","0.00013"
"56.80000","1.89069","9035.54688","0.01891","903.55469","0.00012"
"57.00000","1.89762","9050.84277","0.01898","905.08429","0.00014"
"57.20000","1.90402","9059.97949","0.01904","905.99792","0.00014"
"57.40000","1.91082","9072.02441","0.01911","907.20245","0.00014"
"57.60000","1.91743","9082.54785","0.01917","908.25476","0.00014"
"57.80000","1.92430","9095.25586","0.01924","909.52557","0.00014"
"58.00000","1.93079","9104.23242","0.01931","910.42322","0.00013"
"58.20000","1.93724","9112.28613","0.01937","911.22864","0.00014"
"58.40000","1.94425","9126.86719","0.01944","912.68671","0.00015"
"58.60000","1.95064","9134.70117","0.01951","913.47009","0.00014"
"58.80000","1.95749","9146.56055","0.01957","914.65607","0.00013"
"59.00000","1.96411","9156.29297","0.01964","915.62927","0.00014"
"59.20000","1.97087","9166.16016","0.01971","916.61603","0.00013"
"59.40000","1.97760","9175.73828","0.01978","917.57385","0.00015"
"59.60000","1.98402","9182.07129","0.01984","918.20715","0.00015"
"59.80000","1.99076","9192.10254","0.01991","919.21027","0.00013"
"60.00000","1.99729","9197.50684","0.01997","919.75067","0.00013"
"60.20000","2.00423","9205.27637","0.02004","920.52765","0.00013"
"60.40000","2.01073","9211.25195","0.02011","921.12518","0.00014"
"60.60000","2.01742","9218.80078","0.02017","921.88007","0.00015"
"60.80000","2.02429","9228.12012","0.02024","922.81201","0.00014"
"61.00000","2.03072","9233.41699","0.02031","923.34167","0.00013"
"61.20000","2.03748","9241.44629","0.02037","924.14465","0.00013"
"61.40000","2.04407","9249.57324","0.02044","924.95734","0.00014"
"61.60000","2.05088","9257.89160","0.02051","925.78918","0.00014"
"61.80000","2.05746","9239.79297","0.02057","923.97931","0.00014"
"62.00000","2.06396","9245.17383","0.02064","924.51740","0.00014"
"62.20000","2.07084","9258.54980","0.02071","925.85498","0.00013"
"62.40000","2.07738","9268.81250","0.02077","926.88123","0.00014"
"62.60000","2.08421","9278.52051","0.02084","927.85205","0.00014"
"62.80000","2.09077","9287.08105","0.02091","928.70813","0.00014"
"63.00000","2.09742","9296.92285","0.02097","929.69226","0.00014"
"63.20000","2.10431","9284.25293","0.02104","928.42529","0.00014"
"63.40000","2.11073","9292.59180","0.02111","929.25916","0.00013"
"63.60000","2.11740","9298.74316","0.02117","929.87433","0.00013"
"63.80000","2.12402","9301.12695","0.02124","930.11267","0.00015"
"64.00000","2.13085","9314.55566","0.02131","931.45557","0.00015"
"64.20000","2.13751","9325.66406","0.02138","932.56641","0.00014"
"64.40000","2.14402","9335.33789","0.02144","933.53381","0.00013"
"64.60000","2.15094","9349.16992","0.02151","934.91699","0.00014"
"64.80000","2.15735","9357.40625","0.02157","935.74060","0.00014"
"65.00000","2.16417","9369.52930","0.02164","936.95294","0.00015"
"65.20000","2.17080","9379.62207","0.02171","937.96222","0.00014"
"65.40000","2.17742","9389.11719","0.02177","938.91174","0.00013"
"65.60000","2.18416","9399.79883","0.02184","939.97986","0.00014"
"65.80000","2.19067","9408.08496","0.02191","940.80847","0.00014"
"66.00000","2.19753","9412.08105","0.02198","941.20813","0.00014"
"66.20000","2.20402","9408.77539","0.02204","940.87756","0.00014"
"66.40000","2.21091","9418.64648","0.02211","941.86462","0.00013"
"66.60000","2.21745","9416.94922","0.02217","941.69495","0.00013"
"66.80000","2.22406","9415.80566","0.02224","941.58057","0.00013"
"67.00000","2.23097","9417.82617","0.02231","941.78259","0.00014"
"67.20000","2.23732","9421.99707","0.02237","942.19971","0.00015"
"67.40000","2.24407","9430.46094","0.02244","943.04608","0.00014"
"67.60000","2.25071","9438.86914","0.02251","943.88690","0.00013"
"67.80000","2.25760","9450.42188","0.02258","945.04218","0.00014"
"68.00000","2.26411","9458.17676","0.02264","945.81769","0.00012"
"68.20000","2.27074","9466.84375","0.02271","946.68439","0.00013"
"68.40000","2.27749","9477.07129","0.02277","947.70715","0.00014"
"68.60000","2.28404","9484.88965","0.02284","948.48895","0.00013"
"68.80000","2.29098","9496.60742","0.02291","949.66077","0.00014"
"69.00000","2.29744","9502.88965","0.02297","950.28894","0.00014"
"69.20000","2.30402","9510.29297","0.02304","951.02930","0.00014"
"69.40000","2.31085","9520.47363","0.02311","952.04736","0.00014"
"69.60000","2.31744","9527.81152","0.02317","952.78113","0.00014"
"69.80000","2.32409","9535.10938","0.02324","953.51093","0.00014"
"70.00000","2.33071","9542.17285","0.02331","954.21729","0.00013"
"70.20000","2.33752","9550.84375","0.02338","955.08435","0.00013"
"70.40000","2.34418","9557.99707","0.02344","955.79968","0.00015"
"70.60000","2.35076","9563.64160","0.02351","956.36414","0.00014"
"70.80000","2.35754","9571.46484","0.02358","957.14648","0.00014"
"71.00000","2.36402","9575.97363","0.02364","957.59735","0.00014"
"71.20000","2.37081","9583.62207","0.02371","958.36218","0.00013"
"71.40000","2.37747","9589.90332","0.02377","958.99036","0.00014"
"71.60000","2.38407","9594.97949","0.02384","959.49792","0.00014"
"71.80000","2.39084","9602.07520","0.02391","960.20752","0.00014"
"72.00000","2.39737","9606.60449","0.02397","960.66046","0.00013"
"72.20000","2.40419","9613.92285","0.02404","961.39227","0.00014"
"72.40000","2.41077","9618.90039","0.02411","961.89001","0.00013"
"72.60000","2.41762","9625.80273","0.02418","962.58026","0.00014"
"72.80000","2.42415","9629.58301","0.02424","962.95831","0.00015"
"73.00000","2.43067","9633.02441","0.02431","963.30243","0.00014"
"73.20000","2.43760","9640.39648","0.02438","964.03967","0.00014"
"73.40000","2.44401","9642.40234","0.02444","964.24023","0.00014"
"73.60000","2.45077","9557.48340","0.02451","955.74835","0.00011"
"73.80000","2.45736","9562.50488","0.02457","956.25049","0.00013"
"74.00000","2.46422","9572.91211","0.02464","957.29120","0.00015"
"74.20000","2.47092","9581.66992","0.02471","958.16699","0.00015"
"74.40000","2.47745","9590.11719","0.02477","959.01172","0.00013"
"74.60000","2.48417","9601.04199","0.02484","960.10419","0.00013"
"74.78500","2.49017","9474.88672","0.02490","947.48865","0.00015"
"74.79700","2.49057","9211.92773","0.02491","921.19275","0.00015"
"74.81200","2.49115","8943.93359","0.02491","894.39337","0.00016"
"74.84500","2.49248","8683.72754","0.02492","868.37274","0.00012"
"75.04500","2.49905","8579.51465","0.02499","857.95148","0.00019"
"75.24500","2.50567","8589.24219","0.02506","858.92419","0.00012"
"75.44500","2.51224","8607.22559","0.02512","860.72253","0.00013"
"75.64500","2.51898","8628.48242","0.02519","862.84827","0.00016"
"75.71600","2.52146","8365.06738","0.02521","836.50671","0.00012"
"75.72000","2.52157","8013.70312","0.02522","801.37030","0.00013"
"75.72400","2.52170","7592.39941","0.02522","759.23993","0.00013"
"75.72800","2.52184","7144.57471","0.02522","714.45746","0.00013"
"75.73200","2.52201","6701.89648","0.02522","670.18964","0.00011"
"75.73600","2.52220","6286.32227","0.02522","628.63220","0.00010"
"75.74000","2.52242","5911.93164","0.02522","591.19318","0.00008"
"75.74400","2.52266","5586.26904","0.02523","558.62689","0.00006"
"75.74800","2.52292","5312.02979","0.02523","531.20300","0.00004"
"75.75100","2.52313","5139.82080","0.02523","513.98206","0.00002"