File: Tension/Section_2_Group_2/Hybrid_High_Sample_1_2.is_tens_RawData/Specimen_RawData_1.csv
Time,Extension,Load,Tensile strain (Extension),Tensile stress,Strain-by-clip-gage
(s),(mm),(N),(mm/mm),(MPa),(mm/mm)
"0.00000","0.00000","-29.17803","0.00000","-2.91780","0.00001"
"0.20000","0.00154","-20.34081","0.00002","-2.03408","-0.00001"
"0.40000","0.01038","40.65958","0.00010","4.06596","-0.00004"
"0.60000","0.01694","83.44534","0.00017","8.34453","-0.00002"
"0.80000","0.02375","126.84612","0.00024","12.68461","0.00001"
"1.00000","0.03033","167.08401","0.00030","16.70840","0.00002"
"1.20000","0.03692","205.77357","0.00037","20.57736","0.00000"
"1.40000","0.04376","245.67810","0.00044","24.56781","0.00001"
"1.60000","0.05020","281.94421","0.00050","28.19442","-0.00001"
"1.80000","0.05695","319.49261","0.00057","31.94926","-0.00001"
"2.00000","0.06367","356.08188","0.00064","35.60819","0.00001"
"2.20000","0.07052","392.70828","0.00071","39.27083","0.00002"
"2.40000","0.07704","426.83566","0.00077","42.68357","0.00000"
"2.60000","0.08365","460.47812","0.00084","46.04781","-0.00003"
"2.80000","0.09039","494.84204","0.00090","49.48420","0.00002"
"3.00000","0.09685","526.43958","0.00097","52.64396","0.00005"
"3.20000","0.10372","559.96881","0.00104","55.99688","-0.00004"
"3.40000","0.11025","591.20007","0.00110","59.12001","0.00001"
"3.60000","0.11702","623.14014","0.00117","62.31401","0.00002"
"3.80000","0.12381","654.68915","0.00124","65.46892","-0.00003"
"4.00000","0.13036","683.97375","0.00130","68.39738","0.00000"
"4.20000","0.13699","713.61414","0.00137","71.36141","0.00002"
"4.40000","0.14359","742.19916","0.00144","74.21992","0.00000"
"4.60000","0.15044","772.33655","0.00150","77.23366","-0.00003"
"4.80000","0.15691","799.19550","0.00157","79.91955","0.00001"
"5.00000","0.16362","827.31183","0.00164","82.73119","0.00001"
"5.20000","0.17038","855.69623","0.00170","85.56963","0.00001"
"5.40000","0.17694","882.70410","0.00177","88.27041","0.00002"
"5.60000","0.18369","910.61591","0.00184","91.06159","0.00000"
"5.80000","0.19040","938.14154","0.00190","93.81416","-0.00003"
"6.00000","0.19705","964.98492","0.00197","96.49849","-0.00002"
"6.20000","0.20371","991.90680","0.00204","99.19068","0.00003"
"6.40000","0.21029","1018.11298","0.00210","101.81129","0.00001"
"6.60000","0.21696","1044.62573","0.00217","104.46257","0.00001"
"6.80000","0.22358","1071.13953","0.00224","107.11395","0.00000"
"7.00000","0.23038","1098.74170","0.00230","109.87417","-0.00003"
"7.20000","0.23706","1125.19580","0.00237","112.51958","-0.00002"
"7.40000","0.24363","1150.60486","0.00244","115.06049","0.00002"
"7.60000","0.25049","1178.37427","0.00250","117.83743","0.00002"
"7.80000","0.25696","1203.13135","0.00257","120.31313","0.00001"
"8.00000","0.26364","1229.59436","0.00264","122.95943","0.00000"
"8.20000","0.27025","1255.56750","0.00270","125.55675","-0.00002"
"8.40000","0.27703","1282.25146","0.00277","128.22514","-0.00001"
"8.60000","0.28371","1308.18152","0.00284","130.81815","0.00002"
"8.80000","0.29029","1332.94287","0.00290","133.29428","0.00003"
"9.00000","0.29706","1359.10120","0.00297","135.91013","-0.00001"
"9.20000","0.30356","1382.88843","0.00304","138.28885","-0.00002"
"9.40000","0.31044","1409.22693","0.00310","140.92270","-0.00001"
"9.60000","0.31697","1432.74463","0.00317","143.27446","0.00000"
"9.80000","0.32363","1456.73474","0.00324","145.67348","0.00002"
"10.00000","0.33041","1481.74292","0.00330","148.17429","0.00002"
"10.20000","0.33695","1504.19006","0.00337","150.41901","-0.00001"
"10.40000","0.34366","1528.01782","0.00344","152.80179","-0.00002"
"10.60000","0.35023","1550.46997","0.00350","155.04700","-0.00001"
"10.80000","0.35710","1574.94299","0.00357","157.49429","0.00001"
"11.00000","0.36368","1597.11340","0.00364","159.71133","0.00002"
"11.20000","0.37035","1619.20044","0.00370","161.92004","0.00000"
"11.40000","0.37705","1641.90918","0.00377","164.19092","-0.00001"
"11.60000","0.38354","1662.48535","0.00384","166.24854","-0.00001"
"11.80000","0.39033","1685.46216","0.00390","168.54622","0.00000"
"12.00000","0.39698","1707.08630","0.00397","170.70863","0.00001"
"12.20000","0.40364","1728.76807","0.00404","172.87680","0.00001"
"12.40000","0.41042","1750.99915","0.00410","175.09991","-0.00001"
"12.60000","0.41701","1771.43799","0.00417","177.14380","-0.00001"
"12.80000","0.42367","1792.19897","0.00424","179.21989","-0.00001"
"13.00000","0.43024","1812.55103","0.00430","181.25510","0.00001"
"13.20000","0.43709","1834.77295","0.00437","183.47729","0.00001"
"13.40000","0.44364","1854.55457","0.00444","185.45546","0.00000"
"13.60000","0.45024","1874.78589","0.00450","187.47859","0.00001"
"13.80000","0.45710","1896.53577","0.00457","189.65358","-0.00004"
"14.00000","0.46358","1915.17383","0.00464","191.51738","-0.00003"
"14.20000","0.47036","1936.69336","0.00470","193.66934","0.00007"
"14.40000","0.47701","1956.50476","0.00477","195.65048","-0.00002"
"14.60000","0.48370","1976.67200","0.00484","197.66721","-0.00003"
"14.80000","0.49034","1997.18005","0.00490","199.71800","0.00005"
"15.00000","0.49695","2016.39941","0.00497","201.63994","-0.00001"
"15.20000","0.50368","2036.75757","0.00504","203.67575","0.00000"
"15.40000","0.51016","2055.26587","0.00510","205.52658","0.00002"
"15.60000","0.51704","2076.22510","0.00517","207.62251","-0.00003"
"15.80000","0.52365","2095.84985","0.00524","209.58499","-0.00001"
"16.00000","0.53031","2115.17407","0.00530","211.51741","0.00002"
"16.20000","0.53714","2136.31592","0.00537","213.63159","0.00001"
"16.40000","0.54360","2153.98047","0.00544","215.39804","0.00000"
"16.60000","0.55026","2172.75952","0.00550","217.27596","-0.00001"
"16.80000","0.55692","2191.95190","0.00557","219.19519","-0.00001"
"17.00000","0.56376","2212.26196","0.00564","221.22620","-0.00002"
"17.20000","0.57028","2230.14551","0.00570","223.01456","0.00001"
"17.40000","0.57695","2248.98096","0.00577","224.89810","0.00001"
"17.60000","0.58374","2268.91309","0.00584","226.89131","0.00000"
"17.80000","0.59023","2285.99268","0.00590","228.59927","-0.00001"
"18.00000","0.59708","2306.06079","0.00597","230.60608","-0.00001"
"18.20000","0.60365","2323.85864","0.00604","232.38586","0.00001"
"18.40000","0.61032","2341.91113","0.00610","234.19112","0.00002"
"18.60000","0.61704","2360.91162","0.00617","236.09116","0.00001"
"18.80000","0.62361","2378.26270","0.00624","237.82626","0.00000"
"19.00000","0.63026","2396.41504","0.00630","239.64151","-0.00001"
"19.20000","0.63695","2414.12671","0.00637","241.41267","-0.00002"
"19.40000","0.64377","2433.17358","0.00644","243.31735","0.00001"
"19.60000","0.65036","2449.99780","0.00650","244.99979","0.00001"
"19.80000","0.65694","2466.71558","0.00657","246.67155","0.00000"
"20.00000","0.66376","2485.37891","0.00664","248.53789","-0.00001"
"20.20000","0.67026","2501.51196","0.00670","250.15120","-0.00002"
"20.40000","0.67696","2518.89331","0.00677","251.88933","-0.00001"
"20.60000","0.68363","2536.18799","0.00684","253.61880","0.00002"
"20.80000","0.69032","2553.27588","0.00690","255.32759","0.00001"
"21.00000","0.69708","2570.82495","0.00697","257.08249","0.00001"
"21.20000","0.70358","2586.33765","0.00704","258.63376","0.00002"
"21.40000","0.71040","2604.34595","0.00710","260.43460","-0.00003"
"21.60000","0.71689","2619.95117","0.00717","261.99512","-0.00002"
"21.80000","0.72374","2638.17432","0.00724","263.81744","0.00003"
"22.00000","0.73032","2654.03247","0.00730","265.40326","0.00002"
"22.20000","0.73690","2669.32422","0.00737","266.93243","-0.00001"
"22.40000","0.74375","2687.11865","0.00744","268.71185","0.00000"
"22.60000","0.75023","2701.54395","0.00750","270.15439","-0.00001"
"22.80000","0.75695","2717.70020","0.00757","271.77002","0.00000"
"23.00000","0.76357","2733.67310","0.00764","273.36731","0.00002"
"23.20000","0.77043","2751.01685","0.00770","275.10168","0.00001"
"23.40000","0.77704","2766.34058","0.00777","276.63406","-0.00001"
"23.60000","0.78359","2780.55566","0.00784","278.05557","-0.00001"
"23.80000","0.79039","2797.05713","0.00790","279.70572","0.00000"
"24.00000","0.79686","2810.75269","0.00797","281.07526","0.00001"
"24.20000","0.80368","2827.39819","0.00804","282.73981","0.00001"
"24.40000","0.81024","2841.80835","0.00810","284.18085","0.00000"
"24.60000","0.81703","2857.67090","0.00817","285.76709","-0.00001"
"24.80000","0.82372","2873.13818","0.00824","287.31381","-0.00002"
"25.00000","0.83031","2887.24536","0.00830","288.72455","0.00002"
"25.20000","0.83699","2902.09473","0.00837","290.20947","0.00000"
"25.40000","0.84356","2915.57178","0.00844","291.55719","0.00000"
"25.60000","0.85045","2932.05615","0.00850","293.20563","0.00001"
"25.80000","0.85695","2944.98340","0.00857","294.49835","0.00000"
"26.00000","0.86358","2958.45386","0.00864","295.84540","-0.00002"
"26.20000","0.87039","2973.64697","0.00870","297.36469","0.00001"
"26.40000","0.87696","2986.37402","0.00877","298.63739","0.00001"
"26.60000","0.88362","2999.87988","0.00884","299.98798","-0.00001"
"26.80000","0.89029","3013.52783","0.00890","301.35278","-0.00001"
"27.00000","0.89701","3027.20361","0.00897","302.72037","0.00000"
"27.20000","0.90372","3040.56641","0.00904","304.05664","0.00001"
"27.40000","0.91034","3053.00122","0.00910","305.30011","0.00001"
"27.60000","0.91697","3065.04175","0.00917","306.50418","0.00001"
"27.80000","0.92358","3077.57812","0.00924","307.75781","-0.00001"
"28.00000","0.93038","3090.97314","0.00930","309.09732","-0.00001"
"28.20000","0.93702","3103.34814","0.00937","310.33481","0.00000"
"28.40000","0.94358","3114.49585","0.00944","311.44958","0.00001"
"28.60000","0.95043","3127.86353","0.00950","312.78635","0.00001"
"28.80000","0.95692","3137.89331","0.00957","313.78934","0.00000"
"29.00000","0.96367","3149.44360","0.00964","314.94437","-0.00001"
"29.20000","0.97030","3160.26587","0.00970","316.02658","-0.00001"
"29.40000","0.97705","3171.53442","0.00977","317.15344","0.00001"
"29.60000","0.98368","3182.07446","0.00984","318.20746","0.00001"
"29.80000","0.99025","3191.91895","0.00990","319.19189","0.00000"
"30.00000","0.99710","3204.03052","0.00997","320.40305","-0.00001"
"30.20000","1.00352","3212.15503","0.01004","321.21552","-0.00001"
"30.40000","1.01034","3223.58496","0.01010","322.35849","-0.00001"
"30.60000","1.01695","3233.17090","0.01017","323.31708","0.00001"
"30.80000","1.02365","3242.79858","0.01024","324.27985","0.00001"
"31.00000","1.03048","3253.76587","0.01030","325.37659","0.00000"
"31.20000","1.03697","3261.01294","0.01037","326.10129","-0.00001"
"31.40000","1.04362","3269.85986","0.01044","326.98599","-0.00001"
"31.60000","1.05021","3277.85278","0.01050","327.78528","0.00000"
"31.80000","1.05717","3288.08911","0.01057","328.80890","0.00001"
"32.00000","1.06360","3294.28906","0.01064","329.42889","0.00001"
"32.20000","1.07024","3301.41748","0.01070","330.14175","-0.00001"
"32.40000","1.07705","3310.44531","0.01077","331.04453","-0.00001"
"32.60000","1.08358","3316.41431","0.01084","331.64142","-0.00001"
"32.80000","1.09042","3325.10962","0.01090","332.51096","0.00000"
"33.00000","1.09698","3331.27124","0.01097","333.12714","0.00001"
"33.20000","1.10370","3338.55566","0.01104","333.85556","0.00000"
"33.40000","1.11037","3345.81616","0.01110","334.58160","0.00000"
"33.60000","1.11700","3352.18945","0.01117","335.21893","-0.00001"
"33.80000","1.12361","3358.67896","0.01124","335.86789","0.00000"
"34.00000","1.13022","3365.00562","0.01130","336.50055","0.00001"
"34.20000","1.13707","3373.20557","0.01137","337.32056","0.00001"
"34.40000","1.14367","3379.50635","0.01144","337.95062","0.00000"
"34.60000","1.15031","3385.31909","0.01150","338.53192","-0.00001"
"34.80000","1.15711","3392.00562","0.01157","339.20056","-0.00001"
"35.00000","1.16364","3396.29468","0.01164","339.62946","0.00000"
"35.20000","1.17029","3400.92749","0.01170","340.09274","0.00002"
"35.40000","1.17697","3405.75415","0.01177","340.57541","-0.00001"
"35.60000","1.18368","3410.01831","0.01184","341.00183","-0.00001"
"35.80000","1.19035","3413.28784","0.01190","341.32880","0.00002"
"36.00000","1.19690","3415.32007","0.01197","341.53201","-0.00002"
"36.20000","1.20374","3419.32129","0.01204","341.93213","-0.00001"
"36.40000","1.21026","3420.60449","0.01210","342.06046","0.00003"
"36.60000","1.21712","3424.14087","0.01217","342.41409","0.00000"
"36.80000","1.22371","3425.21582","0.01224","342.52158","-0.00003"
"37.00000","1.23029","3425.74487","0.01230","342.57449","0.00001"
"37.20000","1.23714","3428.74146","0.01237","342.87415","0.00003"
"37.40000","1.24358","3428.07886","0.01244","342.80789","0.00000"
"37.60000","1.25026","3429.61255","0.01250","342.96124","0.00000"
"37.80000","1.25683","3430.17505","0.01257","343.01752","-0.00001"
"38.00000","1.26381","3433.25220","0.01264","343.32523","-0.00002"
"38.20000","1.27038","3433.26001","0.01270","343.32599","0.00000"
"38.40000","1.27704","3433.58325","0.01277","343.35834","0.00002"
"38.60000","1.28381","3435.08472","0.01284","343.50848","0.00000"
"38.80000","1.29024","3433.13770","0.01290","343.31378","-0.00001"
"39.00000","1.29701","3433.88013","0.01297","343.38800","-0.00001"
"39.20000","1.30357","3432.29468","0.01304","343.22946","-0.00001"
"39.40000","1.31033","3431.87744","0.01310","343.18774","0.00000"
"39.60000","1.31701","3430.61987","0.01317","343.06198","0.00002"
"39.80000","1.32368","3428.31860","0.01324","342.83185","0.00001"
"40.00000","1.33040","3426.37891","0.01330","342.63788","-0.00002"
"40.20000","1.33694","3423.08740","0.01337","342.30875","-0.00001"
"40.40000","1.34387","3423.31519","0.01344","342.33151","0.00000"
"40.60000","1.35032","3419.11279","0.01350","341.91129","0.00001"
"40.80000","1.35695","3415.62964","0.01357","341.56296","0.00001"
"41.00000","1.36370","3412.78027","0.01364","341.27802","0.00000"
"41.20000","1.37029","3408.16382","0.01370","340.81638","-0.00001"
"41.40000","1.37693","3403.95898","0.01377","340.39590","-0.00001"
"41.60000","1.38363","3400.30151","0.01384","340.03015","0.00000"
"41.80000","1.39043","3397.48828","0.01390","339.74884","0.00002"
"42.00000","1.39712","3393.64771","0.01397","339.36478","0.00000"
"42.20000","1.40369","3387.96631","0.01404","338.79663","-0.00002"
"42.40000","1.41039","3382.61768","0.01410","338.26178","-0.00001"
"42.60000","1.41688","3375.62866","0.01417","337.56287","0.00000"
"42.80000","1.42367","3371.02930","0.01424","337.10294","0.00001"
"43.00000","1.43031","3365.19922","0.01430","336.51993","0.00001"
"43.20000","1.43690","3359.20679","0.01437","335.92068","0.00000"
"43.40000","1.44374","3356.02124","0.01444","335.60211","-0.00002"
"43.60000","1.45035","3351.07739","0.01450","335.10773","-0.00002"
"43.80000","1.45711","3347.97314","0.01457","334.79730","0.00001"
"44.00000","1.46365","3343.46826","0.01464","334.34683","0.00002"
"44.20000","1.47044","3341.16895","0.01470","334.11688","0.00000"
"44.40000","1.47703","3337.28638","0.01477","333.72864","-0.00001"
"44.60000","1.48355","3332.58740","0.01484","333.25873","-0.00001"
"44.80000","1.49041","3330.87866","0.01490","333.08786","-0.00001"
"45.00000","1.49683","3324.94238","0.01497","332.49423","0.00001"
"45.20000","1.50368","3322.81689","0.01504","332.28168","0.00002"
"45.40000","1.51036","3318.96802","0.01510","331.89679","0.00000"
"45.60000","1.51715","3315.10449","0.01517","331.51044","-0.00002"
"45.80000","1.52376","3308.77930","0.01524","330.87793","-0.00001"
"46.00000","1.53032","3300.43701","0.01530","330.04370","0.00001"
"46.20000","1.53701","3292.48633","0.01537","329.24863","0.00001"
"46.40000","1.54352","3281.82642","0.01544","328.18265","0.00000"
"46.60000","1.55043","3273.86401","0.01550","327.38641","-0.00001"
"46.80000","1.55693","3261.88208","0.01557","326.18820","-0.00001"
"47.00000","1.56360","3251.27441","0.01564","325.12744","-0.00001"
"47.20000","1.57045","3243.16772","0.01570","324.31677","0.00002"
"47.40000","1.57703","3232.92456","0.01577","323.29245","0.00001"
"47.60000","1.58374","3224.02686","0.01584","322.40268","-0.00001"
"47.80000","1.59030","3214.31616","0.01590","321.43161","-0.00002"
"48.00000","1.59708","3206.14062","0.01597","320.61407","-0.00001"
"48.20000","1.60360","3195.83716","0.01604","319.58371","0.00000"
"48.40000","1.61027","3186.65771","0.01610","318.66577","0.00001"
"48.60000","1.61704","3178.17358","0.01617","317.81735","0.00001"
"48.80000","1.62360","3167.12549","0.01624","316.71255","-0.00001"
"49.00000","1.63043","3157.93481","0.01630","315.79349","-0.00001"
"49.20000","1.63709","3147.29736","0.01637","314.72974","0.00000"
"49.40000","1.64368","3136.15527","0.01644","313.61554","0.00001"
"49.60000","1.65038","3127.37109","0.01650","312.73712","0.00001"
"49.80000","1.65696","3118.55908","0.01657","311.85590","-0.00001"
"50.00000","1.66359","3110.72949","0.01664","311.07294","-0.00001"
"50.20000","1.67028","3103.75830","0.01670","310.37582","0.00000"
"50.40000","1.67707","3097.01978","0.01677","309.70197","0.00000"
"50.60000","1.68369","3088.98193","0.01684","308.89819","0.00002"
"50.80000","1.69029","3080.12622","0.01690","308.01263","0.00000"
"51.00000","1.69717","3074.70557","0.01697","307.47055","-0.00002"
"51.20000","1.70361","3065.68555","0.01704","306.56854","-0.00001"
"51.40000","1.71030","3058.45190","0.01710","305.84518","0.00000"
"51.60000","1.71698","3052.54761","0.01717","305.25476","0.00001"
"51.80000","1.72367","3045.81543","0.01724","304.58154","0.00001"
"52.00000","1.73039","3040.19897","0.01730","304.01990","-0.00001"
"52.20000","1.73695","3032.49170","0.01737","303.24918","-0.00002"
"52.40000","1.74366","3026.39160","0.01744","302.63916","-0.00001"
"52.60000","1.75024","3019.42529","0.01750","301.94254","0.00001"
"52.80000","1.75719","3014.84009","0.01757","301.48401","0.00001"
"53.00000","1.76366","3005.04858","0.01764","300.50485","0.00000"
"53.20000","1.77029","2996.17041","0.01770","299.61703","-0.00001"
"53.40000","1.77709","2988.76855","0.01777","298.87686","-0.00001"
"53.60000","1.78357","2977.14160","0.01784","297.71417","-0.00001"
"53.80000","1.79033","2967.24634","0.01790","296.72464","0.00001"
"54.00000","1.79695","2955.66675","0.01797","295.56668","0.00002"
"54.20000","1.80377","2945.89233","0.01804","294.58923","-0.00001"
"54.40000","1.81039","2934.86890","0.01810","293.48688","-0.00002"
"54.60000","1.81702","2924.59644","0.01817","292.45966","-0.00001"
"54.80000","1.82371","2916.14722","0.01824","291.61472","0.00001"
"55.00000","1.83019","2906.10815","0.01830","290.61081","0.00002"
"55.20000","1.83703","2898.78687","0.01837","289.87869","0.00000"
"55.40000","1.84366","2889.69702","0.01844","288.96970","-0.00001"
"55.60000","1.85030","2879.37402","0.01850","287.93741","-0.00001"
"55.80000","1.85711","2869.96875","0.01857","286.99689","0.00000"
"56.00000","1.86365","2857.87842","0.01864","285.78784","0.00001"
"56.20000","1.87033","2846.12622","0.01870","284.61261","0.00001"
"56.40000","1.87695","2833.23218","0.01877","283.32321","-0.00001"
"56.60000","1.88377","2821.96338","0.01884","282.19635","-0.00002"
"56.80000","1.89030","2808.19629","0.01890","280.81964","-0.00001"
"57.00000","1.89694","2794.92969","0.01897","279.49298","0.00001"
"57.20000","1.90375","2783.51440","0.01904","278.35144","0.00001"
"57.40000","1.91025","2769.27930","0.01910","276.92792","0.00000"
"57.60000","1.91701","2757.60132","0.01917","275.76013","-0.00001"
"57.80000","1.92368","2746.35938","0.01924","274.63593","-0.00001"
"58.00000","1.93037","2734.44287","0.01930","273.44427","-0.00001"
"58.20000","1.93705","2723.12427","0.01937","272.31244","0.00001"
"58.40000","1.94363","2710.92041","0.01944","271.09204","0.00001"
"58.60000","1.95033","2699.88208","0.01950","269.98822","0.00000"
"58.80000","1.95684","2687.21680","0.01957","268.72168","-0.00002"
"59.00000","1.96374","2676.76147","0.01964","267.67615","0.00000"
"59.20000","1.97032","2662.67432","0.01970","266.26743","0.00001"
"59.40000","1.97694","2646.92578","0.01977","264.69257","0.00002"
"59.60000","1.98381","2633.10791","0.01984","263.31079","0.00000"
"59.80000","1.99026","2615.60425","0.01990","261.56042","-0.00001"
"60.00000","1.99697","2599.76489","0.01997","259.97650","-0.00001"
"60.20000","2.00360","2583.99219","0.02004","258.39923","0.00001"
"60.40000","2.01037","2569.37769","0.02010","256.93777","0.00001"
"60.60000","2.01701","2553.65967","0.02017","255.36597","0.00000"
"60.80000","2.02366","2536.58521","0.02024","253.65852","0.00000"
"61.00000","2.03041","2518.97021","0.02030","251.89702","-0.00002"
"61.20000","2.03689","2497.77124","0.02037","249.77713","0.00000"
"61.40000","2.04378","2478.81079","0.02044","247.88107","0.00001"
"61.60000","2.05032","2457.46069","0.02050","245.74606","0.00002"
"61.80000","2.05696","2437.33740","0.02057","243.73373","0.00000"
"62.00000","2.06371","2418.86377","0.02064","241.88638","-0.00002"
"62.20000","2.07026","2399.90771","0.02070","239.99077","-0.00001"
"62.40000","2.07697","2382.88086","0.02077","238.28809","0.00000"
"62.60000","2.08363","2364.85083","0.02084","236.48508","0.00001"
"62.80000","2.09043","2348.32642","0.02090","234.83264","0.00001"
"63.00000","2.09701","2330.65527","0.02097","233.06552","0.00000"
"63.20000","2.10365","2313.35986","0.02104","231.33598","-0.00002"
"63.40000","2.11041","2298.58887","0.02110","229.85889","-0.00001"
"63.60000","2.11689","2282.16846","0.02117","228.21684","0.00002"
"63.80000","2.12368","2268.62109","0.02124","226.86211","0.00001"
"64.00000","2.13031","2254.04736","0.02130","225.40474","0.00000"
"64.20000","2.13694","2240.67993","0.02137","224.06799","-0.00001"
"64.40000","2.14376","2229.05469","0.02144","222.90547","-0.00001"
"64.60000","2.15028","2214.75024","0.02150","221.47502","0.00000"
"64.80000","2.15701","2203.23120","0.02157","220.32312","0.00001"
"65.00000","2.16361","2191.48364","0.02164","219.14836","0.00000"
"65.20000","2.17046","2182.31470","0.02170","218.23148","0.00000"
"65.40000","2.17697","2171.95044","0.02177","217.19504","-0.00001"
"65.60000","2.18353","2162.47412","0.02184","216.24741","0.00000"
"65.80000","2.19041","2156.66870","0.02190","215.66687","0.00001"
"66.00000","2.19689","2147.11157","0.02197","214.71115","0.00001"
"66.20000","2.20365","2140.03833","0.02204","214.00383","0.00000"
"66.40000","2.21029","2132.33984","0.02210","213.23398","-0.00001"
"66.60000","2.21708","2125.72266","0.02217","212.57227","0.00000"
"66.80000","2.22374","2118.57056","0.02224","211.85706","0.00000"
"67.00000","2.23028","2109.40820","0.02230","210.94083","0.00001"
"67.20000","2.23700","2102.08911","0.02237","210.20891","0.00001"
"67.40000","2.24351","2093.13892","0.02244","209.31389","0.00000"
"67.60000","2.25039","2087.58569","0.02250","208.75858","-0.00001"
"67.80000","2.25694","2079.79834","0.02257","207.97983","0.00000"
"68.00000","2.26368","2073.28125","0.02264","207.32812","0.00000"
"68.20000","2.27040","2066.83545","0.02270","206.68355","-0.00001"
"68.40000","2.27695","2059.22583","0.02277","205.92258","0.00000"
"68.60000","2.28366","2053.97021","0.02284","205.39702","0.00000"
"68.80000","2.29025","2048.01416","0.02290","204.80142","0.00000"
"69.00000","2.29711","2044.89514","0.02297","204.48952","0.00000"
"69.20000","2.30361","2039.62476","0.02304","203.96248","0.00001"
"69.40000","2.31027","2036.30408","0.02310","203.63040","0.00000"
"69.60000","2.31705","2034.53540","0.02317","203.45354","0.00000"
"69.80000","2.32359","2029.88477","0.02324","202.98848","-0.00001"
"70.00000","2.33032","2026.79358","0.02330","202.67935","0.00000"
"70.20000","2.33697","2022.32324","0.02337","202.23233","0.00000"
"70.40000","2.34368","2017.46863","0.02344","201.74686","0.00001"
"70.60000","2.35044","2013.10352","0.02350","201.31035","0.00001"
"70.80000","2.35698","2006.57922","0.02357","200.65793","0.00000"
"71.00000","2.36361","2000.75586","0.02364","200.07559","-0.00001"
"71.20000","2.37024","1995.12744","0.02370","199.51274","0.00000"
"71.40000","2.37705","1991.30701","0.02377","199.13071","0.00001"
"71.60000","2.38370","1986.99475","0.02384","198.69948","0.00000"
"71.80000","2.39024","1982.07678","0.02390","198.20767","0.00002"
"72.00000","2.39713","1979.98657","0.02397","197.99866","-0.00001"
"72.20000","2.40358","1974.18164","0.02404","197.41817","-0.00003"
"72.40000","2.41034","1970.65637","0.02410","197.06564","-0.00006"
"72.60000","2.41696","1966.46680","0.02417","196.64668","-0.00002"
"72.80000","2.42367","1962.72827","0.02424","196.27283","0.00009"
"73.00000","2.43037","1959.16626","0.02430","195.91663","0.00001"
"73.20000","2.43693","1954.61792","0.02437","195.46179","-0.00002"
"73.40000","2.44375","1953.14026","0.02444","195.31403","-0.00002"
"73.60000","2.45020","1949.07202","0.02450","194.90720","-0.00004"
"73.80000","2.45703","1947.92188","0.02457","194.79219","0.00003"
"74.00000","2.46362","1944.78003","0.02464","194.47800","0.00004"
"74.20000","2.47029","1941.29175","0.02470","194.12918","-0.00003"
"74.40000","2.47717","1940.10962","0.02477","194.01096","0.00000"
"74.60000","2.48361","1935.51233","0.02484","193.55124","0.00002"
"74.80000","2.49027","1932.30066","0.02490","193.23007","-0.00002"
"75.00000","2.49690","1929.68750","0.02497","192.96875","0.00000"
"75.20000","2.50380","1928.79834","0.02504","192.87984","0.00002"
"75.40000","2.51028","1925.35950","0.02510","192.53595","-0.00001"
"75.60000","2.51693","1923.35022","0.02517","192.33502","-0.00001"
"75.80000","2.52372","1923.10425","0.02524","192.31042","0.00001"
"76.00000","2.53025","1920.46606","0.02530","192.04660","0.00000"
"76.20000","2.53711","1920.33069","0.02537","192.03307","0.00000"
"76.40000","2.54361","1917.26587","0.02544","191.72659","-0.00001"
"76.60000","2.55033","1916.02649","0.02550","191.60265","-0.00001"
"76.80000","2.55704","1914.92920","0.02557","191.49292","0.00000"
"77.00000","2.56369","1912.65051","0.02564","191.26505","0.00001"
"77.20000","2.57026","1909.69482","0.02570","190.96948","0.00000"
"77.40000","2.57691","1907.89697","0.02577","190.78970","0.00000"
"77.60000","2.58375","1907.13623","0.02584","190.71362","-0.00001"
"77.80000","2.59031","1903.67834","0.02590","190.36783","-0.00001"
"78.00000","2.59698","1900.61499","0.02597","190.06149","0.00002"
"78.20000","2.60376","1898.91370","0.02604","189.89137","0.00001"
"78.40000","2.61029","1894.78198","0.02610","189.47820","0.00000"
"78.60000","2.61698","1892.20569","0.02617","189.22057","0.00000"
"78.80000","2.62367","1889.89978","0.02624","188.98997","-0.00002"
"79.00000","2.63034","1886.81372","0.02630","188.68137","0.00000"
"79.20000","2.63700","1883.04431","0.02637","188.30443","0.00002"
"79.40000","2.64356","1878.29187","0.02644","187.82919","0.00000"
"79.60000","2.65039","1875.86060","0.02650","187.58606","-0.00001"
"79.80000","2.65693","1870.90576","0.02657","187.09058","0.00000"
"80.00000","2.66382","1868.30164","0.02664","186.83017","-0.00001"
"80.20000","2.67036","1863.22888","0.02670","186.32289","0.00000"
"80.40000","2.67693","1858.27222","0.02677","185.82722","0.00002"
"80.60000","2.68380","1856.77673","0.02684","185.67767","0.00001"
"80.80000","2.69025","1851.73914","0.02690","185.17392","-0.00002"
"81.00000","2.69695","1849.26208","0.02697","184.92621","-0.00001"
"81.20000","2.70353","1846.09875","0.02704","184.60988","0.00000"
"81.40000","2.71046","1846.01001","0.02710","184.60100","0.00000"
"81.60000","2.71707","1844.10156","0.02717","184.41016","0.00001"
"81.80000","2.72369","1842.43225","0.02724","184.24323","0.00000"
"82.00000","2.73042","1842.44324","0.02730","184.24432","-0.00002"
"82.20000","2.73689","1840.30530","0.02737","184.03053","-0.00001"
"82.40000","2.74376","1840.88464","0.02744","184.08847","0.00001"
"82.60000","2.75027","1838.78503","0.02750","183.87851","0.00001"
"82.80000","2.75696","1837.78723","0.02757","183.77872","0.00000"
"83.00000","2.76365","1837.04028","0.02764","183.70403","-0.00001"
"83.20000","2.77032","1835.28552","0.02770","183.52855","-0.00001"
"83.40000","2.77706","1833.54724","0.02777","183.35472","-0.00001"
"83.60000","2.78364","1830.48511","0.02784","183.04851","0.00001"
"83.80000","2.79050","1829.17285","0.02790","182.91728","0.00002"
"84.00000","2.79699","1824.87891","0.02797","182.48788","0.00000"
"84.20000","2.80363","1820.79846","0.02804","182.07985","-0.00001"
"84.40000","2.81034","1817.17017","0.02810","181.71701","-0.00001"
"84.60000","2.81690","1812.71375","0.02817","181.27138","0.00000"
"84.80000","2.82361","1809.15430","0.02824","180.91544","0.00001"
"85.00000","2.83033","1805.55103","0.02830","180.55510","0.00000"
"85.20000","2.83706","1802.41003","0.02837","180.24100","-0.00001"
"85.40000","2.84377","1800.10156","0.02844","180.01016","-0.00001"
"85.60000","2.85033","1796.77441","0.02850","179.67744","0.00000"
"85.80000","2.85700","1794.33984","0.02857","179.43399","0.00001"
"86.00000","2.86358","1791.48181","0.02864","179.14818","0.00001"
"86.20000","2.87036","1790.26929","0.02870","179.02693","0.00000"
"86.40000","2.87697","1788.51025","0.02877","178.85103","-0.00001"
"86.60000","2.88356","1786.80396","0.02884","178.68039","-0.00002"
"86.80000","2.89045","1788.27844","0.02890","178.82785","0.00000"
"87.00000","2.89700","1786.84961","0.02897","178.68497","0.00003"
"87.20000","2.90374","1787.25122","0.02904","178.72513","0.00000"
"87.40000","2.91034","1787.11792","0.02910","178.71179","-0.00002"
"87.60000","2.91709","1787.29797","0.02917","178.72980","-0.00001"
"87.80000","2.92371","1786.77344","0.02924","178.67734","0.00000"
"88.00000","2.93026","1784.75513","0.02930","178.47551","0.00001"
"88.20000","2.93705","1784.93323","0.02937","178.49332","0.00001"
"88.40000","2.94347","1781.90613","0.02943","178.19061","0.00000"
"88.60000","2.95039","1783.53101","0.02950","178.35310","-0.00002"
"88.80000","2.95703","1782.87732","0.02957","178.28773","-0.00001"
"89.00000","2.96379","1782.40576","0.02964","178.24057","0.00001"
"89.20000","2.97048","1781.27734","0.02970","178.12773","0.00002"
"89.40000","2.97697","1777.74133","0.02977","177.77414","0.00000"
"89.60000","2.98366","1775.98315","0.02984","177.59831","-0.00002"
"89.80000","2.99016","1771.71765","0.02990","177.17177","-0.00001"
"90.00000","2.99710","1770.82434","0.02997","177.08243","0.00000"
"90.20000","3.00358","1765.93518","0.03004","176.59352","0.00001"
"90.40000","3.01030","1761.91846","0.03010","176.19185","0.00002"
"90.60000","3.01713","1758.93994","0.03017","175.89400","-0.00001"
"90.80000","3.02369","1753.79846","0.03024","175.37985","-0.00002"
"91.00000","3.03041","1750.55005","0.03030","175.05501","-0.00001"
"91.20000","3.03696","1746.76697","0.03037","174.67670","0.00001"
"91.40000","3.04371","1743.80164","0.03044","174.38016","0.00002"
"91.60000","3.05029","1738.72742","0.03050","173.87274","0.00001"
"91.80000","3.05698","1733.22485","0.03057","173.32248","-0.00001"
"92.00000","3.06363","1727.03931","0.03064","172.70393","-0.00002"
"92.20000","3.07028","1721.02246","0.03070","172.10225","0.00000"
"92.40000","3.07711","1716.91870","0.03077","171.69186","0.00002"
"92.60000","3.08374","1711.78613","0.03084","171.17862","0.00001"
"92.80000","3.09033","1706.56836","0.03090","170.65683","-0.00001"
"93.00000","3.09707","1703.12708","0.03097","170.31271","-0.00002"
"93.20000","3.10362","1697.97388","0.03104","169.79739","0.00000"
"93.40000","3.11024","1694.12122","0.03110","169.41212","0.00001"
"93.60000","3.11696","1692.03723","0.03117","169.20372","0.00001"
"93.80000","3.12368","1690.16418","0.03124","169.01642","0.00001"
"94.00000","3.13036","1688.03259","0.03130","168.80325","-0.00002"
"94.20000","3.13698","1684.28052","0.03137","168.42805","-0.00002"
"94.40000","3.14385","1683.03992","0.03144","168.30399","0.00000"
"94.60000","3.15029","1678.15540","0.03150","167.81554","0.00002"
"94.80000","3.15705","1675.94055","0.03157","167.59406","0.00001"
"95.00000","3.16363","1673.32324","0.03164","167.33232","-0.00001"
"95.20000","3.17027","1671.40137","0.03170","167.14014","-0.00002"
"95.40000","3.17706","1671.84937","0.03177","167.18494","-0.00001"
"95.60000","3.18361","1669.60364","0.03184","166.96036","0.00001"
"95.80000","3.19032","1668.46350","0.03190","166.84634","0.00002"
"96.00000","3.19695","1666.80334","0.03197","166.68033","0.00000"
"96.20000","3.20386","1666.38696","0.03204","166.63870","-0.00002"
"96.40000","3.21035","1661.89685","0.03210","166.18968","-0.00002"
"96.60000","3.21694","1656.63806","0.03217","165.66380","0.00001"
"96.80000","3.22377","1652.99329","0.03224","165.29933","0.00002"
"97.00000","3.23022","1646.12378","0.03230","164.61238","0.00001"
"97.20000","3.23701","1642.70325","0.03237","164.27032","-0.00001"
"97.40000","3.24360","1637.77734","0.03244","163.77774","-0.00002"
"97.60000","3.25040","1634.51733","0.03250","163.45174","0.00000"
"97.80000","3.25706","1630.75684","0.03257","163.07568","0.00002"
"98.00000","3.26370","1626.19458","0.03264","162.61946","0.00002"
"98.20000","3.27036","1620.79272","0.03270","162.07927","0.00000"
"98.40000","3.27690","1614.07214","0.03277","161.40721","-0.00002"
"98.60000","3.28376","1610.00513","0.03284","161.00052","-0.00001"
"98.80000","3.29030","1602.75684","0.03290","160.27568","0.00001"
"99.00000","3.29694","1596.69934","0.03297","159.66994","0.00002"
"99.20000","3.30375","1592.05908","0.03304","159.20590","0.00001"
"99.40000","3.31032","1585.17273","0.03310","158.51727","-0.00001"
"99.60000","3.31698","1579.19226","0.03317","157.91922","-0.00002"
"99.80000","3.32370","1574.60437","0.03324","157.46043","0.00000"
"100.00000","3.33044","1570.89404","0.03330","157.08940","0.00001"
"100.20000","3.33697","1566.30627","0.03337","156.63063","0.00001"
"100.40000","3.34360","1563.10315","0.03344","156.31032","-0.00001"
"100.60000","3.35037","1561.15137","0.03350","156.11514","-0.00001"
"100.80000","3.35690","1557.34583","0.03357","155.73459","0.00000"
"101.00000","3.36370","1555.64856","0.03364","155.56485","0.00001"
"101.20000","3.37035","1552.55737","0.03370","155.25574","0.00002"
"101.40000","3.37699","1549.16467","0.03377","154.91647","-0.00003"
"101.60000","3.38375","1547.37207","0.03384","154.73721","-0.00002"
"101.80000","3.39028","1543.59338","0.03390","154.35934","-0.00001"
"102.00000","3.39693","1540.36316","0.03397","154.03632","0.00001"
"102.20000","3.40355","1537.40015","0.03404","153.74002","0.00001"
"102.40000","3.41042","1535.72656","0.03410","153.57266","0.00001"
"102.60000","3.41699","1531.91370","0.03417","153.19138","-0.00001"
"102.61100","3.41737","1531.86438","0.03417","153.18643","0.00000"