File: Specimen_RawData_1.csv
Test : Rate 1,"1.50000",mm/min
Test : Rate 2,"-5.00000",mm/min

Time,Extension,Load
(s),(mm),(N)
"0.00000","0.00000","0.58068"
"0.10000","0.00057","0.58170"
"0.20000","0.00414","0.56848"
"0.30000","0.00748","0.59679"
"0.40000","0.00997","0.62538"
"0.50000","0.01247","0.60963"
"0.60000","0.01507","0.60223"
"0.70000","0.01757","0.61839"
"0.80000","0.01995","0.63542"
"0.90000","0.02250","0.62066"
"1.00000","0.02499","0.61973"
"1.10000","0.02760","0.63464"
"1.20000","0.03009","0.63665"
"1.30000","0.03247","0.63975"
"1.40000","0.03508","0.63723"
"1.50000","0.03768","0.60497"
"1.60000","0.04006","0.67775"
"1.70000","0.04250","0.62291"
"1.80000","0.04505","0.63862"
"1.90000","0.04749","0.60645"
"2.00000","0.05015","0.60821"
"2.10000","0.05253","0.65006"
"2.20000","0.05497","0.64868"
"2.30000","0.05763","0.68190"
"2.40000","0.06012","0.65421"
"2.50000","0.06256","0.67696"
"2.60000","0.06500","0.67986"
"2.70000","0.06749","0.66109"
"2.80000","0.07010","0.66059"
"2.90000","0.07259","0.70284"
"3.00000","0.07497","0.69637"
"3.10000","0.07752","0.71044"
"3.20000","0.08013","0.66410"
"3.30000","0.08262","0.64379"
"3.40000","0.08506","0.69246"
"3.50000","0.08749","0.69436"
"3.60000","0.09004","0.71321"
"3.70000","0.09265","0.70160"
"3.80000","0.09509","0.68376"
"3.90000","0.09747","0.74010"
"4.00000","0.10007","0.77259"
"4.10000","0.10257","0.70741"
"4.20000","0.10512","0.70147"
"4.30000","0.10761","0.70725"
"4.40000","0.10999","0.75405"
"4.50000","0.11254","0.74405"
"4.60000","0.11509","0.73698"
"4.70000","0.11758","0.73182"
"4.80000","0.12002","0.74653"
"4.90000","0.12251","0.74528"
"5.00000","0.12506","0.71103"
"5.10000","0.12761","0.77332"
"5.20000","0.12994","0.79002"
"5.30000","0.13254","0.76937"
"5.40000","0.13504","0.75154"
"5.50000","0.13759","0.77129"
"5.60000","0.14002","0.76558"
"5.70000","0.14252","0.79608"
"5.80000","0.14501","0.79797"
"5.90000","0.14756","0.77140"
"6.00000","0.15011","0.74554"
"6.10000","0.15260","0.78183"
"6.20000","0.15504","0.78223"
"6.30000","0.15759","0.81089"
"6.40000","0.16003","0.77623"
"6.50000","0.16258","0.75300"
"6.60000","0.16513","0.80547"
"6.70000","0.16756","0.80835"
"6.80000","0.17017","0.78664"
"6.90000","0.17249","0.79433"
"7.00000","0.17504","0.82068"
"7.10000","0.17754","0.85144"
"7.20000","0.18003","0.82870"
"7.30000","0.18247","0.82828"
"7.40000","0.18507","0.81950"
"7.50000","0.18751","0.84634"
"7.60000","0.19006","0.80828"
"7.70000","0.19261","0.82409"
"7.80000","0.19499","0.82393"
"7.90000","0.19754","0.85040"
"8.00000","0.20009","0.83918"
"8.10000","0.20253","0.85177"
"8.20000","0.20496","0.86698"
"8.30000","0.20757","0.82804"
"8.40000","0.21012","0.86883"
"8.50000","0.21261","0.82044"
"8.60000","0.21505","0.88605"
"8.70000","0.21749","0.85898"
"8.80000","0.22009","0.81985"
"8.90000","0.22264","0.86368"
"9.00000","0.22508","0.86132"
"9.10000","0.22763","0.85546"
"9.20000","0.23007","0.85152"
"9.30000","0.23262","0.88184"
"9.40000","0.23511","0.87732"
"9.50000","0.23749","0.90504"
"9.60000","0.24010","0.92232"
"9.70000","0.24259","0.90947"
"9.80000","0.24508","0.89400"
"9.90000","0.24758","0.91934"
"10.00000","0.25001","0.89809"
"10.10000","0.25256","0.93035"
"10.20000","0.25511","0.94443"
"10.30000","0.25761","0.89293"
"10.40000","0.25999","0.92076"
"10.50000","0.26254","0.93423"
"10.60000","0.26520","0.95624"
"10.70000","0.26758","0.92219"
"10.80000","0.26996","0.95134"
"10.90000","0.27257","0.94601"
"11.00000","0.27512","0.92199"
"11.10000","0.27767","0.95620"
"11.20000","0.27999","0.92375"
"11.30000","0.28254","0.97224"
"11.40000","0.28503","0.96241"
"11.50000","0.28764","0.96396"
"11.60000","0.29002","0.98781"
"11.70000","0.29251","0.93536"
"11.80000","0.29506","0.94363"
"11.90000","0.29761","1.00097"
"12.00000","0.30011","0.98695"
"12.10000","0.30249","0.96763"
"12.20000","0.30504","0.95998"
"12.30000","0.30759","0.99812"
"12.40000","0.31014","0.95028"
"12.50000","0.31252","1.02505"
"12.60000","0.31501","1.00920"
"12.70000","0.31756","0.97422"
"12.80000","0.32011","1.02262"
"12.90000","0.32255","1.00628"
"13.00000","0.32504","0.97403"
"13.10000","0.32753","1.03713"
"13.20000","0.33003","0.99196"
"13.30000","0.33263","1.02416"
"13.40000","0.33507","1.00146"
"13.50000","0.33751","1.01974"
"13.60000","0.34011","1.02794"
"13.70000","0.34261","1.03844"
"13.80000","0.34504","0.99984"
"13.90000","0.34754","1.03637"
"14.00000","0.35003","1.03918"
"14.10000","0.35258","1.03766"
"14.20000","0.35513","1.06784"
"14.30000","0.35751","1.03061"
"14.40000","0.36000","1.05654"
"14.50000","0.36267","1.05517"
"14.60000","0.36505","1.02229"
"14.70000","0.36748","1.04444"
"14.80000","0.37009","1.06603"
"14.90000","0.37253","1.08247"
"15.00000","0.37508","1.08287"
"15.10000","0.37763","1.09713"
"15.20000","0.38006","1.11080"
"15.30000","0.38250","1.07402"
"15.40000","0.38505","1.09733"
"15.50000","0.38749","1.06371"
"15.60000","0.39009","1.07067"
"15.70000","0.39259","1.07844"
"15.80000","0.39514","1.07655"
"15.90000","0.39757","1.09579"
"16.00000","0.40001","1.09912"
"16.10000","0.40256","1.09811"
"16.20000","0.40505","1.12675"
"16.30000","0.40755","1.13097"
"16.40000","0.40998","1.09162"
"16.50000","0.41259","1.10456"
"16.60000","0.41503","1.10794"
"16.70000","0.41758","1.12899"
"16.80000","0.42007","1.11940"
"16.90000","0.42251","1.09682"
"17.00000","0.42506","1.12283"
"17.10000","0.42761","1.11393"
"17.20000","0.42999","1.16014"
"17.30000","0.43254","1.13418"
"17.40000","0.43514","1.13539"
"17.50000","0.43758","1.16643"
"17.60000","0.44013","1.14267"
"17.70000","0.44251","1.16835"
"17.80000","0.44500","1.16917"
"17.90000","0.44761","1.17740"
"18.00000","0.45005","1.16079"
"18.10000","0.45260","1.16864"
"18.20000","0.45503","1.15981"
"18.30000","0.45753","1.15420"
"18.40000","0.46013","1.13409"
"18.50000","0.46257","1.14525"
"18.60000","0.46495","1.25456"
"18.70000","0.46761","1.23241"
"18.80000","0.47011","1.16563"
"18.90000","0.47260","1.17354"
"19.00000","0.47504","1.19972"
"19.10000","0.47759","1.17654"
"19.20000","0.48008","1.19405"
"19.30000","0.48257","1.22653"
"19.40000","0.48501","1.23063"
"19.50000","0.48750","1.21426"
"19.60000","0.49011","1.23542"
"19.70000","0.49266","1.24602"
"19.80000","0.49504","1.20700"
"19.90000","0.49753","1.16492"
"20.00000","0.50003","1.23011"
"20.10000","0.50263","1.22923"
"20.20000","0.50513","1.21056"
"20.30000","0.50745","1.23705"
"20.40000","0.51011","1.25309"
"20.50000","0.51255","1.26695"
"20.60000","0.51510","1.26509"
"20.70000","0.51754","1.24162"
"20.80000","0.51997","1.19571"
"20.90000","0.52252","1.25982"
"21.00000","0.52513","1.22965"
"21.10000","0.52751","1.23551"
"21.20000","0.53000","1.26435"
"21.30000","0.53261","1.23785"
"21.40000","0.53510","1.25810"
"21.50000","0.53760","1.21623"
"21.60000","0.54003","1.24472"
"21.70000","0.54253","1.26441"
"21.80000","0.54508","1.24168"
"21.90000","0.54763","1.25845"
"22.00000","0.55006","1.25826"
"22.10000","0.55256","1.24513"
"22.20000","0.55499","1.26563"
"22.30000","0.55754","1.28963"
"22.40000","0.56015","1.31461"
"22.50000","0.56253","1.27099"
"22.60000","0.56508","1.30493"
"22.70000","0.56763","1.26959"
"22.80000","0.57012","1.29697"
"22.90000","0.57250","1.31229"
"23.00000","0.57500","1.32420"
"23.10000","0.57755","1.31699"
"23.20000","0.58015","1.31383"
"23.30000","0.58253","1.30763"
"23.40000","0.58497","1.31301"
"23.50000","0.58752","1.32491"
"23.60000","0.59007","1.34281"
"23.70000","0.59256","1.33910"
"23.80000","0.59500","1.36701"
"23.90000","0.59755","1.34720"
"24.00000","0.60010","1.34232"
"24.10000","0.60265","1.36459"
"24.20000","0.60514","1.36887"
"24.30000","0.60758","1.37099"
"24.40000","0.61002","1.34060"
"24.50000","0.61257","1.35181"
"24.60000","0.61506","1.36161"
"24.70000","0.61755","1.37544"
"24.80000","0.62005","1.34631"
"24.90000","0.62265","1.35456"
"25.00000","0.62498","1.34083"
"25.10000","0.62753","1.35216"
"25.20000","0.63008","1.41160"
"25.30000","0.63257","1.39557"
"25.40000","0.63501","1.38080"
"25.50000","0.63756","1.39513"
"25.60000","0.64005","1.40065"
"25.70000","0.64254","1.42005"
"25.80000","0.64509","1.36217"
"25.90000","0.64753","1.39858"
"26.00000","0.65002","1.41107"
"26.10000","0.65252","1.41213"
"26.20000","0.65501","1.41176"
"26.30000","0.65750","1.41163"
"26.40000","0.66000","1.40195"
"26.50000","0.66266","1.40866"
"26.60000","0.66515","1.45433"
"26.70000","0.66759","1.41887"
"26.80000","0.67003","1.38837"
"26.90000","0.67263","1.41325"
"27.00000","0.67518","1.45607"
"27.10000","0.67756","1.43551"
"27.20000","0.68006","1.40898"
"27.30000","0.68249","1.42309"
"27.40000","0.68504","1.43240"
"27.50000","0.68765","1.42251"
"27.60000","0.68997","1.44383"
"27.70000","0.69247","1.46219"
"27.80000","0.69513","1.42550"
"27.90000","0.69757","1.43984"
"28.00000","0.70000","1.47824"
"28.10000","0.70255","1.47743"
"28.20000","0.70505","1.48133"
"28.30000","0.70760","1.44528"
"28.40000","0.71009","1.46970"
"28.50000","0.71247","1.52894"
"28.60000","0.71508","1.48676"
"28.70000","0.71768","1.46375"
"28.80000","0.72006","1.47376"
"28.90000","0.72250","1.47612"
"29.00000","0.72505","1.49440"
"29.10000","0.72754","1.48611"
"29.20000","0.73021","1.48861"
"29.30000","0.73259","1.46382"
"29.40000","0.73502","1.50896"
"29.50000","0.73763","1.52458"
"29.60000","0.74007","1.51546"
"29.70000","0.74262","1.52803"
"29.80000","0.74505","1.50174"
"29.90000","0.74749","1.53348"
"30.00000","0.75010","1.50974"
"30.10000","0.75259","1.48538"
"30.20000","0.75497","1.53831"
"30.30000","0.75752","1.52634"
"30.40000","0.76013","1.52911"
"30.50000","0.76262","1.53295"
"30.60000","0.76506","1.52123"
"30.70000","0.76755","1.53169"
"30.80000","0.77004","1.54560"
"30.90000","0.77259","1.56712"
"31.00000","0.77509","1.56568"
"31.10000","0.77752","1.51579"
"31.20000","0.78007","1.53779"
"31.30000","0.78251","1.56382"
"31.40000","0.78512","1.53958"
"31.50000","0.78761","1.56160"
"31.60000","0.79005","1.56386"
"31.70000","0.79260","1.56078"
"31.80000","0.79509","1.59391"
"31.90000","0.79764","1.57181"
"32.00000","0.80002","1.56610"
"32.10000","0.80251","1.56306"
"32.20000","0.80506","1.59596"
"32.30000","0.80761","1.57562"
"32.40000","0.80994","1.60717"
"32.50000","0.81254","1.62596"
"32.60000","0.81509","1.57374"
"32.70000","0.81759","1.61404"
"32.80000","0.81997","1.61861"
"32.90000","0.82252","1.64178"
"33.00000","0.82495","1.61688"
"33.10000","0.82756","1.58632"
"33.20000","0.83011","1.62360"
"33.30000","0.83260","1.60941"
"33.40000","0.83504","1.63008"
"33.50000","0.83759","1.59880"
"33.60000","0.84003","1.62295"
"33.70000","0.84252","1.62386"
"33.80000","0.84507","1.61231"
"33.90000","0.84756","1.63214"
"34.00000","0.85017","1.64434"
"34.10000","0.85249","1.62721"
"34.20000","0.85504","1.63990"
"34.30000","0.85759","1.64475"
"34.40000","0.86009","1.64475"
"34.50000","0.86252","1.64385"
"34.60000","0.86507","1.67174"
"34.70000","0.86751","1.62943"
"34.80000","0.87012","1.67052"
"34.90000","0.87261","1.67644"
"35.00000","0.87499","1.68171"
"35.10000","0.87754","1.66348"
"35.20000","0.88009","1.70748"
"35.30000","0.88253","1.67623"
"35.40000","0.88496","1.67326"
"35.50000","0.88757","1.66773"
"35.60000","0.89012","1.68182"
"35.70000","0.89261","1.66719"
"35.80000","0.89505","1.68117"
"35.90000","0.89749","1.70850"
"36.00000","0.90009","1.71193"
"36.10000","0.90264","1.68617"
"36.20000","0.90508","1.72086"
"36.30000","0.90763","1.69297"
"36.40000","0.91007","1.69181"
"36.50000","0.91262","1.70904"
"36.60000","0.91511","1.72642"
"36.70000","0.91743","1.69754"
"36.80000","0.92010","1.68493"
"36.90000","0.92259","1.73339"
"37.00000","0.92508","1.75201"
"37.10000","0.92758","1.67134"
"37.20000","0.93001","1.70514"
"37.30000","0.93256","1.73139"
"37.40000","0.93511","1.73544"
"37.50000","0.93761","1.74948"
"37.60000","0.93999","1.71726"
"37.70000","0.94259","1.74719"
"37.80000","0.94520","1.75142"
"37.90000","0.94758","1.76516"
"38.00000","0.94996","1.75667"
"38.10000","0.95257","1.77924"
"38.20000","0.95512","1.79418"
"38.30000","0.95767","1.78869"
"38.40000","0.95999","1.76932"
"38.50000","0.96254","1.75579"
"38.60000","0.96503","1.80327"
"38.70000","0.96764","1.78266"
"38.80000","0.97008","1.80330"
"38.90000","0.97251","1.81194"
"39.00000","0.97506","1.80556"
"39.10000","0.97761","1.77839"
"39.20000","0.98011","1.79057"
"39.30000","0.98249","1.80882"
"39.40000","0.98504","1.81997"
"39.50000","0.98759","1.78680"
"39.60000","0.99014","1.78841"
"39.70000","0.99252","1.80818"
"39.80000","0.99501","1.80279"
"39.90000","0.99756","1.83664"
"40.00000","1.00011","1.81590"
"40.10000","1.00260","1.77688"
"40.20000","1.00504","1.79111"
"40.30000","1.00748","1.79637"
"40.40000","1.01008","1.83429"
"40.50000","1.01263","1.81926"
"40.60000","1.01507","1.82575"
"40.70000","1.01751","1.82592"
"40.80000","1.02011","1.84229"
"40.90000","1.02261","1.83667"
"41.00000","1.02504","1.84544"
"41.10000","1.02754","1.86596"
"41.20000","1.02997","1.84367"
"41.30000","1.03258","1.85719"
"41.40000","1.03507","1.84838"
"41.50000","1.03745","1.84903"
"41.60000","1.04006","1.86440"
"41.70000","1.04267","1.90439"
"41.80000","1.04510","1.83842"
"41.90000","1.04748","1.85588"
"42.00000","1.05009","1.85720"
"42.10000","1.05253","1.84275"
"42.20000","1.05508","1.86779"
"42.30000","1.05757","1.86312"
"42.40000","1.06006","1.83272"
"42.50000","1.06250","1.85107"
"42.60000","1.06511","1.90218"
"42.70000","1.06749","1.92100"
"42.80000","1.07009","1.86304"
"42.90000","1.07253","1.86504"
"43.00000","1.07514","1.88138"
"43.10000","1.07757","1.90109"
"43.20000","1.08001","1.91185"
"43.30000","1.08256","1.91574"
"43.40000","1.08505","1.89730"
"43.50000","1.08755","1.90980"
"43.60000","1.08998","1.88859"
"43.70000","1.09259","1.91799"
"43.80000","1.09497","1.90342"
"43.90000","1.09758","1.93014"
"44.00000","1.10007","1.94672"
"44.10000","1.10251","1.93170"
"44.20000","1.10511","1.91160"
"44.30000","1.10761","1.95598"
"44.40000","1.11004","1.95503"
"44.50000","1.11254","1.92183"
"44.60000","1.11514","1.93336"
"44.70000","1.11758","1.94136"
"44.80000","1.12007","1.95791"
"44.90000","1.12251","1.98127"
"45.00000","1.12506","1.97672"
"45.10000","1.12761","1.95884"
"45.20000","1.13005","1.96609"
"45.30000","1.13254","1.94665"
"45.40000","1.13498","1.97354"
"45.50000","1.13753","1.97121"
"45.60000","1.14013","2.02258"
"45.70000","1.14257","1.97115"
"45.80000","1.14501","2.00907"
"45.90000","1.14761","1.94687"
"46.00000","1.15011","1.98558"
"46.10000","1.15260","1.98528"
"46.20000","1.15504","1.99673"
"46.30000","1.15753","2.02307"
"46.40000","1.16008","1.98715"
"46.50000","1.16263","2.01759"
"46.60000","1.16501","2.00288"
"46.70000","1.16750","2.00086"
"46.80000","1.17011","2.01105"
"46.90000","1.17266","1.96782"
"47.00000","1.17504","1.99212"
"47.10000","1.17753","1.98963"
"47.20000","1.18003","1.99153"
"47.30000","1.18263","2.00219"
"47.40000","1.18513","2.00900"
"47.50000","1.18745","2.04135"
"47.60000","1.19011","2.04526"
"47.70000","1.19255","2.03454"
"47.80000","1.19510","2.01135"
"47.90000","1.19754","2.02940"
"48.00000","1.19997","2.01226"
"48.10000","1.20252","2.06338"
"48.20000","1.20513","2.03455"
"48.30000","1.20751","2.03762"
"48.40000","1.21000","2.03769"
"48.50000","1.21255","2.02435"
"48.60000","1.21510","2.07904"
"48.70000","1.21760","2.05326"
"48.80000","1.22003","2.04500"
"48.90000","1.22253","2.07998"
"49.00000","1.22513","2.08891"
"49.10000","1.22763","2.03339"
"49.20000","1.23006","2.05515"
"49.30000","1.23256","2.06302"
"49.40000","1.23499","2.06546"
"49.50000","1.23754","2.09190"
"49.60000","1.24015","2.07557"
"49.70000","1.24259","2.08300"
"49.80000","1.24508","2.10952"
"49.90000","1.24763","2.08045"
"50.00000","1.25012","2.08176"
"50.10000","1.25250","2.10178"
"50.20000","1.25500","2.10427"
"50.30000","1.25749","2.09639"
"50.40000","1.26004","2.05099"
"50.50000","1.26253","2.06793"
"50.60000","1.26497","2.12224"
"50.70000","1.26752","2.14229"
"50.80000","1.27013","2.07525"
"50.90000","1.27256","2.11948"
"51.00000","1.27506","2.10548"
"51.10000","1.27755","2.11592"
"51.20000","1.28004","2.08780"
"51.30000","1.28259","2.08433"
"51.40000","1.28514","2.12251"
"51.50000","1.28758","2.10902"
"51.60000","1.29007","2.12967"
"51.70000","1.29257","2.12700"
"51.80000","1.29506","2.11889"
"51.90000","1.29761","2.12462"
"52.00000","1.30005","2.13600"
"52.10000","1.30265","2.11780"
"52.20000","1.30498","2.13606"
"52.30000","1.30753","2.14938"
"52.40000","1.31008","2.16733"
"52.50000","1.31263","2.15503"
"52.60000","1.31501","2.14084"
"52.70000","1.31756","2.14244"
"52.80000","1.32005","2.17271"
"52.90000","1.32249","2.16894"
"53.00000","1.32509","2.16523"
"53.10000","1.32753","2.14374"
"53.20000","1.33002","2.14847"
"53.30000","1.33257","2.20726"
"53.40000","1.33507","2.18979"
"53.50000","1.33750","2.18650"
"53.60000","1.34000","2.16111"
"53.70000","1.34260","2.18387"
"53.80000","1.34510","2.20432"
"53.90000","1.34759","2.12814"
"54.00000","1.35003","2.18785"
"54.10000","1.35258","2.19706"
"54.20000","1.35518","2.23079"
"54.30000","1.35756","2.21076"
"54.40000","1.36011","2.21063"
"54.50000","1.36255","2.21449"
"54.60000","1.36510","2.23287"
"54.70000","1.36765","2.21326"
"54.80000","1.36997","2.22363"
"54.90000","1.37247","2.19963"
"55.00000","1.37513","2.24148"
"55.10000","1.37757","2.25368"
"55.20000","1.38000","2.19884"
"55.30000","1.38255","2.25298"
"55.40000","1.38505","2.23872"
"55.50000","1.38760","2.25319"
"55.60000","1.39009","2.23208"
"55.70000","1.39247","2.27454"
"55.80000","1.39508","2.27767"
"55.90000","1.39768","2.27354"
"56.00000","1.40006","2.21205"
"56.10000","1.40250","2.23480"
"56.20000","1.40505","2.26954"
"56.30000","1.40749","2.29089"
"56.40000","1.41021","2.28630"
"56.50000","1.41259","2.28191"
"56.60000","1.41502","2.25720"
"56.70000","1.41763","2.30196"
"56.80000","1.42012","2.27541"
"56.90000","1.42262","2.28838"
"57.00000","1.42500","2.30465"
"57.10000","1.42749","2.30052"
"57.20000","1.43010","2.29227"
"57.30000","1.43259","2.28788"
"57.40000","1.43497","2.27048"
"57.50000","1.43752","2.29656"
"57.60000","1.44007","2.31138"
"57.70000","1.44262","2.30831"
"57.80000","1.44506","2.29397"
"57.90000","1.44749","2.25773"
"58.00000","1.45004","2.32064"
"58.10000","1.45265","2.31279"
"58.20000","1.45509","2.31909"
"58.30000","1.45752","2.33363"
"58.40000","1.46002","2.31467"
"58.50000","1.46257","2.32798"
"58.60000","1.46512","2.30503"
"58.70000","1.46755","2.34219"
"58.80000","1.47005","2.32225"
"58.90000","1.47254","2.34758"
"59.00000","1.47503","2.33877"
"59.10000","1.47764","2.31552"
"59.20000","1.48002","2.37137"
"59.30000","1.48251","2.32824"
"59.40000","1.48506","2.31808"
"59.50000","1.48761","2.36020"
"59.60000","1.48999","2.32221"
"59.70000","1.49254","2.32644"
"59.80000","1.49509","2.38015"
"59.90000","1.49759","2.35484"
"60.00000","1.50002","2.37211"
"60.10000","1.50252","2.38213"
"60.20000","1.50495","2.34964"
"60.30000","1.50750","2.38412"
"60.40000","1.51005","2.36456"
"60.50000","1.51260","2.40663"
"60.60000","1.51504","2.38473"
"60.70000","1.51765","2.35022"
"60.80000","1.52008","2.37874"
"60.90000","1.52258","2.37259"
"61.00000","1.52513","2.38543"
"61.10000","1.52756","2.41990"
"61.20000","1.53011","2.42197"
"61.30000","1.53249","2.41098"
"61.40000","1.53504","2.39642"
"61.50000","1.53754","2.41394"
"61.60000","1.54009","2.41067"
"61.70000","1.54252","2.42214"
"61.80000","1.54507","2.40332"
"61.90000","1.54751","2.42842"
"62.00000","1.55012","2.40217"
"62.10000","1.55261","2.43269"
"62.20000","1.55505","2.43015"
"62.30000","1.55754","2.41671"
"62.40000","1.56009","2.43905"
"62.50000","1.56258","2.41726"
"62.60000","1.56496","2.47783"
"62.70000","1.56757","2.40684"
"62.80000","1.57006","2.44145"
"62.90000","1.57256","2.45128"
"63.00000","1.57505","2.44078"
"63.10000","1.57749","2.45968"
"63.20000","1.58009","2.44649"
"63.30000","1.58264","2.42685"
"63.40000","1.58508","2.45881"
"63.50000","1.58757","2.45669"
"63.60000","1.59007","2.47284"
"63.70000","1.59262","2.43979"
"63.80000","1.59511","2.49041"
"63.90000","1.59749","2.45058"
"64.00000","1.60010","2.44779"
"64.10000","1.60259","2.46786"
"64.20000","1.60508","2.48024"
"64.30000","1.60752","2.52305"
"64.40000","1.60996","2.49170"
"64.50000","1.61251","2.46085"
"64.60000","1.61511","2.44761"
"64.70000","1.61761","2.46198"
"64.80000","1.61999","2.48550"
"64.90000","1.62259","2.47501"
"65.00000","1.62520","2.51607"
"65.10000","1.62758","2.51428"
"65.20000","1.63002","2.50560"
"65.30000","1.63257","2.53226"
"65.40000","1.63506","2.49557"
"65.50000","1.63767","2.50365"
"65.60000","1.63999","2.52902"
"65.70000","1.64254","2.49482"
"65.80000","1.64503","2.49683"
"65.90000","1.64764","2.50299"
"66.00000","1.65002","2.49635"
"66.10000","1.65251","2.47235"
"66.20000","1.65501","2.54667"
"66.30000","1.65761","2.49144"
"66.40000","1.66011","2.51850"
"66.50000","1.66249","2.54431"
"66.60000","1.66509","2.50480"
"66.70000","1.66764","2.55448"
"66.80000","1.67014","2.52695"
"66.90000","1.67252","2.52587"
"67.00000","1.67501","2.57535"
"67.10000","1.67750","2.54586"
"67.20000","1.68017","2.53107"
"67.30000","1.68255","2.54643"
"67.40000","1.68504","2.56114"
"67.50000","1.68753","2.56879"
"67.60000","1.69003","2.56128"
"67.70000","1.69263","2.57486"
"67.80000","1.69507","2.56604"
"67.90000","1.69751","2.58097"
"68.00000","1.70006","2.55024"
"68.10000","1.70261","2.57789"
"68.20000","1.70504","2.59770"
"68.30000","1.70754","2.57864"
"68.40000","1.71003","2.61659"
"68.50000","1.71252","2.59837"
"68.60000","1.71507","2.60848"
"68.70000","1.71751","2.55061"
"68.80000","1.72000","2.58526"
"68.90000","1.72261","2.60197"
"69.00000","1.72510","2.58977"
"69.10000","1.72748","2.59493"
"69.20000","1.73009","2.60060"
"69.30000","1.73258","2.61409"
"69.40000","1.73513","2.62082"
"69.50000","1.73757","2.57471"
"69.60000","1.74006","2.61667"
"69.70000","1.74250","2.58454"
"69.80000","1.74511","2.64960"
"69.90000","1.74754","2.59997"
"70.00000","1.75009","2.59104"
"70.10000","1.75259","2.63554"
"70.20000","1.75514","2.63742"
"70.30000","1.75757","2.61904"
"70.40000","1.76001","2.65504"
"70.50000","1.76256","2.62067"
"70.60000","1.76505","2.62611"
"70.70000","1.76755","2.64231"
"70.80000","1.76998","2.62554"
"70.90000","1.77253","2.64006"
"71.00000","1.77497","2.65529"
"71.10000","1.77758","2.64182"
"71.20000","1.78007","2.65113"
"71.30000","1.78251","2.66128"
"71.40000","1.78511","2.68281"
"71.50000","1.78766","2.71293"
"71.60000","1.79004","2.64621"
"71.70000","1.79254","2.65772"
"71.80000","1.79514","2.64597"
"71.90000","1.79758","2.71203"
"72.00000","1.80007","2.64454"
"72.10000","1.80251","2.67770"
"72.20000","1.80500","2.68252"
"72.30000","1.80761","2.69275"
"72.40000","1.81005","2.67490"
"72.50000","1.81260","2.69908"
"72.60000","1.81503","2.68255"
"72.70000","1.81753","2.71445"
"72.80000","1.82008","2.72952"
"72.90000","1.82257","2.70889"
"73.00000","1.82495","2.70587"
"73.10000","1.82761","2.73375"
"73.20000","1.83011","2.72675"
"73.30000","1.83254","2.71858"
"73.40000","1.83504","2.72377"
"73.50000","1.83753","2.70340"
"73.60000","1.84002","2.73237"
"73.70000","1.84263","2.69249"
"73.80000","1.84501","2.73529"
"73.90000","1.84750","2.75761"
"74.00000","1.85011","2.72602"
"74.10000","1.85266","2.75780"
"74.20000","1.85504","2.74171"
"74.30000","1.85759","2.72192"
"74.40000","1.86008","2.77240"
"74.50000","1.86263","2.78377"
"74.60000","1.86518","2.76825"
"74.70000","1.86745","2.74143"
"74.80000","1.87011","2.76912"
"74.90000","1.87261","2.80330"
"75.00000","1.87510","2.76426"
"75.10000","1.87754","2.76834"
"75.20000","1.88003","2.78447"
"75.30000","1.88252","2.76602"
"75.40000","1.88513","2.80617"
"75.50000","1.88751","2.81386"
"75.60000","1.89000","2.80539"
"75.70000","1.89255","2.80844"
"75.80000","1.89510","2.78173"
"75.90000","1.89760","2.79143"
"76.00000","1.89998","2.81590"
"76.10000","1.90253","2.81040"
"76.20000","1.90508","2.80504"
"76.30000","1.90763","2.78656"
"76.40000","1.91006","2.78753"
"76.50000","1.91256","2.78880"
"76.60000","1.91505","2.77116"
"76.70000","1.91760","2.81964"
"76.80000","1.92015","2.84125"
"76.90000","1.92259","2.80957"
"77.00000","1.92508","2.82908"
"77.10000","1.92763","2.82574"
"77.20000","1.93012","2.81344"
"77.30000","1.93250","2.82832"
"77.40000","1.93500","2.81925"
"77.50000","1.93755","2.83774"
"77.60000","1.94015","2.77926"
"77.70000","1.94253","2.83895"
"77.80000","1.94497","2.85859"
"77.90000","1.94752","2.86789"
"78.00000","1.95007","2.85622"
"78.10000","1.95256","2.87646"
"78.20000","1.95500","2.83768"
"78.30000","1.95755","2.85611"
"78.40000","1.96004","2.83169"
"78.50000","1.96259","2.87784"
"78.60000","1.96514","2.86530"
"78.70000","1.96752","2.87364"
"78.80000","1.97002","2.85322"
"78.90000","1.97257","2.85840"
"79.00000","1.97506","2.86765"
"79.10000","1.97755","2.83739"
"79.20000","1.98005","2.85679"
"79.30000","1.98265","2.89213"
"79.40000","1.98503","2.85218"
"79.50000","1.98753","2.88749"
"79.60000","1.99002","2.88320"
"79.70000","1.99257","2.85951"
"79.80000","1.99501","2.93066"
"79.90000","1.99756","2.86209"
"80.00000","2.00005","2.87496"
"80.10000","2.00254","2.91931"
"80.20000","2.00509","2.94107"
"80.30000","2.00747","2.90684"
"80.40000","2.01002","2.91540"
"80.50000","2.01252","2.93566"
"80.60000","2.01507","2.92963"
"80.70000","2.01750","2.91107"
"80.80000","2.02000","2.90594"
"80.90000","2.02260","2.93084"
"81.00000","2.02510","2.92042"
"81.10000","2.02759","2.89281"
"81.20000","2.03003","2.89111"
"81.30000","2.03258","2.89582"
"81.40000","2.03518","2.94444"
"81.50000","2.03756","2.91630"
"81.60000","2.04011","2.91795"
"81.70000","2.04255","2.93242"
"81.80000","2.04504","2.95654"
"81.90000","2.04765","2.94424"
"82.00000","2.04997","2.92821"
"82.10000","2.05247","2.95707"
"82.20000","2.05513","2.98604"
"82.30000","2.05757","2.94687"
"82.40000","2.06000","3.01245"
"82.50000","2.06255","2.94969"
"82.60000","2.06505","3.03723"
"82.70000","2.06760","2.98476"
"82.80000","2.07015","2.96712"
"82.90000","2.07247","2.96896"
"83.00000","2.07508","2.99999"
"83.10000","2.07768","2.98120"
"83.20000","2.08006","2.99299"
"83.30000","2.08250","3.00797"
"83.40000","2.08505","2.99071"
"83.50000","2.08749","2.97278"
"83.60000","2.09021","3.02967"
"83.70000","2.09253","3.00503"
"83.80000","2.09502","2.95276"
"83.90000","2.09763","3.02421"
"84.00000","2.10012","3.06558"
"84.10000","2.10262","3.03168"
"84.20000","2.10505","2.99765"
"84.30000","2.10749","3.02247"
"84.40000","2.11010","3.03345"
"84.50000","2.11265","3.03397"
"84.60000","2.11497","3.03463"
"84.70000","2.11752","3.04032"
"84.80000","2.12007","3.07654"
"84.90000","2.12262","3.05083"
"85.00000","2.12506","3.03299"
"85.10000","2.12749","3.03264"
"85.20000","2.13010","3.03149"
"85.30000","2.13265","3.07020"
"85.40000","2.13503","3.05972"
"85.50000","2.13747","3.05954"
"85.60000","2.14002","3.06141"
"85.70000","2.14251","3.02309"
"85.80000","2.14506","3.08893"
"85.90000","2.14761","3.06033"
"86.00000","2.14999","3.06689"
"86.10000","2.15254","3.02368"
"86.20000","2.15509","3.10064"
"86.30000","2.15758","3.08296"
"86.40000","2.16002","3.06711"
"86.50000","2.16257","3.05394"
"86.60000","2.16506","3.10289"
"86.70000","2.16767","3.09228"
"86.80000","2.16999","3.07417"
"86.90000","2.17254","3.07592"
"87.00000","2.17509","3.08035"
"87.10000","2.17759","3.09020"
"87.20000","2.18002","3.11035"
"87.30000","2.18252","3.13313"
"87.40000","2.18501","3.07820"
"87.50000","2.18756","3.09725"
"87.60000","2.19011","3.10722"
"87.70000","2.19260","3.11259"
"87.80000","2.19504","3.11907"
"87.90000","2.19759","3.09985"
"88.00000","2.20003","3.14014"
"88.10000","2.20258","3.17120"
"88.20000","2.20507","3.11388"
"88.30000","2.20756","3.16105"
"88.40000","2.21011","3.09849"
"88.50000","2.21249","3.13025"
"88.60000","2.21504","3.10417"
"88.70000","2.21759","3.17582"
"88.80000","2.22009","3.17896"
"88.90000","2.22252","3.13497"
"89.00000","2.22502","3.13990"
"89.10000","2.22751","3.20944"
"89.20000","2.23012","3.12659"
"89.30000","2.23261","3.17945"
"89.40000","2.23505","3.15707"
"89.50000","2.23760","3.18015"
"89.60000","2.24009","3.15918"
"89.70000","2.24258","3.17797"
"89.80000","2.24496","3.16676"
"89.90000","2.24757","3.22008"
"90.00000","2.25012","3.17558"
"90.10000","2.25256","3.16961"
"90.20000","2.25505","3.19978"
"90.30000","2.25749","3.17549"
"90.40000","2.26009","3.20906"
"90.50000","2.26264","3.17634"
"90.60000","2.26508","3.21279"
"90.70000","2.26757","3.18113"
"90.80000","2.27007","3.24585"
"90.90000","2.27262","3.21027"
"91.00000","2.27505","3.21679"
"91.10000","2.27749","3.25902"
"91.20000","2.28010","3.26513"
"91.30000","2.28259","3.22817"
"91.40000","2.28508","3.20977"
"91.50000","2.28752","3.23770"
"91.60000","2.29001","3.24469"
"91.70000","2.29251","3.22370"
"91.80000","2.29511","3.23720"
"91.90000","2.29761","3.21625"
"92.00000","2.29999","3.26720"
"92.10000","2.30259","3.23987"
"92.20000","2.30520","3.24639"
"92.30000","2.30758","3.26064"
"92.40000","2.30996","3.26619"
"92.50000","2.31257","3.25995"
"92.60000","2.31506","3.27237"
"92.70000","2.31767","3.27895"
"92.80000","2.31999","3.25883"
"92.90000","2.32254","3.27522"
"93.00000","2.32503","3.27004"
"93.10000","2.32764","3.28074"
"93.20000","2.33008","3.28993"
"93.30000","2.33257","3.30200"
"93.40000","2.33501","3.28450"
"93.50000","2.33761","3.31991"
"93.60000","2.34011","3.31282"
"93.70000","2.34243","3.28458"
"93.80000","2.34509","3.28292"
"93.90000","2.34759","3.28608"
"94.00000","2.35014","3.28507"
"94.10000","2.35257","3.31141"
"94.20000","2.35501","3.32988"
"94.30000","2.35750","3.30924"
"94.40000","2.36017","3.31005"
"94.50000","2.36255","3.28320"
"94.60000","2.36504","3.31485"
"94.70000","2.36759","3.28340"
"94.80000","2.37003","3.29630"
"94.90000","2.37263","3.31525"
"95.00000","2.37507","3.32143"
"95.10000","2.37751","3.36008"
"95.20000","2.38006","3.30643"
"95.30000","2.38261","3.30599"
"95.40000","2.38504","3.30793"
"95.50000","2.38754","3.32461"
"95.60000","2.38997","3.34474"
"95.70000","2.39252","3.38010"
"95.80000","2.39513","3.36272"
"95.90000","2.39745","3.34597"
"96.00000","2.40006","3.34444"
"96.10000","2.40267","3.33024"
"96.20000","2.40510","3.36980"
"96.30000","2.40748","3.39573"
"96.40000","2.41009","3.35758"
"96.50000","2.41253","3.35477"
"96.60000","2.41508","3.39810"
"96.70000","2.41757","3.37921"
"96.80000","2.42006","3.38119"
"96.90000","2.42250","3.39300"
"97.00000","2.42505","3.37364"
"97.10000","2.42754","3.45094"
"97.20000","2.43009","3.40667"
"97.30000","2.43259","3.41122"
"97.40000","2.43514","3.41109"
"97.50000","2.43757","3.41787"
"97.60000","2.44001","3.44217"
"97.70000","2.44256","3.40917"
"97.80000","2.44505","3.43512"
"97.90000","2.44755","3.40766"
"98.00000","2.44998","3.41126"
"98.10000","2.45253","3.37644"
"98.20000","2.45497","3.43838"
"98.30000","2.45758","3.42336"
"98.40000","2.46007","3.44160"
"98.50000","2.46251","3.42579"
"98.60000","2.46506","3.46221"
"98.70000","2.46761","3.46881"
"98.80000","2.47004","3.43393"
"98.90000","2.47254","3.44156"
"99.00000","2.47514","3.47800"
"99.10000","2.47764","3.47433"
"99.20000","2.48013","3.43794"
"99.30000","2.48251","3.46600"
"99.40000","2.48500","3.47536"
"99.50000","2.48761","3.47657"
"99.60000","2.49010","3.48311"
"99.70000","2.49260","3.50111"
"99.80000","2.49503","3.44391"
"99.90000","2.49758","3.44348"
"99.99600","2.50002","3.48856"
"99.99800","2.50008","3.48638"
"100.09800","2.49588","3.47524"
"100.19800","2.48381","3.42071"
"100.29800","2.47509","3.38486"
"100.39800","2.46670","3.35835"
"100.49800","2.45837","3.38051"
"100.59800","2.44998","3.35302"
"100.69800","2.44171","3.38396"
"100.79800","2.43338","3.34214"
"100.89800","2.42494","3.32769"
"100.99800","2.41672","3.32396"
"101.09800","2.40828","3.28913"
"101.19800","2.40006","3.32514"
"101.29800","2.39173","3.26060"
"101.39800","2.38340","3.27326"
"101.49800","2.37496","3.25521"
"101.59800","2.36663","3.22559"
"101.69800","2.35830","3.26562"
"101.79800","2.34991","3.20474"
"101.89800","2.34158","3.21281"
"101.99800","2.33331","3.19481"
"102.09800","2.32503","3.19547"
"102.19800","2.31670","3.16542"
"102.29800","2.30826","3.15042"
"102.39800","2.29987","3.17234"
"102.49800","2.29154","3.13966"
"102.59800","2.28333","3.14512"
"102.69800","2.27500","3.09991"
"102.79800","2.26661","3.09102"
"102.89800","2.25822","3.07791"
"102.99800","2.25006","3.06145"
"103.09800","2.24168","3.05389"
"103.19800","2.23329","3.06924"
"103.29800","2.22490","2.99123"
"103.39800","2.21663","3.00377"
"103.49800","2.20836","2.99923"
"103.59800","2.19991","2.98032"
"103.69800","2.19170","2.98713"
"103.79800","2.18331","2.99283"
"103.89800","2.17504","2.91638"
"103.99800","2.16671","2.94743"
"104.09800","2.15826","2.91231"
"104.19800","2.14999","2.90056"
"104.29800","2.14160","2.87385"
"104.39800","2.13333","2.82675"
"104.49800","2.12489","2.88503"
"104.59800","2.11667","2.88975"
"104.69800","2.10828","2.88642"
"104.79800","2.10001","2.84470"
"104.89800","2.09162","2.84082"
"104.99800","2.08318","2.80366"
"105.09800","2.07491","2.80235"
"105.19800","2.06663","2.78424"
"105.29800","2.05830","2.77011"
"105.39800","2.04992","2.78578"
"105.49800","2.04159","2.75318"
"105.59800","2.03331","2.71094"
"105.69800","2.02493","2.73003"
"105.79800","2.01654","2.69417"
"105.89800","2.00832","2.69806"
"105.99800","1.99999","2.64594"
"106.09800","1.99166","2.66941"
"106.19800","1.98339","2.63860"
"106.29800","1.97489","2.63878"
"106.39800","1.96662","2.60786"
"106.49800","1.95834","2.63037"
"106.59800","1.95007","2.64929"
"106.69800","1.94168","2.63716"
"106.79800","1.93324","2.59186"
"106.89800","1.92497","2.58782"
"106.99800","1.91664","2.55723"
"107.09800","1.90831","2.53986"
"107.19800","1.89986","2.56141"
"107.29800","1.89165","2.54578"
"107.39800","1.88343","2.52575"
"107.49800","1.87499","2.49393"
"107.59800","1.86660","2.48704"
"107.69800","1.85816","2.47518"
"107.79800","1.84994","2.44089"
"107.89800","1.84167","2.46067"
"107.99800","1.83334","2.43985"
"108.09800","1.82501","2.45185"
"108.19800","1.81668","2.41648"
"108.29800","1.80829","2.41832"
"108.39800","1.79990","2.40279"
"108.49800","1.79157","2.38787"
"108.59800","1.78319","2.33103"
"108.69800","1.77503","2.35468"
"108.79800","1.76670","2.36404"
"108.89800","1.75842","2.36414"
"108.99800","1.74992","2.32089"
"109.09800","1.74159","2.32917"
"109.19800","1.73326","2.29147"
"109.29800","1.72493","2.33008"
"109.39800","1.71666","2.27954"
"109.49800","1.70827","2.26086"
"109.59800","1.70006","2.26561"
"109.69800","1.69167","2.24519"
"109.79800","1.68328","2.20383"
"109.89800","1.67490","2.20438"
"109.99800","1.66668","2.20129"
"110.09800","1.65835","2.20535"
"110.19800","1.65002","2.18988"
"110.29800","1.64158","2.17087"
"110.39800","1.63325","2.14843"
"110.49800","1.62497","2.15900"
"110.59800","1.61659","2.14136"
"110.69800","1.60831","2.13230"
"110.79800","1.59998","2.09696"
"110.89800","1.59165","2.12052"
"110.99800","1.58327","2.08806"
"111.09800","1.57494","2.06937"
"111.19800","1.56661","2.05983"
"111.29800","1.55828","2.07050"
"111.39800","1.55006","2.05550"
"111.49800","1.54167","2.03214"
"111.59800","1.53334","2.04773"
"111.69800","1.52496","2.03032"
"111.79800","1.51668","1.99092"
"111.89800","1.50830","1.96597"
"111.99800","1.49991","1.97910"
"112.09800","1.49164","1.96992"
"112.19800","1.48336","1.95092"
"112.29800","1.47503","1.92413"
"112.39800","1.46665","1.93514"
"112.49800","1.45826","1.92437"
"112.59800","1.44993","1.88958"
"112.69800","1.44166","1.86858"
"112.79800","1.43333","1.87426"
"112.89800","1.42494","1.84303"
"112.99800","1.41661","1.81035"
"113.09800","1.40828","1.82642"
"113.19800","1.39995","1.85944"
"113.29800","1.39151","1.85566"
"113.39800","1.38323","1.80446"
"113.49800","1.37502","1.79068"
"113.59800","1.36663","1.79592"
"113.69800","1.35830","1.79855"
"113.79800","1.34986","1.76223"
"113.89800","1.34164","1.73415"
"113.99800","1.33331","1.74090"
"114.09800","1.32504","1.73729"
"114.19800","1.31665","1.68862"
"114.29800","1.30832","1.69044"
"114.39800","1.30005","1.68157"
"114.49800","1.29160","1.67916"
"114.59800","1.28322","1.64276"
"114.69800","1.27483","1.68104"
"114.79800","1.26667","1.66617"
"114.89800","1.25845","1.62472"
"114.99800","1.25007","1.60332"
"115.09800","1.24162","1.63798"
"115.19800","1.23324","1.61563"
"115.29800","1.22491","1.58115"
"115.39800","1.21658","1.55865"
"115.49800","1.20830","1.55979"
"115.59800","1.19997","1.52332"
"115.69800","1.19170","1.52037"
"115.79800","1.18331","1.49855"
"115.89800","1.17493","1.52400"
"115.99800","1.16654","1.50230"
"116.09800","1.15821","1.50378"
"116.19800","1.14999","1.46269"
"116.29800","1.14161","1.47393"
"116.39800","1.13333","1.44037"
"116.49800","1.12495","1.45864"
"116.59800","1.11673","1.41251"
"116.69800","1.10829","1.43618"
"116.79800","1.09996","1.40710"
"116.89800","1.09163","1.41853"
"116.99800","1.08335","1.38878"
"117.09800","1.07508","1.36875"
"117.19800","1.06658","1.35180"
"117.29800","1.05831","1.33321"
"117.39800","1.04992","1.35729"
"117.49800","1.04170","1.31732"
"117.59800","1.03332","1.34449"
"117.69800","1.02499","1.27277"
"117.79800","1.01666","1.31185"
"117.89800","1.00833","1.26719"
"117.99800","1.00000","1.26668"
"118.09800","0.99155","1.28769"
"118.19800","0.98334","1.24935"
"118.29800","0.97501","1.23296"
"118.39800","0.96668","1.24693"
"118.49800","0.95829","1.18891"
"118.59800","0.94985","1.19247"
"118.69800","0.94157","1.21681"
"118.79800","0.93330","1.20216"
"118.89800","0.92497","1.15423"
"118.99800","0.91658","1.15101"
"119.09800","0.90820","1.14479"
"119.19800","0.89992","1.10767"
"119.29800","0.89165","1.08232"
"119.39800","0.88321","1.10252"
"119.49800","0.87493","1.08385"
"119.59800","0.86666","1.05805"
"119.69800","0.85833","1.11058"
"119.79800","0.85000","1.06738"
"119.89800","0.84156","1.03742"
"119.99800","0.83328","1.06617"
"120.09800","0.82501","1.01380"
"120.19800","0.81674","1.02874"
"120.29800","0.80829","0.98612"
"120.39800","0.79996","1.00879"
"120.49800","0.79163","1.01355"
"120.59800","0.78325","0.93003"
"120.69800","0.77492","0.97107"
"120.79800","0.76653","0.95389"
"120.89800","0.75837","0.93695"
"120.99800","0.75004","0.92589"
"121.09800","0.74165","0.92598"
"121.19800","0.73327","0.90663"
"121.29800","0.72482","0.91865"
"121.39800","0.71661","0.86175"
"121.49800","0.70833","0.87110"
"121.59800","0.70006","0.86754"
"121.69800","0.69162","0.86315"
"121.79800","0.68329","0.85954"
"121.89800","0.67501","0.83601"
"121.99800","0.66657","0.83036"
"122.09800","0.65818","0.82515"
"122.19800","0.64991","0.79664"
"122.29800","0.64175","0.81953"
"122.39800","0.63342","0.79011"
"122.49800","0.62503","0.80231"
"122.59800","0.61648","0.80507"
"122.69800","0.60826","0.76039"
"122.79800","0.59987","0.75544"
"122.89800","0.59160","0.73504"
"122.99800","0.58333","0.71077"
"123.09800","0.57494","0.71715"
"123.19800","0.56667","0.65824"
"123.29800","0.55822","0.66017"
"123.39800","0.55001","0.67193"
"123.49800","0.54151","0.67872"
"123.59800","0.53329","0.64337"
"123.69800","0.52502","0.62636"
"123.79800","0.51657","0.63261"
"123.89800","0.50830","0.64468"
"123.99800","0.49991","0.60386"
"124.09800","0.49170","0.60818"
"124.19800","0.48325","0.58885"
"124.29800","0.47492","0.63059"
"124.39800","0.46665","0.59723"
"124.49800","0.45838","0.58924"
"124.59800","0.44999","0.55599"
"124.69800","0.44160","0.56162"
"124.79800","0.43316","0.51008"
"124.89800","0.42500","0.53823"
"124.99800","0.41673","0.52587"
"125.09800","0.40828","0.50522"
"125.19800","0.39995","0.46991"
"125.29800","0.39162","0.46052"
"125.39800","0.38346","0.44906"
"125.49800","0.37502","0.44722"
"125.59800","0.36658","0.47369"
"125.69800","0.35830","0.47636"
"125.79800","0.35003","0.46660"
"125.89800","0.34164","0.39372"
"125.99800","0.33326","0.41650"
"126.09800","0.32487","0.37981"
"126.19800","0.31660","0.40159"
"126.29800","0.30832","0.37249"
"126.39800","0.29999","0.40554"
"126.49800","0.29161","0.36760"
"126.59800","0.28322","0.35932"
"126.69800","0.27495","0.34543"
"126.79800","0.26667","0.35386"
"126.89800","0.25829","0.31222"
"126.99800","0.25001","0.34586"
"127.09800","0.24163","0.27024"
"127.19800","0.23330","0.27640"
"127.29800","0.22497","0.27279"
"127.39800","0.21647","0.28584"
"127.49800","0.20825","0.25111"
"127.59800","0.19998","0.25751"
"127.69800","0.19170","0.26392"
"127.79800","0.18332","0.28048"
"127.89800","0.17499","0.18949"
"127.99800","0.16666","0.22166"
"128.09800","0.15821","0.19625"
"128.19800","0.14994","0.18292"
"128.29800","0.14155","0.16781"
"128.39800","0.13334","0.15434"
"128.49800","0.12506","0.18420"
"128.59800","0.11673","0.18385"
"128.69800","0.10829","0.16713"
"128.79800","0.09996","0.15486"
"128.89800","0.09157","0.11392"
"128.99800","0.08324","0.11954"
"129.09800","0.07503","0.11739"
"129.19800","0.06664","0.10189"
"129.29800","0.05837","0.06198"
"129.39800","0.04998","0.09165"
"129.49800","0.04159","0.04037"
"129.59800","0.03315","0.08526"
"129.69800","0.02488","0.06738"
"129.79800","0.01666","0.04065"
"129.89800","0.00833","0.02208"
"129.99800","0.00000","0.04869"
"130.09800","-0.00844","0.07674"
"130.19800","-0.01666","0.04476"
"130.29800","-0.02505","0.01030"
"130.39800","-0.03343","0.07069"
"130.49800","-0.04171","0.04209"
"130.59800","-0.04998","0.01820"
"130.69800","-0.05825","0.03712"
"130.79800","-0.06675","0.01995"
"130.89800","-0.07497","0.05352"
"130.99800","-0.08336","0.06537"
"131.09800","-0.09163","0.03968"
"131.19800","-0.10002","0.05017"
"131.29800","-0.10840","0.05923"
"131.39800","-0.11668","0.01696"
"131.49800","-0.12501","0.04285"
"131.59800","-0.13334","0.07746"
"131.69800","-0.14178","0.06208"
"131.79800","-0.15005","0.06002"
"131.89800","-0.15838","0.06494"
"131.99800","-0.16666","0.03592"
"132.09800","-0.17504","0.06090"
"132.19800","-0.18343","0.07917"
"132.29800","-0.19182","0.01397"
"132.39800","-0.20003","0.06819"
"132.49800","-0.20836","0.00919"
"132.59800","-0.21675","0.07488"
"132.69800","-0.22508","0.09841"
"132.79800","-0.23341","0.04124"
"132.89800","-0.24163","0.03924"
"132.99800","-0.25013","0.03321"
"133.09800","-0.25840","0.06244"
"133.19800","-0.26673","0.04886"
"133.29800","-0.27500","0.05345"
"133.39800","-0.28333","0.03297"
"133.49800","-0.29178","0.05436"
"133.59800","-0.29999","0.07434"
"133.69800","-0.30838","0.04607"
"133.79800","-0.31665","0.04906"
"133.89800","-0.32498","0.06890"
"133.99800","-0.33343","0.02426"
"134.09800","-0.34176","0.06507"
"134.11200","-0.34295","0.07693"