File: Tension/Section_2_Group_2/Hybrid_High_Sample_1_3.is_tens_RawData/Specimen_RawData_1.csv
Time,Extension,Load,Tensile strain (Extension),Tensile stress,Strain-by-clip-gage
(s),(mm),(N),(mm/mm),(MPa),(mm/mm)
"0.00000","0.00000","14.88024","0.00000","1.48802","-0.00001"
"0.30000","0.00769","63.65941","0.00008","6.36594","0.00000"
"0.60000","0.01767","124.30554","0.00018","12.43055","0.00001"
"0.90000","0.02778","183.88615","0.00028","18.38861","0.00002"
"1.20000","0.03782","241.70053","0.00038","24.17005","-0.00002"
"1.50000","0.04769","296.92917","0.00048","29.69292","-0.00002"
"1.80000","0.05759","351.08685","0.00058","35.10868","0.00000"
"2.10000","0.06767","405.48724","0.00068","40.54873","0.00000"
"2.40000","0.07766","457.98123","0.00078","45.79812","-0.00002"
"2.70000","0.08788","511.72739","0.00088","51.17274","-0.00001"
"3.00000","0.09775","561.44702","0.00098","56.14470","-0.00001"
"3.30000","0.10779","612.20166","0.00108","61.22017","0.00013"
"3.60000","0.11769","660.81213","0.00118","66.08121","-0.00003"
"3.90000","0.12770","710.15607","0.00128","71.01561","0.00000"
"4.20000","0.13764","758.33734","0.00138","75.83373","0.00001"
"4.50000","0.14773","807.32458","0.00148","80.73246","0.00008"
"4.80000","0.15771","855.45099","0.00158","85.54510","0.00003"
"5.10000","0.16782","907.36359","0.00168","90.73636","0.00000"
"5.40000","0.17769","961.76068","0.00178","96.17607","-0.00001"
"5.70000","0.18787","1019.25787","0.00188","101.92579","0.00000"
"6.00000","0.19770","1074.27783","0.00198","107.42778","0.00000"
"6.30000","0.20772","1130.74341","0.00208","113.07434","0.00000"
"6.60000","0.21767","1186.35059","0.00218","118.63506","0.00000"
"6.90000","0.22767","1242.16736","0.00228","124.21674","-0.00001"
"7.20000","0.23772","1298.92419","0.00238","129.89243","0.00000"
"7.50000","0.24777","1358.08118","0.00248","135.80812","0.00001"
"7.80000","0.25769","1417.76672","0.00258","141.77667","0.00001"
"8.10000","0.26786","1479.87280","0.00268","147.98727","-0.00001"
"8.40000","0.27774","1539.61792","0.00278","153.96179","-0.00001"
"8.70000","0.28762","1599.19971","0.00288","159.91997","0.00000"
"9.00000","0.29767","1660.41760","0.00298","166.04176","0.00001"
"9.30000","0.30771","1721.47546","0.00308","172.14755","0.00000"
"9.60000","0.31777","1782.43652","0.00318","178.24365","-0.00001"
"9.90000","0.32780","1842.91577","0.00328","184.29158","0.00000"
"10.20000","0.33779","1903.02747","0.00338","190.30275","0.00001"
"10.50000","0.34771","1962.42969","0.00348","196.24297","0.00000"
"10.80000","0.35770","2022.11829","0.00358","202.21182","-0.00001"
"11.10000","0.36766","2081.03271","0.00368","208.10327","-0.00001"
"11.40000","0.37770","2140.63525","0.00378","214.06352","0.00000"
"11.70000","0.38767","2198.96558","0.00388","219.89656","0.00001"
"12.00000","0.39785","2259.30493","0.00398","225.93050","-0.00001"
"12.30000","0.40769","2316.12427","0.00408","231.61243","0.00000"
"12.60000","0.41780","2374.97119","0.00418","237.49712","0.00000"
"12.90000","0.42776","2432.39551","0.00428","243.23955","0.00001"
"13.20000","0.43769","2488.93335","0.00438","248.89334","0.00000"
"13.50000","0.44763","2544.79272","0.00448","254.47928","-0.00001"
"13.80000","0.45774","2601.65796","0.00458","260.16580","0.00000"
"14.10000","0.46760","2656.17529","0.00468","265.61752","0.00000"
"14.40000","0.47781","2713.76343","0.00478","271.37634","0.00000"
"14.70000","0.48772","2767.80615","0.00488","276.78061","0.00000"
"15.00000","0.49784","2823.27393","0.00498","282.32739","-0.00001"
"15.30000","0.50773","2875.95020","0.00508","287.59503","0.00000"
"15.60000","0.51772","2929.44678","0.00518","292.94467","0.00000"
"15.90000","0.52759","2981.16528","0.00528","298.11652","0.00000"
"16.20000","0.53772","3034.42822","0.00538","303.44281","-0.00001"
"16.50000","0.54777","3086.19531","0.00548","308.61954","0.00000"
"16.80000","0.55780","3137.80200","0.00558","313.78021","0.00000"
"17.10000","0.56773","3188.10278","0.00568","318.81027","0.00000"
"17.40000","0.57785","3239.55591","0.00578","323.95560","0.00000"
"17.70000","0.58766","3287.41064","0.00588","328.74106","-0.00001"
"18.00000","0.59763","3336.50000","0.00598","333.64999","0.00000"
"18.30000","0.60767","3385.83594","0.00608","338.58359","0.00001"
"18.60000","0.61764","3434.11792","0.00618","343.41180","-0.00001"
"18.90000","0.62778","3483.54102","0.00628","348.35410","-0.00001"
"19.20000","0.63778","3530.25317","0.00638","353.02533","0.00000"
"19.50000","0.64770","3576.16162","0.00648","357.61615","0.00000"
"19.80000","0.65777","3623.20996","0.00658","362.32098","0.00000"
"20.10000","0.66775","3668.80347","0.00668","366.88034","-0.00001"
"20.40000","0.67765","3712.73486","0.00678","371.27350","-0.00001"
"20.70000","0.68765","3757.23511","0.00688","375.72351","0.00000"
"21.00000","0.69764","3801.20361","0.00698","380.12036","0.00001"
"21.30000","0.70781","3846.16528","0.00708","384.61652","0.00000"
"21.60000","0.71772","3888.00391","0.00718","388.80038","-0.00001"
"21.90000","0.72784","3930.94458","0.00728","393.09445","0.00000"
"22.20000","0.73776","3971.90308","0.00738","397.19031","0.00001"
"22.50000","0.74767","4012.42383","0.00748","401.24237","0.00000"
"22.80000","0.75764","4052.24414","0.00758","405.22443","-0.00001"
"23.10000","0.76771","4092.31958","0.00768","409.23196","-0.00001"
"23.40000","0.77769","4131.65576","0.00778","413.16559","0.00001"
"23.70000","0.78787","4172.33301","0.00788","417.23331","0.00001"
"24.00000","0.79776","4209.40088","0.00798","420.94009","-0.00001"
"24.30000","0.80780","4247.38037","0.00808","424.73804","-0.00001"
"24.60000","0.81773","4283.55371","0.00818","428.35538","0.00000"
"24.90000","0.82769","4319.41748","0.00828","431.94174","0.00001"
"25.20000","0.83761","4354.70654","0.00838","435.47064","-0.00001"
"25.50000","0.84773","4390.70557","0.00848","439.07056","-0.00001"
"25.80000","0.85772","4424.87402","0.00858","442.48740","-0.00001"
"26.10000","0.86777","4458.98047","0.00868","445.89804","0.00001"
"26.40000","0.87773","4491.95068","0.00878","449.19507","0.00000"
"26.70000","0.88785","4525.65723","0.00888","452.56573","-0.00001"
"27.00000","0.89771","4556.18408","0.00898","455.61841","-0.00001"
"27.30000","0.90770","4587.12646","0.00908","458.71265","0.00001"
"27.60000","0.91761","4616.41846","0.00918","461.64185","0.00001"
"27.90000","0.92760","4645.94434","0.00928","464.59442","0.00000"
"28.20000","0.93779","4676.38721","0.00938","467.63873","-0.00002"
"28.50000","0.94785","4704.55078","0.00948","470.45508","0.00000"
"28.80000","0.95775","4731.27344","0.00958","473.12735","0.00002"
"29.10000","0.96783","4759.13916","0.00968","475.91391","0.00000"
"29.40000","0.97772","4784.27344","0.00978","478.42734","-0.00001"
"29.70000","0.98755","4807.76270","0.00988","480.77628","-0.00001"
"30.00000","0.99767","4833.52588","0.00998","483.35260","0.00000"
"30.30000","1.00776","4858.45459","0.01008","485.84546","0.00001"
"30.60000","1.01782","4882.30908","0.01018","488.23090","0.00000"
"30.90000","1.02779","4904.57471","0.01028","490.45746","-0.00001"
"31.20000","1.03780","4926.17578","0.01038","492.61758","-0.00001"
"31.50000","1.04768","4946.58496","0.01048","494.65851","0.00001"
"31.80000","1.05769","4967.90576","0.01058","496.79059","0.00000"
"32.10000","1.06771","4988.29688","0.01068","498.82968","-0.00001"
"32.40000","1.07769","5007.82178","0.01078","500.78217","-0.00002"
"32.70000","1.08769","5026.93896","0.01088","502.69391","0.00001"
"33.00000","1.09782","5047.17432","0.01098","504.71744","0.00001"
"33.30000","1.10765","5063.84912","0.01108","506.38492","0.00000"
"33.60000","1.11785","5083.46582","0.01118","508.34659","-0.00001"
"33.90000","1.12783","5099.93604","0.01128","509.99359","-0.00001"
"34.20000","1.13769","5115.25195","0.01138","511.52521","0.00001"
"34.50000","1.14763","5131.04932","0.01148","513.10492","0.00001"
"34.80000","1.15766","5146.77734","0.01158","514.67773","0.00000"
"35.10000","1.16766","5161.74170","0.01168","516.17419","-0.00002"
"35.40000","1.17782","5177.71143","0.01178","517.77112","0.00000"
"35.70000","1.18783","5191.38965","0.01188","519.13898","0.00001"
"36.00000","1.19780","5203.98730","0.01198","520.39874","0.00000"
"36.30000","1.20775","5215.54150","0.01208","521.55414","-0.00002"
"36.60000","1.21768","5226.07568","0.01218","522.60754","-0.00001"
"36.90000","1.22758","5235.70801","0.01228","523.57080","0.00001"
"37.20000","1.23767","5246.43506","0.01238","524.64349","0.00001"
"37.50000","1.24790","5258.03516","0.01248","525.80353","-0.00002"
"37.80000","1.25773","5265.78369","0.01258","526.57837","-0.00001"
"38.10000","1.26777","5275.78076","0.01268","527.57806","0.00000"
"38.40000","1.27776","5284.73633","0.01278","528.47363","0.00002"
"38.70000","1.28766","5291.51953","0.01288","529.15198","0.00000"
"39.00000","1.29765","5297.96826","0.01298","529.79681","-0.00001"
"39.30000","1.30776","5305.32227","0.01308","530.53223","-0.00001"
"39.60000","1.31762","5309.39941","0.01318","530.93994","0.00001"
"39.90000","1.32780","5316.37207","0.01328","531.63721","0.00001"
"40.20000","1.33769","5320.14648","0.01338","532.01465","-0.00001"
"40.50000","1.34776","5325.09912","0.01348","532.50989","-0.00002"
"40.80000","1.35778","5329.11572","0.01358","532.91156","0.00000"
"41.10000","1.36781","5332.71680","0.01368","533.27167","0.00001"
"41.40000","1.37762","5333.64209","0.01378","533.36420","0.00000"
"41.70000","1.38767","5336.43604","0.01388","533.64362","-0.00001"
"42.00000","1.39762","5338.44971","0.01398","533.84497","-0.00001"
"42.30000","1.40777","5343.29541","0.01408","534.32953","0.00000"
"42.60000","1.41774","5346.35352","0.01418","534.63538","0.00001"
"42.90000","1.42791","5350.87939","0.01428","535.08795","-0.00001"
"43.20000","1.43775","5352.18945","0.01438","535.21893","-0.00002"
"43.50000","1.44767","5355.04199","0.01448","535.50421","0.00000"
"43.80000","1.45757","5358.26514","0.01458","535.82654","0.00001"
"44.10000","1.46768","5363.65088","0.01468","536.36511","0.00000"
"44.40000","1.47774","5368.02539","0.01478","536.80255","-0.00001"
"44.70000","1.48786","5372.68799","0.01488","537.26880","-0.00001"
"45.00000","1.49769","5373.95752","0.01498","537.39575","0.00001"
"45.30000","1.50784","5378.48584","0.01508","537.84857","0.00001"
"45.60000","1.51769","5378.11182","0.01518","537.81116","0.00000"
"45.90000","1.52766","5378.09326","0.01528","537.80933","-0.00001"
"46.20000","1.53765","5377.60840","0.01538","537.76086","0.00000"
"46.50000","1.54772","5377.19385","0.01548","537.71936","0.00001"
"46.80000","1.55776","5376.32324","0.01558","537.63232","0.00000"
"47.10000","1.56778","5374.38965","0.01568","537.43896","-0.00001"
"47.40000","1.57768","5371.19482","0.01578","537.11951","-0.00002"
"47.70000","1.58782","5370.19873","0.01588","537.01990","0.00000"
"48.00000","1.59774","5366.18848","0.01598","536.61884","0.00001"
"48.30000","1.60769","5361.20312","0.01608","536.12030","0.00000"
"48.60000","1.61769","5356.47998","0.01618","535.64801","-0.00001"
"48.90000","1.62763","5353.15723","0.01628","535.31573","0.00000"
"49.20000","1.63776","5352.59277","0.01638","535.25928","0.00001"
"49.50000","1.64774","5350.53223","0.01648","535.05322","0.00000"
"49.80000","1.65780","5348.53613","0.01658","534.85364","-0.00001"
"50.10000","1.66776","5346.18848","0.01668","534.61884","-0.00001"
"50.40000","1.67778","5343.23730","0.01678","534.32373","0.00000"
"50.70000","1.68757","5337.67969","0.01688","533.76794","0.00001"
"51.00000","1.69763","5334.80322","0.01698","533.48035","-0.00001"
"51.30000","1.70770","5331.88672","0.01708","533.18866","-0.00001"
"51.60000","1.71786","5330.07715","0.01718","533.00769","0.00000"
"51.90000","1.72765","5326.08887","0.01728","532.60889","0.00001"
"52.20000","1.73788","5326.70850","0.01738","532.67084","0.00000"
"52.50000","1.74774","5323.12500","0.01748","532.31250","-0.00001"
"52.80000","1.75765","5319.62451","0.01758","531.96246","-0.00001"
"53.10000","1.76759","5315.87207","0.01768","531.58722","0.00000"
"53.40000","1.77772","5313.44971","0.01778","531.34497","0.00000"
"53.70000","1.78769","5308.39600","0.01788","530.83960","0.00000"
"54.00000","1.79792","5305.28174","0.01798","530.52820","-0.00001"
"54.30000","1.80765","5297.77490","0.01808","529.77747","0.00000"
"54.60000","1.81774","5293.18164","0.01818","529.31818","0.00000"
"54.90000","1.82776","5286.76318","0.01828","528.67633","0.00000"
"55.20000","1.83772","5278.75928","0.01838","527.87592","0.00000"
"55.50000","1.84763","5271.40186","0.01848","527.14020","-0.00001"
"55.80000","1.85770","5265.45215","0.01858","526.54523","0.00001"
"56.10000","1.86769","5257.72461","0.01868","525.77246","0.00000"
"56.40000","1.87773","5250.03223","0.01878","525.00323","0.00000"
"56.70000","1.88780","5242.34863","0.01888","524.23486","-0.00001"
"57.00000","1.89784","5236.01660","0.01898","523.60168","0.00000"
"57.30000","1.90772","5227.58545","0.01908","522.75854","0.00000"
"57.60000","1.91772","5220.77148","0.01918","522.07715","-0.00001"
"57.90000","1.92760","5215.11523","0.01928","521.51154","-0.00001"
"58.20000","1.93760","5212.36084","0.01938","521.23608","0.00000"
"58.50000","1.94780","5212.63867","0.01948","521.26385","0.00000"
"58.80000","1.95773","5211.10645","0.01958","521.11066","-0.00001"
"59.10000","1.96779","5211.43164","0.01968","521.14319","-0.00001"
"59.40000","1.97788","5213.33887","0.01978","521.33386","0.00000"
"59.70000","1.98766","5213.06934","0.01988","521.30695","0.00000"
"60.00000","1.99755","5213.86914","0.01998","521.38690","0.00000"
"60.30000","2.00768","5215.13867","0.02008","521.51385","0.00000"
"60.60000","2.01766","5211.82666","0.02018","521.18268","0.00000"
"60.90000","2.02785","5209.63574","0.02028","520.96356","0.00000"
"61.20000","2.03781","5203.01367","0.02038","520.30139","0.00001"
"61.50000","2.04777","5195.10986","0.02048","519.51099","0.00000"
"61.80000","2.05772","5186.67090","0.02058","518.66711","-0.00001"
"62.10000","2.06768","5177.82080","0.02068","517.78210","0.00000"
"62.40000","2.07766","5169.54785","0.02078","516.95477","0.00001"
"62.70000","2.08770","5162.13086","0.02088","516.21307","0.00000"
"63.00000","2.09775","5155.56250","0.02098","515.55627","-0.00002"
"63.30000","2.10777","5149.31982","0.02108","514.93201","-0.00001"
"63.60000","2.11767","5142.86475","0.02118","514.28650","0.00001"
"63.90000","2.12783","5139.55908","0.02128","513.95593","0.00001"
"64.20000","2.13775","5133.40674","0.02138","513.34070","-0.00001"
"64.50000","2.14772","5127.24219","0.02148","512.72424","-0.00001"
"64.80000","2.15767","5121.92578","0.02158","512.19257","0.00000"
"65.10000","2.16763","5117.93750","0.02168","511.79376","0.00001"
"65.40000","2.17770","5114.43896","0.02178","511.44391","0.00000"
"65.70000","2.18778","5110.45996","0.02188","511.04599","-0.00001"
"66.00000","2.19775","5103.38232","0.02198","510.33823","-0.00001"
"66.30000","2.20791","5098.45850","0.02208","509.84586","0.00001"
"66.60000","2.21773","5089.76318","0.02218","508.97632","0.00001"
"66.90000","2.22761","5081.29541","0.02228","508.12955","-0.00001"
"67.20000","2.23762","5074.91113","0.02238","507.49112","-0.00001"
"67.50000","2.24763","5068.56934","0.02248","506.85693","0.00000"
"67.80000","2.25781","5064.46631","0.02258","506.44662","0.00001"
"68.10000","2.26782","5057.62256","0.02268","505.76227","0.00000"
"68.40000","2.27781","5050.07422","0.02278","505.00742","-0.00001"
"68.70000","2.28778","5041.71045","0.02288","504.17105","-0.00001"
"69.00000","2.29773","5034.06445","0.02298","503.40643","0.00000"
"69.30000","2.30760","5026.69141","0.02308","502.66913","0.00001"
"69.60000","2.31769","5021.76221","0.02318","502.17621","0.00000"
"69.90000","2.32771","5015.86523","0.02328","501.58652","-0.00002"
"70.20000","2.33781","5010.77051","0.02338","501.07706","0.00000"
"70.50000","2.34770","5003.22998","0.02348","500.32300","0.00002"
"70.80000","2.35782","4996.87793","0.02358","499.68781","0.00001"
"71.10000","2.36776","4988.47461","0.02368","498.84747","-0.00002"
"71.40000","2.37777","4980.41064","0.02378","498.04108","-0.00001"
"71.70000","2.38765","4971.98682","0.02388","497.19867","0.00001"
"72.00000","2.39767","4965.23193","0.02398","496.52319","0.00001"
"72.30000","2.40766","4958.51807","0.02408","495.85181","-0.00001"
"72.60000","2.41782","4952.22412","0.02418","495.22241","-0.00001"
"72.90000","2.42766","4942.42627","0.02428","494.24261","0.00000"
"73.20000","2.43790","4936.36816","0.02438","493.63681","0.00001"
"73.50000","2.44780","4926.06934","0.02448","492.60693","0.00000"
"73.80000","2.45769","4916.24609","0.02458","491.62460","-0.00001"
"74.10000","2.46762","4908.80371","0.02468","490.88037","-0.00002"
"74.40000","2.47770","4903.67773","0.02478","490.36777","0.00000"
"74.70000","2.48769","4898.77637","0.02488","489.87762","0.00002"
"75.00000","2.49784","4896.67920","0.02498","489.66791","-0.00001"
"75.30000","2.50782","4893.60742","0.02508","489.36075","-0.00002"
"75.60000","2.51778","4890.24951","0.02518","489.02496","0.00000"
"75.90000","2.52770","4886.88867","0.02528","488.68887","0.00001"
"76.20000","2.53767","4883.55762","0.02538","488.35577","0.00000"
"76.50000","2.54766","4880.00195","0.02548","488.00018","-0.00001"
"76.80000","2.55767","4876.68115","0.02558","487.66812","-0.00001"
"77.10000","2.56780","4874.50684","0.02568","487.45068","0.00001"
"77.40000","2.57771","4870.19971","0.02578","487.01996","0.00001"
"77.70000","2.58778","4866.88379","0.02588","486.68839","-0.00001"
"78.00000","2.59785","4862.26318","0.02598","486.22632","-0.00002"
"78.30000","2.60773","4856.51416","0.02608","485.65143","0.00000"
"78.60000","2.61765","4851.99902","0.02618","485.19989","0.00001"
"78.90000","2.62773","4848.35791","0.02628","484.83578","0.00000"
"79.20000","2.63759","4843.07373","0.02638","484.30737","-0.00001"
"79.50000","2.64780","4841.47363","0.02648","484.14737","-0.00001"
"79.80000","2.65771","4835.55176","0.02658","483.55518","0.00001"
"80.10000","2.66779","4829.92090","0.02668","482.99210","0.00001"
"80.40000","2.67781","4824.28223","0.02678","482.42822","-0.00001"
"80.70000","2.68777","4820.08398","0.02688","482.00839","-0.00002"
"81.00000","2.69758","4817.27734","0.02698","481.72772","0.00000"
"81.30000","2.70771","4818.21875","0.02708","481.82187","0.00001"
"81.60000","2.71776","4816.85938","0.02718","481.68594","0.00000"
"81.90000","2.72784","4814.86328","0.02728","481.48633","-0.00001"
"82.20000","2.73772","4810.32373","0.02738","481.03238","-0.00001"
"82.50000","2.74787","4807.97266","0.02748","480.79727","0.00001"
"82.80000","2.75768","4800.55566","0.02758","480.05557","0.00001"
"83.10000","2.76770","4794.41553","0.02768","479.44156","0.00000"
"83.40000","2.77766","4787.17920","0.02778","478.71793","-0.00002"
"83.70000","2.78768","4782.21094","0.02788","478.22110","-0.00001"
"84.00000","2.79773","4778.84717","0.02798","477.88470","0.00001"
"84.30000","2.80785","4776.20117","0.02808","477.62012","0.00000"
"84.60000","2.81767","4769.27734","0.02818","476.92773","-0.00001"
"84.90000","2.82780","4765.98779","0.02828","476.59879","-0.00001"
"85.20000","2.83777","4760.37402","0.02838","476.03741","0.00001"
"85.50000","2.84768","4753.78076","0.02848","475.37808","0.00001"
"85.80000","2.85765","4746.54639","0.02858","474.65463","0.00000"
"86.10000","2.86770","4741.45654","0.02868","474.14566","-0.00001"
"86.40000","2.87773","4738.76172","0.02878","473.87616","0.00000"
"86.70000","2.88775","4737.56641","0.02888","473.75665","0.00001"
"87.00000","2.89782","4737.38721","0.02898","473.73871","0.00001"
"87.30000","2.90783","4735.99609","0.02908","473.59961","-0.00001"
"87.60000","2.91770","4731.51758","0.02918","473.15176","-0.00001"
"87.90000","2.92765","4727.74609","0.02928","472.77460","0.00001"
"88.20000","2.93766","4724.19971","0.02938","472.41998","0.00001"
"88.50000","2.94769","4722.27344","0.02948","472.22736","-0.00001"
"88.80000","2.95786","4722.76025","0.02958","472.27603","-0.00001"
"89.10000","2.96776","4720.07910","0.02968","472.00790","0.00000"
"89.40000","2.97779","4717.91455","0.02978","471.79144","0.00000"
"89.70000","2.98778","4714.59570","0.02988","471.45956","0.00000"
"90.00000","2.99770","4709.47461","0.02998","470.94745","-0.00001"
"90.30000","3.00761","4702.65137","0.03008","470.26514","0.00000"
"90.60000","3.01770","4697.47949","0.03018","469.74796","0.00000"
"90.90000","3.02766","4690.95654","0.03028","469.09564","0.00001"
"91.20000","3.03783","4684.47705","0.03038","468.44769","0.00000"
"91.50000","3.04773","4676.46875","0.03048","467.64688","-0.00001"
"91.80000","3.05783","4673.24805","0.03058","467.32480","0.00000"
"92.10000","3.06770","4669.63867","0.03068","466.96387","0.00001"
"92.40000","3.07774","4667.33887","0.03078","466.73389","0.00000"
"92.70000","3.08763","4662.96045","0.03088","466.29605","-0.00001"
"93.00000","3.09763","4661.79785","0.03098","466.17978","0.00000"
"93.30000","3.10772","4660.78125","0.03108","466.07812","0.00000"
"93.60000","3.11787","4659.83203","0.03118","465.98322","0.00001"
"93.90000","3.12770","4655.86768","0.03128","465.58676","0.00000"
"94.20000","3.13788","4655.38037","0.03138","465.53802","-0.00001"
"94.50000","3.14773","4652.72168","0.03148","465.27216","0.00000"
"94.80000","3.15761","4651.29150","0.03158","465.12915","0.00000"
"95.10000","3.16766","4651.22705","0.03168","465.12271","0.00000"
"95.40000","3.17777","4651.02344","0.03178","465.10236","-0.00001"
"95.70000","3.18777","4649.91455","0.03188","464.99146","0.00000"
"96.00000","3.19777","4647.85059","0.03198","464.78506","0.00000"
"96.30000","3.20779","4646.34814","0.03208","464.63483","0.00000"
"96.60000","3.21776","4645.23535","0.03218","464.52353","-0.00001"
"96.90000","3.22771","4643.66016","0.03228","464.36603","-0.00001"
"97.20000","3.23769","4641.61719","0.03238","464.16171","0.00000"
"97.50000","3.24767","4639.18506","0.03248","463.91852","0.00001"
"97.80000","3.25767","4635.96094","0.03258","463.59610","-0.00001"
"98.10000","3.26782","4633.96436","0.03268","463.39642","0.00000"
"98.40000","3.27768","4629.75537","0.03278","462.97552","0.00000"
"98.70000","3.28779","4627.87402","0.03288","462.78741","0.00001"
"99.00000","3.29786","4626.37598","0.03298","462.63760","0.00000"
"99.30000","3.30771","4622.83398","0.03308","462.28339","-0.00001"
"99.60000","3.31763","4620.50928","0.03318","462.05093","-0.00001"
"99.90000","3.32767","4619.91260","0.03328","461.99127","0.00000"
"100.20000","3.33760","4617.74902","0.03338","461.77490","0.00001"
"100.50000","3.34783","4618.25391","0.03348","461.82538","-0.00001"
"100.80000","3.35784","4616.43359","0.03358","461.64337","-0.00001"
"101.10000","3.36780","4615.34424","0.03368","461.53442","0.00000"
"101.40000","3.37779","4614.97705","0.03378","461.49771","0.00001"
"101.70000","3.38769","4613.61914","0.03388","461.36191","0.00000"
"102.00000","3.39755","4611.64648","0.03398","461.16464","-0.00001"
"102.30000","3.40766","4613.54199","0.03408","461.35419","0.00000"
"102.60000","3.41785","4617.22754","0.03418","461.72275","0.00001"
"102.90000","3.42780","4617.50586","0.03428","461.75058","0.00001"
"103.20000","3.43770","4616.35352","0.03438","461.63535","-0.00001"
"103.50000","3.44780","4616.68311","0.03448","461.66830","-0.00001"
"103.80000","3.45767","4613.58545","0.03458","461.35855","0.00000"
"104.10000","3.46765","4611.66699","0.03468","461.16669","0.00001"
"104.40000","3.47776","4608.96973","0.03478","460.89697","-0.00001"
"104.70000","3.48765","4603.62598","0.03488","460.36261","-0.00001"
"105.00000","3.49775","4601.50000","0.03498","460.14999","-0.00001"
"105.30000","3.50774","4598.09766","0.03508","459.80975","0.00003"
"105.60000","3.51770","4594.06152","0.03518","459.40616","0.00000"
"105.90000","3.52782","4591.35010","0.03528","459.13501","-0.00001"
"106.20000","3.53782","4587.17041","0.03538","458.71704","-0.00001"
"106.50000","3.54768","4582.60352","0.03548","458.26035","0.00001"
"106.80000","3.55768","4580.17188","0.03558","458.01718","0.00001"
"107.10000","3.56764","4577.69385","0.03568","457.76938","-0.00001"
"107.40000","3.57775","4576.77490","0.03578","457.67749","0.00000"
"107.70000","3.58775","4575.96777","0.03588","457.59677","-0.00001"
"108.00000","3.59788","4576.88184","0.03598","457.68817","0.00001"
"108.30000","3.60774","4575.27295","0.03608","457.52728","0.00001"
"108.60000","3.61773","4574.44434","0.03618","457.44443","0.00000"
"108.90000","3.62760","4572.97656","0.03628","457.29767","-0.00001"
"109.20000","3.63765","4573.37744","0.03638","457.33774","0.00000"
"109.50000","3.64769","4573.74805","0.03648","457.37482","0.00002"
"109.80000","3.65792","4576.08887","0.03658","457.60889","0.00000"
"110.10000","3.66766","4573.13623","0.03668","457.31363","-0.00002"
"110.40000","3.67782","4574.73975","0.03678","457.47397","-0.00002"
"110.70000","3.68766","4572.89893","0.03688","457.28989","0.00000"
"111.00000","3.69768","4572.10303","0.03698","457.21030","0.00002"
"111.30000","3.70763","4570.00977","0.03708","457.00098","0.00000"
"111.60000","3.71776","4569.19775","0.03718","456.91977","-0.00001"
"111.90000","3.72769","4566.60059","0.03728","456.66006","0.00000"
"112.20000","3.73780","4566.39307","0.03738","456.63931","0.00002"
"112.50000","3.74766","4564.22607","0.03748","456.42261","0.00000"
"112.80000","3.75783","4565.34082","0.03758","456.53409","-0.00002"
"113.10000","3.76774","4564.20996","0.03768","456.42099","-0.00001"
"113.40000","3.77772","4561.94043","0.03778","456.19403","0.00001"
"113.70000","3.78767","4557.71240","0.03788","455.77124","0.00000"
"114.00000","3.79769","4553.88135","0.03798","455.38812","-0.00001"
"114.30000","3.80773","4549.34961","0.03808","454.93497","-0.00001"
"114.60000","3.81780","4546.62305","0.03818","454.66229","0.00001"
"114.90000","3.82776","4544.49072","0.03828","454.44907","0.00001"
"115.20000","3.83782","4544.12939","0.03838","454.41293","0.00000"
"115.50000","3.84776","4543.55420","0.03848","454.35541","-0.00002"
"115.80000","3.85760","4541.93164","0.03858","454.19318","0.00000"
"116.10000","3.86763","4541.55664","0.03868","454.15567","0.00001"
"116.40000","3.87763","4541.50977","0.03878","454.15097","0.00001"
"116.70000","3.88784","4544.15576","0.03888","454.41559","-0.00001"
"117.00000","3.89769","4542.68750","0.03898","454.26874","-0.00001"
"117.30000","3.90782","4543.54102","0.03908","454.35410","0.00000"
"117.60000","3.91776","4542.74951","0.03918","454.27496","0.00002"
"117.90000","3.92767","4540.42090","0.03928","454.04208","0.00000"
"118.20000","3.93763","4538.36865","0.03938","453.83685","0.00003"
"118.50000","3.94772","4537.80225","0.03948","453.78021","0.00003"
"118.80000","3.95764","4535.27148","0.03958","453.52716","-0.00007"
"119.10000","3.96789","4533.36230","0.03968","453.33624","-0.00007"
"119.40000","3.97766","4526.83740","0.03978","452.68375","0.00008"
"119.70000","3.98774","4524.00781","0.03988","452.40079","0.00000"
"120.00000","3.99775","4521.61768","0.03998","452.16177","-0.00003"
"120.30000","4.00773","4520.15674","0.04008","452.01569","0.00001"
"120.60000","4.01764","4519.04150","0.04018","451.90414","0.00003"
"120.90000","4.02776","4521.64355","0.04028","452.16437","-0.00002"
"121.20000","4.03764","4523.21338","0.04038","452.32135","-0.00002"
"121.50000","4.04775","4525.47754","0.04048","452.54776","0.00002"
"121.80000","4.05772","4526.32471","0.04058","452.63248","0.00002"
"122.10000","4.06785","4528.22900","0.04068","452.82291","-0.00001"
"122.40000","4.07769","4527.56006","0.04078","452.75601","-0.00002"
"122.70000","4.08774","4528.22217","0.04088","452.82220","0.00001"
"123.00000","4.09759","4527.53564","0.04098","452.75357","0.00002"
"123.30000","4.10764","4528.25146","0.04108","452.82513","0.00002"
"123.60000","4.11776","4529.60107","0.04118","452.96011","-0.00007"
"123.90000","4.12777","4529.63477","0.04128","452.96347","-0.00001"
"124.20000","4.13769","4528.02441","0.04138","452.80243","0.00003"
"124.50000","4.14790","4529.53809","0.04148","452.95380","0.00002"
"124.80000","4.15767","4527.00537","0.04158","452.70053","-0.00003"
"125.10000","4.16758","4525.68555","0.04168","452.56854","0.00004"
"125.40000","4.17767","4524.80322","0.04178","452.48032","0.00000"
"125.70000","4.18772","4522.14355","0.04188","452.21436","0.00000"
"126.00000","4.19781","4518.54443","0.04198","451.85443","-0.00002"
"126.30000","4.20786","4515.97656","0.04208","451.59766","0.00000"
"126.60000","4.21771","4513.87109","0.04218","451.38712","0.00001"
"126.90000","4.22768","4514.40088","0.04228","451.44009","0.00000"
"127.20000","4.23773","4515.95898","0.04238","451.59589","0.00000"
"127.50000","4.24768","4515.83545","0.04248","451.58356","-0.00001"
"127.80000","4.25769","4515.58887","0.04258","451.55890","-0.00001"
"128.10000","4.26773","4514.36865","0.04268","451.43686","0.00000"
"128.40000","4.27778","4512.29053","0.04278","451.22906","0.00001"
"128.70000","4.28767","4508.25488","0.04288","450.82550","0.00000"
"129.00000","4.29782","4506.97900","0.04298","450.69791","-0.00001"
"129.30000","4.30778","4502.72168","0.04308","450.27216","0.00000"
"129.60000","4.31770","4495.99268","0.04318","449.59927","0.00001"
"129.90000","4.32767","4490.64502","0.04328","449.06451","0.00000"
"130.20000","4.33766","4485.43750","0.04338","448.54376","0.00000"
"130.50000","4.34765","4480.70947","0.04348","448.07095","-0.00001"
"130.80000","4.35777","4477.11914","0.04358","447.71191","0.00001"
"131.10000","4.36768","4473.86230","0.04368","447.38623","0.00001"
"131.40000","4.37789","4473.56494","0.04378","447.35651","0.00000"
"131.70000","4.38779","4471.30225","0.04388","447.13022","-0.00001"
"132.00000","4.39767","4470.14355","0.04398","447.01434","0.00000"
"132.30000","4.40759","4468.93457","0.04408","446.89346","0.00001"
"132.60000","4.41767","4466.03125","0.04418","446.60312","0.00000"
"132.90000","4.42777","4463.30420","0.04428","446.33041","-0.00001"
"133.20000","4.43786","4461.84521","0.04438","446.18451","0.00000"
"133.50000","4.44777","4458.12842","0.04448","445.81284","0.00001"
"133.80000","4.45778","4455.42676","0.04458","445.54266","0.00001"
"134.10000","4.46770","4452.03467","0.04468","445.20346","0.00000"
"134.40000","4.47768","4448.34668","0.04478","444.83466","-0.00001"
"134.70000","4.48768","4445.47266","0.04488","444.54727","0.00000"
"135.00000","4.49768","4442.70166","0.04498","444.27017","0.00001"
"135.30000","4.50782","4441.94922","0.04508","444.19492","0.00000"
"135.60000","4.51771","4439.49268","0.04518","443.94928","-0.00001"
"135.90000","4.52775","4438.07080","0.04528","443.80707","0.00000"
"136.20000","4.53776","4436.75391","0.04538","443.67538","0.00002"
"136.50000","4.54776","4434.64795","0.04548","443.46478","0.00005"
"136.80000","4.55767","4430.55420","0.04558","443.05542","0.00001"
"137.10000","4.56769","4427.92773","0.04568","442.79279","-0.00004"
"137.40000","4.57763","4424.07031","0.04578","442.40704","0.00000"
"137.70000","4.58782","4423.53760","0.04588","442.35376","0.00002"
"138.00000","4.59765","4419.87549","0.04598","441.98755","0.00000"
"138.30000","4.60786","4419.59180","0.04608","441.95917","-0.00002"
"138.60000","4.61782","4415.73389","0.04618","441.57339","0.00000"
"138.90000","4.62770","4410.00879","0.04628","441.00089","0.00001"
"139.20000","4.63761","4404.77637","0.04638","440.47763","0.00001"
"139.50000","4.64771","4400.73145","0.04648","440.07315","-0.00001"
"139.80000","4.65765","4395.17529","0.04658","439.51752","-0.00001"
"140.10000","4.66787","4392.92383","0.04668","439.29239","0.00000"
"140.40000","4.67778","4388.09277","0.04678","438.80927","0.00001"
"140.70000","4.68782","4383.91064","0.04688","438.39105","0.00000"
"141.00000","4.69773","4379.05029","0.04698","437.90503","0.00000"
"141.30000","4.70771","4374.89404","0.04708","437.48941","0.00000"
"141.60000","4.71761","4370.56201","0.04718","437.05621","0.00001"
"141.90000","4.72769","4369.04395","0.04728","436.90439","0.00000"
"142.20000","4.73776","4366.91602","0.04738","436.69159","0.00000"
"142.50000","4.74778","4364.24316","0.04748","436.42432","-0.00001"
"142.80000","4.75772","4360.13770","0.04758","436.01376","0.00000"
"143.10000","4.76787","4359.23779","0.04768","435.92377","0.00001"
"143.40000","4.77773","4355.41846","0.04778","435.54184","0.00000"
"143.70000","4.78768","4351.78564","0.04788","435.17856","-0.00001"
"144.00000","4.79770","4349.61572","0.04798","434.96158","0.00000"
"144.30000","4.80759","4347.10547","0.04808","434.71054","0.00001"
"144.60000","4.81778","4347.62207","0.04818","434.76221","0.00001"
"144.90000","4.82775","4345.24463","0.04828","434.52448","0.00000"
"145.20000","4.83776","4342.26221","0.04838","434.22623","-0.00001"
"145.50000","4.84786","4338.04541","0.04848","433.80453","0.00000"
"145.80000","4.85776","4330.88428","0.04858","433.08844","0.00001"
"146.10000","4.86760","4324.86084","0.04868","432.48608","0.00000"
"146.40000","4.87764","4321.13379","0.04878","432.11337","-0.00001"
"146.70000","4.88769","4317.92139","0.04888","431.79214","-0.00001"
"147.00000","4.89782","4315.83105","0.04898","431.58310","0.00001"
"147.30000","4.90780","4312.52881","0.04908","431.25287","0.00001"
"147.60000","4.91786","4311.00244","0.04918","431.10025","0.00000"
"147.90000","4.92770","4308.12500","0.04928","430.81250","-0.00001"
"148.20000","4.93769","4306.34619","0.04938","430.63461","0.00000"
"148.50000","4.94764","4305.44775","0.04948","430.54477","0.00001"
"148.80000","4.95770","4305.20312","0.04958","430.52032","0.00000"
"149.10000","4.96770","4302.66309","0.04968","430.26630","-0.00001"
"149.40000","4.97785","4302.29590","0.04978","430.22958","0.00000"
"149.70000","4.98767","4300.10742","0.04988","430.01074","0.00000"
"150.00000","4.99782","4301.03418","0.04998","430.10342","0.00000"
"150.30000","5.00781","4300.15869","0.05008","430.01587","-0.00001"
"150.60000","5.01768","4297.85156","0.05018","429.78516","-0.00001"
"150.90000","5.02761","4294.26562","0.05028","429.42657","0.00002"
"151.20000","5.03772","4290.15479","0.05038","429.01547","0.00001"
"151.50000","5.04771","4283.92920","0.05048","428.39291","0.00000"
"151.80000","5.05780","4279.81885","0.05058","427.98187","-0.00002"
"152.10000","5.06776","4275.57373","0.05068","427.55737","0.00001"
"152.40000","5.07783","4273.58643","0.05078","427.35864","0.00001"
"152.70000","5.08772","4269.61621","0.05088","426.96161","0.00004"
"153.00000","5.09770","4265.42090","0.05098","426.54208","-0.00011"
"153.30000","5.10759","4260.74268","0.05108","426.07428","-0.00002"
"153.60000","5.11767","4257.53467","0.05118","425.75348","0.00006"
"153.90000","5.12786","4255.02881","0.05128","425.50287","0.00000"
"154.20000","5.13780","4252.69775","0.05138","425.26978","-0.00003"
"154.50000","5.14777","4251.69678","0.05148","425.16968","-0.00002"
"154.80000","5.15781","4252.18750","0.05158","425.21875","0.00002"
"155.10000","5.16768","4251.11377","0.05168","425.11139","0.00000"
"155.40000","5.17760","4248.95508","0.05178","424.89551","0.00000"
"155.70000","5.18770","4247.79395","0.05188","424.77939","0.00000"
"156.00000","5.19764","4244.84814","0.05198","424.48480","-0.00001"
"156.30000","5.20781","4243.12451","0.05208","424.31244","0.00001"
"156.60000","5.21779","4238.69141","0.05218","423.86914","-0.00004"
"156.90000","5.22779","4233.90527","0.05228","423.39053","0.00001"
"157.20000","5.23775","4229.64648","0.05238","422.96466","0.00002"
"157.50000","5.24775","4225.09668","0.05248","422.50967","-0.00001"
"157.80000","5.25761","4217.57666","0.05258","421.75766","-0.00001"
"158.10000","5.26766","4212.59814","0.05268","421.25983","0.00003"
"158.40000","5.27770","4209.24316","0.05278","420.92432","0.00000"
"158.70000","5.28786","4207.35059","0.05288","420.73505","-0.00002"
"158.94800","5.29606","4205.58887","0.05296","420.55890","0.00001"