File: Tension/Section_2_Group_2/rivet_low_Sample2.is_tens_RawData/Specimen_RawData_1.csv
Time,Extension,Load,Tensile strain (Extension),Tensile stress,Strain-by-clip-gage
(s),(mm),(N),(mm/mm),(MPa),(mm/mm)
"0.00000","0.00000","-741.18683","0.00000","-74.11868","-0.00010"
"0.50000","0.01442","-683.66534","0.00014","-68.36653","-0.00010"
"1.00000","0.03113","-622.27637","0.00031","-62.22764","-0.00011"
"1.50000","0.04767","-566.41077","0.00048","-56.64108","-0.00011"
"2.00000","0.06450","-514.49591","0.00064","-51.44959","-0.00010"
"2.50000","0.08096","-469.33777","0.00081","-46.93378","-0.00010"
"3.00000","0.09774","-428.13239","0.00098","-42.81324","-0.00010"
"3.50000","0.11435","-391.28192","0.00114","-39.12819","-0.00009"
"4.00000","0.13116","-356.02023","0.00131","-35.60202","-0.00009"
"4.50000","0.14779","-322.66034","0.00148","-32.26603","-0.00009"
"5.00000","0.16444","-289.51849","0.00164","-28.95185","-0.00009"
"5.50000","0.18110","-256.46198","0.00181","-25.64620","-0.00008"
"6.00000","0.19771","-223.26263","0.00198","-22.32626","-0.00006"
"6.50000","0.21446","-189.54459","0.00214","-18.95446","-0.00007"
"7.00000","0.23106","-157.00146","0.00231","-15.70015","-0.00008"
"7.50000","0.24787","-124.57687","0.00248","-12.45769","-0.00009"
"8.00000","0.26427","-94.01582","0.00264","-9.40158","-0.00009"
"8.50000","0.28107","-62.46436","0.00281","-6.24644","-0.00009"
"9.00000","0.29771","-32.02859","0.00298","-3.20286","-0.00009"
"9.50000","0.31458","-1.15319","0.00315","-0.11532","-0.00009"
"10.00000","0.33101","27.12225","0.00331","2.71222","-0.00010"
"10.50000","0.34768","56.55816","0.00348","5.65582","-0.00011"
"11.00000","0.36445","85.53732","0.00364","8.55373","-0.00016"
"11.50000","0.38109","113.88270","0.00381","11.38827","-0.00013"
"12.00000","0.39788","143.25050","0.00398","14.32505","-0.00015"
"12.50000","0.41440","170.76213","0.00414","17.07621","-0.00012"
"13.00000","0.43101","198.56587","0.00431","19.85659","-0.00012"
"13.50000","0.44768","226.59253","0.00448","22.65925","-0.00012"
"14.00000","0.46446","254.58058","0.00464","25.45806","-0.00012"
"14.50000","0.48109","281.43552","0.00481","28.14355","-0.00012"
"15.00000","0.49784","308.75775","0.00498","30.87577","-0.00011"
"15.50000","0.51431","333.58127","0.00514","33.35813","-0.00010"
"16.00000","0.53112","360.49551","0.00531","36.04955","-0.00010"
"16.50000","0.54797","386.33630","0.00548","38.63363","-0.00009"
"17.00000","0.56436","409.56113","0.00564","40.95611","-0.00007"
"17.50000","0.58117","434.08194","0.00581","43.40820","-0.00008"
"18.00000","0.59765","455.53677","0.00598","45.55368","-0.00008"
"18.50000","0.61441","476.89124","0.00614","47.68913","-0.00008"
"19.00000","0.63105","495.22803","0.00631","49.52280","-0.00008"
"19.50000","0.64779","512.06409","0.00648","51.20641","-0.00008"
"20.00000","0.66441","526.73047","0.00664","52.67305","-0.00009"
"20.50000","0.68112","541.23688","0.00681","54.12369","-0.00009"
"21.00000","0.69769","554.12573","0.00698","55.41257","-0.00010"
"21.50000","0.71444","566.44385","0.00714","56.64439","-0.00010"
"22.00000","0.73118","572.95538","0.00731","57.29554","-0.00010"
"22.50000","0.74770","569.70081","0.00748","56.97008","-0.00011"
"23.00000","0.76441","568.33014","0.00764","56.83302","-0.00011"
"23.50000","0.78102","572.51831","0.00781","57.25183","-0.00012"
"24.00000","0.79772","577.58911","0.00798","57.75891","-0.00012"
"24.50000","0.81438","582.67047","0.00814","58.26705","-0.00011"
"25.00000","0.83114","588.47229","0.00831","58.84723","-0.00011"
"25.50000","0.84775","589.92828","0.00848","58.99283","-0.00011"
"26.00000","0.86444","590.28345","0.00864","59.02834","-0.00011"
"26.50000","0.88108","589.97296","0.00881","58.99730","-0.00010"
"27.00000","0.89778","586.52161","0.00898","58.65216","-0.00010"
"27.50000","0.91453","581.70667","0.00915","58.17067","-0.00009"
"28.00000","0.93108","577.93622","0.00931","57.79362","-0.00008"
"28.50000","0.94774","576.37384","0.00948","57.63738","-0.00008"
"29.00000","0.96435","579.49689","0.00964","57.94969","-0.00008"
"29.50000","0.98109","584.65125","0.00981","58.46513","-0.00009"
"30.00000","0.99769","586.47675","0.00998","58.64767","-0.00009"
"30.50000","1.01459","586.75305","0.01015","58.67530","-0.00009"
"31.00000","1.03113","583.24841","0.01031","58.32484","-0.00009"
"31.50000","1.04773","583.64508","0.01048","58.36451","-0.00009"
"32.00000","1.06447","585.28864","0.01064","58.52886","-0.00010"
"32.50000","1.08108","582.85944","0.01081","58.28594","-0.00010"
"33.00000","1.09792","572.17847","0.01098","57.21785","-0.00011"
"33.50000","1.11434","557.50256","0.01114","55.75026","-0.00010"
"34.00000","1.13103","553.82245","0.01131","55.38224","-0.00010"
"34.50000","1.14769","554.66266","0.01148","55.46627","-0.00012"
"35.00000","1.16448","559.44092","0.01164","55.94409","-0.00011"
"35.50000","1.18105","566.23761","0.01181","56.62376","-0.00010"
"36.00000","1.19780","574.22308","0.01198","57.42231","-0.00010"
"36.50000","1.21434","580.92273","0.01214","58.09227","-0.00010"
"37.00000","1.23111","589.58813","0.01231","58.95881","-0.00010"
"37.50000","1.24784","592.71649","0.01248","59.27165","-0.00009"
"38.00000","1.26445","596.33142","0.01264","59.63314","-0.00009"
"38.50000","1.28110","602.99988","0.01281","60.29999","-0.00009"
"39.00000","1.29761","609.67743","0.01298","60.96774","-0.00009"
"39.50000","1.31440","616.67609","0.01314","61.66761","-0.00009"
"40.00000","1.33114","620.67773","0.01331","62.06777","-0.00009"
"40.50000","1.34781","624.10303","0.01348","62.41030","-0.00009"
"41.00000","1.36436","626.49023","0.01364","62.64902","-0.00009"
"41.50000","1.38110","628.71063","0.01381","62.87106","-0.00009"
"42.00000","1.39778","629.60956","0.01398","62.96096","-0.00009"
"42.50000","1.41443","630.62280","0.01414","63.06228","-0.00009"
"43.00000","1.43116","631.78516","0.01431","63.17852","-0.00010"
"43.50000","1.44772","633.19043","0.01448","63.31904","-0.00010"
"44.00000","1.46441","636.52496","0.01464","63.65250","-0.00011"
"44.50000","1.48096","636.26678","0.01481","63.62668","-0.00011"
"45.00000","1.49778","627.19098","0.01498","62.71910","-0.00011"
"45.50000","1.51440","625.96600","0.01514","62.59660","-0.00011"
"46.00000","1.53119","615.93317","0.01531","61.59332","-0.00011"
"46.50000","1.54769","602.48383","0.01548","60.24838","-0.00011"
"47.00000","1.56446","598.59906","0.01564","59.85991","-0.00010"
"47.50000","1.58116","598.94897","0.01581","59.89490","-0.00011"
"48.00000","1.59774","603.94135","0.01598","60.39413","-0.00010"
"48.50000","1.61449","609.42017","0.01614","60.94202","-0.00009"
"49.00000","1.63106","610.15015","0.01631","61.01501","-0.00009"
"49.50000","1.64772","594.74310","0.01648","59.47431","-0.00009"
"50.00000","1.66435","556.23755","0.01664","55.62376","-0.00008"
"50.50000","1.68116","551.59546","0.01681","55.15955","-0.00009"
"51.00000","1.69770","555.79425","0.01698","55.57943","-0.00009"
"51.50000","1.71453","564.50146","0.01715","56.45015","-0.00008"
"52.00000","1.73104","571.53326","0.01731","57.15333","-0.00009"
"52.50000","1.74780","580.50885","0.01748","58.05088","-0.00009"
"53.00000","1.76453","581.79730","0.01765","58.17973","-0.00010"
"53.50000","1.78102","590.44971","0.01781","59.04497","-0.00011"
"54.00000","1.79789","603.39642","0.01798","60.33964","-0.00011"
"54.50000","1.81436","613.10083","0.01814","61.31008","-0.00011"
"55.00000","1.83102","624.03809","0.01831","62.40381","-0.00011"
"55.50000","1.84771","632.57544","0.01848","63.25755","-0.00011"
"56.00000","1.86451","639.65839","0.01865","63.96584","-0.00010"
"56.50000","1.88110","640.15070","0.01881","64.01507","-0.00010"
"57.00000","1.89782","616.04279","0.01898","61.60428","-0.00011"
"57.50000","1.91435","598.52527","0.01914","59.85253","-0.00010"
"58.00000","1.93109","588.45197","0.01931","58.84520","-0.00010"
"58.50000","1.94786","589.69824","0.01948","58.96983","-0.00010"
"59.00000","1.96436","597.13342","0.01964","59.71334","-0.00010"
"59.50000","1.98109","605.87402","0.01981","60.58740","-0.00009"
"60.00000","1.99760","609.73053","0.01998","60.97305","-0.00010"
"60.50000","2.01443","618.89703","0.02014","61.88970","-0.00009"
"61.00000","2.03109","614.09882","0.02031","61.40988","-0.00008"
"61.50000","2.04789","625.06628","0.02048","62.50663","-0.00008"
"62.00000","2.06435","636.66864","0.02064","63.66686","-0.00008"
"62.50000","2.08107","650.08551","0.02081","65.00855","-0.00008"
"63.00000","2.09778","662.64899","0.02098","66.26490","-0.00008"
"63.50000","2.11448","674.15137","0.02114","67.41514","-0.00009"
"64.00000","2.13113","684.33087","0.02131","68.43309","-0.00009"
"64.50000","2.14769","693.28619","0.02148","69.32862","-0.00010"
"65.00000","2.16443","702.84363","0.02164","70.28436","-0.00010"
"65.50000","2.18104","712.64642","0.02181","71.26464","-0.00011"
"66.00000","2.19781","722.07593","0.02198","72.20760","-0.00011"
"66.50000","2.21436","727.90002","0.02214","72.79000","-0.00011"
"67.00000","2.23122","735.98035","0.02231","73.59804","-0.00011"
"67.50000","2.24771","740.32794","0.02248","74.03279","-0.00011"
"68.00000","2.26435","745.37701","0.02264","74.53770","-0.00011"
"68.50000","2.28122","752.32147","0.02281","75.23215","-0.00011"
"69.00000","2.29774","758.25684","0.02298","75.82568","-0.00010"
"69.50000","2.31445","762.52460","0.02314","76.25246","-0.00010"
"70.00000","2.33102","768.29553","0.02331","76.82955","-0.00010"
"70.50000","2.34775","773.96686","0.02348","77.39668","-0.00009"
"71.00000","2.36437","750.71350","0.02364","75.07135","-0.00009"
"71.50000","2.38117","751.41687","0.02381","75.14169","-0.00009"
"72.00000","2.39766","755.10876","0.02398","75.51088","-0.00009"
"72.50000","2.41448","762.01807","0.02414","76.20181","-0.00008"
"73.00000","2.43104","766.11230","0.02431","76.61123","-0.00009"
"73.50000","2.44777","769.38837","0.02448","76.93884","-0.00009"
"74.00000","2.46456","772.95319","0.02465","77.29532","-0.00009"
"74.50000","2.48103","777.04492","0.02481","77.70449","-0.00009"
"75.00000","2.49779","785.60712","0.02498","78.56071","-0.00009"
"75.50000","2.51432","791.71912","0.02514","79.17191","-0.00010"
"76.00000","2.53114","799.32770","0.02531","79.93277","-0.00010"
"76.50000","2.54773","808.08185","0.02548","80.80818","-0.00011"
"77.00000","2.56445","818.08801","0.02564","81.80880","-0.00011"
"77.50000","2.58102","825.42188","0.02581","82.54219","-0.00011"
"78.00000","2.59785","833.15863","0.02598","83.31586","-0.00011"
"78.50000","2.61437","838.45013","0.02614","83.84502","-0.00011"
"79.00000","2.63108","844.81195","0.02631","84.48119","-0.00011"
"79.50000","2.64789","849.23224","0.02648","84.92323","-0.00011"
"80.00000","2.66442","843.77258","0.02664","84.37726","-0.00011"
"80.50000","2.68108","823.99609","0.02681","82.39961","-0.00010"
"81.00000","2.69759","807.09521","0.02698","80.70952","-0.00009"
"81.50000","2.71442","793.07697","0.02714","79.30769","-0.00009"
"82.00000","2.73108","780.94421","0.02731","78.09442","-0.00009"
"82.50000","2.74780","778.31854","0.02748","77.83186","-0.00009"
"83.00000","2.76439","776.33459","0.02764","77.63346","-0.00008"
"83.50000","2.78108","773.98291","0.02781","77.39829","-0.00008"
"84.00000","2.79783","774.44928","0.02798","77.44493","-0.00009"
"84.50000","2.81441","775.41705","0.02814","77.54170","-0.00009"
"85.00000","2.83122","778.15387","0.02831","77.81538","-0.00009"
"85.50000","2.84767","780.92572","0.02848","78.09258","-0.00009"
"86.00000","2.86434","783.83704","0.02864","78.38371","-0.00010"
"86.50000","2.88099","788.73218","0.02881","78.87321","-0.00010"
"87.00000","2.89790","796.21954","0.02898","79.62196","-0.00010"
"87.50000","2.91435","800.12317","0.02914","80.01231","-0.00010"
"88.00000","2.93118","805.17950","0.02931","80.51795","-0.00011"
"88.50000","2.94774","808.97314","0.02948","80.89732","-0.00011"
"89.00000","2.96448","813.57117","0.02964","81.35712","-0.00011"
"89.50000","2.98122","819.00983","0.02981","81.90099","-0.00011"
"90.00000","2.99768","823.17639","0.02998","82.31764","-0.00011"
"90.50000","3.01449","828.86115","0.03014","82.88612","-0.00010"
"91.00000","3.03099","833.59747","0.03031","83.35975","-0.00010"
"91.50000","3.04768","836.63501","0.03048","83.66350","-0.00010"
"92.00000","3.06439","840.48938","0.03064","84.04893","-0.00010"
"92.50000","3.08118","846.40503","0.03081","84.64050","-0.00009"
"93.00000","3.09771","850.63147","0.03098","85.06315","-0.00009"
"93.50000","3.11441","856.43817","0.03114","85.64381","-0.00008"
"94.00000","3.13114","861.39349","0.03131","86.13935","-0.00008"
"94.50000","3.14776","864.82709","0.03148","86.48271","-0.00008"
"95.00000","3.16451","867.15558","0.03165","86.71556","-0.00008"
"95.50000","3.18096","867.42389","0.03181","86.74239","-0.00009"
"96.00000","3.19775","869.84595","0.03198","86.98460","-0.00009"
"96.50000","3.21432","871.45941","0.03214","87.14594","-0.00009"
"97.00000","3.23113","874.46777","0.03231","87.44678","-0.00010"
"97.50000","3.24774","876.40240","0.03248","87.64024","-0.00010"
"98.00000","3.26450","878.09570","0.03264","87.80957","-0.00010"
"98.50000","3.28106","879.57355","0.03281","87.95735","-0.00011"
"99.00000","3.29777","881.99304","0.03298","88.19930","-0.00011"
"99.50000","3.31450","884.93823","0.03315","88.49382","-0.00011"
"100.00000","3.33107","887.33099","0.03331","88.73310","-0.00011"
"100.50000","3.34777","889.48486","0.03348","88.94849","-0.00011"
"101.00000","3.36438","891.32751","0.03364","89.13275","-0.00011"
"101.50000","3.38117","893.59497","0.03381","89.35950","-0.00011"
"102.00000","3.39765","892.36469","0.03398","89.23647","-0.00011"
"102.50000","3.41447","888.32819","0.03414","88.83282","-0.00010"
"103.00000","3.43105","879.99225","0.03431","87.99922","-0.00010"
"103.50000","3.44788","872.86847","0.03448","87.28685","-0.00009"
"104.00000","3.46441","859.54822","0.03464","85.95482","-0.00009"
"104.50000","3.48103","853.29218","0.03481","85.32922","-0.00009"
"105.00000","3.49788","842.78455","0.03498","84.27846","-0.00009"
"105.50000","3.51440","822.97113","0.03514","82.29711","-0.00008"
"106.00000","3.53113","817.55658","0.03531","81.75566","-0.00008"
"106.50000","3.54768","817.19226","0.03548","81.71922","-0.00009"
"107.00000","3.56435","820.34875","0.03564","82.03487","-0.00009"
"107.50000","3.58105","825.95544","0.03581","82.59554","-0.00010"
"108.00000","3.59783","832.38098","0.03598","83.23810","-0.00010"
"108.50000","3.61441","838.09967","0.03614","83.80997","-0.00010"
"109.00000","3.63113","843.89008","0.03631","84.38901","-0.00010"
"109.50000","3.64773","848.99628","0.03648","84.89963","-0.00011"
"110.00000","3.66441","853.57605","0.03664","85.35760","-0.00011"
"110.50000","3.68129","858.01978","0.03681","85.80198","-0.00011"
"111.00000","3.69767","858.53644","0.03698","85.85365","-0.00011"
"111.50000","3.71447","861.09851","0.03714","86.10985","-0.00011"
"112.00000","3.73096","862.73981","0.03731","86.27398","-0.00011"
"112.50000","3.74777","867.96564","0.03748","86.79656","-0.00010"
"113.00000","3.76442","872.53320","0.03764","87.25332","-0.00010"
"113.50000","3.78113","876.20990","0.03781","87.62099","-0.00009"
"114.00000","3.79774","872.96155","0.03798","87.29616","-0.00009"
"114.50000","3.81441","875.27362","0.03814","87.52736","-0.00009"
"115.00000","3.83109","877.90082","0.03831","87.79008","-0.00008"
"115.50000","3.84780","881.27618","0.03848","88.12762","-0.00008"
"116.00000","3.86455","885.26288","0.03865","88.52629","-0.00008"
"116.50000","3.88098","888.51477","0.03881","88.85148","-0.00008"
"117.00000","3.89771","893.32788","0.03898","89.33279","-0.00008"
"117.50000","3.91436","897.65137","0.03914","89.76514","-0.00009"
"118.00000","3.93117","903.73724","0.03931","90.37373","-0.00009"
"118.50000","3.94773","907.74884","0.03948","90.77489","-0.00009"
"119.00000","3.96445","912.81177","0.03964","91.28117","-0.00010"
"119.50000","3.98106","914.41479","0.03981","91.44148","-0.00010"
"120.00000","3.99773","913.73737","0.03998","91.37373","-0.00011"
"120.50000","4.01452","904.99359","0.04015","90.49936","-0.00011"
"121.00000","4.03111","853.01868","0.04031","85.30186","-0.00011"
"121.50000","4.04777","833.73438","0.04048","83.37344","-0.00011"
"122.00000","4.06434","827.52875","0.04064","82.75288","-0.00011"
"122.50000","4.08106","826.11432","0.04081","82.61143","-0.00011"
"123.00000","4.09773","826.58588","0.04098","82.65858","-0.00010"
"123.50000","4.11451","828.21545","0.04115","82.82155","-0.00010"
"124.00000","4.13102","828.05579","0.04131","82.80558","-0.00010"
"124.50000","4.14788","827.59149","0.04148","82.75915","-0.00009"
"125.00000","4.16456","823.51135","0.04165","82.35114","-0.00009"
"125.50000","4.18103","822.72400","0.04181","82.27240","-0.00009"
"126.00000","4.19786","786.26984","0.04198","78.62698","-0.00008"
"126.50000","4.21435","771.82227","0.04214","77.18223","-0.00008"
"127.00000","4.23113","767.00372","0.04231","76.70037","-0.00008"
"127.50000","4.24767","765.04834","0.04248","76.50484","-0.00008"
"128.00000","4.26436","764.63220","0.04264","76.46322","-0.00008"
"128.50000","4.28107","765.16528","0.04281","76.51653","-0.00008"
"129.00000","4.29786","765.21796","0.04298","76.52180","-0.00009"
"129.50000","4.31434","762.37225","0.04314","76.23723","-0.00010"
"130.00000","4.33113","764.39569","0.04331","76.43957","-0.00010"
"130.50000","4.34774","765.63538","0.04348","76.56354","-0.00010"
"131.00000","4.36441","768.71002","0.04364","76.87100","-0.00011"
"131.50000","4.38116","770.30115","0.04381","77.03011","-0.00011"
"132.00000","4.39773","772.62891","0.04398","77.26289","-0.00012"
"132.50000","4.41438","774.52783","0.04414","77.45278","-0.00012"
"133.00000","4.43099","774.64801","0.04431","77.46480","-0.00011"
"133.50000","4.44779","774.70264","0.04448","77.47026","-0.00011"
"134.00000","4.46448","774.99219","0.04464","77.49922","-0.00011"
"134.50000","4.48115","775.09357","0.04481","77.50935","-0.00010"
"135.00000","4.49767","774.67511","0.04498","77.46751","-0.00010"
"135.50000","4.51443","775.68872","0.04514","77.56887","-0.00009"
"136.00000","4.53117","777.32739","0.04531","77.73274","-0.00009"
"136.50000","4.54779","780.19690","0.04548","78.01969","-0.00009"
"137.00000","4.56448","784.13159","0.04564","78.41316","-0.00008"
"137.50000","4.58105","787.67377","0.04581","78.76738","-0.00008"
"138.00000","4.59774","782.97479","0.04598","78.29748","-0.00008"
"138.50000","4.61432","771.07166","0.04614","77.10716","-0.00008"
"139.00000","4.63120","770.69312","0.04631","77.06931","-0.00008"
"139.50000","4.64777","771.86554","0.04648","77.18655","-0.00009"
"140.00000","4.66445","773.72363","0.04664","77.37236","-0.00009"
"140.50000","4.68103","771.73639","0.04681","77.17364","-0.00010"
"141.00000","4.69777","771.12317","0.04698","77.11232","-0.00010"
"141.50000","4.71459","770.84454","0.04715","77.08446","-0.00010"
"142.00000","4.73105","767.45007","0.04731","76.74501","-0.00011"
"142.50000","4.74779","767.04529","0.04748","76.70453","-0.00011"
"143.00000","4.76433","767.23029","0.04764","76.72303","-0.00011"
"143.50000","4.78108","768.75629","0.04781","76.87563","-0.00011"
"144.00000","4.79770","769.46582","0.04798","76.94658","-0.00011"
"144.50000","4.81450","773.51672","0.04815","77.35167","-0.00011"
"145.00000","4.83100","776.07739","0.04831","77.60774","-0.00011"
"145.50000","4.84780","781.44427","0.04848","78.14442","-0.00010"
"146.00000","4.86445","786.27112","0.04864","78.62711","-0.00010"
"146.50000","4.88112","791.06232","0.04881","79.10623","-0.00009"
"147.00000","4.89784","795.92566","0.04898","79.59257","-0.00009"
"147.50000","4.91430","797.14069","0.04914","79.71407","-0.00009"
"148.00000","4.93111","797.27399","0.04931","79.72740","-0.00008"
"148.50000","4.94773","797.24707","0.04948","79.72471","-0.00008"
"149.00000","4.96439","798.53833","0.04964","79.85384","-0.00008"
"149.50000","4.98106","797.52606","0.04981","79.75261","-0.00008"
"150.00000","4.99788","797.15521","0.04998","79.71552","-0.00009"
"150.50000","5.01444","795.17029","0.05014","79.51703","-0.00009"
"151.00000","5.03112","795.43323","0.05031","79.54332","-0.00009"
"151.50000","5.04777","794.99707","0.05048","79.49971","-0.00009"
"152.00000","5.06441","796.82971","0.05064","79.68297","-0.00009"
"152.50000","5.08116","798.35504","0.05081","79.83550","-0.00010"
"153.00000","5.09764","799.80939","0.05098","79.98094","-0.00010"
"153.50000","5.11436","786.40607","0.05114","78.64061","-0.00011"
"154.00000","5.13101","771.42535","0.05131","77.14253","-0.00010"
"154.50000","5.14784","709.43890","0.05148","70.94389","-0.00010"
"155.00000","5.16439","697.05432","0.05164","69.70543","-0.00010"
"155.50000","5.18120","690.15955","0.05181","69.01595","-0.00010"
"156.00000","5.19770","689.30933","0.05198","68.93093","-0.00010"
"156.50000","5.21438","690.36249","0.05214","69.03625","-0.00009"
"157.00000","5.23118","675.84589","0.05231","67.58459","-0.00009"
"157.50000","5.24780","669.35864","0.05248","66.93587","-0.00009"
"158.00000","5.26443","668.45349","0.05264","66.84535","-0.00009"
"158.50000","5.28099","671.24695","0.05281","67.12469","-0.00009"
"159.00000","5.29777","676.98834","0.05298","67.69884","-0.00009"
"159.50000","5.31441","681.89386","0.05314","68.18938","-0.00009"
"160.00000","5.33121","688.05328","0.05331","68.80533","-0.00009"
"160.50000","5.34769","693.52374","0.05348","69.35237","-0.00009"
"161.00000","5.36452","701.75012","0.05365","70.17501","-0.00009"
"161.50000","5.38109","707.92975","0.05381","70.79298","-0.00009"
"162.00000","5.39769","714.44940","0.05398","71.44494","-0.00009"
"162.50000","5.41459","720.55371","0.05415","72.05537","-0.00010"
"163.00000","5.43105","723.54974","0.05431","72.35497","-0.00010"
"163.50000","5.44771","726.44220","0.05448","72.64422","-0.00010"
"164.00000","5.46434","725.62622","0.05464","72.56262","-0.00011"
"164.50000","5.48112","726.70343","0.05481","72.67034","-0.00011"
"165.00000","5.49777","726.45148","0.05498","72.64515","-0.00011"
"165.50000","5.51452","724.20642","0.05515","72.42064","-0.00011"
"166.00000","5.53097","721.88733","0.05531","72.18874","-0.00011"
"166.50000","5.54774","723.51398","0.05548","72.35139","-0.00010"
"167.00000","5.56447","724.31561","0.05564","72.43156","-0.00010"
"167.50000","5.58107","726.98462","0.05581","72.69846","-0.00009"
"168.00000","5.59786","732.10657","0.05598","73.21066","-0.00009"
"168.50000","5.61429","735.00446","0.05614","73.50044","-0.00009"
"169.00000","5.63107","739.92426","0.05631","73.99242","-0.00009"
"169.50000","5.64769","742.17145","0.05648","74.21715","-0.00008"
"170.00000","5.66453","747.00916","0.05665","74.70091","-0.00008"
"170.50000","5.68106","750.77618","0.05681","75.07762","-0.00008"
"171.00000","5.69775","756.91376","0.05698","75.69138","-0.00008"
"171.50000","5.71437","762.73352","0.05714","76.27335","-0.00009"
"172.00000","5.73116","769.72375","0.05731","76.97237","-0.00009"
"172.50000","5.74779","775.68146","0.05748","77.56815","-0.00009"
"173.00000","5.76441","778.74408","0.05764","77.87440","-0.00009"
"173.50000","5.78117","782.05133","0.05781","78.20513","-0.00010"
"174.00000","5.79771","782.21967","0.05798","78.22197","-0.00010"
"174.50000","5.81444","784.81677","0.05814","78.48167","-0.00011"
"175.00000","5.83099","788.14459","0.05831","78.81446","-0.00011"
"175.50000","5.84787","790.51239","0.05848","79.05124","-0.00011"
"176.00000","5.86440","789.41125","0.05864","78.94112","-0.00011"
"176.50000","5.88110","749.38922","0.05881","74.93892","-0.00012"
"177.00000","5.89777","744.51648","0.05898","74.45164","-0.00011"
"177.50000","5.91437","745.36798","0.05914","74.53680","-0.00011"
"178.00000","5.93120","749.50677","0.05931","74.95068","-0.00010"
"178.50000","5.94771","753.92078","0.05948","75.39207","-0.00010"
"179.00000","5.96446","760.31958","0.05964","76.03196","-0.00009"
"179.50000","5.98101","765.94379","0.05981","76.59438","-0.00009"
"180.00000","5.99775","770.52301","0.05998","77.05230","-0.00009"
"180.50000","6.01435","771.63037","0.06014","77.16304","-0.00008"
"181.00000","6.03122","769.77759","0.06031","76.97776","-0.00008"
"181.50000","6.04766","767.88141","0.06048","76.78814","-0.00008"
"182.00000","6.06446","768.35016","0.06064","76.83501","-0.00008"
"182.50000","6.08117","768.30530","0.06081","76.83053","-0.00008"
"183.00000","6.09776","768.04950","0.06098","76.80495","-0.00008"
"183.50000","6.11457","767.83282","0.06115","76.78328","-0.00008"
"184.00000","6.13099","759.53284","0.06131","75.95329","-0.00009"
"184.50000","6.14776","750.54120","0.06148","75.05412","-0.00009"
"185.00000","6.16435","744.63251","0.06164","74.46325","-0.00010"
"185.50000","6.18105","739.86218","0.06181","73.98622","-0.00010"
"186.00000","6.19775","732.49915","0.06198","73.24992","-0.00010"
"186.50000","6.21455","728.27753","0.06215","72.82775","-0.00011"
"187.00000","6.23099","723.33307","0.06231","72.33331","-0.00011"
"187.50000","6.24776","722.13977","0.06248","72.21397","-0.00011"
"188.00000","6.26453","719.89038","0.06265","71.98904","-0.00011"
"188.50000","6.28111","718.46423","0.06281","71.84642","-0.00011"
"189.00000","6.29782","717.16260","0.06298","71.71626","-0.00011"
"189.50000","6.31421","714.80756","0.06314","71.48076","-0.00010"
"190.00000","6.33101","715.58972","0.06331","71.55898","-0.00010"
"190.50000","6.34772","714.72546","0.06348","71.47255","-0.00010"
"191.00000","6.36450","714.89673","0.06364","71.48967","-0.00009"
"191.50000","6.38108","714.54388","0.06381","71.45439","-0.00009"
"192.00000","6.39777","714.54456","0.06398","71.45445","-0.00009"
"192.50000","6.41439","713.86035","0.06414","71.38603","-0.00009"
"193.00000","6.43108","712.25061","0.06431","71.22506","-0.00009"
"193.50000","6.44788","708.33978","0.06448","70.83398","-0.00009"
"194.00000","6.46435","703.87903","0.06464","70.38790","-0.00009"
"194.50000","6.48105","700.56122","0.06481","70.05612","-0.00009"
"195.00000","6.49769","697.25201","0.06498","69.72520","-0.00009"
"195.50000","6.51454","696.36859","0.06515","69.63686","-0.00010"
"196.00000","6.53104","693.64093","0.06531","69.36409","-0.00010"
"196.50000","6.54787","693.62659","0.06548","69.36266","-0.00010"
"197.00000","6.56436","691.72748","0.06564","69.17274","-0.00010"
"197.50000","6.58114","692.87836","0.06581","69.28783","-0.00010"
"198.00000","6.59783","692.31244","0.06598","69.23125","-0.00010"
"198.50000","6.61436","691.70459","0.06614","69.17046","-0.00010"
"199.00000","6.63123","693.52441","0.06631","69.35244","-0.00010"
"199.50000","6.64768","693.70551","0.06648","69.37055","-0.00010"
"200.00000","6.66437","694.00140","0.06664","69.40014","-0.00010"
"200.50000","6.68102","695.35876","0.06681","69.53587","-0.00010"
"201.00000","6.69778","697.45715","0.06698","69.74571","-0.00009"
"201.50000","6.71439","698.57776","0.06714","69.85777","-0.00009"
"202.00000","6.73114","699.85272","0.06731","69.98528","-0.00009"
"202.50000","6.74775","699.49817","0.06748","69.94981","-0.00009"
"203.00000","6.76442","699.77075","0.06764","69.97707","-0.00009"
"203.50000","6.78113","700.66528","0.06781","70.06653","-0.00009"
"204.00000","6.79771","701.70532","0.06798","70.17053","-0.00009"
"204.50000","6.81449","702.44122","0.06814","70.24413","-0.00009"
"205.00000","6.83098","702.03387","0.06831","70.20338","-0.00010"
"205.50000","6.84773","702.92157","0.06848","70.29216","-0.00010"
"206.00000","6.86437","703.30682","0.06864","70.33068","-0.00010"
"206.50000","6.88118","704.00854","0.06881","70.40086","-0.00010"
"207.00000","6.89774","703.24103","0.06898","70.32410","-0.00011"
"207.50000","6.91447","702.77411","0.06914","70.27741","-0.00011"
"208.00000","6.93108","701.40460","0.06931","70.14046","-0.00011"
"208.50000","6.94773","700.86462","0.06948","70.08646","-0.00011"
"209.00000","6.96448","695.46490","0.06964","69.54649","-0.00011"
"209.50000","6.98110","691.92859","0.06981","69.19286","-0.00011"
"210.00000","6.99787","689.94061","0.06998","68.99406","-0.00011"
"210.50000","7.01427","686.96021","0.07014","68.69602","-0.00010"
"211.00000","7.03103","683.02246","0.07031","68.30225","-0.00009"
"211.50000","7.04770","674.32288","0.07048","67.43229","-0.00009"
"212.00000","7.06460","670.18610","0.07065","67.01861","-0.00008"
"212.50000","7.08108","663.39282","0.07081","66.33928","-0.00008"
"213.00000","7.09774","663.44482","0.07098","66.34448","-0.00008"
"213.50000","7.11444","664.39880","0.07114","66.43988","-0.00007"
"214.00000","7.13107","665.67163","0.07131","66.56716","-0.00007"
"214.50000","7.14789","668.15509","0.07148","66.81551","-0.00008"
"215.00000","7.16438","668.42224","0.07164","66.84222","-0.00008"
"215.50000","7.18104","668.86792","0.07181","66.88680","-0.00008"
"216.00000","7.19771","666.80408","0.07198","66.68040","-0.00009"
"216.50000","7.21447","650.51556","0.07214","65.05156","-0.00009"
"217.00000","7.23111","635.64355","0.07231","63.56435","-0.00010"
"217.50000","7.24781","620.18134","0.07248","62.01814","-0.00010"
"218.00000","7.26432","601.74054","0.07264","60.17405","-0.00011"
"218.50000","7.28113","585.35327","0.07281","58.53533","-0.00011"
"219.00000","7.29795","571.61511","0.07298","57.16151","-0.00012"
"219.50000","7.31436","559.99390","0.07314","55.99939","-0.00012"
"220.00000","7.33118","551.44269","0.07331","55.14427","-0.00012"
"220.50000","7.34765","545.88464","0.07348","54.58846","-0.00012"
"221.00000","7.36442","543.88953","0.07364","54.38895","-0.00012"
"221.50000","7.38105","543.47620","0.07381","54.34762","-0.00011"
"222.00000","7.39779","544.28107","0.07398","54.42811","-0.00011"
"222.50000","7.41445","542.90588","0.07414","54.29059","-0.00010"
"223.00000","7.43114","542.17505","0.07431","54.21751","-0.00009"
"223.50000","7.44768","540.43658","0.07448","54.04366","-0.00009"
"224.00000","7.46442","540.32318","0.07464","54.03232","-0.00009"
"224.50000","7.48117","539.12238","0.07481","53.91224","-0.00008"
"225.00000","7.49771","538.21057","0.07498","53.82106","-0.00008"
"225.50000","7.51441","537.48444","0.07514","53.74844","-0.00008"
"226.00000","7.53103","536.64758","0.07531","53.66476","-0.00008"
"226.50000","7.54772","536.50488","0.07548","53.65049","-0.00008"
"227.00000","7.56436","534.57434","0.07564","53.45744","-0.00008"
"227.50000","7.58114","534.83020","0.07581","53.48302","-0.00009"
"228.00000","7.59776","533.25696","0.07598","53.32570","-0.00009"
"228.50000","7.61441","531.69604","0.07614","53.16961","-0.00009"
"229.00000","7.63108","529.35358","0.07631","52.93536","-0.00010"
"229.50000","7.64776","525.96045","0.07648","52.59605","-0.00009"
"230.00000","7.66449","523.25745","0.07664","52.32574","-0.00010"
"230.50000","7.68108","517.67310","0.07681","51.76731","-0.00010"
"231.00000","7.69776","509.96429","0.07698","50.99643","-0.00011"
"231.50000","7.71439","498.06018","0.07714","49.80602","-0.00011"
"232.00000","7.73111","481.51562","0.07731","48.15156","-0.00011"
"232.50000","7.74768","470.70016","0.07748","47.07001","-0.00010"
"233.00000","7.76457","464.66580","0.07765","46.46658","-0.00010"
"233.50000","7.78114","453.89151","0.07781","45.38915","-0.00010"
"234.00000","7.79772","439.91254","0.07798","43.99125","-0.00010"
"234.50000","7.81446","432.26541","0.07814","43.22654","-0.00009"
"235.00000","7.83109","429.44830","0.07831","42.94483","-0.00009"
"235.50000","7.84794","429.20505","0.07848","42.92051","-0.00009"
"236.00000","7.86437","427.30734","0.07864","42.73074","-0.00009"
"236.50000","7.88101","425.87320","0.07881","42.58732","-0.00009"
"237.00000","7.89770","425.14685","0.07898","42.51469","-0.00009"
"237.50000","7.91448","423.90753","0.07914","42.39075","-0.00009"
"238.00000","7.93104","421.26691","0.07931","42.12669","-0.00010"
"238.50000","7.94780","419.93979","0.07948","41.99398","-0.00010"
"239.00000","7.96432","416.26404","0.07964","41.62640","-0.00010"
"239.50000","7.98110","414.49530","0.07981","41.44953","-0.00010"
"240.00000","7.99787","410.81595","0.07998","41.08160","-0.00010"
"240.50000","8.01443","406.64127","0.08014","40.66413","-0.00010"
"241.00000","8.03111","403.07938","0.08031","40.30794","-0.00010"
"241.50000","8.04761","399.16672","0.08048","39.91667","-0.00010"
"242.00000","8.06439","397.52783","0.08064","39.75278","-0.00010"
"242.50000","8.08113","393.48337","0.08081","39.34834","-0.00010"
"243.00000","8.09780","389.46936","0.08098","38.94694","-0.00010"
"243.50000","8.11435","385.36392","0.08114","38.53639","-0.00010"
"244.00000","8.13116","380.89151","0.08131","38.08915","-0.00009"
"244.50000","8.14779","374.22568","0.08148","37.42257","-0.00009"
"245.00000","8.16446","369.36646","0.08164","36.93665","-0.00009"
"245.50000","8.18116","365.05780","0.08181","36.50578","-0.00008"
"246.00000","8.19771","360.54898","0.08198","36.05490","-0.00008"
"246.50000","8.21444","359.47153","0.08214","35.94715","-0.00008"
"247.00000","8.23095","356.06580","0.08231","35.60658","-0.00008"
"247.50000","8.24778","355.59427","0.08248","35.55943","-0.00008"
"248.00000","8.26440","353.32944","0.08264","35.33294","-0.00009"
"248.50000","8.28116","352.35880","0.08281","35.23588","-0.00009"
"249.00000","8.29771","348.04807","0.08298","34.80481","-0.00010"
"249.50000","8.31447","346.69391","0.08314","34.66939","-0.00010"
"250.00000","8.33113","343.02890","0.08331","34.30289","-0.00010"
"250.50000","8.34775","341.16324","0.08348","34.11633","-0.00011"
"251.00000","8.36450","338.87747","0.08364","33.88775","-0.00011"
"251.50000","8.38107","331.50494","0.08381","33.15049","-0.00011"
"252.00000","8.39773","329.57779","0.08398","32.95778","-0.00011"
"252.50000","8.41435","327.69226","0.08414","32.76923","-0.00011"
"253.00000","8.43113","327.17093","0.08431","32.71709","-0.00011"
"253.50000","8.44771","323.93463","0.08448","32.39346","-0.00011"
"254.00000","8.46451","322.05963","0.08465","32.20596","-0.00010"
"254.50000","8.48104","319.06583","0.08481","31.90658","-0.00010"
"255.00000","8.49779","318.45795","0.08498","31.84579","-0.00009"
"255.50000","8.51452","316.39236","0.08515","31.63924","-0.00008"
"256.00000","8.53103","315.56281","0.08531","31.55628","-0.00008"
"256.50000","8.54786","316.32452","0.08548","31.63245","-0.00008"
"257.00000","8.56439","316.19647","0.08564","31.61965","-0.00007"
"257.50000","8.58102","316.68533","0.08581","31.66853","-0.00007"
"258.00000","8.59771","316.05081","0.08598","31.60508","-0.00007"
"258.50000","8.61452","314.54089","0.08615","31.45409","-0.00007"
"259.00000","8.63110","311.24753","0.08631","31.12475","-0.00008"
"259.50000","8.64781","309.02399","0.08648","30.90240","-0.00008"
"260.00000","8.66435","305.53848","0.08664","30.55385","-0.00008"
"260.50000","8.68106","299.61212","0.08681","29.96121","-0.00009"
"261.00000","8.69786","297.76468","0.08698","29.77647","-0.00010"
"261.50000","8.71438","297.14490","0.08714","29.71449","-0.00010"
"262.00000","8.73109","297.76648","0.08731","29.77665","-0.00010"
"262.50000","8.74760","296.94757","0.08748","29.69476","-0.00011"
"263.00000","8.76440","298.00336","0.08764","29.80033","-0.00011"
"263.50000","8.78106","297.08139","0.08781","29.70814","-0.00011"
"264.00000","8.79788","297.23077","0.08798","29.72308","-0.00011"
"264.50000","8.81435","294.72638","0.08814","29.47264","-0.00011"
"265.00000","8.83107","292.47116","0.08831","29.24712","-0.00011"
"265.50000","8.84779","275.70370","0.08848","27.57037","-0.00011"
"266.00000","8.86447","268.76895","0.08864","26.87690","-0.00011"
"266.50000","8.88115","264.23428","0.08881","26.42343","-0.00010"
"267.00000","8.89771","261.91153","0.08898","26.19115","-0.00009"
"267.50000","8.91444","261.41107","0.08914","26.14111","-0.00009"
"268.00000","8.93103","261.73935","0.08931","26.17393","-0.00009"
"268.50000","8.94785","262.78967","0.08948","26.27897","-0.00008"
"269.00000","8.96437","261.85214","0.08964","26.18521","-0.00008"
"269.50000","8.98122","262.40173","0.08981","26.24017","-0.00008"
"270.00000","8.99771","260.28207","0.08998","26.02821","-0.00008"
"270.50000","9.01437","258.92178","0.09014","25.89218","-0.00008"
"271.00000","9.03123","256.72281","0.09031","25.67228","-0.00009"
"271.50000","9.04772","256.01453","0.09048","25.60145","-0.00009"
"272.00000","9.06449","256.11578","0.09064","25.61158","-0.00009"
"272.50000","9.08099","255.45544","0.09081","25.54554","-0.00009"
"273.00000","9.09776","255.53888","0.09098","25.55389","-0.00010"
"273.50000","9.11440","254.62572","0.09114","25.46257","-0.00010"
"274.00000","9.13111","254.45248","0.09131","25.44525","-0.00010"
"274.50000","9.14769","252.95622","0.09148","25.29562","-0.00010"
"275.00000","9.16449","252.45268","0.09164","25.24527","-0.00010"
"275.50000","9.18106","250.10605","0.09181","25.01060","-0.00011"
"276.00000","9.19776","248.65598","0.09198","24.86560","-0.00010"
"276.50000","9.21457","247.95390","0.09215","24.79539","-0.00010"
"277.00000","9.23101","246.60016","0.09231","24.66002","-0.00010"
"277.50000","9.24778","247.53867","0.09248","24.75387","-0.00009"
"278.00000","9.26430","245.50769","0.09264","24.55077","-0.00010"
"278.50000","9.28112","244.48952","0.09281","24.44895","-0.00009"
"279.00000","9.29774","242.21631","0.09298","24.22163","-0.00009"
"279.50000","9.31445","242.37787","0.09314","24.23779","-0.00009"
"280.00000","9.33107","243.43675","0.09331","24.34368","-0.00008"
"280.50000","9.34786","243.84212","0.09348","24.38421","-0.00009"
"281.00000","9.36437","243.45557","0.09364","24.34556","-0.00009"
"281.50000","9.38107","244.00861","0.09381","24.40086","-0.00009"
"282.00000","9.39786","241.32109","0.09398","24.13211","-0.00010"
"282.50000","9.41440","236.77037","0.09414","23.67704","-0.00010"
"283.00000","9.43109","226.74263","0.09431","22.67426","-0.00010"
"283.50000","9.44760","220.08629","0.09448","22.00863","-0.00010"
"284.00000","9.46443","196.04543","0.09464","19.60454","-0.00010"
"284.50000","9.48109","187.88977","0.09481","18.78898","-0.00011"
"285.00000","9.49781","119.64714","0.09498","11.96471","-0.00011"
"285.50000","9.51439","95.30539","0.09514","9.53054","-0.00010"
"286.00000","9.53104","84.71181","0.09531","8.47118","-0.00010"
"286.50000","9.54785","43.95135","0.09548","4.39513","-0.00010"
"287.00000","9.56441","37.13604","0.09564","3.71360","-0.00010"
"287.50000","9.58120","37.72275","0.09581","3.77227","-0.00009"
"288.00000","9.59765","38.55084","0.09598","3.85508","-0.00009"
"288.50000","9.61438","38.85146","0.09614","3.88515","-0.00009"
"289.00000","9.63100","41.14403","0.09631","4.11440","-0.00008"
"289.50000","9.64793","43.47459","0.09648","4.34746","-0.00008"
"290.00000","9.66434","43.57599","0.09664","4.35760","-0.00008"
"290.50000","9.68115","44.26425","0.09681","4.42642","-0.00008"
"291.00000","9.69773","45.54385","0.09698","4.55438","-0.00008"
"291.50000","9.71446","45.93477","0.09714","4.59348","-0.00008"
"292.00000","9.73123","41.10094","0.09731","4.11009","-0.00008"
"292.50000","9.74772","38.93828","0.09748","3.89383","-0.00008"
"293.00000","9.76450","38.78130","0.09765","3.87813","-0.00009"
"293.50000","9.78100","37.09529","0.09781","3.70953","-0.00010"
"294.00000","9.79768","37.03679","0.09798","3.70368","-0.00010"
"294.50000","9.81440","32.80960","0.09814","3.28096","-0.00010"
"295.00000","9.83120","33.68560","0.09831","3.36856","-0.00011"
"295.50000","9.84767","33.97491","0.09848","3.39749","-0.00011"
"296.00000","9.86443","15.71079","0.09864","1.57108","-0.00012"
"296.50000","9.88113","17.30560","0.09881","1.73056","-0.00011"
"297.00000","9.89778","20.55417","0.09898","2.05542","-0.00011"
"297.50000","9.91451","22.88075","0.09915","2.28808","-0.00011"
"298.00000","9.93095","24.79770","0.09931","2.47977","-0.00011"
"298.50000","9.94769","28.28614","0.09948","2.82861","-0.00009"
"299.00000","9.96434","31.84599","0.09964","3.18460","-0.00010"
"299.50000","9.98112","35.36066","0.09981","3.53607","-0.00010"
"300.00000","9.99775","37.28774","0.09998","3.72877","-0.00009"
"300.50000","10.01453","38.87508","0.10015","3.88751","-0.00008"
"301.00000","10.03105","37.55371","0.10031","3.75537","-0.00008"
"301.50000","10.04778","36.37339","0.10048","3.63734","-0.00005"
"302.00000","10.06450","35.20417","0.10064","3.52042","-0.00006"
"302.50000","10.08103","33.25661","0.10081","3.32566","-0.00008"
"303.00000","10.09777","32.08201","0.10098","3.20820","-0.00008"
"303.50000","10.11438","27.38720","0.10114","2.73872","-0.00007"
"304.00000","10.13118","24.35421","0.10131","2.43542","-0.00009"
"304.50000","10.14766","20.55740","0.10148","2.05574","-0.00009"
"305.00000","10.16448","18.54498","0.10164","1.85450","-0.00009"
"305.50000","10.18105","16.39734","0.10181","1.63973","-0.00010"
"306.00000","10.19791","15.63790","0.10198","1.56379","-0.00010"
"306.50000","10.21443","13.85038","0.10214","1.38504","-0.00011"
"307.00000","10.23102","12.83040","0.10231","1.28304","-0.00011"
"307.50000","10.24786","10.70492","0.10248","1.07049","-0.00011"
"308.00000","10.26438","8.15464","0.10264","0.81546","-0.00011"
"308.50000","10.28115","6.42037","0.10281","0.64204","-0.00013"
"309.00000","10.29768","4.02800","0.10298","0.40280","-0.00013"
"309.50000","10.31435","0.58320","0.10314","0.05832","-0.00004"
"310.00000","10.33108","-3.76540","0.10331","-0.37654","-0.00001"
"310.50000","10.34783","-9.26723","0.10348","-0.92672","-0.00009"
"311.00000","10.36443","-14.09483","0.10364","-1.40948","-0.00011"
"311.25800","10.37317","-15.28300","0.10373","-1.52830","-0.00014"