File: Tension/Section_2_Group_2/hybrid_high_Sample_1_redonewiththepowerofAnton.is_tens_RawData/Specimen_RawData_1.csv
Time,Extension,Load,Tensile strain (Extension),Tensile stress,Strain-by-clip-gage
(s),(mm),(N),(mm/mm),(MPa),(mm/mm)
"0.00000","0.00000","1180.34802","0.00000","118.03481","-0.00026"
"0.50000","0.01406","1295.55896","0.00014","129.55589","-0.00024"
"1.00000","0.03087","1422.80444","0.00031","142.28044","-0.00026"
"1.50000","0.04745","1540.10950","0.00047","154.01096","-0.00029"
"2.00000","0.06411","1652.23389","0.00064","165.22339","-0.00032"
"2.50000","0.08057","1758.54578","0.00081","175.85458","-0.00028"
"3.00000","0.09741","1864.33740","0.00097","186.43375","-0.00027"
"3.50000","0.11408","1964.85632","0.00114","196.48563","-0.00029"
"4.00000","0.13085","2063.40649","0.00131","206.34065","-0.00027"
"4.50000","0.14741","2156.11548","0.00147","215.61154","-0.00028"
"5.00000","0.16406","2247.79419","0.00164","224.77942","-0.00028"
"5.50000","0.18080","2339.35669","0.00181","233.93567","-0.00027"
"6.00000","0.19742","2428.54590","0.00197","242.85458","-0.00027"
"6.50000","0.21425","2518.53027","0.00214","251.85303","-0.00028"
"7.00000","0.23071","2604.92310","0.00231","260.49231","-0.00028"
"7.50000","0.24735","2692.77246","0.00247","269.27725","-0.00023"
"8.00000","0.26399","2780.95410","0.00264","278.09540","-0.00025"
"8.50000","0.28093","2870.58130","0.00281","287.05814","-0.00028"
"9.00000","0.29736","2955.57397","0.00297","295.55740","-0.00027"
"9.50000","0.31420","3043.72583","0.00314","304.37259","-0.00027"
"10.00000","0.33070","3127.43457","0.00331","312.74347","-0.00028"
"10.50000","0.34748","3213.80493","0.00347","321.38049","-0.00030"
"11.00000","0.36428","3299.88525","0.00364","329.98853","-0.00031"
"11.50000","0.38070","3382.26489","0.00381","338.22650","-0.00029"
"12.00000","0.39758","3468.84009","0.00398","346.88400","-0.00026"
"12.50000","0.41401","3550.02881","0.00414","355.00287","-0.00027"
"13.00000","0.43068","3634.30933","0.00431","363.43094","-0.00027"
"13.50000","0.44741","3718.74316","0.00447","371.87433","-0.00028"
"14.00000","0.46416","3802.08057","0.00464","380.20807","-0.00028"
"14.50000","0.48072","3884.34497","0.00481","388.43451","-0.00027"
"15.00000","0.49749","3967.09961","0.00497","396.70996","-0.00028"
"15.50000","0.51408","4047.97876","0.00514","404.79788","-0.00028"
"16.00000","0.53079","4130.54541","0.00531","413.05453","-0.00028"
"16.50000","0.54755","4212.74512","0.00548","421.27451","-0.00028"
"17.00000","0.56400","4291.81592","0.00564","429.18158","-0.00029"
"17.50000","0.58080","4374.02930","0.00581","437.40292","-0.00027"
"18.00000","0.59729","4452.34082","0.00597","445.23407","-0.00026"
"18.50000","0.61413","4533.57715","0.00614","453.35773","-0.00027"
"19.00000","0.63078","4612.21436","0.00631","461.22144","-0.00027"
"19.50000","0.64752","4690.84570","0.00648","469.08456","-0.00028"
"20.00000","0.66408","4767.76758","0.00664","476.77676","-0.00028"
"20.50000","0.68084","4845.71533","0.00681","484.57153","-0.00029"
"21.00000","0.69747","4921.72217","0.00697","492.17221","-0.00028"
"21.50000","0.71408","4996.80127","0.00714","499.68011","-0.00028"
"22.00000","0.73082","5072.52295","0.00731","507.25229","-0.00028"
"22.50000","0.74739","5145.95117","0.00747","514.59509","-0.00027"
"23.00000","0.76421","5221.25928","0.00764","522.12592","-0.00028"
"23.50000","0.78062","5291.49561","0.00781","529.14954","-0.00028"
"24.00000","0.79744","5364.81982","0.00797","536.48199","-0.00028"
"24.50000","0.81406","5435.11768","0.00814","543.51178","-0.00027"
"25.00000","0.83096","5508.18115","0.00831","550.81812","-0.00028"
"25.50000","0.84747","5576.34180","0.00847","557.63416","-0.00028"
"26.00000","0.86407","5644.66992","0.00864","564.46698","-0.00027"
"26.50000","0.88080","5713.27490","0.00881","571.32751","-0.00026"
"27.00000","0.89742","5780.68359","0.00897","578.06836","-0.00026"
"27.50000","0.91417","5847.93750","0.00914","584.79376","-0.00027"
"28.00000","0.93070","5912.18652","0.00931","591.21863","-0.00028"
"28.50000","0.94739","5976.90186","0.00947","597.69019","-0.00028"
"29.00000","0.96402","6040.97412","0.00964","604.09741","-0.00028"
"29.50000","0.98087","6106.33398","0.00981","610.63342","-0.00029"
"30.00000","0.99745","6168.28320","0.00997","616.82831","-0.00029"
"30.50000","1.01416","6230.46777","0.01014","623.04675","-0.00028"
"31.00000","1.03066","6289.45312","0.01031","628.94531","-0.00029"
"31.50000","1.04747","6351.51025","0.01047","635.15100","-0.00028"
"32.00000","1.06432","6412.80713","0.01064","641.28070","-0.00029"
"32.50000","1.08070","6468.90088","0.01081","646.89008","-0.00029"
"33.00000","1.09751","6528.11377","0.01098","652.81140","-0.00028"
"33.50000","1.11397","6583.19824","0.01114","658.31982","-0.00028"
"34.00000","1.13082","6641.11133","0.01131","664.11115","-0.00027"
"34.50000","1.14741","6695.94727","0.01147","669.59473","-0.00027"
"35.00000","1.16420","6752.11719","0.01164","675.21173","-0.00027"
"35.50000","1.18075","6804.54980","0.01181","680.45496","-0.00027"
"36.00000","1.19747","6858.78223","0.01197","685.87823","-0.00026"
"36.50000","1.21408","6910.26660","0.01214","691.02667","-0.00027"
"37.00000","1.23081","6962.59229","0.01231","696.25922","-0.00027"
"37.50000","1.24756","7014.19189","0.01248","701.41919","-0.00027"
"38.00000","1.26404","7062.72949","0.01264","706.27295","-0.00028"
"38.50000","1.28070","7111.86230","0.01281","711.18622","-0.00027"
"39.00000","1.29736","7160.61230","0.01297","716.06122","-0.00028"
"39.50000","1.31412","7208.75488","0.01314","720.87549","-0.00028"
"40.00000","1.33071","7255.19141","0.01331","725.51917","-0.00028"
"40.50000","1.34752","7302.25732","0.01348","730.22571","-0.00028"
"41.00000","1.36404","7346.25000","0.01364","734.62500","-0.00028"
"41.50000","1.38077","7392.38428","0.01381","739.23840","-0.00029"
"42.00000","1.39749","7437.13086","0.01397","743.71307","-0.00028"
"42.50000","1.41412","7480.97314","0.01414","748.09729","-0.00028"
"43.00000","1.43085","7524.11768","0.01431","752.41174","-0.00028"
"43.50000","1.44738","7564.44482","0.01447","756.44446","-0.00028"
"44.00000","1.46409","7606.34619","0.01464","760.63464","-0.00028"
"44.50000","1.48075","7646.12256","0.01481","764.61224","-0.00027"
"45.00000","1.49749","7686.05176","0.01497","768.60516","-0.00027"
"45.50000","1.51404","7723.96680","0.01514","772.39667","-0.00027"
"46.00000","1.53097","7764.86084","0.01531","776.48608","-0.00027"
"46.50000","1.54751","7800.84375","0.01548","780.08435","-0.00028"
"47.00000","1.56409","7836.72119","0.01564","783.67212","-0.00028"
"47.50000","1.58082","7872.69678","0.01581","787.26965","-0.00028"
"48.00000","1.59739","7903.08057","0.01597","790.30804","-0.00027"
"48.50000","1.61428","7937.45654","0.01614","793.74567","-0.00028"
"49.00000","1.63071","7968.48682","0.01631","796.84869","-0.00028"
"49.50000","1.64739","8001.55762","0.01647","800.15576","-0.00028"
"50.00000","1.66404","8033.66992","0.01664","803.36700","-0.00028"
"50.50000","1.68085","8067.01709","0.01681","806.70172","-0.00028"
"51.00000","1.69736","8095.64209","0.01697","809.56421","-0.00028"
"51.50000","1.71418","8126.86816","0.01714","812.68683","-0.00028"
"52.00000","1.73069","8153.35742","0.01731","815.33575","-0.00028"
"52.50000","1.74745","8181.82324","0.01747","818.18231","-0.00028"
"53.00000","1.76423","8209.49219","0.01764","820.94922","-0.00028"
"53.50000","1.78077","8233.33301","0.01781","823.33331","-0.00028"
"54.00000","1.79740","8257.05566","0.01797","825.70557","-0.00027"
"54.50000","1.81393","8279.93555","0.01814","827.99353","-0.00024"
"55.00000","1.83082","8305.30566","0.01831","830.53058","-0.00024"
"55.50000","1.84749","8328.02539","0.01847","832.80255","-0.00026"
"56.00000","1.86416","8350.20508","0.01864","835.02051","-0.00028"
"56.50000","1.88073","8371.03320","0.01881","837.10333","-0.00030"
"57.00000","1.89753","8394.30957","0.01898","839.43097","-0.00032"
"57.50000","1.91415","8415.57422","0.01914","841.55743","-0.00032"
"58.00000","1.93082","8437.16309","0.01931","843.71631","-0.00029"
"58.50000","1.94749","8457.53418","0.01947","845.75342","-0.00026"
"59.00000","1.96407","8476.50098","0.01964","847.65009","-0.00028"
"59.50000","1.98077","8495.85645","0.01981","849.58563","-0.00028"
"60.00000","1.99729","8514.33789","0.01997","851.43378","-0.00027"
"60.50000","2.01423","8535.80273","0.02014","853.58026","-0.00027"
"61.00000","2.03078","8552.37598","0.02031","855.23761","-0.00028"
"61.50000","2.04757","8570.23828","0.02048","857.02380","-0.00028"
"62.00000","2.06395","8583.12793","0.02064","858.31281","-0.00028"
"62.50000","2.08075","8599.96289","0.02081","859.99628","-0.00027"
"63.00000","2.09752","8614.05176","0.02098","861.40515","-0.00029"
"63.50000","2.11410","8625.58496","0.02114","862.55847","-0.00027"
"64.00000","2.13080","8637.06934","0.02131","863.70691","-0.00026"
"64.50000","2.14733","8645.43262","0.02147","864.54327","-0.00027"
"65.00000","2.16406","8653.24805","0.02164","865.32483","-0.00027"
"65.50000","2.18068","8659.34961","0.02181","865.93494","-0.00027"
"66.00000","2.19759","8665.80957","0.02198","866.58093","-0.00027"
"66.50000","2.21395","8665.35352","0.02214","866.53534","-0.00028"
"67.00000","2.23094","8671.82617","0.02231","867.18262","-0.00028"
"67.50000","2.24748","8672.36719","0.02247","867.23669","-0.00028"
"68.00000","2.26417","8676.94043","0.02264","867.69403","-0.00028"
"68.50000","2.28086","8680.93848","0.02281","868.09387","-0.00028"
"69.00000","2.29730","8683.09473","0.02297","868.30945","-0.00028"
"69.50000","2.31421","8689.46094","0.02314","868.94611","-0.00028"
"70.00000","2.33074","8691.57422","0.02331","869.15741","-0.00029"
"70.50000","2.34739","8696.50391","0.02347","869.65039","-0.00028"
"71.00000","2.36402","8701.14648","0.02364","870.11462","-0.00028"
"71.50000","2.38097","8708.14355","0.02381","870.81433","-0.00028"
"72.00000","2.39742","8712.32324","0.02397","871.23230","-0.00028"
"72.50000","2.41422","8718.04688","0.02414","871.80469","-0.00027"
"73.00000","2.43067","8722.54980","0.02431","872.25500","-0.00027"
"73.50000","2.44746","8729.69434","0.02447","872.96942","-0.00027"
"74.00000","2.46423","8733.73633","0.02464","873.37366","-0.00027"
"74.50000","2.48067","8733.04785","0.02481","873.30481","-0.00027"
"75.00000","2.49740","8732.07617","0.02497","873.20764","-0.00027"
"75.50000","2.51392","8725.25391","0.02514","872.52539","-0.00028"
"76.00000","2.53078","8721.81250","0.02531","872.18127","-0.00027"
"76.50000","2.54736","8713.21484","0.02547","871.32147","-0.00027"
"77.00000","2.56428","8707.96680","0.02564","870.79669","-0.00028"
"77.50000","2.58067","8695.98633","0.02581","869.59863","-0.00027"
"78.00000","2.59741","8690.51562","0.02597","869.05157","-0.00027"
"78.50000","2.61415","8687.49902","0.02614","868.74988","-0.00028"
"79.00000","2.63083","8684.80664","0.02631","868.48065","-0.00028"
"79.50000","2.64748","8681.19727","0.02647","868.11975","-0.00028"
"80.00000","2.66398","8676.01660","0.02664","867.60168","-0.00028"
"80.50000","2.68082","8673.93945","0.02681","867.39392","-0.00028"
"81.00000","2.69738","8670.83301","0.02697","867.08331","-0.00028"
"81.50000","2.71427","8674.13184","0.02714","867.41321","-0.00027"
"82.00000","2.73069","8672.42871","0.02731","867.24286","-0.00027"
"82.50000","2.74767","8676.82812","0.02748","867.68280","-0.00027"
"83.00000","2.76413","8675.33789","0.02764","867.53381","-0.00028"
"83.50000","2.78073","8675.09277","0.02781","867.50928","-0.00027"
"84.00000","2.79760","8676.95996","0.02798","867.69598","-0.00027"
"84.50000","2.81408","8671.57324","0.02814","867.15735","-0.00028"
"85.00000","2.83074","8663.54688","0.02831","866.35468","-0.00028"
"85.50000","2.84728","8651.04688","0.02847","865.10468","-0.00027"
"86.00000","2.86415","8637.73340","0.02864","863.77332","-0.00027"
"86.50000","2.88074","8622.95508","0.02881","862.29553","-0.00027"
"87.00000","2.89757","8613.17480","0.02898","861.31750","-0.00027"
"87.50000","2.91395","8599.78809","0.02914","859.97882","-0.00028"
"88.00000","2.93078","8593.50000","0.02931","859.34998","-0.00028"
"88.50000","2.94741","8587.54590","0.02947","858.75458","-0.00028"
"89.00000","2.96409","8587.27832","0.02964","858.72784","-0.00028"
"89.50000","2.98093","8589.28418","0.02981","858.92841","-0.00028"
"90.00000","2.99734","8588.91895","0.02997","858.89191","-0.00027"
"90.50000","3.01410","8592.66895","0.03014","859.26691","-0.00027"
"91.00000","3.03068","8594.77246","0.03031","859.47723","-0.00028"
"91.50000","3.04757","8600.59180","0.03048","860.05920","-0.00028"
"92.00000","3.06406","8599.93164","0.03064","859.99316","-0.00028"
"92.50000","3.08081","8598.04883","0.03081","859.80487","-0.00027"
"93.00000","3.09735","8589.18457","0.03097","858.91846","-0.00027"
"93.50000","3.11422","8581.24023","0.03114","858.12402","-0.00028"
"94.00000","3.13081","8569.49512","0.03131","856.94952","-0.00027"
"94.50000","3.14744","8558.11035","0.03147","855.81104","-0.00028"
"95.00000","3.16425","8546.98438","0.03164","854.69843","-0.00027"
"95.50000","3.18077","8532.91211","0.03181","853.29120","-0.00028"
"96.00000","3.19744","8523.96680","0.03197","852.39667","-0.00028"
"96.50000","3.21391","8513.71777","0.03214","851.37177","-0.00028"
"97.00000","3.23084","8510.06152","0.03231","851.00616","-0.00028"
"97.50000","3.24745","8502.33398","0.03247","850.23340","-0.00028"
"98.00000","3.26420","8493.17773","0.03264","849.31775","-0.00028"
"98.50000","3.28074","8480.20020","0.03281","848.02002","-0.00028"
"99.00000","3.29741","8468.63281","0.03297","846.86328","-0.00028"
"99.50000","3.31421","8459.98145","0.03314","845.99817","-0.00028"
"100.00000","3.33073","8449.99219","0.03331","844.99921","-0.00027"
"100.50000","3.34753","8442.96094","0.03348","844.29608","-0.00027"
"101.00000","3.36402","8432.45215","0.03364","843.24524","-0.00028"
"101.50000","3.38072","8425.73535","0.03381","842.57355","-0.00028"
"102.00000","3.39737","8421.47070","0.03397","842.14709","-0.00026"
"102.50000","3.41427","8418.34180","0.03414","841.83417","-0.00026"
"103.00000","3.43069","8407.68262","0.03431","840.76825","-0.00027"
"103.50000","3.44755","8402.62500","0.03448","840.26251","-0.00027"
"104.00000","3.46415","8394.54980","0.03464","839.45496","-0.00028"
"104.50000","3.48080","8387.73145","0.03481","838.77313","-0.00027"
"105.00000","3.49762","8381.80664","0.03498","838.18066","-0.00028"
"105.50000","3.51406","8373.51270","0.03514","837.35126","-0.00028"
"106.00000","3.53088","8368.32227","0.03531","836.83221","-0.00028"
"106.50000","3.54733","8359.62402","0.03547","835.96240","-0.00029"
"107.00000","3.56406","8354.48535","0.03564","835.44855","-0.00031"
"107.50000","3.58075","8348.60938","0.03581","834.86096","-0.00026"
"108.00000","3.59759","8342.26953","0.03598","834.22693","-0.00029"
"108.50000","3.61403","8329.23730","0.03614","832.92371","-0.00030"
"109.00000","3.63079","8320.38477","0.03631","832.03845","-0.00028"
"109.50000","3.64748","8313.10840","0.03647","831.31085","-0.00028"
"110.00000","3.66416","8305.13965","0.03664","830.51398","-0.00027"
"110.50000","3.68086","8295.44824","0.03681","829.54480","-0.00028"
"111.00000","3.69723","8282.66504","0.03697","828.26648","-0.00027"
"111.50000","3.71403","8275.62500","0.03714","827.56250","-0.00027"
"112.00000","3.73066","8271.84863","0.03731","827.18488","-0.00027"
"112.50000","3.74755","8273.72168","0.03748","827.37219","-0.00027"
"113.00000","3.76410","8270.04688","0.03764","827.00470","-0.00027"
"113.50000","3.78083","8266.53418","0.03781","826.65344","-0.00027"
"114.00000","3.79736","8259.47852","0.03797","825.94788","-0.00027"
"114.50000","3.81414","8254.74609","0.03814","825.47461","-0.00028"
"115.00000","3.83089","8247.62793","0.03831","824.76282","-0.00027"
"115.50000","3.84744","8234.57520","0.03847","823.45752","-0.00028"
"116.00000","3.86409","8222.14453","0.03864","822.21448","-0.00028"
"116.50000","3.88070","8211.02441","0.03881","821.10242","-0.00028"
"117.00000","3.89757","8203.13281","0.03898","820.31329","-0.00028"
"117.50000","3.91399","8195.15234","0.03914","819.51526","-0.00028"
"118.00000","3.93088","8195.08789","0.03931","819.50879","-0.00028"
"118.50000","3.94738","8191.34131","0.03947","819.13416","-0.00028"
"119.00000","3.96425","8195.02148","0.03964","819.50214","-0.00028"
"119.50000","3.98086","8196.95020","0.03981","819.69501","-0.00028"
"120.00000","3.99739","8199.12500","0.03997","819.91248","-0.00028"
"120.50000","4.01424","8202.09277","0.04014","820.20929","-0.00027"
"121.00000","4.03071","8198.50000","0.04031","819.84998","-0.00027"
"121.50000","4.04740","8196.51367","0.04047","819.65137","-0.00027"
"122.00000","4.06401","8191.52197","0.04064","819.15222","-0.00027"
"122.50000","4.08074","8189.96973","0.04081","818.99695","-0.00027"
"123.00000","4.09742","8184.69238","0.04097","818.46924","-0.00027"
"123.50000","4.11424","8179.68848","0.04114","817.96887","-0.00028"
"124.00000","4.13070","8172.47314","0.04131","817.24731","-0.00028"
"124.50000","4.14745","8171.15967","0.04147","817.11597","-0.00027"
"125.00000","4.16407","8168.37842","0.04164","816.83783","-0.00027"
"125.50000","4.18073","8166.23047","0.04181","816.62305","-0.00028"
"126.00000","4.19760","8167.89697","0.04198","816.78967","-0.00027"
"126.50000","4.21400","8164.49512","0.04214","816.44952","-0.00028"
"127.00000","4.23085","8167.68115","0.04231","816.76813","-0.00027"
"127.50000","4.24736","8167.05225","0.04247","816.70520","-0.00027"
"128.00000","4.26420","8172.67090","0.04264","817.26709","-0.00027"
"128.50000","4.28079","8176.22266","0.04281","817.62225","-0.00028"
"129.00000","4.29756","8178.90820","0.04298","817.89081","-0.00028"
"129.50000","4.31407","8177.39648","0.04314","817.73962","-0.00027"
"130.00000","4.33075","8177.10547","0.04331","817.71057","-0.00027"
"130.50000","4.34748","8175.51074","0.04347","817.55109","-0.00027"
"131.00000","4.36413","8173.51660","0.04364","817.35168","-0.00027"
"131.50000","4.38093","8169.57520","0.04381","816.95752","-0.00027"
"132.00000","4.39731","8165.09814","0.04397","816.50983","-0.00026"
"132.50000","4.41406","8168.17041","0.04414","816.81702","-0.00028"
"133.00000","4.43070","8170.05176","0.04431","817.00519","-0.00028"
"133.50000","4.44758","8172.98291","0.04448","817.29828","-0.00028"
"134.00000","4.46404","8171.64941","0.04464","817.16492","-0.00028"
"134.50000","4.48078","8176.47803","0.04481","817.64783","-0.00028"
"135.00000","4.49737","8177.56494","0.04497","817.75647","-0.00028"
"135.50000","4.51413","8177.98438","0.04514","817.79846","-0.00029"
"136.00000","4.53089","8178.35645","0.04531","817.83563","-0.00029"
"136.50000","4.54745","8177.27588","0.04547","817.72760","-0.00028"
"137.00000","4.56408","8176.59424","0.04564","817.65942","-0.00026"
"137.50000","4.58066","8172.48291","0.04581","817.24829","-0.00027"
"138.00000","4.59747","8170.73486","0.04597","817.07349","-0.00028"
"138.50000","4.61412","8169.16846","0.04614","816.91687","-0.00027"
"139.00000","4.63088","8168.98438","0.04631","816.89844","-0.00027"
"139.50000","4.64732","8162.91406","0.04647","816.29138","-0.00027"
"140.00000","4.66424","8162.62500","0.04664","816.26251","-0.00027"
"140.50000","4.68095","8158.75830","0.04681","815.87585","-0.00027"
"141.00000","4.69741","8153.56738","0.04697","815.35675","-0.00027"
"141.50000","4.71423","8155.43604","0.04714","815.54358","-0.00027"
"142.00000","4.73069","8154.31836","0.04731","815.43182","-0.00027"
"142.50000","4.74754","8154.42041","0.04748","815.44202","-0.00027"
"143.00000","4.76405","8149.13818","0.04764","814.91382","-0.00028"
"143.50000","4.78083","8147.17285","0.04781","814.71729","-0.00028"
"144.00000","4.79740","8143.34668","0.04797","814.33466","-0.00028"
"144.50000","4.81420","8141.66748","0.04814","814.16675","-0.00028"
"145.00000","4.83067","8134.53174","0.04831","813.45319","-0.00028"
"145.50000","4.84746","8130.52783","0.04847","813.05280","-0.00029"
"146.00000","4.86415","8122.68799","0.04864","812.26880","-0.00028"
"146.50000","4.88076","8115.14502","0.04881","811.51453","-0.00028"
"147.00000","4.89749","8107.56006","0.04897","810.75598","-0.00028"
"147.50000","4.91404","8097.10693","0.04914","809.71069","-0.00027"
"148.00000","4.93067","8090.50439","0.04931","809.05042","-0.00027"
"148.50000","4.94733","8086.08301","0.04947","808.60828","-0.00027"
"149.00000","4.96418","8079.96777","0.04964","807.99677","-0.00027"
"149.50000","4.98078","8067.91992","0.04981","806.79199","-0.00027"
"150.00000","4.99751","8058.37939","0.04998","805.83795","-0.00027"
"150.50000","5.01409","8045.48779","0.05014","804.54877","-0.00027"
"151.00000","5.03080","8033.98877","0.05031","803.39886","-0.00027"
"151.50000","5.04756","8025.11963","0.05048","802.51196","-0.00027"
"152.00000","5.06409","8014.36230","0.05064","801.43622","-0.00027"
"152.50000","5.08080","8003.48145","0.05081","800.34814","-0.00027"
"153.00000","5.09740","7988.93945","0.05097","798.89392","-0.00028"
"153.50000","5.11412","7975.48047","0.05114","797.54803","-0.00028"
"154.00000","5.13069","7961.71045","0.05131","796.17102","-0.00028"
"154.50000","5.14762","7950.85205","0.05148","795.08521","-0.00028"
"155.00000","5.16413","7936.14844","0.05164","793.61487","-0.00028"
"155.50000","5.18082","7921.69141","0.05181","792.16913","-0.00028"
"156.00000","5.19737","7907.27832","0.05197","790.72784","-0.00028"
"156.50000","5.21411","7897.25049","0.05214","789.72504","-0.00028"
"157.00000","5.23098","7888.73193","0.05231","788.87317","-0.00027"
"157.50000","5.24741","7876.77100","0.05247","787.67712","-0.00028"
"158.00000","5.26410","7866.43848","0.05264","786.64386","-0.00028"
"158.50000","5.28070","7854.75586","0.05281","785.47559","-0.00028"
"159.00000","5.29746","7846.62012","0.05297","784.66199","-0.00027"
"159.50000","5.31407","7834.80762","0.05314","783.48077","-0.00027"
"160.00000","5.33089","7820.97510","0.05331","782.09753","-0.00027"
"160.50000","5.34728","7798.00244","0.05347","779.80023","-0.00027"
"161.00000","5.36420","7782.39209","0.05364","778.23920","-0.00027"
"161.50000","5.38084","7764.89893","0.05381","776.48987","-0.00027"
"162.00000","5.39747","7748.85254","0.05397","774.88525","-0.00027"
"162.50000","5.41419","7737.29980","0.05414","773.72998","-0.00027"
"163.00000","5.43060","7722.27588","0.05431","772.22760","-0.00028"
"163.50000","5.44747","7711.97510","0.05447","771.19751","-0.00028"
"164.00000","5.46408","7699.27344","0.05464","769.92737","-0.00028"
"164.50000","5.48080","7689.30322","0.05481","768.93030","-0.00028"
"165.00000","5.49741","7676.68408","0.05497","767.66840","-0.00028"
"165.50000","5.51422","7662.89990","0.05514","766.28998","-0.00028"
"166.00000","5.53078","7647.29883","0.05531","764.72986","-0.00027"
"166.50000","5.54752","7633.12500","0.05548","763.31250","-0.00027"
"167.00000","5.56414","7617.55762","0.05564","761.75574","-0.00027"
"167.50000","5.58079","7602.32959","0.05581","760.23297","-0.00027"
"168.00000","5.59750","7588.69189","0.05597","758.86920","-0.00027"
"168.50000","5.61397","7575.52539","0.05614","757.55255","-0.00027"
"169.00000","5.63075","7565.62207","0.05631","756.56219","-0.00027"
"169.50000","5.64734","7555.06396","0.05647","755.50641","-0.00027"
"170.00000","5.66423","7548.96533","0.05664","754.89655","-0.00028"
"170.50000","5.68069","7537.01855","0.05681","753.70184","-0.00027"
"171.00000","5.69751","7533.84766","0.05698","753.38477","-0.00028"
"171.50000","5.71408","7529.59424","0.05714","752.95941","-0.00028"
"172.00000","5.73077","7524.64404","0.05731","752.46442","-0.00028"
"172.50000","5.74755","7521.11426","0.05748","752.11145","-0.00028"
"173.00000","5.76410","7514.63623","0.05764","751.46362","-0.00028"
"173.50000","5.78073","7511.51514","0.05781","751.15149","-0.00028"
"174.00000","5.79733","7506.03613","0.05797","750.60364","-0.00028"
"174.50000","5.81417","7500.87061","0.05814","750.08704","-0.00028"
"175.00000","5.83072","7494.75342","0.05831","749.47534","-0.00028"
"175.50000","5.84759","7492.53125","0.05848","749.25311","-0.00027"
"176.00000","5.86406","7483.61133","0.05864","748.36115","-0.00027"
"176.50000","5.88086","7475.42236","0.05881","747.54224","-0.00027"
"177.00000","5.89752","7465.38867","0.05898","746.53888","-0.00027"
"177.50000","5.91404","7455.54639","0.05914","745.55463","-0.00027"
"178.00000","5.93093","7453.41699","0.05931","745.34167","-0.00027"
"178.50000","5.94739","7442.27832","0.05947","744.22784","-0.00027"
"179.00000","5.96412","7432.85107","0.05964","743.28510","-0.00027"
"179.50000","5.98066","7423.84424","0.05981","742.38440","-0.00027"
"180.00000","5.99754","7420.31104","0.05998","742.03113","-0.00027"
"180.50000","6.01412","7415.03906","0.06014","741.50391","-0.00028"
"181.00000","6.03091","7411.48535","0.06031","741.14856","-0.00027"
"181.50000","6.04731","7404.94678","0.06047","740.49469","-0.00028"
"182.00000","6.06407","7401.29053","0.06064","740.12903","-0.00028"
"182.50000","6.08085","7392.77832","0.06081","739.27783","-0.00028"
"183.00000","6.09741","7383.80908","0.06097","738.38092","-0.00028"
"183.50000","6.11416","7377.75781","0.06114","737.77576","-0.00028"
"184.00000","6.13063","7368.39697","0.06131","736.83972","-0.00028"
"184.50000","6.14743","7365.16992","0.06147","736.51697","-0.00028"
"185.00000","6.16406","7358.61377","0.06164","735.86139","-0.00028"
"185.50000","6.18091","7352.87988","0.06181","735.28796","-0.00027"
"186.00000","6.19737","7344.92529","0.06197","734.49255","-0.00027"
"186.50000","6.21408","7344.49854","0.06214","734.44983","-0.00026"
"187.00000","6.23074","7342.72949","0.06231","734.27295","-0.00027"
"187.50000","6.24755","7341.04150","0.06248","734.10413","-0.00027"
"188.00000","6.26418","7336.26562","0.06264","733.62659","-0.00027"
"188.50000","6.28073","7333.87744","0.06281","733.38776","-0.00027"
"189.00000","6.29753","7335.06982","0.06298","733.50696","-0.00027"
"189.50000","6.31405","7331.37646","0.06314","733.13763","-0.00027"
"190.00000","6.33081","7328.57373","0.06331","732.85736","-0.00027"
"190.50000","6.34735","7320.91650","0.06347","732.09167","-0.00028"
"191.00000","6.36427","7315.23877","0.06364","731.52386","-0.00027"
"191.50000","6.38075","7303.68848","0.06381","730.36884","-0.00028"
"192.00000","6.39743","7295.42383","0.06397","729.54236","-0.00028"
"192.50000","6.41415","7290.53369","0.06414","729.05334","-0.00028"
"193.00000","6.43074","7282.80859","0.06431","728.28088","-0.00028"
"193.50000","6.44752","7279.94531","0.06448","727.99451","-0.00028"
"194.00000","6.46400","7273.36475","0.06464","727.33649","-0.00028"
"194.50000","6.48079","7266.68896","0.06481","726.66888","-0.00028"
"195.00000","6.49736","7259.68799","0.06497","725.96881","-0.00027"
"195.50000","6.51417","7255.97314","0.06514","725.59729","-0.00027"
"196.00000","6.53070","7249.71436","0.06531","724.97144","-0.00027"
"196.50000","6.54753","7245.71045","0.06548","724.57104","-0.00027"
"197.00000","6.56401","7236.30176","0.06564","723.63019","-0.00027"
"197.50000","6.58078","7229.95312","0.06581","722.99530","-0.00027"
"198.00000","6.59757","7221.90967","0.06598","722.19098","-0.00027"
"198.50000","6.61410","7211.14746","0.06614","721.11475","-0.00027"
"199.00000","6.63087","7206.58594","0.06631","720.65857","-0.00028"
"199.50000","6.64736","7199.92725","0.06647","719.99274","-0.00027"
"200.00000","6.66419","7199.92383","0.06664","719.99237","-0.00027"
"200.50000","6.68069","7195.67773","0.06681","719.56775","-0.00028"
"201.00000","6.69746","7193.69775","0.06697","719.36975","-0.00028"
"201.50000","6.71405","7187.81934","0.06714","718.78192","-0.00028"
"202.00000","6.73092","7183.10986","0.06731","718.31097","-0.00028"
"202.50000","6.74737","7169.65137","0.06747","716.96515","-0.00028"
"203.00000","6.76411","7159.93945","0.06764","715.99396","-0.00028"
"203.50000","6.78091","7152.47900","0.06781","715.24792","-0.00027"
"204.00000","6.79748","7143.09521","0.06797","714.30951","-0.00028"
"204.50000","6.81413","7131.58252","0.06814","713.15826","-0.00027"
"205.00000","6.83055","7116.91162","0.06831","711.69116","-0.00027"
"205.50000","6.84738","7110.35303","0.06847","711.03528","-0.00027"
"206.00000","6.86407","7103.37305","0.06864","710.33728","-0.00027"
"206.50000","6.88087","7097.60938","0.06881","709.76093","-0.00027"
"207.00000","6.89741","7090.10889","0.06897","709.01086","-0.00027"
"207.50000","6.91411","7085.97314","0.06914","708.59729","-0.00027"
"208.00000","6.93082","7084.62744","0.06931","708.46277","-0.00027"
"208.50000","6.94743","7080.81055","0.06947","708.08105","-0.00027"
"209.00000","6.96425","7078.32812","0.06964","707.83282","-0.00027"
"209.50000","6.98070","7071.32666","0.06981","707.13269","-0.00028"
"210.00000","6.99734","7065.92139","0.06997","706.59216","-0.00028"
"210.50000","7.01400","7061.56787","0.07014","706.15680","-0.00028"
"211.00000","7.03092","7060.25488","0.07031","706.02551","-0.00028"
"211.50000","7.04736","7051.73682","0.07047","705.17371","-0.00027"
"212.00000","7.06425","7044.37939","0.07064","704.43793","-0.00028"
"212.50000","7.08070","7027.73047","0.07081","702.77307","-0.00028"
"213.00000","7.09756","7018.40381","0.07098","701.84039","-0.00028"
"213.50000","7.11426","7009.85840","0.07114","700.98584","-0.00028"
"214.00000","7.13073","7001.30615","0.07131","700.13062","-0.00027"
"214.50000","7.14759","6996.59668","0.07148","699.65967","-0.00027"
"215.00000","7.16400","6984.84912","0.07164","698.48492","-0.00027"
"215.50000","7.18071","6975.42041","0.07181","697.54205","-0.00025"
"216.00000","7.19740","6964.04004","0.07197","696.40399","-0.00024"
"216.50000","7.21418","6953.56201","0.07214","695.35620","-0.00026"
"217.00000","7.23076","6946.02441","0.07231","694.60242","-0.00026"
"217.50000","7.24751","6942.48730","0.07248","694.24872","-0.00027"
"218.00000","7.26404","6933.50293","0.07264","693.35028","-0.00027"
"218.50000","7.28078","6926.67676","0.07281","692.66766","-0.00028"
"219.00000","7.29748","6921.48584","0.07297","692.14856","-0.00029"
"219.50000","7.31402","6916.16699","0.07314","691.61670","-0.00029"
"220.00000","7.33081","6912.17871","0.07331","691.21790","-0.00028"
"220.50000","7.34734","6906.29346","0.07347","690.62933","-0.00028"
"221.00000","7.36418","6903.40527","0.07364","690.34052","-0.00028"
"221.50000","7.38075","6895.26807","0.07381","689.52679","-0.00028"
"222.00000","7.39754","6891.37891","0.07398","689.13788","-0.00028"
"222.50000","7.41407","6884.80664","0.07414","688.48065","-0.00028"
"223.00000","7.43082","6881.72559","0.07431","688.17255","-0.00027"
"223.50000","7.44747","6875.46680","0.07447","687.54669","-0.00027"
"224.00000","7.46410","6867.38037","0.07464","686.73804","-0.00027"
"224.50000","7.48082","6863.50488","0.07481","686.35046","-0.00027"
"225.00000","7.49745","6859.24805","0.07497","685.92480","-0.00027"
"225.50000","7.51424","6856.14551","0.07514","685.61456","-0.00027"
"226.00000","7.53062","6849.14746","0.07531","684.91473","-0.00027"
"226.50000","7.54747","6846.23779","0.07547","684.62378","-0.00027"
"227.00000","7.56404","6840.15771","0.07564","684.01575","-0.00027"
"227.50000","7.58094","6835.72217","0.07581","683.57220","-0.00028"
"228.00000","7.59742","6824.38916","0.07597","682.43890","-0.00028"
"228.50000","7.61408","6817.83105","0.07614","681.78308","-0.00026"
"229.00000","7.63082","6811.11230","0.07631","681.11121","-0.00027"
"229.50000","7.64745","6806.80518","0.07647","680.68054","-0.00029"
"230.00000","7.66420","6805.50342","0.07664","680.55035","-0.00028"
"230.50000","7.68073","6803.59473","0.07681","680.35950","-0.00027"
"231.00000","7.69736","6801.93066","0.07697","680.19305","-0.00029"
"231.50000","7.71402","6800.35645","0.07714","680.03564","-0.00028"
"232.00000","7.73087","6800.50195","0.07731","680.05017","-0.00027"
"232.50000","7.74743","6796.93457","0.07747","679.69348","-0.00028"
"233.00000","7.76418","6796.09033","0.07764","679.60901","-0.00029"
"233.50000","7.78068","6788.59668","0.07781","678.85968","-0.00027"
"234.00000","7.79747","6785.63574","0.07797","678.56360","-0.00027"
"234.50000","7.81434","6784.17090","0.07814","678.41711","-0.00024"
"235.00000","7.83069","6780.00098","0.07831","678.00012","-0.00027"
"235.50000","7.84753","6778.45166","0.07848","677.84515","-0.00030"
"236.00000","7.86399","6768.90820","0.07864","676.89081","-0.00028"
"236.50000","7.88082","6763.97705","0.07881","676.39771","-0.00027"
"237.00000","7.89743","6755.29688","0.07897","675.52966","-0.00027"
"237.50000","7.91421","6750.52637","0.07914","675.05261","-0.00027"
"238.00000","7.93076","6744.97656","0.07931","674.49768","-0.00024"
"238.50000","7.94747","6743.49121","0.07947","674.34912","-0.00029"
"239.00000","7.96404","6738.84326","0.07964","673.88434","-0.00032"
"239.50000","7.98079","6734.70801","0.07981","673.47083","-0.00030"
"240.00000","7.99758","6728.35693","0.07998","672.83569","-0.00026"
"240.50000","8.01404","6719.33057","0.08014","671.93304","-0.00027"
"241.00000","8.03074","6715.23340","0.08031","671.52332","-0.00028"
"241.50000","8.04736","6711.12402","0.08047","671.11243","-0.00029"
"242.00000","8.06411","6708.80664","0.08064","670.88068","-0.00028"
"242.50000","8.08074","6707.15967","0.08081","670.71594","-0.00027"
"243.00000","8.09752","6705.34082","0.08098","670.53406","-0.00027"
"243.50000","8.11405","6702.43115","0.08114","670.24310","-0.00026"
"244.00000","8.13077","6704.20752","0.08131","670.42078","-0.00027"
"244.50000","8.14750","6705.19238","0.08147","670.51923","-0.00027"
"245.00000","8.16413","6702.63623","0.08164","670.26361","-0.00027"
"245.50000","8.18085","6701.52393","0.08181","670.15240","-0.00026"
"246.00000","8.19738","6695.92236","0.08197","669.59222","-0.00027"
"246.50000","8.21411","6692.09521","0.08214","669.20953","-0.00028"
"247.00000","8.23077","6685.16699","0.08231","668.51672","-0.00028"
"247.50000","8.24748","6677.76465","0.08247","667.77649","-0.00027"
"248.00000","8.26404","6671.33496","0.08264","667.13348","-0.00027"
"248.50000","8.28094","6668.94092","0.08281","666.89410","-0.00029"
"249.00000","8.29751","6664.28369","0.08298","666.42834","-0.00029"
"249.50000","8.31408","6661.84863","0.08314","666.18488","-0.00028"
"250.00000","8.33084","6659.96582","0.08331","665.99658","-0.00028"
"250.50000","8.34742","6653.94287","0.08347","665.39429","-0.00028"
"251.00000","8.36429","6649.52783","0.08364","664.95276","-0.00028"
"251.50000","8.38071","6640.79248","0.08381","664.07922","-0.00027"
"252.00000","8.39740","6635.50732","0.08397","663.55072","-0.00027"
"252.50000","8.41403","6628.48730","0.08414","662.84875","-0.00027"
"253.00000","8.43087","6623.87256","0.08431","662.38727","-0.00027"
"253.50000","8.44736","6614.22559","0.08447","661.42255","-0.00027"
"254.00000","8.46416","6607.86426","0.08464","660.78644","-0.00026"
"254.50000","8.48069","6599.29590","0.08481","659.92957","-0.00027"
"255.00000","8.49746","6592.93359","0.08497","659.29333","-0.00026"
"255.50000","8.51421","6585.44092","0.08514","658.54407","-0.00027"
"256.00000","8.53078","6577.86182","0.08531","657.78619","-0.00026"
"256.50000","8.54742","6573.40430","0.08547","657.34045","-0.00027"
"257.00000","8.56393","6567.00732","0.08564","656.70074","-0.00028"
"257.50000","8.58081","6561.10352","0.08581","656.11035","-0.00028"
"258.00000","8.59751","6551.00195","0.08598","655.10022","-0.00029"
"258.50000","8.61416","6542.10889","0.08614","654.21088","-0.00029"
"259.00000","8.63073","6532.27783","0.08631","653.22778","-0.00029"
"259.50000","8.64750","6525.20605","0.08648","652.52063","-0.00028"
"260.00000","8.66418","6517.08984","0.08664","651.70898","-0.00028"
"260.50000","8.68081","6511.00781","0.08681","651.10077","-0.00027"
"261.00000","8.69754","6505.27832","0.08698","650.52783","-0.00027"
"261.50000","8.71409","6497.42871","0.08714","649.74286","-0.00027"
"262.00000","8.73079","6490.84814","0.08731","649.08484","-0.00027"
"262.50000","8.74732","6481.57617","0.08747","648.15759","-0.00027"
"263.00000","8.76419","6473.22070","0.08764","647.32208","-0.00027"
"263.50000","8.78074","6464.05811","0.08781","646.40582","-0.00026"
"264.00000","8.79754","6456.90625","0.08798","645.69061","-0.00026"
"264.50000","8.81400","6443.50879","0.08814","644.35089","-0.00027"
"265.00000","8.83077","6434.82080","0.08831","643.48206","-0.00027"
"265.50000","8.84756","6426.22998","0.08848","642.62299","-0.00027"
"266.00000","8.86410","6418.48682","0.08864","641.84869","-0.00027"
"266.50000","8.88081","6412.69238","0.08881","641.26923","-0.00028"
"267.00000","8.89736","6405.71875","0.08897","640.57190","-0.00028"
"267.50000","8.91405","6398.91406","0.08914","639.89142","-0.00028"
"268.00000","8.93070","6391.16992","0.08931","639.11700","-0.00028"
"268.50000","8.94755","6387.46924","0.08948","638.74695","-0.00028"
"269.00000","8.96404","6380.48438","0.08964","638.04846","-0.00028"
"269.50000","8.98091","6377.98242","0.08981","637.79822","-0.00028"
"270.00000","8.99743","6372.65137","0.08997","637.26514","-0.00027"
"270.50000","9.01416","6368.29639","0.09014","636.82965","-0.00027"
"271.00000","9.03090","6362.76660","0.09031","636.27667","-0.00027"
"271.50000","9.04731","6356.89795","0.09047","635.68982","-0.00027"
"272.00000","9.06421","6358.07080","0.09064","635.80707","-0.00030"
"272.50000","9.08075","6350.65869","0.09081","635.06586","-0.00030"
"273.00000","9.09737","6343.63086","0.09097","634.36310","-0.00027"
"273.50000","9.11408","6338.18604","0.09114","633.81860","-0.00026"
"274.00000","9.13094","6334.15332","0.09131","633.41534","-0.00026"
"274.50000","9.14744","6324.43262","0.09147","632.44324","-0.00027"
"275.00000","9.16418","6318.15283","0.09164","631.81531","-0.00027"
"275.50000","9.18070","6309.19775","0.09181","630.91980","-0.00028"
"276.00000","9.19737","6302.15088","0.09197","630.21509","-0.00028"
"276.50000","9.21420","6297.61719","0.09214","629.76172","-0.00028"
"277.00000","9.23066","6288.91797","0.09231","628.89178","-0.00028"
"277.50000","9.24744","6281.90283","0.09247","628.19031","-0.00028"
"278.00000","9.26397","6273.30078","0.09264","627.33008","-0.00027"
"278.50000","9.28083","6267.55664","0.09281","626.75568","-0.00028"
"279.00000","9.29742","6260.70117","0.09297","626.07013","-0.00027"
"279.50000","9.31425","6256.89111","0.09314","625.68909","-0.00027"
"280.00000","9.33069","6248.31201","0.09331","624.83118","-0.00027"
"280.50000","9.34740","6242.71240","0.09347","624.27124","-0.00027"
"281.00000","9.36414","6240.66016","0.09364","624.06604","-0.00027"
"281.50000","9.38085","6237.37061","0.09381","623.73706","-0.00026"
"282.00000","9.39748","6229.22363","0.09397","622.92236","-0.00026"
"282.50000","9.41402","6220.19336","0.09414","622.01935","-0.00027"
"283.00000","9.43081","6213.28955","0.09431","621.32898","-0.00027"
"283.50000","9.44740","6203.71680","0.09447","620.37170","-0.00027"
"284.00000","9.46424","6198.13037","0.09464","619.81305","-0.00026"
"284.50000","9.48070","6189.51562","0.09481","618.95154","-0.00027"
"285.00000","9.49760","6186.50537","0.09498","618.65051","-0.00028"
"285.50000","9.51411","6177.89307","0.09514","617.78931","-0.00029"
"286.00000","9.53072","6172.88428","0.09531","617.28845","-0.00028"
"286.50000","9.54758","6169.31934","0.09548","616.93195","-0.00028"
"287.00000","9.56408","6162.42139","0.09564","616.24213","-0.00028"
"287.50000","9.58077","6158.97852","0.09581","615.89783","-0.00028"
"288.00000","9.59732","6149.20508","0.09597","614.92053","-0.00027"
"288.50000","9.61411","6144.42920","0.09614","614.44293","-0.00028"
"289.00000","9.63076","6138.65527","0.09631","613.86554","-0.00028"
"289.50000","9.64758","6131.14258","0.09648","613.11426","-0.00027"
"290.00000","9.66398","6120.36377","0.09664","612.03638","-0.00027"
"290.50000","9.68078","6114.81250","0.09681","611.48126","-0.00027"
"291.00000","9.69742","6108.23779","0.09697","610.82379","-0.00026"
"291.50000","9.71410","6104.59814","0.09714","610.45984","-0.00026"
"292.00000","9.73093","6103.78223","0.09731","610.37823","-0.00026"
"292.50000","9.74734","6097.87939","0.09747","609.78796","-0.00027"
"293.00000","9.76409","6096.92432","0.09764","609.69244","-0.00027"
"293.50000","9.78067","6096.52832","0.09781","609.65283","-0.00027"
"294.00000","9.79752","6095.50537","0.09798","609.55054","-0.00027"
"294.50000","9.81406","6090.37305","0.09814","609.03729","-0.00027"
"295.00000","9.83081","6089.11914","0.09831","608.91193","-0.00028"
"295.50000","9.84738","6085.92578","0.09847","608.59259","-0.00028"
"296.00000","9.86424","6082.51807","0.09864","608.25183","-0.00028"
"296.50000","9.88077","6076.06104","0.09881","607.60608","-0.00028"
"297.00000","9.89742","6070.35254","0.09897","607.03528","-0.00028"
"297.50000","9.91425","6062.74902","0.09914","606.27490","-0.00028"
"298.00000","9.93074","6052.48877","0.09931","605.24890","-0.00027"
"298.50000","9.94746","6047.42969","0.09947","604.74298","-0.00028"
"299.00000","9.96396","6041.19727","0.09964","604.11975","-0.00027"
"299.50000","9.98083","6039.22266","0.09981","603.92224","-0.00026"
"300.00000","9.99743","6033.49023","0.09997","603.34900","-0.00027"
"300.50000","10.01416","6030.97852","0.10014","603.09784","-0.00027"
"301.00000","10.03074","6027.95215","0.10031","602.79523","-0.00027"
"301.50000","10.04741","6024.69580","0.10047","602.46960","-0.00027"
"302.00000","10.06421","6020.69141","0.10064","602.06915","-0.00027"
"302.50000","10.08075","6013.04346","0.10081","601.30432","-0.00027"
"303.00000","10.09750","6007.43604","0.10097","600.74359","-0.00027"
"303.50000","10.11402","5999.10303","0.10114","599.91028","-0.00027"
"304.00000","10.13073","5992.99951","0.10131","599.29993","-0.00027"
"304.50000","10.14738","5986.28174","0.10147","598.62817","-0.00027"
"305.00000","10.16426","5981.41211","0.10164","598.14124","-0.00027"
"305.50000","10.18069","5973.19824","0.10181","597.31982","-0.00028"
"306.00000","10.19748","5969.87256","0.10197","596.98724","-0.00028"
"306.50000","10.21415","5963.31836","0.10214","596.33185","-0.00028"
"307.00000","10.23078","5958.32227","0.10231","595.83221","-0.00028"
"307.50000","10.24761","5959.02246","0.10248","595.90222","-0.00028"
"308.00000","10.26404","5953.52441","0.10264","595.35242","-0.00027"
"308.50000","10.28085","5949.97900","0.10281","594.99792","-0.00027"
"309.00000","10.29733","5945.03174","0.10297","594.50317","-0.00027"
"309.50000","10.31404","5941.09180","0.10314","594.10919","-0.00026"
"310.00000","10.33076","5938.32812","0.10331","593.83282","-0.00027"
"310.50000","10.34758","5936.10889","0.10348","593.61090","-0.00027"
"311.00000","10.36403","5929.49561","0.10364","592.94958","-0.00027"
"311.50000","10.38077","5927.01270","0.10381","592.70129","-0.00027"
"312.00000","10.39749","5921.11084","0.10397","592.11108","-0.00027"
"312.50000","10.41414","5915.65088","0.10414","591.56506","-0.00027"
"313.00000","10.43083","5912.92285","0.10431","591.29230","-0.00027"
"313.50000","10.44729","5905.86328","0.10447","590.58630","-0.00028"
"314.00000","10.46403","5899.59668","0.10464","589.95966","-0.00027"
"314.50000","10.48072","5894.36426","0.10481","589.43640","-0.00027"
"315.00000","10.49753","5893.07422","0.10498","589.30743","-0.00028"
"315.50000","10.51408","5885.11475","0.10514","588.51147","-0.00028"
"316.00000","10.53082","5879.04932","0.10531","587.90491","-0.00027"
"316.50000","10.54738","5868.71289","0.10547","586.87128","-0.00028"
"317.00000","10.56412","5860.98486","0.10564","586.09851","-0.00028"
"317.50000","10.58088","5851.85352","0.10581","585.18536","-0.00028"
"318.00000","10.59743","5843.95312","0.10597","584.39532","-0.00027"
"318.50000","10.61412","5842.01074","0.10614","584.20105","-0.00027"
"319.00000","10.63068","5834.70752","0.10631","583.47076","-0.00027"
"319.50000","10.64756","5829.12744","0.10648","582.91272","-0.00027"
"320.00000","10.66401","5821.23486","0.10664","582.12347","-0.00027"
"320.50000","10.68089","5816.89648","0.10681","581.68964","-0.00027"
"321.00000","10.69738","5808.98438","0.10697","580.89844","-0.00027"
"321.50000","10.71421","5805.07129","0.10714","580.50714","-0.00027"
"322.00000","10.73079","5795.75537","0.10731","579.57556","-0.00026"
"322.50000","10.74739","5787.42969","0.10747","578.74298","-0.00025"
"323.00000","10.76426","5783.22559","0.10764","578.32257","-0.00026"
"323.50000","10.78071","5774.14551","0.10781","577.41455","-0.00027"
"324.00000","10.79742","5770.12207","0.10797","577.01221","-0.00028"
"324.50000","10.81403","5765.95459","0.10814","576.59546","-0.00029"
"325.00000","10.83073","5761.74561","0.10831","576.17456","-0.00029"
"325.50000","10.84739","5757.31152","0.10847","575.73114","-0.00028"
"326.00000","10.86421","5752.87598","0.10864","575.28760","-0.00028"
"326.50000","10.88072","5745.80811","0.10881","574.58081","-0.00028"
"327.00000","10.89746","5740.85352","0.10897","574.08533","-0.00027"
"327.50000","10.91410","5737.20264","0.10914","573.72028","-0.00027"
"328.00000","10.93075","5734.04004","0.10931","573.40399","-0.00026"
"328.50000","10.94761","5731.41211","0.10948","573.14124","-0.00026"
"329.00000","10.96397","5723.45312","0.10964","572.34534","-0.00026"
"329.50000","10.98082","5721.06055","0.10981","572.10608","-0.00028"
"330.00000","10.99736","5716.06396","0.10997","571.60638","-0.00028"
"330.50000","11.01418","5715.43994","0.11014","571.54401","-0.00027"
"331.00000","11.03078","5711.23340","0.11031","571.12335","-0.00027"
"331.50000","11.04754","5708.34766","0.11048","570.83478","-0.00027"
"332.00000","11.06408","5703.79980","0.11064","570.38000","-0.00027"
"332.50000","11.08077","5701.46631","0.11081","570.14661","-0.00027"
"333.00000","11.09748","5698.80176","0.11097","569.88019","-0.00028"
"333.50000","11.11414","5695.25098","0.11114","569.52509","-0.00028"
"334.00000","11.13093","5692.32861","0.11131","569.23285","-0.00027"
"334.50000","11.14731","5685.44775","0.11147","568.54480","-0.00028"
"335.00000","11.16405","5680.56689","0.11164","568.05670","-0.00028"
"335.50000","11.18071","5674.97656","0.11181","567.49768","-0.00034"
"335.99000","11.19726","5669.79443","0.11197","566.97943","-0.00033"