File: Tension/Section_2_Group_4/f2a.is_tens_RawData/Specimen_RawData_1.csv
Time,Extension,Load,Tensile strain (Extension),Tensile stress,Strain-by-clip-gage
(s),(mm),(N),(mm/mm),(MPa),(mm/mm)
"0.00000","0.00000","-3.26047","0.00000","-0.32605","-0.00001"
"0.70000","0.02043","38.65670","0.00020","3.86567","0.00000"
"1.40000","0.04379","82.95889","0.00044","8.29589","-0.00001"
"2.10000","0.06712","123.45364","0.00067","12.34536","0.00000"
"2.80000","0.09045","160.62166","0.00090","16.06217","0.00000"
"3.50000","0.11382","195.63371","0.00114","19.56337","0.00000"
"4.20000","0.13708","228.24979","0.00137","22.82498","0.00000"
"4.90000","0.16040","259.09903","0.00160","25.90990","0.00000"
"5.60000","0.18378","288.00955","0.00184","28.80095","0.00000"
"6.30000","0.20711","315.14755","0.00207","31.51476","0.00000"
"7.00000","0.23049","340.78873","0.00230","34.07887","0.00000"
"7.70000","0.25377","364.91660","0.00254","36.49166","0.00000"
"8.40000","0.27709","387.50110","0.00277","38.75011","-0.00001"
"9.10000","0.30055","409.14658","0.00301","40.91466","0.00000"
"9.80000","0.32374","429.40601","0.00324","42.94060","0.00000"
"10.50000","0.34720","448.71988","0.00347","44.87199","-0.00001"
"11.20000","0.37052","466.93677","0.00371","46.69368","0.00000"
"11.90000","0.39391","484.35474","0.00394","48.43547","0.00001"
"12.60000","0.41723","500.55905","0.00417","50.05590","0.00000"
"13.30000","0.44054","516.25043","0.00441","51.62504","0.00000"
"14.00000","0.46385","531.25244","0.00464","53.12524","0.00000"
"14.70000","0.48710","545.41559","0.00487","54.54156","0.00000"
"15.40000","0.51043","559.19208","0.00510","55.91921","0.00000"
"16.10000","0.53385","572.36523","0.00534","57.23652","0.00000"
"16.80000","0.55723","585.18695","0.00557","58.51870","-0.00001"
"17.50000","0.58069","597.39880","0.00581","59.73988","0.00000"
"18.20000","0.60397","609.13007","0.00604","60.91301","0.00000"
"18.90000","0.62724","620.13666","0.00627","62.01366","0.00000"
"19.60000","0.65053","631.09406","0.00651","63.10941","0.00000"
"20.30000","0.67374","641.39722","0.00674","64.13972","0.00000"
"21.00000","0.69704","651.41449","0.00697","65.14145","0.00000"
"21.70000","0.72042","661.21210","0.00720","66.12121","0.00000"
"22.40000","0.74371","670.64154","0.00744","67.06416","0.00000"
"23.10000","0.76709","679.80859","0.00767","67.98086","0.00000"
"23.80000","0.79045","688.84546","0.00790","68.88454","0.00000"
"24.50000","0.81375","697.08618","0.00814","69.70862","0.00000"
"25.20000","0.83718","705.63013","0.00837","70.56301","-0.00001"
"25.90000","0.86040","713.44867","0.00860","71.34486","0.00000"
"26.60000","0.88379","721.21204","0.00884","72.12120","0.00000"
"27.30000","0.90710","728.69183","0.00907","72.86919","-0.00001"
"28.00000","0.93045","735.96002","0.00930","73.59600","0.00000"
"28.70000","0.95384","743.00684","0.00954","74.30068","0.00000"
"29.40000","0.97713","749.77478","0.00977","74.97748","0.00000"
"30.10000","1.00046","756.32886","0.01000","75.63289","0.00000"
"30.80000","1.02386","762.65228","0.01024","76.26523","0.00000"
"31.50000","1.04707","768.67035","0.01047","76.86703","0.00000"
"32.20000","1.07056","774.78802","0.01071","77.47881","0.00000"
"32.90000","1.09384","780.54504","0.01094","78.05450","0.00000"
"33.60000","1.11726","786.11963","0.01117","78.61196","0.00000"
"34.30000","1.14054","791.44006","0.01141","79.14400","0.00000"
"35.00000","1.16383","796.36865","0.01164","79.63686","0.00000"
"35.70000","1.18717","801.59418","0.01187","80.15942","0.00000"
"36.40000","1.21046","806.23907","0.01210","80.62391","0.00000"
"37.10000","1.23377","811.01141","0.01234","81.10114","0.00000"
"37.80000","1.25722","815.76685","0.01257","81.57668","0.00000"
"38.50000","1.28061","820.23962","0.01281","82.02396","0.00000"
"39.20000","1.30399","824.69818","0.01304","82.46982","0.00000"
"39.90000","1.32730","828.62347","0.01327","82.86235","0.00000"
"40.60000","1.35056","832.40021","0.01351","83.24002","0.00000"
"41.30000","1.37385","836.22198","0.01374","83.62220","0.00000"
"42.00000","1.39706","839.71832","0.01397","83.97183","0.00000"
"42.70000","1.42038","843.37927","0.01420","84.33793","0.00000"
"43.40000","1.44374","846.92633","0.01444","84.69263","0.00000"
"44.10000","1.46706","850.40063","0.01467","85.04006","0.00000"
"44.80000","1.49045","854.06348","0.01490","85.40635","0.00000"
"45.50000","1.51376","857.03058","0.01514","85.70306","0.00000"
"46.20000","1.53709","860.39227","0.01537","86.03923","0.00000"
"46.90000","1.56048","863.51306","0.01560","86.35130","0.00000"
"47.60000","1.58375","866.69403","0.01584","86.66940","0.00000"
"48.30000","1.60711","869.69537","0.01607","86.96954","0.00000"
"49.00000","1.63040","872.65485","0.01630","87.26549","0.00000"
"49.70000","1.65380","875.66516","0.01654","87.56651","0.00000"
"50.40000","1.67714","878.59705","0.01677","87.85970","0.00000"
"51.10000","1.70045","881.34332","0.01700","88.13433","0.00000"
"51.80000","1.72381","884.33075","0.01724","88.43307","0.00000"
"52.50000","1.74720","887.11481","0.01747","88.71148","-0.00001"
"53.20000","1.77046","889.72150","0.01770","88.97215","0.00000"
"53.90000","1.79391","892.50476","0.01794","89.25047","0.00001"
"54.60000","1.81721","895.19482","0.01817","89.51949","0.00000"
"55.30000","1.84053","897.71674","0.01841","89.77168","0.00000"
"56.00000","1.86389","900.50458","0.01864","90.05046","0.00000"
"56.70000","1.88713","902.67853","0.01887","90.26785","0.00000"
"57.40000","1.91051","905.44696","0.01911","90.54469","0.00000"
"58.10000","1.93378","907.76971","0.01934","90.77697","0.00000"
"58.80000","1.95711","910.17523","0.01957","91.01752","0.00001"
"59.50000","1.98058","913.01410","0.01981","91.30141","0.00000"
"60.20000","2.00399","915.58527","0.02004","91.55853","0.00000"
"60.90000","2.02731","917.97968","0.02027","91.79797","0.00000"
"61.60000","2.05064","920.27466","0.02051","92.02747","0.00001"
"62.30000","2.07387","922.64728","0.02074","92.26472","0.00001"
"63.00000","2.09718","924.86462","0.02097","92.48647","0.00000"
"63.70000","2.12039","926.88397","0.02120","92.68840","0.00000"
"64.40000","2.14373","929.11133","0.02144","92.91113","0.00001"
"65.10000","2.16705","931.58099","0.02167","93.15810","0.00000"
"65.80000","2.19040","933.72809","0.02190","93.37281","0.00000"
"66.50000","2.21378","936.17926","0.02214","93.61793","0.00000"
"67.20000","2.23709","938.42877","0.02237","93.84288","0.00000"
"67.90000","2.26042","940.86798","0.02260","94.08680","0.00000"
"68.60000","2.28377","943.00482","0.02284","94.30048","0.00000"
"69.30000","2.30710","945.22992","0.02307","94.52299","0.00000"
"70.00000","2.33045","947.34412","0.02330","94.73441","0.00000"
"70.70000","2.35378","949.80469","0.02354","94.98047","0.00000"
"71.40000","2.37712","951.97278","0.02377","95.19728","0.00000"
"72.10000","2.40049","954.13831","0.02400","95.41383","0.00000"
"72.80000","2.42380","956.48663","0.02424","95.64867","0.00000"
"73.50000","2.44714","958.63129","0.02447","95.86313","0.00000"
"74.20000","2.47054","960.93213","0.02471","96.09322","0.00000"
"74.90000","2.49376","962.79449","0.02494","96.27945","0.00000"
"75.60000","2.51727","965.31342","0.02517","96.53134","0.00000"
"76.30000","2.54055","967.30804","0.02541","96.73080","0.00000"
"77.00000","2.56384","969.25439","0.02564","96.92544","0.00000"
"77.70000","2.58721","971.31244","0.02587","97.13124","0.00000"
"78.40000","2.61046","973.25256","0.02610","97.32526","0.00000"
"79.10000","2.63382","975.32001","0.02634","97.53200","0.00000"
"79.80000","2.65715","977.39093","0.02657","97.73909","0.00000"
"80.50000","2.68047","979.24890","0.02680","97.92489","0.00000"
"81.20000","2.70394","981.57239","0.02704","98.15724","0.00000"
"81.90000","2.72732","983.51294","0.02727","98.35130","0.00000"
"82.60000","2.75066","985.62726","0.02751","98.56273","0.00000"
"83.30000","2.77397","987.43958","0.02774","98.74396","0.00000"
"84.00000","2.79716","989.28876","0.02797","98.92888","0.00000"
"84.70000","2.82048","991.12970","0.02820","99.11297","0.00000"
"85.40000","2.84373","992.98486","0.02844","99.29848","-0.00001"
"86.10000","2.86704","994.78217","0.02867","99.47822","0.00000"
"86.80000","2.89041","996.66248","0.02890","99.66624","0.00001"
"87.50000","2.91372","998.63599","0.02914","99.86360","0.00001"
"88.20000","2.93711","1000.70007","0.02937","100.07001","0.00000"
"88.90000","2.96042","1002.49109","0.02960","100.24911","0.00000"
"89.60000","2.98375","1004.39636","0.02984","100.43964","0.00001"
"90.30000","3.00712","1006.33630","0.03007","100.63363","0.00001"
"91.00000","3.03044","1008.13837","0.03030","100.81384","0.00000"
"91.70000","3.05379","1009.99835","0.03054","100.99983","0.00000"
"92.40000","3.07711","1011.91785","0.03077","101.19179","0.00001"
"93.10000","3.10046","1013.61523","0.03100","101.36153","0.00000"
"93.80000","3.12381","1015.43457","0.03124","101.54346","0.00000"
"94.50000","3.14713","1017.07977","0.03147","101.70798","0.00001"
"95.20000","3.17049","1019.00555","0.03170","101.90056","0.00001"
"95.90000","3.19385","1020.86572","0.03194","102.08657","0.00001"
"96.60000","3.21717","1022.53796","0.03217","102.25380","0.00000"
"97.30000","3.24060","1024.50098","0.03241","102.45010","0.00000"
"98.00000","3.26387","1026.01660","0.03264","102.60166","0.00000"
"98.70000","3.28719","1027.97986","0.03287","102.79799","0.00000"
"99.40000","3.31051","1029.47290","0.03311","102.94729","0.00000"
"100.10000","3.33379","1031.25891","0.03334","103.12589","0.00000"
"100.80000","3.35715","1032.93042","0.03357","103.29305","0.00001"
"101.50000","3.38049","1034.80994","0.03380","103.48100","0.00000"
"102.20000","3.40382","1036.59326","0.03404","103.65932","-0.00001"
"102.90000","3.42731","1038.61438","0.03427","103.86143","0.00000"
"103.60000","3.45064","1040.08167","0.03451","104.00816","0.00000"
"104.30000","3.47398","1041.74268","0.03474","104.17427","0.00000"
"105.00000","3.49726","1043.38452","0.03497","104.33846","0.00000"
"105.70000","3.52051","1044.80078","0.03521","104.48008","0.00000"
"106.40000","3.54380","1046.35767","0.03544","104.63577","0.00001"
"107.10000","3.56706","1047.93945","0.03567","104.79395","0.00000"
"107.80000","3.59036","1049.47681","0.03590","104.94768","0.00000"
"108.50000","3.61378","1051.12366","0.03614","105.11237","0.00000"
"109.20000","3.63707","1052.59424","0.03637","105.25942","0.00000"
"109.90000","3.66043","1054.31580","0.03660","105.43158","0.00000"
"110.60000","3.68373","1055.77478","0.03684","105.57748","0.00000"
"111.30000","3.70706","1057.18640","0.03707","105.71864","0.00000"
"112.00000","3.73045","1058.86475","0.03730","105.88647","0.00000"
"112.70000","3.75377","1060.08069","0.03754","106.00807","0.00000"
"113.40000","3.77714","1061.69116","0.03777","106.16911","0.00000"
"114.10000","3.80043","1062.98364","0.03800","106.29836","0.00000"
"114.80000","3.82379","1064.52356","0.03824","106.45235","0.00000"
"115.50000","3.84712","1065.87158","0.03847","106.58716","0.00000"
"116.20000","3.87049","1067.40576","0.03870","106.74058","0.00000"
"116.90000","3.89383","1068.85046","0.03894","106.88505","0.00000"
"117.60000","3.91725","1070.54492","0.03917","107.05449","0.00001"
"118.30000","3.94050","1071.79822","0.03940","107.17982","0.00000"
"119.00000","3.96395","1073.52393","0.03964","107.35239","-0.00001"
"119.70000","3.98719","1074.69287","0.03987","107.46928","0.00000"
"120.40000","4.01050","1076.00403","0.04011","107.60040","0.00000"
"121.10000","4.03385","1077.17517","0.04034","107.71751","0.00000"
"121.80000","4.05711","1078.48193","0.04057","107.84819","0.00000"
"122.50000","4.08049","1079.87231","0.04080","107.98723","0.00000"
"123.20000","4.10384","1081.54175","0.04104","108.15417","0.00001"
"123.90000","4.12715","1082.89966","0.04127","108.28996","0.00000"
"124.60000","4.15065","1084.46631","0.04151","108.44663","0.00000"
"125.30000","4.17399","1085.95142","0.04174","108.59514","0.00000"
"126.00000","4.19729","1087.26416","0.04197","108.72642","0.00001"
"126.70000","4.22054","1088.55798","0.04221","108.85580","0.00000"
"127.40000","4.24381","1089.92407","0.04244","108.99241","-0.00001"
"128.10000","4.26713","1091.16235","0.04267","109.11623","0.00000"
"128.80000","4.29042","1092.44543","0.04290","109.24454","0.00001"
"129.50000","4.31373","1093.63098","0.04314","109.36310","0.00000"
"130.20000","4.33710","1094.93579","0.04337","109.49358","0.00000"
"130.90000","4.36040","1096.35962","0.04360","109.63596","0.00000"
"131.60000","4.38373","1097.59241","0.04384","109.75924","0.00000"
"132.30000","4.40709","1098.93945","0.04407","109.89394","0.00000"
"133.00000","4.43039","1100.30872","0.04430","110.03087","0.00000"
"133.70000","4.45378","1101.68469","0.04454","110.16847","0.00001"
"134.40000","4.47714","1103.11511","0.04477","110.31151","0.00000"
"135.10000","4.50048","1104.57678","0.04500","110.45768","-0.00001"
"135.80000","4.52380","1105.68567","0.04524","110.56857","0.00000"
"136.50000","4.54714","1107.12744","0.04547","110.71275","0.00000"
"137.20000","4.57046","1108.39648","0.04570","110.83965","0.00000"
"137.90000","4.59384","1109.96033","0.04594","110.99603","0.00000"
"138.60000","4.61717","1111.31653","0.04617","111.13165","0.00000"
"139.30000","4.64059","1112.92688","0.04641","111.29269","0.00000"
"140.00000","4.66384","1114.05493","0.04664","111.40549","0.00001"
"140.70000","4.68727","1115.48682","0.04687","111.54868","0.00000"
"141.40000","4.71051","1116.64697","0.04711","111.66470","0.00000"
"142.10000","4.73383","1117.94702","0.04734","111.79470","0.00000"
"142.80000","4.75713","1119.33887","0.04757","111.93388","0.00000"
"143.50000","4.78045","1120.52576","0.04780","112.05257","0.00000"
"144.20000","4.80384","1121.93604","0.04804","112.19360","0.00000"
"144.90000","4.82715","1123.21484","0.04827","112.32149","0.00000"
"145.60000","4.85052","1124.85510","0.04851","112.48551","0.00000"
"146.30000","4.87399","1126.35388","0.04874","112.63539","0.00000"
"147.00000","4.89733","1127.92017","0.04897","112.79202","0.00000"
"147.70000","4.92059","1128.96008","0.04921","112.89601","0.00000"
"148.40000","4.94387","1130.30444","0.04944","113.03044","0.00000"
"149.10000","4.96711","1131.52405","0.04967","113.15240","0.00000"
"149.80000","4.99044","1133.03296","0.04990","113.30330","0.00000"
"150.50000","5.01375","1134.41272","0.05014","113.44127","0.00001"
"151.20000","5.03708","1135.73096","0.05037","113.57310","0.00000"
"151.90000","5.06044","1137.29517","0.05060","113.72952","0.00000"
"152.60000","5.08373","1138.65820","0.05084","113.86582","0.00000"
"153.30000","5.10708","1140.05676","0.05107","114.00568","0.00000"
"154.00000","5.13041","1141.47949","0.05130","114.14795","0.00000"
"154.70000","5.15371","1142.81714","0.05154","114.28172","0.00000"
"155.40000","5.17712","1144.34106","0.05177","114.43410","0.00000"
"156.10000","5.20043","1145.74744","0.05200","114.57475","0.00000"
"156.80000","5.22385","1147.30005","0.05224","114.73000","0.00000"
"157.50000","5.24713","1148.60706","0.05247","114.86070","0.00000"
"158.20000","5.27048","1150.03198","0.05270","115.00320","-0.00001"
"158.90000","5.29380","1151.52527","0.05294","115.15253","0.00000"
"159.60000","5.31719","1152.85852","0.05317","115.28585","0.00000"
"160.30000","5.34054","1154.31445","0.05341","115.43144","0.00000"
"161.00000","5.36395","1156.00598","0.05364","115.60060","0.00000"
"161.70000","5.38718","1157.26221","0.05387","115.72622","0.00001"
"162.40000","5.41061","1158.68103","0.05411","115.86810","0.00000"
"163.10000","5.43383","1159.86816","0.05434","115.98682","0.00000"
"163.80000","5.45714","1161.20642","0.05457","116.12064","0.00000"
"164.50000","5.48045","1162.41650","0.05480","116.24165","0.00000"
"165.20000","5.50375","1163.59741","0.05504","116.35974","0.00000"
"165.90000","5.52717","1165.12781","0.05527","116.51278","0.00000"
"166.60000","5.55052","1166.32690","0.05551","116.63269","0.00000"
"167.30000","5.57386","1167.69067","0.05574","116.76907","0.00000"
"168.00000","5.59735","1169.12500","0.05597","116.91250","0.00000"
"168.70000","5.62069","1170.38049","0.05621","117.03805","0.00000"
"169.40000","5.64389","1171.26990","0.05644","117.12699","0.00000"
"170.10000","5.66720","1172.45984","0.05667","117.24599","0.00000"
"170.80000","5.69042","1173.69238","0.05690","117.36924","0.00000"
"171.50000","5.71378","1174.86816","0.05714","117.48682","0.00000"
"172.20000","5.73709","1176.23401","0.05737","117.62340","-0.00001"
"172.90000","5.76041","1177.55383","0.05760","117.75539","0.00000"
"173.60000","5.78380","1178.90759","0.05784","117.89076","0.00000"
"174.30000","5.80705","1180.02673","0.05807","118.00267","0.00000"
"175.00000","5.83041","1181.36792","0.05830","118.13680","0.00000"
"175.70000","5.85375","1182.60291","0.05854","118.26029","0.00001"
"176.40000","5.87704","1183.83752","0.05877","118.38375","0.00000"
"177.10000","5.90045","1185.20605","0.05900","118.52061","0.00000"
"177.80000","5.92380","1186.43152","0.05924","118.64315","0.00001"
"178.50000","5.94716","1187.73169","0.05947","118.77317","0.00000"
"179.20000","5.97045","1188.88782","0.05970","118.88878","0.00000"
"179.90000","5.99377","1190.35156","0.05994","119.03516","0.00000"
"180.60000","6.01714","1191.73169","0.06017","119.17317","0.00000"
"181.30000","6.04050","1192.72009","0.06040","119.27201","0.00000"
"182.00000","6.06386","1194.28662","0.06064","119.42867","0.00000"
"182.70000","6.08730","1195.53186","0.06087","119.55318","0.00000"
"183.40000","6.11057","1196.72571","0.06111","119.67257","0.00000"
"184.10000","6.13393","1197.98157","0.06134","119.79816","0.00000"
"184.80000","6.15715","1198.90649","0.06157","119.89065","0.00001"
"185.50000","6.18045","1200.18652","0.06180","120.01865","0.00000"
"186.20000","6.20380","1201.55664","0.06204","120.15566","0.00000"
"186.90000","6.22709","1202.68115","0.06227","120.26811","0.00000"
"187.60000","6.25053","1204.01929","0.06251","120.40193","0.00000"
"188.30000","6.27385","1205.34900","0.06274","120.53490","0.00000"
"189.00000","6.29726","1206.89880","0.06297","120.68988","0.00000"
"189.70000","6.32068","1208.39001","0.06321","120.83900","0.00001"
"190.40000","6.34399","1209.37939","0.06344","120.93794","0.00000"
"191.10000","6.36724","1210.56506","0.06367","121.05650","0.00000"
"191.80000","6.39048","1211.66272","0.06390","121.16628","0.00000"
"192.50000","6.41377","1212.70764","0.06414","121.27077","0.00001"
"193.20000","6.43711","1213.92969","0.06437","121.39297","0.00000"
"193.90000","6.46042","1215.15466","0.06460","121.51546","0.00000"
"194.60000","6.48376","1216.25220","0.06484","121.62522","0.00001"
"195.30000","6.50714","1217.71362","0.06507","121.77136","0.00001"
"196.00000","6.53036","1218.75769","0.06530","121.87577","0.00000"
"196.70000","6.55375","1220.18433","0.06554","122.01843","0.00000"
"197.40000","6.57706","1221.33362","0.06577","122.13336","0.00001"
"198.10000","6.60038","1222.55713","0.06600","122.25571","0.00000"
"198.80000","6.62378","1223.78442","0.06624","122.37844","0.00000"
"199.50000","6.64713","1225.01135","0.06647","122.50114","0.00000"
"200.20000","6.67049","1226.21387","0.06670","122.62138","0.00000"
"200.90000","6.69382","1227.42407","0.06694","122.74241","0.00000"
"201.60000","6.71710","1228.47583","0.06717","122.84758","0.00000"
"202.30000","6.74046","1229.60352","0.06740","122.96035","0.00000"
"203.00000","6.76387","1231.12415","0.06764","123.11241","0.00000"
"203.70000","6.78725","1232.48096","0.06787","123.24809","0.00001"
"204.40000","6.81061","1233.72437","0.06811","123.37244","0.00000"
"205.10000","6.83388","1235.02478","0.06834","123.50248","0.00000"
"205.80000","6.85726","1236.27332","0.06857","123.62733","0.00000"
"206.50000","6.88047","1237.22827","0.06880","123.72282","0.00000"
"207.20000","6.90379","1238.71106","0.06904","123.87111","0.00000"
"207.90000","6.92711","1239.71692","0.06927","123.97169","0.00000"
"208.60000","6.95042","1241.10815","0.06950","124.11082","0.00000"
"209.30000","6.97386","1242.39417","0.06974","124.23942","0.00000"
"210.00000","6.99720","1243.62097","0.06997","124.36210","0.00000"
"210.70000","7.02057","1244.84302","0.07021","124.48430","0.00001"
"211.40000","7.04403","1246.30225","0.07044","124.63023","0.00001"
"212.10000","7.06730","1247.31665","0.07067","124.73167","0.00000"
"212.80000","7.09054","1248.24561","0.07091","124.82456","0.00000"
"213.50000","7.11379","1248.97888","0.07114","124.89789","0.00000"
"214.20000","7.13708","1250.15161","0.07137","125.01516","0.00000"
"214.90000","7.16047","1251.24622","0.07160","125.12462","0.00000"
"215.60000","7.18379","1252.44385","0.07184","125.24438","0.00000"
"216.30000","7.20709","1253.43103","0.07207","125.34310","0.00000"
"217.00000","7.23047","1254.74768","0.07230","125.47477","0.00000"
"217.70000","7.25370","1255.63733","0.07254","125.56374","0.00000"
"218.40000","7.27707","1257.15869","0.07277","125.71587","0.00000"
"219.10000","7.30041","1258.23779","0.07300","125.82378","0.00000"
"219.80000","7.32372","1259.56543","0.07324","125.95654","0.00000"
"220.50000","7.34711","1260.87256","0.07347","126.08726","0.00001"
"221.20000","7.37047","1262.17236","0.07370","126.21724","0.00000"
"221.90000","7.39383","1263.48193","0.07394","126.34819","0.00000"
"222.60000","7.41713","1264.58008","0.07417","126.45801","0.00000"
"223.30000","7.44045","1265.78113","0.07440","126.57811","0.00001"
"224.00000","7.46379","1266.94836","0.07464","126.69484","0.00000"
"224.70000","7.48721","1268.33630","0.07487","126.83363","0.00000"
"225.40000","7.51059","1269.57715","0.07511","126.95772","0.00000"
"226.10000","7.53395","1270.82703","0.07534","127.08270","0.00001"
"226.80000","7.55722","1271.85559","0.07557","127.18556","0.00000"
"227.50000","7.58059","1273.16187","0.07581","127.31618","0.00000"
"228.20000","7.60382","1274.17078","0.07604","127.41708","0.00000"
"228.90000","7.62711","1275.33752","0.07627","127.53375","0.00000"
"229.60000","7.65043","1276.47681","0.07650","127.64768","0.00000"
"230.30000","7.67378","1277.87939","0.07674","127.78794","0.00000"
"231.00000","7.69719","1279.08508","0.07697","127.90851","0.00000"
"231.70000","7.72058","1280.48755","0.07721","128.04875","0.00001"
"232.40000","7.74391","1281.77905","0.07744","128.17790","0.00001"
"233.10000","7.76737","1283.36462","0.07767","128.33646","0.00000"
"233.80000","7.79061","1284.64880","0.07791","128.46487","0.00000"
"234.50000","7.81386","1285.88904","0.07814","128.58890","0.00001"
"235.20000","7.83711","1287.09631","0.07837","128.70963","0.00000"
"235.90000","7.86043","1288.53650","0.07860","128.85365","0.00000"
"236.60000","7.88380","1289.90991","0.07884","128.99100","0.00000"
"237.30000","7.90713","1291.39673","0.07907","129.13968","0.00001"
"238.00000","7.93042","1292.76453","0.07930","129.27646","0.00000"
"238.70000","7.95378","1294.06848","0.07954","129.40685","0.00000"
"239.40000","7.97705","1295.34985","0.07977","129.53499","0.00000"
"240.10000","8.00043","1296.88904","0.08000","129.68890","0.00001"
"240.80000","8.02370","1298.08704","0.08024","129.80870","0.00000"
"241.50000","8.04706","1299.70569","0.08047","129.97057","0.00000"
"242.20000","8.07047","1301.20618","0.08070","130.12062","0.00000"
"242.90000","8.09380","1302.52173","0.08094","130.25217","0.00000"
"243.60000","8.11717","1303.88477","0.08117","130.38847","0.00000"
"244.30000","8.14044","1305.02173","0.08140","130.50217","0.00000"
"245.00000","8.16379","1306.42542","0.08164","130.64255","0.00000"
"245.70000","8.18713","1307.78516","0.08187","130.77852","0.00000"
"246.40000","8.21057","1309.41443","0.08211","130.94144","0.00001"
"247.10000","8.23393","1310.75256","0.08234","131.07526","0.00000"
"247.80000","8.25732","1312.28394","0.08257","131.22839","0.00000"
"248.50000","8.28054","1313.51379","0.08281","131.35138","0.00001"
"249.20000","8.30393","1314.64233","0.08304","131.46423","0.00001"
"249.90000","8.32713","1315.91455","0.08327","131.59146","0.00000"
"250.60000","8.35041","1317.04846","0.08350","131.70485","0.00000"
"251.30000","8.37377","1318.51929","0.08374","131.85193","0.00000"
"252.00000","8.39712","1319.86670","0.08397","131.98666","0.00000"
"252.70000","8.42054","1321.39246","0.08421","132.13925","0.00000"
"253.40000","8.44392","1322.61816","0.08444","132.26181","0.00000"
"254.10000","8.46726","1323.90613","0.08467","132.39061","0.00000"
"254.80000","8.49068","1325.14587","0.08491","132.51459","0.00001"
"255.50000","8.51393","1326.42432","0.08514","132.64243","0.00000"
"256.20000","8.53715","1327.39392","0.08537","132.73940","0.00000"
"256.90000","8.56042","1328.37402","0.08560","132.83740","0.00000"
"257.60000","8.58377","1329.79944","0.08584","132.97995","0.00000"
"258.30000","8.60716","1331.23828","0.08607","133.12383","0.00000"
"259.00000","8.63045","1332.41760","0.08630","133.24176","0.00000"
"259.70000","8.65376","1333.72327","0.08654","133.37233","0.00000"
"260.40000","8.67709","1334.83545","0.08677","133.48355","0.00000"
"261.10000","8.70038","1335.89783","0.08700","133.58978","0.00000"
"261.80000","8.72374","1337.19653","0.08724","133.71965","0.00000"
"262.50000","8.74705","1338.50146","0.08747","133.85014","0.00000"
"263.20000","8.77038","1339.93970","0.08770","133.99397","0.00000"
"263.90000","8.79381","1341.14673","0.08794","134.11467","0.00000"
"264.60000","8.81714","1342.47424","0.08817","134.24742","0.00000"
"265.30000","8.84051","1343.74744","0.08841","134.37474","0.00000"
"266.00000","8.86379","1344.94641","0.08864","134.49464","0.00000"
"266.70000","8.88712","1346.23987","0.08887","134.62399","0.00000"
"267.40000","8.91048","1347.46936","0.08910","134.74693","0.00000"
"268.10000","8.93390","1348.96558","0.08934","134.89656","0.00000"
"268.80000","8.95728","1350.28259","0.08957","135.02826","0.00000"
"269.50000","8.98066","1351.67432","0.08981","135.16743","0.00000"
"270.20000","9.00389","1352.94092","0.09004","135.29410","0.00000"
"270.90000","9.02722","1354.16663","0.09027","135.41666","0.00000"
"271.60000","9.05044","1355.39294","0.09050","135.53929","0.00000"
"272.30000","9.07375","1356.63220","0.09074","135.66322","0.00000"
"273.00000","9.09711","1358.22375","0.09097","135.82237","0.00000"
"273.70000","9.12048","1359.76746","0.09120","135.97675","0.00000"
"274.40000","9.14391","1361.43042","0.09144","136.14304","0.00000"
"275.10000","9.16725","1362.72754","0.09167","136.27275","0.00000"
"275.80000","9.19059","1364.37122","0.09191","136.43712","0.00000"
"276.50000","9.21402","1366.12402","0.09214","136.61240","0.00000"
"277.20000","9.23727","1367.39807","0.09237","136.73981","0.00000"
"277.90000","9.26047","1368.72327","0.09260","136.87233","0.00000"
"278.60000","9.28375","1370.03064","0.09284","137.00307","0.00001"
"279.30000","9.30706","1371.59192","0.09307","137.15919","0.00000"
"280.00000","9.33049","1373.13794","0.09330","137.31380","0.00000"
"280.70000","9.35379","1374.66663","0.09354","137.46666","0.00000"
"281.40000","9.37711","1376.07031","0.09377","137.60703","0.00000"
"282.10000","9.40045","1377.60132","0.09400","137.76013","0.00000"
"282.80000","9.42370","1379.20081","0.09424","137.92007","0.00000"
"283.50000","9.44709","1380.73242","0.09447","138.07324","0.00000"
"284.20000","9.47038","1382.02954","0.09470","138.20296","0.00001"
"284.90000","9.49374","1383.80823","0.09494","138.38083","0.00000"
"285.60000","9.51714","1385.48206","0.09517","138.54820","0.00000"
"286.30000","9.54048","1386.98279","0.09540","138.69827","0.00000"
"287.00000","9.56382","1388.44519","0.09564","138.84451","0.00000"
"287.70000","9.58712","1389.87561","0.09587","138.98756","0.00000"
"288.40000","9.61046","1391.27478","0.09610","139.12747","0.00000"
"289.10000","9.63382","1392.74426","0.09634","139.27443","0.00000"
"289.80000","9.65722","1394.36877","0.09657","139.43687","0.00000"
"290.50000","9.68064","1396.03113","0.09681","139.60312","0.00000"
"291.20000","9.70397","1397.33911","0.09704","139.73392","0.00000"
"291.90000","9.72723","1398.59790","0.09727","139.85979","0.00000"
"292.60000","9.75055","1399.94128","0.09751","139.99413","0.00001"
"293.30000","9.77379","1401.05054","0.09774","140.10506","0.00000"
"294.00000","9.79708","1402.34973","0.09797","140.23497","0.00000"
"294.70000","9.82044","1403.58838","0.09820","140.35884","0.00000"
"295.40000","9.84381","1404.95789","0.09844","140.49579","0.00000"
"296.10000","9.86728","1406.61902","0.09867","140.66190","0.00000"
"296.80000","9.89062","1407.99475","0.09891","140.79947","0.00000"
"297.50000","9.91393","1409.15955","0.09914","140.91595","0.00000"
"298.20000","9.93734","1410.75537","0.09937","141.07553","0.00000"
"298.90000","9.96059","1412.04419","0.09961","141.20442","0.00001"
"299.60000","9.98381","1413.14563","0.09984","141.31456","0.00000"
"300.30000","10.00709","1414.30237","0.10007","141.43024","0.00000"
"301.00000","10.03044","1415.89368","0.10030","141.58937","0.00000"
"301.70000","10.05381","1417.20605","0.10054","141.72061","0.00000"
"302.40000","10.07714","1418.70007","0.10077","141.87001","0.00000"
"303.10000","10.10042","1420.06213","0.10100","142.00621","0.00000"
"303.80000","10.12378","1421.57166","0.10124","142.15717","0.00000"
"304.50000","10.14702","1422.72363","0.10147","142.27237","0.00000"
"305.20000","10.17044","1424.37000","0.10170","142.43700","0.00000"
"305.90000","10.19372","1425.70789","0.10194","142.57079","0.00000"
"306.60000","10.21708","1427.18518","0.10217","142.71852","0.00000"
"307.30000","10.24047","1428.73511","0.10240","142.87350","0.00000"
"308.00000","10.26379","1430.16724","0.10264","143.01672","0.00001"
"308.70000","10.28717","1431.55408","0.10287","143.15541","0.00000"
"309.40000","10.31045","1433.10864","0.10310","143.31087","0.00000"
"310.10000","10.33377","1434.26990","0.10334","143.42699","0.00000"
"310.80000","10.35718","1435.92749","0.10357","143.59274","0.00001"
"311.50000","10.38058","1437.68298","0.10381","143.76830","0.00000"
"312.20000","10.40397","1439.16882","0.10404","143.91689","0.00000"
"312.90000","10.42728","1440.62830","0.10427","144.06284","0.00000"
"313.60000","10.45057","1441.95264","0.10451","144.19527","0.00001"
"314.30000","10.47388","1443.55298","0.10474","144.35530","0.00000"
"315.00000","10.49710","1444.84949","0.10497","144.48495","0.00000"
"315.70000","10.52044","1446.41321","0.10520","144.64133","0.00000"
"316.40000","10.54379","1447.89819","0.10544","144.78983","0.00000"
"317.10000","10.56714","1449.55200","0.10567","144.95520","0.00000"
"317.80000","10.59057","1451.01221","0.10591","145.10123","0.00000"
"318.50000","10.61397","1452.61475","0.10614","145.26147","0.00000"
"319.20000","10.63723","1454.06189","0.10637","145.40619","0.00000"
"319.90000","10.66065","1455.82349","0.10661","145.58235","0.00000"
"320.60000","10.68389","1457.13757","0.10684","145.71376","0.00000"
"321.30000","10.70712","1458.46423","0.10707","145.84642","0.00000"
"322.00000","10.73040","1459.99548","0.10730","145.99954","0.00000"
"322.70000","10.75377","1461.54749","0.10754","146.15475","0.00000"
"323.40000","10.77715","1463.22888","0.10777","146.32289","0.00000"
"324.10000","10.80048","1464.74500","0.10800","146.47450","0.00000"
"324.80000","10.82375","1466.07861","0.10824","146.60786","0.00001"
"325.50000","10.84711","1467.58484","0.10847","146.75848","0.00001"
"326.20000","10.87036","1469.01184","0.10870","146.90118","0.00000"
"326.90000","10.89376","1470.72595","0.10894","147.07260","0.00000"
"327.60000","10.91705","1472.30811","0.10917","147.23080","0.00001"
"328.30000","10.94044","1474.03906","0.10940","147.40390","0.00001"
"329.00000","10.96380","1475.68811","0.10964","147.56882","0.00000"
"329.70000","10.98717","1477.37708","0.10987","147.73770","0.00000"
"330.40000","11.01049","1479.08960","0.11010","147.90897","0.00000"
"331.10000","11.03380","1480.60132","0.11034","148.06013","0.00000"
"331.80000","11.05712","1482.37561","0.11057","148.23756","0.00000"
"332.50000","11.08049","1484.10132","0.11080","148.41013","0.00000"
"333.20000","11.10393","1486.12488","0.11104","148.61249","0.00000"
"333.90000","11.12730","1487.84033","0.11127","148.78403","0.00001"
"334.60000","11.15062","1489.63098","0.11151","148.96310","0.00000"
"335.30000","11.17388","1491.26965","0.11174","149.12697","0.00000"
"336.00000","11.19721","1493.09680","0.11197","149.30968","0.00000"
"336.70000","11.22039","1494.57068","0.11220","149.45706","0.00000"
"337.40000","11.24380","1496.45032","0.11244","149.64503","0.00000"
"338.10000","11.26715","1498.27954","0.11267","149.82796","0.00000"
"338.80000","11.29051","1500.08203","0.11291","150.00821","0.00000"
"339.50000","11.31391","1501.85254","0.11314","150.18526","0.00001"
"340.20000","11.33728","1503.57129","0.11337","150.35713","0.00001"
"340.90000","11.36055","1505.18237","0.11361","150.51823","0.00000"
"341.60000","11.38398","1507.00745","0.11384","150.70074","0.00000"
"342.30000","11.40721","1508.54395","0.11407","150.85440","0.00001"
"343.00000","11.43047","1510.07263","0.11430","151.00726","0.00001"
"343.70000","11.45377","1511.59229","0.11454","151.15923","0.00000"
"344.40000","11.47712","1513.26135","0.11477","151.32614","0.00000"
"345.10000","11.50049","1514.96692","0.11500","151.49669","0.00000"
"345.80000","11.52380","1516.45557","0.11524","151.64555","0.00000"
"346.50000","11.54707","1517.94641","0.11547","151.79465","0.00000"
"347.20000","11.57041","1519.70862","0.11570","151.97086","0.00000"
"347.90000","11.59369","1521.15833","0.11594","152.11583","0.00000"
"348.60000","11.61708","1522.91736","0.11617","152.29173","0.00000"
"349.30000","11.64041","1524.73779","0.11640","152.47379","0.00000"
"350.00000","11.66375","1526.37512","0.11664","152.63751","0.00000"
"350.70000","11.68713","1528.08374","0.11687","152.80838","0.00000"
"351.40000","11.71047","1529.71655","0.11710","152.97165","0.00000"
"352.10000","11.73384","1531.29199","0.11734","153.12920","0.00001"
"352.80000","11.75712","1533.02136","0.11757","153.30214","0.00000"
"353.50000","11.78048","1534.62354","0.11780","153.46236","0.00000"
"354.20000","11.80385","1536.47778","0.11804","153.64778","0.00000"
"354.90000","11.82727","1538.20837","0.11827","153.82083","0.00001"
"355.60000","11.85063","1539.79309","0.11851","153.97931","0.00000"
"356.30000","11.87393","1541.24146","0.11874","154.12415","-0.00001"
"357.00000","11.89721","1542.83044","0.11897","154.28305","0.00000"
"357.70000","11.92054","1544.43921","0.11921","154.44392","0.00000"
"358.40000","11.94376","1545.91284","0.11944","154.59128","0.00000"
"359.10000","11.96712","1547.57642","0.11967","154.75764","0.00003"
"359.80000","11.99049","1549.33496","0.11990","154.93350","0.00001"
"360.50000","12.01386","1550.85474","0.12014","155.08548","0.00002"
"361.20000","12.03726","1552.59644","0.12037","155.25964","0.00000"
"361.90000","12.06058","1554.10559","0.12061","155.41055","0.00000"
"362.60000","12.08391","1555.70605","0.12084","155.57060","0.00000"
"363.30000","12.10727","1557.34192","0.12107","155.73419","0.00000"
"364.00000","12.13054","1558.78491","0.12131","155.87849","0.00000"
"364.70000","12.15377","1560.11951","0.12154","156.01195","0.00001"
"365.40000","12.17709","1561.62671","0.12177","156.16267","0.00001"
"366.10000","12.20045","1563.24426","0.12200","156.32443","0.00001"
"366.80000","12.22380","1564.80115","0.12224","156.48012","0.00000"
"367.50000","12.24714","1566.39111","0.12247","156.63911","0.00000"
"368.20000","12.27040","1567.82495","0.12270","156.78250","0.00000"
"368.90000","12.29377","1569.42236","0.12294","156.94223","0.00000"
"369.60000","12.31704","1570.83826","0.12317","157.08383","0.00000"
"370.30000","12.34044","1572.53333","0.12340","157.25333","0.00000"
"371.00000","12.36374","1574.08057","0.12364","157.40805","0.00000"
"371.70000","12.38707","1575.65906","0.12387","157.56590","0.00001"
"372.40000","12.41047","1577.31775","0.12410","157.73178","0.00001"
"373.10000","12.43379","1578.73315","0.12434","157.87332","0.00000"
"373.80000","12.45717","1580.60522","0.12457","158.06052","0.00000"
"374.50000","12.48045","1582.08142","0.12480","158.20815","0.00000"
"375.20000","12.50382","1583.78516","0.12504","158.37851","0.00000"
"375.90000","12.52720","1585.38599","0.12527","158.53860","0.00000"
"376.60000","12.55062","1587.13513","0.12551","158.71352","0.00000"
"377.30000","12.57398","1588.64819","0.12574","158.86482","0.00000"
"378.00000","12.59723","1590.09692","0.12597","159.00969","0.00000"
"378.70000","12.62054","1591.79565","0.12621","159.17957","0.00000"
"379.40000","12.64384","1593.37366","0.12644","159.33737","0.00000"
"380.10000","12.66710","1594.87048","0.12667","159.48705","0.00001"
"380.80000","12.69045","1596.62048","0.12690","159.66205","0.00001"
"381.50000","12.71384","1598.45972","0.12714","159.84598","0.00000"
"382.20000","12.73720","1600.28577","0.12737","160.02858","0.00000"
"382.90000","12.76061","1602.36060","0.12761","160.23605","0.00000"
"383.60000","12.78392","1603.92017","0.12784","160.39201","0.00000"
"384.30000","12.80721","1605.60901","0.12807","160.56090","0.00000"
"385.00000","12.83058","1607.30505","0.12831","160.73050","0.00000"
"385.70000","12.85382","1608.74597","0.12854","160.87460","0.00000"
"386.40000","12.87713","1610.62866","0.12877","161.06287","0.00001"
"387.10000","12.90042","1612.11084","0.12900","161.21109","0.00001"
"387.80000","12.92378","1613.95972","0.12924","161.39597","0.00000"
"388.50000","12.94715","1615.54370","0.12947","161.55437","0.00000"
"389.20000","12.97046","1617.20959","0.12970","161.72096","0.00001"
"389.90000","12.99374","1618.75928","0.12994","161.87593","0.00000"
"390.60000","13.01710","1620.24255","0.13017","162.02426","0.00000"
"391.30000","13.04037","1621.57532","0.13040","162.15753","0.00000"
"392.00000","13.06380","1623.22375","0.13064","162.32237","0.00001"
"392.70000","13.08710","1624.75562","0.13087","162.47556","0.00000"
"393.40000","13.11043","1626.28113","0.13110","162.62811","0.00000"
"394.10000","13.13378","1627.77307","0.13134","162.77731","0.00000"
"394.80000","13.15716","1629.43921","0.13157","162.94392","0.00000"
"395.50000","13.18047","1631.03308","0.13180","163.10330","0.00000"
"396.20000","13.20379","1632.48499","0.13204","163.24850","0.00000"
"396.90000","13.22715","1634.28784","0.13227","163.42879","0.00000"
"397.60000","13.25056","1635.91370","0.13251","163.59137","0.00001"
"398.30000","13.27398","1637.90662","0.13274","163.79066","0.00000"
"399.00000","13.29732","1639.57202","0.13297","163.95720","0.00000"
"399.70000","13.32055","1641.00403","0.13321","164.10040","0.00000"
"400.40000","13.34387","1642.61084","0.13344","164.26108","0.00000"
"401.10000","13.36718","1644.16101","0.13367","164.41611","0.00001"
"401.80000","13.39044","1645.46484","0.13390","164.54648","0.00000"
"402.50000","13.41380","1646.99890","0.13414","164.69989","0.00000"
"403.20000","13.43723","1648.62781","0.13437","164.86278","0.00000"
"403.90000","13.46052","1650.14307","0.13461","165.01431","0.00001"
"404.60000","13.48394","1651.76111","0.13484","165.17612","0.00000"
"405.30000","13.50724","1653.20056","0.13507","165.32005","0.00000"
"406.00000","13.53055","1654.43481","0.13531","165.44348","0.00000"
"406.70000","13.55391","1655.83716","0.13554","165.58371","0.00000"
"407.40000","13.57718","1657.11682","0.13577","165.71169","0.00000"
"408.10000","13.60046","1658.55127","0.13600","165.85513","0.00000"
"408.80000","13.62377","1659.82190","0.13624","165.98219","0.00000"
"409.50000","13.64713","1661.29675","0.13647","166.12967","0.00000"
"410.20000","13.67048","1662.73486","0.13670","166.27348","0.00000"
"410.90000","13.69380","1664.17029","0.13694","166.41702","0.00000"
"411.60000","13.71705","1665.51843","0.13717","166.55185","0.00000"
"412.30000","13.74044","1667.03235","0.13740","166.70323","0.00001"
"413.00000","13.76371","1668.17139","0.13764","166.81714","0.00000"
"413.70000","13.78712","1669.61304","0.13787","166.96130","0.00000"
"414.40000","13.81042","1670.78577","0.13810","167.07858","0.00000"
"415.10000","13.83375","1672.23682","0.13834","167.22368","0.00000"
"415.80000","13.85711","1673.55896","0.13857","167.35590","0.00000"
"416.50000","13.88046","1674.92944","0.13880","167.49295","0.00000"
"417.20000","13.90381","1676.24744","0.13904","167.62474","0.00000"
"417.90000","13.92714","1677.41174","0.13927","167.74118","0.00000"
"418.60000","13.95049","1678.67395","0.13950","167.86740","0.00000"
"419.30000","13.97395","1680.15283","0.13974","168.01529","0.00000"
"420.00000","13.99727","1681.33374","0.13997","168.13338","0.00000"
"420.70000","14.02060","1682.58081","0.14021","168.25809","0.00000"
"421.40000","14.04386","1683.90906","0.14044","168.39090","0.00000"
"422.10000","14.06720","1685.04993","0.14067","168.50499","0.00000"
"422.80000","14.09052","1686.43445","0.14091","168.64345","0.00000"
"423.50000","14.11377","1687.27612","0.14114","168.72762","0.00000"
"424.20000","14.13715","1688.84583","0.14137","168.88458","0.00000"
"424.90000","14.16055","1690.17871","0.14161","169.01787","0.00000"
"425.60000","14.18388","1691.53564","0.14184","169.15356","0.00000"
"426.30000","14.20726","1692.91382","0.14207","169.29138","-0.00001"
"427.00000","14.23055","1694.12305","0.14231","169.41231","0.00000"
"427.70000","14.25384","1695.27417","0.14254","169.52742","0.00001"
"428.40000","14.27723","1696.43103","0.14277","169.64310","0.00000"
"429.10000","14.30049","1697.43286","0.14300","169.74329","0.00000"
"429.80000","14.32379","1698.66284","0.14324","169.86629","0.00000"
"430.50000","14.34711","1699.72632","0.14347","169.97263","0.00001"
"431.20000","14.37046","1700.84167","0.14370","170.08417","0.00000"
"431.90000","14.39379","1701.84119","0.14394","170.18411","0.00000"
"432.60000","14.41711","1702.71643","0.14417","170.27164","0.00001"
"433.30000","14.44040","1703.53467","0.14440","170.35347","0.00000"
"434.00000","14.46378","1704.64270","0.14464","170.46426","0.00000"
"434.70000","14.48704","1705.55933","0.14487","170.55594","-0.00001"
"435.40000","14.51047","1706.59106","0.14510","170.65910","0.00000"
"436.10000","14.53376","1707.46985","0.14534","170.74698","0.00000"
"436.80000","14.55710","1708.45227","0.14557","170.84523","0.00000"
"437.50000","14.58045","1709.39673","0.14580","170.93967","-0.00001"
"438.20000","14.60379","1710.38171","0.14604","171.03818","0.00000"
"438.90000","14.62718","1711.33765","0.14627","171.13376","0.00001"
"439.60000","14.65048","1712.02454","0.14650","171.20245","0.00000"
"440.30000","14.67386","1713.13123","0.14674","171.31313","-0.00001"
"441.00000","14.69723","1714.19153","0.14697","171.41916","0.00000"
"441.70000","14.72064","1715.34900","0.14721","171.53490","0.00001"
"442.40000","14.74393","1716.21802","0.14744","171.62180","0.00000"
"443.10000","14.76718","1716.94043","0.14767","171.69405","0.00000"
"443.80000","14.79052","1717.75110","0.14791","171.77512","0.00000"
"444.50000","14.81384","1718.55090","0.14814","171.85509","0.00000"
"445.20000","14.83711","1719.24622","0.14837","171.92462","0.00000"
"445.90000","14.86051","1720.34277","0.14861","172.03427","0.00000"
"446.60000","14.88387","1721.11780","0.14884","172.11179","0.00000"
"447.30000","14.90722","1721.93738","0.14907","172.19374","0.00000"
"448.00000","14.93061","1722.66174","0.14931","172.26617","0.00000"
"448.70000","14.95385","1723.13342","0.14954","172.31334","0.00000"
"449.40000","14.97716","1723.83276","0.14977","172.38327","0.00000"
"450.10000","15.00057","1724.35510","0.15001","172.43552","-0.00001"
"450.80000","15.02379","1724.72937","0.15024","172.47293","0.00000"
"451.50000","15.04714","1725.30322","0.15047","172.53032","0.00001"
"452.20000","15.07044","1725.43457","0.15070","172.54346","0.00000"
"452.90000","15.09378","1725.55273","0.15094","172.55527","0.00000"
"453.60000","15.11712","1725.93872","0.15117","172.59387","0.00000"
"454.30000","15.14045","1726.34570","0.15140","172.63457","0.00000"
"455.00000","15.16373","1726.70703","0.15164","172.67070","0.00000"
"455.70000","15.18711","1726.76782","0.15187","172.67679","-0.00001"
"456.40000","15.21039","1727.05042","0.15210","172.70505","0.00000"
"457.10000","15.23382","1726.84094","0.15234","172.68410","0.00000"
"457.80000","15.25709","1726.40198","0.15257","172.64020","0.00000"
"458.50000","15.28043","1725.52600","0.15280","172.55260","0.00000"
"459.20000","15.30379","1722.93298","0.15304","172.29330","0.00000"
"459.90000","15.32713","1719.15369","0.15327","171.91537","0.00001"
"460.60000","15.35048","1707.76624","0.15350","170.77663","0.00001"
"461.03600","15.36500","1226.48120","0.15365","122.64812","0.00001"
"461.04100","15.36520","990.01440","0.15365","99.00144","0.00000"