File: Tension/Section_2_Group_2/hybrid_high_Sample_2.is_tens_RawData/Specimen_RawData_1.csv
Time,Extension,Load,Tensile strain (Extension),Tensile stress,Strain-by-clip-gage
(s),(mm),(N),(mm/mm),(MPa),(mm/mm)
"0.00000","0.00000","918.96906","0.00000","91.89690","0.00013"
"0.30000","0.00740","977.84216","0.00007","97.78422","0.00010"
"0.60000","0.01760","1057.48254","0.00018","105.74825","0.00009"
"0.90000","0.02761","1133.27771","0.00028","113.32777","0.00013"
"1.20000","0.03772","1207.44434","0.00038","120.74443","0.00012"
"1.50000","0.04755","1276.83020","0.00048","127.68302","0.00007"
"1.80000","0.05777","1347.97363","0.00058","134.79736","0.00010"
"2.10000","0.06770","1415.04785","0.00068","141.50479","0.00015"
"2.40000","0.07760","1478.99756","0.00078","147.89975","0.00011"
"2.70000","0.08753","1540.99255","0.00088","154.09926","0.00011"
"3.00000","0.09761","1600.81055","0.00098","160.08105","0.00010"
"3.30000","0.10760","1657.54980","0.00108","165.75497","0.00009"
"3.60000","0.11779","1713.42139","0.00118","171.34213","0.00007"
"3.90000","0.12765","1764.60034","0.00128","176.46004","0.00011"
"4.20000","0.13774","1816.34607","0.00138","181.63461","0.00014"
"4.50000","0.14764","1866.39966","0.00148","186.63997","0.00014"
"4.80000","0.15760","1916.25598","0.00158","191.62560","0.00008"
"5.10000","0.16754","1965.14893","0.00168","196.51489","0.00010"
"5.40000","0.17762","2014.95593","0.00178","201.49559","0.00011"
"5.70000","0.18769","2064.31958","0.00188","206.43196","0.00010"
"6.00000","0.19764","2112.87524","0.00198","211.28752","0.00011"
"6.30000","0.20763","2161.24634","0.00208","216.12463","0.00011"
"6.60000","0.21777","2211.28076","0.00218","221.12808","0.00009"
"6.90000","0.22764","2258.41772","0.00228","225.84177","0.00010"
"7.20000","0.23759","2306.60718","0.00238","230.66072","0.00012"
"7.50000","0.24760","2355.39990","0.00248","235.53999","0.00011"
"7.80000","0.25752","2402.99414","0.00258","240.29941","0.00009"
"8.10000","0.26771","2452.74219","0.00268","245.27422","0.00011"
"8.40000","0.27764","2500.37939","0.00278","250.03793","0.00011"
"8.70000","0.28766","2549.35352","0.00288","254.93535","0.00011"
"9.00000","0.29778","2598.95044","0.00298","259.89505","0.00011"
"9.30000","0.30767","2646.31543","0.00308","264.63153","0.00012"
"9.60000","0.31750","2692.99902","0.00317","269.29990","0.00009"
"9.90000","0.32761","2742.46338","0.00328","274.24634","0.00010"
"10.20000","0.33761","2791.20190","0.00338","279.12018","0.00012"
"10.50000","0.34773","2840.37329","0.00348","284.03732","0.00012"
"10.80000","0.35765","2887.68628","0.00358","288.76862","0.00009"
"11.10000","0.36775","2936.72070","0.00368","293.67206","0.00012"
"11.40000","0.37763","2983.70508","0.00378","298.37051","0.00012"
"11.70000","0.38764","3031.90210","0.00388","303.19022","0.00010"
"12.00000","0.39756","3078.58960","0.00398","307.85895","0.00010"
"12.30000","0.40761","3127.01416","0.00408","312.70142","0.00012"
"12.60000","0.41762","3174.73901","0.00418","317.47391","0.00011"
"12.90000","0.42776","3223.81934","0.00428","322.38193","0.00010"
"13.20000","0.43757","3269.09009","0.00438","326.90900","0.00011"
"13.50000","0.44775","3317.85840","0.00448","331.78583","0.00012"
"13.80000","0.45770","3364.42334","0.00458","336.44232","0.00010"
"14.10000","0.46757","3409.71509","0.00468","340.97150","0.00006"
"14.40000","0.47753","3455.77051","0.00478","345.57706","0.00007"
"14.70000","0.48765","3502.26270","0.00488","350.22626","0.00008"
"15.00000","0.49757","3546.72510","0.00498","354.67252","0.00011"
"15.30000","0.50770","3593.63770","0.00508","359.36377","0.00009"
"15.60000","0.51762","3638.13257","0.00518","363.81326","0.00009"
"15.90000","0.52777","3683.94629","0.00528","368.39462","0.00009"
"16.20000","0.53764","3726.59277","0.00538","372.65927","0.00012"
"16.50000","0.54763","3769.20020","0.00548","376.92001","0.00011"
"16.80000","0.55753","3811.03784","0.00558","381.10379","0.00011"
"17.10000","0.56762","3854.00977","0.00568","385.40097","0.00010"
"17.40000","0.57775","3896.60229","0.00578","389.66022","0.00012"
"17.70000","0.58764","3936.72437","0.00588","393.67242","0.00012"
"18.00000","0.59764","3978.16309","0.00598","397.81631","0.00010"
"18.30000","0.60775","4020.70557","0.00608","402.07056","0.00011"
"18.60000","0.61761","4060.36157","0.00618","406.03616","0.00012"
"18.90000","0.62754","4100.63281","0.00628","410.06329","0.00010"
"19.20000","0.63762","4142.43359","0.00638","414.24335","0.00010"
"19.50000","0.64757","4183.00000","0.00648","418.29999","0.00011"
"19.80000","0.65773","4225.52734","0.00658","422.55273","0.00011"
"20.10000","0.66768","4264.96436","0.00668","426.49643","0.00010"
"20.40000","0.67769","4305.17773","0.00678","430.51776","0.00011"
"20.70000","0.68766","4344.91357","0.00688","434.49136","0.00011"
"21.00000","0.69767","4384.97217","0.00698","438.49722","0.00010"
"21.30000","0.70753","4422.82861","0.00708","442.28287","0.00011"
"21.60000","0.71757","4462.25684","0.00718","446.22568","0.00011"
"21.90000","0.72761","4501.46777","0.00728","450.14679","0.00011"
"22.20000","0.73778","4541.71826","0.00738","454.17181","0.00010"
"22.50000","0.74761","4578.56934","0.00748","457.85693","0.00012"
"22.80000","0.75781","4618.66943","0.00758","461.86694","0.00011"
"23.10000","0.76766","4654.93018","0.00768","465.49301","0.00010"
"23.40000","0.77754","4691.38867","0.00778","469.13885","0.00011"
"23.70000","0.78755","4728.41895","0.00788","472.84189","0.00012"
"24.00000","0.79764","4766.14062","0.00798","476.61407","0.00010"
"24.30000","0.80769","4803.05420","0.00808","480.30542","0.00010"
"24.60000","0.81773","4839.89209","0.00818","483.98920","0.00012"
"24.90000","0.82768","4875.09912","0.00828","487.50992","0.00010"
"25.20000","0.83771","4910.62207","0.00838","491.06219","0.00010"
"25.50000","0.84767","4945.13477","0.00848","494.51349","0.00011"
"25.80000","0.85759","4978.88574","0.00858","497.88858","0.00011"
"26.10000","0.86753","5012.72070","0.00868","501.27206","0.00010"
"26.40000","0.87761","5047.91260","0.00878","504.79126","0.00011"
"26.70000","0.88772","5082.06934","0.00888","508.20694","0.00011"
"27.00000","0.89766","5114.55566","0.00898","511.45557","0.00011"
"27.30000","0.90768","5147.16748","0.00908","514.71674","0.00010"
"27.60000","0.91779","5180.80469","0.00918","518.08044","0.00012"
"27.90000","0.92762","5210.87256","0.00928","521.08728","0.00010"
"28.20000","0.93757","5241.70264","0.00938","524.17029","0.00010"
"28.50000","0.94758","5272.90186","0.00948","527.29016","0.00011"
"28.80000","0.95754","5303.40674","0.00958","530.34070","0.00011"
"29.10000","0.96778","5336.27881","0.00968","533.62787","0.00010"
"29.40000","0.97779","5365.61475","0.00978","536.56146","0.00011"
"29.70000","0.98770","5393.57275","0.00988","539.35730","0.00012"
"30.00000","0.99775","5423.91748","0.00998","542.39172","0.00011"
"30.30000","1.00762","5451.80225","0.01008","545.18024","0.00010"
"30.60000","1.01743","5478.50049","0.01017","547.85004","0.00011"
"30.90000","1.02761","5508.68701","0.01028","550.86871","0.00011"
"31.20000","1.03774","5538.33203","0.01038","553.83319","0.00010"
"31.50000","1.04776","5567.58447","0.01048","556.75842","0.00011"
"31.80000","1.05763","5594.74463","0.01058","559.47449","0.00011"
"32.10000","1.06774","5624.19873","0.01068","562.41986","0.00010"
"32.40000","1.07763","5651.05469","0.01078","565.10547","0.00011"
"32.70000","1.08760","5677.97021","0.01088","567.79700","0.00012"
"33.00000","1.09762","5705.41211","0.01098","570.54120","0.00010"
"33.30000","1.10760","5732.08105","0.01108","573.20813","0.00010"
"33.60000","1.11768","5759.47168","0.01118","575.94714","0.00011"
"33.90000","1.12773","5786.75439","0.01128","578.67542","0.00011"
"34.20000","1.13758","5811.39014","0.01138","581.13904","0.00010"
"34.50000","1.14780","5839.19141","0.01148","583.91913","0.00011"
"34.80000","1.15777","5863.69482","0.01158","586.36951","0.00011"
"35.10000","1.16757","5886.23486","0.01168","588.62347","0.00010"
"35.40000","1.17757","5909.90674","0.01178","590.99066","0.00010"
"35.70000","1.18758","5933.79395","0.01188","593.37939","0.00012"
"36.00000","1.19762","5956.96777","0.01198","595.69678","0.00011"
"36.30000","1.20774","5980.83105","0.01208","598.08313","0.00009"
"36.60000","1.21777","6002.35986","0.01218","600.23596","0.00011"
"36.90000","1.22770","6022.95898","0.01228","602.29590","0.00011"
"37.20000","1.23766","6042.56885","0.01238","604.25690","0.00011"
"37.50000","1.24754","6061.58203","0.01248","606.15820","0.00010"
"37.80000","1.25753","6081.35400","0.01258","608.13538","0.00011"
"38.10000","1.26760","6099.85938","0.01268","609.98596","0.00010"
"38.40000","1.27787","6117.28369","0.01278","611.72839","0.00010"
"38.70000","1.28756","6130.90283","0.01288","613.09027","0.00012"
"39.00000","1.29772","6150.05664","0.01298","615.00568","0.00011"
"39.30000","1.30764","6166.60889","0.01308","616.66089","0.00010"
"39.60000","1.31759","6183.22559","0.01318","618.32257","0.00011"
"39.90000","1.32754","6199.54346","0.01328","619.95435","0.00012"
"40.20000","1.33769","6216.89014","0.01338","621.68903","0.00010"
"40.50000","1.34755","6231.08350","0.01348","623.10834","0.00011"
"40.80000","1.35774","6249.02295","0.01358","624.90228","0.00012"
"41.10000","1.36757","6262.24365","0.01368","626.22437","0.00011"
"41.40000","1.37773","6277.83398","0.01378","627.78339","0.00010"
"41.70000","1.38769","6291.36621","0.01388","629.13660","0.00011"
"42.00000","1.39771","6304.86084","0.01398","630.48608","0.00012"
"42.30000","1.40752","6316.71094","0.01408","631.67108","0.00010"
"42.60000","1.41762","6331.41113","0.01418","633.14111","0.00011"
"42.90000","1.42763","6344.27002","0.01428","634.42700","0.00012"
"43.20000","1.43770","6357.79639","0.01438","635.77966","0.00011"
"43.50000","1.44766","6369.72949","0.01448","636.97296","0.00010"
"43.80000","1.45778","6383.51221","0.01458","638.35120","0.00012"
"44.10000","1.46766","6393.96289","0.01468","639.39630","0.00011"
"44.40000","1.47753","6405.10693","0.01478","640.51068","0.00010"
"44.70000","1.48753","6416.52295","0.01488","641.65228","0.00011"
"45.00000","1.49762","6429.35205","0.01498","642.93518","0.00012"
"45.30000","1.50775","6442.66846","0.01508","644.26685","0.00010"
"45.60000","1.51771","6454.16602","0.01518","645.41663","0.00010"
"45.90000","1.52763","6465.75928","0.01528","646.57593","0.00012"
"46.20000","1.53769","6478.68652","0.01538","647.86865","0.00011"
"46.50000","1.54759","6489.47119","0.01548","648.94714","0.00009"
"46.80000","1.55750","6499.52295","0.01557","649.95227","0.00011"
"47.10000","1.56761","6510.95898","0.01568","651.09589","0.00012"
"47.40000","1.57759","6517.49609","0.01578","651.74963","0.00010"
"47.70000","1.58777","6526.24756","0.01588","652.62476","0.00010"
"48.00000","1.59764","6493.60693","0.01598","649.36072","0.00012"
"48.30000","1.60762","6501.35645","0.01608","650.13562","0.00011"
"48.60000","1.61769","6514.16406","0.01618","651.41638","0.00010"
"48.90000","1.62766","6525.58057","0.01628","652.55804","0.00011"
"49.20000","1.63758","6536.03760","0.01638","653.60376","0.00011"
"49.50000","1.64763","6546.96533","0.01648","654.69653","0.00010"
"49.80000","1.65758","6556.74414","0.01658","655.67444","0.00011"
"50.10000","1.66771","6567.90674","0.01668","656.79065","0.00012"
"50.40000","1.67762","6575.76025","0.01678","657.57605","0.00010"
"50.70000","1.68774","6583.94092","0.01688","658.39410","0.00010"
"51.00000","1.69765","6588.52393","0.01698","658.85242","0.00012"
"51.30000","1.70767","6594.18701","0.01708","659.41870","0.00011"
"51.60000","1.71748","6597.63428","0.01717","659.76343","0.00010"
"51.90000","1.72757","6603.56445","0.01728","660.35645","0.00011"
"52.20000","1.73766","6608.59814","0.01738","660.85980","0.00012"
"52.50000","1.74777","6614.12305","0.01748","661.41229","0.00010"
"52.80000","1.75760","6616.62061","0.01758","661.66205","0.00010"
"53.10000","1.76780","6623.16846","0.01768","662.31683","0.00012"
"53.40000","1.77760","6625.69482","0.01778","662.56946","0.00011"
"53.70000","1.78754","6629.90527","0.01788","662.99054","0.00010"
"54.00000","1.79754","6634.80029","0.01798","663.48004","0.00011"
"54.30000","1.80760","6640.14746","0.01808","664.01477","0.00012"
"54.60000","1.81768","6646.18750","0.01818","664.61877","0.00010"
"54.90000","1.82781","6652.58594","0.01828","665.25861","0.00010"
"55.20000","1.83760","6655.11328","0.01838","665.51135","0.00012"
"55.50000","1.84767","6660.05518","0.01848","666.00549","0.00011"
"55.80000","1.85764","6663.84863","0.01858","666.38489","0.00010"
"56.10000","1.86758","6665.93311","0.01868","666.59332","0.00011"
"56.40000","1.87756","6667.32129","0.01878","666.73212","0.00011"
"56.70000","1.88766","6669.45361","0.01888","666.94537","0.00009"
"57.00000","1.89764","6669.71631","0.01898","666.97162","0.00011"
"57.30000","1.90759","6669.01562","0.01908","666.90155","0.00012"
"57.60000","1.91771","6669.20166","0.01918","666.92017","0.00009"
"57.90000","1.92765","6666.59033","0.01928","666.65906","0.00007"
"58.20000","1.93762","6664.05713","0.01938","666.40570","0.00014"
"58.50000","1.94762","6659.45264","0.01948","665.94525","0.00012"
"58.80000","1.95756","6653.03857","0.01958","665.30383","0.00011"
"59.10000","1.96756","6647.15674","0.01968","664.71570","0.00009"
"59.40000","1.97777","6643.98145","0.01978","664.39813","0.00012"
"59.70000","1.98758","6636.97998","0.01988","663.69800","0.00011"
"60.00000","1.99776","6634.64307","0.01998","663.46429","0.00010"
"60.30000","2.00774","6630.58398","0.02008","663.05841","0.00011"
"60.60000","2.01756","6625.64111","0.02018","662.56409","0.00011"
"60.90000","2.02747","6622.00293","0.02027","662.20032","0.00011"
"61.20000","2.03763","6621.42627","0.02038","662.14264","0.00012"
"61.50000","2.04762","6618.75928","0.02048","661.87592","0.00010"
"61.80000","2.05780","6618.99463","0.02058","661.89948","0.00012"
"62.10000","2.06769","6617.18701","0.02068","661.71869","0.00012"
"62.40000","2.07770","6617.18555","0.02078","661.71857","0.00011"
"62.70000","2.08764","6616.53711","0.02088","661.65369","0.00010"
"63.00000","2.09760","6615.94873","0.02098","661.59485","0.00011"
"63.30000","2.10753","6614.62939","0.02108","661.46295","0.00011"
"63.60000","2.11761","6613.06250","0.02118","661.30627","0.00010"
"63.90000","2.12773","6609.84082","0.02128","660.98407","0.00010"
"64.20000","2.13769","6603.61719","0.02138","660.36169","0.00011"
"64.50000","2.14762","6595.66309","0.02148","659.56628","0.00011"
"64.80000","2.15774","6588.64307","0.02158","658.86432","0.00010"
"65.10000","2.16765","6577.48633","0.02168","657.74866","0.00011"
"65.40000","2.17762","6565.16846","0.02178","656.51685","0.00011"
"65.70000","2.18761","6553.05029","0.02188","655.30505","0.00011"
"66.00000","2.19753","6539.47900","0.02198","653.94788","0.00011"
"66.30000","2.20772","6527.82764","0.02208","652.78278","0.00011"
"66.60000","2.21761","6514.12305","0.02218","651.41229","0.00011"
"66.90000","2.22773","6503.53857","0.02228","650.35388","0.00010"
"67.20000","2.23778","6495.20312","0.02238","649.52032","0.00011"
"67.50000","2.24764","6486.54639","0.02248","648.65466","0.00011"
"67.80000","2.25752","6479.11182","0.02258","647.91119","0.00010"
"68.10000","2.26758","6474.45605","0.02268","647.44562","0.00011"
"68.40000","2.27755","6470.19531","0.02278","647.01953","0.00011"
"68.70000","2.28778","6469.97559","0.02288","646.99756","0.00011"
"69.00000","2.29768","6466.40039","0.02298","646.64001","0.00010"
"69.30000","2.30774","6464.36377","0.02308","646.43640","0.00011"
"69.60000","2.31767","6460.86719","0.02318","646.08673","0.00011"
"69.90000","2.32765","6457.83008","0.02328","645.78302","0.00010"
"70.20000","2.33752","6453.16260","0.02338","645.31628","0.00011"
"70.50000","2.34761","6450.56738","0.02348","645.05676","0.00011"
"70.80000","2.35765","6447.17432","0.02358","644.71741","0.00011"
"71.10000","2.36771","6443.87744","0.02368","644.38776","0.00010"
"71.40000","2.37761","6438.29932","0.02378","643.82996","0.00011"
"71.70000","2.38776","6434.45264","0.02388","643.44525","0.00011"
"72.00000","2.39765","6425.01660","0.02398","642.50165","0.00010"
"72.30000","2.40767","6414.39648","0.02408","641.43964","0.00011"
"72.60000","2.41760","6400.22656","0.02418","640.02264","0.00011"
"72.90000","2.42754","6382.82617","0.02428","638.28259","0.00011"
"73.20000","2.43765","6363.69873","0.02438","636.36987","0.00010"
"73.50000","2.44770","6342.05273","0.02448","634.20526","0.00011"
"73.80000","2.45761","6319.15332","0.02458","631.91534","0.00011"
"74.10000","2.46783","6301.48291","0.02468","630.14832","0.00011"
"74.40000","2.47770","6281.45166","0.02478","628.14514","0.00011"
"74.70000","2.48753","6262.70264","0.02488","626.27026","0.00011"
"75.00000","2.49758","6247.74268","0.02498","624.77429","0.00011"
"75.30000","2.50761","6234.71533","0.02508","623.47156","0.00011"
"75.60000","2.51769","6223.80762","0.02518","622.38074","0.00012"
"75.90000","2.52772","6213.23975","0.02528","621.32397","0.00010"
"76.20000","2.53773","6204.11426","0.02538","620.41144","0.00010"
"76.50000","2.54770","6196.68701","0.02548","619.66870","0.00011"
"76.80000","2.55764","6189.47266","0.02558","618.94727","0.00011"
"77.10000","2.56755","6181.98682","0.02568","618.19867","0.00010"
"77.40000","2.57759","6175.78369","0.02578","617.57837","0.00011"
"77.70000","2.58762","6168.88428","0.02588","616.88843","0.00011"
"78.00000","2.59776","6163.95947","0.02598","616.39594","0.00011"
"78.30000","2.60756","6154.53223","0.02608","615.45325","0.00011"
"78.60000","2.61773","6148.00146","0.02618","614.80017","0.00011"
"78.90000","2.62774","6137.51758","0.02628","613.75177","0.00011"
"79.20000","2.63765","6123.51025","0.02638","612.35101","0.00010"
"79.50000","2.64755","6108.75049","0.02648","610.87506","0.00011"
"79.80000","2.65764","6095.10254","0.02658","609.51025","0.00011"
"80.10000","2.66754","6079.87402","0.02668","607.98743","0.00011"
"80.40000","2.67775","6067.31152","0.02678","606.73114","0.00011"
"80.70000","2.68760","6051.60352","0.02688","605.16034","0.00012"
"81.00000","2.69777","6038.78564","0.02698","603.87854","0.00010"
"81.30000","2.70769","6023.86816","0.02708","602.38684","0.00011"
"81.60000","2.71768","6011.14014","0.02718","601.11401","0.00011"
"81.90000","2.72748","5998.12109","0.02727","599.81213","0.00012"
"82.20000","2.73763","5990.00439","0.02738","599.00043","0.00011"
"82.50000","2.74769","5981.54639","0.02748","598.15466","0.00009"
"82.80000","2.75775","5975.23975","0.02758","597.52399","0.00013"
"83.10000","2.76765","5968.17041","0.02768","596.81702","0.00011"
"83.40000","2.77778","5964.79883","0.02778","596.47986","0.00010"
"83.70000","2.78758","5959.80420","0.02788","595.98041","0.00011"
"84.00000","2.79758","5957.20654","0.02798","595.72064","0.00012"
"84.30000","2.80757","5954.69336","0.02808","595.46936","0.00011"
"84.60000","2.81760","5954.09814","0.02818","595.40979","0.00011"
"84.90000","2.82769","5954.03857","0.02828","595.40387","0.00011"
"85.20000","2.83770","5952.44531","0.02838","595.24451","0.00010"
"85.50000","2.84767","5949.41650","0.02848","594.94165","0.00011"
"85.80000","2.85770","5946.47998","0.02858","594.64801","0.00011"
"86.10000","2.86765","5941.48438","0.02868","594.14844","0.00010"
"86.40000","2.87753","5934.42969","0.02878","593.44299","0.00011"
"86.70000","2.88757","5926.40771","0.02888","592.64075","0.00012"
"87.00000","2.89759","5917.96582","0.02898","591.79657","0.00011"
"87.30000","2.90776","5909.72559","0.02908","590.97253","0.00011"
"87.60000","2.91765","5898.13623","0.02918","589.81360","0.00011"
"87.90000","2.92774","5888.86475","0.02928","588.88647","0.00013"
"88.20000","2.93772","5877.93408","0.02938","587.79340","0.00010"
"88.50000","2.94760","5865.85449","0.02948","586.58545","0.00012"
"88.80000","2.95757","5855.25537","0.02958","585.52551","0.00011"
"89.10000","2.96759","5845.90527","0.02968","584.59052","0.00012"
"89.40000","2.97764","5836.47070","0.02978","583.64709","0.00010"
"89.70000","2.98781","5828.66162","0.02988","582.86615","0.00011"
"90.00000","2.99767","5817.13428","0.02998","581.71344","0.00011"
"90.30000","3.00773","5808.54346","0.03008","580.85437","0.00011"
"90.60000","3.01771","5800.92725","0.03018","580.09271","0.00011"
"90.90000","3.02762","5792.20850","0.03028","579.22083","0.00012"
"91.20000","3.03752","5785.01709","0.03038","578.50171","0.00011"
"91.50000","3.04760","5781.41455","0.03048","578.14148","0.00011"
"91.80000","3.05762","5777.48145","0.03058","577.74817","0.00011"
"92.10000","3.06772","5773.91602","0.03068","577.39160","0.00011"
"92.40000","3.07767","5768.45996","0.03078","576.84601","0.00010"
"92.70000","3.08783","5765.27246","0.03088","576.52722","0.00011"
"93.00000","3.09766","5760.25830","0.03098","576.02582","0.00012"
"93.30000","3.10763","5755.99121","0.03108","575.59912","0.00011"
"93.60000","3.11756","5750.43896","0.03118","575.04388","0.00010"
"93.90000","3.12751","5744.59863","0.03128","574.45984","0.00012"
"94.20000","3.13772","5741.08008","0.03138","574.10803","0.00012"
"94.50000","3.14775","5735.81445","0.03148","573.58142","0.00011"
"94.80000","3.15769","5729.94141","0.03158","572.99414","0.00011"
"95.10000","3.16784","5726.53809","0.03168","572.65381","0.00012"
"95.40000","3.17765","5719.16699","0.03178","571.91669","0.00010"
"95.70000","3.18745","5710.77979","0.03187","571.07800","0.00011"
"96.00000","3.19759","5703.61328","0.03198","570.36133","0.00010"
"96.30000","3.20772","5695.04102","0.03208","569.50409","0.00011"
"96.60000","3.21776","5685.56104","0.03218","568.55609","0.00011"
"96.90000","3.22762","5674.91553","0.03228","567.49158","0.00012"
"97.20000","3.23774","5667.16162","0.03238","566.71619","0.00012"
"97.50000","3.24766","5657.56689","0.03248","565.75671","0.00010"
"97.80000","3.25764","5648.93750","0.03258","564.89374","0.00011"
"98.10000","3.26761","5639.09229","0.03268","563.90924","0.00011"
"98.40000","3.27760","5630.54980","0.03278","563.05499","0.00011"
"98.70000","3.28762","5623.85156","0.03288","562.38513","0.00010"
"99.00000","3.29776","5620.13135","0.03298","562.01312","0.00012"
"99.30000","3.30761","5612.90479","0.03308","561.29047","0.00011"
"99.60000","3.31778","5610.08057","0.03318","561.00806","0.00011"
"99.90000","3.32778","5606.07568","0.03328","560.60754","0.00012"
"100.20000","3.33762","5602.17383","0.03338","560.21741","0.00011"
"100.50000","3.34757","5600.52002","0.03348","560.05200","0.00011"
"100.80000","3.35755","5600.87549","0.03358","560.08752","0.00011"
"101.10000","3.36757","5601.43115","0.03368","560.14313","0.00012"
"101.40000","3.37776","5603.71680","0.03378","560.37170","0.00011"
"101.70000","3.38778","5602.74512","0.03388","560.27454","0.00010"
"102.00000","3.39773","5601.44922","0.03398","560.14490","0.00012"
"102.30000","3.40768","5600.25537","0.03408","560.02551","0.00011"
"102.60000","3.41756","5596.91064","0.03418","559.69104","0.00011"
"102.90000","3.42748","5591.78125","0.03427","559.17810","0.00011"
"103.20000","3.43759","5586.46680","0.03438","558.64667","0.00011"
"103.50000","3.44785","5581.37695","0.03448","558.13770","0.00011"
"103.80000","3.45762","5571.03027","0.03458","557.10303","0.00011"
"104.10000","3.46768","5563.22217","0.03468","556.32220","0.00012"
"104.40000","3.47772","5554.13623","0.03478","555.41364","0.00011"
"104.70000","3.48759","5543.73242","0.03488","554.37323","0.00010"
"105.00000","3.49754","5534.17725","0.03498","553.41772","0.00011"
"105.30000","3.50767","5528.64502","0.03508","552.86450","0.00012"
"105.60000","3.51754","5522.34961","0.03518","552.23499","0.00010"
"105.90000","3.52775","5520.73535","0.03528","552.07355","0.00011"
"106.20000","3.53761","5516.95703","0.03538","551.69568","0.00012"
"106.50000","3.54767","5516.01514","0.03548","551.60150","0.00011"
"106.80000","3.55774","5517.33398","0.03558","551.73340","0.00011"
"107.10000","3.56775","5519.19971","0.03568","551.91998","0.00011"
"107.40000","3.57754","5518.37549","0.03578","551.83752","0.00012"
"107.70000","3.58760","5520.01611","0.03588","552.00159","0.00011"
"108.00000","3.59758","5520.32910","0.03598","552.03290","0.00011"
"108.30000","3.60773","5521.17920","0.03608","552.11792","0.00011"
"108.60000","3.61768","5519.07666","0.03618","551.90765","0.00011"
"108.90000","3.62780","5516.94873","0.03628","551.69489","0.00010"
"109.20000","3.63764","5510.33447","0.03638","551.03345","0.00011"
"109.50000","3.64760","5504.69287","0.03648","550.46930","0.00011"
"109.80000","3.65753","5498.10059","0.03658","549.81006","0.00011"
"110.10000","3.66757","5491.03711","0.03668","549.10370","0.00012"
"110.40000","3.67769","5483.86816","0.03678","548.38684","0.00011"
"110.70000","3.68779","5476.34326","0.03688","547.63434","0.00011"
"111.00000","3.69763","5466.68262","0.03698","546.66827","0.00011"
"111.30000","3.70779","5460.87500","0.03708","546.08752","0.00011"
"111.60000","3.71758","5451.06543","0.03718","545.10657","0.00011"
"111.90000","3.72756","5443.19873","0.03728","544.31989","0.00011"
"112.20000","3.73757","5435.19824","0.03738","543.51984","0.00011"
"112.50000","3.74765","5427.66797","0.03748","542.76678","0.00011"
"112.80000","3.75766","5419.51270","0.03758","541.95129","0.00010"
"113.10000","3.76766","5413.31299","0.03768","541.33130","0.00011"
"113.40000","3.77760","5406.69385","0.03778","540.66937","0.00011"
"113.70000","3.78776","5401.27148","0.03788","540.12714","0.00011"
"114.00000","3.79769","5393.94775","0.03798","539.39478","0.00011"
"114.30000","3.80762","5387.30420","0.03808","538.73041","0.00011"
"114.60000","3.81760","5382.20752","0.03818","538.22076","0.00011"
"114.90000","3.82754","5377.78369","0.03828","537.77838","0.00010"
"115.20000","3.83768","5375.13916","0.03838","537.51392","0.00011"
"115.50000","3.84766","5371.24902","0.03848","537.12488","0.00011"
"115.80000","3.85770","5369.03174","0.03858","536.90320","0.00011"
"116.10000","3.86767","5365.67920","0.03868","536.56793","0.00010"
"116.40000","3.87769","5362.08057","0.03878","536.20807","0.00012"
"116.70000","3.88748","5355.29883","0.03887","535.52991","0.00011"
"117.00000","3.89754","5350.57764","0.03898","535.05774","0.00011"
"117.30000","3.90761","5344.75928","0.03908","534.47595","0.00011"
"117.60000","3.91779","5339.00293","0.03918","533.90027","0.00011"
"117.90000","3.92756","5328.64111","0.03928","532.86414","0.00010"
"118.20000","3.93776","5322.67236","0.03938","532.26721","0.00011"
"118.50000","3.94764","5314.34131","0.03948","531.43414","0.00011"
"118.80000","3.95758","5305.74121","0.03958","530.57410","0.00011"
"119.10000","3.96752","5296.62305","0.03968","529.66229","0.00011"
"119.40000","3.97765","5289.07471","0.03978","528.90747","0.00012"
"119.70000","3.98761","5279.84717","0.03988","527.98474","0.00011"
"120.00000","3.99784","5274.50977","0.03998","527.45099","0.00011"
"120.30000","4.00757","5264.18262","0.04008","526.41827","0.00011"
"120.60000","4.01769","5257.26611","0.04018","525.72662","0.00011"
"120.90000","4.02765","5249.21631","0.04028","524.92163","0.00010"
"121.20000","4.03761","5241.91309","0.04038","524.19128","0.00011"
"121.50000","4.04757","5234.44434","0.04048","523.44446","0.00011"
"121.80000","4.05767","5229.51416","0.04058","522.95142","0.00011"
"122.10000","4.06761","5224.48145","0.04068","522.44812","0.00011"
"122.40000","4.07766","5221.12354","0.04078","522.11237","0.00012"
"122.70000","4.08765","5217.98633","0.04088","521.79865","0.00010"
"123.00000","4.09771","5216.37305","0.04098","521.63733","0.00010"
"123.30000","4.10763","5212.72266","0.04108","521.27228","0.00012"
"123.60000","4.11761","5209.67676","0.04118","520.96765","0.00012"
"123.90000","4.12754","5206.45508","0.04128","520.64551","0.00010"
"124.20000","4.13754","5204.04736","0.04138","520.40472","0.00011"
"124.50000","4.14776","5203.15723","0.04148","520.31573","0.00011"
"124.80000","4.15763","5196.56055","0.04158","519.65607","0.00011"
"125.10000","4.16767","5192.14697","0.04168","519.21472","0.00010"
"125.40000","4.17776","5189.49658","0.04178","518.94965","0.00011"
"125.70000","4.18758","5184.29004","0.04188","518.42902","0.00012"
"126.00000","4.19751","5178.57617","0.04198","517.85760","0.00010"
"126.30000","4.20761","5174.96631","0.04208","517.49664","0.00011"
"126.60000","4.21760","5170.24707","0.04218","517.02472","0.00011"
"126.90000","4.22778","5167.58838","0.04228","516.75885","0.00011"
"127.20000","4.23770","5162.95312","0.04238","516.29529","0.00010"
"127.50000","4.24769","5158.45508","0.04248","515.84552","0.00011"
"127.80000","4.25764","5152.90967","0.04258","515.29095","0.00011"
"128.10000","4.26761","5147.66895","0.04268","514.76691","0.00010"
"128.40000","4.27756","5142.25977","0.04278","514.22595","0.00011"
"128.70000","4.28764","5137.02637","0.04288","513.70264","0.00011"
"129.00000","4.29766","5131.08789","0.04298","513.10876","0.00010"
"129.30000","4.30768","5125.97900","0.04308","512.59790","0.00011"
"129.60000","4.31758","5119.30273","0.04318","511.93027","0.00011"
"129.90000","4.32777","5116.18896","0.04328","511.61890","0.00011"
"130.20000","4.33765","5111.04443","0.04338","511.10443","0.00010"
"130.50000","4.34764","5107.42090","0.04348","510.74210","0.00011"
"130.80000","4.35759","5102.48047","0.04358","510.24805","0.00012"
"131.10000","4.36756","5097.82959","0.04368","509.78296","0.00010"
"131.40000","4.37766","5093.35840","0.04378","509.33585","0.00011"
"131.70000","4.38765","5088.86328","0.04388","508.88632","0.00011"
"132.00000","4.39762","5084.04932","0.04398","508.40494","0.00011"
"132.30000","4.40778","5081.36572","0.04408","508.13657","0.00011"
"132.60000","4.41768","5076.25098","0.04418","507.62509","0.00011"
"132.90000","4.42751","5069.66650","0.04428","506.96664","0.00011"
"133.20000","4.43753","5065.20215","0.04438","506.52020","0.00011"
"133.50000","4.44755","5060.62988","0.04448","506.06299","0.00011"
"133.80000","4.45776","5058.86328","0.04458","505.88632","0.00011"
"134.10000","4.46776","5054.50049","0.04468","505.45004","0.00010"
"134.40000","4.47769","5048.67480","0.04478","504.86749","0.00010"
"134.70000","4.48768","5042.12256","0.04488","504.21225","0.00011"
"135.00000","4.49767","5035.52637","0.04498","503.55264","0.00011"
"135.30000","4.50756","5027.55762","0.04508","502.75577","0.00010"
"135.60000","4.51760","5020.52051","0.04518","502.05206","0.00011"
"135.90000","4.52763","5013.42285","0.04528","501.34229","0.00012"
"136.20000","4.53775","5006.37158","0.04538","500.63715","0.00011"
"136.50000","4.54760","4996.87939","0.04548","499.68793","0.00010"
"136.80000","4.55774","4989.93506","0.04558","498.99350","0.00011"
"137.10000","4.56763","4980.34424","0.04568","498.03442","0.00011"
"137.40000","4.57767","4971.26807","0.04578","497.12680","0.00010"
"137.70000","4.58760","4959.33838","0.04588","495.93384","0.00011"
"138.00000","4.59762","4946.95068","0.04598","494.69507","0.00011"
"138.30000","4.60760","4934.97998","0.04608","493.49799","0.00010"
"138.60000","4.61772","4924.72412","0.04618","492.47241","0.00011"
"138.90000","4.62757","4912.52588","0.04628","491.25259","0.00011"
"139.20000","4.63781","4905.39160","0.04638","490.53915","0.00011"
"139.50000","4.64771","4894.72900","0.04648","489.47290","0.00010"
"139.80000","4.65757","4883.73975","0.04658","488.37396","0.00011"
"140.10000","4.66756","4874.37646","0.04668","487.43765","0.00011"
"140.40000","4.67762","4866.15771","0.04678","486.61578","0.00010"
"140.70000","4.68764","4858.55029","0.04688","485.85504","0.00011"
"141.00000","4.69777","4852.82080","0.04698","485.28207","0.00011"
"141.30000","4.70767","4845.12549","0.04708","484.51254","0.00011"
"141.60000","4.71768","4838.92432","0.04718","483.89243","0.00011"
"141.90000","4.72761","4832.78174","0.04728","483.27817","0.00012"
"142.20000","4.73761","4827.88428","0.04738","482.78842","0.00011"
"142.50000","4.74758","4822.72900","0.04748","482.27289","0.00011"
"142.80000","4.75761","4818.20801","0.04758","481.82080","0.00011"
"143.10000","4.76776","4814.19727","0.04768","481.41974","0.00011"
"143.40000","4.77763","4806.74072","0.04778","480.67407","0.00010"
"143.70000","4.78766","4799.12549","0.04788","479.91254","0.00011"
"144.00000","4.79773","4791.91895","0.04798","479.19189","0.00012"
"144.30000","4.80764","4782.11084","0.04808","478.21109","0.00011"
"144.60000","4.81756","4771.82666","0.04818","477.18268","0.00010"
"144.90000","4.82766","4763.15381","0.04828","476.31537","0.00011"
"145.20000","4.83750","4752.26709","0.04837","475.22672","0.00011"
"145.50000","4.84775","4744.77686","0.04848","474.47769","0.00011"
"145.80000","4.85763","4733.30859","0.04858","473.33087","0.00011"
"146.10000","4.86776","4723.98486","0.04868","472.39850","0.00011"
"146.40000","4.87774","4714.59912","0.04878","471.45990","0.00010"
"146.70000","4.88767","4705.13086","0.04888","470.51309","0.00011"
"147.00000","4.89749","4695.73340","0.04897","469.57333","0.00011"
"147.30000","4.90766","4690.00293","0.04908","469.00031","0.00011"
"147.60000","4.91764","4683.37988","0.04918","468.33798","0.00010"
"147.90000","4.92774","4679.12207","0.04928","467.91220","0.00011"
"148.20000","4.93763","4671.82373","0.04938","467.18237","0.00011"
"148.50000","4.94780","4666.78369","0.04948","466.67838","0.00011"
"148.80000","4.95760","4657.88037","0.04958","465.78802","0.00011"
"149.10000","4.96758","4651.54590","0.04968","465.15460","0.00011"
"149.40000","4.97757","4646.44580","0.04978","464.64459","0.00011"
"149.70000","4.98760","4642.49854","0.04988","464.24985","0.00011"
"150.00000","4.99767","4638.65430","0.04998","463.86542","0.00011"
"150.30000","5.00774","4634.25879","0.05008","463.42587","0.00011"
"150.60000","5.01756","4626.52832","0.05018","462.65283","0.00011"
"150.90000","5.02773","4619.30762","0.05028","461.93076","0.00011"
"151.20000","5.03769","4608.10889","0.05038","460.81088","0.00011"
"151.50000","5.04761","4594.87158","0.05048","459.48715","0.00011"
"151.80000","5.05755","4580.86523","0.05058","458.08652","0.00011"
"152.10000","5.06762","4570.41406","0.05068","457.04141","0.00012"
"152.40000","5.07767","4561.61035","0.05078","456.16104","0.00011"
"152.70000","5.08768","4552.82275","0.05088","455.28229","0.00011"
"153.00000","5.09770","4543.64258","0.05098","454.36426","0.00011"
"153.30000","5.10770","4534.35205","0.05108","453.43521","0.00011"
"153.60000","5.11764","4524.70801","0.05118","452.47079","0.00010"
"153.90000","5.12761","4514.77881","0.05128","451.47787","0.00011"
"154.20000","5.13760","4504.99170","0.05138","450.49918","0.00011"
"154.50000","5.14759","4496.60547","0.05148","449.66055","0.00011"
"154.80000","5.15779","4490.92920","0.05158","449.09293","0.00011"
"155.10000","5.16772","4482.35693","0.05168","448.23569","0.00011"
"155.40000","5.17770","4475.23438","0.05178","447.52344","0.00011"
"155.70000","5.18770","4468.61035","0.05188","446.86102","0.00010"
"156.00000","5.19761","4462.00684","0.05198","446.20068","0.00011"
"156.30000","5.20753","4456.27637","0.05208","445.62762","0.00011"
"156.60000","5.21766","4452.77637","0.05218","445.27765","0.00011"
"156.90000","5.22761","4448.15918","0.05228","444.81592","0.00010"
"157.20000","5.23772","4445.28613","0.05238","444.52863","0.00011"
"157.50000","5.24764","4439.90625","0.05248","443.99063","0.00011"
"157.80000","5.25777","4435.86279","0.05258","443.58627","0.00010"
"158.10000","5.26765","4429.18848","0.05268","442.91885","0.00012"
"158.40000","5.27764","4423.79736","0.05278","442.37973","0.00011"
"158.70000","5.28753","4418.26221","0.05288","441.82623","0.00011"
"159.00000","5.29754","4412.05713","0.05298","441.20572","0.00011"
"159.30000","5.30767","4406.12891","0.05308","440.61288","0.00009"
"159.60000","5.31782","4401.02539","0.05318","440.10254","0.00012"
"159.90000","5.32762","4392.79443","0.05328","439.27945","0.00011"
"160.20000","5.33779","4389.08008","0.05338","438.90802","0.00011"
"160.50000","5.34765","4382.94482","0.05348","438.29449","0.00010"
"160.80000","5.35750","4377.51660","0.05358","437.75165","0.00011"
"161.10000","5.36760","4375.08691","0.05368","437.50870","0.00011"
"161.40000","5.37769","4373.49902","0.05378","437.34991","0.00011"
"161.70000","5.38774","4372.59619","0.05388","437.25961","0.00010"
"162.00000","5.39773","4370.74902","0.05398","437.07489","0.00011"
"162.30000","5.40770","4368.87842","0.05408","436.88785","0.00012"
"162.44000","5.41226","4367.34424","0.05412","436.73444","0.00012"