File: Tension/Section_2_Group_2/epoxy_high_sample_1_round2.is_tens_RawData/Specimen_RawData_1.csv
Time,Extension,Load,Tensile strain (Extension),Tensile stress,Strain-by-clip-gage
(s),(mm),(N),(mm/mm),(MPa),(mm/mm)
"0.00000","0.00000","1229.19189","0.00000","122.91919","-0.04179"
"0.20000","0.00234","1247.09167","0.00002","124.70917","-0.04178"
"0.40000","0.01080","1313.81128","0.00011","131.38113","-0.04181"
"0.60000","0.01743","1362.48584","0.00017","136.24858","-0.04183"
"0.80000","0.02412","1410.22583","0.00024","141.02258","-0.04183"
"1.00000","0.03091","1457.31042","0.00031","145.73105","-0.04183"
"1.20000","0.03750","1501.96802","0.00037","150.19681","-0.04183"
"1.40000","0.04413","1546.68909","0.00044","154.66891","-0.04181"
"1.60000","0.05093","1593.00281","0.00051","159.30028","-0.04181"
"1.80000","0.05740","1637.34839","0.00057","163.73483","-0.04181"
"2.00000","0.06422","1685.19507","0.00064","168.51950","-0.04181"
"2.20000","0.07084","1731.61536","0.00071","173.16153","-0.04182"
"2.40000","0.07750","1778.04077","0.00078","177.80408","-0.04182"
"2.60000","0.08419","1824.72314","0.00084","182.47232","-0.04183"
"2.80000","0.09075","1869.83215","0.00091","186.98322","-0.04181"
"3.00000","0.09752","1916.46484","0.00098","191.64648","-0.04182"
"3.20000","0.10407","1961.02136","0.00104","196.10214","-0.04182"
"3.40000","0.11093","2007.80298","0.00111","200.78030","-0.04181"
"3.60000","0.11748","2051.76465","0.00117","205.17647","-0.04181"
"3.80000","0.12411","2095.88843","0.00124","209.58884","-0.04182"
"4.00000","0.13097","2142.36938","0.00131","214.23694","-0.04182"
"4.20000","0.13741","2185.05933","0.00137","218.50594","-0.04182"
"4.40000","0.14413","2230.10034","0.00144","223.01004","-0.04182"
"4.60000","0.15077","2274.33154","0.00151","227.43315","-0.04182"
"4.80000","0.15767","2320.71167","0.00158","232.07117","-0.04182"
"5.00000","0.16414","2363.36792","0.00164","236.33679","-0.04182"
"5.20000","0.17078","2407.19165","0.00171","240.71916","-0.04182"
"5.40000","0.17756","2452.75732","0.00178","245.27573","-0.04181"
"5.60000","0.18406","2495.68433","0.00184","249.56844","-0.04182"
"5.80000","0.19098","2542.30835","0.00191","254.23083","-0.04182"
"6.00000","0.19748","2584.96021","0.00197","258.49603","-0.04182"
"6.20000","0.20415","2629.16968","0.00204","262.91696","-0.04181"
"6.40000","0.21091","2674.89209","0.00211","267.48920","-0.04181"
"6.60000","0.21751","2718.82666","0.00218","271.88266","-0.04182"
"6.80000","0.22408","2762.62061","0.00224","276.26205","-0.04182"
"7.00000","0.23076","2807.42358","0.00231","280.74237","-0.04181"
"7.20000","0.23760","2853.75024","0.00238","285.37503","-0.04181"
"7.40000","0.24423","2898.22217","0.00244","289.82220","-0.04182"
"7.60000","0.25083","2941.90332","0.00251","294.19034","-0.04182"
"7.80000","0.25759","2987.83350","0.00258","298.78336","-0.04182"
"8.00000","0.26409","3031.23315","0.00264","303.12332","-0.04181"
"8.20000","0.27084","3077.07544","0.00271","307.70755","-0.04181"
"8.40000","0.27752","3122.22144","0.00278","312.22214","-0.04182"
"8.60000","0.28416","3166.54150","0.00284","316.65414","-0.04182"
"8.80000","0.29088","3211.68457","0.00291","321.16846","-0.04181"
"9.00000","0.29747","3255.32812","0.00297","325.53281","-0.04182"
"9.20000","0.30421","3300.75806","0.00304","330.07581","-0.04182"
"9.40000","0.31077","3344.25049","0.00311","334.42505","-0.04181"
"9.60000","0.31762","3390.86768","0.00318","339.08676","-0.04181"
"9.80000","0.32420","3434.74512","0.00324","343.47452","-0.04182"
"10.00000","0.33076","3478.31323","0.00331","347.83133","-0.04182"
"10.20000","0.33768","3525.70605","0.00338","352.57062","-0.04182"
"10.40000","0.34405","3567.20288","0.00344","356.72028","-0.04182"
"10.60000","0.35077","3612.41333","0.00351","361.24133","-0.04182"
"10.80000","0.35742","3656.93018","0.00357","365.69302","-0.04182"
"11.00000","0.36428","3703.43359","0.00364","370.34335","-0.04182"
"11.20000","0.37091","3747.54956","0.00371","374.75494","-0.04182"
"11.40000","0.37752","3791.22803","0.00378","379.12280","-0.04181"
"11.60000","0.38422","3835.80957","0.00384","383.58096","-0.04182"
"11.80000","0.39070","3877.99170","0.00391","387.79916","-0.04182"
"12.00000","0.39762","3924.99609","0.00398","392.49960","-0.04182"
"12.20000","0.40411","3967.78467","0.00404","396.77847","-0.04181"
"12.40000","0.41075","4011.58301","0.00411","401.15829","-0.04182"
"12.60000","0.41759","4057.46167","0.00418","405.74615","-0.04182"
"12.80000","0.42417","4100.41406","0.00424","410.04141","-0.04182"
"13.00000","0.43088","4144.46582","0.00431","414.44659","-0.04182"
"13.20000","0.43746","4187.58594","0.00437","418.75861","-0.04181"
"13.40000","0.44433","4233.61475","0.00444","423.36148","-0.04182"
"13.60000","0.45084","4276.11475","0.00451","427.61148","-0.04182"
"13.80000","0.45747","4319.35400","0.00457","431.93539","-0.04182"
"14.00000","0.46419","4363.54932","0.00464","436.35492","-0.04182"
"14.20000","0.47075","4406.03369","0.00471","440.60336","-0.04181"
"14.40000","0.47753","4450.73486","0.00478","445.07349","-0.04182"
"14.60000","0.48419","4494.39502","0.00484","449.43951","-0.04182"
"14.80000","0.49088","4537.80371","0.00491","453.78036","-0.04182"
"15.00000","0.49762","4582.21240","0.00498","458.22125","-0.04182"
"15.20000","0.50418","4624.43506","0.00504","462.44351","-0.04181"
"15.40000","0.51083","4667.49756","0.00511","466.74976","-0.04184"
"15.60000","0.51747","4710.62158","0.00517","471.06216","-0.04183"
"15.80000","0.52424","4754.37402","0.00524","475.43741","-0.04181"
"16.00000","0.53082","4796.74512","0.00531","479.67450","-0.04181"
"16.20000","0.53736","4838.46338","0.00537","483.84634","-0.04183"
"16.40000","0.54428","4884.32861","0.00544","488.43286","-0.04182"
"16.60000","0.55084","4926.07422","0.00551","492.60742","-0.04180"
"16.80000","0.55762","4969.79785","0.00558","496.97980","-0.04182"
"17.00000","0.56420","5011.48145","0.00564","501.14813","-0.04182"
"17.20000","0.57091","5054.37451","0.00571","505.43744","-0.04182"
"17.40000","0.57760","5097.47803","0.00578","509.74780","-0.04182"
"17.60000","0.58406","5137.92041","0.00584","513.79205","-0.04182"
"17.80000","0.59086","5181.82129","0.00591","518.18213","-0.04182"
"18.00000","0.59732","5222.21387","0.00597","522.22137","-0.04182"
"18.20000","0.60430","5268.22363","0.00604","526.82239","-0.04182"
"18.40000","0.61089","5309.83789","0.00611","530.98376","-0.04181"
"18.60000","0.61756","5352.09570","0.00618","535.20959","-0.04181"
"18.80000","0.62435","5395.82373","0.00624","539.58240","-0.04182"
"19.00000","0.63079","5435.77637","0.00631","543.57764","-0.04182"
"19.20000","0.63747","5477.99072","0.00637","547.79907","-0.04180"
"19.40000","0.64404","5518.95410","0.00644","551.89539","-0.04180"
"19.60000","0.65095","5563.40381","0.00651","556.34039","-0.04181"
"19.80000","0.65748","5603.90479","0.00657","560.39050","-0.04182"
"20.00000","0.66413","5645.11768","0.00664","564.51178","-0.04182"
"20.20000","0.67094","5688.72021","0.00671","568.87201","-0.04182"
"20.40000","0.67749","5729.07617","0.00677","572.90759","-0.04182"
"20.60000","0.68430","5772.18604","0.00684","577.21863","-0.04182"
"20.80000","0.69082","5812.53418","0.00691","581.25342","-0.04182"
"21.00000","0.69752","5853.88037","0.00698","585.38806","-0.04181"
"21.20000","0.70422","5895.52344","0.00704","589.55237","-0.04181"
"21.40000","0.71080","5935.85352","0.00711","593.58533","-0.04182"
"21.60000","0.71745","5977.07373","0.00717","597.70740","-0.04182"
"21.80000","0.72411","6017.83252","0.00724","601.78326","-0.04182"
"22.00000","0.73100","6060.58057","0.00731","606.05804","-0.04182"
"22.20000","0.73762","6100.55713","0.00738","610.05573","-0.04182"
"22.40000","0.74416","6139.61963","0.00744","613.96198","-0.04182"
"22.60000","0.75092","6181.21045","0.00751","618.12103","-0.04181"
"22.80000","0.75743","6219.96094","0.00757","621.99609","-0.04182"
"23.00000","0.76411","6260.06787","0.00764","626.00677","-0.04182"
"23.20000","0.77082","6300.64404","0.00771","630.06439","-0.04182"
"23.40000","0.77750","6340.53955","0.00778","634.05396","-0.04182"
"23.60000","0.78424","6381.19580","0.00784","638.11957","-0.04181"
"23.80000","0.79087","6420.09082","0.00791","642.00909","-0.04181"
"24.00000","0.79765","6460.77246","0.00798","646.07727","-0.04182"
"24.20000","0.80407","6497.71973","0.00804","649.77197","-0.04182"
"24.40000","0.81093","6539.21436","0.00811","653.92145","-0.04182"
"24.60000","0.81753","6577.76318","0.00818","657.77631","-0.04182"
"24.80000","0.82409","6615.47949","0.00824","661.54797","-0.04182"
"25.00000","0.83100","6657.13916","0.00831","665.71393","-0.04181"
"25.20000","0.83741","6692.92871","0.00837","669.29285","-0.04181"
"25.40000","0.84414","6732.32080","0.00844","673.23206","-0.04181"
"25.60000","0.85083","6771.78418","0.00851","677.17841","-0.04182"
"25.80000","0.85773","6812.89941","0.00858","681.28992","-0.04183"
"26.00000","0.86423","6849.55273","0.00864","684.95526","-0.04183"
"26.20000","0.87081","6886.80908","0.00871","688.68091","-0.04182"
"26.40000","0.87762","6926.60205","0.00878","692.66022","-0.04181"
"26.60000","0.88400","6961.66895","0.00884","696.16687","-0.04181"
"26.80000","0.89092","7002.30908","0.00891","700.23090","-0.04181"
"27.00000","0.89744","7038.94141","0.00897","703.89417","-0.04181"
"27.20000","0.90421","7077.57422","0.00904","707.75745","-0.04182"
"27.40000","0.91095","7115.89160","0.00911","711.58917","-0.04182"
"27.60000","0.91757","7152.69727","0.00918","715.26971","-0.04182"
"27.80000","0.92422","7189.38867","0.00924","718.93884","-0.04182"
"28.00000","0.93070","7224.80176","0.00931","722.48016","-0.04182"
"28.20000","0.93763","7265.11475","0.00938","726.51147","-0.04181"
"28.40000","0.94415","7300.68408","0.00944","730.06842","-0.04182"
"28.60000","0.95079","7337.21533","0.00951","733.72156","-0.04182"
"28.80000","0.95760","7375.55273","0.00958","737.55530","-0.04182"
"29.00000","0.96411","7410.18750","0.00964","741.01874","-0.04182"
"29.20000","0.97088","7447.54053","0.00971","744.75403","-0.04182"
"29.40000","0.97754","7483.92188","0.00978","748.39221","-0.04178"
"29.60000","0.98425","7520.61084","0.00984","752.06110","-0.04181"
"29.80000","0.99087","7556.12256","0.00991","755.61224","-0.04183"
"30.00000","0.99747","7590.91016","0.00997","759.09100","-0.04183"
"30.20000","1.00419","7626.82617","0.01004","762.68262","-0.04183"
"30.40000","1.01073","7660.71582","0.01011","766.07159","-0.04182"
"30.60000","1.01756","7697.81836","0.01018","769.78186","-0.04180"
"30.80000","1.02424","7733.20361","0.01024","773.32037","-0.04179"
"31.00000","1.03078","7766.48877","0.01031","776.64886","-0.04180"
"31.20000","1.03764","7803.48242","0.01038","780.34827","-0.04181"
"31.40000","1.04411","7835.91406","0.01044","783.59143","-0.04183"
"31.60000","1.05084","7870.59814","0.01051","787.05981","-0.04183"
"31.80000","1.05743","7904.02832","0.01057","790.40283","-0.04183"
"32.00000","1.06424","7939.26025","0.01064","793.92603","-0.04182"
"32.20000","1.07089","7973.17383","0.01071","797.31738","-0.04181"
"32.40000","1.07743","8005.31299","0.01077","800.53131","-0.04182"
"32.60000","1.08430","8040.78564","0.01084","804.07855","-0.04181"
"32.80000","1.09074","8071.46338","0.01091","807.14636","-0.04182"
"33.00000","1.09756","8106.18848","0.01098","810.61884","-0.04181"
"33.20000","1.10422","8139.15527","0.01104","813.91553","-0.04181"
"33.40000","1.11085","8171.09863","0.01111","817.10986","-0.04182"
"33.60000","1.11758","8204.53906","0.01118","820.45392","-0.04184"
"33.80000","1.12411","8235.04688","0.01124","823.50470","-0.04182"
"34.00000","1.13090","8268.33105","0.01131","826.83313","-0.04182"
"34.20000","1.13743","8298.52930","0.01137","829.85291","-0.04182"
"34.40000","1.14433","8332.67676","0.01144","833.26770","-0.04182"
"34.60000","1.15086","8362.54492","0.01151","836.25452","-0.04183"
"34.80000","1.15747","8392.63184","0.01157","839.26318","-0.04184"
"35.00000","1.16428","8425.08105","0.01164","842.50812","-0.04183"
"35.20000","1.17074","8453.02148","0.01171","845.30212","-0.04180"
"35.40000","1.17750","8482.85840","0.01177","848.28583","-0.04180"
"35.60000","1.18417","8512.92285","0.01184","851.29230","-0.04181"
"35.80000","1.19089","8543.39453","0.01191","854.33948","-0.04181"
"36.00000","1.19756","8573.16797","0.01198","857.31677","-0.04183"
"36.20000","1.20415","8601.82617","0.01204","860.18262","-0.04183"
"36.40000","1.21088","8631.77637","0.01211","863.17761","-0.04182"
"36.60000","1.21743","8659.19629","0.01217","865.91962","-0.04181"
"36.80000","1.22425","8689.28711","0.01224","868.92871","-0.04181"
"37.00000","1.23084","8716.83398","0.01231","871.68341","-0.04181"
"37.20000","1.23741","8743.20215","0.01237","874.32019","-0.04182"
"37.40000","1.24431","8773.87012","0.01244","877.38702","-0.04182"
"37.60000","1.25076","8799.35059","0.01251","879.93506","-0.04182"
"37.80000","1.25753","8827.70605","0.01258","882.77063","-0.04183"
"38.00000","1.26419","8854.27051","0.01264","885.42706","-0.04182"
"38.20000","1.27094","8881.25684","0.01271","888.12567","-0.04182"
"38.40000","1.27750","8905.92871","0.01277","890.59290","-0.04182"
"38.60000","1.28407","8930.90527","0.01284","893.09052","-0.04181"
"38.80000","1.29092","8958.74707","0.01291","895.87469","-0.04181"
"39.00000","1.29735","8981.79004","0.01297","898.17902","-0.04182"
"39.20000","1.30423","9008.94141","0.01304","900.89417","-0.04182"
"39.40000","1.31084","9033.44824","0.01311","903.34485","-0.04182"
"39.60000","1.31754","9057.97852","0.01318","905.79785","-0.04182"
"39.80000","1.32440","9084.64648","0.01324","908.46466","-0.04182"
"40.00000","1.33077","9105.36523","0.01331","910.53650","-0.04182"
"40.20000","1.33741","9128.55762","0.01337","912.85577","-0.04182"
"40.40000","1.34405","9152.19531","0.01344","915.21954","-0.04181"
"40.60000","1.35098","9178.34668","0.01351","917.83466","-0.04181"
"40.80000","1.35748","9199.45508","0.01357","919.94550","-0.04182"
"41.00000","1.36415","9221.75293","0.01364","922.17529","-0.04182"
"41.20000","1.37096","9246.01172","0.01371","924.60120","-0.04182"
"41.40000","1.37742","9265.71191","0.01377","926.57117","-0.04182"
"41.60000","1.38421","9288.35449","0.01384","928.83545","-0.04183"
"41.80000","1.39077","9308.30957","0.01391","930.83093","-0.04182"
"42.00000","1.39752","9329.24023","0.01398","932.92401","-0.04181"
"42.20000","1.40423","9349.90332","0.01404","934.99036","-0.04181"
"42.40000","1.41078","9367.94043","0.01411","936.79407","-0.04181"
"42.60000","1.41750","9388.12012","0.01417","938.81201","-0.04182"
"42.80000","1.42408","9406.43750","0.01424","940.64374","-0.04182"
"43.00000","1.43090","9426.99023","0.01431","942.69904","-0.04182"
"43.20000","1.43755","9445.20898","0.01438","944.52087","-0.04182"
"43.40000","1.44419","9461.48633","0.01444","946.14862","-0.04182"
"43.60000","1.45100","9479.92578","0.01451","947.99255","-0.04181"
"43.80000","1.45742","9493.83789","0.01457","949.38379","-0.04181"
"44.00000","1.46413","9510.84766","0.01464","951.08478","-0.04181"
"44.20000","1.47080","9527.42090","0.01471","952.74207","-0.04182"
"44.40000","1.47754","9544.18066","0.01478","954.41809","-0.04182"
"44.60000","1.48429","9559.68750","0.01484","955.96875","-0.04182"
"44.80000","1.49076","9572.20117","0.01491","957.22009","-0.04182"
"45.00000","1.49767","9588.99707","0.01498","958.89972","-0.04182"
"45.20000","1.50405","9600.20898","0.01504","960.02087","-0.04181"
"45.40000","1.51093","9615.84180","0.01511","961.58417","-0.04181"
"45.60000","1.51751","9628.74609","0.01518","962.87463","-0.04181"
"45.80000","1.52413","9641.01270","0.01524","964.10126","-0.04182"
"46.00000","1.53096","9655.53516","0.01531","965.55353","-0.04182"
"46.20000","1.53742","9665.14258","0.01537","966.51428","-0.04182"
"46.40000","1.54418","9677.42773","0.01544","967.74280","-0.04182"
"46.60000","1.55070","9687.38672","0.01551","968.73865","-0.04182"
"46.80000","1.55762","9700.92676","0.01558","970.09265","-0.04182"
"47.00000","1.56421","9710.92480","0.01564","971.09247","-0.04182"
"47.20000","1.57076","9718.98926","0.01571","971.89893","-0.04182"
"47.40000","1.57768","9731.09863","0.01578","973.10986","-0.04182"
"47.60000","1.58399","9735.86426","0.01584","973.58643","-0.04183"
"47.80000","1.59081","9745.89551","0.01591","974.58954","-0.04182"
"48.00000","1.59741","9753.34570","0.01597","975.33459","-0.04182"
"48.20000","1.60433","9763.58398","0.01604","976.35840","-0.04182"
"48.40000","1.61082","9769.49512","0.01611","976.94952","-0.04181"
"48.60000","1.61741","9775.31836","0.01617","977.53186","-0.04182"
"48.80000","1.62425","9784.02539","0.01624","978.40253","-0.04182"
"49.00000","1.63073","9788.58887","0.01631","978.85889","-0.04181"
"49.20000","1.63769","9798.18066","0.01638","979.81805","-0.04181"
"49.40000","1.64415","9802.35742","0.01644","980.23572","-0.04182"
"49.60000","1.65076","9807.66699","0.01651","980.76672","-0.04181"
"49.80000","1.65761","9816.45605","0.01658","981.64563","-0.04181"
"50.00000","1.66413","9820.78125","0.01664","982.07812","-0.04181"
"50.20000","1.67077","9826.43652","0.01671","982.64368","-0.04183"
"50.40000","1.67751","9833.65918","0.01678","983.36591","-0.04183"
"50.60000","1.68427","9840.56738","0.01684","984.05676","-0.04182"
"50.80000","1.69090","9846.90234","0.01691","984.69025","-0.04182"
"51.00000","1.69744","9851.58301","0.01697","985.15833","-0.04181"
"51.20000","1.70423","9858.49023","0.01704","985.84900","-0.04180"
"51.40000","1.71072","9862.59570","0.01711","986.25958","-0.04185"
"51.60000","1.71751","9870.07520","0.01718","987.00751","-0.04181"
"51.80000","1.72421","9876.89258","0.01724","987.68927","-0.04175"
"52.00000","1.73081","9882.32520","0.01731","988.23254","-0.04179"
"52.20000","1.73763","9890.35742","0.01738","989.03577","-0.04185"
"52.40000","1.74408","9845.66309","0.01744","984.56628","-0.04184"
"52.60000","1.75088","9861.00195","0.01751","986.10022","-0.04183"
"52.80000","1.75746","9872.97559","0.01757","987.29755","-0.04186"
"53.00000","1.76433","9880.99902","0.01764","988.09991","-0.04185"
"53.20000","1.77085","9890.68555","0.01771","989.06854","-0.04179"
"53.40000","1.77738","9899.61328","0.01777","989.96130","-0.04177"
"53.60000","1.78435","9912.87793","0.01784","991.28778","-0.04179"
"53.80000","1.79071","9919.26758","0.01791","991.92676","-0.04182"
"54.00000","1.79751","9919.93945","0.01798","991.99396","-0.04184"
"54.20000","1.80414","9925.13574","0.01804","992.51355","-0.04184"
"54.40000","1.81093","9925.04395","0.01811","992.50439","-0.04183"
"54.60000","1.81767","9933.89258","0.01818","993.38928","-0.04181"
"54.80000","1.82411","9940.81934","0.01824","994.08191","-0.04180"
"55.00000","1.83085","9951.35059","0.01831","995.13507","-0.04180"
"55.20000","1.83738","9958.86621","0.01837","995.88660","-0.04181"
"55.40000","1.84435","9970.51562","0.01844","997.05157","-0.04182"
"55.60000","1.85083","9976.12012","0.01851","997.61200","-0.04183"
"55.80000","1.85741","9981.94922","0.01857","998.19495","-0.04183"
"56.00000","1.86428","9981.28809","0.01864","998.12878","-0.04182"
"56.20000","1.87077","9986.82422","0.01871","998.68243","-0.04182"
"56.40000","1.87759","9995.99219","0.01878","999.59924","-0.04182"
"56.60000","1.88414","10001.43848","0.01884","1000.14386","-0.04181"
"56.80000","1.89095","10009.16504","0.01891","1000.91650","-0.04182"
"57.00000","1.89754","10014.81152","0.01898","1001.48114","-0.04182"
"57.20000","1.90415","10019.80273","0.01904","1001.98029","-0.04182"
"57.40000","1.91086","10026.06250","0.01911","1002.60626","-0.04182"
"57.60000","1.91737","10029.54199","0.01917","1002.95422","-0.04182"
"57.80000","1.92420","10036.34082","0.01924","1003.63409","-0.04181"
"58.00000","1.93089","10041.06055","0.01931","1004.10608","-0.04182"
"58.20000","1.93752","10044.26367","0.01938","1004.42639","-0.04182"
"58.40000","1.94440","10050.98633","0.01944","1005.09863","-0.04182"
"58.60000","1.95081","10052.35059","0.01951","1005.23505","-0.04182"
"58.80000","1.95748","10055.86914","0.01957","1005.58691","-0.04182"
"59.00000","1.96410","10058.09277","0.01964","1005.80927","-0.04182"
"59.20000","1.97093","10063.52246","0.01971","1006.35223","-0.04182"
"59.40000","1.97751","10066.28223","0.01978","1006.62823","-0.04181"
"59.60000","1.98402","10067.95020","0.01984","1006.79504","-0.04182"
"59.80000","1.99093","10074.49805","0.01991","1007.44983","-0.04182"
"60.00000","1.99746","10076.71387","0.01997","1007.67139","-0.04182"
"60.20000","2.00435","10082.34961","0.02004","1008.23499","-0.04181"
"60.40000","2.01089","10078.83594","0.02011","1007.88361","-0.04182"
"60.60000","2.01754","10081.34082","0.02018","1008.13409","-0.04182"
"60.80000","2.02434","10086.60547","0.02024","1008.66052","-0.04182"
"61.00000","2.03073","10087.09375","0.02031","1008.70935","-0.04182"
"61.20000","2.03750","10091.87891","0.02038","1009.18787","-0.04182"
"61.40000","2.04398","10093.51172","0.02044","1009.35120","-0.04181"
"61.60000","2.05100","10100.65527","0.02051","1010.06555","-0.04181"
"61.80000","2.05756","10102.55469","0.02058","1010.25549","-0.04182"
"62.00000","2.06423","10105.16016","0.02064","1010.51599","-0.04182"
"62.20000","2.07107","10109.93164","0.02071","1010.99316","-0.04182"
"62.40000","2.07743","10109.56738","0.02077","1010.95673","-0.04182"
"62.60000","2.08420","10113.32227","0.02084","1011.33221","-0.04182"
"62.80000","2.09073","10114.53418","0.02091","1011.45343","-0.04182"
"63.00000","2.09757","10118.64062","0.02098","1011.86407","-0.04182"
"63.20000","2.10419","10120.97754","0.02104","1012.09778","-0.04182"
"63.40000","2.11079","10122.00977","0.02111","1012.20099","-0.04181"
"63.60000","2.11763","10126.03711","0.02118","1012.60370","-0.04182"
"63.80000","2.12414","10126.46289","0.02124","1012.64630","-0.04182"
"64.00000","2.13107","10131.75781","0.02131","1013.17578","-0.04182"
"64.20000","2.13750","10131.94238","0.02137","1013.19421","-0.04183"
"64.40000","2.14414","10134.08691","0.02144","1013.40869","-0.04182"
"64.60000","2.15088","10137.74609","0.02151","1013.77460","-0.04181"
"64.80000","2.15743","10138.70215","0.02157","1013.87024","-0.04181"
"65.00000","2.16413","10141.25391","0.02164","1014.12537","-0.04182"
"65.20000","2.17082","10143.83984","0.02171","1014.38397","-0.04182"
"65.40000","2.17767","10147.46680","0.02178","1014.74670","-0.04182"
"65.60000","2.18433","10145.47461","0.02184","1014.54749","-0.04182"
"65.80000","2.19081","10145.42969","0.02191","1014.54297","-0.04181"
"66.00000","2.19765","10149.66016","0.02198","1014.96600","-0.04181"
"66.20000","2.20408","10149.24902","0.02204","1014.92493","-0.04182"
"66.40000","2.21079","10151.75684","0.02211","1015.17566","-0.04182"
"66.60000","2.21751","10154.68262","0.02218","1015.46826","-0.04182"
"66.80000","2.22412","10155.76172","0.02224","1015.57617","-0.04182"
"67.00000","2.23093","10158.87695","0.02231","1015.88770","-0.04182"
"67.20000","2.23750","10159.19043","0.02237","1015.91907","-0.04181"
"67.40000","2.24432","10162.07324","0.02244","1016.20734","-0.04181"
"67.60000","2.25077","10161.07324","0.02251","1016.10730","-0.04181"
"67.80000","2.25765","10164.23730","0.02258","1016.42371","-0.04182"
"68.00000","2.26419","10164.61621","0.02264","1016.46161","-0.04183"
"68.20000","2.27072","10163.82031","0.02271","1016.38202","-0.04182"
"68.40000","2.27763","10167.54395","0.02278","1016.75439","-0.04181"
"68.60000","2.28405","10165.74512","0.02284","1016.57452","-0.04181"
"68.80000","2.29083","10167.74707","0.02291","1016.77472","-0.04181"
"69.00000","2.29751","10168.99414","0.02298","1016.89941","-0.04183"
"69.20000","2.30439","10171.80078","0.02304","1017.18005","-0.04183"
"69.40000","2.31098","10171.91699","0.02311","1017.19171","-0.04185"
"69.60000","2.31745","10170.36328","0.02317","1017.03632","-0.04183"
"69.80000","2.32419","10172.91113","0.02324","1017.29114","-0.04178"
"70.00000","2.33068","10171.66406","0.02331","1017.16638","-0.04177"
"70.20000","2.33767","10175.48926","0.02338","1017.54895","-0.04180"
"70.40000","2.34415","10170.17188","0.02344","1017.01721","-0.04183"
"70.60000","2.35082","10170.79883","0.02351","1017.07990","-0.04185"
"70.80000","2.35763","10173.47559","0.02358","1017.34753","-0.04185"
"71.00000","2.36418","10172.39355","0.02364","1017.23938","-0.04183"
"71.20000","2.37089","10173.08984","0.02371","1017.30896","-0.04181"
"71.40000","2.37745","10171.66309","0.02377","1017.16632","-0.04180"
"71.60000","2.38430","10173.55371","0.02384","1017.35535","-0.04180"
"71.80000","2.39085","10172.17480","0.02391","1017.21747","-0.04181"
"72.00000","2.39747","10171.04004","0.02397","1017.10400","-0.04182"
"72.20000","2.40423","10171.94141","0.02404","1017.19415","-0.04183"
"72.40000","2.41075","10169.73047","0.02411","1016.97302","-0.04183"
"72.60000","2.41758","10170.52148","0.02418","1017.05212","-0.04182"
"72.80000","2.42427","10169.63086","0.02424","1016.96307","-0.04181"
"73.00000","2.43092","10168.35645","0.02431","1016.83563","-0.04181"
"73.20000","2.43759","10167.50781","0.02438","1016.75079","-0.04181"
"73.40000","2.44413","10165.55762","0.02444","1016.55579","-0.04181"
"73.60000","2.45082","10165.10059","0.02451","1016.51007","-0.04182"
"73.80000","2.45742","10163.86719","0.02457","1016.38672","-0.04183"
"74.00000","2.46427","10164.50000","0.02464","1016.45001","-0.04183"
"74.20000","2.47087","10162.39453","0.02471","1016.23944","-0.04182"
"74.40000","2.47745","10159.57031","0.02477","1015.95703","-0.04182"
"74.60000","2.48440","10160.95410","0.02484","1016.09540","-0.04181"
"74.80000","2.49078","10156.34570","0.02491","1015.63458","-0.04181"
"75.00000","2.49751","10155.51855","0.02498","1015.55188","-0.04181"
"75.20000","2.50410","10153.37695","0.02504","1015.33771","-0.04181"
"75.40000","2.51089","10152.88672","0.02511","1015.28870","-0.04182"
"75.60000","2.51758","10151.87598","0.02518","1015.18762","-0.04182"
"75.80000","2.52411","10148.86230","0.02524","1014.88623","-0.04182"
"76.00000","2.53092","10149.62891","0.02531","1014.96289","-0.04182"
"76.20000","2.53739","10146.63184","0.02537","1014.66321","-0.04182"
"76.40000","2.54434","10148.34863","0.02544","1014.83484","-0.04182"
"76.60000","2.55085","10145.74414","0.02551","1014.57440","-0.04182"
"76.80000","2.55751","10144.49121","0.02558","1014.44910","-0.04181"
"77.00000","2.56431","10145.20605","0.02564","1014.52063","-0.04182"
"77.20000","2.57072","10140.87695","0.02571","1014.08771","-0.04182"
"77.40000","2.57757","10142.14160","0.02578","1014.21417","-0.04182"
"77.60000","2.58412","10139.68945","0.02584","1013.96893","-0.04182"
"77.80000","2.59101","10140.42676","0.02591","1014.04266","-0.04182"
"78.00000","2.59752","10136.53320","0.02598","1013.65332","-0.04182"
"78.20000","2.60412","10133.15820","0.02604","1013.31580","-0.04181"
"78.40000","2.61101","10133.17188","0.02611","1013.31720","-0.04181"
"78.60000","2.61740","10127.37793","0.02617","1012.73779","-0.04181"
"78.80000","2.62417","10125.77344","0.02624","1012.57733","-0.04181"
"79.00000","2.63087","10122.98438","0.02631","1012.29846","-0.04182"
"79.20000","2.63754","10119.74316","0.02638","1011.97430","-0.04182"
"79.40000","2.64428","10117.58203","0.02644","1011.75818","-0.04182"
"79.60000","2.65079","10112.93262","0.02651","1011.29327","-0.04182"
"79.80000","2.65758","10111.40820","0.02658","1011.14081","-0.04182"
"80.00000","2.66412","10107.69824","0.02664","1010.76984","-0.04181"
"80.20000","2.67092","10106.49414","0.02671","1010.64941","-0.04181"
"80.40000","2.67751","10103.28711","0.02678","1010.32874","-0.04182"
"80.60000","2.68407","10099.64355","0.02684","1009.96436","-0.04182"
"80.80000","2.69102","10099.90234","0.02691","1009.99023","-0.04182"
"81.00000","2.69741","10093.92773","0.02697","1009.39276","-0.04182"
"81.20000","2.70418","10092.07227","0.02704","1009.20721","-0.04182"
"81.40000","2.71088","10089.59668","0.02711","1008.95966","-0.04181"
"81.60000","2.71762","10086.97363","0.02718","1008.69739","-0.04182"
"81.80000","2.72419","10083.18262","0.02724","1008.31824","-0.04181"
"82.00000","2.73073","10078.72949","0.02731","1007.87292","-0.04181"
"82.20000","2.73756","10078.24512","0.02738","1007.82452","-0.04182"
"82.40000","2.74400","10073.81543","0.02744","1007.38153","-0.04182"
"82.60000","2.75093","10074.95410","0.02751","1007.49542","-0.04182"
"82.80000","2.75751","10072.99609","0.02758","1007.29962","-0.04182"
"83.00000","2.76415","10070.80957","0.02764","1007.08093","-0.04182"
"83.20000","2.77104","10071.98047","0.02771","1007.19806","-0.04181"
"83.40000","2.77741","10066.97266","0.02777","1006.69727","-0.04182"
"83.60000","2.78411","10066.02246","0.02784","1006.60223","-0.04182"
"83.80000","2.79075","10065.10938","0.02791","1006.51093","-0.04182"
"84.00000","2.79764","10066.82129","0.02798","1006.68213","-0.04182"
"84.20000","2.80413","10063.74902","0.02804","1006.37488","-0.04182"
"84.40000","2.81079","10061.42285","0.02811","1006.14227","-0.04182"
"84.60000","2.81763","10061.55176","0.02818","1006.15515","-0.04182"
"84.80000","2.82407","10056.16992","0.02824","1005.61700","-0.04182"
"85.00000","2.83093","10056.01660","0.02831","1005.60168","-0.04182"
"85.20000","2.83749","10052.28711","0.02837","1005.22870","-0.04182"
"85.40000","2.84416","10049.70410","0.02844","1004.97040","-0.04181"
"85.60000","2.85091","10048.67969","0.02851","1004.86798","-0.04181"
"85.80000","2.85742","10044.59668","0.02857","1004.45966","-0.04181"
"86.00000","2.86415","10043.16992","0.02864","1004.31702","-0.04182"
"86.20000","2.87079","10040.46777","0.02871","1004.04675","-0.04182"
"86.40000","2.87768","10040.36328","0.02878","1004.03632","-0.04181"
"86.60000","2.88419","10036.21191","0.02884","1003.62122","-0.04182"
"86.80000","2.89078","10032.62891","0.02891","1003.26288","-0.04182"
"87.00000","2.89770","10033.57812","0.02898","1003.35779","-0.04182"
"87.20000","2.90407","10028.62891","0.02904","1002.86292","-0.04182"
"87.40000","2.91077","10027.41602","0.02911","1002.74158","-0.04182"
"87.60000","2.91742","10026.28125","0.02917","1002.62811","-0.04182"
"87.80000","2.92422","10027.26953","0.02924","1002.72693","-0.04182"
"88.00000","2.93103","10028.37988","0.02931","1002.83801","-0.04182"
"88.20000","2.93739","10024.20215","0.02937","1002.42023","-0.04182"
"88.40000","2.94425","10025.39941","0.02944","1002.53992","-0.04182"
"88.60000","2.95076","10022.11230","0.02951","1002.21124","-0.04182"
"88.80000","2.95767","10023.09570","0.02958","1002.30957","-0.04182"
"89.00000","2.96418","10019.14746","0.02964","1001.91473","-0.04181"
"89.20000","2.97071","10014.28711","0.02971","1001.42871","-0.04182"
"89.40000","2.97763","10013.57617","0.02978","1001.35760","-0.04181"
"89.60000","2.98406","10006.70020","0.02984","1000.67004","-0.04181"
"89.80000","2.99088","10003.03711","0.02991","1000.30371","-0.04182"
"90.00000","2.99742","9996.35547","0.02997","999.63556","-0.04182"
"90.20000","3.00432","9993.72461","0.03004","999.37244","-0.04182"
"90.40000","3.01090","9988.25391","0.03011","998.82538","-0.04182"
"90.60000","3.01742","9982.49316","0.03017","998.24933","-0.04182"
"90.80000","3.02428","9982.01074","0.03024","998.20105","-0.04181"
"91.00000","3.03065","9976.40430","0.03031","997.64044","-0.04181"
"91.20000","3.03747","9976.50000","0.03037","997.65002","-0.04182"
"91.40000","3.04410","9974.73633","0.03044","997.47363","-0.04181"
"91.60000","3.05095","9975.04688","0.03051","997.50470","-0.04181"
"91.80000","3.05757","9973.52051","0.03058","997.35205","-0.04181"
"92.00000","3.06410","9971.12207","0.03064","997.11218","-0.04182"
"92.20000","3.07086","9971.71680","0.03071","997.17169","-0.04182"
"92.40000","3.07740","9969.65723","0.03077","996.96570","-0.04182"
"92.60000","3.08432","9971.49707","0.03084","997.14972","-0.04182"
"92.80000","3.09080","9968.40918","0.03091","996.84094","-0.04182"
"93.00000","3.09741","9966.31055","0.03097","996.63104","-0.04182"
"93.20000","3.10427","9967.20020","0.03104","996.72003","-0.04182"
"93.40000","3.11079","9963.65137","0.03111","996.36511","-0.04181"
"93.60000","3.11743","9961.11914","0.03117","996.11194","-0.04181"
"93.80000","3.12416","9959.20508","0.03124","995.92053","-0.04182"
"94.00000","3.13093","9956.75000","0.03131","995.67499","-0.04182"
"94.20000","3.13761","9952.94434","0.03138","995.29443","-0.04181"
"94.40000","3.14415","9947.16016","0.03144","994.71600","-0.04182"
"94.60000","3.15082","9942.51660","0.03151","994.25165","-0.04182"
"94.80000","3.15737","9936.83301","0.03157","993.68329","-0.04182"
"95.00000","3.16421","9934.23926","0.03164","993.42395","-0.04182"
"95.20000","3.17091","9930.83203","0.03171","993.08319","-0.04182"
"95.40000","3.17747","9926.40039","0.03177","992.64001","-0.04182"
"95.60000","3.18429","9925.03320","0.03184","992.50330","-0.04181"
"95.80000","3.19074","9919.80762","0.03191","991.98077","-0.04181"
"96.00000","3.19760","9918.43359","0.03198","991.84338","-0.04181"
"96.20000","3.20417","9913.42773","0.03204","991.34277","-0.04182"
"96.40000","3.21093","9908.39258","0.03211","990.83923","-0.04182"
"96.60000","3.21753","9903.65234","0.03218","990.36523","-0.04182"
"96.80000","3.22406","9898.21484","0.03224","989.82147","-0.04182"
"97.00000","3.23104","9897.56250","0.03231","989.75623","-0.04182"
"97.20000","3.23734","9888.28613","0.03237","988.82861","-0.04181"
"97.40000","3.24414","9883.82129","0.03244","988.38214","-0.04181"
"97.60000","3.25078","9877.99316","0.03251","987.79932","-0.04181"
"97.80000","3.25759","9873.72461","0.03258","987.37244","-0.04181"
"98.00000","3.26438","9869.27832","0.03264","986.92786","-0.04182"
"98.20000","3.27080","9859.74805","0.03271","985.97479","-0.04182"
"98.40000","3.27744","9853.02832","0.03277","985.30286","-0.04182"
"98.60000","3.28406","9846.28613","0.03284","984.62860","-0.04181"
"98.80000","3.29101","9844.20215","0.03291","984.42023","-0.04183"
"99.00000","3.29741","9837.08984","0.03297","983.70898","-0.04184"
"99.20000","3.30403","9833.53809","0.03304","983.35382","-0.04183"
"99.40000","3.31094","9834.51367","0.03311","983.45135","-0.04183"
"99.60000","3.31742","9831.21289","0.03317","983.12128","-0.04181"
"99.80000","3.32429","9832.66016","0.03324","983.26599","-0.04181"
"100.00000","3.33081","9830.05371","0.03331","983.00537","-0.04181"
"100.20000","3.33757","9830.45410","0.03338","983.04541","-0.04180"
"100.40000","3.34423","9830.38574","0.03344","983.03857","-0.04180"
"100.60000","3.35079","9829.03613","0.03351","982.90363","-0.04181"
"100.80000","3.35748","9828.73730","0.03357","982.87372","-0.04183"
"101.00000","3.36406","9827.10156","0.03364","982.71014","-0.04184"
"101.20000","3.37093","9829.06055","0.03371","982.90607","-0.04183"
"101.40000","3.37754","9828.90332","0.03378","982.89032","-0.04182"
"101.60000","3.38416","9828.50000","0.03384","982.84998","-0.04180"
"101.80000","3.39105","9831.42285","0.03391","983.14227","-0.04180"
"102.00000","3.39745","9828.79590","0.03397","982.87958","-0.04180"
"102.20000","3.40413","9829.43359","0.03404","982.94336","-0.04188"
"102.40000","3.41082","9829.78418","0.03411","982.97839","-0.04186"
"102.60000","3.41761","9830.91992","0.03418","983.09198","-0.04180"
"102.80000","3.42420","9829.68555","0.03424","982.96857","-0.04179"
"103.00000","3.43071","9826.93066","0.03431","982.69305","-0.04180"
"103.20000","3.43764","9828.35938","0.03438","982.83594","-0.04182"
"103.40000","3.44412","9823.96191","0.03444","982.39618","-0.04184"
"103.60000","3.45103","9823.68066","0.03451","982.36804","-0.04183"
"103.80000","3.45758","9819.73535","0.03458","981.97351","-0.04183"
"104.00000","3.46417","9815.92871","0.03464","981.59290","-0.04179"
"104.20000","3.47105","9815.17090","0.03471","981.51709","-0.04175"
"104.40000","3.47740","9806.84570","0.03477","980.68457","-0.04180"
"104.60000","3.48410","9801.38867","0.03484","980.13885","-0.04193"
"104.80000","3.49065","9793.08789","0.03491","979.30878","-0.04178"
"105.00000","3.49770","9789.63184","0.03498","978.96320","-0.04181"
"105.20000","3.50430","9781.30957","0.03504","978.13098","-0.04185"
"105.40000","3.51091","9772.86426","0.03511","977.28644","-0.04182"
"105.60000","3.51768","9767.41602","0.03518","976.74158","-0.04182"
"105.80000","3.52408","9757.84961","0.03524","975.78497","-0.04183"
"106.00000","3.53082","9753.24023","0.03531","975.32404","-0.04180"
"106.20000","3.53740","9747.19043","0.03537","974.71906","-0.04180"
"106.40000","3.54418","9743.59570","0.03544","974.35956","-0.04182"
"106.60000","3.55089","9740.37305","0.03551","974.03729","-0.04182"
"106.80000","3.55747","9735.75293","0.03557","973.57532","-0.04181"
"107.00000","3.56428","9734.50391","0.03564","973.45038","-0.04182"
"107.20000","3.57081","9730.87891","0.03571","973.08789","-0.04183"
"107.40000","3.57772","9732.16797","0.03578","973.21680","-0.04182"
"107.60000","3.58418","9727.68945","0.03584","972.76892","-0.04182"
"107.80000","3.59078","9724.60352","0.03591","972.46033","-0.04182"
"108.00000","3.59752","9723.17578","0.03598","972.31757","-0.04181"
"108.20000","3.60410","9720.24023","0.03604","972.02405","-0.04180"
"108.40000","3.61079","9717.99023","0.03611","971.79901","-0.04182"
"108.60000","3.61747","9715.42871","0.03617","971.54285","-0.04181"
"108.80000","3.62432","9714.72754","0.03624","971.47278","-0.04183"
"109.00000","3.63105","9712.10938","0.03631","971.21094","-0.04182"
"109.20000","3.63750","9705.66113","0.03637","970.56610","-0.04178"
"109.40000","3.64424","9702.06543","0.03644","970.20654","-0.04179"
"109.60000","3.65071","9695.48145","0.03651","969.54816","-0.04182"
"109.80000","3.65748","9690.79980","0.03657","969.07996","-0.04182"
"110.00000","3.66419","9685.46973","0.03664","968.54700","-0.04183"
"110.20000","3.67076","9678.26074","0.03671","967.82605","-0.04181"
"110.40000","3.67767","9674.74707","0.03678","967.47473","-0.04180"
"110.60000","3.68418","9667.59082","0.03684","966.75909","-0.04182"
"110.80000","3.69100","9665.14746","0.03691","966.51477","-0.04181"
"111.00000","3.69747","9659.61035","0.03697","965.96106","-0.04181"
"111.20000","3.70429","9658.46875","0.03704","965.84686","-0.04184"
"111.40000","3.71092","9655.83301","0.03711","965.58331","-0.04178"
"111.60000","3.71738","9650.81152","0.03717","965.08118","-0.04175"
"111.80000","3.72432","9652.29102","0.03724","965.22913","-0.04180"
"112.00000","3.73067","9646.95312","0.03731","964.69531","-0.04182"
"112.20000","3.73751","9646.97656","0.03738","964.69763","-0.04185"
"112.40000","3.74419","9645.69727","0.03744","964.56970","-0.04188"
"112.60000","3.75104","9646.01758","0.03751","964.60175","-0.04185"
"112.80000","3.75767","9644.20996","0.03758","964.42102","-0.04180"
"113.00000","3.76415","9641.14551","0.03764","964.11456","-0.04178"
"113.20000","3.77087","9641.75488","0.03771","964.17548","-0.04179"
"113.40000","3.77730","9638.52734","0.03777","963.85272","-0.04180"
"113.60000","3.78433","9642.38086","0.03784","964.23810","-0.04182"
"113.80000","3.79079","9639.24121","0.03791","963.92413","-0.04184"
"114.00000","3.79742","9637.94824","0.03797","963.79480","-0.04184"
"114.20000","3.80440","9641.08301","0.03804","964.10828","-0.04182"
"114.40000","3.81092","9638.86719","0.03811","963.88672","-0.04181"
"114.60000","3.81758","9638.85156","0.03818","963.88513","-0.04181"
"114.80000","3.82412","9637.50391","0.03824","963.75037","-0.04180"
"115.00000","3.83091","9639.10449","0.03831","963.91046","-0.04181"
"115.20000","3.83753","9638.05469","0.03838","963.80548","-0.04182"
"115.40000","3.84411","9636.50391","0.03844","963.65039","-0.04182"
"115.60000","3.85092","9637.17969","0.03851","963.71796","-0.04182"
"115.80000","3.85738","9633.66992","0.03857","963.36700","-0.04182"
"116.00000","3.86429","9635.34668","0.03864","963.53467","-0.04182"
"116.20000","3.87093","9634.05273","0.03871","963.40527","-0.04181"
"116.40000","3.87753","9631.45117","0.03878","963.14514","-0.04181"
"116.60000","3.88428","9631.25488","0.03884","963.12549","-0.04181"
"116.80000","3.89082","9627.84473","0.03891","962.78448","-0.04181"
"117.00000","3.89745","9625.14258","0.03897","962.51428","-0.04181"
"117.20000","3.90403","9621.71582","0.03904","962.17157","-0.04182"
"117.40000","3.91091","9621.06543","0.03911","962.10657","-0.04182"
"117.60000","3.91759","9619.73340","0.03918","961.97333","-0.04182"
"117.80000","3.92412","9616.48145","0.03924","961.64813","-0.04181"
"118.00000","3.93102","9617.04688","0.03931","961.70471","-0.04181"
"118.20000","3.93744","9611.43848","0.03937","961.14386","-0.04181"
"118.40000","3.94422","9609.86328","0.03944","960.98633","-0.04181"
"118.60000","3.95078","9606.51367","0.03951","960.65137","-0.04181"
"118.80000","3.95750","9605.42188","0.03957","960.54218","-0.04182"
"119.00000","3.96429","9605.66992","0.03964","960.56702","-0.04182"
"119.20000","3.97079","9601.62695","0.03971","960.16272","-0.04182"
"119.40000","3.97756","9600.49902","0.03978","960.04993","-0.04182"
"119.60000","3.98408","9596.49902","0.03984","959.64990","-0.04181"
"119.80000","3.99100","9597.61719","0.03991","959.76172","-0.04181"
"120.00000","3.99760","9595.55273","0.03998","959.55530","-0.04181"
"120.20000","4.00416","9593.76953","0.04004","959.37695","-0.04181"
"120.40000","4.01095","9595.38965","0.04011","959.53894","-0.04182"
"120.60000","4.01737","9592.03418","0.04017","959.20343","-0.04182"
"120.80000","4.02430","9595.16113","0.04024","959.51611","-0.04182"
"121.00000","4.03075","9592.68848","0.04031","959.26886","-0.04182"
"121.20000","4.03766","9595.56543","0.04038","959.55652","-0.04182"
"121.40000","4.04422","9594.58984","0.04044","959.45898","-0.04181"
"121.60000","4.05086","9594.22266","0.04051","959.42224","-0.04181"
"121.80000","4.05760","9594.66406","0.04058","959.46643","-0.04182"
"122.00000","4.06404","9591.33789","0.04064","959.13379","-0.04182"
"122.20000","4.07088","9591.43262","0.04071","959.14325","-0.04181"
"122.40000","4.07751","9589.07227","0.04078","958.90723","-0.04182"
"122.60000","4.08419","9587.18555","0.04084","958.71857","-0.04182"
"122.80000","4.09102","9586.76172","0.04091","958.67615","-0.04181"
"123.00000","4.09746","9581.01270","0.04097","958.10126","-0.04182"
"123.20000","4.10416","9578.08984","0.04104","957.80896","-0.04182"
"123.40000","4.11078","9575.34863","0.04111","957.53485","-0.04181"
"123.60000","4.11763","9575.89648","0.04118","957.58966","-0.04182"
"123.80000","4.12417","9572.84570","0.04124","957.28455","-0.04182"
"124.00000","4.13077","9570.77832","0.04131","957.07782","-0.04181"
"124.20000","4.13763","9571.96484","0.04138","957.19647","-0.04181"
"124.40000","4.14403","9567.99316","0.04144","956.79932","-0.04181"
"124.60000","4.15095","9569.47266","0.04151","956.94727","-0.04181"
"124.80000","4.15755","9566.91309","0.04158","956.69128","-0.04182"
"125.00000","4.16422","9563.69238","0.04164","956.36926","-0.04182"
"125.20000","4.17088","9559.38574","0.04171","955.93860","-0.04182"
"125.40000","4.17745","9553.22852","0.04177","955.32288","-0.04182"
"125.60000","4.18421","9549.95410","0.04184","954.99542","-0.04181"
"125.80000","4.19066","9543.42383","0.04191","954.34241","-0.04182"
"126.00000","4.19760","9542.43066","0.04198","954.24304","-0.04182"
"126.20000","4.20421","9538.52637","0.04204","953.85266","-0.04182"
"126.40000","4.21083","9534.65918","0.04211","953.46594","-0.04181"
"126.60000","4.21776","9535.32129","0.04218","953.53210","-0.04181"
"126.80000","4.22406","9528.73340","0.04224","952.87335","-0.04181"
"127.00000","4.23071","9526.18945","0.04231","952.61896","-0.04182"
"127.20000","4.23747","9524.26465","0.04237","952.42645","-0.04182"
"127.40000","4.24428","9522.58203","0.04244","952.25818","-0.04182"
"127.60000","4.25087","9518.38867","0.04251","951.83887","-0.04181"
"127.80000","4.25747","9514.28613","0.04257","951.42859","-0.04181"
"128.00000","4.26433","9514.36719","0.04264","951.43671","-0.04182"
"128.20000","4.27076","9509.81055","0.04271","950.98108","-0.04181"
"128.40000","4.27766","9510.85059","0.04278","951.08508","-0.04181"
"128.60000","4.28418","9508.01270","0.04284","950.80127","-0.04182"
"128.80000","4.29077","9506.07812","0.04291","950.60779","-0.04182"
"129.00000","4.29761","9506.99023","0.04298","950.69904","-0.04182"
"129.20000","4.30411","9503.86426","0.04304","950.38641","-0.04181"
"129.40000","4.31080","9503.20117","0.04311","950.32013","-0.04181"
"129.60000","4.31749","9503.18164","0.04317","950.31818","-0.04182"
"129.80000","4.32431","9505.22070","0.04324","950.52209","-0.04181"
"130.00000","4.33085","9504.42578","0.04331","950.44257","-0.04181"
"130.20000","4.33744","9504.56152","0.04337","950.45618","-0.04181"
"130.40000","4.34433","9508.12500","0.04344","950.81250","-0.04182"
"130.60000","4.35075","9506.03613","0.04351","950.60364","-0.04181"
"130.80000","4.35749","9507.67383","0.04357","950.76740","-0.04181"
"131.00000","4.36417","9508.47656","0.04364","950.84766","-0.04182"
"131.20000","4.37083","9508.44336","0.04371","950.84436","-0.04182"
"131.40000","4.37764","9510.70312","0.04378","951.07031","-0.04182"
"131.60000","4.38411","9508.79785","0.04384","950.87976","-0.04182"
"131.80000","4.39091","9510.48633","0.04391","951.04865","-0.04182"
"132.00000","4.39744","9509.13965","0.04397","950.91394","-0.04181"
"132.20000","4.40431","9511.54395","0.04404","951.15442","-0.04181"
"132.40000","4.41084","9510.27539","0.04411","951.02753","-0.04181"
"132.60000","4.41740","9507.75879","0.04417","950.77588","-0.04181"
"132.80000","4.42427","9508.59277","0.04424","950.85925","-0.04181"
"133.00000","4.43072","9503.85547","0.04431","950.38556","-0.04182"
"133.20000","4.43752","9502.87305","0.04438","950.28729","-0.04182"
"133.40000","4.44411","9498.31836","0.04444","949.83185","-0.04182"
"133.60000","4.45096","9495.15527","0.04451","949.51550","-0.04182"
"133.80000","4.45763","9489.55957","0.04458","948.95593","-0.04182"
"134.00000","4.46411","9415.38281","0.04464","941.53827","-0.04181"
"134.12200","4.46834","9220.43945","0.04468","922.04395","-0.04181"
"134.12500","4.46845","8846.95410","0.04468","884.69543","-0.04181"
"134.12700","4.46852","8484.64551","0.04469","848.46454","-0.04181"
"134.12900","4.46860","8057.61523","0.04469","805.76154","-0.04181"
"134.13100","4.46868","7583.37549","0.04469","758.33752","-0.04181"
"134.13300","4.46877","7076.32080","0.04469","707.63208","-0.04183"
"134.13500","4.46887","6548.87256","0.04469","654.88727","-0.04184"
"134.13700","4.46898","6011.93848","0.04469","601.19385","-0.04185"
"134.13900","4.46911","5474.91943","0.04469","547.49194","-0.04188"