File: Tension/Section_1_Group_4/3_days/Sample_10_3_days_tension.is_tens_RawData/Specimen_RawData_1.csv
Time,Extension,Load,Tensile strain (Extension),Axial Video,Tensile stress,Transverse Video
(s),(mm),(N),(mm/mm),(mm/mm),(MPa),(mm/mm)
"0.00000","0.00000","-0.16874","0.00000","-0.00003","-0.01687","0.00000"
"0.20000","0.00180","7.06139","0.00002","-0.00003","0.70614","0.00000"
"0.40000","0.01045","45.50362","0.00010","0.00001","4.55036","0.00000"
"0.60000","0.01727","75.53519","0.00017","0.00009","7.55352","-0.00003"
"0.80000","0.02402","104.80766","0.00024","0.00013","10.48077","-0.00005"
"1.00000","0.03054","132.84407","0.00031","0.00022","13.28441","-0.00007"
"1.20000","0.03742","162.52646","0.00037","0.00026","16.25265","-0.00005"
"1.40000","0.04389","190.03264","0.00044","0.00030","19.00326","-0.00006"
"1.60000","0.05059","218.18718","0.00051","0.00034","21.81872","-0.00005"
"1.80000","0.05726","245.78831","0.00057","0.00039","24.57883","-0.00008"
"2.00000","0.06390","272.89233","0.00064","0.00042","27.28923","-0.00005"
"2.20000","0.07054","299.40125","0.00071","0.00046","29.94012","-0.00010"
"2.40000","0.07720","325.83789","0.00077","0.00049","32.58379","-0.00010"
"2.60000","0.08402","352.51736","0.00084","0.00052","35.25174","-0.00014"
"2.80000","0.09067","378.30240","0.00091","0.00056","37.83024","-0.00014"
"3.00000","0.09728","403.44992","0.00097","0.00059","40.34499","-0.00012"
"3.20000","0.10401","428.73416","0.00104","0.00060","42.87342","-0.00005"
"3.40000","0.11054","452.54520","0.00111","0.00063","45.25452","0.00000"
"3.60000","0.11723","476.79520","0.00117","0.00066","47.67952","0.00005"
"3.80000","0.12385","500.65714","0.00124","0.00069","50.06571","0.00005"
"4.00000","0.13053","524.01868","0.00131","0.00074","52.40187","0.00010"
"4.20000","0.13731","547.90723","0.00137","0.00078","54.79072","0.00005"
"4.40000","0.14392","570.48846","0.00144","0.00081","57.04885","0.00000"
"4.60000","0.15073","593.42859","0.00151","0.00083","59.34286","0.00000"
"4.80000","0.15724","615.00824","0.00157","0.00087","61.50082","-0.00010"
"5.00000","0.16401","637.27252","0.00164","0.00091","63.72725","-0.00010"
"5.20000","0.17055","658.31970","0.00171","0.00094","65.83197","-0.00011"
"5.40000","0.17716","679.29419","0.00177","0.00097","67.92942","-0.00011"
"5.60000","0.18401","701.43610","0.00184","0.00099","70.14361","-0.00010"
"5.80000","0.19047","721.09027","0.00190","0.00101","72.10902","-0.00010"
"6.00000","0.19726","742.13904","0.00197","0.00103","74.21391","-0.00006"
"6.20000","0.20392","762.24359","0.00204","0.00106","76.22436","0.00000"
"6.40000","0.21076","782.65240","0.00211","0.00107","78.26524","0.00000"
"6.60000","0.21732","801.99054","0.00217","0.00110","80.19905","0.00005"
"6.80000","0.22389","820.76501","0.00224","0.00113","82.07650","0.00004"
"7.00000","0.23060","840.08539","0.00231","0.00117","84.00854","0.00005"
"7.20000","0.23709","858.14783","0.00237","0.00119","85.81478","0.00000"
"7.40000","0.24401","877.88867","0.00244","0.00122","87.78886","-0.00005"
"7.60000","0.25050","895.44867","0.00251","0.00124","89.54487","-0.00010"
"7.80000","0.25724","913.89978","0.00257","0.00129","91.38998","-0.00010"
"8.00000","0.26405","932.41931","0.00264","0.00132","93.24193","-0.00015"
"8.20000","0.27063","949.49023","0.00271","0.00135","94.94902","-0.00016"
"8.40000","0.27728","966.85040","0.00277","0.00138","96.68504","-0.00015"
"8.60000","0.28386","983.88306","0.00284","0.00139","98.38831","-0.00010"
"8.80000","0.29068","1001.82220","0.00291","0.00143","100.18222","-0.00010"
"9.00000","0.29719","1017.84729","0.00297","0.00145","101.78473","-0.00001"
"9.20000","0.30388","1034.47253","0.00304","0.00147","103.44725","0.00005"
"9.40000","0.31062","1051.50317","0.00311","0.00147","105.15031","0.00007"
"9.60000","0.31721","1067.49426","0.00317","0.00150","106.74943","0.00006"
"9.80000","0.32399","1084.28796","0.00324","0.00153","108.42879","0.00005"
"10.00000","0.33066","1100.34973","0.00331","0.00154","110.03497","-0.00005"
"10.20000","0.33730","1116.05835","0.00337","0.00155","111.60583","-0.00008"
"10.40000","0.34396","1131.68811","0.00344","0.00157","113.16881","-0.00015"
"10.60000","0.35055","1146.94751","0.00351","0.00159","114.69475","-0.00020"
"10.80000","0.35719","1162.16492","0.00357","0.00161","116.21649","-0.00020"
"11.00000","0.36383","1177.46387","0.00364","0.00163","117.74638","-0.00025"
"11.20000","0.37065","1193.19995","0.00371","0.00166","119.31999","-0.00015"
"11.40000","0.37727","1207.78137","0.00377","0.00168","120.77814","-0.00015"
"11.60000","0.38388","1222.29858","0.00384","0.00172","122.22986","-0.00015"
"11.80000","0.39075","1238.23962","0.00391","0.00175","123.82396","-0.00010"
"12.00000","0.39720","1251.86560","0.00397","0.00179","125.18656","-0.00010"
"12.20000","0.40391","1266.50513","0.00404","0.00181","126.65051","-0.00010"
"12.40000","0.41051","1280.75977","0.00411","0.00184","128.07597","-0.00010"
"12.60000","0.41727","1295.06458","0.00417","0.00188","129.50645","-0.00015"
"12.80000","0.42395","1309.29810","0.00424","0.00190","130.92981","-0.00015"
"13.00000","0.43055","1322.94031","0.00431","0.00193","132.29404","-0.00015"
"13.20000","0.43729","1337.08508","0.00437","0.00194","133.70851","-0.00020"
"13.40000","0.44382","1350.29321","0.00444","0.00195","135.02933","-0.00024"
"13.60000","0.45068","1364.64185","0.00451","0.00197","136.46419","-0.00025"
"13.80000","0.45726","1377.95569","0.00457","0.00197","137.79556","-0.00020"
"14.00000","0.46392","1390.98145","0.00464","0.00199","139.09814","-0.00020"
"14.20000","0.47067","1404.65967","0.00471","0.00200","140.46597","-0.00015"
"14.40000","0.47719","1416.84521","0.00477","0.00202","141.68452","-0.00013"
"14.60000","0.48391","1430.06262","0.00484","0.00205","143.00626","-0.00009"
"14.80000","0.49050","1442.52734","0.00490","0.00208","144.25273","-0.00005"
"15.00000","0.49739","1456.21375","0.00497","0.00208","145.62137","-0.00006"
"15.20000","0.50395","1468.13440","0.00504","0.00210","146.81345","-0.00010"
"15.40000","0.51058","1479.99670","0.00511","0.00211","147.99966","-0.00015"
"15.60000","0.51731","1492.65601","0.00517","0.00213","149.26559","-0.00015"
"15.80000","0.52382","1504.25452","0.00524","0.00215","150.42545","-0.00020"
"16.00000","0.53057","1516.92554","0.00531","0.00217","151.69255","-0.00020"
"16.20000","0.53720","1528.65308","0.00537","0.00221","152.86531","-0.00020"
"16.40000","0.54391","1540.66345","0.00544","0.00223","154.06635","-0.00016"
"16.60000","0.55066","1552.68372","0.00551","0.00223","155.26837","-0.00016"
"16.80000","0.55726","1563.66772","0.00557","0.00226","156.36678","-0.00020"
"17.00000","0.56392","1574.67188","0.00564","0.00228","157.46719","-0.00015"
"17.20000","0.57055","1585.83899","0.00571","0.00229","158.58389","-0.00010"
"17.40000","0.57734","1597.26306","0.00577","0.00232","159.72630","-0.00005"
"17.60000","0.58387","1607.47156","0.00584","0.00232","160.74716","-0.00010"
"17.80000","0.59050","1617.64978","0.00591","0.00234","161.76498","-0.00011"
"18.00000","0.59738","1628.77930","0.00597","0.00233","162.87793","-0.00012"
"18.20000","0.60385","1638.03625","0.00604","0.00236","163.80362","-0.00020"
"18.40000","0.61058","1648.10583","0.00611","0.00238","164.81058","-0.00020"
"18.60000","0.61725","1658.00769","0.00617","0.00241","165.80077","-0.00024"
"18.80000","0.62395","1667.69788","0.00624","0.00242","166.76979","-0.00025"
"19.00000","0.63060","1677.30530","0.00631","0.00243","167.73053","-0.00025"
"19.20000","0.63722","1686.61694","0.00637","0.00244","168.66170","-0.00025"
"19.40000","0.64394","1696.34729","0.00644","0.00244","169.63474","-0.00024"
"19.60000","0.65043","1704.82996","0.00650","0.00245","170.48300","-0.00020"
"19.80000","0.65732","1715.15491","0.00657","0.00246","171.51549","-0.00015"
"20.00000","0.66389","1724.05322","0.00664","0.00247","172.40532","-0.00015"
"20.20000","0.67053","1733.00989","0.00671","0.00251","173.30099","-0.00009"
"20.40000","0.67743","1743.31958","0.00677","0.00252","174.33195","-0.00005"
"20.60000","0.68387","1750.42407","0.00684","0.00252","175.04240","0.00000"
"20.80000","0.69051","1758.46558","0.00691","0.00253","175.84656","-0.00001"
"21.00000","0.69718","1766.68750","0.00697","0.00254","176.66875","-0.00006"
"21.20000","0.70400","1775.30408","0.00704","0.00255","177.53041","-0.00010"
"21.40000","0.71051","1782.49927","0.00711","0.00256","178.24992","-0.00011"
"21.60000","0.71726","1790.67053","0.00717","0.00258","179.06705","-0.00014"
"21.80000","0.72400","1798.25476","0.00724","0.00258","179.82547","-0.00015"
"22.00000","0.73049","1804.01953","0.00730","0.00260","180.40195","-0.00017"
"22.20000","0.73734","1811.32214","0.00737","0.00262","181.13222","-0.00018"
"22.40000","0.74391","1817.13416","0.00744","0.00262","181.71341","-0.00015"
"22.60000","0.75056","1822.91125","0.00751","0.00263","182.29112","-0.00010"
"22.80000","0.75728","1829.38831","0.00757","0.00264","182.93883","-0.00005"
"23.00000","0.76389","1835.03101","0.00764","0.00264","183.50310","0.00003"
"23.20000","0.77053","1839.89624","0.00771","0.00265","183.98962","0.00010"
"23.40000","0.77719","1845.13818","0.00777","0.00268","184.51382","0.00010"
"23.60000","0.78402","1850.85986","0.00784","0.00270","185.08598","0.00010"
"23.80000","0.79057","1855.22827","0.00791","0.00271","185.52283","0.00010"
"24.00000","0.79721","1860.23486","0.00797","0.00271","186.02348","0.00010"
"24.20000","0.80401","1865.60901","0.00804","0.00272","186.56090","0.00010"
"24.40000","0.81053","1869.44421","0.00811","0.00272","186.94443","0.00005"
"24.60000","0.81722","1873.93616","0.00817","0.00274","187.39362","0.00005"
"24.80000","0.82389","1878.46643","0.00824","0.00275","187.84665","0.00000"
"25.00000","0.83056","1882.05969","0.00831","0.00276","188.20596","0.00000"
"25.20000","0.83733","1884.93542","0.00837","0.00275","188.49355","0.00000"
"25.40000","0.84385","1886.30237","0.00844","0.00276","188.63023","0.00000"
"25.60000","0.85060","1888.95667","0.00851","0.00277","188.89566","-0.00001"
"25.80000","0.85716","1890.27625","0.00857","0.00277","189.02762","0.00001"
"26.00000","0.86404","1892.46130","0.00864","0.00277","189.24612","0.00009"
"26.20000","0.87056","1892.79480","0.00871","0.00278","189.27948","0.00009"
"26.40000","0.87713","1893.10352","0.00877","0.00279","189.31035","0.00010"
"26.60000","0.88399","1895.26099","0.00884","0.00278","189.52609","0.00015"
"26.80000","0.89049","1895.93579","0.00890","0.00279","189.59358","0.00024"
"27.00000","0.89723","1898.10278","0.00897","0.00279","189.81027","0.00030"
"27.20000","0.90384","1900.16333","0.00904","0.00279","190.01633","0.00030"
"27.40000","0.91067","1902.88159","0.00911","0.00280","190.28816","0.00030"
"27.60000","0.91728","1904.58240","0.00917","0.00282","190.45824","0.00030"
"27.80000","0.92383","1905.87366","0.00924","0.00283","190.58737","0.00025"
"28.00000","0.93065","1909.41248","0.00931","0.00283","190.94125","0.00029"
"28.20000","0.93708","1911.01587","0.00937","0.00285","191.10159","0.00025"
"28.40000","0.94393","1914.79956","0.00944","0.00285","191.47995","0.00025"
"28.60000","0.95050","1916.70837","0.00950","0.00286","191.67084","0.00025"
"28.80000","0.95731","1919.08569","0.00957","0.00287","191.90857","0.00024"
"29.00000","0.96396","1920.02148","0.00964","0.00285","192.00215","0.00026"
"29.20000","0.97055","1919.80774","0.00971","0.00287","191.98077","0.00025"
"29.40000","0.97725","1919.72498","0.00977","0.00289","191.97250","0.00025"
"29.60000","0.98380","1919.02014","0.00984","0.00288","191.90201","0.00030"
"29.80000","0.99072","1919.48901","0.00991","0.00290","191.94890","0.00034"
"30.00000","0.99719","1917.78076","0.00997","0.00289","191.77808","0.00035"
"30.20000","1.00385","1916.66370","0.01004","0.00290","191.66637","0.00040"
"30.40000","1.01061","1916.44055","0.01011","0.00290","191.64406","0.00044"
"30.60000","1.01721","1915.03748","0.01017","0.00292","191.50375","0.00049"
"30.80000","1.02389","1913.49158","0.01024","0.00291","191.34915","0.00048"
"31.00000","1.03056","1911.76941","0.01031","0.00292","191.17694","0.00047"
"31.20000","1.03727","1910.18188","0.01037","0.00293","191.01819","0.00044"
"31.40000","1.04396","1909.14697","0.01044","0.00292","190.91470","0.00044"
"31.60000","1.05060","1908.38428","0.01051","0.00293","190.83842","0.00044"
"31.80000","1.05723","1907.62732","0.01057","0.00293","190.76273","0.00040"
"32.00000","1.06381","1906.58899","0.01064","0.00292","190.65891","0.00040"
"32.20000","1.07062","1905.88647","0.01071","0.00294","190.58865","0.00035"
"32.40000","1.07729","1904.14844","0.01077","0.00295","190.41484","0.00029"
"32.60000","1.08383","1901.96301","0.01084","0.00295","190.19630","0.00030"
"32.80000","1.09068","1901.80444","0.01091","0.00295","190.18045","0.00030"
"33.00000","1.09721","1899.67383","0.01097","0.00296","189.96738","0.00035"
"33.20000","1.10394","1897.61328","0.01104","0.00297","189.76132","0.00040"
"33.40000","1.11055","1894.63892","0.01111","0.00295","189.46390","0.00040"
"33.60000","1.11728","1892.22058","0.01117","0.00296","189.22206","0.00043"
"33.80000","1.12392","1890.27319","0.01124","0.00296","189.02731","0.00050"
"34.00000","1.13052","1889.15564","0.01131","0.00295","188.91556","0.00049"
"34.20000","1.13737","1889.89514","0.01137","0.00295","188.98952","0.00053"
"34.40000","1.14377","1888.44128","0.01144","0.00297","188.84413","0.00049"
"34.60000","1.15061","1889.44055","0.01151","0.00296","188.94406","0.00044"
"34.80000","1.15719","1888.67090","0.01157","0.00296","188.86710","0.00044"
"35.00000","1.16391","1886.63477","0.01164","0.00295","188.66348","0.00045"
"35.20000","1.17073","1886.50171","0.01171","0.00294","188.65018","0.00041"
"35.40000","1.17720","1886.16382","0.01177","0.00293","188.61638","0.00034"
"35.60000","1.18387","1885.75232","0.01184","0.00294","188.57523","0.00037"
"35.80000","1.19045","1883.59985","0.01190","0.00295","188.35999","0.00039"
"36.00000","1.19741","1882.95752","0.01197","0.00298","188.29575","0.00043"
"36.20000","1.20384","1880.79138","0.01204","0.00296","188.07913","0.00049"
"36.40000","1.21051","1880.43750","0.01211","0.00297","188.04375","0.00054"
"36.60000","1.21734","1881.71960","0.01217","0.00298","188.17197","0.00054"
"36.80000","1.22384","1882.26477","0.01224","0.00295","188.22647","0.00054"
"37.00000","1.23068","1885.12354","0.01231","0.00296","188.51236","0.00046"
"37.20000","1.23721","1885.59143","0.01237","0.00295","188.55914","0.00046"
"37.40000","1.24394","1886.34546","0.01244","0.00296","188.63455","0.00044"
"37.60000","1.25062","1887.61145","0.01251","0.00298","188.76114","0.00049"
"37.80000","1.25728","1888.23486","0.01257","0.00297","188.82349","0.00044"
"38.00000","1.26385","1886.30725","0.01264","0.00298","188.63072","0.00045"
"38.20000","1.27051","1881.91528","0.01271","0.00296","188.19153","0.00053"
"38.40000","1.27733","1878.63672","0.01277","0.00296","187.86368","0.00059"
"38.60000","1.28388","1873.14697","0.01284","0.00296","187.31470","0.00064"
"38.80000","1.29057","1868.22595","0.01291","0.00296","186.82260","0.00064"
"39.00000","1.29738","1863.92688","0.01297","0.00294","186.39268","0.00064"
"39.20000","1.30390","1859.28943","0.01304","0.00291","185.92894","0.00064"
"39.40000","1.31054","1856.34924","0.01311","0.00291","185.63492","0.00064"
"39.60000","1.31728","1856.48291","0.01317","0.00291","185.64828","0.00060"
"39.80000","1.32396","1855.84021","0.01324","0.00291","185.58401","0.00054"
"40.00000","1.33057","1855.26147","0.01331","0.00292","185.52615","0.00059"
"40.20000","1.33714","1854.40088","0.01337","0.00292","185.44009","0.00069"
"40.40000","1.34399","1854.66650","0.01344","0.00292","185.46664","0.00074"
"40.60000","1.35054","1851.50317","0.01351","0.00292","185.15031","0.00076"
"40.80000","1.35738","1846.54126","0.01357","0.00290","184.65413","0.00079"
"41.00000","1.36395","1839.85425","0.01364","0.00290","183.98543","0.00075"
"41.20000","1.37055","1832.27710","0.01371","0.00290","183.22771","0.00079"
"41.40000","1.37740","1826.39392","0.01377","0.00288","182.63939","0.00077"
"41.60000","1.38382","1819.22974","0.01384","0.00287","181.92297","0.00070"
"41.80000","1.39053","1811.26465","0.01391","0.00286","181.12646","0.00070"
"42.00000","1.39711","1801.17932","0.01397","0.00285","180.11794","0.00073"
"42.20000","1.40405","1793.85583","0.01404","0.00284","179.38559","0.00078"
"42.40000","1.41063","1786.28784","0.01411","0.00283","178.62878","0.00084"
"42.60000","1.41728","1780.59485","0.01417","0.00282","178.05948","0.00094"
"42.80000","1.42404","1779.43481","0.01424","0.00281","177.94348","0.00094"
"43.00000","1.43052","1778.00903","0.01431","0.00281","177.80090","0.00099"
"43.20000","1.43727","1778.62732","0.01437","0.00281","177.86273","0.00093"
"43.40000","1.44381","1779.34485","0.01444","0.00282","177.93448","0.00094"
"43.60000","1.45058","1780.67834","0.01451","0.00283","178.06784","0.00094"
"43.80000","1.45728","1782.44446","0.01457","0.00284","178.24445","0.00089"
"44.00000","1.46390","1781.23010","0.01464","0.00283","178.12302","0.00089"
"44.20000","1.47063","1775.68884","0.01471","0.00283","177.56888","0.00085"
"44.40000","1.47722","1768.77832","0.01477","0.00281","176.87784","0.00084"
"44.60000","1.48410","1764.03369","0.01484","0.00281","176.40337","0.00088"
"44.80000","1.49056","1758.76221","0.01491","0.00282","175.87622","0.00089"
"45.00000","1.49722","1757.69800","0.01497","0.00283","175.76981","0.00089"
"45.20000","1.50394","1758.17407","0.01504","0.00282","175.81741","0.00088"
"45.40000","1.51055","1757.36230","0.01511","0.00282","175.73624","0.00089"
"45.60000","1.51716","1754.44519","0.01517","0.00283","175.44452","0.00088"
"45.80000","1.52390","1751.97180","0.01524","0.00284","175.19717","0.00088"
"46.00000","1.53069","1747.53052","0.01531","0.00284","174.75305","0.00094"
"46.20000","1.53736","1742.29333","0.01537","0.00283","174.22934","0.00094"
"46.40000","1.54393","1736.84192","0.01544","0.00283","173.68419","0.00098"
"46.60000","1.55061","1733.89209","0.01551","0.00282","173.38921","0.00099"
"46.80000","1.55718","1732.52722","0.01557","0.00282","173.25272","0.00099"
"47.00000","1.56393","1732.39563","0.01564","0.00283","173.23956","0.00102"
"47.20000","1.57056","1727.96191","0.01571","0.00283","172.79619","0.00104"
"47.40000","1.57717","1724.54749","0.01577","0.00283","172.45474","0.00109"
"47.60000","1.58401","1724.02502","0.01584","0.00283","172.40250","0.00109"
"47.80000","1.59061","1721.61816","0.01591","0.00283","172.16182","0.00108"
"48.00000","1.59735","1720.38916","0.01597","0.00282","172.03891","0.00109"
"48.20000","1.60388","1717.65430","0.01604","0.00283","171.76543","0.00109"
"48.40000","1.61066","1715.01111","0.01611","0.00282","171.50111","0.00113"
"48.60000","1.61728","1708.65637","0.01617","0.00283","170.86563","0.00113"
"48.80000","1.62383","1703.59595","0.01624","0.00284","170.35959","0.00113"
"49.00000","1.63069","1700.54175","0.01631","0.00283","170.05417","0.00113"
"49.20000","1.63710","1689.19604","0.01637","0.00284","168.91960","0.00109"
"49.40000","1.64392","1681.90881","0.01644","0.00281","168.19089","0.00114"
"49.60000","1.65059","1677.56262","0.01651","0.00280","167.75626","0.00111"
"49.80000","1.65742","1675.61206","0.01657","0.00281","167.56120","0.00113"
"50.00000","1.66402","1673.47253","0.01664","0.00281","167.34726","0.00113"
"50.20000","1.67060","1668.63257","0.01671","0.00281","166.86325","0.00114"
"50.40000","1.67730","1660.95361","0.01677","0.00281","166.09537","0.00118"
"50.60000","1.68377","1650.42078","0.01684","0.00281","165.04208","0.00118"
"50.80000","1.69069","1644.13977","0.01691","0.00280","164.41397","0.00118"
"51.00000","1.69717","1638.40393","0.01697","0.00280","163.84039","0.00114"
"51.20000","1.70389","1637.34460","0.01704","0.00279","163.73447","0.00116"
"51.40000","1.71074","1638.64990","0.01711","0.00280","163.86499","0.00118"
"51.60000","1.71731","1638.80884","0.01717","0.00280","163.88089","0.00115"
"51.80000","1.72399","1638.66760","0.01724","0.00281","163.86676","0.00118"
"52.00000","1.73050","1637.45325","0.01731","0.00281","163.74533","0.00117"
"52.20000","1.73732","1638.59180","0.01737","0.00280","163.85918","0.00118"
"52.40000","1.74387","1640.07251","0.01744","0.00281","164.00725","0.00118"
"52.60000","1.75055","1638.23291","0.01751","0.00282","163.82329","0.00116"
"52.80000","1.75726","1629.24084","0.01757","0.00281","162.92409","0.00118"
"53.00000","1.76387","1617.52576","0.01764","0.00280","161.75258","0.00119"
"53.20000","1.77067","1610.27869","0.01771","0.00280","161.02786","0.00113"
"53.40000","1.77730","1603.27148","0.01777","0.00279","160.32715","0.00118"
"53.60000","1.78393","1595.96167","0.01784","0.00278","159.59616","0.00118"
"53.80000","1.79067","1590.17407","0.01791","0.00278","159.01741","0.00123"
"54.00000","1.79723","1583.77454","0.01797","0.00279","158.37746","0.00123"
"54.20000","1.80387","1579.55603","0.01804","0.00278","157.95560","0.00128"
"54.40000","1.81051","1572.69556","0.01811","0.00277","157.26956","0.00124"
"54.60000","1.81729","1562.75000","0.01817","0.00277","156.27499","0.00123"
"54.80000","1.82396","1550.99756","0.01824","0.00276","155.09976","0.00123"
"55.00000","1.83055","1536.81970","0.01831","0.00274","153.68198","0.00127"
"55.20000","1.83742","1526.53552","0.01837","0.00273","152.65355","0.00128"
"55.40000","1.84389","1514.69153","0.01844","0.00272","151.46915","0.00128"
"55.60000","1.85062","1506.74915","0.01851","0.00272","150.67491","0.00133"
"55.80000","1.85722","1498.09045","0.01857","0.00272","149.80905","0.00137"
"56.00000","1.86390","1491.31201","0.01864","0.00270","149.13120","0.00138"
"56.20000","1.87064","1487.48608","0.01871","0.00269","148.74861","0.00138"
"56.40000","1.87720","1481.29187","0.01877","0.00269","148.12918","0.00138"
"56.60000","1.88395","1472.94983","0.01884","0.00269","147.29498","0.00142"
"56.80000","1.89054","1462.43616","0.01891","0.00269","146.24362","0.00143"
"57.00000","1.89740","1451.62292","0.01897","0.00267","145.16229","0.00139"
"57.20000","1.90393","1438.55603","0.01904","0.00266","143.85561","0.00143"
"57.40000","1.91054","1421.96301","0.01911","0.00263","142.19630","0.00143"
"57.60000","1.91734","1410.80505","0.01917","0.00261","141.08051","0.00148"
"57.80000","1.92385","1400.55542","0.01924","0.00262","140.05554","0.00152"
"58.00000","1.93060","1389.64258","0.01931","0.00261","138.96426","0.00148"
"58.20000","1.93718","1375.95605","0.01937","0.00260","137.59561","0.00148"
"58.40000","1.94401","1360.83594","0.01944","0.00259","136.08359","0.00153"
"58.60000","1.95062","1343.33325","0.01951","0.00257","134.33333","0.00156"
"58.80000","1.95728","1331.60303","0.01957","0.00257","133.16031","0.00153"
"59.00000","1.96396","1322.95105","0.01964","0.00255","132.29510","0.00153"
"59.20000","1.97049","1312.36230","0.01970","0.00254","131.23624","0.00153"
"59.40000","1.97731","1305.80334","0.01977","0.00253","130.58034","0.00148"
"59.60000","1.98390","1297.82312","0.01984","0.00252","129.78232","0.00148"
"59.80000","1.99053","1285.17322","0.01991","0.00251","128.51732","0.00145"
"60.00000","1.99732","1276.37854","0.01997","0.00249","127.63786","0.00147"
"60.20000","2.00392","1267.62329","0.02004","0.00249","126.76233","0.00148"
"60.40000","2.01059","1259.22119","0.02011","0.00248","125.92212","0.00148"
"60.60000","2.01723","1250.65710","0.02017","0.00247","125.06571","0.00148"
"60.80000","2.02401","1240.86426","0.02024","0.00246","124.08643","0.00143"
"61.00000","2.03057","1225.60754","0.02031","0.00245","122.56075","0.00144"
"61.20000","2.03718","1210.55847","0.02037","0.00244","121.05585","0.00143"
"61.40000","2.04399","1193.81458","0.02044","0.00244","119.38145","0.00143"
"61.60000","2.05049","1172.67822","0.02050","0.00243","117.26782","0.00144"
"61.80000","2.05726","1155.34985","0.02057","0.00242","115.53499","0.00148"
"62.00000","2.06393","1141.62817","0.02064","0.00241","114.16282","0.00148"
"62.20000","2.07062","1124.68005","0.02071","0.00240","112.46800","0.00138"
"62.40000","2.07731","1097.90576","0.02077","0.00240","109.79057","0.00138"
"62.60000","2.08388","1074.05054","0.02084","0.00241","107.40505","0.00143"
"62.80000","2.09058","1054.77039","0.02091","0.00241","105.47704","0.00142"
"63.00000","2.09711","1037.35754","0.02097","0.00239","103.73576","0.00138"
"63.20000","2.10400","1022.47809","0.02104","0.00239","102.24781","0.00138"
"63.40000","2.11056","1005.90631","0.02111","0.00240","100.59063","0.00138"
"63.60000","2.11722","992.93402","0.02117","0.00238","99.29340","0.00138"
"63.80000","2.12411","980.62262","0.02124","0.00237","98.06226","0.00143"
"64.00000","2.13053","962.67938","0.02131","0.00236","96.26794","0.00139"
"64.20000","2.13718","944.03131","0.02137","0.00234","94.40313","0.00148"
"64.40000","2.14385","925.97351","0.02144","0.00233","92.59735","0.00148"
"64.60000","2.15067","905.74884","0.02151","0.00232","90.57488","0.00153"
"64.80000","2.15723","881.15912","0.02157","0.00229","88.11591","0.00158"
"65.00000","2.16390","856.63507","0.02164","0.00227","85.66351","0.00163"
"65.20000","2.17065","834.47437","0.02171","0.00226","83.44743","0.00163"
"65.40000","2.17715","807.46942","0.02177","0.00223","80.74694","0.00161"
"65.60000","2.18405","784.02728","0.02184","0.00220","78.40273","0.00159"
"65.80000","2.19055","765.22644","0.02191","0.00217","76.52264","0.00154"
"66.00000","2.19721","744.64764","0.02197","0.00216","74.46477","0.00153"
"66.20000","2.20401","723.74683","0.02204","0.00217","72.37468","0.00152"
"66.40000","2.21057","702.31555","0.02211","0.00215","70.23155","0.00148"
"66.60000","2.21717","684.24316","0.02217","0.00215","68.42432","0.00143"
"66.80000","2.22385","670.94910","0.02224","0.00213","67.09491","0.00148"
"67.00000","2.23069","660.34827","0.02231","0.00211","66.03483","0.00148"
"67.20000","2.23724","650.31256","0.02237","0.00210","65.03126","0.00153"
"67.40000","2.24391","638.77740","0.02244","0.00210","63.87774","0.00158"
"67.60000","2.25067","626.21094","0.02251","0.00207","62.62109","0.00155"
"67.80000","2.25719","614.85364","0.02257","0.00206","61.48536","0.00153"
"68.00000","2.26389","605.49176","0.02264","0.00205","60.54918","0.00158"
"68.20000","2.27054","600.90784","0.02271","0.00203","60.09078","0.00158"
"68.40000","2.27719","595.55377","0.02277","0.00202","59.55538","0.00158"
"68.60000","2.28400","589.42230","0.02284","0.00200","58.94223","0.00158"
"68.80000","2.29054","583.55731","0.02291","0.00198","58.35573","0.00158"
"69.00000","2.29730","577.79919","0.02297","0.00197","57.77992","0.00158"
"69.20000","2.30386","572.14038","0.02304","0.00197","57.21404","0.00158"
"69.40000","2.31069","568.35944","0.02311","0.00194","56.83595","0.00153"
"69.60000","2.31722","565.44489","0.02317","0.00193","56.54449","0.00158"
"69.80000","2.32380","562.14050","0.02324","0.00192","56.21405","0.00158"
"70.00000","2.33067","561.80646","0.02331","0.00191","56.18064","0.00163"
"70.20000","2.33713","559.92731","0.02337","0.00190","55.99273","0.00163"
"70.40000","2.34389","557.93268","0.02344","0.00188","55.79327","0.00168"
"70.60000","2.35053","556.97357","0.02351","0.00188","55.69736","0.00168"
"70.80000","2.35733","556.07611","0.02357","0.00187","55.60761","0.00167"
"71.00000","2.36396","556.22656","0.02364","0.00185","55.62266","0.00167"
"71.20000","2.37053","555.48175","0.02371","0.00185","55.54818","0.00164"
"71.40000","2.37728","556.03668","0.02377","0.00184","55.60367","0.00159"
"71.60000","2.38375","555.70209","0.02384","0.00183","55.57021","0.00158"
"71.80000","2.39063","557.13531","0.02391","0.00183","55.71353","0.00157"
"72.00000","2.39716","556.93970","0.02397","0.00182","55.69397","0.00153"
"72.20000","2.40396","556.47803","0.02404","0.00180","55.64780","0.00150"
"72.40000","2.41064","556.45947","0.02411","0.00179","55.64595","0.00149"
"72.60000","2.41722","554.06305","0.02417","0.00177","55.40630","0.00150"
"72.80000","2.42393","550.65918","0.02424","0.00177","55.06592","0.00148"
"73.00000","2.43050","546.22760","0.02431","0.00177","54.62276","0.00148"
"73.20000","2.43735","543.78870","0.02437","0.00176","54.37887","0.00148"
"73.40000","2.44385","541.80322","0.02444","0.00176","54.18032","0.00145"
"73.60000","2.45051","540.87207","0.02451","0.00175","54.08721","0.00143"
"73.80000","2.45726","539.65070","0.02457","0.00174","53.96507","0.00143"
"74.00000","2.46385","537.58447","0.02464","0.00172","53.75845","0.00143"
"74.20000","2.47058","535.97357","0.02471","0.00172","53.59736","0.00143"
"74.40000","2.47722","534.85858","0.02477","0.00172","53.48586","0.00143"
"74.60000","2.48390","534.74182","0.02484","0.00171","53.47418","0.00143"
"74.80000","2.49064","535.02875","0.02491","0.00170","53.50288","0.00139"
"75.00000","2.49725","533.28772","0.02497","0.00169","53.32877","0.00143"
"75.20000","2.50387","532.78778","0.02504","0.00169","53.27878","0.00141"
"75.40000","2.51050","533.12146","0.02510","0.00168","53.31215","0.00138"
"75.60000","2.51729","533.82294","0.02517","0.00168","53.38229","0.00141"
"75.80000","2.52395","534.44690","0.02524","0.00167","53.44469","0.00143"
"76.00000","2.53048","534.29675","0.02530","0.00168","53.42968","0.00144"
"76.20000","2.53737","535.90588","0.02537","0.00167","53.59059","0.00145"
"76.40000","2.54383","535.15967","0.02544","0.00166","53.51597","0.00148"
"76.60000","2.55061","537.45972","0.02551","0.00166","53.74597","0.00146"
"76.80000","2.55723","539.27319","0.02557","0.00165","53.92732","0.00143"
"77.00000","2.56394","540.69128","0.02564","0.00164","54.06913","0.00139"
"77.20000","2.57059","541.93054","0.02571","0.00163","54.19305","0.00138"
"77.40000","2.57716","541.99298","0.02577","0.00162","54.19930","0.00142"
"77.60000","2.58400","543.06311","0.02584","0.00162","54.30631","0.00138"
"77.80000","2.59044","543.35974","0.02590","0.00163","54.33598","0.00138"
"78.00000","2.59732","544.93549","0.02597","0.00163","54.49355","0.00138"
"78.20000","2.60389","544.48737","0.02604","0.00163","54.44874","0.00138"
"78.30100","2.60730","544.03009","0.02607","0.00162","54.40301","0.00138"