File: Tension/Section_1_Group3/banana_tension_per3.is_tens_RawData/Specimen_RawData_1.csv
Time,Extension,Load,Tensile strain (Extension),Axial Video,Tensile stress,Transverse Video
(s),(mm),(N),(mm/mm),(mm/mm),(MPa),(mm/mm)
"0.00000","0.00000","-0.02111","0.00000","-0.00002","-0.00211","0.00004"
"0.20000","0.00174","3.53205","0.00002","-0.00002","0.35320","0.00003"
"0.40000","0.01044","24.73979","0.00010","0.00004","2.47398","-0.00001"
"0.60000","0.01713","39.93627","0.00017","0.00013","3.99363","0.00000"
"0.80000","0.02382","54.70238","0.00024","0.00023","5.47024","0.00000"
"1.00000","0.03044","68.64645","0.00030","0.00032","6.86464","0.00003"
"1.20000","0.03707","82.23022","0.00037","0.00037","8.22302","0.00006"
"1.40000","0.04387","95.38798","0.00044","0.00041","9.53880","0.00005"
"1.60000","0.05041","106.73878","0.00050","0.00043","10.67388","0.00008"
"1.80000","0.05706","118.79326","0.00057","0.00044","11.87933","0.00003"
"2.00000","0.06387","131.29106","0.00064","0.00043","13.12911","-0.00003"
"2.20000","0.07037","142.50725","0.00070","0.00046","14.25072","-0.00006"
"2.40000","0.07711","154.23090","0.00077","0.00052","15.42309","-0.00006"
"2.60000","0.08378","165.37860","0.00084","0.00056","16.53786","-0.00003"
"2.80000","0.09053","176.35887","0.00091","0.00061","17.63589","-0.00006"
"3.00000","0.09710","186.56009","0.00097","0.00069","18.65601","-0.00006"
"3.20000","0.10375","196.68788","0.00104","0.00076","19.66879","-0.00003"
"3.40000","0.11050","206.83850","0.00110","0.00083","20.68385","0.00000"
"3.60000","0.11697","216.11407","0.00117","0.00090","21.61141","0.00000"
"3.80000","0.12383","226.03479","0.00124","0.00099","22.60348","0.00003"
"4.00000","0.13044","235.27167","0.00130","0.00104","23.52717","0.00003"
"4.20000","0.13712","244.21527","0.00137","0.00108","24.42153","0.00006"
"4.40000","0.14395","253.36833","0.00144","0.00111","25.33683","0.00008"
"4.60000","0.15040","261.32004","0.00150","0.00113","26.13200","0.00008"
"4.80000","0.15707","269.79309","0.00157","0.00116","26.97931","0.00009"
"5.00000","0.16369","277.77039","0.00164","0.00120","27.77704","0.00008"
"5.20000","0.17057","286.48883","0.00171","0.00120","28.64888","0.00006"
"5.40000","0.17705","293.93652","0.00177","0.00124","29.39365","0.00000"
"5.60000","0.18379","301.93863","0.00184","0.00130","30.19386","0.00003"
"5.80000","0.19054","310.12915","0.00191","0.00136","31.01291","0.00003"
"6.00000","0.19704","317.59885","0.00197","0.00141","31.75988","0.00006"
"6.20000","0.20386","325.89755","0.00204","0.00146","32.58976","0.00007"
"6.40000","0.21042","333.31479","0.00210","0.00153","33.33148","0.00006"
"6.60000","0.21715","341.23846","0.00217","0.00158","34.12385","0.00003"
"6.80000","0.22378","349.24152","0.00224","0.00158","34.92415","0.00006"
"7.00000","0.23043","357.11789","0.00230","0.00162","35.71179","0.00008"
"7.20000","0.23709","364.95486","0.00237","0.00162","36.49549","0.00011"
"7.40000","0.24368","372.38690","0.00244","0.00162","37.23869","0.00008"
"7.60000","0.25054","380.48886","0.00251","0.00166","38.04889","0.00010"
"7.80000","0.25711","387.62323","0.00257","0.00165","38.76232","0.00008"
"8.00000","0.26375","394.69003","0.00264","0.00166","39.46900","0.00006"
"8.20000","0.27053","402.17093","0.00271","0.00167","40.21709","0.00003"
"8.40000","0.27706","408.93317","0.00277","0.00168","40.89332","0.00000"
"8.60000","0.28373","416.12360","0.00284","0.00172","41.61236","-0.00003"
"8.80000","0.29043","423.18903","0.00290","0.00175","42.31890","-0.00003"
"9.00000","0.29715","430.31146","0.00297","0.00179","43.03115","-0.00006"
"9.20000","0.30382","437.28171","0.00304","0.00182","43.72817","-0.00008"
"9.40000","0.31038","443.85873","0.00310","0.00187","44.38587","-0.00007"
"9.60000","0.31719","450.86713","0.00317","0.00191","45.08671","-0.00006"
"9.80000","0.32367","457.34933","0.00324","0.00195","45.73493","-0.00006"
"10.00000","0.33054","464.36856","0.00331","0.00199","46.43686","-0.00005"
"10.20000","0.33712","470.84958","0.00337","0.00200","47.08496","-0.00003"
"10.40000","0.34373","477.31995","0.00344","0.00204","47.73199","-0.00003"
"10.60000","0.35049","484.18799","0.00350","0.00208","48.41880","-0.00001"
"10.80000","0.35703","490.17233","0.00357","0.00207","49.01723","-0.00003"
"11.00000","0.36380","496.61639","0.00364","0.00210","49.66164","-0.00003"
"11.20000","0.37038","502.79782","0.00370","0.00212","50.27978","-0.00002"
"11.40000","0.37725","509.44946","0.00377","0.00214","50.94495","0.00000"
"11.60000","0.38380","515.37793","0.00384","0.00214","51.53779","-0.00002"
"11.80000","0.39037","521.37817","0.00390","0.00212","52.13782","-0.00004"
"12.00000","0.39723","527.98798","0.00397","0.00215","52.79880","-0.00006"
"12.20000","0.40365","533.41400","0.00404","0.00217","53.34140","-0.00006"
"12.40000","0.41045","539.85492","0.00410","0.00222","53.98549","-0.00005"
"12.60000","0.41707","545.84351","0.00417","0.00224","54.58435","-0.00005"
"12.80000","0.42389","552.08228","0.00424","0.00228","55.20823","-0.00004"
"13.00000","0.43044","557.75214","0.00430","0.00230","55.77522","-0.00006"
"13.20000","0.43708","563.51965","0.00437","0.00230","56.35197","-0.00007"
"13.40000","0.44376","569.29425","0.00444","0.00235","56.92942","-0.00003"
"13.60000","0.45034","574.76111","0.00450","0.00236","57.47611","-0.00003"
"13.80000","0.45728","580.90051","0.00457","0.00240","58.09005","0.00000"
"14.00000","0.46374","586.06256","0.00464","0.00240","58.60625","0.00000"
"14.20000","0.47040","591.71149","0.00470","0.00241","59.17115","0.00000"
"14.40000","0.47714","597.51154","0.00477","0.00243","59.75115","0.00000"
"14.60000","0.48377","603.05127","0.00484","0.00241","60.30513","0.00002"
"14.80000","0.49037","608.34283","0.00490","0.00243","60.83428","-0.00002"
"15.00000","0.49711","613.96600","0.00497","0.00245","61.39660","-0.00004"
"15.20000","0.50386","619.34625","0.00504","0.00246","61.93462","-0.00008"
"15.40000","0.51045","624.46582","0.00510","0.00247","62.44658","-0.00011"
"15.60000","0.51710","629.77966","0.00517","0.00254","62.97797","-0.00011"
"15.80000","0.52379","635.10297","0.00524","0.00256","63.51030","-0.00011"
"16.00000","0.53037","640.26495","0.00530","0.00260","64.02650","-0.00008"
"16.20000","0.53717","645.82849","0.00537","0.00262","64.58285","-0.00011"
"16.40000","0.54381","650.82300","0.00544","0.00265","65.08230","-0.00006"
"16.60000","0.55042","655.78101","0.00550","0.00266","65.57810","-0.00006"
"16.80000","0.55718","661.21008","0.00557","0.00269","66.12101","-0.00003"
"17.00000","0.56369","665.96936","0.00564","0.00269","66.59694","-0.00002"
"17.20000","0.57046","671.27533","0.00570","0.00271","67.12753","0.00000"
"17.40000","0.57708","676.09723","0.00577","0.00273","67.60973","0.00000"
"17.60000","0.58391","680.62933","0.00584","0.00271","68.06293","-0.00002"
"17.80000","0.59046","684.08276","0.00590","0.00271","68.40828","-0.00003"
"18.00000","0.59704","687.81049","0.00597","0.00272","68.78105","-0.00003"
"18.20000","0.60391","693.01727","0.00604","0.00273","69.30173","-0.00003"
"18.40000","0.61031","697.25623","0.00610","0.00276","69.72562","-0.00005"
"18.60000","0.61710","702.41449","0.00617","0.00276","70.24145","-0.00006"
"18.80000","0.62372","707.28448","0.00624","0.00278","70.72845","-0.00011"
"19.00000","0.63049","712.36554","0.00630","0.00281","71.23656","-0.00008"
"19.20000","0.63724","717.41919","0.00637","0.00281","71.74192","-0.00011"
"19.40000","0.64377","721.78448","0.00644","0.00281","72.17845","-0.00011"
"19.60000","0.65043","726.67322","0.00650","0.00281","72.66732","-0.00017"
"19.80000","0.65701","731.25220","0.00657","0.00281","73.12522","-0.00014"
"20.00000","0.66396","736.64447","0.00664","0.00285","73.66444","-0.00014"
"20.20000","0.67037","740.91608","0.00670","0.00287","74.09161","-0.00011"
"20.40000","0.67701","745.61615","0.00677","0.00288","74.56161","-0.00008"
"20.60000","0.68387","750.97351","0.00684","0.00289","75.09735","-0.00007"
"20.80000","0.69038","755.44568","0.00690","0.00291","75.54457","-0.00005"
"21.00000","0.69716","760.44427","0.00697","0.00295","76.04443","-0.00003"
"21.20000","0.70375","765.33545","0.00704","0.00297","76.53355","0.00000"
"21.40000","0.71055","770.49725","0.00711","0.00298","77.04973","-0.00003"
"21.60000","0.71712","775.26270","0.00717","0.00299","77.52627","0.00000"
"21.80000","0.72381","780.07703","0.00724","0.00299","78.00771","0.00000"
"22.00000","0.73039","784.91492","0.00730","0.00297","78.49149","-0.00003"
"22.20000","0.73700","789.49469","0.00737","0.00299","78.94947","-0.00004"
"22.40000","0.74382","794.72308","0.00744","0.00300","79.47231","-0.00008"
"22.60000","0.75045","799.36395","0.00750","0.00300","79.93639","-0.00013"
"22.80000","0.75712","804.33368","0.00757","0.00302","80.43336","-0.00016"
"23.00000","0.76390","809.25580","0.00764","0.00301","80.92558","-0.00014"
"23.20000","0.77043","813.72644","0.00770","0.00306","81.37264","-0.00011"
"23.40000","0.77708","818.51648","0.00777","0.00309","81.85165","-0.00011"
"23.60000","0.78375","823.50543","0.00784","0.00316","82.35054","-0.00014"
"23.80000","0.79053","828.52234","0.00791","0.00317","82.85223","-0.00016"
"24.00000","0.79707","832.86969","0.00797","0.00318","83.28697","-0.00020"
"24.20000","0.80367","837.26465","0.00804","0.00318","83.72646","-0.00020"
"24.40000","0.81056","842.33441","0.00811","0.00323","84.23344","-0.00018"
"24.60000","0.81708","846.60120","0.00817","0.00323","84.66012","-0.00017"
"24.80000","0.82390","851.94287","0.00824","0.00326","85.19429","-0.00015"
"25.00000","0.83049","856.59027","0.00830","0.00326","85.65903","-0.00013"
"25.20000","0.83712","861.15302","0.00837","0.00327","86.11530","-0.00011"
"25.40000","0.84389","866.07776","0.00844","0.00328","86.60777","-0.00012"
"25.60000","0.85037","870.24390","0.00850","0.00331","87.02439","-0.00014"
"25.80000","0.85706","874.77246","0.00857","0.00334","87.47725","-0.00008"
"26.00000","0.86363","879.29547","0.00864","0.00333","87.92955","-0.00008"
"26.20000","0.87060","884.78729","0.00871","0.00334","88.47873","-0.00008"
"26.40000","0.87716","889.31696","0.00877","0.00334","88.93169","-0.00010"
"26.60000","0.88383","893.92773","0.00884","0.00335","89.39278","-0.00009"
"26.80000","0.89059","898.80872","0.00891","0.00335","89.88087","-0.00009"
"27.00000","0.89706","903.07343","0.00897","0.00334","90.30734","-0.00014"
"27.20000","0.90379","907.79077","0.00904","0.00335","90.77908","-0.00012"
"27.40000","0.91034","912.14801","0.00910","0.00333","91.21480","-0.00014"
"27.60000","0.91714","916.92249","0.00917","0.00337","91.69225","-0.00017"
"27.80000","0.92375","921.29260","0.00924","0.00340","92.12926","-0.00022"
"28.00000","0.93046","925.74554","0.00930","0.00339","92.57455","-0.00025"
"28.20000","0.93720","930.44788","0.00937","0.00342","93.04478","-0.00023"
"28.40000","0.94373","934.58929","0.00944","0.00343","93.45893","-0.00028"
"28.60000","0.95062","939.82874","0.00951","0.00345","93.98287","-0.00031"
"28.80000","0.95711","943.97534","0.00957","0.00347","94.39754","-0.00028"
"29.00000","0.96379","948.50354","0.00964","0.00347","94.85036","-0.00028"
"29.20000","0.97045","952.89154","0.00970","0.00349","95.28915","-0.00028"
"29.40000","0.97706","957.24750","0.00977","0.00350","95.72475","-0.00028"
"29.60000","0.98373","961.75385","0.00984","0.00353","96.17538","-0.00028"
"29.80000","0.99044","966.08521","0.00990","0.00356","96.60852","-0.00028"
"30.00000","0.99724","970.74255","0.00997","0.00358","97.07426","-0.00028"
"30.20000","1.00385","974.95428","0.01004","0.00361","97.49543","-0.00025"
"30.40000","1.01049","979.34912","0.01010","0.00365","97.93491","-0.00023"
"30.60000","1.01718","983.95099","0.01017","0.00365","98.39510","-0.00020"
"30.80000","1.02372","988.19080","0.01024","0.00370","98.81908","-0.00017"
"31.00000","1.03042","992.86029","0.01030","0.00370","99.28603","-0.00020"
"31.20000","1.03710","997.44861","0.01037","0.00373","99.74486","-0.00018"
"31.40000","1.04373","1001.86487","0.01044","0.00375","100.18649","-0.00017"
"31.60000","1.05052","1006.74768","0.01051","0.00375","100.67477","-0.00015"
"31.80000","1.05713","1011.06390","0.01057","0.00375","101.10639","-0.00016"
"32.00000","1.06389","1015.82513","0.01064","0.00376","101.58251","-0.00018"
"32.20000","1.07040","1019.77307","0.01070","0.00379","101.97731","-0.00021"
"32.40000","1.07724","1024.70581","0.01077","0.00380","102.47058","-0.00023"
"32.60000","1.08377","1028.83972","0.01084","0.00384","102.88397","-0.00025"
"32.80000","1.09033","1032.94202","0.01090","0.00387","103.29420","-0.00031"
"33.00000","1.09721","1037.92200","0.01097","0.00389","103.79220","-0.00033"
"33.20000","1.10365","1041.76184","0.01104","0.00391","104.17619","-0.00034"
"33.40000","1.11043","1046.50037","0.01110","0.00395","104.65004","-0.00031"
"33.60000","1.11715","1051.29736","0.01117","0.00397","105.12974","-0.00036"
"33.80000","1.12396","1056.02881","0.01124","0.00398","105.60288","-0.00037"
"34.00000","1.13054","1060.64832","0.01131","0.00399","106.06483","-0.00040"
"34.20000","1.13708","1064.87854","0.01137","0.00405","106.48785","-0.00040"
"34.40000","1.14377","1069.69031","0.01144","0.00405","106.96903","-0.00040"
"34.60000","1.15030","1074.02173","0.01150","0.00407","107.40218","-0.00037"
"34.80000","1.15724","1079.59436","0.01157","0.00411","107.95943","-0.00037"
"35.00000","1.16373","1083.95789","0.01164","0.00413","108.39579","-0.00037"
"35.20000","1.17043","1088.74927","0.01170","0.00415","108.87492","-0.00034"
"35.40000","1.17725","1093.89465","0.01177","0.00417","109.38947","-0.00033"
"35.60000","1.18383","1098.25330","0.01184","0.00415","109.82533","-0.00032"
"35.80000","1.19047","1102.92090","0.01190","0.00417","110.29209","-0.00028"
"36.00000","1.19705","1107.60156","0.01197","0.00415","110.76015","-0.00031"
"36.20000","1.20388","1112.60742","0.01204","0.00419","111.26074","-0.00028"
"36.40000","1.21043","1117.15601","0.01210","0.00418","111.71560","-0.00029"
"36.60000","1.21707","1121.86450","0.01217","0.00417","112.18645","-0.00028"
"36.80000","1.22380","1126.76477","0.01224","0.00417","112.67648","-0.00025"
"37.00000","1.23038","1131.50220","0.01230","0.00418","113.15022","-0.00026"
"37.20000","1.23723","1136.77905","0.01237","0.00419","113.67790","-0.00027"
"37.40000","1.24385","1141.45776","0.01244","0.00421","114.14577","-0.00028"
"37.60000","1.25051","1146.09546","0.01251","0.00423","114.60954","-0.00031"
"37.80000","1.25718","1151.08997","0.01257","0.00424","115.10899","-0.00034"
"38.00000","1.26376","1155.77039","0.01264","0.00426","115.57704","-0.00034"
"38.20000","1.27039","1160.57556","0.01270","0.00429","116.05756","-0.00040"
"38.40000","1.27703","1165.63501","0.01277","0.00431","116.56350","-0.00040"
"38.60000","1.28385","1170.89832","0.01284","0.00433","117.08983","-0.00042"
"38.80000","1.29049","1175.97791","0.01290","0.00437","117.59779","-0.00045"
"39.00000","1.29708","1180.68945","0.01297","0.00441","118.06895","-0.00048"
"39.20000","1.30394","1186.20813","0.01304","0.00444","118.62081","-0.00046"
"39.40000","1.31036","1190.69983","0.01310","0.00446","119.06998","-0.00047"
"39.60000","1.31712","1195.75000","0.01317","0.00450","119.57500","-0.00049"
"39.80000","1.32375","1200.61816","0.01324","0.00452","120.06181","-0.00053"
"40.00000","1.33048","1205.68140","0.01330","0.00456","120.56814","-0.00053"
"40.20000","1.33715","1210.86682","0.01337","0.00459","121.08669","-0.00053"
"40.40000","1.34374","1215.86133","0.01344","0.00462","121.58614","-0.00051"
"40.60000","1.35050","1221.47571","0.01350","0.00464","122.14757","-0.00045"
"40.80000","1.35704","1226.02808","0.01357","0.00468","122.60281","-0.00043"
"41.00000","1.36393","1231.38159","0.01364","0.00473","123.13816","-0.00043"
"41.20000","1.37045","1236.21265","0.01370","0.00472","123.62126","-0.00048"
"41.40000","1.37708","1241.18188","0.01377","0.00472","124.11819","-0.00043"
"41.60000","1.38384","1246.61682","0.01384","0.00472","124.66168","-0.00042"
"41.80000","1.39038","1251.55920","0.01390","0.00472","125.15592","-0.00040"
"42.00000","1.39713","1257.07117","0.01397","0.00475","125.70712","-0.00043"
"42.20000","1.40371","1262.23669","0.01404","0.00478","126.22367","-0.00040"
"42.40000","1.41058","1267.97205","0.01411","0.00478","126.79720","-0.00036"
"42.60000","1.41714","1272.87537","0.01417","0.00478","127.28754","-0.00038"
"42.80000","1.42380","1278.02771","0.01424","0.00478","127.80277","-0.00041"
"43.00000","1.43050","1283.38550","0.01431","0.00478","128.33855","-0.00042"
"43.20000","1.43701","1288.04114","0.01437","0.00478","128.80411","-0.00041"
"43.40000","1.44381","1293.56580","0.01444","0.00480","129.35658","-0.00043"
"43.60000","1.45044","1298.37927","0.01450","0.00481","129.83792","-0.00045"
"43.80000","1.45712","1303.62646","0.01457","0.00485","130.36264","-0.00046"
"44.00000","1.46383","1308.92383","0.01464","0.00485","130.89238","-0.00048"
"44.20000","1.47045","1313.99585","0.01470","0.00485","131.39958","-0.00048"
"44.40000","1.47711","1319.23804","0.01477","0.00486","131.92380","-0.00049"
"44.60000","1.48377","1324.55225","0.01484","0.00488","132.45523","-0.00051"
"44.80000","1.49057","1330.33008","0.01491","0.00490","133.03300","-0.00051"
"45.00000","1.49708","1335.32898","0.01497","0.00492","133.53290","-0.00056"
"45.20000","1.50369","1340.59619","0.01504","0.00495","134.05962","-0.00058"
"45.40000","1.51056","1346.47327","0.01511","0.00499","134.64732","-0.00057"
"45.60000","1.51704","1350.81140","0.01517","0.00504","135.08115","-0.00057"
"45.80000","1.52379","1355.94470","0.01524","0.00507","135.59447","-0.00057"
"46.00000","1.53047","1361.23657","0.01530","0.00508","136.12366","-0.00056"
"46.20000","1.53718","1366.67969","0.01537","0.00511","136.66797","-0.00057"
"46.40000","1.54381","1372.19556","0.01544","0.00514","137.21956","-0.00057"
"46.60000","1.55039","1377.16956","0.01550","0.00517","137.71695","-0.00057"
"46.80000","1.55711","1382.59546","0.01557","0.00521","138.25955","-0.00057"
"47.00000","1.56364","1385.24817","0.01564","0.00523","138.52481","-0.00056"
"47.20000","1.57054","1390.57507","0.01571","0.00525","139.05751","-0.00058"
"47.40000","1.57712","1395.44312","0.01577","0.00527","139.54431","-0.00057"
"47.60000","1.58375","1400.41187","0.01584","0.00528","140.04118","-0.00057"
"47.80000","1.59058","1406.12598","0.01591","0.00532","140.61259","-0.00055"
"48.00000","1.59707","1411.10242","0.01597","0.00533","141.11024","-0.00051"
"48.20000","1.60372","1416.01221","0.01604","0.00533","141.60123","-0.00051"
"48.40000","1.61037","1421.33606","0.01610","0.00535","142.13361","-0.00054"
"48.60000","1.61723","1427.14600","0.01617","0.00537","142.71460","-0.00056"
"48.80000","1.62375","1432.21716","0.01624","0.00538","143.22171","-0.00056"
"49.00000","1.63043","1437.55334","0.01630","0.00538","143.75534","-0.00053"
"49.20000","1.63718","1443.16260","0.01637","0.00539","144.31625","-0.00051"
"49.40000","1.64370","1448.22424","0.01644","0.00540","144.82242","-0.00049"
"49.60000","1.65055","1453.96765","0.01651","0.00541","145.39676","-0.00050"
"49.80000","1.65711","1458.95728","0.01657","0.00542","145.89572","-0.00051"
"50.00000","1.66379","1464.22192","0.01664","0.00544","146.42220","-0.00048"
"50.20000","1.67049","1469.65222","0.01670","0.00545","146.96523","-0.00048"
"50.40000","1.67705","1474.62109","0.01677","0.00545","147.46211","-0.00051"
"50.60000","1.68372","1479.98633","0.01684","0.00546","147.99863","-0.00051"
"50.80000","1.69039","1485.31006","0.01690","0.00547","148.53101","-0.00052"
"51.00000","1.69721","1491.13452","0.01697","0.00547","149.11345","-0.00054"
"51.20000","1.70378","1496.16199","0.01704","0.00547","149.61620","-0.00054"
"51.40000","1.71044","1501.48962","0.01710","0.00550","150.14896","-0.00054"
"51.60000","1.71721","1507.25574","0.01717","0.00551","150.72557","-0.00056"
"51.80000","1.72371","1512.28149","0.01724","0.00554","151.22815","-0.00057"
"52.00000","1.73043","1517.98572","0.01730","0.00556","151.79857","-0.00059"
"52.20000","1.73709","1523.28625","0.01737","0.00558","152.32863","-0.00062"
"52.40000","1.74377","1528.77209","0.01744","0.00560","152.87721","-0.00063"
"52.60000","1.75052","1534.49268","0.01751","0.00563","153.44926","-0.00062"
"52.80000","1.75707","1539.43408","0.01757","0.00566","153.94341","-0.00062"
"53.00000","1.76379","1544.89783","0.01764","0.00568","154.48978","-0.00062"
"53.20000","1.77035","1549.98926","0.01770","0.00571","154.99893","-0.00068"
"53.40000","1.77723","1555.84448","0.01777","0.00575","155.58444","-0.00071"
"53.60000","1.78378","1561.02393","0.01784","0.00577","156.10239","-0.00072"
"53.80000","1.79039","1566.19995","0.01790","0.00581","156.62000","-0.00074"
"54.00000","1.79720","1572.05554","0.01797","0.00586","157.20555","-0.00073"
"54.20000","1.80369","1577.08643","0.01804","0.00587","157.70865","-0.00074"
"54.40000","1.81042","1582.44470","0.01810","0.00588","158.24448","-0.00074"
"54.60000","1.81707","1588.05884","0.01817","0.00591","158.80588","-0.00074"
"54.80000","1.82390","1593.85815","0.01824","0.00592","159.38582","-0.00076"
"55.00000","1.83047","1598.99146","0.01830","0.00594","159.89914","-0.00079"
"55.20000","1.83706","1603.97144","0.01837","0.00597","160.39714","-0.00079"
"55.40000","1.84384","1609.71729","0.01844","0.00600","160.97173","-0.00079"
"55.60000","1.85029","1614.57336","0.01850","0.00599","161.45734","-0.00079"
"55.80000","1.85715","1620.39124","0.01857","0.00601","162.03912","-0.00081"
"56.00000","1.86375","1625.65088","0.01864","0.00603","162.56509","-0.00080"
"56.20000","1.87053","1631.16455","0.01871","0.00602","163.11646","-0.00083"
"56.40000","1.87709","1636.39917","0.01877","0.00604","163.63992","-0.00079"
"56.60000","1.88376","1641.68103","0.01884","0.00606","164.16811","-0.00076"
"56.80000","1.89044","1647.04272","0.01890","0.00606","164.70427","-0.00076"
"57.00000","1.89705","1652.22192","0.01897","0.00608","165.22220","-0.00074"
"57.20000","1.90392","1658.09802","0.01904","0.00609","165.80980","-0.00074"
"57.40000","1.91041","1662.94910","0.01910","0.00611","166.29491","-0.00070"
"57.60000","1.91706","1668.15149","0.01917","0.00615","166.81516","-0.00071"
"57.80000","1.92381","1673.63733","0.01924","0.00617","167.36374","-0.00069"
"58.00000","1.93040","1678.81213","0.01930","0.00618","167.88121","-0.00071"
"58.20000","1.93706","1684.11084","0.01937","0.00622","168.41109","-0.00073"
"58.40000","1.94379","1689.45459","0.01944","0.00625","168.94547","-0.00072"
"58.60000","1.95051","1694.99329","0.01951","0.00627","169.49933","-0.00074"
"58.80000","1.95713","1700.04736","0.01957","0.00633","170.00473","-0.00074"
"59.00000","1.96376","1705.12366","0.01964","0.00636","170.51236","-0.00074"
"59.20000","1.97041","1710.13196","0.01970","0.00637","171.01320","-0.00072"
"59.40000","1.97706","1715.23022","0.01977","0.00641","171.52303","-0.00076"
"59.60000","1.98382","1720.56091","0.01984","0.00642","172.05609","-0.00079"
"59.80000","1.99047","1725.11792","0.01990","0.00643","172.51180","-0.00077"
"60.00000","1.99704","1729.94226","0.01997","0.00647","172.99423","-0.00076"
"60.20000","2.00389","1735.82886","0.02004","0.00650","173.58289","-0.00076"
"60.40000","2.01038","1740.54834","0.02010","0.00653","174.05484","-0.00082"
"60.60000","2.01712","1746.13208","0.02017","0.00655","174.61320","-0.00082"
"60.80000","2.02379","1751.18262","0.02024","0.00656","175.11826","-0.00091"
"61.00000","2.03053","1755.98486","0.02031","0.00657","175.59848","-0.00090"
"61.20000","2.03712","1760.31494","0.02037","0.00657","176.03149","-0.00091"
"61.40000","2.04371","1765.18054","0.02044","0.00660","176.51805","-0.00091"
"61.60000","2.05055","1770.89551","0.02051","0.00664","177.08955","-0.00093"
"61.80000","2.05699","1775.37012","0.02057","0.00667","177.53702","-0.00091"
"62.00000","2.06381","1781.04602","0.02064","0.00667","178.10460","-0.00093"
"62.20000","2.07041","1785.62659","0.02070","0.00667","178.56265","-0.00096"
"62.40000","2.07711","1789.67847","0.02077","0.00667","178.96785","-0.00096"
"62.60000","2.08392","1794.39453","0.02084","0.00669","179.43945","-0.00099"
"62.80000","2.09043","1798.62439","0.02090","0.00671","179.86244","-0.00102"
"63.00000","2.09708","1803.24768","0.02097","0.00671","180.32477","-0.00102"
"63.20000","2.10370","1807.73718","0.02104","0.00672","180.77371","-0.00101"
"63.40000","2.11066","1811.31311","0.02111","0.00672","181.13132","-0.00104"
"63.60000","2.11704","1813.72742","0.02117","0.00674","181.37274","-0.00099"
"63.80000","2.12369","1817.17700","0.02124","0.00673","181.71770","-0.00102"
"64.00000","2.13051","1821.54333","0.02131","0.00676","182.15433","-0.00102"
"64.20000","2.13703","1824.96545","0.02137","0.00676","182.49655","-0.00100"
"64.40000","2.14387","1829.61987","0.02144","0.00679","182.96199","-0.00099"
"64.60000","2.15044","1833.97388","0.02150","0.00678","183.39738","-0.00099"
"64.80000","2.15721","1838.84448","0.02157","0.00679","183.88445","-0.00099"
"65.00000","2.16377","1843.50928","0.02164","0.00680","184.35092","-0.00096"
"65.20000","2.17047","1848.54163","0.02170","0.00684","184.85416","-0.00096"
"65.40000","2.17702","1852.85046","0.02177","0.00686","185.28505","-0.00096"
"65.60000","2.18371","1855.46497","0.02184","0.00691","185.54649","-0.00093"
"65.80000","2.19054","1860.04602","0.02191","0.00693","186.00461","-0.00095"
"66.00000","2.19713","1864.02478","0.02197","0.00697","186.40248","-0.00097"
"66.20000","2.20376","1868.05542","0.02204","0.00698","186.80554","-0.00096"
"66.40000","2.21055","1872.69543","0.02211","0.00700","187.26955","-0.00096"
"66.60000","2.21708","1876.83032","0.02217","0.00703","187.68303","-0.00096"
"66.80000","2.22373","1881.07043","0.02224","0.00707","188.10704","-0.00096"
"67.00000","2.23046","1885.18091","0.02230","0.00711","188.51810","-0.00096"
"67.20000","2.23718","1887.12476","0.02237","0.00713","188.71248","-0.00096"
"67.40000","2.24379","1885.73376","0.02244","0.00714","188.57338","-0.00093"
"67.60000","2.25035","1883.70593","0.02250","0.00714","188.37059","-0.00095"
"67.75600","2.25572","1722.55286","0.02256","0.00710","172.25528","-0.00099"
"67.76500","2.25605","1416.35632","0.02256","0.00678","141.63564","-0.00100"
"67.77300","2.25636","1114.86890","0.02256","0.00602","111.48689","-0.00100"