File: Tension/Section_2_Group_4/f9a_1.is_tens_RawData/Specimen_RawData_1.csv
Time,Extension,Load,Tensile strain (Extension),Tensile stress,Strain-by-clip-gage
(s),(mm),(N),(mm/mm),(MPa),(mm/mm)
"0.00000","0.00000","-0.44981","0.00000","-0.04498","0.00000"
"0.10000","0.00086","2.13746","0.00001","0.21375","0.00000"
"0.20000","0.00234","7.48475","0.00002","0.74848","0.00002"
"0.30000","0.00713","25.17953","0.00007","2.51795","0.00001"
"0.40000","0.01059","37.00938","0.00011","3.70094","-0.00002"
"0.50000","0.01400","48.35486","0.00014","4.83549","0.00001"
"0.60000","0.01742","59.39944","0.00017","5.93994","-0.00002"
"0.70000","0.02067","69.31816","0.00021","6.93182","0.00002"
"0.80000","0.02421","79.35910","0.00024","7.93591","0.00000"
"0.90000","0.02755","87.83384","0.00028","8.78338","0.00000"
"1.00000","0.03076","95.53436","0.00031","9.55344","0.00000"
"1.10000","0.03403","104.06638","0.00034","10.40664","-0.00001"
"1.20000","0.03740","113.12749","0.00037","11.31275","0.00001"
"1.30000","0.04071","121.92358","0.00041","12.19236","-0.00002"
"1.40000","0.04404","130.86835","0.00044","13.08683","0.00002"
"1.50000","0.04741","139.92761","0.00047","13.99276","-0.00002"
"1.60000","0.05081","148.92250","0.00051","14.89225","0.00001"
"1.70000","0.05401","157.45288","0.00054","15.74529","0.00000"
"1.80000","0.05732","166.34534","0.00057","16.63453","-0.00001"
"1.90000","0.06077","175.48305","0.00061","17.54831","0.00000"
"2.00000","0.06405","184.04922","0.00064","18.40492","0.00000"
"2.10000","0.06741","192.80116","0.00067","19.28012","0.00000"
"2.20000","0.07076","201.46831","0.00071","20.14683","0.00000"
"2.30000","0.07409","210.10715","0.00074","21.01072","0.00000"
"2.40000","0.07737","218.35892","0.00077","21.83589","-0.00001"
"2.50000","0.08085","227.17319","0.00081","22.71732","0.00001"
"2.60000","0.08419","235.56033","0.00084","23.55603","-0.00001"
"2.70000","0.08742","243.61388","0.00087","24.36139","0.00000"
"2.80000","0.09080","251.87489","0.00091","25.18749","0.00000"
"2.90000","0.09402","259.76535","0.00094","25.97654","0.00000"
"3.00000","0.09746","268.25974","0.00097","26.82597","0.00000"
"3.10000","0.10067","275.97931","0.00101","27.59793","0.00000"
"3.20000","0.10416","284.57254","0.00104","28.45725","0.00000"
"3.30000","0.10748","292.47653","0.00107","29.24765","0.00000"
"3.40000","0.11073","300.12903","0.00111","30.01290","0.00000"
"3.50000","0.11412","308.33243","0.00114","30.83324","0.00000"
"3.60000","0.11736","315.72504","0.00117","31.57250","0.00000"
"3.70000","0.12069","323.57486","0.00121","32.35749","0.00000"
"3.80000","0.12404","331.29480","0.00124","33.12948","0.00000"
"3.90000","0.12752","339.56940","0.00128","33.95694","0.00000"
"4.00000","0.13080","346.93872","0.00131","34.69387","0.00000"
"4.10000","0.13401","354.10675","0.00134","35.41068","-0.00001"
"4.20000","0.13746","362.09894","0.00137","36.20989","0.00000"
"4.30000","0.14077","369.54483","0.00141","36.95448","0.00000"
"4.40000","0.14406","376.78964","0.00144","37.67896","0.00000"
"4.50000","0.14740","384.18295","0.00147","38.41830","0.00000"
"4.60000","0.15090","392.11804","0.00151","39.21180","0.00000"
"4.70000","0.15415","399.25156","0.00154","39.92516","0.00001"
"4.80000","0.15738","406.21436","0.00157","40.62144","0.00000"
"4.90000","0.16077","413.63071","0.00161","41.36307","0.00000"
"5.00000","0.16411","420.78491","0.00164","42.07849","0.00000"
"5.10000","0.16735","427.76111","0.00167","42.77611","0.00000"
"5.20000","0.17072","435.05075","0.00171","43.50507","0.00000"
"5.30000","0.17416","442.68207","0.00174","44.26821","0.00000"
"5.40000","0.17741","449.23743","0.00177","44.92374","0.00000"
"5.50000","0.18061","456.04907","0.00181","45.60491","0.00000"
"5.60000","0.18419","463.90881","0.00184","46.39088","0.00000"
"5.70000","0.18743","470.54758","0.00187","47.05476","0.00000"
"5.80000","0.19068","477.14218","0.00191","47.71422","0.00000"
"5.90000","0.19406","484.47348","0.00194","48.44735","0.00000"
"6.00000","0.19742","491.28101","0.00197","49.12810","0.00000"
"6.10000","0.20073","498.16367","0.00201","49.81637","-0.00001"
"6.20000","0.20406","505.10104","0.00204","50.51011","0.00000"
"6.30000","0.20756","512.37128","0.00208","51.23713","0.00000"
"6.40000","0.21097","519.48016","0.00211","51.94802","-0.00001"
"6.50000","0.21404","525.12073","0.00214","52.51207","0.00000"
"6.60000","0.21747","532.35339","0.00217","53.23534","0.00000"
"6.70000","0.22067","538.42694","0.00221","53.84269","0.00000"
"6.80000","0.22402","545.24255","0.00224","54.52425","0.00000"
"6.90000","0.22730","551.68408","0.00227","55.16841","0.00000"
"7.00000","0.23080","558.87402","0.00231","55.88740","0.00000"
"7.10000","0.23426","565.92053","0.00234","56.59205","-0.00001"
"7.20000","0.23730","571.47870","0.00237","57.14787","0.00000"
"7.30000","0.24069","578.29309","0.00241","57.82931","0.00000"
"7.40000","0.24413","585.02045","0.00244","58.50204","0.00000"
"7.50000","0.24735","591.11438","0.00247","59.11144","0.00000"
"7.60000","0.25071","597.71185","0.00251","59.77119","-0.00001"
"7.70000","0.25413","604.34045","0.00254","60.43404","0.00000"
"7.80000","0.25755","610.90186","0.00258","61.09019","0.00000"
"7.90000","0.26066","616.40155","0.00261","61.64016","0.00000"
"8.00000","0.26415","623.38635","0.00264","62.33863","0.00000"
"8.10000","0.26752","629.54456","0.00268","62.95446","0.00000"
"8.20000","0.27079","635.54175","0.00271","63.55418","0.00000"
"8.30000","0.27407","641.59802","0.00274","64.15981","0.00000"
"8.40000","0.27748","648.08508","0.00277","64.80851","0.00000"
"8.50000","0.28080","654.04730","0.00281","65.40473","0.00000"
"8.60000","0.28397","659.63629","0.00284","65.96363","0.00000"
"8.70000","0.28746","666.40161","0.00287","66.64016","-0.00001"
"8.80000","0.29082","672.53607","0.00291","67.25361","0.00001"
"8.90000","0.29411","678.37250","0.00294","67.83725","0.00000"
"9.00000","0.29741","684.16736","0.00297","68.41673","0.00000"
"9.10000","0.30069","690.01544","0.00301","69.00154","0.00000"
"9.20000","0.30407","695.93994","0.00304","69.59399","-0.00001"
"9.30000","0.30735","701.79633","0.00307","70.17963","0.00000"
"9.40000","0.31082","707.95392","0.00311","70.79539","0.00000"
"9.50000","0.31419","714.10590","0.00314","71.41059","0.00000"
"9.60000","0.31739","719.53516","0.00317","71.95351","0.00000"
"9.70000","0.32073","725.41254","0.00321","72.54125","0.00000"
"9.80000","0.32409","731.38379","0.00324","73.13838","0.00000"
"9.90000","0.32740","736.91534","0.00327","73.69154","0.00000"
"10.00000","0.33077","742.80731","0.00331","74.28073","0.00000"
"10.10000","0.33420","748.86584","0.00334","74.88658","0.00000"
"10.20000","0.33754","754.46704","0.00338","75.44670","-0.00001"
"10.30000","0.34071","759.50848","0.00341","75.95085","0.00001"
"10.40000","0.34409","765.51770","0.00344","76.55177","0.00000"
"10.50000","0.34740","770.99030","0.00347","77.09903","0.00000"
"10.60000","0.35068","776.51294","0.00351","77.65129","0.00000"
"10.70000","0.35410","782.37177","0.00354","78.23717","0.00000"
"10.80000","0.35747","787.98309","0.00357","78.79831","0.00000"
"10.90000","0.36080","793.58246","0.00361","79.35825","-0.00001"
"11.00000","0.36397","798.51160","0.00364","79.85116","0.00000"
"11.10000","0.36739","804.32941","0.00367","80.43294","0.00000"
"11.20000","0.37078","810.04071","0.00371","81.00407","0.00000"
"11.30000","0.37400","815.08057","0.00374","81.50806","0.00000"
"11.40000","0.37744","820.84790","0.00377","82.08479","0.00000"
"11.50000","0.38081","826.32825","0.00381","82.63283","0.00000"
"11.60000","0.38413","831.57495","0.00384","83.15749","0.00000"
"11.70000","0.38739","836.72076","0.00387","83.67207","-0.00001"
"11.80000","0.39082","842.40662","0.00391","84.24066","0.00001"
"11.90000","0.39423","847.88037","0.00394","84.78804","0.00000"
"12.00000","0.39736","852.56390","0.00397","85.25639","0.00000"
"12.10000","0.40079","858.25299","0.00401","85.82530","0.00000"
"12.20000","0.40406","863.23767","0.00404","86.32377","0.00000"
"12.30000","0.40737","868.42273","0.00407","86.84227","0.00001"
"12.40000","0.41063","873.50085","0.00411","87.35008","-0.00001"
"12.50000","0.41422","879.49316","0.00414","87.94932","0.00001"
"12.60000","0.41752","884.52008","0.00418","88.45201","0.00000"
"12.70000","0.42065","888.99585","0.00421","88.89958","0.00000"
"12.80000","0.42409","894.47705","0.00424","89.44771","0.00000"
"12.90000","0.42735","899.33386","0.00427","89.93339","0.00000"
"13.00000","0.43071","904.45020","0.00431","90.44502","0.00000"
"13.10000","0.43397","909.29083","0.00434","90.92908","0.00000"
"13.20000","0.43756","915.15833","0.00438","91.51583","0.00000"
"13.30000","0.44091","920.18622","0.00441","92.01862","0.00000"
"13.40000","0.44403","924.62592","0.00444","92.46259","0.00000"
"13.50000","0.44746","929.81512","0.00447","92.98151","0.00000"
"13.60000","0.45075","934.67468","0.00451","93.46747","0.00000"
"13.70000","0.45409","939.72144","0.00454","93.97215","0.00000"
"13.80000","0.45735","944.53467","0.00457","94.45347","0.00000"
"13.90000","0.46085","949.97089","0.00461","94.99709","0.00000"
"14.00000","0.46415","954.70001","0.00464","95.47000","0.00000"
"14.10000","0.46732","959.00531","0.00467","95.90053","0.00000"
"14.20000","0.47075","964.31000","0.00471","96.43100","-0.00001"
"14.30000","0.47417","969.31549","0.00474","96.93155","0.00000"
"14.40000","0.47740","973.65100","0.00477","97.36510","0.00000"
"14.50000","0.48071","978.41333","0.00481","97.84133","0.00000"
"14.60000","0.48414","983.40381","0.00484","98.34038","0.00000"
"14.70000","0.48739","987.74072","0.00487","98.77407","0.00000"
"14.80000","0.49063","992.27716","0.00491","99.22771","0.00000"
"14.90000","0.49411","997.31824","0.00494","99.73183","0.00000"
"15.00000","0.49757","1002.39673","0.00498","100.23967","0.00000"
"15.10000","0.50074","1006.44250","0.00501","100.64425","0.00000"
"15.20000","0.50408","1011.03632","0.00504","101.10363","0.00000"
"15.30000","0.50746","1015.65485","0.00507","101.56548","0.00000"
"15.40000","0.51073","1019.99884","0.00511","101.99989","0.00000"
"15.50000","0.51405","1024.54614","0.00514","102.45461","-0.00001"
"15.60000","0.51751","1029.41614","0.00518","102.94161","0.00001"
"15.70000","0.52096","1034.16821","0.00521","103.41682","0.00000"
"15.80000","0.52405","1037.71167","0.00524","103.77116","0.00000"
"15.90000","0.52741","1042.11816","0.00527","104.21181","0.00000"
"16.00000","0.53069","1046.35400","0.00531","104.63540","0.00000"
"16.10000","0.53405","1050.74304","0.00534","105.07430","0.00000"
"16.20000","0.53739","1054.96509","0.00537","105.49651","0.00000"
"16.30000","0.54078","1059.45569","0.00541","105.94557","0.00000"
"16.40000","0.54422","1064.00476","0.00544","106.40047","0.00000"
"16.50000","0.54733","1067.36682","0.00547","106.73668","0.00000"
"16.60000","0.55075","1071.72559","0.00551","107.17256","0.00000"
"16.70000","0.55407","1075.81042","0.00554","107.58104","0.00000"
"16.80000","0.55740","1079.91504","0.00557","107.99150","0.00000"
"16.90000","0.56079","1084.18591","0.00561","108.41859","0.00000"
"17.00000","0.56418","1088.35510","0.00564","108.83551","0.00000"
"17.10000","0.56750","1092.31982","0.00568","109.23198","0.00000"
"17.20000","0.57070","1095.87158","0.00571","109.58716","0.00000"
"17.30000","0.57419","1100.41541","0.00574","110.04154","-0.00001"
"17.40000","0.57743","1104.01331","0.00577","110.40133","0.00001"
"17.50000","0.58077","1108.09521","0.00581","110.80952","0.00000"
"17.60000","0.58405","1111.91858","0.00584","111.19186","0.00000"
"17.70000","0.58747","1116.07764","0.00587","111.60777","0.00000"
"17.80000","0.59070","1119.76038","0.00591","111.97604","0.00000"
"17.90000","0.59400","1123.42188","0.00594","112.34219","0.00001"
"18.00000","0.59754","1127.80762","0.00598","112.78076","-0.00001"
"18.10000","0.60080","1131.62256","0.00601","113.16225","0.00000"
"18.20000","0.60407","1135.05286","0.00604","113.50529","-0.00001"
"18.30000","0.60740","1138.76453","0.00607","113.87645","0.00000"
"18.40000","0.61074","1142.45728","0.00611","114.24573","0.00000"
"18.50000","0.61403","1146.12769","0.00614","114.61277","0.00000"
"18.60000","0.61736","1149.89966","0.00617","114.98997","0.00000"
"18.70000","0.62085","1154.13745","0.00621","115.41374","0.00000"
"18.80000","0.62424","1158.01514","0.00624","115.80151","0.00000"
"18.90000","0.62741","1161.12671","0.00627","116.11267","0.00000"
"19.00000","0.63072","1164.76636","0.00631","116.47664","0.00000"
"19.10000","0.63418","1168.66321","0.00634","116.86632","0.00000"
"19.20000","0.63729","1171.48511","0.00637","117.14851","0.00000"
"19.30000","0.64076","1175.75549","0.00641","117.57555","-0.00001"
"19.40000","0.64416","1179.31287","0.00644","117.93129","0.00001"
"19.50000","0.64752","1183.05127","0.00648","118.30513","-0.00001"
"19.60000","0.65064","1185.79199","0.00651","118.57920","0.00000"
"19.70000","0.65412","1189.83142","0.00654","118.98314","0.00000"
"19.80000","0.65745","1193.35461","0.00657","119.33546","-0.00001"
"19.90000","0.66067","1196.47278","0.00661","119.64728","0.00000"
"20.00000","0.66405","1200.07947","0.00664","120.00795","-0.00001"
"20.10000","0.66745","1203.78943","0.00667","120.37894","0.00000"
"20.20000","0.67081","1207.38513","0.00671","120.73851","0.00000"
"20.30000","0.67394","1210.24963","0.00674","121.02496","-0.00001"
"20.40000","0.67748","1214.26978","0.00677","121.42698","0.00001"
"20.50000","0.68081","1217.41138","0.00681","121.74113","0.00000"
"20.60000","0.68405","1220.33130","0.00684","122.03313","0.00000"
"20.70000","0.68746","1223.96570","0.00687","122.39657","0.00000"
"20.80000","0.69075","1227.02771","0.00691","122.70277","0.00000"
"20.90000","0.69421","1230.56433","0.00694","123.05643","0.00000"
"21.00000","0.69729","1233.14819","0.00697","123.31482","0.00000"
"21.10000","0.70087","1237.26489","0.00701","123.72649","0.00000"
"21.20000","0.70420","1240.55994","0.00704","124.05599","0.00000"
"21.30000","0.70740","1243.33630","0.00707","124.33363","0.00000"
"21.40000","0.71069","1246.54578","0.00711","124.65458","0.00000"
"21.50000","0.71406","1249.95703","0.00714","124.99570","0.00000"
"21.60000","0.71743","1253.27734","0.00717","125.32774","0.00000"
"21.70000","0.72061","1256.03430","0.00721","125.60343","0.00000"
"21.80000","0.72414","1260.00842","0.00724","126.00084","-0.00001"
"21.90000","0.72753","1263.25818","0.00728","126.32582","0.00000"
"22.00000","0.73073","1265.96863","0.00731","126.59686","0.00000"
"22.10000","0.73403","1269.01379","0.00734","126.90138","0.00000"
"22.20000","0.73743","1272.24744","0.00737","127.22475","0.00000"
"22.30000","0.74074","1275.30066","0.00741","127.53007","-0.00001"
"22.40000","0.74404","1278.29626","0.00744","127.82963","0.00001"
"22.50000","0.74755","1281.83081","0.00748","128.18307","0.00000"
"22.60000","0.75087","1284.96191","0.00751","128.49619","0.00000"
"22.70000","0.75411","1287.81665","0.00754","128.78166","0.00001"
"22.80000","0.75738","1290.70837","0.00757","129.07083","0.00000"
"22.90000","0.76083","1294.24353","0.00761","129.42435","0.00000"
"23.00000","0.76403","1296.72107","0.00764","129.67210","0.00000"
"23.10000","0.76739","1300.12463","0.00767","130.01247","0.00000"
"23.20000","0.77076","1303.24133","0.00771","130.32413","0.00000"
"23.30000","0.77416","1306.48792","0.00774","130.64879","0.00000"
"23.40000","0.77736","1309.16870","0.00777","130.91687","0.00000"
"23.50000","0.78076","1312.53857","0.00781","131.25386","0.00000"
"23.60000","0.78411","1315.75745","0.00784","131.57574","0.00000"
"23.70000","0.78740","1318.67090","0.00787","131.86710","0.00000"
"23.80000","0.79077","1321.86218","0.00791","132.18622","0.00000"
"23.90000","0.79406","1324.82434","0.00794","132.48244","0.00000"
"24.00000","0.79742","1328.00061","0.00797","132.80006","0.00000"
"24.10000","0.80070","1330.92175","0.00801","133.09218","-0.00001"
"24.20000","0.80417","1334.56323","0.00804","133.45633","0.00000"
"24.30000","0.80756","1337.89661","0.00808","133.78966","0.00000"
"24.40000","0.81072","1340.59216","0.00811","134.05922","0.00000"
"24.50000","0.81414","1343.99231","0.00814","134.39923","0.00000"
"24.60000","0.81738","1346.88660","0.00817","134.68866","0.00000"
"24.70000","0.82075","1350.17053","0.00821","135.01706","0.00000"
"24.80000","0.82403","1353.33337","0.00824","135.33334","-0.00001"
"24.90000","0.82750","1357.09705","0.00828","135.70970","0.00000"
"25.00000","0.83082","1360.28040","0.00831","136.02805","0.00000"
"25.10000","0.83406","1363.15112","0.00834","136.31511","0.00000"
"25.20000","0.83746","1366.52136","0.00837","136.65213","0.00000"
"25.30000","0.84071","1369.42273","0.00841","136.94228","0.00000"
"25.40000","0.84401","1372.75146","0.00844","137.27515","0.00000"
"25.50000","0.84735","1376.10535","0.00847","137.61053","0.00000"
"25.60000","0.85082","1379.65820","0.00851","137.96582","0.00000"
"25.70000","0.85412","1383.00293","0.00854","138.30029","0.00001"
"25.80000","0.85732","1386.02429","0.00857","138.60243","0.00000"
"25.90000","0.86078","1389.63794","0.00861","138.96379","0.00000"
"26.00000","0.86411","1392.99084","0.00864","139.29909","0.00000"
"26.10000","0.86743","1396.24109","0.00867","139.62411","0.00000"
"26.20000","0.87077","1399.52673","0.00871","139.95267","0.00000"
"26.30000","0.87422","1403.32190","0.00874","140.33218","0.00000"
"26.40000","0.87747","1406.27100","0.00877","140.62711","0.00000"
"26.50000","0.88070","1409.37915","0.00881","140.93791","0.00001"
"26.60000","0.88412","1412.82495","0.00884","141.28250","-0.00001"
"26.70000","0.88748","1416.24854","0.00887","141.62485","0.00001"
"26.80000","0.89067","1419.19287","0.00891","141.91928","0.00000"
"26.90000","0.89407","1422.71082","0.00894","142.27109","0.00000"
"27.00000","0.89750","1426.28723","0.00897","142.62872","0.00000"
"27.10000","0.90069","1429.22485","0.00901","142.92249","-0.00001"
"27.20000","0.90394","1432.21277","0.00904","143.22128","0.00001"
"27.30000","0.90751","1436.29541","0.00908","143.62955","0.00000"
"27.40000","0.91086","1439.62427","0.00911","143.96243","0.00000"
"27.50000","0.91406","1442.46484","0.00914","144.24649","0.00000"
"27.60000","0.91739","1445.89722","0.00917","144.58972","0.00000"
"27.70000","0.92074","1449.17200","0.00921","144.91721","0.00000"
"27.80000","0.92406","1452.26355","0.00924","145.22635","0.00000"
"27.90000","0.92740","1455.66895","0.00927","145.56689","-0.00001"
"28.00000","0.93088","1459.29724","0.00931","145.92972","0.00001"
"28.10000","0.93429","1462.84412","0.00934","146.28441","0.00000"
"28.20000","0.93732","1465.30347","0.00937","146.53035","0.00000"
"28.30000","0.94080","1468.91016","0.00941","146.89102","0.00000"
"28.40000","0.94404","1471.96448","0.00944","147.19644","0.00000"
"28.50000","0.94735","1475.22754","0.00947","147.52275","0.00000"
"28.60000","0.95071","1478.58301","0.00951","147.85831","0.00000"
"28.70000","0.95414","1482.20166","0.00954","148.22017","0.00000"
"28.80000","0.95760","1485.77747","0.00958","148.57774","0.00000"
"28.90000","0.96064","1488.16187","0.00961","148.81619","0.00000"
"29.00000","0.96400","1491.49927","0.00964","149.14993","0.00000"
"29.10000","0.96748","1495.15076","0.00967","149.51508","0.00000"
"29.20000","0.97070","1498.17639","0.00971","149.81764","0.00000"
"29.30000","0.97404","1501.35608","0.00974","150.13560","0.00000"
"29.40000","0.97747","1504.91565","0.00977","150.49156","-0.00001"
"29.50000","0.98082","1508.18494","0.00981","150.81850","0.00001"
"29.60000","0.98401","1510.94678","0.00984","151.09468","0.00000"
"29.70000","0.98752","1514.88635","0.00988","151.48863","0.00000"
"29.80000","0.99086","1518.03406","0.00991","151.80341","0.00000"
"29.90000","0.99416","1521.08777","0.00994","152.10878","0.00000"
"30.00000","0.99741","1524.16809","0.00997","152.41681","0.00000"
"30.10000","1.00075","1527.35437","0.01001","152.73544","0.00000"
"30.20000","1.00410","1530.57275","0.01004","153.05728","0.00000"
"30.30000","1.00730","1533.43970","0.01007","153.34396","0.00001"
"30.40000","1.01080","1537.13757","0.01011","153.71376","-0.00001"
"30.50000","1.01421","1540.65295","0.01014","154.06529","0.00000"
"30.60000","1.01743","1543.40662","0.01017","154.34067","0.00000"
"30.70000","1.02075","1546.63879","0.01021","154.66388","0.00000"
"30.80000","1.02399","1549.51770","0.01024","154.95177","0.00000"
"30.90000","1.02736","1552.85547","0.01027","155.28555","-0.00001"
"31.00000","1.03072","1556.09387","0.01031","155.60939","0.00001"
"31.10000","1.03414","1559.59387","0.01034","155.95938","0.00000"
"31.20000","1.03752","1563.01611","0.01038","156.30161","0.00000"
"31.30000","1.04072","1565.67883","0.01041","156.56789","0.00000"
"31.40000","1.04406","1568.92078","0.01044","156.89207","0.00000"
"31.50000","1.04744","1572.24890","0.01047","157.22488","0.00000"
"31.60000","1.05073","1575.23010","0.01051","157.52301","-0.00001"
"31.70000","1.05412","1578.69946","0.01054","157.86995","0.00000"
"31.80000","1.05751","1581.84949","0.01058","158.18495","0.00000"
"31.90000","1.06085","1585.04675","0.01061","158.50467","-0.00001"
"32.00000","1.06404","1587.79858","0.01064","158.77986","0.00000"
"32.10000","1.06742","1591.11804","0.01067","159.11180","0.00000"
"32.20000","1.07073","1594.16687","0.01071","159.41669","0.00000"
"32.30000","1.07404","1597.25085","0.01074","159.72508","0.00000"
"32.40000","1.07744","1600.60583","0.01077","160.06058","0.00000"
"32.50000","1.08079","1603.75586","0.01081","160.37558","0.00000"
"32.60000","1.08410","1606.87622","0.01084","160.68762","0.00000"
"32.70000","1.08732","1609.62939","0.01087","160.96294","0.00000"
"32.80000","1.09079","1613.06909","0.01091","161.30692","0.00001"
"32.90000","1.09413","1616.15613","0.01094","161.61562","0.00000"
"33.00000","1.09734","1619.03076","0.01097","161.90308","0.00000"
"33.10000","1.10082","1622.59583","0.01101","162.25958","0.00000"
"33.20000","1.10414","1625.55200","0.01104","162.55521","0.00000"
"33.30000","1.10743","1628.33313","0.01107","162.83331","0.00001"
"33.40000","1.11071","1631.17224","0.01111","163.11722","-0.00001"
"33.50000","1.11415","1634.60596","0.01114","163.46060","0.00000"
"33.60000","1.11757","1637.96716","0.01118","163.79672","0.00000"
"33.70000","1.12072","1640.50623","0.01121","164.05063","-0.00001"
"33.80000","1.12410","1643.79565","0.01124","164.37956","0.00000"
"33.90000","1.12738","1646.70496","0.01127","164.67050","-0.00001"
"34.00000","1.13070","1649.78137","0.01131","164.97813","0.00000"
"34.10000","1.13398","1652.67395","0.01134","165.26740","0.00000"
"34.20000","1.13757","1656.40527","0.01138","165.64053","0.00000"
"34.30000","1.14085","1659.34583","0.01141","165.93459","0.00000"
"34.40000","1.14401","1661.71606","0.01144","166.17160","0.00000"
"34.50000","1.14742","1665.08850","0.01147","166.50885","0.00000"
"34.60000","1.15069","1667.81567","0.01151","166.78157","0.00000"
"34.70000","1.15407","1670.94800","0.01154","167.09480","0.00000"
"34.80000","1.15732","1673.72437","0.01157","167.37244","0.00001"
"34.90000","1.16090","1677.41943","0.01161","167.74194","0.00000"
"35.00000","1.16421","1680.27856","0.01164","168.02786","0.00000"
"35.10000","1.16735","1682.73511","0.01167","168.27351","0.00000"
"35.20000","1.17079","1686.07458","0.01171","168.60745","0.00000"
"35.30000","1.17408","1688.90039","0.01174","168.89005","0.00000"
"35.40000","1.17745","1691.88477","0.01177","169.18848","0.00000"
"35.50000","1.18074","1694.83447","0.01181","169.48344","0.00000"
"35.60000","1.18415","1698.11304","0.01184","169.81131","0.00000"
"35.70000","1.18747","1700.91516","0.01187","170.09152","-0.00001"
"35.80000","1.19067","1703.46887","0.01191","170.34689","0.00000"
"35.90000","1.19411","1706.93420","0.01194","170.69342","0.00000"
"36.00000","1.19753","1710.09692","0.01198","171.00969","0.00000"
"36.10000","1.20073","1712.49402","0.01201","171.24940","0.00000"
"36.20000","1.20402","1715.55164","0.01204","171.55516","-0.00001"
"36.30000","1.20745","1718.73608","0.01207","171.87361","0.00000"
"36.40000","1.21069","1721.38159","0.01211","172.13815","0.00000"
"36.50000","1.21397","1724.27991","0.01214","172.42799","0.00000"
"36.60000","1.21744","1727.78772","0.01217","172.77878","0.00000"
"36.70000","1.22092","1731.05151","0.01221","173.10515","0.00000"
"36.80000","1.22409","1733.40405","0.01224","173.34041","0.00000"
"36.90000","1.22744","1736.50610","0.01227","173.65060","0.00000"
"37.00000","1.23080","1739.30933","0.01231","173.93094","0.00000"
"37.10000","1.23402","1741.86084","0.01234","174.18608","0.00000"
"37.20000","1.23740","1744.89392","0.01237","174.48940","-0.00001"
"37.30000","1.24083","1748.35413","0.01241","174.83542","0.00000"
"37.40000","1.24429","1751.49854","0.01244","175.14986","0.00000"
"37.50000","1.24734","1753.63940","0.01247","175.36394","0.00000"
"37.60000","1.25073","1756.67773","0.01251","175.66777","0.00000"
"37.70000","1.25406","1759.65686","0.01254","175.96568","-0.00001"
"37.80000","1.25737","1762.57825","0.01257","176.25783","0.00000"
"37.90000","1.26072","1765.55591","0.01261","176.55559","0.00000"
"38.00000","1.26410","1768.49011","0.01264","176.84901","0.00000"
"38.10000","1.26751","1771.77307","0.01268","177.17731","0.00001"
"38.20000","1.27067","1774.04810","0.01271","177.40482","0.00000"
"38.30000","1.27410","1777.34680","0.01274","177.73468","0.00000"
"38.40000","1.27741","1780.21655","0.01277","178.02165","0.00000"
"38.50000","1.28074","1782.95081","0.01281","178.29507","0.00000"
"38.60000","1.28412","1786.08728","0.01284","178.60873","0.00001"
"38.70000","1.28752","1789.19263","0.01288","178.91927","-0.00001"
"38.80000","1.29081","1791.77100","0.01291","179.17709","0.00000"
"38.90000","1.29403","1794.27783","0.01294","179.42778","0.00000"
"39.00000","1.29753","1797.80444","0.01298","179.78044","0.00000"
"39.10000","1.30079","1800.37915","0.01301","180.03792","0.00000"
"39.20000","1.30410","1803.08313","0.01304","180.30832","0.00000"
"39.30000","1.30738","1805.78418","0.01307","180.57841","0.00000"
"39.40000","1.31076","1808.86218","0.01311","180.88622","0.00000"
"39.50000","1.31403","1811.52686","0.01314","181.15268","0.00000"
"39.60000","1.31735","1814.29224","0.01317","181.42923","0.00000"
"39.70000","1.32087","1817.77795","0.01321","181.77780","0.00000"
"39.80000","1.32416","1820.32324","0.01324","182.03232","0.00000"
"39.90000","1.32739","1822.97400","0.01327","182.29739","0.00000"
"40.00000","1.33073","1825.71875","0.01331","182.57187","0.00000"
"40.10000","1.33409","1828.51611","0.01334","182.85161","0.00000"
"40.20000","1.33730","1830.97327","0.01337","183.09732","0.00000"
"40.30000","1.34071","1834.02881","0.01341","183.40288","0.00000"
"40.40000","1.34418","1837.36035","0.01344","183.73604","0.00001"
"40.50000","1.34753","1840.15015","0.01348","184.01501","0.00000"
"40.60000","1.35075","1842.60718","0.01351","184.26071","0.00000"
"40.70000","1.35406","1845.25452","0.01354","184.52545","0.00000"
"40.80000","1.35752","1848.47302","0.01358","184.84731","0.00000"
"40.90000","1.36067","1850.66699","0.01361","185.06670","0.00000"
"41.00000","1.36411","1853.68250","0.01364","185.36826","-0.00001"
"41.10000","1.36751","1856.64612","0.01368","185.66461","0.00000"
"41.20000","1.37085","1859.40149","0.01371","185.94016","0.00000"
"41.30000","1.37398","1861.54321","0.01374","186.15433","0.00000"
"41.40000","1.37746","1864.89417","0.01377","186.48941","0.00000"
"41.50000","1.38077","1867.48987","0.01381","186.74899","0.00000"
"41.60000","1.38399","1869.98291","0.01384","186.99829","0.00000"
"41.70000","1.38742","1873.22461","0.01387","187.32246","0.00000"
"41.80000","1.39078","1875.85498","0.01391","187.58549","0.00000"
"41.90000","1.39412","1878.64465","0.01394","187.86447","0.00001"
"42.00000","1.39725","1880.86047","0.01397","188.08604","0.00000"
"42.10000","1.40085","1884.58984","0.01401","188.45898","0.00000"
"42.20000","1.40417","1887.18677","0.01404","188.71867","0.00000"
"42.30000","1.40737","1889.54858","0.01407","188.95486","0.00000"
"42.40000","1.41082","1892.65576","0.01411","189.26558","0.00000"
"42.50000","1.41406","1894.98962","0.01414","189.49896","-0.00001"
"42.60000","1.41752","1898.31799","0.01418","189.83180","0.00000"
"42.70000","1.42065","1900.40381","0.01421","190.04037","0.00000"
"42.80000","1.42424","1903.97961","0.01424","190.39796","0.00000"
"42.90000","1.42752","1906.45789","0.01428","190.64578","0.00000"
"43.00000","1.43074","1908.99023","0.01431","190.89902","0.00000"
"43.10000","1.43402","1911.73279","0.01434","191.17328","0.00000"
"43.20000","1.43739","1914.39368","0.01437","191.43936","0.00000"
"43.30000","1.44075","1917.19885","0.01441","191.71988","0.00000"
"43.40000","1.44396","1919.68066","0.01444","191.96806","0.00000"
"43.50000","1.44749","1923.06189","0.01447","192.30618","0.00000"
"43.60000","1.45086","1925.73425","0.01451","192.57343","-0.00001"
"43.70000","1.45405","1928.03796","0.01454","192.80380","0.00000"
"43.80000","1.45738","1930.93640","0.01457","193.09364","0.00000"
"43.90000","1.46078","1933.73633","0.01461","193.37363","0.00000"
"44.00000","1.46408","1936.37781","0.01464","193.63779","-0.00001"
"44.10000","1.46736","1938.90588","0.01467","193.89059","0.00000"
"44.20000","1.47087","1942.22998","0.01471","194.22299","0.00001"
"44.30000","1.47417","1944.77734","0.01474","194.47774","-0.00001"
"44.40000","1.47741","1947.32825","0.01477","194.73282","0.00000"
"44.50000","1.48071","1949.91992","0.01481","194.99199","0.00000"
"44.60000","1.48418","1953.00732","0.01484","195.30074","0.00000"
"44.70000","1.48738","1955.16577","0.01487","195.51657","0.00000"
"44.80000","1.49075","1958.01294","0.01491","195.80130","0.00000"
"44.90000","1.49409","1960.49719","0.01494","196.04971","0.00000"
"45.00000","1.49747","1963.37659","0.01497","196.33766","0.00000"
"45.10000","1.50071","1965.61755","0.01501","196.56175","0.00000"
"45.20000","1.50409","1968.47375","0.01504","196.84738","0.00000"
"45.30000","1.50749","1971.36719","0.01507","197.13672","0.00000"
"45.40000","1.51072","1973.57947","0.01511","197.35794","0.00001"
"45.50000","1.51408","1976.29236","0.01514","197.62924","-0.00001"
"45.60000","1.51738","1978.93713","0.01517","197.89371","0.00000"
"45.70000","1.52074","1981.54749","0.01521","198.15475","0.00000"
"45.80000","1.52401","1984.07007","0.01524","198.40701","-0.00001"
"45.90000","1.52750","1987.22632","0.01527","198.72263","0.00000"
"46.00000","1.53090","1990.20264","0.01531","199.02026","0.00000"
"46.10000","1.53407","1992.27039","0.01534","199.22704","0.00000"
"46.20000","1.53749","1995.18152","0.01537","199.51816","0.00000"
"46.30000","1.54070","1997.55481","0.01541","199.75548","0.00000"
"46.40000","1.54409","2000.28699","0.01544","200.02870","0.00000"
"46.50000","1.54737","2002.84924","0.01547","200.28493","0.00000"
"46.60000","1.55086","2006.09790","0.01551","200.60979","-0.00001"
"46.70000","1.55415","2008.51929","0.01554","200.85193","0.00000"
"46.80000","1.55737","2010.96851","0.01557","201.09685","0.00000"
"46.90000","1.56078","2013.89343","0.01561","201.38934","0.00000"
"47.00000","1.56402","2016.40332","0.01564","201.64034","0.00000"
"47.10000","1.56736","2019.15356","0.01567","201.91536","-0.00001"
"47.20000","1.57073","2022.09558","0.01571","202.20956","0.00001"
"47.30000","1.57417","2025.09497","0.01574","202.50949","-0.00001"
"47.40000","1.57743","2027.56226","0.01577","202.75623","0.00000"
"47.50000","1.58066","2030.09363","0.01581","203.00937","0.00000"
"47.60000","1.58412","2032.97681","0.01584","203.29768","0.00000"
"47.70000","1.58748","2035.89587","0.01587","203.58958","0.00000"
"47.80000","1.59077","2038.45984","0.01591","203.84598","-0.00001"
"47.90000","1.59411","2041.28552","0.01594","204.12856","0.00000"
"48.00000","1.59758","2044.22827","0.01598","204.42282","0.00000"
"48.10000","1.60074","2046.52100","0.01601","204.65210","0.00000"
"48.20000","1.60401","2049.28125","0.01604","204.92813","0.00000"
"48.30000","1.60745","2052.35938","0.01607","205.23593","0.00000"
"48.40000","1.61081","2055.15820","0.01611","205.51582","0.00000"
"48.50000","1.61403","2057.58374","0.01614","205.75838","0.00000"
"48.60000","1.61742","2060.66455","0.01617","206.06645","0.00000"
"48.70000","1.62079","2063.38940","0.01621","206.33894","0.00000"
"48.80000","1.62404","2065.84204","0.01624","206.58420","0.00000"
"48.90000","1.62730","2068.32861","0.01627","206.83286","-0.00001"
"49.00000","1.63085","2071.91211","0.01631","207.19121","0.00000"
"49.10000","1.63420","2074.76440","0.01634","207.47644","0.00000"
"49.20000","1.63735","2076.83423","0.01637","207.68343","0.00000"
"49.30000","1.64074","2079.76538","0.01641","207.97653","-0.00001"
"49.40000","1.64407","2082.51904","0.01644","208.25191","0.00000"
"49.50000","1.64736","2084.95825","0.01647","208.49582","0.00000"
"49.60000","1.65077","2088.22607","0.01651","208.82260","-0.00001"
"49.70000","1.65422","2091.20288","0.01654","209.12029","0.00000"
"49.80000","1.65762","2094.23462","0.01658","209.42346","0.00000"
"49.90000","1.66067","2096.04956","0.01661","209.60495","0.00000"
"50.00000","1.66408","2099.06152","0.01664","209.90616","0.00000"
"50.10000","1.66738","2101.59155","0.01667","210.15915","0.00000"
"50.20000","1.67070","2104.43042","0.01671","210.44304","0.00000"
"50.30000","1.67403","2107.24243","0.01674","210.72424","-0.00001"
"50.40000","1.67754","2110.32397","0.01678","211.03239","0.00000"
"50.50000","1.68090","2113.11475","0.01681","211.31148","0.00000"
"50.60000","1.68397","2115.04541","0.01684","211.50455","-0.00001"
"50.70000","1.68738","2118.07812","0.01687","211.80782","0.00000"
"50.80000","1.69079","2121.02271","0.01691","212.10226","0.00000"
"50.90000","1.69403","2123.56738","0.01694","212.35674","0.00000"
"51.00000","1.69736","2126.31567","0.01697","212.63156","0.00000"
"51.10000","1.70077","2129.27563","0.01701","212.92757","-0.00001"
"51.20000","1.70416","2132.19043","0.01704","213.21904","0.00000"
"51.30000","1.70731","2134.34814","0.01707","213.43481","0.00000"
"51.40000","1.71084","2137.57471","0.01711","213.75748","-0.00001"
"51.50000","1.71423","2140.37231","0.01714","214.03723","0.00000"
"51.60000","1.71747","2142.84912","0.01717","214.28491","0.00000"
"51.70000","1.72073","2145.47900","0.01721","214.54790","0.00000"
"51.80000","1.72411","2148.12500","0.01724","214.81250","0.00000"
"51.90000","1.72739","2150.61914","0.01727","215.06192","0.00000"
"52.00000","1.73069","2153.40845","0.01731","215.34085","0.00000"
"52.10000","1.73413","2156.46875","0.01734","215.64688","-0.00001"
"52.20000","1.73751","2159.41040","0.01738","215.94104","0.00000"
"52.30000","1.74077","2161.83179","0.01741","216.18318","0.00000"
"52.40000","1.74406","2164.45874","0.01744","216.44588","0.00000"
"52.50000","1.74733","2167.02148","0.01747","216.70215","0.00000"
"52.60000","1.75068","2169.72632","0.01751","216.97263","-0.00001"
"52.70000","1.75404","2172.65747","0.01754","217.26575","0.00000"
"52.80000","1.75750","2175.74902","0.01758","217.57491","0.00000"
"52.90000","1.76086","2178.53735","0.01761","217.85373","0.00000"
"53.00000","1.76407","2180.84155","0.01764","218.08415","0.00000"
"53.10000","1.76743","2183.48267","0.01767","218.34827","0.00000"
"53.20000","1.77079","2186.26343","0.01771","218.62634","0.00000"
"53.30000","1.77408","2188.86377","0.01774","218.88638","0.00000"
"53.40000","1.77746","2191.80322","0.01777","219.18033","0.00000"
"53.50000","1.78083","2194.50195","0.01781","219.45020","0.00000"
"53.60000","1.78419","2197.43994","0.01784","219.74399","0.00000"
"53.70000","1.78735","2199.42090","0.01787","219.94209","0.00000"
"53.80000","1.79074","2202.53687","0.01791","220.25369","0.00000"
"53.90000","1.79407","2205.22510","0.01794","220.52251","-0.00001"
"54.00000","1.79735","2207.81641","0.01797","220.78165","0.00000"
"54.10000","1.80079","2210.87842","0.01801","221.08784","0.00000"
"54.20000","1.80411","2213.53857","0.01804","221.35385","0.00000"
"54.30000","1.80744","2216.13843","0.01807","221.61385","0.00000"
"54.40000","1.81065","2218.44800","0.01811","221.84480","-0.00001"
"54.50000","1.81411","2221.60156","0.01814","222.16016","0.00000"
"54.60000","1.81749","2224.52539","0.01817","222.45255","0.00000"
"54.70000","1.82069","2226.72363","0.01821","222.67236","0.00000"
"54.80000","1.82414","2229.83350","0.01824","222.98335","0.00000"
"54.90000","1.82746","2232.44116","0.01827","223.24411","-0.00001"
"55.00000","1.83074","2234.93091","0.01831","223.49309","0.00000"
"55.10000","1.83404","2237.50195","0.01834","223.75020","0.00000"
"55.20000","1.83750","2240.72534","0.01838","224.07254","0.00000"
"55.30000","1.84089","2243.51465","0.01841","224.35147","0.00000"
"55.40000","1.84406","2245.89990","0.01844","224.59000","0.00000"
"55.50000","1.84745","2248.68848","0.01847","224.86885","0.00000"
"55.60000","1.85073","2251.15601","0.01851","225.11560","0.00000"
"55.70000","1.85401","2253.60278","0.01854","225.36028","-0.00001"
"55.80000","1.85730","2256.23071","0.01857","225.62308","0.00000"
"55.90000","1.86091","2259.79639","0.01861","225.97964","0.00000"
"56.00000","1.86418","2262.28491","0.01864","226.22849","0.00000"
"56.10000","1.86732","2264.37573","0.01867","226.43758","0.00000"
"56.20000","1.87075","2267.38745","0.01871","226.73874","-0.00001"
"56.30000","1.87400","2269.87720","0.01874","226.98772","0.00000"
"56.40000","1.87738","2272.50464","0.01877","227.25046","0.00000"
"56.50000","1.88066","2275.19897","0.01881","227.51990","0.00000"
"56.60000","1.88420","2278.42456","0.01884","227.84245","0.00000"
"56.70000","1.88755","2281.13428","0.01888","228.11343","0.00000"
"56.80000","1.89069","2283.30762","0.01891","228.33076","0.00000"
"56.90000","1.89418","2286.48389","0.01894","228.64839","0.00000"
"57.00000","1.89746","2289.10742","0.01897","228.91074","0.00000"
"57.10000","1.90077","2291.46582","0.01901","229.14658","0.00000"
"57.20000","1.90409","2294.15356","0.01904","229.41536","0.00000"
"57.30000","1.90747","2296.84961","0.01907","229.68497","-0.00001"
"57.40000","1.91080","2299.47388","0.01911","229.94739","0.00000"
"57.50000","1.91400","2301.87183","0.01914","230.18718","0.00000"
"57.60000","1.91743","2304.87280","0.01917","230.48727","0.00000"
"57.70000","1.92085","2307.83423","0.01921","230.78342","-0.00001"
"57.80000","1.92405","2310.08008","0.01924","231.00801","0.00000"
"57.90000","1.92734","2312.62378","0.01927","231.26237","0.00000"
"58.00000","1.93077","2315.60596","0.01931","231.56059","0.00000"
"58.10000","1.93401","2317.91504","0.01934","231.79150","0.00000"
"58.20000","1.93732","2320.65552","0.01937","232.06555","-0.00001"
"58.30000","1.94082","2323.86377","0.01941","232.38638","0.00000"
"58.40000","1.94428","2326.71973","0.01944","232.67197","0.00000"
"58.50000","1.94742","2328.77808","0.01947","232.87781","0.00000"
"58.60000","1.95079","2331.57007","0.01951","233.15701","0.00000"
"58.70000","1.95413","2334.10498","0.01954","233.41049","0.00000"
"58.80000","1.95737","2336.52563","0.01957","233.65256","0.00000"
"58.90000","1.96072","2339.26465","0.01961","233.92647","0.00000"
"59.00000","1.96416","2342.10815","0.01964","234.21082","0.00000"
"59.10000","1.96761","2345.05225","0.01968","234.50522","0.00000"
"59.20000","1.97067","2346.95532","0.01971","234.69553","0.00000"
"59.30000","1.97405","2349.77002","0.01974","234.97701","0.00000"
"59.40000","1.97739","2352.40527","0.01977","235.24052","0.00000"
"59.50000","1.98072","2354.84888","0.01981","235.48489","0.00000"
"59.60000","1.98407","2357.54468","0.01984","235.75447","0.00000"
"59.70000","1.98742","2360.24146","0.01987","236.02414","0.00000"
"59.80000","1.99084","2362.91431","0.01991","236.29143","0.00000"
"59.90000","1.99401","2364.93750","0.01994","236.49374","0.00000"
"60.00000","1.99743","2367.81714","0.01997","236.78171","0.00000"
"60.10000","2.00077","2370.34180","0.02001","237.03418","0.00000"
"60.20000","2.00406","2372.90259","0.02004","237.29025","0.00000"
"60.30000","2.00743","2375.59302","0.02007","237.55930","0.00000"
"60.40000","2.01081","2378.37695","0.02011","237.83769","0.00000"
"60.50000","2.01412","2380.77539","0.02014","238.07755","-0.00001"
"60.60000","2.01734","2383.15405","0.02017","238.31540","0.00000"
"60.70000","2.02088","2386.29663","0.02021","238.62967","0.00000"
"60.80000","2.02416","2388.75513","0.02024","238.87552","0.00000"
"60.90000","2.02742","2391.05566","0.02027","239.10556","0.00000"
"61.00000","2.03073","2393.13525","0.02031","239.31352","0.00000"
"61.10000","2.03408","2395.52954","0.02034","239.55295","0.00000"
"61.20000","2.03736","2397.41943","0.02037","239.74194","-0.00001"
"61.30000","2.04070","2399.80957","0.02041","239.98096","0.00000"
"61.40000","2.04419","2401.60400","0.02044","240.16040","0.00000"
"61.50000","2.04751","2403.78467","0.02048","240.37846","0.00000"
"61.60000","2.05070","2405.79150","0.02051","240.57915","0.00000"
"61.70000","2.05407","2408.32593","0.02054","240.83260","-0.00001"
"61.80000","2.05743","2410.19263","0.02057","241.01926","0.00000"
"61.90000","2.06064","2411.15576","0.02061","241.11557","0.00000"
"62.00000","2.06402","2405.64917","0.02064","240.56491","0.00000"
"62.10000","2.06752","2403.37939","0.02068","240.33794","0.00000"
"62.20000","2.07090","2401.08667","0.02071","240.10867","0.00000"
"62.30000","2.07408","2395.69556","0.02074","239.56955","0.00000"
"62.40000","2.07740","2393.70361","0.02077","239.37036","0.00000"
"62.50000","2.08087","2385.17944","0.02081","238.51794","-0.00001"
"62.59700","2.08392","2229.76074","0.02084","222.97607","0.00000"
"62.60000","2.08402","2086.18335","0.02084","208.61833","0.00000"
"62.60300","2.08413","1911.84314","0.02084","191.18431","0.00000"
"62.60500","2.08421","1784.91321","0.02084","178.49132","0.00000"
"62.60700","2.08429","1653.16223","0.02084","165.31622","0.00001"
"62.60900","2.08437","1519.30298","0.02084","151.93030","0.00001"
"62.61100","2.08446","1385.65979","0.02084","138.56598","0.00002"