File: Tension/Section_2_Group_4/f10a.is_tens_RawData/Specimen_RawData_1.csv
Time,Extension,Load,Tensile strain (Extension),Tensile stress,Strain-by-clip-gage
(s),(mm),(N),(mm/mm),(MPa),(mm/mm)
"0.00000","0.00000","-0.27635","0.00000","-0.02763","0.00000"
"0.50000","0.01387","11.04970","0.00014","1.10497","0.00003"
"1.00000","0.03061","20.17568","0.00031","2.01757","0.00003"
"1.50000","0.04725","27.50779","0.00047","2.75078","0.00001"
"2.00000","0.06390","33.30921","0.00064","3.33092","0.00000"
"2.50000","0.08053","38.79431","0.00081","3.87943","0.00000"
"3.00000","0.09734","44.40974","0.00097","4.44097","0.00000"
"3.50000","0.11395","49.55676","0.00114","4.95568","0.00001"
"4.00000","0.13062","54.33881","0.00131","5.43388","0.00001"
"4.50000","0.14727","58.75891","0.00147","5.87589","0.00000"
"5.00000","0.16395","63.09316","0.00164","6.30932","0.00001"
"5.50000","0.18073","67.31681","0.00181","6.73168","0.00000"
"6.00000","0.19728","71.22365","0.00197","7.12236","0.00000"
"6.50000","0.21395","74.92370","0.00214","7.49237","0.00000"
"7.00000","0.23053","78.55495","0.00231","7.85549","0.00000"
"7.50000","0.24725","82.05305","0.00247","8.20531","0.00000"
"8.00000","0.26385","85.54147","0.00264","8.55415","0.00000"
"8.50000","0.28076","89.28069","0.00281","8.92807","0.00001"
"9.00000","0.29730","92.36195","0.00297","9.23619","0.00000"
"9.50000","0.31391","95.48132","0.00314","9.54813","0.00000"
"10.00000","0.33059","98.71503","0.00331","9.87150","0.00000"
"10.50000","0.34726","101.90243","0.00347","10.19024","0.00000"
"11.00000","0.36415","105.04948","0.00364","10.50495","0.00001"
"11.50000","0.38055","107.63523","0.00381","10.76352","0.00001"
"12.00000","0.39720","110.41787","0.00397","11.04179","0.00001"
"12.50000","0.41387","113.22264","0.00414","11.32226","0.00000"
"13.00000","0.43065","116.12225","0.00431","11.61222","-0.00001"
"13.50000","0.44726","118.64791","0.00447","11.86479","0.00000"
"14.00000","0.46406","121.37617","0.00464","12.13762","0.00000"
"14.50000","0.48054","123.67768","0.00481","12.36777","0.00000"
"15.00000","0.49729","126.48026","0.00497","12.64803","0.00000"
"15.50000","0.51402","128.99536","0.00514","12.89954","0.00000"
"16.00000","0.53064","131.42834","0.00531","13.14283","0.00000"
"16.50000","0.54734","133.75493","0.00547","13.37549","0.00000"
"17.00000","0.56378","135.93611","0.00564","13.59361","0.00000"
"17.50000","0.58059","138.35312","0.00581","13.83531","0.00000"
"18.00000","0.59729","140.61388","0.00597","14.06139","0.00000"
"18.50000","0.61398","142.96713","0.00614","14.29671","0.00000"
"19.00000","0.63058","145.06212","0.00631","14.50621","0.00000"
"19.50000","0.64733","147.55536","0.00647","14.75554","0.00000"
"20.00000","0.66395","149.40405","0.00664","14.94040","0.00000"
"20.50000","0.68063","151.60562","0.00681","15.16056","0.00000"
"21.00000","0.69732","153.88342","0.00697","15.38834","0.00000"
"21.50000","0.71395","155.83437","0.00714","15.58344","0.00001"
"22.00000","0.73062","157.84796","0.00731","15.78480","0.00000"
"22.50000","0.74714","159.81052","0.00747","15.98105","-0.00001"
"23.00000","0.76394","161.89096","0.00764","16.18910","-0.00001"
"23.50000","0.78053","163.87854","0.00781","16.38785","0.00000"
"24.00000","0.79736","166.15596","0.00797","16.61560","0.00000"
"24.50000","0.81386","167.73978","0.00814","16.77398","0.00000"
"25.00000","0.83067","170.05344","0.00831","17.00534","0.00000"
"25.50000","0.84732","171.73473","0.00847","17.17347","0.00000"
"26.00000","0.86393","173.69971","0.00864","17.36997","0.00000"
"26.50000","0.88072","175.81798","0.00881","17.58180","0.00000"
"27.00000","0.89730","177.52661","0.00897","17.75266","0.00000"
"27.50000","0.91389","179.33186","0.00914","17.93319","0.00000"
"28.00000","0.93051","181.16196","0.00931","18.11620","0.00000"
"28.50000","0.94733","183.13423","0.00947","18.31342","0.00000"
"29.00000","0.96390","184.86081","0.00964","18.48608","0.00000"
"29.50000","0.98073","186.80214","0.00981","18.68021","-0.00001"
"30.00000","0.99721","188.42186","0.00997","18.84219","0.00000"
"30.50000","1.01399","190.34064","0.01014","19.03406","-0.00001"
"31.00000","1.03069","192.11261","0.01031","19.21126","-0.00001"
"31.50000","1.04719","193.84927","0.01047","19.38493","0.00000"
"32.00000","1.06409","195.80540","0.01064","19.58054","-0.00001"
"32.50000","1.08058","197.25098","0.01081","19.72510","-0.00001"
"33.00000","1.09721","198.99658","0.01097","19.89966","-0.00001"
"33.50000","1.11388","200.76730","0.01114","20.07673","0.00000"
"34.00000","1.13072","202.47667","0.01131","20.24767","0.00000"
"34.50000","1.14731","204.28053","0.01147","20.42805","-0.00001"
"35.00000","1.16404","206.00362","0.01164","20.60036","-0.00001"
"35.50000","1.18051","207.43045","0.01181","20.74305","-0.00001"
"36.00000","1.19726","209.22542","0.01197","20.92254","0.00000"
"36.50000","1.21403","211.00468","0.01214","21.10047","0.00000"
"37.00000","1.23053","212.47359","0.01231","21.24736","0.00000"
"37.50000","1.24732","214.14578","0.01247","21.41458","0.00000"
"38.00000","1.26381","215.55708","0.01264","21.55571","0.00000"
"38.50000","1.28060","217.40555","0.01281","21.74055","0.00000"
"39.00000","1.29724","218.95831","0.01297","21.89583","0.00000"
"39.50000","1.31407","220.63600","0.01314","22.06360","0.00000"
"40.00000","1.33057","222.09724","0.01331","22.20972","0.00000"
"40.50000","1.34724","223.74547","0.01347","22.37455","0.00000"
"41.00000","1.36396","225.45172","0.01364","22.54517","0.00001"
"41.50000","1.38066","226.95010","0.01381","22.69501","0.00000"
"42.00000","1.39734","228.62817","0.01397","22.86282","0.00001"
"42.50000","1.41389","230.11479","0.01414","23.01148","0.00001"
"43.00000","1.43064","231.74092","0.01431","23.17409","0.00000"
"43.50000","1.44721","233.14278","0.01447","23.31428","0.00000"
"44.00000","1.46402","234.77655","0.01464","23.47766","0.00000"
"44.50000","1.48056","236.26706","0.01481","23.62671","0.00000"
"45.00000","1.49737","237.84355","0.01497","23.78436","0.00001"
"45.50000","1.51388","239.22127","0.01514","23.92213","0.00000"
"46.00000","1.53054","240.80357","0.01531","24.08036","0.00000"
"46.50000","1.54738","242.51100","0.01547","24.25110","0.00000"
"47.00000","1.56392","243.91647","0.01564","24.39165","0.00000"
"47.50000","1.58070","245.60713","0.01581","24.56071","0.00000"
"48.00000","1.59720","246.87688","0.01597","24.68769","0.00000"
"48.50000","1.61396","248.41626","0.01614","24.84163","0.00001"
"49.00000","1.63055","249.81644","0.01631","24.98164","0.00000"
"49.50000","1.64735","251.36177","0.01647","25.13618","0.00000"
"50.00000","1.66385","252.71974","0.01664","25.27197","0.00000"
"50.50000","1.68066","254.46031","0.01681","25.44603","0.00000"
"51.00000","1.69722","255.68146","0.01697","25.56815","0.00000"
"51.50000","1.71393","257.34583","0.01714","25.73458","0.00001"
"52.00000","1.73074","258.86948","0.01731","25.88695","0.00000"
"52.50000","1.74723","260.11319","0.01747","26.01132","0.00000"
"53.00000","1.76400","261.64890","0.01764","26.16489","0.00000"
"53.50000","1.78054","263.05011","0.01781","26.30501","0.00000"
"54.00000","1.79730","264.61609","0.01797","26.46161","0.00000"
"54.50000","1.81390","265.92404","0.01814","26.59240","0.00000"
"55.00000","1.83060","267.55212","0.01831","26.75521","0.00000"
"55.50000","1.84724","268.89450","0.01847","26.88945","0.00000"
"56.00000","1.86404","270.58200","0.01864","27.05820","0.00000"
"56.50000","1.88056","271.76495","0.01881","27.17649","0.00001"
"57.00000","1.89724","273.35464","0.01897","27.33546","0.00000"
"57.50000","1.91405","274.91095","0.01914","27.49109","0.00000"
"58.00000","1.93061","276.25421","0.01931","27.62542","-0.00001"
"58.50000","1.94729","277.69925","0.01947","27.76992","0.00000"
"59.00000","1.96377","278.88605","0.01964","27.88861","0.00000"
"59.50000","1.98059","280.52643","0.01981","28.05264","0.00000"
"60.00000","1.99725","282.05066","0.01997","28.20507","0.00000"
"60.50000","2.01401","283.56644","0.02014","28.35664","0.00000"
"61.00000","2.03055","284.84055","0.02031","28.48405","0.00000"
"61.50000","2.04724","286.21609","0.02047","28.62161","0.00000"
"62.00000","2.06399","287.79874","0.02064","28.77987","0.00000"
"62.50000","2.08062","289.30405","0.02081","28.93040","0.00000"
"63.00000","2.09744","290.83713","0.02097","29.08371","0.00000"
"63.50000","2.11388","291.93716","0.02114","29.19372","0.00000"
"64.00000","2.13054","293.36047","0.02131","29.33605","0.00000"
"64.50000","2.14718","294.91592","0.02147","29.49159","0.00000"
"65.00000","2.16405","296.42477","0.02164","29.64248","-0.00001"
"65.50000","2.18054","297.61176","0.02181","29.76118","-0.00001"
"66.00000","2.19736","299.21906","0.02197","29.92191","-0.00001"
"66.50000","2.21389","300.50024","0.02214","30.05002","0.00000"
"67.00000","2.23064","302.19647","0.02231","30.21965","-0.00001"
"67.50000","2.24743","303.73334","0.02247","30.37333","-0.00001"
"68.00000","2.26388","304.84415","0.02264","30.48442","-0.00001"
"68.50000","2.28074","306.50348","0.02281","30.65035","-0.00001"
"69.00000","2.29718","307.78592","0.02297","30.77859","-0.00001"
"69.50000","2.31386","309.22205","0.02314","30.92220","-0.00001"
"70.00000","2.33058","310.63562","0.02331","31.06356","0.00000"
"70.50000","2.34735","312.03705","0.02347","31.20370","-0.00001"
"71.00000","2.36389","313.33817","0.02364","31.33382","-0.00001"
"71.50000","2.38062","314.85562","0.02381","31.48556","0.00000"
"72.00000","2.39727","316.12866","0.02397","31.61287","-0.00001"
"72.50000","2.41396","317.43021","0.02414","31.74302","0.00000"
"73.00000","2.43070","319.10699","0.02431","31.91070","-0.00001"
"73.50000","2.44716","320.19073","0.02447","32.01907","0.00000"
"74.00000","2.46393","321.65976","0.02464","32.16598","0.00000"
"74.50000","2.48050","322.90921","0.02480","32.29092","-0.00001"
"75.00000","2.49732","324.48627","0.02497","32.44863","0.00000"
"75.50000","2.51393","325.84198","0.02514","32.58420","-0.00001"
"76.00000","2.53068","327.25229","0.02531","32.72523","0.00000"
"76.50000","2.54727","328.45908","0.02547","32.84591","0.00000"
"77.00000","2.56392","329.68546","0.02564","32.96854","0.00000"
"77.50000","2.58067","331.17725","0.02581","33.11773","0.00000"
"78.00000","2.59726","332.52872","0.02597","33.25287","0.00000"
"78.50000","2.61401","334.07028","0.02614","33.40703","0.00000"
"79.00000","2.63056","335.22208","0.02631","33.52221","0.00001"
"79.50000","2.64734","336.68903","0.02647","33.66890","0.00001"
"80.00000","2.66381","337.85010","0.02664","33.78501","0.00000"
"80.50000","2.68063","339.29968","0.02681","33.92997","0.00000"
"81.00000","2.69721","340.59427","0.02697","34.05943","0.00001"
"81.50000","2.71408","342.11780","0.02714","34.21178","0.00001"
"82.00000","2.73059","343.25327","0.02731","34.32533","0.00001"
"82.50000","2.74719","344.60767","0.02747","34.46077","0.00001"
"83.00000","2.76403","345.90179","0.02764","34.59018","0.00001"
"83.50000","2.78060","347.29208","0.02781","34.72921","0.00000"
"84.00000","2.79734","348.71426","0.02797","34.87143","0.00000"
"84.50000","2.81391","349.92340","0.02814","34.99234","0.00000"
"85.00000","2.83055","351.12967","0.02831","35.11297","0.00000"
"85.50000","2.84722","352.65106","0.02847","35.26511","0.00000"
"86.00000","2.86402","354.01938","0.02864","35.40194","0.00001"
"86.50000","2.88060","355.34909","0.02881","35.53491","0.00000"
"87.00000","2.89731","356.68176","0.02897","35.66817","0.00000"
"87.50000","2.91387","357.71310","0.02914","35.77131","0.00000"
"88.00000","2.93056","359.26791","0.02931","35.92679","0.00000"
"88.50000","2.94750","360.83716","0.02948","36.08372","0.00000"
"89.00000","2.96388","361.93341","0.02964","36.19334","0.00001"
"89.50000","2.98069","363.41071","0.02981","36.34107","0.00000"
"90.00000","2.99717","364.39459","0.02997","36.43946","0.00000"
"90.50000","3.01395","365.93237","0.03014","36.59324","0.00000"
"91.00000","3.03062","367.23880","0.03031","36.72388","0.00001"
"91.50000","3.04734","368.67963","0.03047","36.86796","0.00001"
"92.00000","3.06391","369.92679","0.03064","36.99268","0.00000"
"92.50000","3.08061","371.36026","0.03081","37.13602","0.00000"
"93.00000","3.09726","372.45004","0.03097","37.24500","0.00000"
"93.50000","3.11398","374.06375","0.03114","37.40638","0.00000"
"94.00000","3.13075","375.40784","0.03131","37.54078","0.00000"
"94.50000","3.14716","376.42529","0.03147","37.64253","0.00000"
"95.00000","3.16384","377.76401","0.03164","37.77640","0.00000"
"95.50000","3.18055","379.19012","0.03181","37.91901","0.00000"
"96.00000","3.19731","380.54184","0.03197","38.05418","0.00000"
"96.50000","3.21392","381.72525","0.03214","38.17252","0.00001"
"97.00000","3.23066","383.32635","0.03231","38.33263","0.00000"
"97.50000","3.24722","384.36285","0.03247","38.43629","0.00000"
"98.00000","3.26395","385.79373","0.03264","38.57937","0.00000"
"98.50000","3.28069","387.35046","0.03281","38.73505","0.00000"
"99.00000","3.29730","388.65369","0.03297","38.86537","0.00000"
"99.50000","3.31402","389.89523","0.03314","38.98952","0.00000"
"100.00000","3.33056","391.05023","0.03331","39.10502","0.00000"
"100.50000","3.34725","392.45081","0.03347","39.24508","0.00000"
"101.00000","3.36391","393.81622","0.03364","39.38162","0.00000"
"101.50000","3.38065","395.10037","0.03381","39.51004","0.00000"
"102.00000","3.39720","396.28693","0.03397","39.62869","0.00000"
"102.50000","3.41405","397.80405","0.03414","39.78040","0.00000"
"103.00000","3.43070","399.02744","0.03431","39.90274","0.00000"
"103.50000","3.44722","400.27856","0.03447","40.02785","0.00000"
"104.00000","3.46404","401.77979","0.03464","40.17798","0.00000"
"104.50000","3.48056","402.93192","0.03481","40.29319","0.00000"
"105.00000","3.49739","404.55438","0.03497","40.45544","0.00000"
"105.50000","3.51388","405.60522","0.03514","40.56052","0.00000"
"106.00000","3.53055","406.97739","0.03531","40.69774","0.00000"
"106.50000","3.54724","408.40976","0.03547","40.84098","0.00000"
"107.00000","3.56401","409.87219","0.03564","40.98722","-0.00001"
"107.50000","3.58054","410.87262","0.03581","41.08726","0.00000"
"108.00000","3.59727","412.34698","0.03597","41.23470","0.00000"
"108.50000","3.61395","413.51715","0.03614","41.35172","-0.00001"
"109.00000","3.63059","414.94177","0.03631","41.49418","0.00000"
"109.50000","3.64738","416.47717","0.03647","41.64772","0.00000"
"110.00000","3.66396","417.66711","0.03664","41.76671","0.00000"
"110.50000","3.68058","418.98206","0.03681","41.89820","0.00000"
"111.00000","3.69714","420.09927","0.03697","42.00993","0.00000"
"111.50000","3.71394","421.61063","0.03714","42.16106","0.00000"
"112.00000","3.73068","423.04196","0.03731","42.30420","0.00000"
"112.50000","3.74733","424.43970","0.03747","42.44397","0.00000"
"113.00000","3.76387","425.55585","0.03764","42.55558","0.00000"
"113.50000","3.78061","426.98383","0.03781","42.69838","0.00000"
"114.00000","3.79735","428.28940","0.03797","42.82894","0.00000"
"114.50000","3.81396","429.61667","0.03814","42.96167","0.00000"
"115.00000","3.83067","431.01450","0.03831","43.10145","0.00000"
"115.50000","3.84724","432.07935","0.03847","43.20794","0.00000"
"116.00000","3.86392","433.45178","0.03864","43.34518","0.00000"
"116.50000","3.88050","434.65277","0.03881","43.46528","0.00000"
"117.00000","3.89740","436.30832","0.03897","43.63083","0.00000"
"117.50000","3.91395","437.45526","0.03914","43.74553","0.00001"
"118.00000","3.93066","438.98346","0.03931","43.89835","0.00000"
"118.50000","3.94718","439.92386","0.03947","43.99239","0.00001"
"119.00000","3.96393","441.46548","0.03964","44.14655","0.00000"
"119.50000","3.98078","442.99374","0.03981","44.29937","0.00000"
"120.00000","3.99724","444.03616","0.03997","44.40362","0.00001"
"120.50000","4.01396","445.57639","0.04014","44.55764","0.00001"
"121.00000","4.03055","446.49527","0.04031","44.64953","0.00001"
"121.50000","4.04725","447.90842","0.04047","44.79084","0.00001"
"122.00000","4.06391","449.29227","0.04064","44.92923","0.00000"
"122.50000","4.08072","450.67715","0.04081","45.06771","0.00000"
"123.00000","4.09719","451.63614","0.04097","45.16361","0.00000"
"123.50000","4.11403","453.09705","0.04114","45.30970","0.00001"
"124.00000","4.13059","454.40976","0.04131","45.44098","0.00000"
"124.50000","4.14732","455.79419","0.04147","45.57942","0.00000"
"125.00000","4.16406","457.25195","0.04164","45.72520","0.00001"
"125.50000","4.18049","458.25842","0.04180","45.82584","0.00000"
"126.00000","4.19731","459.69006","0.04197","45.96901","0.00000"
"126.50000","4.21392","460.74713","0.04214","46.07471","0.00000"
"127.00000","4.23056","462.13531","0.04231","46.21353","0.00000"
"127.50000","4.24724","463.48312","0.04247","46.34831","0.00000"
"128.00000","4.26404","464.93201","0.04264","46.49320","0.00000"
"128.50000","4.28061","466.04468","0.04281","46.60447","0.00001"
"129.00000","4.29730","467.41660","0.04297","46.74166","0.00000"
"129.50000","4.31391","468.46313","0.04314","46.84631","0.00000"
"130.00000","4.33062","470.05148","0.04331","47.00515","0.00001"
"130.50000","4.34738","471.39526","0.04347","47.13953","0.00001"
"131.00000","4.36383","472.52783","0.04364","47.25278","0.00000"
"131.50000","4.38060","473.83774","0.04381","47.38377","0.00000"
"132.00000","4.39715","475.02969","0.04397","47.50297","0.00000"
"132.50000","4.41401","476.59549","0.04414","47.65955","0.00000"
"133.00000","4.43057","477.81503","0.04431","47.78150","0.00000"
"133.50000","4.44740","479.39658","0.04447","47.93966","0.00000"
"134.00000","4.46389","480.35733","0.04464","48.03573","0.00000"
"134.50000","4.48055","481.70886","0.04481","48.17089","0.00000"
"135.00000","4.49736","483.18314","0.04497","48.31831","0.00000"
"135.50000","4.51402","484.50827","0.04514","48.45083","0.00000"
"136.00000","4.53061","485.71307","0.04531","48.57131","0.00000"
"136.50000","4.54717","486.93610","0.04547","48.69361","0.00000"
"137.00000","4.56395","488.33237","0.04564","48.83324","0.00000"
"137.50000","4.58057","489.69742","0.04581","48.96974","-0.00001"
"138.00000","4.59740","491.14926","0.04597","49.11493","0.00000"
"138.50000","4.61391","492.25952","0.04614","49.22595","0.00000"
"139.00000","4.63069","493.73050","0.04631","49.37305","0.00000"
"139.50000","4.64727","494.78766","0.04647","49.47877","0.00000"
"140.00000","4.66386","496.18796","0.04664","49.61880","0.00000"
"140.50000","4.68078","497.78745","0.04681","49.77874","0.00000"
"141.00000","4.69725","498.83469","0.04697","49.88347","0.00000"
"141.50000","4.71392","500.20599","0.04714","50.02060","0.00000"
"142.00000","4.73054","501.46976","0.04731","50.14698","0.00000"
"142.50000","4.74730","502.83545","0.04747","50.28355","0.00000"
"143.00000","4.76393","504.20981","0.04764","50.42098","0.00000"
"143.50000","4.78072","505.71420","0.04781","50.57142","-0.00001"
"144.00000","4.79714","506.81290","0.04797","50.68129","0.00000"
"144.50000","4.81393","508.16647","0.04814","50.81665","0.00000"
"145.00000","4.83065","509.59564","0.04831","50.95956","0.00000"
"145.50000","4.84726","510.98611","0.04847","51.09861","0.00000"
"146.00000","4.86409","512.55005","0.04864","51.25500","0.00000"
"146.50000","4.88053","513.48724","0.04881","51.34872","0.00000"
"147.00000","4.89728","515.01263","0.04897","51.50126","0.00000"
"147.50000","4.91388","516.29675","0.04914","51.62968","0.00000"
"148.00000","4.93069","517.63293","0.04931","51.76329","0.00000"
"148.50000","4.94724","518.95410","0.04947","51.89541","0.00000"
"149.00000","4.96392","520.25232","0.04964","52.02523","0.00000"
"149.50000","4.98053","521.55603","0.04981","52.15560","-0.00001"
"150.00000","4.99735","523.02264","0.04997","52.30227","0.00000"
"150.50000","5.01395","524.21667","0.05014","52.42167","0.00000"
"151.00000","5.03057","525.67456","0.05031","52.56746","0.00000"
"151.50000","5.04739","527.15057","0.05047","52.71506","0.00000"
"152.00000","5.06387","528.28595","0.05064","52.82859","0.00000"
"152.50000","5.08063","529.92010","0.05081","52.99201","0.00000"
"153.00000","5.09715","530.99066","0.05097","53.09907","0.00001"
"153.50000","5.11405","532.77197","0.05114","53.27720","0.00000"
"154.00000","5.13057","533.85242","0.05131","53.38524","0.00000"
"154.50000","5.14725","535.19891","0.05147","53.51989","0.00000"
"155.00000","5.16395","536.67365","0.05164","53.66737","0.00000"
"155.50000","5.18057","538.05621","0.05181","53.80562","0.00001"
"156.00000","5.19739","539.70117","0.05197","53.97012","0.00001"
"156.50000","5.21392","540.93152","0.05214","54.09315","0.00000"
"157.00000","5.23071","542.31616","0.05231","54.23162","0.00000"
"157.50000","5.24718","543.63586","0.05247","54.36359","0.00000"
"158.00000","5.26389","545.11084","0.05264","54.51109","0.00000"
"158.50000","5.28051","546.45099","0.05281","54.64510","0.00001"
"159.00000","5.29743","548.27234","0.05297","54.82723","0.00000"
"159.50000","5.31388","549.43726","0.05314","54.94373","0.00000"
"160.00000","5.33067","550.99286","0.05331","55.09929","0.00000"
"160.50000","5.34733","552.51361","0.05347","55.25136","0.00000"
"161.00000","5.36398","553.92365","0.05364","55.39236","0.00001"
"161.50000","5.38076","555.51672","0.05381","55.55167","0.00001"
"162.00000","5.39717","556.60352","0.05397","55.66035","0.00001"
"162.50000","5.41396","558.11188","0.05414","55.81119","0.00000"
"163.00000","5.43050","559.36548","0.05430","55.93655","0.00000"
"163.50000","5.44723","560.98627","0.05447","56.09863","0.00001"
"164.00000","5.46391","562.36035","0.05464","56.23603","0.00001"
"164.50000","5.48073","564.03412","0.05481","56.40341","0.00000"
"165.00000","5.49719","565.00665","0.05497","56.50066","0.00000"
"165.50000","5.51389","566.50952","0.05514","56.65095","0.00000"
"166.00000","5.53070","568.03680","0.05531","56.80368","0.00000"
"166.50000","5.54730","569.40302","0.05547","56.94030","0.00001"
"167.00000","5.56404","570.88770","0.05564","57.08877","0.00001"
"167.50000","5.58047","572.02734","0.05580","57.20274","0.00000"
"168.00000","5.59727","573.51770","0.05597","57.35177","0.00000"
"168.50000","5.61390","575.07355","0.05614","57.50735","0.00000"
"169.00000","5.63071","576.64697","0.05631","57.66470","0.00000"
"169.50000","5.64725","578.01862","0.05647","57.80186","0.00000"
"170.00000","5.66395","579.46558","0.05664","57.94656","0.00000"
"170.50000","5.68059","580.72937","0.05681","58.07294","0.00000"
"171.00000","5.69725","582.21643","0.05697","58.22164","0.00001"
"171.50000","5.71408","583.87994","0.05714","58.38799","0.00000"
"172.00000","5.73058","585.03107","0.05731","58.50311","0.00000"
"172.50000","5.74725","586.54926","0.05747","58.65493","0.00000"
"173.00000","5.76388","587.93365","0.05764","58.79337","0.00000"
"173.50000","5.78070","589.48297","0.05781","58.94830","0.00000"
"174.00000","5.79721","590.81561","0.05797","59.08156","0.00000"
"174.50000","5.81405","592.51215","0.05814","59.25121","0.00000"
"175.00000","5.83054","593.67621","0.05831","59.36762","-0.00001"
"175.50000","5.84736","595.36890","0.05847","59.53689","-0.00001"
"176.00000","5.86402","596.73267","0.05864","59.67327","0.00000"
"176.50000","5.88054","598.12561","0.05881","59.81256","0.00000"
"177.00000","5.89743","599.85651","0.05897","59.98565","0.00000"
"177.50000","5.91386","600.97943","0.05914","60.09794","-0.00001"
"178.00000","5.93059","602.56830","0.05931","60.25683","0.00000"
"178.50000","5.94720","603.99261","0.05947","60.39926","0.00000"
"179.00000","5.96392","605.35083","0.05964","60.53508","0.00000"
"179.50000","5.98058","606.92303","0.05981","60.69230","0.00000"
"180.00000","5.99736","608.53345","0.05997","60.85334","-0.00001"
"180.50000","6.01391","609.83698","0.06014","60.98370","0.00000"
"181.00000","6.03062","611.40692","0.06031","61.14069","0.00000"
"181.50000","6.04730","612.80121","0.06047","61.28012","0.00000"
"182.00000","6.06392","614.36395","0.06064","61.43639","-0.00001"
"182.50000","6.08076","616.06897","0.06081","61.60690","-0.00001"
"183.00000","6.09714","617.17834","0.06097","61.71783","0.00000"
"183.50000","6.11396","618.75580","0.06114","61.87558","0.00000"
"184.00000","6.13052","620.04919","0.06131","62.00492","0.00000"
"184.50000","6.14734","621.84808","0.06147","62.18481","0.00000"
"185.00000","6.16396","623.23267","0.06164","62.32327","0.00000"
"185.50000","6.18065","624.82831","0.06181","62.48283","0.00000"
"186.00000","6.19725","626.26392","0.06197","62.62639","0.00000"
"186.50000","6.21393","627.66315","0.06214","62.76632","0.00000"
"187.00000","6.23068","629.46521","0.06231","62.94652","0.00000"
"187.50000","6.24731","630.83752","0.06247","63.08375","0.00000"
"188.00000","6.26405","632.24207","0.06264","63.22421","0.00000"
"188.50000","6.28045","633.42053","0.06280","63.34205","0.00001"
"189.00000","6.29721","635.01141","0.06297","63.50114","0.00000"
"189.50000","6.31386","636.44031","0.06314","63.64403","0.00000"
"190.00000","6.33075","638.27399","0.06331","63.82740","0.00001"
"190.50000","6.34728","639.39130","0.06347","63.93913","0.00000"
"191.00000","6.36393","641.00769","0.06364","64.10077","0.00000"
"191.50000","6.38060","642.22943","0.06381","64.22295","0.00000"
"192.00000","6.39726","643.69452","0.06397","64.36945","0.00000"
"192.50000","6.41407","645.36395","0.06414","64.53639","0.00001"
"193.00000","6.43062","646.60345","0.06431","64.66035","0.00000"
"193.50000","6.44723","647.87164","0.06447","64.78716","0.00001"
"194.00000","6.46387","649.33374","0.06464","64.93337","0.00000"
"194.50000","6.48065","650.98627","0.06481","65.09863","0.00000"
"195.00000","6.49728","652.54431","0.06497","65.25443","0.00000"
"195.50000","6.51402","654.05096","0.06514","65.40510","0.00001"
"196.00000","6.53048","655.10608","0.06530","65.51060","0.00001"
"196.50000","6.54730","656.95343","0.06547","65.69534","0.00000"
"197.00000","6.56413","658.43323","0.06564","65.84332","0.00000"
"197.50000","6.58054","659.67352","0.06581","65.96735","0.00000"
"198.00000","6.59738","661.49542","0.06597","66.14954","0.00000"
"198.50000","6.61383","662.48047","0.06614","66.24805","0.00000"
"199.00000","6.63064","664.21704","0.06631","66.42171","0.00000"
"199.50000","6.64724","665.59033","0.06647","66.55904","0.00000"
"200.00000","6.66396","667.06525","0.06664","66.70653","0.00000"
"200.50000","6.68057","668.34937","0.06681","66.83494","0.00000"
"201.00000","6.69733","669.90533","0.06697","66.99053","0.00000"
"201.50000","6.71386","671.14185","0.06714","67.11418","0.00000"
"202.00000","6.73065","672.89825","0.06731","67.28983","0.00000"
"202.50000","6.74736","674.30640","0.06747","67.43064","0.00000"
"203.00000","6.76387","675.63123","0.06764","67.56313","0.00000"
"203.50000","6.78064","677.25854","0.06781","67.72585","0.00000"
"204.00000","6.79723","678.60211","0.06797","67.86021","0.00000"
"204.50000","6.81389","680.10248","0.06814","68.01025","0.00000"
"205.00000","6.83054","681.38599","0.06831","68.13860","0.00000"
"205.50000","6.84734","683.10486","0.06847","68.31049","0.00001"
"206.00000","6.86397","684.60095","0.06864","68.46010","0.00000"
"206.50000","6.88062","686.01154","0.06881","68.60115","0.00000"
"207.00000","6.89724","687.47253","0.06897","68.74725","0.00000"
"207.50000","6.91393","689.08478","0.06914","68.90848","0.00001"
"208.00000","6.93071","690.63086","0.06931","69.06309","0.00000"
"208.50000","6.94727","691.99896","0.06947","69.19990","0.00000"
"209.00000","6.96397","693.43945","0.06964","69.34395","0.00000"
"209.50000","6.98057","694.87939","0.06981","69.48794","0.00000"
"210.00000","6.99727","696.27667","0.06997","69.62767","0.00000"
"210.50000","7.01383","697.64380","0.07014","69.76438","0.00000"
"211.00000","7.03076","699.32556","0.07031","69.93256","0.00000"
"211.50000","7.04729","700.66241","0.07047","70.06624","0.00000"
"212.00000","7.06391","701.86554","0.07064","70.18655","0.00000"
"212.50000","7.08061","703.33008","0.07081","70.33301","0.00000"
"213.00000","7.09727","704.90405","0.07097","70.49040","0.00000"
"213.50000","7.11414","706.46747","0.07114","70.64674","0.00000"
"214.00000","7.13057","707.67609","0.07131","70.76761","0.00000"
"214.50000","7.14727","709.06708","0.07147","70.90671","0.00000"
"215.00000","7.16387","710.31610","0.07164","71.03161","0.00000"
"215.50000","7.18066","712.06293","0.07181","71.20629","-0.00001"
"216.00000","7.19721","713.13269","0.07197","71.31327","0.00000"
"216.50000","7.21403","714.81110","0.07214","71.48111","0.00000"
"217.00000","7.23052","715.86475","0.07231","71.58647","0.00000"
"217.50000","7.24727","717.48096","0.07247","71.74809","0.00000"
"218.00000","7.26405","719.06726","0.07264","71.90672","0.00000"
"218.50000","7.28065","720.34619","0.07281","72.03462","0.00000"
"219.00000","7.29733","721.77783","0.07297","72.17778","0.00000"
"219.50000","7.31378","722.89819","0.07314","72.28982","0.00000"
"220.00000","7.33059","724.49017","0.07331","72.44902","0.00000"
"220.50000","7.34731","725.92181","0.07347","72.59218","0.00000"
"221.00000","7.36397","727.25861","0.07364","72.72586","0.00000"
"221.50000","7.38055","728.55170","0.07381","72.85517","0.00000"
"222.00000","7.39736","730.12463","0.07397","73.01247","0.00000"
"222.50000","7.41397","731.41669","0.07414","73.14167","0.00000"
"223.00000","7.43061","732.83398","0.07431","73.28340","0.00000"
"223.50000","7.44735","734.41315","0.07447","73.44131","0.00000"
"224.00000","7.46392","735.62140","0.07464","73.56214","0.00000"
"224.50000","7.48062","737.16974","0.07481","73.71697","0.00000"
"225.00000","7.49715","738.47833","0.07497","73.84783","0.00000"
"225.50000","7.51395","740.02942","0.07514","74.00294","0.00000"
"226.00000","7.53056","741.45190","0.07531","74.14519","0.00000"
"226.50000","7.54738","743.10999","0.07547","74.31100","0.00000"
"227.00000","7.56387","744.28601","0.07564","74.42860","0.00000"
"227.50000","7.58067","745.92334","0.07581","74.59233","0.00000"
"228.00000","7.59731","747.19202","0.07597","74.71920","0.00001"
"228.50000","7.61388","748.73737","0.07614","74.87373","0.00001"
"229.00000","7.63071","750.40961","0.07631","75.04096","0.00001"
"229.50000","7.64729","751.75092","0.07647","75.17509","0.00001"
"230.00000","7.66392","752.98474","0.07664","75.29848","0.00001"
"230.50000","7.68052","754.38177","0.07681","75.43818","0.00001"
"231.00000","7.69731","756.03326","0.07697","75.60332","0.00001"
"231.50000","7.71392","757.42566","0.07714","75.74257","0.00001"
"232.00000","7.73074","759.07233","0.07731","75.90723","0.00000"
"232.50000","7.74722","760.29718","0.07747","76.02972","0.00000"
"233.00000","7.76398","761.77637","0.07764","76.17764","0.00001"
"233.50000","7.78068","763.34717","0.07781","76.33472","0.00001"
"234.00000","7.79720","764.72290","0.07797","76.47229","0.00001"
"234.50000","7.81409","766.47357","0.07814","76.64735","0.00000"
"235.00000","7.83056","767.53729","0.07831","76.75373","0.00000"
"235.50000","7.84722","769.07446","0.07847","76.90745","0.00001"
"236.00000","7.86388","770.43011","0.07864","77.04301","0.00001"
"236.50000","7.88067","771.99445","0.07881","77.19945","0.00000"
"237.00000","7.89729","773.46960","0.07897","77.34696","0.00000"
"237.50000","7.91400","774.96820","0.07914","77.49682","0.00000"
"238.00000","7.93051","776.22479","0.07931","77.62248","0.00000"
"238.50000","7.94725","777.80115","0.07947","77.78011","0.00001"
"239.00000","7.96407","779.56824","0.07964","77.95683","0.00000"
"239.50000","7.98059","780.83051","0.07981","78.08305","0.00000"
"240.00000","7.99733","782.43121","0.07997","78.24312","0.00000"
"240.50000","8.01378","783.37622","0.08014","78.33762","0.00000"
"241.00000","8.03059","785.11353","0.08031","78.51135","0.00000"
"241.50000","8.04722","786.54309","0.08047","78.65431","0.00000"
"242.00000","8.06406","788.28027","0.08064","78.82803","0.00000"
"242.50000","8.08054","789.43158","0.08081","78.94316","0.00000"
"243.00000","8.09724","790.93372","0.08097","79.09337","0.00000"
"243.50000","8.11393","792.33032","0.08114","79.23303","0.00001"
"244.00000","8.13068","793.96179","0.08131","79.39618","0.00000"
"244.50000","8.14734","795.23035","0.08147","79.52303","0.00000"
"245.00000","8.16391","796.62616","0.08164","79.66261","0.00000"
"245.50000","8.18063","798.02051","0.08181","79.80205","0.00000"
"246.00000","8.19723","799.30731","0.08197","79.93073","0.00000"
"246.50000","8.21404","800.79071","0.08214","80.07907","0.00000"
"247.00000","8.23053","802.17151","0.08231","80.21715","0.00000"
"247.50000","8.24740","803.79053","0.08247","80.37905","0.00000"
"248.00000","8.26388","804.86096","0.08264","80.48610","0.00000"
"248.50000","8.28053","806.19354","0.08281","80.61935","0.00000"
"249.00000","8.29737","807.72668","0.08297","80.77267","0.00000"
"249.50000","8.31389","809.05109","0.08314","80.90511","0.00000"
"250.00000","8.33070","810.68280","0.08331","81.06828","0.00000"
"250.50000","8.34723","811.94220","0.08347","81.19422","0.00000"
"251.00000","8.36395","813.28040","0.08364","81.32804","0.00000"
"251.50000","8.38056","814.76324","0.08381","81.47633","0.00001"
"252.00000","8.39736","816.30396","0.08397","81.63039","0.00000"
"252.50000","8.41387","817.51819","0.08414","81.75182","0.00000"
"253.00000","8.43068","819.21582","0.08431","81.92159","0.00000"
"253.50000","8.44720","820.49957","0.08447","82.04996","0.00000"
"254.00000","8.46394","822.07788","0.08464","82.20779","-0.00001"
"254.50000","8.48075","823.53857","0.08481","82.35386","0.00000"
"255.00000","8.49721","824.70367","0.08497","82.47037","0.00000"
"255.50000","8.51401","826.24524","0.08514","82.62453","0.00000"
"256.00000","8.53049","827.40240","0.08530","82.74024","0.00000"
"256.50000","8.54727","828.90417","0.08547","82.89042","0.00000"
"257.00000","8.56388","830.41412","0.08564","83.04141","-0.00001"
"257.50000","8.58062","831.73523","0.08581","83.17352","0.00000"
"258.00000","8.59727","833.33289","0.08597","83.33329","0.00001"
"258.50000","8.61404","834.74329","0.08614","83.47433","0.00000"
"259.00000","8.63055","835.86816","0.08631","83.58681","0.00000"
"259.50000","8.64725","837.41193","0.08647","83.74120","-0.00001"
"260.00000","8.66406","838.89545","0.08664","83.88954","0.00000"
"260.50000","8.68060","840.10168","0.08681","84.01017","0.00001"
"261.00000","8.69728","841.47955","0.08697","84.14796","0.00001"
"261.50000","8.71377","842.61334","0.08714","84.26134","0.00000"
"262.00000","8.73059","844.17798","0.08731","84.41780","0.00000"
"262.50000","8.74726","845.69714","0.08747","84.56972","0.00000"
"263.00000","8.76400","847.04639","0.08764","84.70464","0.00001"
"263.50000","8.78058","848.33716","0.08781","84.83372","0.00001"
"264.00000","8.79723","849.72839","0.08797","84.97284","0.00000"
"264.50000","8.81401","851.16754","0.08814","85.11675","0.00001"
"265.00000","8.83061","852.55615","0.08831","85.25562","0.00001"
"265.50000","8.84742","854.12164","0.08847","85.41216","0.00001"
"266.00000","8.86388","855.24969","0.08864","85.52497","0.00001"
"266.50000","8.88057","856.59222","0.08881","85.65923","0.00000"
"267.00000","8.89719","858.04639","0.08897","85.80464","0.00001"
"267.50000","8.91408","859.64929","0.08914","85.96493","0.00001"
"268.00000","8.93056","860.78503","0.08931","86.07851","0.00001"
"268.50000","8.94738","862.42194","0.08947","86.24220","0.00001"
"269.00000","8.96388","863.57471","0.08964","86.35747","0.00001"
"269.50000","8.98062","865.18079","0.08981","86.51808","0.00001"
"270.00000","8.99743","866.65125","0.08997","86.66512","0.00001"
"270.50000","9.01389","867.71863","0.09014","86.77187","0.00001"
"271.00000","9.03073","869.45557","0.09031","86.94556","0.00000"
"271.50000","9.04717","870.56970","0.09047","87.05697","0.00000"
"272.00000","9.06387","872.03766","0.09064","87.20377","0.00001"
"272.50000","9.08057","873.38678","0.09081","87.33868","0.00001"
"273.00000","9.09739","875.05786","0.09097","87.50578","0.00001"
"273.50000","9.11389","876.25317","0.09114","87.62532","0.00000"
"274.00000","9.13061","877.74609","0.09131","87.77461","0.00000"
"274.50000","9.14729","879.04169","0.09147","87.90417","0.00000"
"275.00000","9.16396","880.29968","0.09164","88.02997","0.00000"
"275.50000","9.18072","881.75293","0.09181","88.17529","0.00000"
"276.00000","9.19719","882.66821","0.09197","88.26682","0.00000"
"276.50000","9.21396","884.17700","0.09214","88.41770","0.00000"
"277.00000","9.23051","885.23535","0.09231","88.52354","0.00000"
"277.50000","9.24730","886.62506","0.09247","88.66251","0.00000"
"278.00000","9.26391","887.93756","0.09264","88.79375","0.00000"
"278.50000","9.28073","889.23798","0.09281","88.92380","0.00000"
"279.00000","9.29724","890.26440","0.09297","89.02644","0.00000"
"279.50000","9.31394","891.60278","0.09314","89.16028","0.00000"
"280.00000","9.33067","892.80762","0.09331","89.28076","0.00000"
"280.50000","9.34724","894.15631","0.09347","89.41563","0.00000"
"281.00000","9.36401","895.44409","0.09364","89.54441","0.00000"
"281.50000","9.38057","896.32330","0.09381","89.63233","0.00000"
"282.00000","9.39735","897.76434","0.09397","89.77644","0.00000"
"282.50000","9.41379","898.63806","0.09414","89.86381","0.00000"
"283.00000","9.43063","899.92462","0.09431","89.99246","0.00000"
"283.50000","9.44723","900.96332","0.09447","90.09633","0.00000"
"284.00000","9.46410","902.30273","0.09464","90.23027","0.00000"
"284.50000","9.48062","903.08826","0.09481","90.30882","0.00000"
"285.00000","9.49721","904.16504","0.09497","90.41650","0.00000"
"285.50000","9.51401","905.53845","0.09514","90.55385","0.00000"
"286.00000","9.53056","906.38556","0.09531","90.63856","0.00000"
"286.50000","9.54735","907.53705","0.09547","90.75371","0.00000"
"287.00000","9.56388","908.07092","0.09564","90.80709","0.00000"
"287.50000","9.58057","908.96863","0.09581","90.89687","0.00000"
"288.00000","9.59721","910.16174","0.09597","91.01617","0.00001"
"288.50000","9.61404","911.45227","0.09614","91.14523","0.00000"
"289.00000","9.63062","912.24805","0.09631","91.22481","0.00000"
"289.50000","9.64731","913.40839","0.09647","91.34084","0.00001"
"290.00000","9.66387","913.93262","0.09664","91.39326","0.00001"
"290.50000","9.68060","915.05756","0.09681","91.50575","0.00000"
"291.00000","9.69746","915.90363","0.09697","91.59036","0.00000"
"291.50000","9.71387","916.35248","0.09714","91.63525","-0.00001"
"292.00000","9.73068","917.14484","0.09731","91.71449","0.00000"
"292.50000","9.74717","917.73950","0.09747","91.77395","0.00000"
"293.00000","9.76398","918.76819","0.09764","91.87682","0.00000"
"293.50000","9.78064","919.57367","0.09781","91.95737","0.00000"
"294.00000","9.79736","919.77094","0.09797","91.97710","0.00000"
"294.50000","9.81390","919.88074","0.09814","91.98808","0.00000"
"295.00000","9.83060","920.30585","0.09831","92.03059","0.00000"
"295.50000","9.84726","920.56866","0.09847","92.05687","0.00000"
"296.00000","9.86396","920.80475","0.09864","92.08047","0.00000"
"296.50000","9.88077","921.04095","0.09881","92.10410","0.00000"
"297.00000","9.89719","921.03137","0.09897","92.10313","0.00000"
"297.50000","9.91392","920.88068","0.09914","92.08807","0.00000"
"298.00000","9.93054","920.82050","0.09931","92.08205","0.00001"
"298.50000","9.94734","920.88806","0.09947","92.08881","0.00000"
"299.00000","9.96391","920.36694","0.09964","92.03670","0.00000"
"299.50000","9.98065","918.87238","0.09981","91.88724","0.00000"
"300.00000","9.99727","913.78650","0.09997","91.37865","0.00000"
"300.50000","10.01391","911.49646","0.10014","91.14964","0.00001"
"301.00000","10.03069","910.93549","0.10031","91.09355","0.00000"
"301.50000","10.04729","910.72052","0.10047","91.07205","0.00000"
"302.00000","10.06400","911.00714","0.10064","91.10072","0.00000"
"302.50000","10.08057","911.43268","0.10081","91.14326","0.00001"
"303.00000","10.09728","911.86731","0.10097","91.18673","0.00000"
"303.50000","10.11393","912.72760","0.10114","91.27276","0.00001"
"304.00000","10.13065","913.22980","0.10131","91.32298","0.00001"
"304.50000","10.14716","913.49951","0.10147","91.34995","0.00000"
"305.00000","10.16403","914.25458","0.10164","91.42546","0.00001"
"305.50000","10.18068","914.99213","0.10181","91.49921","0.00001"
"306.00000","10.19721","915.96210","0.10197","91.59621","0.00001"
"306.50000","10.21407","917.14899","0.10214","91.71490","0.00002"
"307.00000","10.23058","917.82202","0.10231","91.78220","0.00002"
"307.50000","10.24739","918.84973","0.10247","91.88497","0.00002"
"308.00000","10.26389","919.19897","0.10264","91.91990","0.00001"
"308.50000","10.28054","919.97821","0.10281","91.99782","0.00000"
"309.00000","10.29725","920.94727","0.10297","92.09473","0.00000"
"309.50000","10.31404","921.94574","0.10314","92.19457","0.00000"
"310.00000","10.33054","922.66333","0.10331","92.26633","0.00000"
"310.50000","10.34731","923.81964","0.10347","92.38197","0.00001"
"311.00000","10.36390","924.59235","0.10364","92.45924","0.00001"
"311.50000","10.38057","925.46594","0.10381","92.54659","0.00000"
"312.00000","10.39739","926.46375","0.10397","92.64638","0.00000"
"312.50000","10.41391","927.23499","0.10414","92.72350","0.00000"
"313.00000","10.43056","928.20282","0.10431","92.82028","0.00001"
"313.50000","10.44715","928.97992","0.10447","92.89799","0.00000"
"314.00000","10.46394","930.23254","0.10464","93.02325","0.00000"
"314.50000","10.48066","931.21259","0.10481","93.12126","0.00000"
"315.00000","10.49734","932.19000","0.10497","93.21900","0.00000"
"315.50000","10.51386","932.92932","0.10514","93.29293","0.00000"
"316.00000","10.53062","933.95282","0.10531","93.39528","0.00000"
"316.50000","10.54735","934.68561","0.10547","93.46856","0.00000"
"317.00000","10.56396","935.46973","0.10564","93.54697","0.00000"
"317.50000","10.58068","936.37500","0.10581","93.63750","0.00000"
"318.00000","10.59724","936.79492","0.10597","93.67949","0.00000"
"318.50000","10.61390","937.41565","0.10614","93.74156","0.00000"
"319.00000","10.63048","937.85486","0.10630","93.78548","0.00000"
"319.50000","10.64735","938.82520","0.10647","93.88252","0.00000"
"320.00000","10.66394","938.86212","0.10664","93.88622","0.00000"
"320.50000","10.68064","939.44611","0.10681","93.94461","0.00000"
"321.00000","10.69720","939.76294","0.10697","93.97630","0.00000"
"321.50000","10.71397","940.36005","0.10714","94.03600","0.00000"
"322.00000","10.73075","940.98828","0.10731","94.09883","0.00000"
"322.50000","10.74726","941.21948","0.10747","94.12195","0.00000"
"323.00000","10.76399","940.94434","0.10764","94.09444","0.00000"
"323.50000","10.78055","940.70502","0.10781","94.07050","0.00000"
"324.00000","10.79728","940.72559","0.10797","94.07256","0.00000"
"324.50000","10.81388","940.73358","0.10814","94.07336","0.00000"
"325.00000","10.83068","940.57135","0.10831","94.05714","0.00000"
"325.50000","10.84719","938.66687","0.10847","93.86668","0.00000"
"326.00000","10.86399","938.29724","0.10864","93.82973","0.00000"
"326.50000","10.88060","936.56879","0.10881","93.65688","0.00000"
"327.00000","10.89730","933.50745","0.10897","93.35075","0.00000"
"327.50000","10.91404","931.27051","0.10914","93.12705","0.00000"
"328.00000","10.93051","929.68561","0.10931","92.96856","0.00000"
"328.50000","10.94734","925.60620","0.10947","92.56062","0.00000"
"329.00000","10.96392","922.83246","0.10964","92.28325","0.00000"
"329.50000","10.98060","919.05566","0.10981","91.90556","-0.00001"
"330.00000","10.99723","916.25574","0.10997","91.62557","-0.00001"
"330.50000","11.01406","906.13562","0.11014","90.61356","0.00000"
"331.00000","11.03058","892.26031","0.11031","89.22603","0.00000"
"331.50000","11.04729","869.53345","0.11047","86.95335","0.00000"
"332.00000","11.06393","839.52722","0.11064","83.95272","0.00000"
"332.50000","11.08059","798.80664","0.11081","79.88066","0.00000"
"333.00000","11.09739","769.51154","0.11097","76.95116","0.00000"
"333.50000","11.11387","743.03931","0.11114","74.30393","0.00000"
"334.00000","11.13058","724.87860","0.11131","72.48786","0.00000"
"334.50000","11.14714","709.42114","0.11147","70.94212","0.00000"
"335.00000","11.16399","692.58997","0.11164","69.25900","0.00000"
"335.50000","11.18057","638.80194","0.11181","63.88020","0.00000"
"336.00000","11.19738","581.32599","0.11197","58.13260","0.00000"
"336.50000","11.21388","519.70636","0.11214","51.97063","0.00000"
"337.00000","11.23056","465.22409","0.11231","46.52241","0.00001"
"337.50000","11.24736","391.57999","0.11247","39.15800","0.00001"
"338.00000","11.26399","367.82794","0.11264","36.78279","0.00000"
"338.50000","11.28063","353.05374","0.11281","35.30537","0.00000"
"339.00000","11.29719","341.02203","0.11297","34.10220","0.00000"
"339.50000","11.31394","332.88760","0.11314","33.28876","0.00000"
"340.00000","11.33060","324.59464","0.11331","32.45947","0.00001"
"340.50000","11.34741","317.24899","0.11347","31.72490","0.00000"
"341.00000","11.36392","305.68784","0.11364","30.56878","0.00000"
"341.50000","11.38071","296.33936","0.11381","29.63394","0.00000"
"342.00000","11.39725","287.16562","0.11397","28.71656","0.00001"
"342.50000","11.41388","282.48407","0.11414","28.24841","0.00001"
"343.00000","11.43081","276.62201","0.11431","27.66220","0.00001"
"343.50000","11.44725","272.40903","0.11447","27.24090","0.00000"
"344.00000","11.46393","270.01822","0.11464","27.00182","0.00000"
"344.50000","11.48051","267.54453","0.11481","26.75445","0.00000"
"345.00000","11.49731","265.34161","0.11497","26.53416","0.00000"
"345.50000","11.51394","262.12213","0.11514","26.21221","0.00000"
"346.00000","11.53071","259.12289","0.11531","25.91229","0.00001"
"346.50000","11.54716","255.81848","0.11547","25.58185","0.00000"
"347.00000","11.56395","252.20135","0.11564","25.22013","0.00000"
"347.50000","11.58065","246.98160","0.11581","24.69816","0.00000"
"348.00000","11.59728","237.40797","0.11597","23.74080","0.00003"
"348.50000","11.61408","222.83490","0.11614","22.28349","-0.00001"
"349.00000","11.63050","210.89290","0.11631","21.08929","0.00000"
"349.50000","11.64726","203.37349","0.11647","20.33735","0.00000"
"350.00000","11.66384","197.39175","0.11664","19.73918","-0.00001"
"350.50000","11.68069","190.32881","0.11681","19.03288","0.00000"
"351.00000","11.69726","185.72752","0.11697","18.57275","-0.00002"
"351.50000","11.71394","181.88142","0.11714","18.18814","0.00001"
"352.00000","11.73060","179.38632","0.11731","17.93863","0.00001"
"352.50000","11.74737","177.33905","0.11747","17.73391","0.00001"
"353.00000","11.76396","175.91394","0.11764","17.59139","0.00001"
"353.50000","11.78057","174.45020","0.11781","17.44502","0.00000"
"354.00000","11.79736","173.29631","0.11797","17.32963","-0.00002"
"354.50000","11.81388","172.22577","0.11814","17.22258","-0.00003"
"354.74600","11.82211","170.66014","0.11822","17.06601","0.00002"