File: Tension/Section_1_Group3/control_tension.is_tens_RawData/Specimen_RawData_1.csv
Time,Extension,Load,Tensile strain (Extension),Axial Video,Tensile stress,Transverse Video
(s),(mm),(N),(mm/mm),(mm/mm),(MPa),(mm/mm)
"0.00000","73.00001","-0.19314","0.00000","-0.00002","-0.01931","0.00003"
"0.10000","73.00080","0.83047","0.00001","-0.00002","0.08305","0.00003"
"0.20000","73.00250","3.78782","0.00002","-0.00004","0.37878","0.00003"
"0.30000","73.00753","12.84481","0.00008","-0.00004","1.28448","0.00003"
"0.40000","73.01092","18.74538","0.00011","-0.00003","1.87454","0.00000"
"0.50000","73.01422","24.19371","0.00014","-0.00002","2.41937","-0.00002"
"0.60000","73.01778","30.18023","0.00018","-0.00003","3.01802","-0.00003"
"0.70000","73.02108","35.47266","0.00021","-0.00002","3.54727","-0.00003"
"0.80000","73.02427","40.59663","0.00024","-0.00003","4.05966","-0.00003"
"0.90000","73.02769","46.18409","0.00028","-0.00003","4.61841","-0.00004"
"1.00000","73.03102","51.26991","0.00031","-0.00001","5.12699","-0.00003"
"1.10000","73.03436","56.51067","0.00034","-0.00002","5.65107","-0.00005"
"1.20000","73.03764","61.36403","0.00038","-0.00002","6.13640","-0.00005"
"1.30000","73.04116","66.81285","0.00041","-0.00002","6.68128","-0.00005"
"1.40000","73.04444","71.65538","0.00044","-0.00004","7.16554","-0.00008"
"1.50000","73.04761","76.17698","0.00048","-0.00002","7.61770","-0.00006"
"1.60000","73.05103","81.26588","0.00051","-0.00004","8.12659","-0.00005"
"1.70000","73.05436","86.08734","0.00054","-0.00002","8.60873","-0.00010"
"1.80000","73.05763","90.64513","0.00058","-0.00001","9.06451","-0.00010"
"1.90000","73.06095","95.36929","0.00061","0.00000","9.53693","-0.00010"
"2.00000","73.06441","100.15004","0.00064","0.00000","10.01500","-0.00012"
"2.10000","73.06769","104.70871","0.00068","0.00002","10.47087","-0.00013"
"2.20000","73.07089","108.84563","0.00071","0.00002","10.88456","-0.00013"
"2.30000","73.07442","113.66228","0.00074","0.00005","11.36623","-0.00010"
"2.40000","73.07772","118.01691","0.00078","0.00005","11.80169","-0.00012"
"2.50000","73.08097","122.14188","0.00081","0.00004","12.21419","-0.00012"
"2.60000","73.08430","126.43113","0.00084","0.00005","12.64311","-0.00016"
"2.70000","73.08771","130.85117","0.00088","0.00005","13.08512","-0.00019"
"2.80000","73.09100","134.82527","0.00091","0.00007","13.48253","-0.00019"
"2.90000","73.09428","139.08626","0.00094","0.00009","13.90863","-0.00016"
"3.00000","73.09782","143.39981","0.00098","0.00011","14.33998","-0.00016"
"3.10000","73.10119","147.36957","0.00101","0.00012","14.73696","-0.00016"
"3.20000","73.10432","151.11581","0.00104","0.00013","15.11158","-0.00018"
"3.30000","73.10767","155.11433","0.00108","0.00015","15.51143","-0.00019"
"3.40000","73.11098","158.95158","0.00111","0.00019","15.89516","-0.00021"
"3.50000","73.11431","162.73265","0.00114","0.00020","16.27327","-0.00021"
"3.60000","73.11758","166.58011","0.00118","0.00023","16.65801","-0.00021"
"3.70000","73.12111","170.80264","0.00121","0.00026","17.08027","-0.00022"
"3.80000","73.12454","174.60516","0.00125","0.00027","17.46052","-0.00020"
"3.90000","73.12759","177.74261","0.00128","0.00027","17.77426","-0.00016"
"4.00000","73.13092","181.46805","0.00131","0.00030","18.14680","-0.00016"
"4.10000","73.13433","185.12947","0.00134","0.00030","18.51295","-0.00015"
"4.20000","73.13762","188.85513","0.00138","0.00033","18.88551","-0.00013"
"4.30000","73.14094","192.18839","0.00141","0.00034","19.21884","-0.00013"
"4.40000","73.14439","196.10861","0.00144","0.00037","19.61086","-0.00016"
"4.50000","73.14782","199.86069","0.00148","0.00038","19.98607","-0.00016"
"4.60000","73.15092","202.70622","0.00151","0.00039","20.27062","-0.00014"
"4.70000","73.15437","206.44933","0.00154","0.00042","20.64493","-0.00014"
"4.80000","73.15776","209.83621","0.00158","0.00043","20.98362","-0.00016"
"4.90000","73.16106","213.12257","0.00161","0.00042","21.31226","-0.00019"
"5.00000","73.16433","216.40463","0.00164","0.00044","21.64046","-0.00019"
"5.10000","73.16772","219.70995","0.00168","0.00045","21.97099","-0.00019"
"5.20000","73.17110","223.09639","0.00171","0.00047","22.30964","-0.00019"
"5.30000","73.17419","225.91336","0.00174","0.00047","22.59134","-0.00021"
"5.40000","73.17769","229.45383","0.00178","0.00047","22.94538","-0.00021"
"5.50000","73.18107","232.63591","0.00181","0.00049","23.26359","-0.00024"
"5.60000","73.18436","235.73010","0.00184","0.00049","23.57301","-0.00024"
"5.70000","73.18765","238.74979","0.00188","0.00051","23.87498","-0.00026"
"5.80000","73.19091","241.68839","0.00191","0.00051","24.16884","-0.00025"
"5.90000","73.19432","244.98442","0.00194","0.00051","24.49844","-0.00026"
"6.00000","73.19761","247.90874","0.00198","0.00052","24.79087","-0.00026"
"6.10000","73.20108","251.18277","0.00201","0.00053","25.11828","-0.00029"
"6.20000","73.20444","254.11160","0.00204","0.00054","25.41116","-0.00031"
"6.30000","73.20768","256.90387","0.00208","0.00057","25.69039","-0.00032"
"6.40000","73.21101","259.94052","0.00211","0.00060","25.99405","-0.00032"
"6.50000","73.21434","262.70865","0.00214","0.00059","26.27086","-0.00032"
"6.60000","73.21767","265.59473","0.00218","0.00060","26.55947","-0.00033"
"6.70000","73.22098","268.57541","0.00221","0.00062","26.85754","-0.00034"
"6.80000","73.22444","271.52277","0.00224","0.00062","27.15228","-0.00034"
"6.90000","73.22778","274.48367","0.00228","0.00064","27.44837","-0.00034"
"7.00000","73.23099","277.01340","0.00231","0.00065","27.70134","-0.00037"
"7.10000","73.23431","279.81320","0.00234","0.00065","27.98132","-0.00037"
"7.20000","73.23763","282.72562","0.00238","0.00067","28.27256","-0.00039"
"7.30000","73.24094","285.42023","0.00241","0.00068","28.54202","-0.00039"
"7.40000","73.24435","288.31693","0.00244","0.00070","28.83169","-0.00039"
"7.50000","73.24775","291.13403","0.00248","0.00070","29.11340","-0.00040"
"7.60000","73.25106","293.85037","0.00251","0.00071","29.38504","-0.00040"
"7.70000","73.25426","296.33554","0.00254","0.00072","29.63355","-0.00038"
"7.80000","73.25768","299.28098","0.00258","0.00073","29.92810","-0.00038"
"7.90000","73.26101","301.91830","0.00261","0.00074","30.19183","-0.00039"
"8.00000","73.26427","304.48264","0.00264","0.00074","30.44826","-0.00041"
"8.10000","73.26772","307.31879","0.00268","0.00074","30.73188","-0.00042"
"8.20000","73.27108","310.15952","0.00271","0.00074","31.01595","-0.00042"
"8.30000","73.27440","312.84778","0.00274","0.00074","31.28478","-0.00039"
"8.40000","73.27760","315.22705","0.00278","0.00077","31.52271","-0.00040"
"8.50000","73.28104","318.22989","0.00281","0.00079","31.82299","-0.00040"
"8.60000","73.28447","321.07904","0.00284","0.00078","32.10790","-0.00039"
"8.70000","73.28763","323.40552","0.00288","0.00077","32.34055","-0.00039"
"8.80000","73.29103","326.15668","0.00291","0.00079","32.61567","-0.00040"
"8.90000","73.29433","328.84738","0.00294","0.00079","32.88474","-0.00037"
"9.00000","73.29765","331.53168","0.00298","0.00080","33.15317","-0.00040"
"9.10000","73.30089","333.97531","0.00301","0.00082","33.39753","-0.00040"
"9.20000","73.30448","337.23267","0.00304","0.00081","33.72327","-0.00042"
"9.30000","73.30774","339.72418","0.00308","0.00080","33.97242","-0.00042"
"9.40000","73.31092","342.09756","0.00311","0.00080","34.20975","-0.00042"
"9.50000","73.31438","344.89975","0.00314","0.00080","34.48997","-0.00042"
"9.60000","73.31757","347.26605","0.00318","0.00080","34.72660","-0.00042"
"9.70000","73.32100","350.00784","0.00321","0.00082","35.00079","-0.00040"
"9.80000","73.32417","352.27722","0.00324","0.00082","35.22772","-0.00040"
"9.90000","73.32784","355.38397","0.00328","0.00081","35.53840","-0.00042"
"10.00000","73.33116","357.88220","0.00331","0.00080","35.78822","-0.00042"
"10.10000","73.33427","359.93057","0.00334","0.00082","35.99306","-0.00044"
"10.20000","73.33775","362.64731","0.00338","0.00080","36.26473","-0.00048"
"10.30000","73.34099","365.01852","0.00341","0.00082","36.50185","-0.00043"
"10.40000","73.34439","367.71814","0.00344","0.00082","36.77181","-0.00045"
"10.50000","73.34763","370.00583","0.00348","0.00085","37.00058","-0.00044"
"10.60000","73.35111","372.64767","0.00351","0.00086","37.26477","-0.00043"
"10.70000","73.35442","375.10315","0.00354","0.00087","37.51031","-0.00045"
"10.80000","73.35758","377.13467","0.00358","0.00087","37.71347","-0.00042"
"10.90000","73.36099","379.68909","0.00361","0.00089","37.96891","-0.00042"
"11.00000","73.36438","382.13736","0.00364","0.00089","38.21374","-0.00042"
"11.10000","73.36767","384.29050","0.00368","0.00091","38.42905","-0.00044"
"11.20000","73.37094","386.64481","0.00371","0.00094","38.66448","-0.00044"
"11.30000","73.37440","388.96814","0.00374","0.00093","38.89681","-0.00041"
"11.40000","73.37768","391.07507","0.00378","0.00093","39.10751","-0.00040"
"11.50000","73.38091","392.98929","0.00381","0.00094","39.29893","-0.00038"
"11.60000","73.38435","395.18933","0.00384","0.00096","39.51893","-0.00035"
"11.70000","73.38778","397.47391","0.00388","0.00095","39.74739","-0.00034"
"11.80000","73.39102","399.37350","0.00391","0.00096","39.93735","-0.00037"
"11.90000","73.39435","401.55249","0.00394","0.00096","40.15525","-0.00037"
"12.00000","73.39771","403.47650","0.00398","0.00096","40.34765","-0.00034"
"12.10000","73.40100","405.51376","0.00401","0.00096","40.55138","-0.00033"
"12.20000","73.40428","407.33716","0.00404","0.00093","40.73372","-0.00032"
"12.30000","73.40771","409.65680","0.00408","0.00093","40.96568","-0.00032"
"12.40000","73.41119","411.94031","0.00411","0.00095","41.19403","-0.00034"
"12.50000","73.41430","413.55029","0.00414","0.00094","41.35503","-0.00035"
"12.60000","73.41767","415.72919","0.00418","0.00094","41.57292","-0.00036"
"12.70000","73.42096","417.60742","0.00421","0.00097","41.76074","-0.00034"
"12.80000","73.42433","419.58057","0.00424","0.00098","41.95806","-0.00037"
"12.90000","73.42762","421.63489","0.00428","0.00099","42.16349","-0.00038"
"13.00000","73.43102","423.68976","0.00431","0.00098","42.36898","-0.00037"
"13.10000","73.43449","425.98230","0.00434","0.00101","42.59823","-0.00037"
"13.20000","73.43761","427.63898","0.00438","0.00103","42.76390","-0.00040"
"13.30000","73.44102","429.80054","0.00441","0.00101","42.98005","-0.00040"
"13.40000","73.44424","431.70667","0.00444","0.00102","43.17067","-0.00040"
"13.50000","73.44769","433.83771","0.00448","0.00103","43.38377","-0.00042"
"13.60000","73.45100","435.78586","0.00451","0.00104","43.57859","-0.00042"
"13.70000","73.45441","437.91431","0.00454","0.00105","43.79143","-0.00040"
"13.80000","73.45779","439.95288","0.00458","0.00107","43.99529","-0.00040"
"13.90000","73.46095","441.77628","0.00461","0.00109","44.17763","-0.00038"
"14.00000","73.46443","443.74615","0.00464","0.00109","44.37461","-0.00038"
"14.10000","73.46766","445.48715","0.00468","0.00109","44.54871","-0.00037"
"14.20000","73.47105","447.33664","0.00471","0.00109","44.73367","-0.00039"
"14.30000","73.47434","449.20657","0.00474","0.00111","44.92066","-0.00037"
"14.40000","73.47769","451.15186","0.00478","0.00112","45.11518","-0.00038"
"14.50000","73.48100","452.88181","0.00481","0.00112","45.28818","-0.00040"
"14.60000","73.48427","454.54803","0.00484","0.00114","45.45480","-0.00037"
"14.70000","73.48777","456.79404","0.00488","0.00113","45.67941","-0.00039"
"14.80000","73.49105","458.36508","0.00491","0.00116","45.83651","-0.00040"
"14.90000","73.49432","460.10074","0.00494","0.00116","46.01007","-0.00040"
"15.00000","73.49764","461.94000","0.00498","0.00116","46.19400","-0.00040"
"15.10000","73.50101","463.68985","0.00501","0.00116","46.36898","-0.00040"
"15.20000","73.50426","465.46463","0.00504","0.00117","46.54646","-0.00038"
"15.30000","73.50758","467.18088","0.00508","0.00116","46.71809","-0.00038"
"15.40000","73.51112","469.26752","0.00511","0.00117","46.92675","-0.00040"
"15.50000","73.51447","471.12015","0.00514","0.00118","47.11201","-0.00040"
"15.60000","73.51771","472.74725","0.00518","0.00120","47.27473","-0.00040"
"15.70000","73.52101","474.50903","0.00521","0.00118","47.45090","-0.00040"
"15.80000","73.52443","476.45718","0.00524","0.00121","47.64572","-0.00040"
"15.90000","73.52760","478.04547","0.00528","0.00120","47.80455","-0.00041"
"16.00000","73.53098","479.97083","0.00531","0.00120","47.99708","-0.00044"
"16.10000","73.53443","481.99408","0.00534","0.00119","48.19941","-0.00045"
"16.20000","73.53779","483.85989","0.00538","0.00123","48.38599","-0.00047"
"16.30000","73.54092","485.44034","0.00541","0.00123","48.54403","-0.00049"
"16.40000","73.54435","487.29050","0.00544","0.00125","48.72905","-0.00049"
"16.50000","73.54764","488.96643","0.00548","0.00127","48.89664","-0.00049"
"16.60000","73.55095","490.71381","0.00551","0.00129","49.07138","-0.00050"
"16.70000","73.55433","492.37656","0.00554","0.00129","49.23766","-0.00048"
"16.80000","73.55773","494.08096","0.00558","0.00130","49.40810","-0.00052"
"16.90000","73.56113","495.70169","0.00561","0.00129","49.57017","-0.00052"
"17.00000","73.56416","496.80179","0.00564","0.00130","49.68018","-0.00050"
"17.10000","73.56776","498.95871","0.00568","0.00130","49.89587","-0.00050"
"17.20000","73.57104","500.44400","0.00571","0.00130","50.04440","-0.00052"
"17.30000","73.57428","501.79587","0.00574","0.00130","50.17959","-0.00052"
"17.40000","73.57771","503.68674","0.00578","0.00131","50.36868","-0.00051"
"17.50000","73.58104","505.40628","0.00581","0.00132","50.54063","-0.00052"
"17.60000","73.58447","507.05945","0.00584","0.00133","50.70594","-0.00050"
"17.70000","73.58753","508.31592","0.00588","0.00132","50.83159","-0.00050"
"17.80000","73.59110","510.33200","0.00591","0.00132","51.03320","-0.00053"
"17.90000","73.59443","512.00024","0.00594","0.00135","51.20002","-0.00053"
"18.00000","73.59766","513.54883","0.00598","0.00139","51.35488","-0.00053"
"18.10000","73.60096","515.08588","0.00601","0.00141","51.50859","-0.00053"
"18.20000","73.60433","516.70898","0.00604","0.00141","51.67090","-0.00055"
"18.30000","73.60771","518.46368","0.00608","0.00140","51.84637","-0.00054"
"18.40000","73.61086","519.86993","0.00611","0.00141","51.98699","-0.00056"
"18.50000","73.61440","521.89392","0.00614","0.00141","52.18939","-0.00056"
"18.60000","73.61778","523.42346","0.00618","0.00142","52.34235","-0.00056"
"18.70000","73.62097","524.84241","0.00621","0.00141","52.48424","-0.00053"
"18.80000","73.62428","526.62915","0.00624","0.00141","52.66291","-0.00055"
"18.90000","73.62763","528.34253","0.00628","0.00141","52.83425","-0.00054"
"19.00000","73.63101","529.99475","0.00631","0.00144","52.99947","-0.00053"
"19.10000","73.63422","531.54449","0.00634","0.00145","53.15445","-0.00053"
"19.20000","73.63782","533.71533","0.00638","0.00147","53.37153","-0.00052"
"19.30000","73.64114","535.17438","0.00641","0.00147","53.51744","-0.00050"
"19.40000","73.64436","536.68933","0.00644","0.00145","53.66893","-0.00050"
"19.50000","73.64766","538.51941","0.00648","0.00147","53.85194","-0.00052"
"19.60000","73.65105","540.28656","0.00651","0.00148","54.02866","-0.00050"
"19.70000","73.65432","541.85583","0.00654","0.00149","54.18559","-0.00049"
"19.80000","73.65765","543.65167","0.00658","0.00150","54.36517","-0.00051"
"19.90000","73.66103","545.40424","0.00661","0.00152","54.54042","-0.00052"
"20.00000","73.66443","547.15930","0.00664","0.00150","54.71593","-0.00053"
"20.10000","73.66761","548.71051","0.00668","0.00151","54.87105","-0.00053"
"20.20000","73.67097","550.50092","0.00671","0.00152","55.05009","-0.00050"
"20.30000","73.67432","552.47125","0.00674","0.00154","55.24712","-0.00050"
"20.40000","73.67763","554.11310","0.00678","0.00154","55.41131","-0.00050"
"20.50000","73.68102","555.95508","0.00681","0.00152","55.59551","-0.00050"
"20.60000","73.68433","557.80176","0.00684","0.00154","55.78017","-0.00053"
"20.70000","73.68772","559.47455","0.00688","0.00154","55.94746","-0.00052"
"20.80000","73.69095","561.05640","0.00691","0.00154","56.10564","-0.00052"
"20.90000","73.69442","563.19629","0.00694","0.00153","56.31963","-0.00055"
"21.00000","73.69784","565.12164","0.00698","0.00156","56.51217","-0.00053"
"21.10000","73.70100","566.61737","0.00701","0.00156","56.66174","-0.00053"
"21.20000","73.70440","568.56439","0.00704","0.00155","56.85644","-0.00053"
"21.30000","73.70763","570.19452","0.00708","0.00156","57.01945","-0.00054"
"21.40000","73.71101","572.15668","0.00711","0.00156","57.21567","-0.00055"
"21.50000","73.71427","574.00555","0.00714","0.00157","57.40055","-0.00056"
"21.60000","73.71773","576.04431","0.00718","0.00158","57.60443","-0.00056"
"21.70000","73.72108","577.90784","0.00721","0.00158","57.79078","-0.00054"
"21.80000","73.72428","579.45911","0.00724","0.00160","57.94591","-0.00053"
"21.90000","73.72773","581.48193","0.00728","0.00160","58.14819","-0.00056"
"22.00000","73.73093","583.17596","0.00731","0.00161","58.31760","-0.00059"
"22.10000","73.73430","584.95447","0.00734","0.00163","58.49545","-0.00060"
"22.20000","73.73757","586.64435","0.00738","0.00165","58.66444","-0.00059"
"22.30000","73.74110","588.67664","0.00741","0.00165","58.86766","-0.00058"
"22.40000","73.74442","590.49976","0.00744","0.00163","59.04998","-0.00061"
"22.50000","73.74759","592.02429","0.00748","0.00168","59.20243","-0.00061"
"22.60000","73.75108","594.03705","0.00751","0.00167","59.40371","-0.00058"
"22.70000","73.75436","595.71661","0.00754","0.00167","59.57166","-0.00059"
"22.80000","73.75768","597.53992","0.00758","0.00168","59.75399","-0.00061"
"22.90000","73.76102","599.09613","0.00761","0.00168","59.90961","-0.00058"
"23.00000","73.76447","601.09344","0.00764","0.00168","60.10934","-0.00058"
"23.10000","73.76775","602.80615","0.00768","0.00170","60.28062","-0.00058"
"23.20000","73.77092","604.40961","0.00771","0.00172","60.44096","-0.00059"
"23.30000","73.77437","606.31757","0.00774","0.00174","60.63176","-0.00058"
"23.40000","73.77771","608.35730","0.00778","0.00173","60.83573","-0.00059"
"23.50000","73.78094","610.20642","0.00781","0.00174","61.02064","-0.00058"
"23.60000","73.78432","612.58911","0.00784","0.00175","61.25891","-0.00058"
"23.70000","73.78776","614.97412","0.00788","0.00177","61.49741","-0.00058"
"23.80000","73.79102","617.27289","0.00791","0.00179","61.72729","-0.00058"
"23.90000","73.79420","619.29236","0.00794","0.00178","61.92924","-0.00056"
"24.00000","73.79778","622.33984","0.00798","0.00178","62.23399","-0.00053"
"24.10000","73.80105","624.70966","0.00801","0.00180","62.47097","-0.00053"
"24.20000","73.80431","626.89325","0.00804","0.00182","62.68932","-0.00053"
"24.30000","73.80762","629.30212","0.00808","0.00182","62.93021","-0.00051"
"24.40000","73.81104","631.76776","0.00811","0.00184","63.17678","-0.00051"
"24.50000","73.81433","634.18085","0.00814","0.00186","63.41808","-0.00050"
"24.60000","73.81762","636.46484","0.00818","0.00187","63.64648","-0.00051"
"24.70000","73.82117","638.92633","0.00821","0.00187","63.89263","-0.00051"
"24.80000","73.82454","641.39490","0.00825","0.00187","64.13949","-0.00052"
"24.90000","73.82760","643.00891","0.00828","0.00189","64.30089","-0.00052"
"25.00000","73.83104","645.36102","0.00831","0.00188","64.53610","-0.00050"
"25.10000","73.83431","647.26385","0.00834","0.00189","64.72639","-0.00048"
"25.20000","73.83764","649.24310","0.00838","0.00192","64.92431","-0.00048"
"25.30000","73.84093","651.24060","0.00841","0.00192","65.12406","-0.00048"
"25.40000","73.84442","653.56189","0.00844","0.00193","65.35619","-0.00050"
"25.50000","73.84785","655.86670","0.00848","0.00194","65.58667","-0.00050"
"25.60000","73.85089","657.25751","0.00851","0.00196","65.72575","-0.00050"
"25.70000","73.85425","659.53723","0.00854","0.00197","65.95372","-0.00050"
"25.80000","73.85770","661.55981","0.00858","0.00198","66.15598","-0.00050"
"25.90000","73.86094","663.17731","0.00861","0.00199","66.31773","-0.00050"
"26.00000","73.86426","664.70648","0.00864","0.00199","66.47065","-0.00053"
"26.10000","73.86775","666.13269","0.00868","0.00200","66.61327","-0.00053"
"26.20000","73.87114","667.16840","0.00871","0.00202","66.71684","-0.00055"
"26.30000","73.87424","668.51349","0.00874","0.00202","66.85135","-0.00055"
"26.40000","73.87778","670.97900","0.00878","0.00202","67.09790","-0.00058"
"26.50000","73.88112","672.90118","0.00881","0.00203","67.29012","-0.00058"
"26.60000","73.88440","675.06342","0.00884","0.00203","67.50634","-0.00058"
"26.70000","73.88765","676.99634","0.00888","0.00205","67.69963","-0.00058"
"26.80000","73.89103","679.24829","0.00891","0.00205","67.92483","-0.00058"
"26.90000","73.89440","681.47180","0.00894","0.00207","68.14718","-0.00062"
"27.00000","73.89754","683.32947","0.00898","0.00206","68.33295","-0.00061"
"27.10000","73.90101","685.62555","0.00901","0.00205","68.56255","-0.00060"
"27.20000","73.90440","687.83063","0.00904","0.00204","68.78307","-0.00061"
"27.30000","73.90769","689.73560","0.00908","0.00205","68.97356","-0.00062"
"27.40000","73.91101","691.81482","0.00911","0.00205","69.18148","-0.00064"
"27.50000","73.91423","693.58972","0.00914","0.00207","69.35897","-0.00061"
"27.60000","73.91767","695.93390","0.00918","0.00208","69.59339","-0.00061"
"27.70000","73.92095","698.02692","0.00921","0.00210","69.80269","-0.00061"
"27.80000","73.92442","700.24957","0.00924","0.00212","70.02496","-0.00064"
"27.90000","73.92774","702.33173","0.00928","0.00212","70.23317","-0.00067"
"28.00000","73.93095","704.10315","0.00931","0.00214","70.41032","-0.00066"
"28.10000","73.93431","706.26196","0.00934","0.00214","70.62620","-0.00069"
"28.20000","73.93769","708.22986","0.00938","0.00217","70.82298","-0.00069"
"28.30000","73.94099","710.20026","0.00941","0.00217","71.02003","-0.00068"
"28.40000","73.94434","712.46240","0.00944","0.00217","71.24624","-0.00066"
"28.50000","73.94776","714.55371","0.00948","0.00218","71.45537","-0.00068"
"28.60000","73.95113","716.90979","0.00951","0.00219","71.69098","-0.00066"
"28.70000","73.95432","718.62598","0.00954","0.00220","71.86259","-0.00066"
"28.80000","73.95765","720.59338","0.00958","0.00223","72.05934","-0.00067"
"28.90000","73.96095","722.61670","0.00961","0.00221","72.26167","-0.00069"
"29.00000","73.96428","724.42822","0.00964","0.00223","72.44283","-0.00069"
"29.10000","73.96770","726.64417","0.00968","0.00223","72.66441","-0.00071"
"29.20000","73.97105","728.68713","0.00971","0.00223","72.86871","-0.00071"
"29.30000","73.97439","730.78394","0.00974","0.00223","73.07839","-0.00072"
"29.40000","73.97756","732.47815","0.00978","0.00223","73.24782","-0.00072"
"29.50000","73.98100","734.80975","0.00981","0.00226","73.48097","-0.00074"
"29.60000","73.98435","736.79706","0.00984","0.00230","73.67970","-0.00072"
"29.70000","73.98760","738.63287","0.00988","0.00232","73.86329","-0.00071"
"29.80000","73.99103","740.82208","0.00991","0.00232","74.08221","-0.00071"
"29.90000","73.99438","742.79144","0.00994","0.00234","74.27914","-0.00069"
"30.00000","73.99773","744.76855","0.00998","0.00235","74.47685","-0.00071"
"30.10000","74.00095","746.63916","0.01001","0.00235","74.66392","-0.00070"
"30.20000","74.00439","748.94183","0.01004","0.00235","74.89418","-0.00072"
"30.30000","74.00783","751.05585","0.01008","0.00237","75.10558","-0.00074"
"30.40000","74.01101","752.76599","0.01011","0.00241","75.27660","-0.00071"
"30.50000","74.01440","754.95337","0.01014","0.00241","75.49534","-0.00072"
"30.60000","74.01764","756.68744","0.01018","0.00242","75.66875","-0.00072"
"30.70000","74.02097","758.73969","0.01021","0.00242","75.87397","-0.00073"
"30.80000","74.02421","760.51282","0.01024","0.00242","76.05128","-0.00073"
"30.90000","74.02783","763.11621","0.01028","0.00243","76.31162","-0.00072"
"31.00000","74.03110","764.98401","0.01031","0.00243","76.49840","-0.00071"
"31.10000","74.03424","766.57269","0.01034","0.00244","76.65727","-0.00071"
"31.20000","74.03769","768.79053","0.01038","0.00244","76.87905","-0.00074"
"31.30000","74.04095","770.58917","0.01041","0.00246","77.05891","-0.00072"
"31.40000","74.04429","772.49841","0.01044","0.00246","77.24984","-0.00074"
"31.50000","74.04756","774.36676","0.01048","0.00248","77.43668","-0.00075"
"31.60000","74.05116","776.83380","0.01051","0.00248","77.68338","-0.00077"
"31.70000","74.05448","778.80975","0.01054","0.00250","77.88097","-0.00077"
"31.80000","74.05762","780.35132","0.01058","0.00250","78.03513","-0.00076"
"31.90000","74.06107","782.52869","0.01061","0.00252","78.25287","-0.00077"
"32.00000","74.06431","784.26807","0.01064","0.00252","78.42680","-0.00079"
"32.10000","74.06771","786.43896","0.01068","0.00254","78.64390","-0.00082"
"32.20000","74.07096","788.11731","0.01071","0.00256","78.81173","-0.00082"
"32.30000","74.07444","790.22711","0.01074","0.00256","79.02271","-0.00084"
"32.40000","74.07776","792.36713","0.01078","0.00258","79.23671","-0.00085"
"32.50000","74.08089","793.88525","0.01081","0.00260","79.38853","-0.00087"
"32.60000","74.08435","796.01251","0.01084","0.00260","79.60125","-0.00090"
"32.70000","74.08776","798.01886","0.01088","0.00261","79.80189","-0.00094"
"32.80000","74.09100","799.72949","0.01091","0.00261","79.97295","-0.00093"
"32.90000","74.09427","801.65808","0.01094","0.00261","80.16581","-0.00093"
"33.00000","74.09774","803.81653","0.01098","0.00263","80.38165","-0.00095"
"33.10000","74.10099","805.63586","0.01101","0.00264","80.56358","-0.00097"
"33.20000","74.10425","807.43915","0.01104","0.00264","80.74391","-0.00098"
"33.30000","74.10769","809.81012","0.01108","0.00264","80.98101","-0.00101"
"33.40000","74.11116","811.99854","0.01111","0.00263","81.19985","-0.00103"
"33.50000","74.11434","813.64282","0.01114","0.00264","81.36428","-0.00103"
"33.60000","74.11768","815.64197","0.01118","0.00266","81.56419","-0.00104"
"33.70000","74.12104","817.54767","0.01121","0.00268","81.75477","-0.00103"
"33.80000","74.12434","819.44006","0.01124","0.00268","81.94401","-0.00103"
"33.90000","74.12765","821.37946","0.01128","0.00270","82.13795","-0.00106"
"34.00000","74.13109","823.67084","0.01131","0.00272","82.36708","-0.00106"
"34.10000","74.13453","825.79443","0.01135","0.00274","82.57944","-0.00105"
"34.20000","74.13764","827.37299","0.01138","0.00275","82.73730","-0.00109"
"34.30000","74.14102","829.62067","0.01141","0.00277","82.96207","-0.00108"
"34.40000","74.14423","831.18805","0.01144","0.00277","83.11880","-0.00111"
"34.50000","74.14771","833.32977","0.01148","0.00279","83.33298","-0.00109"
"34.60000","74.15096","835.33795","0.01151","0.00281","83.53380","-0.00111"
"34.70000","74.15436","837.46472","0.01154","0.00279","83.74648","-0.00111"
"34.80000","74.15782","839.75903","0.01158","0.00281","83.97591","-0.00111"
"34.90000","74.16093","841.08368","0.01161","0.00281","84.10837","-0.00111"
"35.00000","74.16435","843.32690","0.01164","0.00281","84.33269","-0.00111"
"35.10000","74.16763","845.02704","0.01168","0.00284","84.50270","-0.00111"
"35.20000","74.17096","846.98395","0.01171","0.00284","84.69839","-0.00111"
"35.30000","74.17433","849.16095","0.01174","0.00284","84.91609","-0.00112"
"35.40000","74.17775","851.23175","0.01178","0.00286","85.12318","-0.00111"
"35.50000","74.18112","853.26990","0.01181","0.00286","85.32699","-0.00114"
"35.60000","74.18428","855.02539","0.01184","0.00288","85.50254","-0.00114"
"35.70000","74.18778","857.27118","0.01188","0.00290","85.72712","-0.00114"
"35.80000","74.19106","859.18658","0.01191","0.00288","85.91866","-0.00115"
"35.90000","74.19439","860.95013","0.01194","0.00290","86.09502","-0.00111"
"36.00000","74.19765","862.75226","0.01198","0.00290","86.27522","-0.00113"
"36.10000","74.20100","864.70471","0.01201","0.00292","86.47047","-0.00114"
"36.20000","74.20429","866.51587","0.01204","0.00292","86.65159","-0.00115"
"36.30000","74.20760","868.42242","0.01208","0.00293","86.84224","-0.00118"
"36.40000","74.21111","870.50061","0.01211","0.00295","87.05006","-0.00116"
"36.50000","74.21436","872.24786","0.01214","0.00293","87.22478","-0.00118"
"36.60000","74.21766","874.16547","0.01218","0.00294","87.41655","-0.00119"
"36.70000","74.22099","875.96533","0.01221","0.00294","87.59653","-0.00119"
"36.80000","74.22434","877.76007","0.01224","0.00294","87.77601","-0.00119"
"36.90000","74.22759","879.36578","0.01228","0.00294","87.93658","-0.00119"
"37.00000","74.23093","881.26532","0.01231","0.00294","88.12653","-0.00119"
"37.10000","74.23444","883.53650","0.01234","0.00295","88.35365","-0.00116"
"37.20000","74.23782","885.36432","0.01238","0.00294","88.53643","-0.00116"
"37.30000","74.24101","887.11084","0.01241","0.00295","88.71108","-0.00116"
"37.40000","74.24431","888.90485","0.01244","0.00295","88.89049","-0.00119"
"37.50000","74.24773","890.85345","0.01248","0.00295","89.08534","-0.00119"
"37.60000","74.25092","892.62415","0.01251","0.00295","89.26241","-0.00119"
"37.70000","74.25433","894.62604","0.01254","0.00295","89.46260","-0.00119"
"37.80000","74.25774","896.65594","0.01258","0.00296","89.66560","-0.00122"
"37.90000","74.26112","898.62842","0.01261","0.00294","89.86284","-0.00124"
"38.00000","74.26423","899.96289","0.01264","0.00296","89.99629","-0.00126"
"38.10000","74.26771","902.26654","0.01268","0.00297","90.22665","-0.00127"
"38.20000","74.27100","904.06842","0.01271","0.00295","90.40685","-0.00127"
"38.30000","74.27425","905.84912","0.01274","0.00295","90.58492","-0.00128"
"38.40000","74.27767","907.91711","0.01278","0.00297","90.79171","-0.00128"
"38.50000","74.28108","909.83044","0.01281","0.00296","90.98305","-0.00127"
"38.60000","74.28443","911.76367","0.01284","0.00297","91.17637","-0.00128"
"38.70000","74.28749","913.15967","0.01287","0.00298","91.31596","-0.00124"
"38.80000","74.29108","915.43243","0.01291","0.00297","91.54324","-0.00125"
"38.90000","74.29440","916.81311","0.01294","0.00297","91.68131","-0.00127"
"39.00000","74.29762","918.24561","0.01298","0.00297","91.82456","-0.00125"
"39.10000","74.30105","920.11493","0.01301","0.00298","92.01149","-0.00127"
"39.20000","74.30437","921.77216","0.01304","0.00299","92.17722","-0.00129"
"39.30000","74.30779","923.68762","0.01308","0.00301","92.36876","-0.00132"
"39.40000","74.31085","924.87158","0.01311","0.00301","92.48716","-0.00132"
"39.50000","74.31451","927.28326","0.01314","0.00303","92.72832","-0.00132"
"39.60000","74.31776","928.77911","0.01318","0.00302","92.87791","-0.00132"
"39.70000","74.32098","930.49213","0.01321","0.00300","93.04921","-0.00129"
"39.80000","74.32429","932.29010","0.01324","0.00302","93.22901","-0.00130"
"39.90000","74.32765","934.13843","0.01328","0.00302","93.41384","-0.00130"
"40.00000","74.33106","935.83258","0.01331","0.00304","93.58326","-0.00130"
"40.10000","74.33420","937.04004","0.01334","0.00306","93.70400","-0.00131"
"40.20000","74.33775","938.85931","0.01338","0.00303","93.88593","-0.00129"
"40.30000","74.34115","940.44122","0.01341","0.00305","94.04412","-0.00132"
"40.40000","74.34428","941.34564","0.01344","0.00306","94.13457","-0.00132"
"40.50000","74.34762","943.12738","0.01348","0.00305","94.31274","-0.00132"
"40.60000","74.35099","944.73175","0.01351","0.00305","94.47318","-0.00133"
"40.70000","74.35433","946.39539","0.01354","0.00306","94.63954","-0.00134"
"40.80000","74.35762","948.18378","0.01358","0.00304","94.81837","-0.00133"
"40.90000","74.36114","950.27777","0.01361","0.00304","95.02778","-0.00136"
"41.00000","74.36446","952.13464","0.01364","0.00303","95.21346","-0.00134"
"41.10000","74.36770","953.64832","0.01368","0.00307","95.36483","-0.00130"
"41.20000","74.37101","955.40991","0.01371","0.00310","95.54099","-0.00132"
"41.30000","74.37440","957.30908","0.01374","0.00310","95.73091","-0.00132"
"41.40000","74.37765","959.10199","0.01378","0.00309","95.91020","-0.00131"
"41.50000","74.38098","960.85376","0.01381","0.00310","96.08537","-0.00131"
"41.60000","74.38435","962.81671","0.01384","0.00310","96.28167","-0.00130"
"41.70000","74.38774","964.98224","0.01388","0.00310","96.49822","-0.00132"
"41.80000","74.39091","966.42303","0.01391","0.00310","96.64230","-0.00134"
"41.90000","74.39430","968.61115","0.01394","0.00310","96.86111","-0.00132"
"42.00000","74.39770","970.52258","0.01398","0.00312","97.05226","-0.00134"
"42.10000","74.40098","972.45953","0.01401","0.00313","97.24596","-0.00133"
"42.20000","74.40434","974.38013","0.01404","0.00317","97.43801","-0.00132"
"42.30000","74.40765","976.19525","0.01408","0.00317","97.61952","-0.00132"
"42.40000","74.41105","978.19708","0.01411","0.00320","97.81971","-0.00132"
"42.50000","74.41430","979.90784","0.01414","0.00321","97.99078","-0.00132"
"42.60000","74.41776","982.12866","0.01418","0.00321","98.21287","-0.00130"
"42.70000","74.42116","984.26135","0.01421","0.00321","98.42613","-0.00131"
"42.80000","74.42432","985.84863","0.01424","0.00321","98.58486","-0.00130"
"42.90000","74.42775","987.98529","0.01428","0.00323","98.79853","-0.00128"
"43.00000","74.43094","989.58087","0.01431","0.00323","98.95808","-0.00130"
"43.10000","74.43436","991.61200","0.01434","0.00324","99.16120","-0.00131"
"43.20000","74.43759","993.33813","0.01438","0.00324","99.33382","-0.00132"
"43.30000","74.44107","995.74963","0.01441","0.00327","99.57497","-0.00134"
"43.40000","74.44442","997.58899","0.01444","0.00328","99.75890","-0.00133"
"43.50000","74.44766","999.33325","0.01448","0.00330","99.93333","-0.00135"
"43.60000","74.45108","1001.57996","0.01451","0.00328","100.15800","-0.00135"
"43.70000","74.45424","1002.80603","0.01454","0.00330","100.28060","-0.00133"
"43.80000","74.45761","1004.62250","0.01458","0.00330","100.46225","-0.00132"
"43.90000","74.46095","1006.50397","0.01461","0.00330","100.65040","-0.00133"
"44.00000","74.46445","1008.43982","0.01464","0.00331","100.84398","-0.00135"
"44.10000","74.46773","1009.86212","0.01468","0.00335","100.98621","-0.00135"
"44.20000","74.47088","1011.25061","0.01471","0.00334","101.12506","-0.00135"
"44.30000","74.47440","1013.28455","0.01474","0.00335","101.32845","-0.00133"
"44.40000","74.47771","1014.70770","0.01478","0.00335","101.47077","-0.00135"
"44.50000","74.48097","1016.31720","0.01481","0.00335","101.63172","-0.00135"
"44.60000","74.48436","1018.12372","0.01484","0.00336","101.81237","-0.00138"
"44.70000","74.48782","1020.06897","0.01488","0.00338","102.00690","-0.00137"
"44.80000","74.49105","1021.38965","0.01491","0.00337","102.13896","-0.00138"
"44.90000","74.49426","1022.83118","0.01494","0.00335","102.28312","-0.00140"
"45.00000","74.49773","1024.03455","0.01498","0.00336","102.40346","-0.00140"
"45.10000","74.50105","1025.19983","0.01501","0.00336","102.51998","-0.00140"
"45.20000","74.50428","1026.62659","0.01504","0.00339","102.66266","-0.00140"
"45.30000","74.50767","1028.23120","0.01508","0.00339","102.82312","-0.00140"
"45.40000","74.51107","1029.59607","0.01511","0.00341","102.95961","-0.00140"
"45.50000","74.51431","1030.85083","0.01514","0.00340","103.08508","-0.00140"
"45.60000","74.51756","1032.31982","0.01518","0.00341","103.23198","-0.00140"
"45.70000","74.52111","1034.31653","0.01521","0.00341","103.43166","-0.00142"
"45.80000","74.52440","1035.72791","0.01524","0.00340","103.57279","-0.00143"
"45.90000","74.52761","1037.00537","0.01528","0.00341","103.70054","-0.00146"
"46.00000","74.53099","1038.76013","0.01531","0.00342","103.87601","-0.00146"
"46.10000","74.53429","1040.56567","0.01534","0.00345","104.05656","-0.00146"
"46.20000","74.53764","1042.29773","0.01538","0.00345","104.22977","-0.00143"
"46.30000","74.54095","1044.22571","0.01541","0.00346","104.42257","-0.00144"
"46.40000","74.54450","1046.25415","0.01544","0.00346","104.62541","-0.00146"
"46.50000","74.54790","1048.14209","0.01548","0.00347","104.81421","-0.00145"
"46.60000","74.55093","1049.29773","0.01551","0.00348","104.92977","-0.00143"
"46.70000","74.55441","1051.38550","0.01554","0.00346","105.13855","-0.00145"
"46.80000","74.55761","1052.99133","0.01558","0.00344","105.29913","-0.00145"
"46.90000","74.56097","1054.85999","0.01561","0.00344","105.48600","-0.00143"
"47.00000","74.56426","1056.77148","0.01564","0.00346","105.67715","-0.00146"
"47.10000","74.56773","1058.91858","0.01568","0.00346","105.89186","-0.00145"
"47.20000","74.57119","1061.19202","0.01571","0.00346","106.11920","-0.00143"
"47.30000","74.57423","1062.46338","0.01574","0.00347","106.24634","-0.00143"
"47.40000","74.57759","1064.73889","0.01578","0.00348","106.47389","-0.00143"
"47.50000","74.58107","1066.90430","0.01581","0.00345","106.69043","-0.00144"
"47.60000","74.58429","1068.59705","0.01584","0.00346","106.85970","-0.00146"
"47.70000","74.58762","1070.68774","0.01588","0.00345","107.06877","-0.00146"
"47.80000","74.59103","1072.51489","0.01591","0.00348","107.25149","-0.00147"
"47.90000","74.59444","1074.28027","0.01594","0.00348","107.42802","-0.00151"
"48.00000","74.59758","1075.73816","0.01598","0.00349","107.57381","-0.00151"
"48.10000","74.60106","1077.91650","0.01601","0.00350","107.79165","-0.00151"
"48.20000","74.60444","1079.89514","0.01604","0.00350","107.98952","-0.00154"
"48.30000","74.60772","1081.17151","0.01608","0.00352","108.11715","-0.00151"
"48.40000","74.61096","1082.40930","0.01611","0.00353","108.24093","-0.00151"
"48.50000","74.61436","1083.87061","0.01614","0.00355","108.38706","-0.00151"
"48.60000","74.61771","1085.63208","0.01618","0.00356","108.56321","-0.00150"
"48.70000","74.62086","1086.97437","0.01621","0.00356","108.69743","-0.00148"
"48.80000","74.62437","1089.06091","0.01624","0.00354","108.90609","-0.00148"
"48.90000","74.62777","1090.95496","0.01628","0.00353","109.09550","-0.00148"
"49.00000","74.63102","1092.44067","0.01631","0.00353","109.24406","-0.00151"
"49.10000","74.63434","1094.13562","0.01634","0.00352","109.41356","-0.00148"
"49.20000","74.63757","1094.72754","0.01638","0.00351","109.47276","-0.00149"
"49.30000","74.64098","1095.14514","0.01641","0.00353","109.51451","-0.00148"
"49.40000","74.64429","1096.35278","0.01644","0.00353","109.63528","-0.00146"
"49.50000","74.64774","1098.02820","0.01648","0.00353","109.80282","-0.00148"
"49.60000","74.65112","1099.64014","0.01651","0.00353","109.96401","-0.00148"
"49.70000","74.65428","1100.70142","0.01654","0.00353","110.07014","-0.00145"
"49.80000","74.65767","1102.53516","0.01658","0.00354","110.25352","-0.00144"
"49.90000","74.66103","1103.98608","0.01661","0.00355","110.39861","-0.00146"
"50.00000","74.66432","1105.74365","0.01664","0.00355","110.57436","-0.00146"
"50.10000","74.66771","1107.43433","0.01668","0.00357","110.74343","-0.00149"
"50.20000","74.67110","1108.93787","0.01671","0.00359","110.89378","-0.00149"
"50.30000","74.67445","1110.58777","0.01674","0.00357","111.05878","-0.00151"
"50.40000","74.67764","1111.96106","0.01678","0.00360","111.19611","-0.00151"
"50.50000","74.68099","1113.57703","0.01681","0.00360","111.35770","-0.00151"
"50.60000","74.68433","1115.09436","0.01684","0.00360","111.50944","-0.00151"
"50.70000","74.68764","1116.46533","0.01688","0.00361","111.64653","-0.00151"
"50.80000","74.69102","1118.02087","0.01691","0.00361","111.80209","-0.00151"
"50.90000","74.69440","1119.57056","0.01694","0.00363","111.95705","-0.00149"
"51.00000","74.69770","1121.00500","0.01698","0.00364","112.10050","-0.00147"
"51.10000","74.70090","1122.32617","0.01701","0.00362","112.23262","-0.00148"
"51.20000","74.70435","1124.23901","0.01704","0.00364","112.42390","-0.00150"
"51.30000","74.70770","1125.40222","0.01708","0.00368","112.54022","-0.00151"
"51.40000","74.71095","1126.45203","0.01711","0.00367","112.64520","-0.00153"
"51.50000","74.71436","1127.86035","0.01714","0.00370","112.78603","-0.00153"
"51.60000","74.71770","1128.85046","0.01718","0.00373","112.88505","-0.00153"
"51.70000","74.72104","1129.81934","0.01721","0.00374","112.98193","-0.00153"
"51.80000","74.72432","1129.67322","0.01724","0.00375","112.96732","-0.00156"
"51.90000","74.72779","1130.12415","0.01728","0.00375","113.01241","-0.00156"
"52.00000","74.73117","1130.08752","0.01731","0.00376","113.00875","-0.00158"
"52.10000","74.73432","1128.28247","0.01734","0.00374","112.82825","-0.00159"
"52.20000","74.73769","1125.38574","0.01738","0.00373","112.53857","-0.00161"
"52.30000","74.74097","1121.64490","0.01741","0.00372","112.16449","-0.00158"
"52.40000","74.74429","1116.55066","0.01744","0.00369","111.65507","-0.00156"
"52.50000","74.74756","1113.64441","0.01748","0.00368","111.36444","-0.00155"
"52.60000","74.75115","1109.88110","0.01751","0.00367","110.98811","-0.00155"
"52.70000","74.75443","1105.05029","0.01754","0.00364","110.50503","-0.00154"
"52.80000","74.75756","1102.41248","0.01758","0.00361","110.24125","-0.00156"
"52.90000","74.76105","1093.16553","0.01761","0.00357","109.31655","-0.00153"
"53.00000","74.76427","1082.87305","0.01764","0.00356","108.28731","-0.00153"
"53.10000","74.76765","1059.81104","0.01768","0.00351","105.98110","-0.00155"
"53.20000","74.77092","1046.28125","0.01771","0.00346","104.62813","-0.00153"
"53.30000","74.77451","1000.04926","0.01774","0.00336","100.00493","-0.00151"
"53.40000","74.77785","951.92578","0.01778","0.00316","95.19258","-0.00150"
"53.50000","74.78092","905.32684","0.01781","0.00293","90.53268","-0.00147"
"53.60000","74.78440","885.03973","0.01784","0.00292","88.50397","-0.00145"
"53.70000","74.78775","837.36163","0.01788","0.00278","83.73616","-0.00147"
"53.75600","74.78975","709.23346","0.01790","0.00254","70.92335","-0.00143"
"53.79300","74.79085","582.00092","0.01791","0.00194","58.20009","-0.00134"
"53.89300","74.79410","458.15720","0.01794","0.00126","45.81572","-0.00100"
"53.99300","74.79758","409.71542","0.01798","0.00070","40.97154","-0.00100"
"54.09300","74.80086","383.32104","0.01801","0.00059","38.33210","-0.00100"
"54.19300","74.80402","372.56595","0.01804","0.00057","37.25660","-0.00097"
"54.29300","74.80742","364.56320","0.01807","0.00035","36.45632","-0.00095"
"54.39300","74.81082","359.62653","0.01811","0.00027","35.96265","-0.00095"
"54.49300","74.81412","355.41354","0.01814","0.00043","35.54136","-0.00095"
"54.59300","74.81738","352.60052","0.01817","0.00052","35.26005","-0.00095"
"54.69300","74.82083","350.57217","0.01821","0.00051","35.05722","-0.00099"
"54.79300","74.82410","348.92355","0.01824","0.00048","34.89236","-0.00101"
"54.89300","74.82734","347.60464","0.01827","0.00049","34.76046","-0.00098"
"54.99300","74.83080","346.80725","0.01831","0.00047","34.68073","-0.00097"
"55.09300","74.83422","345.91422","0.01834","0.00047","34.59142","-0.00098"
"55.19300","74.83744","344.92273","0.01837","0.00047","34.49227","-0.00098"
"55.29300","74.84077","344.29651","0.01841","0.00050","34.42965","-0.00098"
"55.39300","74.84414","343.17236","0.01844","0.00047","34.31724","-0.00100"
"55.49300","74.84743","342.52609","0.01847","0.00040","34.25261","-0.00103"
"55.59300","74.85073","342.00299","0.01851","0.00038","34.20030","-0.00103"
"55.69300","74.85416","341.80380","0.01854","0.00036","34.18038","-0.00104"
"55.79300","74.85764","341.62247","0.01858","0.00035","34.16225","-0.00105"
"55.89300","74.86073","340.85867","0.01861","0.00038","34.08587","-0.00106"
"55.99300","74.86411","340.18884","0.01864","0.00039","34.01888","-0.00103"
"56.09300","74.86738","339.37949","0.01867","0.00040","33.93795","-0.00104"
"56.19300","74.87075","338.89877","0.01871","0.00040","33.88988","-0.00106"
"56.29300","74.87408","338.70096","0.01874","0.00041","33.87009","-0.00104"
"56.39300","74.87747","338.51260","0.01877","0.00040","33.85126","-0.00103"
"56.49300","74.88090","338.23053","0.01881","0.00039","33.82305","-0.00105"
"56.59300","74.88404","337.44559","0.01884","0.00042","33.74456","-0.00106"
"56.69300","74.88745","337.11905","0.01887","0.00041","33.71191","-0.00108"
"56.79300","74.89070","336.37030","0.01891","0.00039","33.63703","-0.00110"
"56.89300","74.89410","335.93262","0.01894","0.00036","33.59326","-0.00110"
"56.99300","74.89744","335.47369","0.01897","0.00037","33.54737","-0.00108"
"57.09300","74.90087","334.47290","0.01901","0.00036","33.44729","-0.00110"
"57.19300","74.90423","333.61780","0.01904","0.00036","33.36178","-0.00111"
"57.29300","74.90740","332.88965","0.01907","0.00036","33.28896","-0.00111"
"57.39300","74.91088","332.86185","0.01911","0.00034","33.28619","-0.00111"
"57.49300","74.91410","331.21341","0.01914","0.00035","33.12134","-0.00111"
"57.59300","74.91747","330.28644","0.01917","0.00034","33.02864","-0.00112"
"57.69300","74.92078","329.74402","0.01921","0.00036","32.97440","-0.00114"
"57.79300","74.92411","329.47971","0.01924","0.00034","32.94797","-0.00111"
"57.89300","74.92739","329.17593","0.01927","0.00035","32.91759","-0.00111"
"57.99300","74.93068","329.02679","0.01931","0.00034","32.90268","-0.00108"
"58.09300","74.93420","328.83395","0.01934","0.00033","32.88340","-0.00108"
"58.19300","74.93748","328.47327","0.01937","0.00033","32.84733","-0.00111"
"58.29300","74.94074","328.08493","0.01941","0.00031","32.80849","-0.00111"
"58.39300","74.94409","327.54172","0.01944","0.00031","32.75417","-0.00114"
"58.49300","74.94745","327.07822","0.01947","0.00032","32.70782","-0.00114"
"58.59300","74.95070","326.47281","0.01951","0.00033","32.64728","-0.00114"
"58.69300","74.95404","326.21155","0.01954","0.00034","32.62115","-0.00114"
"58.79300","74.95755","326.09204","0.01958","0.00034","32.60920","-0.00113"
"58.89300","74.96091","325.72635","0.01961","0.00034","32.57264","-0.00113"
"58.99300","74.96413","325.23746","0.01964","0.00033","32.52375","-0.00116"
"59.01200","74.96471","324.93158","0.01965","0.00033","32.49316","-0.00116"