File: Tension/Section_2_Group_2/rivet_high_Sample1.is_tens_RawData/Specimen_RawData_1.csv
Time,Extension,Load,Tensile strain (Extension),Tensile stress,Strain-by-clip-gage
(s),(mm),(N),(mm/mm),(MPa),(mm/mm)
"0.00000","0.00000","-349.38123","0.00000","-34.93812","-0.00024"
"0.40000","0.01064","-299.40906","0.00011","-29.94091","-0.00022"
"0.80000","0.02393","-242.89929","0.00024","-24.28993","-0.00024"
"1.20000","0.03728","-193.05290","0.00037","-19.30529","-0.00024"
"1.60000","0.05067","-149.47731","0.00051","-14.94773","-0.00023"
"2.00000","0.06404","-111.32705","0.00064","-11.13270","-0.00023"
"2.40000","0.07752","-76.34843","0.00078","-7.63484","-0.00024"
"2.80000","0.09064","-45.70395","0.00091","-4.57039","-0.00022"
"3.20000","0.10395","-16.37778","0.00104","-1.63778","-0.00024"
"3.60000","0.11733","10.54656","0.00117","1.05466","-0.00023"
"4.00000","0.13079","35.09942","0.00131","3.50994","-0.00022"
"4.40000","0.14402","56.56213","0.00144","5.65621","-0.00024"
"4.80000","0.15734","77.26868","0.00157","7.72687","-0.00023"
"5.20000","0.17061","95.49178","0.00171","9.54918","-0.00023"
"5.60000","0.18402","113.56705","0.00184","11.35671","-0.00024"
"6.00000","0.19733","131.63049","0.00197","13.16305","-0.00023"
"6.40000","0.21071","150.28325","0.00211","15.02833","-0.00023"
"6.80000","0.22407","169.19658","0.00224","16.91966","-0.00024"
"7.20000","0.23736","187.88435","0.00237","18.78843","-0.00022"
"7.60000","0.25085","207.77708","0.00251","20.77771","-0.00024"
"8.00000","0.26398","226.18680","0.00264","22.61868","-0.00024"
"8.40000","0.27719","244.76610","0.00277","24.47661","-0.00022"
"8.80000","0.29062","264.34744","0.00291","26.43474","-0.00024"
"9.20000","0.30416","284.05411","0.00304","28.40541","-0.00023"
"9.60000","0.31739","301.68466","0.00317","30.16847","-0.00022"
"10.00000","0.33074","319.57709","0.00331","31.95771","-0.00025"
"10.40000","0.34398","336.22940","0.00344","33.62294","-0.00023"
"10.80000","0.35726","352.39029","0.00357","35.23903","-0.00023"
"11.20000","0.37076","369.22656","0.00371","36.92266","-0.00024"
"11.60000","0.38409","384.77493","0.00384","38.47749","-0.00022"
"12.00000","0.39727","399.07101","0.00397","39.90710","-0.00023"
"12.40000","0.41072","413.92334","0.00411","41.39233","-0.00024"
"12.80000","0.42400","426.15182","0.00424","42.61518","-0.00022"
"13.20000","0.43729","437.33902","0.00437","43.73390","-0.00024"
"13.60000","0.45064","448.23251","0.00451","44.82325","-0.00024"
"14.00000","0.46406","459.33734","0.00464","45.93373","-0.00022"
"14.40000","0.47735","469.80707","0.00477","46.98071","-0.00024"
"14.80000","0.49086","482.62891","0.00491","48.26289","-0.00023"
"15.20000","0.50395","493.48254","0.00504","49.34826","-0.00023"
"15.60000","0.51726","505.37405","0.00517","50.53741","-0.00024"
"16.00000","0.53061","517.33295","0.00531","51.73330","-0.00023"
"16.40000","0.54408","528.51422","0.00544","52.85142","-0.00023"
"16.80000","0.55737","535.90503","0.00557","53.59050","-0.00024"
"17.20000","0.57076","539.09973","0.00571","53.90997","-0.00022"
"17.60000","0.58396","536.22711","0.00584","53.62271","-0.00024"
"18.00000","0.59733","536.11542","0.00597","53.61154","-0.00024"
"18.40000","0.61066","539.73212","0.00611","53.97321","-0.00022"
"18.80000","0.62400","545.78748","0.00624","54.57875","-0.00024"
"19.20000","0.63740","552.74719","0.00637","55.27472","-0.00024"
"19.60000","0.65068","559.89972","0.00651","55.98997","-0.00022"
"20.00000","0.66405","567.22742","0.00664","56.72274","-0.00024"
"20.40000","0.67731","573.37085","0.00677","57.33709","-0.00023"
"20.80000","0.69054","579.33777","0.00691","57.93378","-0.00023"
"21.20000","0.70401","586.00903","0.00704","58.60090","-0.00024"
"21.60000","0.71749","596.04797","0.00717","59.60480","-0.00023"
"22.00000","0.73059","603.76593","0.00731","60.37659","-0.00023"
"22.40000","0.74408","613.69476","0.00744","61.36948","-0.00024"
"22.80000","0.75733","622.78119","0.00757","62.27812","-0.00023"
"23.20000","0.77055","632.04987","0.00771","63.20499","-0.00024"
"23.60000","0.78401","641.92450","0.00784","64.19245","-0.00023"
"24.00000","0.79742","650.11017","0.00797","65.01102","-0.00022"
"24.40000","0.81060","656.43011","0.00811","65.64301","-0.00024"
"24.80000","0.82411","664.33020","0.00824","66.43302","-0.00023"
"25.20000","0.83733","668.99078","0.00837","66.89908","-0.00023"
"25.60000","0.85057","671.32239","0.00851","67.13224","-0.00024"
"26.00000","0.86399","667.89496","0.00864","66.78950","-0.00023"
"26.40000","0.87746","662.44647","0.00877","66.24464","-0.00023"
"26.80000","0.89066","662.31781","0.00891","66.23178","-0.00024"
"27.20000","0.90413","665.78503","0.00904","66.57851","-0.00023"
"27.60000","0.91724","667.04944","0.00917","66.70494","-0.00023"
"28.00000","0.93056","665.55005","0.00931","66.55501","-0.00024"
"28.40000","0.94398","664.95453","0.00944","66.49545","-0.00023"
"28.80000","0.95744","667.70032","0.00957","66.77003","-0.00023"
"29.20000","0.97064","665.08258","0.00971","66.50826","-0.00024"
"29.60000","0.98408","653.35724","0.00984","65.33572","-0.00023"
"30.00000","0.99731","645.71600","0.00997","64.57160","-0.00023"
"30.40000","1.01065","644.55951","0.01011","64.45595","-0.00023"
"30.80000","1.02391","645.60010","0.01024","64.56001","-0.00022"
"31.20000","1.03730","647.68677","0.01037","64.76868","-0.00024"
"31.60000","1.05067","651.57977","0.01051","65.15797","-0.00023"
"32.00000","1.06405","655.71210","0.01064","65.57121","-0.00023"
"32.40000","1.07734","658.57043","0.01077","65.85704","-0.00024"
"32.80000","1.09065","660.47351","0.01091","66.04735","-0.00023"
"33.20000","1.10393","662.27869","0.01104","66.22787","-0.00023"
"33.60000","1.11738","667.61597","0.01117","66.76160","-0.00024"
"34.00000","1.13075","673.27484","0.01131","67.32748","-0.00023"
"34.40000","1.14401","679.83429","0.01144","67.98343","-0.00023"
"34.80000","1.15736","686.55664","0.01157","68.65566","-0.00024"
"35.20000","1.17061","693.35095","0.01171","69.33510","-0.00022"
"35.60000","1.18389","698.59021","0.01184","69.85902","-0.00024"
"36.00000","1.19732","705.28485","0.01197","70.52849","-0.00024"
"36.40000","1.21081","711.29431","0.01211","71.12943","-0.00022"
"36.80000","1.22396","717.04254","0.01224","71.70425","-0.00024"
"37.20000","1.23749","723.72083","0.01237","72.37209","-0.00023"
"37.60000","1.25063","730.02466","0.01251","73.00246","-0.00023"
"38.00000","1.26388","737.13092","0.01264","73.71309","-0.00024"
"38.40000","1.27731","744.00122","0.01277","74.40012","-0.00023"
"38.80000","1.29073","750.73151","0.01291","75.07315","-0.00023"
"39.20000","1.30392","754.02374","0.01304","75.40237","-0.00024"
"39.60000","1.31743","759.56720","0.01317","75.95672","-0.00022"
"40.00000","1.33064","761.93933","0.01331","76.19393","-0.00024"
"40.40000","1.34395","765.42163","0.01344","76.54216","-0.00024"
"40.80000","1.35736","770.10321","0.01357","77.01032","-0.00022"
"41.20000","1.37070","772.95416","0.01371","77.29542","-0.00024"
"41.60000","1.38403","774.73749","0.01384","77.47375","-0.00023"
"42.00000","1.39748","777.86127","0.01397","77.78613","-0.00022"
"42.40000","1.41062","779.67163","0.01411","77.96716","-0.00025"
"42.80000","1.42391","783.63232","0.01424","78.36324","-0.00022"
"43.20000","1.43721","789.80084","0.01437","78.98009","-0.00023"
"43.60000","1.45076","797.41431","0.01451","79.74143","-0.00024"
"44.00000","1.46408","803.37006","0.01464","80.33701","-0.00022"
"44.40000","1.47741","806.13623","0.01477","80.61362","-0.00024"
"44.80000","1.49065","807.71527","0.01491","80.77153","-0.00023"
"45.20000","1.50398","810.26581","0.01504","81.02658","-0.00022"
"45.60000","1.51730","814.55756","0.01517","81.45576","-0.00024"
"46.00000","1.53067","817.68341","0.01531","81.76834","-0.00023"
"46.40000","1.54401","810.70343","0.01544","81.07034","-0.00022"
"46.80000","1.55735","809.05145","0.01557","80.90514","-0.00024"
"47.20000","1.57072","810.15247","0.01571","81.01524","-0.00022"
"47.60000","1.58403","812.82111","0.01584","81.28211","-0.00023"
"48.00000","1.59729","816.98254","0.01597","81.69826","-0.00024"
"48.40000","1.61065","823.01770","0.01611","82.30177","-0.00022"
"48.80000","1.62410","828.25830","0.01624","82.82583","-0.00024"
"49.20000","1.63744","832.52240","0.01637","83.25224","-0.00024"
"49.60000","1.65074","833.05249","0.01651","83.30525","-0.00022"
"50.00000","1.66393","831.62793","0.01664","83.16280","-0.00024"
"50.40000","1.67714","832.09351","0.01677","83.20935","-0.00023"
"50.80000","1.69072","833.97736","0.01691","83.39774","-0.00023"
"51.20000","1.70418","835.64838","0.01704","83.56483","-0.00025"
"51.60000","1.71731","834.93219","0.01717","83.49322","-0.00022"
"52.00000","1.73080","826.57300","0.01731","82.65730","-0.00023"
"52.40000","1.74400","820.68201","0.01744","82.06820","-0.00024"
"52.80000","1.75734","815.61145","0.01757","81.56114","-0.00022"
"53.20000","1.77066","813.55078","0.01771","81.35508","-0.00024"
"53.60000","1.78399","811.57581","0.01784","81.15758","-0.00023"
"54.00000","1.79729","784.67493","0.01797","78.46749","-0.00022"
"54.40000","1.81081","776.21753","0.01811","77.62175","-0.00024"
"54.80000","1.82403","776.27039","0.01824","77.62704","-0.00023"
"55.20000","1.83729","780.43677","0.01837","78.04368","-0.00023"
"55.60000","1.85063","785.37909","0.01851","78.53791","-0.00024"
"56.00000","1.86404","791.45276","0.01864","79.14528","-0.00022"
"56.40000","1.87748","798.17523","0.01877","79.81752","-0.00024"
"56.80000","1.89072","803.82007","0.01891","80.38200","-0.00023"
"57.20000","1.90396","807.44446","0.01904","80.74445","-0.00022"
"57.60000","1.91727","812.83881","0.01917","81.28388","-0.00024"
"58.00000","1.93064","817.97241","0.01931","81.79724","-0.00023"
"58.40000","1.94404","824.30328","0.01944","82.43033","-0.00022"
"58.80000","1.95744","830.12164","0.01957","83.01216","-0.00024"
"59.20000","1.97070","834.06146","0.01971","83.40614","-0.00023"
"59.60000","1.98410","839.01837","0.01984","83.90184","-0.00023"
"60.00000","1.99737","843.66083","0.01997","84.36608","-0.00024"
"60.40000","2.01057","847.70892","0.02011","84.77089","-0.00022"
"60.80000","2.02397","852.69476","0.02024","85.26948","-0.00024"
"61.20000","2.03743","857.80176","0.02037","85.78017","-0.00023"
"61.60000","2.05068","861.65759","0.02051","86.16576","-0.00022"
"62.00000","2.06410","866.82050","0.02064","86.68205","-0.00024"
"62.40000","2.07729","870.30792","0.02077","87.03079","-0.00023"
"62.80000","2.09057","873.98737","0.02091","87.39874","-0.00022"
"63.20000","2.10404","879.47174","0.02104","87.94717","-0.00024"
"63.60000","2.11742","876.74762","0.02117","87.67476","-0.00023"
"64.00000","2.13066","876.00378","0.02131","87.60038","-0.00022"
"64.40000","2.14410","877.23981","0.02144","87.72398","-0.00024"
"64.80000","2.15729","877.52026","0.02157","87.75203","-0.00023"
"65.20000","2.17061","879.76733","0.02171","87.97673","-0.00023"
"65.60000","2.18400","883.51935","0.02184","88.35194","-0.00024"
"66.00000","2.19735","886.28754","0.02197","88.62875","-0.00022"
"66.40000","2.21071","888.40796","0.02211","88.84080","-0.00023"
"66.80000","2.22418","891.09064","0.02224","89.10906","-0.00024"
"67.20000","2.23728","891.72180","0.02237","89.17218","-0.00022"
"67.60000","2.25062","896.55237","0.02251","89.65524","-0.00024"
"68.00000","2.26398","901.07166","0.02264","90.10716","-0.00023"
"68.40000","2.27734","904.50806","0.02277","90.45081","-0.00023"
"68.80000","2.29073","904.54633","0.02291","90.45464","-0.00024"
"69.20000","2.30406","901.78650","0.02304","90.17865","-0.00023"
"69.60000","2.31727","899.97034","0.02317","89.99703","-0.00023"
"70.00000","2.33061","901.34247","0.02331","90.13425","-0.00024"
"70.40000","2.34396","902.68048","0.02344","90.26805","-0.00023"
"70.80000","2.35731","904.66681","0.02357","90.46668","-0.00023"
"71.20000","2.37072","907.43079","0.02371","90.74308","-0.00024"
"71.60000","2.38402","908.13141","0.02384","90.81314","-0.00023"
"72.00000","2.39739","908.00299","0.02397","90.80030","-0.00023"
"72.40000","2.41063","906.33844","0.02411","90.63384","-0.00022"
"72.80000","2.42387","907.68347","0.02424","90.76835","-0.00023"
"73.20000","2.43728","911.41797","0.02437","91.14180","-0.00024"
"73.60000","2.45075","913.98505","0.02451","91.39851","-0.00023"
"74.00000","2.46403","911.18121","0.02464","91.11812","-0.00023"
"74.40000","2.47740","908.09113","0.02477","90.80911","-0.00024"
"74.80000","2.49064","906.35388","0.02491","90.63539","-0.00023"
"75.20000","2.50394","895.61780","0.02504","89.56178","-0.00022"
"75.60000","2.51733","894.98346","0.02517","89.49834","-0.00024"
"76.00000","2.53081","897.23969","0.02531","89.72397","-0.00023"
"76.40000","2.54393","897.43176","0.02544","89.74318","-0.00022"
"76.80000","2.55738","898.61603","0.02557","89.86160","-0.00024"
"77.20000","2.57062","898.23724","0.02571","89.82372","-0.00023"
"77.60000","2.58392","894.48730","0.02584","89.44873","-0.00023"
"78.00000","2.59734","893.59937","0.02597","89.35994","-0.00024"
"78.40000","2.61072","894.74518","0.02611","89.47452","-0.00022"
"78.80000","2.62403","897.40491","0.02624","89.74049","-0.00024"
"79.20000","2.63743","901.80786","0.02637","90.18079","-0.00023"
"79.60000","2.65063","903.91895","0.02651","90.39189","-0.00022"
"80.00000","2.66390","901.19110","0.02664","90.11911","-0.00024"
"80.40000","2.67725","902.70282","0.02677","90.27028","-0.00023"
"80.80000","2.69066","903.43988","0.02691","90.34399","-0.00022"
"81.20000","2.70404","900.47235","0.02704","90.04723","-0.00024"
"81.60000","2.71750","892.34442","0.02717","89.23444","-0.00023"
"82.00000","2.73062","881.50342","0.02731","88.15034","-0.00023"
"82.40000","2.74399","881.66284","0.02744","88.16628","-0.00024"
"82.80000","2.75731","882.12433","0.02757","88.21243","-0.00022"
"83.20000","2.77068","882.82117","0.02771","88.28212","-0.00023"
"83.60000","2.78407","884.07324","0.02784","88.40733","-0.00024"
"84.00000","2.79735","886.46503","0.02797","88.64650","-0.00022"
"84.40000","2.81065","888.89941","0.02811","88.88994","-0.00024"
"84.80000","2.82392","890.69531","0.02824","89.06953","-0.00023"
"85.20000","2.83728","890.54980","0.02837","89.05498","-0.00022"
"85.60000","2.85069","891.70074","0.02851","89.17007","-0.00024"
"86.00000","2.86415","892.88379","0.02864","89.28838","-0.00023"
"86.40000","2.87729","887.88336","0.02877","88.78834","-0.00022"
"86.80000","2.89077","883.17554","0.02891","88.31755","-0.00024"
"87.20000","2.90401","882.27435","0.02904","88.22743","-0.00023"
"87.60000","2.91723","883.06165","0.02917","88.30617","-0.00023"
"88.00000","2.93060","882.06903","0.02931","88.20690","-0.00024"
"88.40000","2.94410","884.34375","0.02944","88.43437","-0.00022"
"88.80000","2.95733","882.14288","0.02957","88.21429","-0.00023"
"89.20000","2.97081","880.93170","0.02971","88.09317","-0.00024"
"89.60000","2.98398","880.58429","0.02984","88.05843","-0.00022"
"90.00000","2.99728","881.35309","0.02997","88.13531","-0.00024"
"90.40000","3.01066","883.75391","0.03011","88.37539","-0.00024"
"90.80000","3.02418","887.30951","0.03024","88.73095","-0.00022"
"91.20000","3.03731","880.11890","0.03037","88.01189","-0.00024"
"91.60000","3.05072","879.55750","0.03051","87.95575","-0.00023"
"92.00000","3.06390","880.83569","0.03064","88.08357","-0.00022"
"92.40000","3.07733","883.24072","0.03077","88.32407","-0.00024"
"92.80000","3.09070","884.50806","0.03091","88.45081","-0.00023"
"93.20000","3.10409","888.73926","0.03104","88.87392","-0.00023"
"93.60000","3.11736","892.30652","0.03117","89.23065","-0.00024"
"94.00000","3.13077","892.89667","0.03131","89.28967","-0.00022"
"94.40000","3.14413","892.55597","0.03144","89.25560","-0.00023"
"94.80000","3.15732","889.12054","0.03157","88.91206","-0.00024"
"95.20000","3.17056","871.05695","0.03171","87.10570","-0.00022"
"95.60000","3.18394","859.94238","0.03184","85.99424","-0.00024"
"96.00000","3.19744","851.88422","0.03197","85.18842","-0.00023"
"96.40000","3.21083","843.07355","0.03211","84.30736","-0.00022"
"96.80000","3.22401","837.53625","0.03224","83.75362","-0.00024"
"97.20000","3.23731","833.82324","0.03237","83.38232","-0.00023"
"97.60000","3.25063","832.29456","0.03251","83.22945","-0.00023"
"98.00000","3.26411","830.73602","0.03264","83.07360","-0.00024"
"98.40000","3.27743","824.05072","0.03277","82.40508","-0.00022"
"98.80000","3.29062","822.47711","0.03291","82.24771","-0.00023"
"99.20000","3.30401","824.76520","0.03304","82.47652","-0.00024"
"99.60000","3.31733","826.15588","0.03317","82.61559","-0.00022"
"100.00000","3.33062","829.47498","0.03331","82.94749","-0.00024"
"100.40000","3.34402","833.14020","0.03344","83.31402","-0.00023"
"100.80000","3.35747","835.86981","0.03357","83.58698","-0.00022"
"101.20000","3.37063","837.43909","0.03371","83.74391","-0.00024"
"101.60000","3.38423","840.79810","0.03384","84.07981","-0.00023"
"102.00000","3.39730","838.62183","0.03397","83.86218","-0.00023"
"102.40000","3.41053","835.56573","0.03411","83.55657","-0.00024"
"102.80000","3.42397","836.04816","0.03424","83.60481","-0.00022"
"103.20000","3.43746","837.84412","0.03437","83.78441","-0.00023"
"103.60000","3.45066","840.18457","0.03451","84.01846","-0.00024"
"104.00000","3.46413","841.83228","0.03464","84.18323","-0.00022"
"104.40000","3.47729","844.39020","0.03477","84.43902","-0.00024"
"104.80000","3.49062","835.09900","0.03491","83.50990","-0.00023"
"105.20000","3.50404","828.29169","0.03504","82.82917","-0.00023"
"105.60000","3.51737","829.88629","0.03517","82.98863","-0.00023"
"106.00000","3.53066","833.89471","0.03531","83.38947","-0.00023"
"106.40000","3.54406","840.21259","0.03544","84.02126","-0.00023"
"106.80000","3.55734","841.85974","0.03557","84.18597","-0.00024"
"107.20000","3.57064","842.15033","0.03571","84.21503","-0.00023"
"107.60000","3.58392","842.51801","0.03584","84.25180","-0.00022"
"108.00000","3.59736","843.74042","0.03597","84.37404","-0.00024"
"108.40000","3.61079","844.08539","0.03611","84.40854","-0.00023"
"108.80000","3.62404","842.06165","0.03624","84.20616","-0.00023"
"109.20000","3.63737","838.15649","0.03637","83.81565","-0.00024"
"109.60000","3.65063","834.27264","0.03651","83.42726","-0.00022"
"110.00000","3.66392","832.15143","0.03664","83.21514","-0.00023"
"110.40000","3.67735","832.11737","0.03677","83.21174","-0.00023"
"110.80000","3.69077","830.72583","0.03691","83.07259","-0.00023"
"111.20000","3.70396","825.10278","0.03704","82.51028","-0.00024"
"111.60000","3.71737","819.41113","0.03717","81.94112","-0.00023"
"112.00000","3.73069","815.42480","0.03731","81.54248","-0.00023"
"112.40000","3.74392","811.61139","0.03744","81.16114","-0.00024"
"112.80000","3.75732","811.95587","0.03757","81.19559","-0.00023"
"113.20000","3.77078","814.28064","0.03771","81.42806","-0.00023"
"113.60000","3.78399","815.91223","0.03784","81.59122","-0.00024"
"114.00000","3.79744","819.87073","0.03797","81.98708","-0.00023"
"114.40000","3.81060","822.04279","0.03811","82.20428","-0.00023"
"114.80000","3.82386","825.37524","0.03824","82.53752","-0.00024"
"115.20000","3.83734","829.38049","0.03837","82.93805","-0.00023"
"115.60000","3.85083","833.66772","0.03851","83.36678","-0.00023"
"116.00000","3.86390","834.39697","0.03864","83.43970","-0.00024"
"116.40000","3.87747","838.29285","0.03877","83.82928","-0.00022"
"116.80000","3.89064","839.73035","0.03891","83.97304","-0.00023"
"117.20000","3.90394","841.86401","0.03904","84.18640","-0.00024"
"117.60000","3.91729","843.37128","0.03917","84.33713","-0.00023"
"118.00000","3.93072","845.45593","0.03931","84.54559","-0.00023"
"118.40000","3.94392","847.37555","0.03944","84.73756","-0.00023"
"118.80000","3.95746","852.78033","0.03957","85.27803","-0.00022"
"119.20000","3.97063","856.75177","0.03971","85.67518","-0.00024"
"119.60000","3.98395","860.92493","0.03984","86.09249","-0.00023"
"120.00000","3.99729","863.91595","0.03997","86.39159","-0.00023"
"120.40000","4.01073","866.93719","0.04011","86.69372","-0.00024"
"120.80000","4.02406","870.28583","0.04024","87.02858","-0.00022"
"121.20000","4.03743","874.19141","0.04037","87.41914","-0.00023"
"121.60000","4.05060","876.32825","0.04051","87.63283","-0.00023"
"122.00000","4.06394","878.68146","0.04064","87.86815","-0.00022"
"122.40000","4.07724","880.14099","0.04077","88.01410","-0.00023"
"122.80000","4.09069","882.07910","0.04091","88.20791","-0.00024"
"123.20000","4.10409","882.72479","0.04104","88.27248","-0.00023"
"123.60000","4.11731","882.37897","0.04117","88.23790","-0.00024"
"124.00000","4.13074","883.19519","0.04131","88.31952","-0.00023"
"124.40000","4.14400","881.97821","0.04144","88.19782","-0.00023"
"124.80000","4.15723","881.25018","0.04157","88.12502","-0.00024"
"125.20000","4.17065","881.69958","0.04171","88.16996","-0.00023"
"125.60000","4.18405","881.21027","0.04184","88.12103","-0.00023"
"126.00000","4.19728","882.28656","0.04197","88.22865","-0.00024"
"126.40000","4.21071","883.13220","0.04211","88.31322","-0.00023"
"126.80000","4.22402","882.81036","0.04224","88.28104","-0.00023"
"127.20000","4.23726","881.35107","0.04237","88.13511","-0.00024"
"127.60000","4.25069","879.70111","0.04251","87.97011","-0.00022"
"128.00000","4.26410","850.49384","0.04264","85.04939","-0.00024"
"128.40000","4.27735","830.64966","0.04277","83.06496","-0.00023"
"128.80000","4.29080","811.76367","0.04291","81.17637","-0.00022"
"129.20000","4.30393","800.94318","0.04304","80.09431","-0.00024"
"129.60000","4.31723","798.30725","0.04317","79.83073","-0.00023"
"130.00000","4.33061","798.87518","0.04331","79.88752","-0.00022"
"130.40000","4.34412","800.64862","0.04344","80.06487","-0.00024"
"130.80000","4.35732","800.42944","0.04357","80.04295","-0.00023"
"131.20000","4.37083","803.08429","0.04371","80.30843","-0.00023"
"131.60000","4.38392","803.09467","0.04384","80.30946","-0.00024"
"132.00000","4.39729","804.74689","0.04397","80.47469","-0.00022"
"132.40000","4.41066","805.39960","0.04411","80.53996","-0.00023"
"132.80000","4.42401","807.17877","0.04424","80.71788","-0.00024"
"133.20000","4.43730","809.13995","0.04437","80.91399","-0.00022"
"133.60000","4.45072","810.15417","0.04451","81.01542","-0.00023"
"134.00000","4.46401","810.69702","0.04464","81.06970","-0.00024"
"134.40000","4.47732","812.47510","0.04477","81.24751","-0.00022"
"134.80000","4.49066","813.95648","0.04491","81.39565","-0.00024"
"135.20000","4.50401","814.86096","0.04504","81.48610","-0.00023"
"135.60000","4.51744","816.53168","0.04517","81.65317","-0.00022"
"136.00000","4.53078","818.17926","0.04531","81.81792","-0.00024"
"136.40000","4.54402","819.14124","0.04544","81.91412","-0.00022"
"136.80000","4.55726","820.38788","0.04557","82.03879","-0.00023"
"137.20000","4.57050","821.91583","0.04571","82.19158","-0.00024"
"137.60000","4.58403","825.23773","0.04584","82.52377","-0.00022"
"138.00000","4.59751","826.78918","0.04598","82.67892","-0.00023"
"138.40000","4.61061","825.81445","0.04611","82.58144","-0.00023"
"138.80000","4.62407","827.96039","0.04624","82.79604","-0.00022"
"139.20000","4.63734","829.95117","0.04637","82.99512","-0.00024"
"139.60000","4.65064","831.84912","0.04651","83.18491","-0.00023"
"140.00000","4.66399","834.46362","0.04664","83.44637","-0.00022"
"140.40000","4.67737","834.39679","0.04677","83.43968","-0.00024"
"140.80000","4.69059","836.54456","0.04691","83.65446","-0.00022"
"141.20000","4.70414","840.41656","0.04704","84.04166","-0.00023"
"141.60000","4.71736","841.70020","0.04717","84.17002","-0.00024"
"142.00000","4.73061","843.25305","0.04731","84.32530","-0.00022"
"142.40000","4.74398","845.50641","0.04744","84.55064","-0.00024"
"142.80000","4.75740","847.17767","0.04757","84.71777","-0.00024"
"143.20000","4.77081","846.80328","0.04771","84.68033","-0.00022"
"143.60000","4.78409","845.26025","0.04784","84.52602","-0.00024"
"144.00000","4.79726","843.29230","0.04797","84.32923","-0.00023"
"144.40000","4.81056","840.16559","0.04811","84.01656","-0.00023"
"144.80000","4.82399","837.08038","0.04824","83.70804","-0.00024"
"145.20000","4.83740","835.08252","0.04837","83.50826","-0.00022"
"145.60000","4.85072","831.62756","0.04851","83.16276","-0.00023"
"146.00000","4.86408","830.42908","0.04864","83.04291","-0.00024"
"146.40000","4.87734","827.98218","0.04877","82.79822","-0.00022"
"146.80000","4.89071","824.21973","0.04891","82.42197","-0.00024"
"147.20000","4.90396","816.53119","0.04904","81.65312","-0.00023"
"147.60000","4.91733","812.12891","0.04917","81.21289","-0.00022"
"148.00000","4.93072","809.42462","0.04931","80.94246","-0.00023"
"148.40000","4.94410","805.84845","0.04944","80.58485","-0.00023"
"148.80000","4.95739","802.59991","0.04957","80.25999","-0.00023"
"149.20000","4.97064","798.00385","0.04971","79.80038","-0.00024"
"149.60000","4.98391","790.87457","0.04984","79.08746","-0.00023"
"150.00000","4.99738","783.89410","0.04997","78.38941","-0.00023"
"150.40000","5.01082","776.46869","0.05011","77.64687","-0.00023"
"150.80000","5.02400","764.75085","0.05024","76.47508","-0.00022"
"151.20000","5.03739","755.87292","0.05037","75.58730","-0.00023"
"151.60000","5.05062","750.43567","0.05051","75.04356","-0.00023"
"152.00000","5.06394","746.03345","0.05064","74.60335","-0.00022"
"152.40000","5.07734","742.19733","0.05077","74.21973","-0.00024"
"152.80000","5.09075","738.62408","0.05091","73.86241","-0.00023"
"153.20000","5.10401","733.84485","0.05104","73.38448","-0.00023"
"153.60000","5.11751","730.53278","0.05118","73.05328","-0.00024"
"154.00000","5.13068","725.16248","0.05131","72.51625","-0.00022"
"154.40000","5.14390","721.27667","0.05144","72.12767","-0.00023"
"154.80000","5.15732","714.32300","0.05157","71.43230","-0.00024"
"155.20000","5.17074","711.04999","0.05171","71.10500","-0.00022"
"155.60000","5.18400","707.93994","0.05184","70.79399","-0.00023"
"156.00000","5.19743","706.61298","0.05197","70.66130","-0.00024"
"156.40000","5.21060","702.67902","0.05211","70.26790","-0.00022"
"156.80000","5.22393","698.71515","0.05224","69.87151","-0.00024"
"157.20000","5.23734","695.36053","0.05237","69.53606","-0.00023"
"157.60000","5.25069","689.57477","0.05251","68.95747","-0.00022"
"158.00000","5.26400","676.02783","0.05264","67.60278","-0.00024"
"158.40000","5.27742","654.78876","0.05277","65.47887","-0.00023"
"158.80000","5.29063","637.53760","0.05291","63.75376","-0.00023"
"159.20000","5.30398","622.44855","0.05304","62.24485","-0.00024"
"159.60000","5.31725","608.56305","0.05317","60.85630","-0.00023"
"160.00000","5.33065","600.25488","0.05331","60.02549","-0.00022"
"160.40000","5.34408","594.57605","0.05344","59.45760","-0.00024"
"160.80000","5.35742","591.05579","0.05357","59.10558","-0.00022"
"161.20000","5.37065","585.83911","0.05371","58.58391","-0.00023"
"161.60000","5.38400","582.34875","0.05384","58.23487","-0.00023"
"162.00000","5.39728","579.09125","0.05397","57.90913","-0.00022"
"162.40000","5.41065","577.54932","0.05411","57.75493","-0.00024"
"162.80000","5.42412","574.90826","0.05424","57.49083","-0.00023"
"163.20000","5.43729","570.71564","0.05437","57.07156","-0.00023"
"163.60000","5.45066","558.14746","0.05451","55.81475","-0.00023"
"164.00000","5.46397","553.84778","0.05464","55.38478","-0.00023"
"164.40000","5.47725","548.78290","0.05477","54.87829","-0.00023"
"164.80000","5.49066","544.84808","0.05491","54.48481","-0.00023"
"165.20000","5.50405","541.75287","0.05504","54.17529","-0.00022"
"165.60000","5.51733","539.09900","0.05517","53.90990","-0.00023"
"166.00000","5.53077","538.41107","0.05531","53.84111","-0.00023"
"166.40000","5.54394","536.92010","0.05544","53.69201","-0.00022"
"166.80000","5.55720","535.78326","0.05557","53.57833","-0.00024"
"167.20000","5.57061","535.36359","0.05571","53.53636","-0.00023"
"167.60000","5.58404","535.67450","0.05584","53.56745","-0.00023"
"168.00000","5.59732","534.65564","0.05597","53.46556","-0.00024"
"168.40000","5.61080","534.28790","0.05611","53.42879","-0.00022"
"168.80000","5.62393","531.85492","0.05624","53.18549","-0.00023"
"169.20000","5.63729","531.29327","0.05637","53.12933","-0.00023"
"169.60000","5.65066","531.92041","0.05651","53.19204","-0.00022"
"170.00000","5.66405","532.60236","0.05664","53.26023","-0.00024"
"170.40000","5.67731","532.39551","0.05677","53.23955","-0.00023"
"170.80000","5.69072","532.28845","0.05691","53.22884","-0.00022"
"171.20000","5.70394","529.12494","0.05704","52.91249","-0.00024"
"171.60000","5.71729","530.23395","0.05717","53.02340","-0.00023"
"172.00000","5.73064","530.20935","0.05731","53.02094","-0.00022"
"172.40000","5.74404","530.34222","0.05744","53.03422","-0.00024"
"172.80000","5.75743","529.93896","0.05757","52.99390","-0.00022"
"173.20000","5.77069","528.07782","0.05771","52.80778","-0.00023"
"173.60000","5.78400","526.35291","0.05784","52.63529","-0.00024"
"174.00000","5.79732","522.46100","0.05797","52.24610","-0.00022"
"174.40000","5.81055","484.64420","0.05811","48.46442","-0.00024"
"174.80000","5.82396","475.71243","0.05824","47.57124","-0.00023"
"175.20000","5.83740","472.06940","0.05837","47.20694","-0.00021"
"175.60000","5.85072","469.92776","0.05851","46.99277","-0.00025"
"176.00000","5.86405","469.50974","0.05864","46.95097","-0.00022"
"176.40000","5.87734","469.48767","0.05877","46.94877","-0.00022"
"176.80000","5.89056","468.36050","0.05891","46.83605","-0.00024"
"177.20000","5.90400","467.64392","0.05904","46.76439","-0.00022"
"177.60000","5.91747","465.21603","0.05917","46.52160","-0.00023"
"178.00000","5.93064","463.32562","0.05931","46.33256","-0.00023"
"178.40000","5.94404","463.33722","0.05944","46.33372","-0.00022"
"178.80000","5.95726","460.04453","0.05957","46.00445","-0.00024"
"179.20000","5.97063","456.69205","0.05971","45.66920","-0.00023"
"179.60000","5.98404","453.10254","0.05984","45.31025","-0.00022"
"180.00000","5.99745","449.22168","0.05997","44.92217","-0.00024"
"180.40000","6.01062","444.35672","0.06011","44.43567","-0.00022"
"180.80000","6.02414","440.18448","0.06024","44.01845","-0.00023"
"181.20000","6.03738","435.25494","0.06037","43.52549","-0.00024"
"181.60000","6.05059","429.80923","0.06051","42.98092","-0.00022"
"182.00000","6.06395","424.08762","0.06064","42.40876","-0.00024"
"182.40000","6.07734","417.74432","0.06077","41.77443","-0.00024"
"182.80000","6.09071","411.41226","0.06091","41.14123","-0.00022"
"183.20000","6.10421","407.51248","0.06104","40.75125","-0.00024"
"183.60000","6.11728","401.07434","0.06117","40.10743","-0.00023"
"184.00000","6.13064","397.12424","0.06131","39.71243","-0.00022"
"184.40000","6.14400","394.23407","0.06144","39.42341","-0.00024"
"184.80000","6.15745","391.63818","0.06157","39.16382","-0.00023"
"185.20000","6.17069","386.95767","0.06171","38.69577","-0.00022"
"185.60000","6.18402","382.11499","0.06184","38.21150","-0.00024"
"186.00000","6.19726","376.87103","0.06197","37.68710","-0.00022"
"186.40000","6.21069","372.84790","0.06211","37.28479","-0.00023"
"186.80000","6.22400","369.48923","0.06224","36.94892","-0.00023"
"187.20000","6.23736","367.17892","0.06237","36.71789","-0.00022"
"187.60000","6.25075","363.95056","0.06251","36.39506","-0.00024"
"188.00000","6.26399","360.85745","0.06264","36.08575","-0.00023"
"188.40000","6.27751","358.72504","0.06278","35.87251","-0.00022"
"188.80000","6.29067","355.26080","0.06291","35.52608","-0.00024"
"189.20000","6.30385","351.50760","0.06304","35.15076","-0.00023"
"189.60000","6.31729","347.72311","0.06317","34.77231","-0.00022"
"190.00000","6.33085","344.01465","0.06331","34.40147","-0.00024"
"190.40000","6.34406","339.29352","0.06344","33.92935","-0.00022"
"190.80000","6.35744","335.34317","0.06357","33.53432","-0.00023"
"191.20000","6.37065","330.71558","0.06371","33.07156","-0.00024"
"191.60000","6.38396","328.04135","0.06384","32.80413","-0.00022"
"192.00000","6.39739","324.90475","0.06397","32.49047","-0.00023"
"192.40000","6.41075","319.79608","0.06411","31.97961","-0.00023"
"192.80000","6.42397","312.59500","0.06424","31.25950","-0.00022"
"193.20000","6.43741","307.41159","0.06437","30.74116","-0.00023"
"193.60000","6.45067","302.88809","0.06451","30.28881","-0.00023"
"194.00000","6.46398","299.85736","0.06464","29.98574","-0.00023"
"194.40000","6.47730","296.40842","0.06477","29.64084","-0.00024"
"194.80000","6.49072","293.72543","0.06491","29.37254","-0.00022"
"195.20000","6.50401","290.78586","0.06504","29.07859","-0.00023"
"195.60000","6.51752","289.84503","0.06518","28.98450","-0.00023"
"196.00000","6.53063","284.89505","0.06531","28.48951","-0.00022"
"196.40000","6.54392","282.06720","0.06544","28.20672","-0.00023"
"196.80000","6.55729","278.83966","0.06557","27.88397","-0.00023"
"197.20000","6.57073","276.92957","0.06571","27.69296","-0.00022"
"197.60000","6.58405","273.12100","0.06584","27.31210","-0.00023"
"198.00000","6.59739","262.60001","0.06597","26.26000","-0.00023"
"198.40000","6.61064","245.43083","0.06611","24.54308","-0.00022"
"198.80000","6.62400","232.15829","0.06624","23.21583","-0.00023"
"199.20000","6.63732","221.96844","0.06637","22.19684","-0.00023"
"199.60000","6.65064","209.29785","0.06651","20.92978","-0.00023"
"200.00000","6.66407","196.49419","0.06664","19.64942","-0.00023"
"200.40000","6.67736","187.31476","0.06677","18.73148","-0.00022"
"200.80000","6.69071","182.14493","0.06691","18.21449","-0.00023"
"201.20000","6.70396","176.00034","0.06704","17.60003","-0.00023"
"201.60000","6.71721","173.41531","0.06717","17.34153","-0.00022"
"202.00000","6.73067","171.23912","0.06731","17.12391","-0.00023"
"202.40000","6.74416","169.88789","0.06744","16.98879","-0.00023"
"202.80000","6.75727","159.15120","0.06757","15.91512","-0.00022"
"203.20000","6.77078","149.65334","0.06771","14.96533","-0.00024"
"203.60000","6.78397","143.20349","0.06784","14.32035","-0.00022"
"204.00000","6.79723","139.24019","0.06797","13.92402","-0.00023"
"204.40000","6.81066","135.79843","0.06811","13.57984","-0.00024"
"204.80000","6.82410","131.75882","0.06824","13.17588","-0.00022"
"205.20000","6.83725","128.45168","0.06837","12.84517","-0.00023"
"205.60000","6.85079","128.68884","0.06851","12.86888","-0.00024"
"206.00000","6.86397","127.00461","0.06864","12.70046","-0.00022"
"206.40000","6.87726","125.30234","0.06877","12.53023","-0.00023"
"206.80000","6.89062","122.93163","0.06891","12.29316","-0.00023"
"207.20000","6.90412","120.70956","0.06904","12.07096","-0.00022"
"207.60000","6.91733","116.78838","0.06917","11.67884","-0.00024"
"208.00000","6.93079","115.06634","0.06931","11.50663","-0.00022"
"208.40000","6.94392","105.80669","0.06944","10.58067","-0.00023"
"208.80000","6.95724","98.58009","0.06957","9.85801","-0.00024"
"209.20000","6.97064","94.34040","0.06971","9.43404","-0.00022"
"209.60000","6.98408","47.40791","0.06984","4.74079","-0.00023"
"210.00000","6.99735","37.87178","0.06997","3.78718","-0.00024"
"210.40000","7.01073","33.94228","0.07011","3.39423","-0.00022"
"210.80000","7.02405","32.36102","0.07024","3.23610","-0.00024"
"211.20000","7.03730","30.28889","0.07037","3.02889","-0.00023"
"211.60000","7.05061","29.52082","0.07051","2.95208","-0.00022"
"212.00000","7.06397","28.78680","0.07064","2.87868","-0.00024"
"212.40000","7.07736","28.98522","0.07077","2.89852","-0.00023"
"212.80000","7.09069","26.50908","0.07091","2.65091","-0.00023"
"213.20000","7.10401","20.88233","0.07104","2.08823","-0.00024"
"213.60000","7.11732","17.86703","0.07117","1.78670","-0.00022"
"214.00000","7.13059","14.47934","0.07131","1.44793","-0.00024"
"214.40000","7.14400","12.80199","0.07144","1.28020","-0.00023"
"214.80000","7.15740","11.87892","0.07157","1.18789","-0.00022"
"215.20000","7.17071","10.11169","0.07171","1.01117","-0.00024"
"215.60000","7.18404","6.20203","0.07184","0.62020","-0.00023"
"216.00000","7.19725","2.49606","0.07197","0.24961","-0.00022"
"216.40000","7.21055","-1.02180","0.07211","-0.10218","-0.00024"
"216.80000","7.22399","-5.16807","0.07224","-0.51681","-0.00022"
"217.20000","7.23749","-9.03561","0.07237","-0.90356","-0.00023"
"217.60000","7.25062","-11.06396","0.07251","-1.10640","-0.00023"
"218.00000","7.26417","-10.91959","0.07264","-1.09196","-0.00022"
"218.40000","7.27728","-14.28447","0.07277","-1.42845","-0.00024"
"218.80000","7.29055","-15.51928","0.07291","-1.55193","-0.00023"
"219.20000","7.30398","-14.81417","0.07304","-1.48142","-0.00022"
"219.60000","7.31738","-13.68643","0.07317","-1.36864","-0.00024"
"220.00000","7.33060","-13.87615","0.07331","-1.38761","-0.00023"
"220.40000","7.34410","-11.64731","0.07344","-1.16473","-0.00022"
"220.80000","7.35733","-11.57374","0.07357","-1.15737","-0.00024"
"221.20000","7.37064","-11.31465","0.07371","-1.13147","-0.00022"
"221.60000","7.38401","-14.34847","0.07384","-1.43485","-0.00023"
"222.00000","7.39737","-48.01376","0.07397","-4.80138","-0.00024"
"222.40000","7.41073","-49.80884","0.07411","-4.98088","-0.00022"
"222.80000","7.42413","-94.77248","0.07424","-9.47725","-0.00023"
"223.20000","7.43731","-98.20226","0.07437","-9.82023","-0.00024"
"223.60000","7.45059","-96.67768","0.07451","-9.66777","-0.00022"
"224.00000","7.46390","-93.94389","0.07464","-9.39439","-0.00024"
"224.40000","7.47737","-90.61832","0.07477","-9.06183","-0.00023"
"224.80000","7.49079","-87.74581","0.07491","-8.77458","-0.00023"
"225.20000","7.50406","-86.50581","0.07504","-8.65058","-0.00024"
"225.60000","7.51733","-84.59372","0.07517","-8.45937","-0.00023"
"226.00000","7.53066","-81.42767","0.07531","-8.14277","-0.00023"
"226.40000","7.54397","-78.17068","0.07544","-7.81707","-0.00023"
"226.80000","7.55730","-75.26259","0.07557","-7.52626","-0.00022"
"227.20000","7.57070","-74.45802","0.07571","-7.44580","-0.00023"
"227.60000","7.58398","-74.84663","0.07584","-7.48466","-0.00023"
"228.00000","7.59743","-76.16277","0.07597","-7.61628","-0.00022"
"228.40000","7.61070","-75.26854","0.07611","-7.52685","-0.00024"
"228.80000","7.62395","-74.71081","0.07624","-7.47108","-0.00023"
"229.20000","7.63731","-73.44850","0.07637","-7.34485","-0.00023"
"229.60000","7.65076","-70.40882","0.07651","-7.04088","-0.00023"
"230.00000","7.66411","-68.85225","0.07664","-6.88522","-0.00022"
"230.40000","7.67744","-67.17526","0.07677","-6.71753","-0.00023"
"230.80000","7.69055","-66.24014","0.07691","-6.62401","-0.00024"
"231.20000","7.70385","-65.74706","0.07704","-6.57471","-0.00023"
"231.60000","7.71735","-65.73805","0.07717","-6.57381","-0.00023"
"232.00000","7.73083","-64.78411","0.07731","-6.47841","-0.00023"
"232.40000","7.74400","-66.57623","0.07744","-6.65762","-0.00022"
"232.80000","7.75748","-66.05338","0.07757","-6.60534","-0.00024"
"233.20000","7.77064","-66.68210","0.07771","-6.66821","-0.00023"
"233.60000","7.78404","-66.08537","0.07784","-6.60854","-0.00023"
"234.00000","7.79729","-65.91492","0.07797","-6.59149","-0.00024"
"234.40000","7.81066","-64.73140","0.07811","-6.47314","-0.00022"
"234.80000","7.82395","-62.94337","0.07824","-6.29434","-0.00023"
"235.20000","7.83749","-59.89078","0.07837","-5.98908","-0.00026"
"235.60000","7.85068","-57.91950","0.07851","-5.79195","-0.00024"
"236.00000","7.86397","-54.59016","0.07864","-5.45902","-0.00021"
"236.40000","7.87729","-51.66340","0.07877","-5.16634","-0.00024"
"236.80000","7.89071","-49.86979","0.07891","-4.98698","-0.00023"
"237.20000","7.90416","-47.75906","0.07904","-4.77591","-0.00022"
"237.60000","7.91737","-45.76020","0.07917","-4.57602","-0.00023"
"238.00000","7.93065","-44.13819","0.07931","-4.41382","-0.00023"
"238.40000","7.94393","-42.25396","0.07944","-4.22540","-0.00023"
"238.80000","7.95730","-41.80444","0.07957","-4.18044","-0.00022"
"239.20000","7.97066","-40.68705","0.07971","-4.06870","-0.00023"
"239.60000","7.98414","-40.39681","0.07984","-4.03968","-0.00024"
"240.00000","7.99736","-43.11993","0.07997","-4.31199","-0.00022"
"240.40000","8.01076","-46.00658","0.08011","-4.60066","-0.00023"
"240.80000","8.02406","-45.89256","0.08024","-4.58926","-0.00024"
"241.20000","8.03717","-45.19441","0.08037","-4.51944","-0.00022"
"241.60000","8.05062","-44.03200","0.08051","-4.40320","-0.00024"
"242.00000","8.06408","-41.87222","0.08064","-4.18722","-0.00023"
"242.40000","8.07735","-41.21490","0.08077","-4.12149","-0.00022"
"242.80000","8.09077","-39.82059","0.08091","-3.98206","-0.00023"
"243.20000","8.10394","-37.83881","0.08104","-3.78388","-0.00023"
"243.60000","8.11724","-36.78725","0.08117","-3.67873","-0.00022"
"244.00000","8.13072","-34.78453","0.08131","-3.47845","-0.00023"
"244.40000","8.14407","-35.85087","0.08144","-3.58509","-0.00022"
"244.80000","8.15734","-36.87915","0.08157","-3.68792","-0.00023"
"245.20000","8.17078","-36.38556","0.08171","-3.63856","-0.00024"
"245.37600","8.17653","-36.44561","0.08177","-3.64456","-0.00022"