File: Tension/Section_1_Group3/sawdust_tension_per5.is_tens_RawData/Specimen_RawData_1.csv
Time,Extension,Load,Tensile strain (Extension),Axial Video,Tensile stress,Transverse Video
(s),(mm),(N),(mm/mm),(mm/mm),(MPa),(mm/mm)
"0.00000","0.00000","-0.33935","0.00000","-0.00006","-0.03394","0.00000"
"0.20000","0.00264","6.85081","0.00003","-0.00006","0.68508","-0.00003"
"0.40000","0.01084","27.70508","0.00011","-0.00001","2.77051","-0.00001"
"0.60000","0.01748","43.19125","0.00017","0.00006","4.31913","-0.00004"
"0.80000","0.02440","58.39142","0.00024","0.00008","5.83914","-0.00011"
"1.00000","0.03084","71.80111","0.00031","0.00011","7.18011","-0.00014"
"1.20000","0.03756","85.01945","0.00038","0.00021","8.50194","-0.00021"
"1.40000","0.04419","97.44863","0.00044","0.00032","9.74486","-0.00014"
"1.60000","0.05080","109.15629","0.00051","0.00033","10.91563","-0.00010"
"1.80000","0.05753","120.09857","0.00058","0.00039","12.00986","-0.00003"
"2.00000","0.06420","130.35229","0.00064","0.00039","13.03523","0.00009"
"2.20000","0.07090","139.87375","0.00071","0.00043","13.98738","0.00015"
"2.40000","0.07766","148.46445","0.00078","0.00038","14.84645","0.00013"
"2.60000","0.08424","150.11519","0.00084","0.00042","15.01152","0.00004"
"2.80000","0.09083","159.93265","0.00091","0.00045","15.99327","0.00007"
"3.00000","0.09748","169.85025","0.00097","0.00056","16.98503","0.00016"
"3.20000","0.10427","179.77626","0.00104","0.00059","17.97763","0.00024"
"3.40000","0.11083","188.72873","0.00111","0.00062","18.87287","0.00032"
"3.60000","0.11743","197.75075","0.00117","0.00071","19.77507","0.00029"
"3.80000","0.12431","207.12593","0.00124","0.00075","20.71259","0.00033"
"4.00000","0.13087","215.54623","0.00131","0.00078","21.55462","0.00032"
"4.20000","0.13762","224.47629","0.00138","0.00077","22.44763","0.00021"
"4.40000","0.14421","233.10602","0.00144","0.00080","23.31060","0.00017"
"4.60000","0.15093","241.42459","0.00151","0.00091","24.14246","0.00005"
"4.80000","0.15759","249.78206","0.00158","0.00090","24.97821","0.00005"
"5.00000","0.16413","257.54309","0.00164","0.00096","25.75431","0.00000"
"5.20000","0.17087","265.67181","0.00171","0.00099","26.56718","-0.00006"
"5.40000","0.17735","273.10760","0.00177","0.00103","27.31076","-0.00004"
"5.60000","0.18432","281.37152","0.00184","0.00099","28.13715","-0.00003"
"5.80000","0.19091","288.56241","0.00191","0.00098","28.85624","-0.00006"
"6.00000","0.19761","295.99271","0.00198","0.00099","29.59927","-0.00003"
"6.20000","0.20433","303.41800","0.00204","0.00101","30.34180","-0.00008"
"6.40000","0.21084","310.18057","0.00211","0.00103","31.01806","-0.00007"
"6.60000","0.21752","317.26822","0.00218","0.00103","31.72682","-0.00012"
"6.80000","0.22408","323.96997","0.00224","0.00101","32.39700","-0.00015"
"7.00000","0.23095","331.55942","0.00231","0.00104","33.15594","-0.00026"
"7.20000","0.23747","338.04077","0.00237","0.00105","33.80408","-0.00026"
"7.40000","0.24420","344.89493","0.00244","0.00103","34.48949","-0.00024"
"7.60000","0.25099","352.37274","0.00251","0.00106","35.23727","-0.00026"
"7.80000","0.25754","359.37396","0.00258","0.00105","35.93740","-0.00031"
"8.00000","0.26430","366.58548","0.00264","0.00109","36.65855","-0.00038"
"8.20000","0.27086","373.04080","0.00271","0.00111","37.30408","-0.00034"
"8.40000","0.27757","379.55099","0.00278","0.00116","37.95510","-0.00035"
"8.60000","0.28420","385.93460","0.00284","0.00112","38.59346","-0.00034"
"8.80000","0.29083","392.23373","0.00291","0.00110","39.22337","-0.00024"
"9.00000","0.29748","398.48718","0.00297","0.00110","39.84872","-0.00022"
"9.20000","0.30417","404.64908","0.00304","0.00108","40.46491","-0.00021"
"9.40000","0.31104","411.24295","0.00311","0.00112","41.12429","-0.00020"
"9.60000","0.31759","416.91797","0.00318","0.00110","41.69180","-0.00015"
"9.80000","0.32421","422.56573","0.00324","0.00110","42.25657","-0.00021"
"10.00000","0.33095","428.68558","0.00331","0.00116","42.86856","-0.00019"
"10.20000","0.33750","434.02347","0.00337","0.00114","43.40235","-0.00018"
"10.40000","0.34415","439.48666","0.00344","0.00115","43.94867","-0.00016"
"10.60000","0.35084","445.19980","0.00351","0.00115","44.51998","-0.00015"
"10.80000","0.35756","450.64014","0.00358","0.00118","45.06401","-0.00017"
"11.00000","0.36425","456.32751","0.00364","0.00119","45.63275","-0.00008"
"11.20000","0.37089","461.69186","0.00371","0.00116","46.16919","-0.00008"
"11.40000","0.37764","467.14517","0.00378","0.00121","46.71452","-0.00009"
"11.60000","0.38413","472.01196","0.00384","0.00117","47.20119","-0.00005"
"11.80000","0.39097","477.52521","0.00391","0.00118","47.75252","-0.00006"
"12.00000","0.39751","482.43488","0.00398","0.00118","48.24349","-0.00002"
"12.20000","0.40414","487.43115","0.00404","0.00119","48.74311","0.00002"
"12.40000","0.41098","492.99445","0.00411","0.00119","49.29945","0.00004"
"12.60000","0.41745","497.38251","0.00417","0.00123","49.73825","0.00014"
"12.80000","0.42418","502.44360","0.00424","0.00124","50.24436","0.00016"
"13.00000","0.43087","507.41751","0.00431","0.00128","50.74175","0.00023"
"13.20000","0.43776","512.43140","0.00438","0.00126","51.24314","0.00030"
"13.40000","0.44425","516.10980","0.00444","0.00132","51.61098","0.00037"
"13.60000","0.45084","519.43329","0.00451","0.00134","51.94333","0.00034"
"13.80000","0.45760","524.14587","0.00458","0.00138","52.41459","0.00030"
"14.00000","0.46407","528.18427","0.00464","0.00143","52.81843","0.00028"
"14.20000","0.47097","533.63776","0.00471","0.00142","53.36378","0.00030"
"14.40000","0.47748","538.07550","0.00477","0.00137","53.80755","0.00029"
"14.60000","0.48426","543.05450","0.00484","0.00137","54.30545","0.00026"
"14.80000","0.49099","548.11780","0.00491","0.00140","54.81178","0.00026"
"15.00000","0.49761","552.85834","0.00498","0.00145","55.28584","0.00025"
"15.20000","0.50420","557.60388","0.00504","0.00144","55.76039","0.00031"
"15.40000","0.51076","562.30408","0.00511","0.00140","56.23041","0.00020"
"15.60000","0.51763","567.55969","0.00518","0.00142","56.75597","0.00020"
"15.80000","0.52419","572.23749","0.00524","0.00142","57.22375","0.00018"
"16.00000","0.53082","576.94745","0.00531","0.00147","57.69474","0.00021"
"16.20000","0.53760","582.17401","0.00538","0.00149","58.21740","0.00019"
"16.40000","0.54414","586.68506","0.00544","0.00153","58.66851","0.00015"
"16.60000","0.55092","591.82587","0.00551","0.00157","59.18259","0.00017"
"16.80000","0.55756","596.68042","0.00558","0.00158","59.66804","0.00018"
"17.00000","0.56429","601.62244","0.00564","0.00157","60.16224","0.00024"
"17.20000","0.57085","606.35608","0.00571","0.00157","60.63561","0.00027"
"17.40000","0.57750","611.16248","0.00578","0.00156","61.11625","0.00031"
"17.60000","0.58419","616.02692","0.00584","0.00159","61.60269","0.00023"
"17.80000","0.59075","620.83508","0.00591","0.00157","62.08351","0.00029"
"18.00000","0.59758","626.12781","0.00598","0.00158","62.61278","0.00032"
"18.20000","0.60422","631.03632","0.00604","0.00157","63.10363","0.00041"
"18.40000","0.61086","636.00873","0.00611","0.00163","63.60087","0.00038"
"18.60000","0.61766","641.07770","0.00618","0.00166","64.10777","0.00036"
"18.80000","0.62419","645.64233","0.00624","0.00165","64.56423","0.00034"
"19.00000","0.63084","650.33179","0.00631","0.00172","65.03318","0.00034"
"19.20000","0.63744","655.06213","0.00637","0.00176","65.50621","0.00039"
"19.40000","0.64427","660.33710","0.00644","0.00171","66.03371","0.00033"
"19.60000","0.65087","664.90588","0.00651","0.00174","66.49059","0.00027"
"19.80000","0.65747","669.57526","0.00657","0.00179","66.95753","0.00024"
"20.00000","0.66434","674.93195","0.00664","0.00176","67.49319","0.00028"
"20.20000","0.67079","679.28790","0.00671","0.00173","67.92879","0.00020"
"20.40000","0.67760","684.52777","0.00678","0.00173","68.45277","0.00019"
"20.60000","0.68420","689.29370","0.00684","0.00180","68.92937","0.00018"
"20.80000","0.69091","694.20709","0.00691","0.00180","69.42071","0.00014"
"21.00000","0.69759","699.08820","0.00698","0.00182","69.90882","0.00012"
"21.20000","0.70417","703.60120","0.00704","0.00178","70.36012","0.00007"
"21.40000","0.71089","708.77032","0.00711","0.00176","70.87703","0.00006"
"21.60000","0.71743","713.28754","0.00717","0.00177","71.32875","0.00004"
"21.80000","0.72440","719.00787","0.00724","0.00181","71.90079","0.00004"
"22.00000","0.73088","723.32721","0.00731","0.00179","72.33272","-0.00003"
"22.20000","0.73751","728.03766","0.00738","0.00179","72.80376","0.00005"
"22.40000","0.74429","733.26740","0.00744","0.00184","73.32674","0.00006"
"22.60000","0.75081","737.68500","0.00751","0.00182","73.76850","0.00003"
"22.80000","0.75750","742.65979","0.00758","0.00183","74.26598","0.00002"
"23.00000","0.76417","747.35034","0.00764","0.00182","74.73503","-0.00009"
"23.20000","0.77095","752.44824","0.00771","0.00183","75.24483","-0.00006"
"23.40000","0.77759","757.17664","0.00778","0.00187","75.71767","-0.00004"
"23.60000","0.78418","762.10803","0.00784","0.00191","76.21080","-0.00006"
"23.80000","0.79091","767.20520","0.00791","0.00192","76.72052","-0.00001"
"24.00000","0.79750","772.03778","0.00798","0.00191","77.20378","0.00000"
"24.20000","0.80431","777.45050","0.00804","0.00196","77.74505","0.00000"
"24.40000","0.81082","782.12823","0.00811","0.00196","78.21282","-0.00003"
"24.60000","0.81745","787.04468","0.00817","0.00199","78.70447","0.00000"
"24.80000","0.82431","792.63373","0.00824","0.00198","79.26337","0.00000"
"25.00000","0.83084","797.29047","0.00831","0.00203","79.72905","0.00000"
"25.20000","0.83753","802.32147","0.00838","0.00204","80.23215","0.00002"
"25.40000","0.84419","807.54395","0.00844","0.00210","80.75439","-0.00004"
"25.60000","0.85099","813.08765","0.00851","0.00216","81.30876","-0.00005"
"25.80000","0.85751","817.96478","0.00858","0.00216","81.79648","-0.00006"
"26.00000","0.86413","822.74719","0.00864","0.00221","82.27472","-0.00007"
"26.20000","0.87090","828.29633","0.00871","0.00216","82.82964","-0.00014"
"26.40000","0.87741","833.14832","0.00877","0.00223","83.31483","-0.00021"
"26.60000","0.88426","838.83356","0.00884","0.00220","83.88335","-0.00020"
"26.80000","0.89088","843.97382","0.00891","0.00225","84.39738","-0.00026"
"27.00000","0.89756","848.89905","0.00898","0.00230","84.88991","-0.00028"
"27.20000","0.90433","854.35101","0.00904","0.00230","85.43510","-0.00030"
"27.40000","0.91080","858.99664","0.00911","0.00228","85.89967","-0.00035"
"27.60000","0.91752","864.27887","0.00918","0.00232","86.42789","-0.00034"
"27.80000","0.92409","869.14374","0.00924","0.00224","86.91438","-0.00039"
"28.00000","0.93098","874.65735","0.00931","0.00229","87.46574","-0.00038"
"28.20000","0.93749","878.90869","0.00937","0.00227","87.89087","-0.00034"
"28.40000","0.94422","883.88434","0.00944","0.00233","88.38844","-0.00038"
"28.60000","0.95097","889.17206","0.00951","0.00234","88.91721","-0.00046"
"28.80000","0.95746","893.70337","0.00957","0.00227","89.37034","-0.00039"
"29.00000","0.96427","899.23889","0.00964","0.00228","89.92389","-0.00040"
"29.20000","0.97084","903.90985","0.00971","0.00226","90.39098","-0.00039"
"29.40000","0.97761","908.77496","0.00978","0.00229","90.87749","-0.00048"
"29.60000","0.98420","913.72980","0.00984","0.00231","91.37298","-0.00042"
"29.80000","0.99084","918.55896","0.00991","0.00227","91.85590","-0.00043"
"30.00000","0.99749","923.42438","0.00997","0.00229","92.34244","-0.00040"
"30.20000","1.00410","928.42981","0.01004","0.00238","92.84298","-0.00033"
"30.40000","1.01099","934.10901","0.01011","0.00236","93.41090","-0.00034"
"30.60000","1.01752","938.68787","0.01018","0.00237","93.86879","-0.00031"
"30.80000","1.02420","943.60645","0.01024","0.00240","94.36064","-0.00029"
"31.00000","1.03099","948.95459","0.01031","0.00240","94.89546","-0.00030"
"31.20000","1.03750","953.68365","0.01038","0.00239","95.36836","-0.00035"
"31.40000","1.04413","958.57495","0.01044","0.00245","95.85750","-0.00031"
"31.60000","1.05083","963.91852","0.01051","0.00246","96.39185","-0.00022"
"31.80000","1.05760","969.20587","0.01058","0.00247","96.92059","-0.00024"
"32.00000","1.06426","974.57788","0.01064","0.00249","97.45779","-0.00021"
"32.20000","1.07081","979.32733","0.01071","0.00251","97.93273","-0.00015"
"32.40000","1.07764","985.00818","0.01078","0.00258","98.50082","-0.00021"
"32.60000","1.08409","989.75043","0.01084","0.00262","98.97504","-0.00024"
"32.80000","1.09092","995.21680","0.01091","0.00264","99.52168","-0.00021"
"33.00000","1.09755","1000.35901","0.01098","0.00263","100.03590","-0.00024"
"33.20000","1.10418","1005.23633","0.01104","0.00269","100.52364","-0.00022"
"33.40000","1.11093","1010.80554","0.01111","0.00274","101.08055","-0.00017"
"33.60000","1.11746","1015.51031","0.01117","0.00274","101.55103","-0.00016"
"33.80000","1.12424","1020.96210","0.01124","0.00282","102.09621","-0.00020"
"34.00000","1.13079","1026.17297","0.01131","0.00285","102.61729","-0.00024"
"34.20000","1.13765","1031.87866","0.01138","0.00286","103.18787","-0.00026"
"34.40000","1.14421","1037.11951","0.01144","0.00289","103.71195","-0.00023"
"34.60000","1.15078","1042.03467","0.01151","0.00289","104.20347","-0.00016"
"34.80000","1.15767","1047.90002","0.01158","0.00289","104.79000","-0.00013"
"35.00000","1.16409","1052.69226","0.01164","0.00284","105.26923","-0.00017"
"35.20000","1.17082","1058.34509","0.01171","0.00287","105.83451","-0.00016"
"35.40000","1.17748","1063.89331","0.01177","0.00290","106.38933","-0.00016"
"35.60000","1.18435","1069.82178","0.01184","0.00289","106.98218","-0.00010"
"35.80000","1.19083","1074.91003","0.01191","0.00290","107.49100","-0.00008"
"36.00000","1.19750","1080.30298","0.01198","0.00288","108.03030","-0.00005"
"36.20000","1.20422","1085.67175","0.01204","0.00294","108.56718","0.00000"
"36.40000","1.21075","1090.39136","0.01211","0.00293","109.03914","-0.00003"
"36.60000","1.21768","1096.26135","0.01218","0.00300","109.62614","-0.00003"
"36.80000","1.22415","1101.10779","0.01224","0.00299","110.11078","-0.00003"
"37.00000","1.23084","1106.43225","0.01231","0.00297","110.64323","-0.00001"
"37.20000","1.23761","1111.90540","0.01238","0.00298","111.19054","-0.00003"
"37.40000","1.24420","1117.16040","0.01244","0.00293","111.71604","0.00012"
"37.60000","1.25079","1122.06348","0.01251","0.00295","112.20634","0.00011"
"37.80000","1.25752","1127.71509","0.01258","0.00295","112.77151","0.00013"
"38.00000","1.26429","1133.01953","0.01264","0.00304","113.30196","0.00010"
"38.20000","1.27086","1137.59827","0.01271","0.00303","113.75983","0.00012"
"38.40000","1.27753","1142.55042","0.01278","0.00301","114.25504","0.00015"
"38.60000","1.28424","1147.68982","0.01284","0.00303","114.76898","0.00011"
"38.80000","1.29080","1152.43005","0.01291","0.00299","115.24300","0.00009"
"39.00000","1.29757","1157.79382","0.01298","0.00298","115.77938","0.00003"
"39.20000","1.30422","1163.15674","0.01304","0.00302","116.31567","0.00007"
"39.40000","1.31084","1168.34521","0.01311","0.00308","116.83452","0.00010"
"39.60000","1.31758","1174.12244","0.01318","0.00312","117.41225","0.00009"
"39.80000","1.32416","1179.30579","0.01324","0.00311","117.93058","0.00001"
"40.00000","1.33088","1184.81335","0.01331","0.00311","118.48134","0.00000"
"40.20000","1.33752","1190.09229","0.01338","0.00314","119.00923","-0.00002"
"40.40000","1.34434","1195.81665","0.01344","0.00315","119.58167","-0.00005"
"40.60000","1.35089","1201.13025","0.01351","0.00314","120.11302","-0.00003"
"40.80000","1.35744","1206.21692","0.01357","0.00313","120.62169","-0.00003"
"41.00000","1.36435","1212.31897","0.01364","0.00313","121.23190","-0.00004"
"41.20000","1.37073","1216.84827","0.01371","0.00318","121.68483","-0.00006"
"41.40000","1.37752","1222.22803","0.01378","0.00317","122.22280","-0.00017"
"41.60000","1.38416","1227.52795","0.01384","0.00319","122.75279","-0.00015"
"41.80000","1.39095","1232.83264","0.01391","0.00318","123.28326","-0.00015"
"42.00000","1.39763","1238.32715","0.01398","0.00323","123.83272","-0.00010"
"42.20000","1.40418","1243.43848","0.01404","0.00324","124.34385","-0.00006"
"42.40000","1.41089","1248.94946","0.01411","0.00327","124.89494","-0.00011"
"42.60000","1.41742","1253.99707","0.01417","0.00319","125.39970","-0.00012"
"42.80000","1.42437","1259.96008","0.01424","0.00326","125.99601","-0.00009"
"43.00000","1.43080","1264.59473","0.01431","0.00325","126.45947","-0.00010"
"43.20000","1.43746","1269.84460","0.01437","0.00326","126.98446","-0.00017"
"43.40000","1.44426","1275.31860","0.01444","0.00324","127.53186","-0.00010"
"43.60000","1.45081","1280.09521","0.01451","0.00325","128.00952","-0.00009"
"43.80000","1.45756","1285.64148","0.01458","0.00326","128.56415","-0.00010"
"44.00000","1.46418","1290.69495","0.01464","0.00322","129.06949","-0.00016"
"44.20000","1.47101","1296.41382","0.01471","0.00324","129.64139","-0.00027"
"44.40000","1.47753","1301.21399","0.01478","0.00322","130.12140","-0.00022"
"44.60000","1.48419","1306.47473","0.01484","0.00323","130.64748","-0.00019"
"44.80000","1.49083","1311.79602","0.01491","0.00325","131.17960","-0.00019"
"45.00000","1.49744","1316.81458","0.01497","0.00327","131.68146","-0.00018"
"45.20000","1.50424","1322.56848","0.01504","0.00325","132.25685","-0.00021"
"45.40000","1.51089","1327.77917","0.01511","0.00328","132.77792","-0.00028"
"45.60000","1.51755","1332.33704","0.01518","0.00334","133.23370","-0.00029"
"45.80000","1.52433","1337.74329","0.01524","0.00337","133.77432","-0.00027"
"46.00000","1.53087","1342.50085","0.01531","0.00339","134.25009","-0.00028"
"46.20000","1.53750","1347.40234","0.01538","0.00341","134.74023","-0.00035"
"46.40000","1.54417","1352.52429","0.01544","0.00342","135.25243","-0.00039"
"46.60000","1.55093","1357.74841","0.01551","0.00338","135.77484","-0.00042"
"46.80000","1.55751","1362.57922","0.01558","0.00343","136.25792","-0.00045"
"47.00000","1.56411","1367.49829","0.01564","0.00345","136.74983","-0.00051"
"47.20000","1.57096","1372.90430","0.01571","0.00346","137.29044","-0.00048"
"47.40000","1.57751","1377.51135","0.01578","0.00346","137.75113","-0.00058"
"47.60000","1.58428","1382.98669","0.01584","0.00347","138.29868","-0.00061"
"47.80000","1.59091","1388.05505","0.01591","0.00343","138.80551","-0.00067"
"48.00000","1.59758","1392.94531","0.01598","0.00344","139.29453","-0.00072"
"48.20000","1.60430","1398.09985","0.01604","0.00343","139.80998","-0.00078"
"48.40000","1.61079","1402.55078","0.01611","0.00348","140.25508","-0.00079"
"48.60000","1.61750","1407.62952","0.01618","0.00352","140.76295","-0.00078"
"48.80000","1.62403","1412.40833","0.01624","0.00350","141.24083","-0.00082"
"49.00000","1.63100","1418.26709","0.01631","0.00347","141.82671","-0.00084"
"49.20000","1.63757","1423.04529","0.01638","0.00344","142.30453","-0.00082"
"49.40000","1.64426","1428.02429","0.01644","0.00348","142.80243","-0.00081"
"49.60000","1.65105","1433.54614","0.01651","0.00347","143.35461","-0.00083"
"49.80000","1.65748","1437.84351","0.01657","0.00352","143.78435","-0.00085"
"50.00000","1.66417","1442.90112","0.01664","0.00351","144.29012","-0.00088"
"50.20000","1.67078","1447.90979","0.01671","0.00352","144.79099","-0.00082"
"50.40000","1.67758","1453.12317","0.01678","0.00348","145.31232","-0.00084"
"50.60000","1.68417","1457.45679","0.01684","0.00354","145.74568","-0.00081"
"50.80000","1.69088","1462.01648","0.01691","0.00358","146.20164","-0.00081"
"51.00000","1.69763","1466.56897","0.01698","0.00357","146.65689","-0.00085"
"51.20000","1.70418","1470.89062","0.01704","0.00353","147.08907","-0.00080"
"51.40000","1.71104","1476.19617","0.01711","0.00357","147.61961","-0.00083"
"51.60000","1.71752","1480.58423","0.01718","0.00356","148.05843","-0.00087"
"51.80000","1.72418","1485.48657","0.01724","0.00356","148.54866","-0.00091"
"52.00000","1.73089","1490.38696","0.01731","0.00362","149.03870","-0.00095"
"52.20000","1.73752","1495.04443","0.01738","0.00358","149.50444","-0.00093"
"52.40000","1.74416","1499.65063","0.01744","0.00361","149.96506","-0.00094"
"52.60000","1.75083","1504.23523","0.01751","0.00360","150.42352","-0.00091"
"52.80000","1.75768","1509.20288","0.01758","0.00358","150.92029","-0.00092"
"53.00000","1.76426","1513.75415","0.01764","0.00362","151.37541","-0.00090"
"53.20000","1.77089","1518.30347","0.01771","0.00363","151.83035","-0.00096"
"53.40000","1.77759","1523.38916","0.01778","0.00369","152.33891","-0.00095"
"53.60000","1.78415","1527.88000","0.01784","0.00369","152.78799","-0.00099"
"53.80000","1.79086","1532.70105","0.01791","0.00369","153.27011","-0.00103"
"54.00000","1.79751","1537.47961","0.01798","0.00367","153.74796","-0.00101"
"54.20000","1.80417","1542.17969","0.01804","0.00370","154.21797","-0.00104"
"54.40000","1.81092","1547.32129","0.01811","0.00364","154.73213","-0.00110"
"54.60000","1.81756","1552.11145","0.01818","0.00365","155.21115","-0.00115"
"54.80000","1.82431","1557.13257","0.01824","0.00363","155.71326","-0.00114"
"55.00000","1.83084","1561.67639","0.01831","0.00363","156.16763","-0.00114"
"55.20000","1.83764","1566.93237","0.01838","0.00363","156.69324","-0.00119"
"55.40000","1.84420","1571.85107","0.01844","0.00360","157.18510","-0.00121"
"55.60000","1.85079","1576.55811","0.01851","0.00360","157.65581","-0.00120"
"55.80000","1.85762","1582.25562","0.01858","0.00360","158.22556","-0.00122"
"56.00000","1.86409","1586.98462","0.01864","0.00362","158.69846","-0.00121"
"56.20000","1.87086","1592.16077","0.01871","0.00367","159.21608","-0.00120"
"56.40000","1.87758","1597.38245","0.01878","0.00370","159.73825","-0.00118"
"56.60000","1.88441","1602.58472","0.01884","0.00370","160.25847","-0.00115"
"56.80000","1.89095","1607.06116","0.01891","0.00371","160.70612","-0.00114"
"57.00000","1.89749","1611.42188","0.01897","0.00367","161.14218","-0.00116"
"57.20000","1.90422","1616.59192","0.01904","0.00371","161.65919","-0.00110"
"57.40000","1.91075","1621.10632","0.01911","0.00375","162.11063","-0.00107"
"57.60000","1.91766","1626.82629","0.01918","0.00381","162.68263","-0.00110"
"57.80000","1.92416","1631.18945","0.01924","0.00385","163.11894","-0.00102"
"58.00000","1.93086","1635.97339","0.01931","0.00384","163.59734","-0.00109"
"58.20000","1.93765","1641.10376","0.01938","0.00386","164.11038","-0.00115"
"58.40000","1.94424","1645.46838","0.01944","0.00384","164.54684","-0.00111"
"58.60000","1.95087","1650.02161","0.01951","0.00386","165.00217","-0.00109"
"58.80000","1.95746","1654.37256","0.01957","0.00389","165.43726","-0.00111"
"59.00000","1.96433","1659.46240","0.01964","0.00391","165.94624","-0.00111"
"59.20000","1.97086","1663.71069","0.01971","0.00391","166.37106","-0.00118"
"59.40000","1.97748","1668.40735","0.01977","0.00392","166.84073","-0.00118"
"59.60000","1.98423","1673.36804","0.01984","0.00391","167.33681","-0.00126"
"59.80000","1.99082","1678.09570","0.01991","0.00393","167.80957","-0.00126"
"60.00000","1.99762","1683.27087","0.01998","0.00400","168.32709","-0.00131"
"60.20000","2.00426","1687.85645","0.02004","0.00399","168.78564","-0.00127"
"60.40000","2.01094","1692.68030","0.02011","0.00399","169.26804","-0.00128"
"60.60000","2.01757","1697.55579","0.02018","0.00400","169.75558","-0.00134"
"60.80000","2.02418","1702.36511","0.02024","0.00403","170.23651","-0.00130"
"61.00000","2.03083","1707.12830","0.02031","0.00405","170.71283","-0.00133"
"61.20000","2.03745","1712.05676","0.02037","0.00404","171.20567","-0.00133"
"61.40000","2.04427","1717.38867","0.02044","0.00398","171.73886","-0.00142"
"61.60000","2.05093","1722.23450","0.02051","0.00404","172.22345","-0.00144"
"61.80000","2.05754","1727.00012","0.02058","0.00408","172.70001","-0.00147"
"62.00000","2.06433","1732.39172","0.02064","0.00407","173.23917","-0.00148"
"62.20000","2.07081","1736.72083","0.02071","0.00409","173.67209","-0.00151"
"62.40000","2.07753","1741.63074","0.02078","0.00407","174.16307","-0.00155"
"62.60000","2.08414","1746.50574","0.02084","0.00405","174.65057","-0.00154"
"62.80000","2.09092","1751.53674","0.02091","0.00405","175.15367","-0.00153"
"63.00000","2.09761","1756.29150","0.02098","0.00411","175.62915","-0.00151"
"63.20000","2.10418","1760.72778","0.02104","0.00412","176.07278","-0.00151"
"63.40000","2.11092","1765.29456","0.02111","0.00415","176.52945","-0.00152"
"63.60000","2.11744","1769.48010","0.02117","0.00413","176.94801","-0.00150"
"63.80000","2.12432","1774.75452","0.02124","0.00412","177.47545","-0.00143"
"64.00000","2.13089","1779.17188","0.02131","0.00419","177.91719","-0.00135"
"64.20000","2.13751","1783.75525","0.02138","0.00415","178.37552","-0.00138"
"64.40000","2.14426","1788.90491","0.02144","0.00420","178.89049","-0.00129"
"64.60000","2.15079","1792.95239","0.02151","0.00422","179.29524","-0.00133"
"64.80000","2.15755","1797.95007","0.02158","0.00424","179.79501","-0.00124"
"65.00000","2.16413","1802.29993","0.02164","0.00425","180.23000","-0.00120"
"65.20000","2.17103","1806.97571","0.02171","0.00427","180.69757","-0.00126"
"65.40000","2.17754","1810.72668","0.02178","0.00427","181.07266","-0.00123"
"65.60000","2.18421","1814.69397","0.02184","0.00433","181.46939","-0.00122"
"65.80000","2.19095","1816.43555","0.02191","0.00427","181.64355","-0.00127"
"66.00000","2.19742","1816.29041","0.02197","0.00434","181.62904","-0.00121"
"66.20000","2.20423","1818.06067","0.02204","0.00432","181.80606","-0.00119"
"66.40000","2.21085","1820.32227","0.02211","0.00428","182.03223","-0.00120"
"66.60000","2.21756","1823.26453","0.02218","0.00434","182.32645","-0.00123"
"66.80000","2.22424","1826.60254","0.02224","0.00441","182.66025","-0.00123"
"67.00000","2.23088","1829.65747","0.02231","0.00441","182.96574","-0.00124"
"67.20000","2.23754","1833.10413","0.02238","0.00443","183.31041","-0.00122"
"67.40000","2.24416","1836.66016","0.02244","0.00444","183.66602","-0.00122"
"67.60000","2.25097","1840.65442","0.02251","0.00451","184.06544","-0.00119"
"67.80000","2.25751","1843.61584","0.02258","0.00451","184.36159","-0.00121"
"68.00000","2.26413","1846.10986","0.02264","0.00455","184.61099","-0.00123"
"68.20000","2.27099","1849.33044","0.02271","0.00457","184.93304","-0.00130"
"68.40000","2.27749","1851.81238","0.02277","0.00457","185.18124","-0.00124"
"68.60000","2.28419","1855.07068","0.02284","0.00457","185.50706","-0.00127"
"68.80000","2.29090","1858.37842","0.02291","0.00457","185.83784","-0.00123"
"69.00000","2.29762","1860.75903","0.02298","0.00460","186.07590","-0.00126"
"69.20000","2.30420","1862.72278","0.02304","0.00457","186.27228","-0.00131"
"69.40000","2.31082","1864.65210","0.02311","0.00452","186.46521","-0.00133"
"69.60000","2.31755","1867.57690","0.02318","0.00453","186.75769","-0.00142"
"69.80000","2.32407","1870.07263","0.02324","0.00450","187.00726","-0.00141"
"70.00000","2.33094","1873.36694","0.02331","0.00455","187.33670","-0.00142"
"70.20000","2.33754","1875.57483","0.02338","0.00455","187.55748","-0.00141"
"70.40000","2.34419","1877.78381","0.02344","0.00453","187.77838","-0.00143"
"70.60000","2.35105","1881.24231","0.02351","0.00451","188.12424","-0.00141"
"70.80000","2.35750","1883.57068","0.02357","0.00454","188.35707","-0.00141"
"71.00000","2.36415","1886.10718","0.02364","0.00453","188.61072","-0.00139"
"71.20000","2.37080","1888.20007","0.02371","0.00449","188.82001","-0.00139"
"71.40000","2.37766","1890.16406","0.02378","0.00451","189.01640","-0.00143"
"71.60000","2.38415","1891.80896","0.02384","0.00452","189.18089","-0.00140"
"71.80000","2.39084","1892.88037","0.02391","0.00453","189.28804","-0.00139"
"72.00000","2.39762","1893.20813","0.02398","0.00450","189.32082","-0.00143"
"72.20000","2.40415","1890.76807","0.02404","0.00452","189.07681","-0.00143"
"72.40000","2.41098","1890.32666","0.02411","0.00452","189.03267","-0.00143"
"72.60000","2.41752","1888.63953","0.02418","0.00450","188.86395","-0.00150"
"72.80000","2.42420","1884.19592","0.02424","0.00449","188.41959","-0.00147"
"73.00000","2.43089","1881.51257","0.02431","0.00441","188.15126","-0.00148"
"73.20000","2.43751","1874.09949","0.02438","0.00440","187.40994","-0.00149"
"73.40000","2.44415","1846.40198","0.02444","0.00436","184.64020","-0.00150"
"73.48000","2.44693","1587.62524","0.02447","0.00434","158.76253","-0.00144"
"73.48800","2.44718","1291.55115","0.02447","0.00420","129.15512","-0.00145"
"73.49300","2.44735","1097.75476","0.02447","0.00389","109.77547","-0.00145"