File: Tension/Section_1_Group_2/Sunflower_5%-2.is_tens_RawData/Specimen_RawData_1.csv
Time,Extension,Load,Tensile strain (Extension),Tensile stress,Strain-by-clip-gage
(s),(mm),(N),(mm/mm),(MPa),(mm/mm)
"0.00000","0.00000","-0.90628","0.00000","-0.09063","-0.00002"
"0.10000","0.00017","-0.91154","0.00000","-0.09115","-0.00001"
"0.20000","0.00084","0.58186","0.00001","0.05819","-0.00001"
"0.30000","0.00172","1.97165","0.00002","0.19717","-0.00001"
"0.40000","0.00468","7.92356","0.00005","0.79236","0.00004"
"0.50000","0.00649","11.59100","0.00006","1.15910","0.00004"
"0.60000","0.00805","14.49675","0.00008","1.44968","0.00005"
"0.70000","0.00987","18.09274","0.00010","1.80927","0.00009"
"0.80000","0.01171","21.72140","0.00012","2.17214","0.00010"
"0.90000","0.01307","24.30617","0.00013","2.43062","0.00011"
"1.00000","0.01501","28.07422","0.00015","2.80742","0.00014"
"1.10000","0.01638","30.59382","0.00016","3.05938","0.00014"
"1.20000","0.01817","33.96800","0.00018","3.39680","0.00016"
"1.30000","0.01985","37.06654","0.00020","3.70665","0.00019"
"1.40000","0.02146","40.13275","0.00021","4.01328","0.00019"
"1.50000","0.02336","43.89193","0.00023","4.38919","0.00021"
"1.60000","0.02470","46.37157","0.00025","4.63716","0.00023"
"1.70000","0.02669","50.03488","0.00027","5.00349","0.00025"
"1.80000","0.02809","52.59144","0.00028","5.25914","0.00026"
"1.90000","0.02979","55.82095","0.00030","5.58210","0.00027"
"2.00000","0.03149","58.99242","0.00031","5.89924","0.00029"
"2.10000","0.03314","62.13381","0.00033","6.21338","0.00031"
"2.20000","0.03507","65.84241","0.00035","6.58424","0.00033"
"2.30000","0.03641","68.17616","0.00036","6.81762","0.00034"
"2.40000","0.03832","71.78716","0.00038","7.17872","0.00036"
"2.50000","0.03975","74.34821","0.00040","7.43482","0.00037"
"2.60000","0.04148","77.52440","0.00041","7.75244","0.00039"
"2.70000","0.04325","80.74728","0.00043","8.07473","0.00040"
"2.80000","0.04480","83.60768","0.00045","8.36077","0.00042"
"2.90000","0.04667","87.03874","0.00047","8.70387","0.00044"
"3.00000","0.04814","89.59707","0.00048","8.95971","0.00045"
"3.10000","0.04997","92.85788","0.00050","9.28579","0.00047"
"3.20000","0.05152","95.89639","0.00052","9.58964","0.00048"
"3.30000","0.05307","98.46649","0.00053","9.84665","0.00049"
"3.40000","0.05491","101.89364","0.00055","10.18936","0.00051"
"3.50000","0.05651","104.77161","0.00057","10.47716","0.00053"
"3.60000","0.05828","107.88899","0.00058","10.78890","0.00054"
"3.70000","0.05983","110.63669","0.00060","11.06367","0.00056"
"3.80000","0.06152","113.75739","0.00062","11.37574","0.00057"
"3.90000","0.06325","116.73162","0.00063","11.67316","0.00059"
"4.00000","0.06475","119.52139","0.00065","11.95214","0.00060"
"4.10000","0.06654","122.61090","0.00067","12.26109","0.00062"
"4.20000","0.06815","125.43787","0.00068","12.54379","0.00063"
"4.30000","0.06988","128.52208","0.00070","12.85221","0.00065"
"4.40000","0.07163","131.73595","0.00072","13.17359","0.00066"
"4.50000","0.07314","134.40411","0.00073","13.44041","0.00067"
"4.60000","0.07491","137.43987","0.00075","13.74399","0.00069"
"4.70000","0.07637","140.03224","0.00076","14.00322","0.00070"
"4.80000","0.07819","143.32849","0.00078","14.33285","0.00072"
"4.90000","0.07985","146.14185","0.00080","14.61418","0.00073"
"5.00000","0.08152","148.98370","0.00082","14.89837","0.00075"
"5.10000","0.08330","152.18834","0.00083","15.21883","0.00076"
"5.20000","0.08474","154.65251","0.00085","15.46525","0.00078"
"5.30000","0.08665","158.02110","0.00087","15.80211","0.00079"
"5.40000","0.08807","160.41357","0.00088","16.04136","0.00081"
"5.50000","0.08983","163.55077","0.00090","16.35508","0.00082"
"5.60000","0.09160","166.58302","0.00092","16.65830","0.00084"
"5.70000","0.09314","169.19682","0.00093","16.91968","0.00085"
"5.80000","0.09508","172.62451","0.00095","17.26245","0.00087"
"5.90000","0.09638","174.72121","0.00096","17.47212","0.00088"
"6.00000","0.09829","178.15576","0.00098","17.81558","0.00090"
"6.10000","0.09974","180.51512","0.00100","18.05151","0.00091"
"6.20000","0.10152","183.67720","0.00102","18.36772","0.00093"
"6.30000","0.10337","186.88557","0.00103","18.68856","0.00094"
"6.40000","0.10478","189.14655","0.00105","18.91465","0.00096"
"6.50000","0.10675","192.52872","0.00107","19.25287","0.00097"
"6.60000","0.10805","194.73248","0.00108","19.47325","0.00099"
"6.70000","0.10998","198.09857","0.00110","19.80986","0.00100"
"6.80000","0.11150","200.65578","0.00111","20.06558","0.00102"
"6.90000","0.11311","203.26303","0.00113","20.32630","0.00103"
"7.00000","0.11502","206.61424","0.00115","20.66142","0.00105"
"7.10000","0.11646","208.92320","0.00116","20.89232","0.00106"
"7.20000","0.11840","212.33354","0.00118","21.23335","0.00108"
"7.30000","0.11970","214.34982","0.00120","21.43498","0.00109"
"7.40000","0.12153","217.47919","0.00122","21.74792","0.00110"
"7.50000","0.12318","220.19308","0.00123","22.01931","0.00112"
"7.60000","0.12478","222.80060","0.00125","22.28006","0.00113"
"7.70000","0.12664","226.02794","0.00127","22.60279","0.00115"
"7.80000","0.12804","228.17287","0.00128","22.81729","0.00116"
"7.90000","0.13002","231.58046","0.00130","23.15805","0.00118"
"8.00000","0.13145","233.83102","0.00131","23.38310","0.00119"
"8.10000","0.13319","236.78539","0.00133","23.67854","0.00121"
"8.20000","0.13488","239.50066","0.00135","23.95007","0.00122"
"8.30000","0.13640","241.95563","0.00136","24.19556","0.00123"
"8.40000","0.13832","245.14429","0.00138","24.51443","0.00125"
"8.50000","0.13977","247.29356","0.00140","24.72936","0.00126"
"8.60000","0.14163","250.34154","0.00142","25.03415","0.00128"
"8.70000","0.14311","252.54712","0.00143","25.25471","0.00129"
"8.80000","0.14479","255.31500","0.00145","25.53150","0.00130"
"8.90000","0.14659","258.32596","0.00147","25.83260","0.00132"
"9.00000","0.14814","260.64178","0.00148","26.06418","0.00133"
"9.10000","0.14996","263.57520","0.00150","26.35752","0.00135"
"9.20000","0.15146","265.73654","0.00151","26.57365","0.00136"
"9.30000","0.15321","268.63940","0.00153","26.86394","0.00137"
"9.40000","0.15485","271.01700","0.00155","27.10170","0.00139"
"9.50000","0.15646","273.45099","0.00156","27.34510","0.00140"
"9.60000","0.15824","276.11172","0.00158","27.61117","0.00141"
"9.70000","0.15981","278.53268","0.00160","27.85327","0.00143"
"9.80000","0.16161","281.14539","0.00162","28.11454","0.00144"
"9.90000","0.16324","283.55334","0.00163","28.35534","0.00145"
"10.00000","0.16483","285.69888","0.00165","28.56989","0.00146"
"10.10000","0.16659","288.27609","0.00167","28.82761","0.00148"
"10.20000","0.16807","290.22327","0.00168","29.02233","0.00149"
"10.30000","0.16995","293.05801","0.00170","29.30580","0.00150"
"10.40000","0.17155","295.40155","0.00172","29.54016","0.00152"
"10.50000","0.17317","297.86176","0.00173","29.78617","0.00153"
"10.60000","0.17492","300.38354","0.00175","30.03835","0.00154"
"10.70000","0.17648","302.65866","0.00176","30.26587","0.00155"
"10.80000","0.17831","305.44147","0.00178","30.54415","0.00157"
"10.90000","0.17973","307.62271","0.00180","30.76227","0.00158"
"11.00000","0.18155","310.41806","0.00182","31.04181","0.00159"
"11.10000","0.18323","313.02463","0.00183","31.30246","0.00161"
"11.20000","0.18483","315.32864","0.00185","31.53286","0.00162"
"11.30000","0.18663","318.39087","0.00187","31.83909","0.00164"
"11.40000","0.18806","320.38550","0.00188","32.03855","0.00165"
"11.50000","0.18998","323.54764","0.00190","32.35476","0.00166"
"11.60000","0.19143","325.56766","0.00191","32.55677","0.00168"
"11.70000","0.19323","328.59189","0.00193","32.85919","0.00169"
"11.80000","0.19496","331.10724","0.00195","33.11073","0.00171"
"11.90000","0.19644","333.39456","0.00196","33.33945","0.00172"
"12.00000","0.19831","336.32211","0.00198","33.63221","0.00173"
"12.10000","0.19972","338.60617","0.00200","33.86062","0.00175"
"12.20000","0.20160","341.46774","0.00202","34.14677","0.00176"
"12.30000","0.20307","343.74277","0.00203","34.37428","0.00178"
"12.40000","0.20483","346.34509","0.00205","34.63451","0.00179"
"12.50000","0.20667","349.32126","0.00207","34.93213","0.00181"
"12.60000","0.20811","351.41696","0.00208","35.14170","0.00182"
"12.70000","0.21001","354.45712","0.00210","35.44571","0.00183"
"12.80000","0.21134","356.28531","0.00211","35.62853","0.00185"
"12.90000","0.21324","359.44424","0.00213","35.94442","0.00186"
"13.00000","0.21483","361.81335","0.00215","36.18134","0.00188"
"13.10000","0.21650","364.27930","0.00216","36.42793","0.00189"
"13.20000","0.21834","367.26639","0.00218","36.72664","0.00191"
"13.30000","0.21975","369.23398","0.00220","36.92340","0.00192"
"13.40000","0.22170","372.34091","0.00222","37.23409","0.00193"
"13.50000","0.22307","374.33539","0.00223","37.43354","0.00195"
"13.60000","0.22493","377.16965","0.00225","37.71696","0.00196"
"13.70000","0.22650","379.54108","0.00226","37.95411","0.00197"
"13.80000","0.22811","381.95901","0.00228","38.19590","0.00199"
"13.90000","0.23011","385.11459","0.00230","38.51146","0.00201"
"14.00000","0.23149","386.92850","0.00231","38.69285","0.00202"
"14.10000","0.23330","389.76395","0.00233","38.97639","0.00203"
"14.20000","0.23471","391.67212","0.00235","39.16721","0.00204"
"14.30000","0.23653","394.61252","0.00237","39.46125","0.00206"
"14.40000","0.23827","397.27121","0.00238","39.72712","0.00207"
"14.50000","0.23978","399.34650","0.00240","39.93465","0.00209"
"14.60000","0.24168","402.34122","0.00242","40.23412","0.00210"
"14.70000","0.24311","404.33487","0.00243","40.43349","0.00211"
"14.80000","0.24495","407.15430","0.00245","40.71543","0.00213"
"14.90000","0.24643","409.32776","0.00246","40.93278","0.00214"
"15.00000","0.24810","411.76965","0.00248","41.17696","0.00215"
"15.10000","0.24989","414.44666","0.00250","41.44466","0.00217"
"15.20000","0.25149","416.80032","0.00251","41.68003","0.00218"
"15.30000","0.25333","419.52045","0.00253","41.95205","0.00220"
"15.40000","0.25478","421.55927","0.00255","42.15593","0.00221"
"15.50000","0.25656","424.33710","0.00257","42.43371","0.00223"
"15.60000","0.25814","426.58508","0.00258","42.65851","0.00224"
"15.70000","0.25973","428.91614","0.00260","42.89161","0.00225"
"15.80000","0.26159","431.76505","0.00262","43.17651","0.00227"
"15.90000","0.26315","433.98669","0.00263","43.39867","0.00228"
"16.00000","0.26494","436.68143","0.00265","43.66814","0.00230"
"16.10000","0.26653","438.89316","0.00267","43.88932","0.00231"
"16.20000","0.26816","441.34756","0.00268","44.13476","0.00232"
"16.30000","0.26988","443.72244","0.00270","44.37225","0.00234"
"16.40000","0.27136","445.83682","0.00271","44.58368","0.00235"
"16.50000","0.27322","448.60104","0.00273","44.86010","0.00237"
"16.60000","0.27491","451.07999","0.00275","45.10800","0.00238"
"16.70000","0.27654","453.35837","0.00277","45.33584","0.00239"
"16.80000","0.27826","455.88446","0.00278","45.58845","0.00241"
"16.90000","0.27979","458.06387","0.00280","45.80639","0.00242"
"17.00000","0.28158","460.69910","0.00282","46.06991","0.00243"
"17.10000","0.28310","462.66425","0.00283","46.26643","0.00245"
"17.20000","0.28492","465.39288","0.00285","46.53929","0.00246"
"17.30000","0.28663","467.82080","0.00287","46.78208","0.00248"
"17.40000","0.28809","469.78210","0.00288","46.97821","0.00249"
"17.50000","0.29004","472.68118","0.00290","47.26812","0.00251"
"17.60000","0.29148","474.62393","0.00291","47.46239","0.00252"
"17.70000","0.29326","477.25208","0.00293","47.72521","0.00253"
"17.80000","0.29471","479.12759","0.00295","47.91276","0.00255"
"17.90000","0.29657","481.87988","0.00297","48.18799","0.00256"
"18.00000","0.29834","484.43274","0.00298","48.44328","0.00258"
"18.10000","0.29974","486.11737","0.00300","48.61174","0.00259"
"18.20000","0.30168","489.14664","0.00302","48.91467","0.00260"
"18.30000","0.30305","490.88202","0.00303","49.08820","0.00261"
"18.40000","0.30494","493.58160","0.00305","49.35816","0.00263"
"18.50000","0.30639","495.50781","0.00306","49.55078","0.00264"
"18.60000","0.30813","497.96301","0.00308","49.79630","0.00266"
"18.70000","0.31001","500.60187","0.00310","50.06019","0.00267"
"18.80000","0.31139","502.42618","0.00311","50.24262","0.00268"
"18.90000","0.31344","505.46954","0.00313","50.54696","0.00270"
"19.00000","0.31470","506.92792","0.00315","50.69279","0.00271"
"19.10000","0.31658","509.61032","0.00317","50.96103","0.00273"
"19.20000","0.31809","511.71249","0.00318","51.17125","0.00274"
"19.30000","0.31980","513.98792","0.00320","51.39879","0.00275"
"19.40000","0.32171","516.81311","0.00322","51.68131","0.00277"
"19.50000","0.32307","518.35004","0.00323","51.83500","0.00278"
"19.60000","0.32504","521.28992","0.00325","52.12899","0.00280"
"19.70000","0.32638","522.97717","0.00326","52.29772","0.00281"
"19.80000","0.32822","525.50824","0.00328","52.55082","0.00282"
"19.90000","0.32984","527.61859","0.00330","52.76186","0.00284"
"20.00000","0.33143","529.78949","0.00331","52.97895","0.00285"
"20.10000","0.33334","532.40857","0.00333","53.24086","0.00286"
"20.20000","0.33478","534.33771","0.00335","53.43377","0.00288"
"20.30000","0.33669","537.02466","0.00337","53.70247","0.00289"
"20.40000","0.33810","538.66620","0.00338","53.86662","0.00290"
"20.50000","0.33982","540.93201","0.00340","54.09320","0.00292"
"20.60000","0.34154","543.38892","0.00342","54.33889","0.00293"
"20.70000","0.34314","545.36566","0.00343","54.53657","0.00294"
"20.80000","0.34503","548.06628","0.00345","54.80663","0.00296"
"20.90000","0.34645","549.82330","0.00346","54.98233","0.00297"
"21.00000","0.34826","552.25446","0.00348","55.22544","0.00298"
"21.10000","0.34984","554.36755","0.00350","55.43676","0.00300"
"21.20000","0.35149","556.53632","0.00351","55.65363","0.00301"
"21.30000","0.35323","558.88135","0.00353","55.88813","0.00302"
"21.40000","0.35476","560.80463","0.00355","56.08046","0.00304"
"21.50000","0.35666","563.42841","0.00357","56.34284","0.00305"
"21.60000","0.35822","565.43152","0.00358","56.54315","0.00306"
"21.70000","0.35987","567.55109","0.00360","56.75511","0.00308"
"21.80000","0.36151","569.70923","0.00362","56.97092","0.00309"
"21.90000","0.36307","571.60303","0.00363","57.16030","0.00310"
"22.00000","0.36495","574.36005","0.00365","57.43600","0.00312"
"22.10000","0.36645","576.08105","0.00366","57.60810","0.00313"
"22.20000","0.36823","578.48303","0.00368","57.84830","0.00314"
"22.30000","0.36986","580.48663","0.00370","58.04866","0.00316"
"22.40000","0.37152","582.62323","0.00372","58.26232","0.00317"
"22.50000","0.37328","584.87610","0.00373","58.48761","0.00319"
"22.60000","0.37474","586.76715","0.00375","58.67672","0.00320"
"22.70000","0.37658","589.17340","0.00377","58.91734","0.00321"
"22.80000","0.37813","591.00409","0.00378","59.10041","0.00322"
"22.90000","0.37984","593.30615","0.00380","59.33062","0.00324"
"23.00000","0.38165","595.64954","0.00382","59.56495","0.00325"
"23.10000","0.38309","597.38580","0.00383","59.73858","0.00326"
"23.20000","0.38495","599.84283","0.00385","59.98428","0.00328"
"23.30000","0.38639","601.43561","0.00386","60.14356","0.00329"
"23.40000","0.38821","603.85248","0.00388","60.38525","0.00330"
"23.50000","0.38991","605.88989","0.00390","60.58899","0.00332"
"23.60000","0.39145","607.75171","0.00391","60.77517","0.00333"
"23.70000","0.39330","610.28290","0.00393","61.02829","0.00335"
"23.80000","0.39474","611.78754","0.00395","61.17875","0.00336"
"23.90000","0.39662","614.39545","0.00397","61.43954","0.00337"
"24.00000","0.39812","616.03973","0.00398","61.60397","0.00338"
"24.10000","0.39987","618.29584","0.00400","61.82958","0.00340"
"24.20000","0.40162","620.49945","0.00402","62.04995","0.00341"
"24.30000","0.40310","622.24127","0.00403","62.22413","0.00343"
"24.40000","0.40506","624.89008","0.00405","62.48901","0.00344"
"24.50000","0.40640","626.13031","0.00406","62.61303","0.00345"
"24.60000","0.40830","628.70477","0.00408","62.87048","0.00346"
"24.70000","0.40980","630.44989","0.00410","63.04499","0.00348"
"24.80000","0.41157","632.70520","0.00412","63.27052","0.00349"
"24.90000","0.41332","634.85962","0.00413","63.48596","0.00350"
"25.00000","0.41471","636.38660","0.00415","63.63866","0.00351"
"25.10000","0.41672","639.04144","0.00417","63.90414","0.00353"
"25.20000","0.41810","640.53589","0.00418","64.05359","0.00354"
"25.30000","0.41991","642.67218","0.00420","64.26722","0.00356"
"25.40000","0.42144","644.43561","0.00421","64.44356","0.00357"
"25.50000","0.42315","646.55035","0.00423","64.65504","0.00358"
"25.60000","0.42504","648.95551","0.00425","64.89555","0.00360"
"25.70000","0.42639","650.29675","0.00426","65.02968","0.00361"
"25.80000","0.42832","652.94153","0.00428","65.29415","0.00362"
"25.90000","0.42969","654.17865","0.00430","65.41786","0.00363"
"26.00000","0.43154","656.57257","0.00432","65.65726","0.00365"
"26.10000","0.43322","658.57520","0.00433","65.85752","0.00366"
"26.20000","0.43480","660.40015","0.00435","66.04002","0.00367"
"26.30000","0.43669","662.76837","0.00437","66.27684","0.00369"
"26.40000","0.43804","664.17896","0.00438","66.41789","0.00370"
"26.50000","0.43997","666.61108","0.00440","66.66111","0.00371"
"26.60000","0.44141","668.06848","0.00441","66.80685","0.00372"
"26.70000","0.44316","670.30194","0.00443","67.03020","0.00374"
"26.80000","0.44488","672.27203","0.00445","67.22720","0.00375"
"26.90000","0.44647","674.06519","0.00446","67.40652","0.00376"
"27.00000","0.44836","676.36890","0.00448","67.63689","0.00378"
"27.10000","0.44978","677.77087","0.00450","67.77708","0.00379"
"27.20000","0.45158","679.92462","0.00452","67.99246","0.00380"
"27.30000","0.45311","681.72638","0.00453","68.17264","0.00381"
"27.40000","0.45479","683.61365","0.00455","68.36137","0.00383"
"27.50000","0.45664","685.82855","0.00457","68.58286","0.00384"
"27.60000","0.45815","687.33234","0.00458","68.73323","0.00385"
"27.70000","0.45998","689.78064","0.00460","68.97807","0.00387"
"27.80000","0.46150","691.40356","0.00462","69.14036","0.00388"
"27.90000","0.46323","693.30658","0.00463","69.33066","0.00389"
"28.00000","0.46486","695.24921","0.00465","69.52492","0.00390"
"28.10000","0.46642","696.93311","0.00466","69.69331","0.00392"
"28.20000","0.46826","699.05750","0.00468","69.90575","0.00393"
"28.30000","0.46980","700.67987","0.00470","70.06799","0.00394"
"28.40000","0.47168","703.01617","0.00472","70.30162","0.00396"
"28.50000","0.47326","704.64996","0.00473","70.46500","0.00397"
"28.60000","0.47481","706.30231","0.00475","70.63023","0.00398"
"28.70000","0.47654","708.28186","0.00477","70.82819","0.00399"
"28.80000","0.47809","710.02081","0.00478","71.00208","0.00400"
"28.90000","0.47996","712.23346","0.00480","71.22334","0.00402"
"29.00000","0.48147","713.72852","0.00481","71.37285","0.00403"
"29.10000","0.48320","715.61633","0.00483","71.56163","0.00404"
"29.20000","0.48492","717.75128","0.00485","71.77513","0.00406"
"29.30000","0.48645","719.27246","0.00486","71.92725","0.00407"
"29.40000","0.48822","721.19769","0.00488","72.11977","0.00408"
"29.50000","0.48970","722.73199","0.00490","72.27320","0.00409"
"29.60000","0.49156","724.83759","0.00492","72.48376","0.00411"
"29.70000","0.49329","726.84882","0.00493","72.68488","0.00412"
"29.80000","0.49484","728.50983","0.00495","72.85098","0.00413"
"29.90000","0.49662","730.57416","0.00497","73.05742","0.00414"
"30.00000","0.49806","731.73938","0.00498","73.17393","0.00416"
"30.10000","0.49992","734.12445","0.00500","73.41245","0.00417"
"30.20000","0.50142","735.48541","0.00501","73.54854","0.00418"
"30.30000","0.50321","737.53021","0.00503","73.75302","0.00419"
"30.40000","0.50497","739.56195","0.00505","73.95619","0.00421"
"30.50000","0.50640","740.84167","0.00506","74.08417","0.00422"
"30.60000","0.50839","743.24219","0.00508","74.32422","0.00423"
"30.70000","0.50971","744.28516","0.00510","74.42851","0.00424"
"30.80000","0.51158","746.41028","0.00512","74.64103","0.00426"
"30.90000","0.51307","747.96167","0.00513","74.79617","0.00427"
"31.00000","0.51484","749.97961","0.00515","74.99796","0.00428"
"31.10000","0.51673","752.13690","0.00517","75.21369","0.00430"
"31.20000","0.51806","753.00714","0.00518","75.30071","0.00431"
"31.30000","0.52005","755.53430","0.00520","75.55343","0.00432"
"31.40000","0.52137","756.64941","0.00521","75.66494","0.00433"
"31.50000","0.52321","758.65875","0.00523","75.86588","0.00435"
"31.60000","0.52485","760.29010","0.00525","76.02901","0.00436"
"31.70000","0.52650","762.07147","0.00527","76.20715","0.00437"
"31.80000","0.52839","764.38934","0.00528","76.43893","0.00439"
"31.90000","0.52967","765.21210","0.00530","76.52121","0.00440"
"32.00000","0.53178","767.92499","0.00532","76.79250","0.00441"
"32.10000","0.53309","768.86139","0.00533","76.88614","0.00442"
"32.20000","0.53482","770.74359","0.00535","77.07436","0.00443"
"32.30000","0.53651","772.55780","0.00537","77.25578","0.00445"
"32.40000","0.53817","774.17609","0.00538","77.41761","0.00446"
"32.50000","0.54008","776.52808","0.00540","77.65281","0.00447"
"32.60000","0.54136","777.41534","0.00541","77.74153","0.00448"
"32.70000","0.54335","779.76825","0.00543","77.97682","0.00450"
"32.80000","0.54475","780.87610","0.00545","78.08761","0.00451"
"32.90000","0.54649","782.70642","0.00546","78.27065","0.00452"
"33.00000","0.54820","784.47357","0.00548","78.44736","0.00453"
"33.10000","0.54980","785.85083","0.00550","78.58508","0.00454"
"33.20000","0.55170","788.10834","0.00552","78.81084","0.00456"
"33.30000","0.55311","789.29358","0.00553","78.92936","0.00457"
"33.40000","0.55500","791.40497","0.00555","79.14050","0.00458"
"33.50000","0.55646","792.66577","0.00556","79.26658","0.00459"
"33.60000","0.55809","794.16864","0.00558","79.41686","0.00460"
"33.70000","0.55985","796.06830","0.00560","79.60683","0.00462"
"33.80000","0.56146","797.61206","0.00561","79.76121","0.00463"
"33.90000","0.56331","799.59241","0.00563","79.95924","0.00464"
"34.00000","0.56482","800.83527","0.00565","80.08353","0.00465"
"34.10000","0.56653","802.64771","0.00567","80.26477","0.00466"
"34.20000","0.56820","804.20721","0.00568","80.42072","0.00468"
"34.30000","0.56975","805.65625","0.00570","80.56563","0.00469"
"34.40000","0.57154","807.55865","0.00572","80.75587","0.00470"
"34.50000","0.57313","809.00171","0.00573","80.90017","0.00471"
"34.60000","0.57490","810.93005","0.00575","81.09300","0.00472"
"34.70000","0.57660","812.48059","0.00577","81.24806","0.00474"
"34.80000","0.57814","813.65759","0.00578","81.36576","0.00475"
"34.90000","0.57992","815.55621","0.00580","81.55562","0.00476"
"35.00000","0.58139","816.63483","0.00581","81.66348","0.00477"
"35.10000","0.58324","818.77203","0.00583","81.87720","0.00478"
"35.20000","0.58490","820.33722","0.00585","82.03372","0.00480"
"35.30000","0.58653","821.80609","0.00587","82.18061","0.00481"
"35.40000","0.58835","823.65057","0.00588","82.36506","0.00482"
"35.50000","0.58972","824.66888","0.00590","82.46689","0.00483"
"35.60000","0.59168","826.80609","0.00592","82.68061","0.00484"
"35.70000","0.59308","828.01550","0.00593","82.80155","0.00485"
"35.80000","0.59487","829.73193","0.00595","82.97319","0.00487"
"35.90000","0.59659","831.44952","0.00597","83.14495","0.00488"
"36.00000","0.59816","832.62769","0.00598","83.26277","0.00489"
"36.10000","0.60010","834.71558","0.00600","83.47156","0.00490"
"36.20000","0.60136","835.50793","0.00601","83.55080","0.00491"
"36.30000","0.60329","837.51538","0.00603","83.75154","0.00493"
"36.40000","0.60473","838.72705","0.00605","83.87270","0.00494"
"36.50000","0.60655","840.66132","0.00607","84.06613","0.00495"
"36.60000","0.60827","842.08899","0.00608","84.20890","0.00496"
"36.70000","0.60974","843.21088","0.00610","84.32109","0.00497"
"36.80000","0.61171","845.35870","0.00612","84.53587","0.00499"
"36.90000","0.61304","846.27716","0.00613","84.62772","0.00499"
"37.00000","0.61498","848.28699","0.00615","84.82870","0.00501"
"37.10000","0.61643","849.44757","0.00616","84.94476","0.00502"
"37.20000","0.61814","850.94489","0.00618","85.09449","0.00503"
"37.30000","0.61993","852.74371","0.00620","85.27437","0.00504"
"37.40000","0.62139","853.89288","0.00621","85.38929","0.00505"
"37.50000","0.62342","856.06409","0.00623","85.60641","0.00507"
"37.60000","0.62469","856.91864","0.00625","85.69186","0.00507"
"37.70000","0.62657","858.75702","0.00627","85.87570","0.00509"
"37.80000","0.62816","860.02844","0.00628","86.00285","0.00510"
"37.90000","0.62982","861.41339","0.00630","86.14134","0.00511"
"38.00000","0.63166","863.31348","0.00632","86.33134","0.00512"
"38.10000","0.63307","864.30029","0.00633","86.43003","0.00513"
"38.20000","0.63500","866.32947","0.00635","86.63295","0.00514"
"38.30000","0.63642","867.19598","0.00636","86.71960","0.00515"
"38.40000","0.63820","869.07355","0.00638","86.90736","0.00517"
"38.50000","0.63987","870.47278","0.00640","87.04728","0.00518"
"38.60000","0.64148","871.87457","0.00641","87.18745","0.00519"
"38.70000","0.64335","873.69269","0.00643","87.36927","0.00520"
"38.80000","0.64478","874.60468","0.00645","87.46046","0.00521"
"38.90000","0.64664","876.53259","0.00647","87.65326","0.00522"
"39.00000","0.64812","877.63202","0.00648","87.76320","0.00523"
"39.10000","0.64981","879.13202","0.00650","87.91320","0.00525"
"39.20000","0.65161","880.80957","0.00652","88.08096","0.00526"
"39.30000","0.65317","881.96283","0.00653","88.19628","0.00527"
"39.40000","0.65498","883.70221","0.00655","88.37022","0.00528"
"39.50000","0.65643","884.71265","0.00656","88.47127","0.00529"
"39.60000","0.65828","886.46564","0.00658","88.64656","0.00530"
"39.70000","0.65986","887.68549","0.00660","88.76855","0.00531"
"39.80000","0.66143","888.88434","0.00661","88.88844","0.00532"
"39.90000","0.66321","890.70306","0.00663","89.07030","0.00534"
"40.00000","0.66479","891.99878","0.00665","89.19987","0.00535"
"40.10000","0.66663","893.68823","0.00667","89.36882","0.00536"
"40.20000","0.66816","894.88507","0.00668","89.48851","0.00537"
"40.30000","0.66983","896.33539","0.00670","89.63354","0.00538"
"40.40000","0.67152","897.80127","0.00672","89.78013","0.00539"
"40.50000","0.67308","898.86047","0.00673","89.88605","0.00540"
"40.60000","0.67497","900.68683","0.00675","90.06868","0.00541"
"40.70000","0.67653","901.98505","0.00677","90.19850","0.00542"
"40.80000","0.67823","903.47070","0.00678","90.34707","0.00544"
"40.90000","0.67985","904.62744","0.00680","90.46275","0.00545"
"41.00000","0.68145","905.95123","0.00681","90.59512","0.00546"
"41.10000","0.68322","907.46869","0.00683","90.74687","0.00547"
"41.20000","0.68474","908.55359","0.00685","90.85536","0.00548"
"41.30000","0.68656","910.16351","0.00687","91.01635","0.00549"
"41.40000","0.68820","911.43634","0.00688","91.14363","0.00550"
"41.50000","0.68986","912.76886","0.00690","91.27689","0.00551"
"41.60000","0.69159","914.34558","0.00692","91.43456","0.00552"
"41.70000","0.69309","915.41754","0.00693","91.54176","0.00553"
"41.80000","0.69491","917.11078","0.00695","91.71107","0.00554"
"41.90000","0.69643","918.16980","0.00696","91.81698","0.00555"
"42.00000","0.69827","919.80164","0.00698","91.98016","0.00557"
"42.10000","0.69989","921.07776","0.00700","92.10777","0.00558"
"42.20000","0.70149","922.39185","0.00701","92.23918","0.00559"
"42.30000","0.70332","924.06879","0.00703","92.40688","0.00560"
"42.40000","0.70474","924.81390","0.00705","92.48139","0.00561"
"42.50000","0.70661","926.59760","0.00707","92.65976","0.00562"
"42.60000","0.70809","927.65643","0.00708","92.76564","0.00563"
"42.70000","0.70988","929.25482","0.00710","92.92548","0.00564"
"42.80000","0.71167","930.78113","0.00712","93.07811","0.00565"
"42.90000","0.71315","931.69867","0.00713","93.16987","0.00566"
"43.00000","0.71503","933.53687","0.00715","93.35368","0.00568"
"43.10000","0.71636","934.14270","0.00716","93.41427","0.00568"
"43.20000","0.71829","935.95099","0.00718","93.59510","0.00570"
"43.30000","0.71982","937.07629","0.00720","93.70763","0.00571"
"43.40000","0.72152","938.55206","0.00722","93.85521","0.00572"
"43.50000","0.72332","940.13617","0.00723","94.01362","0.00573"
"43.60000","0.72475","940.88837","0.00725","94.08884","0.00574"
"43.70000","0.72672","942.81689","0.00727","94.28169","0.00575"
"43.80000","0.72803","943.51929","0.00728","94.35193","0.00576"
"43.90000","0.72988","945.16992","0.00730","94.51699","0.00577"
"44.00000","0.73146","946.23090","0.00731","94.62309","0.00578"
"44.10000","0.73318","947.60431","0.00733","94.76043","0.00579"
"44.20000","0.73505","949.31042","0.00735","94.93105","0.00580"
"44.30000","0.73638","949.94836","0.00736","94.99483","0.00581"
"44.40000","0.73835","951.78821","0.00738","95.17882","0.00582"
"44.50000","0.73971","952.57343","0.00740","95.25734","0.00583"
"44.60000","0.74148","953.96722","0.00741","95.39672","0.00584"
"44.70000","0.74321","955.45752","0.00743","95.54575","0.00585"
"44.80000","0.74480","956.32861","0.00745","95.63286","0.00586"
"44.90000","0.74668","958.16217","0.00747","95.81622","0.00588"
"45.00000","0.74805","958.85815","0.00748","95.88582","0.00588"
"45.10000","0.74999","960.70154","0.00750","96.07015","0.00590"
"45.20000","0.75143","961.46521","0.00751","96.14652","0.00590"
"45.30000","0.75308","962.74976","0.00753","96.27498","0.00592"
"45.40000","0.75487","964.23114","0.00755","96.42311","0.00593"
"45.50000","0.75650","965.43610","0.00756","96.54361","0.00594"
"45.60000","0.75835","966.92145","0.00758","96.69215","0.00595"
"45.70000","0.75979","967.79077","0.00760","96.77908","0.00596"
"45.80000","0.76160","969.23560","0.00762","96.92356","0.00597"
"45.90000","0.76312","970.35236","0.00763","97.03523","0.00598"
"46.00000","0.76477","971.50476","0.00765","97.15047","0.00599"
"46.10000","0.76661","973.13513","0.00767","97.31351","0.00600"
"46.20000","0.76818","974.21405","0.00768","97.42140","0.00601"
"46.30000","0.76994","975.70111","0.00770","97.57011","0.00602"
"46.40000","0.77152","976.67212","0.00772","97.66721","0.00603"
"46.50000","0.77328","978.07404","0.00773","97.80740","0.00604"
"46.60000","0.77487","979.19122","0.00775","97.91912","0.00605"
"46.70000","0.77639","980.23157","0.00776","98.02316","0.00606"
"46.80000","0.77826","981.69812","0.00778","98.16982","0.00607"
"46.90000","0.77990","982.98627","0.00780","98.29863","0.00608"
"47.00000","0.78156","984.13043","0.00782","98.41304","0.00609"
"47.10000","0.78320","985.25146","0.00783","98.52515","0.00610"
"47.20000","0.78482","986.30804","0.00785","98.63081","0.00611"
"47.30000","0.78660","987.82501","0.00787","98.78250","0.00612"
"47.40000","0.78807","988.67987","0.00788","98.86799","0.00613"
"47.50000","0.78988","990.24500","0.00790","99.02450","0.00614"
"47.60000","0.79155","991.33783","0.00792","99.13378","0.00615"
"47.70000","0.79317","992.45245","0.00793","99.24525","0.00616"
"47.80000","0.79499","994.03558","0.00795","99.40356","0.00617"
"47.90000","0.79646","994.75970","0.00796","99.47597","0.00618"
"48.00000","0.79827","996.32458","0.00798","99.63246","0.00619"
"48.10000","0.79970","997.02466","0.00800","99.70247","0.00620"
"48.20000","0.80151","998.51080","0.00802","99.85108","0.00621"
"48.30000","0.80324","999.84741","0.00803","99.98474","0.00622"
"48.40000","0.80482","1000.93018","0.00805","100.09302","0.00623"
"48.50000","0.80669","1002.50244","0.00807","100.25024","0.00625"
"48.60000","0.80805","1003.02081","0.00808","100.30208","0.00625"
"48.70000","0.80994","1004.54089","0.00810","100.45409","0.00627"
"48.80000","0.81143","1005.42444","0.00811","100.54244","0.00627"
"48.90000","0.81315","1006.67651","0.00813","100.66765","0.00628"
"49.00000","0.81496","1008.01746","0.00815","100.80174","0.00630"
"49.10000","0.81646","1009.01190","0.00816","100.90119","0.00630"
"49.20000","0.81842","1010.77191","0.00818","101.07719","0.00632"
"49.30000","0.81973","1011.17480","0.00820","101.11748","0.00632"
"49.40000","0.82158","1012.77100","0.00822","101.27710","0.00633"
"49.50000","0.82311","1013.56415","0.00823","101.35641","0.00634"
"49.60000","0.82484","1014.85699","0.00825","101.48570","0.00635"
"49.70000","0.82669","1016.28375","0.00827","101.62837","0.00637"
"49.80000","0.82811","1017.05219","0.00828","101.70522","0.00637"
"49.90000","0.83008","1018.82025","0.00830","101.88203","0.00639"
"50.00000","0.83140","1019.31494","0.00831","101.93150","0.00639"
"50.10000","0.83329","1020.82202","0.00833","102.08220","0.00640"
"50.20000","0.83482","1021.80621","0.00835","102.18062","0.00641"
"50.30000","0.83644","1023.02472","0.00836","102.30247","0.00642"
"50.40000","0.83836","1024.57129","0.00838","102.45713","0.00644"
"50.50000","0.83977","1025.21362","0.00840","102.52136","0.00644"
"50.60000","0.84173","1026.94495","0.00842","102.69450","0.00646"
"50.70000","0.84304","1027.49756","0.00843","102.74976","0.00646"
"50.80000","0.84485","1028.76270","0.00845","102.87627","0.00647"
"50.90000","0.84654","1030.04492","0.00847","103.00449","0.00648"
"51.00000","0.84811","1031.01428","0.00848","103.10143","0.00649"
"51.10000","0.85000","1032.51648","0.00850","103.25165","0.00651"
"51.20000","0.85141","1033.16357","0.00851","103.31636","0.00651"
"51.30000","0.85333","1034.94006","0.00853","103.49400","0.00653"
"51.40000","0.85478","1035.58521","0.00855","103.55852","0.00653"
"51.50000","0.85648","1036.87305","0.00856","103.68730","0.00654"
"51.60000","0.85823","1038.10181","0.00858","103.81018","0.00655"
"51.70000","0.85977","1039.07703","0.00860","103.90770","0.00656"
"51.80000","0.86162","1040.44617","0.00862","104.04462","0.00658"
"51.90000","0.86315","1041.45215","0.00863","104.14522","0.00658"
"52.00000","0.86493","1042.68848","0.00865","104.26884","0.00659"
"52.10000","0.86648","1043.61877","0.00866","104.36188","0.00660"
"52.20000","0.86810","1044.71094","0.00868","104.47109","0.00661"
"52.30000","0.86992","1046.08093","0.00870","104.60809","0.00662"
"52.40000","0.87149","1047.02344","0.00871","104.70235","0.00663"
"52.50000","0.87323","1048.23157","0.00873","104.82316","0.00664"
"52.60000","0.87484","1049.23315","0.00875","104.92332","0.00665"
"52.70000","0.87650","1050.33008","0.00877","105.03300","0.00666"
"52.80000","0.87823","1051.63843","0.00878","105.16384","0.00667"
"52.90000","0.87977","1052.62439","0.00880","105.26244","0.00668"
"53.00000","0.88156","1053.79626","0.00882","105.37962","0.00669"
"53.10000","0.88316","1054.84607","0.00883","105.48460","0.00670"
"53.20000","0.88489","1056.02710","0.00885","105.60271","0.00671"
"53.30000","0.88664","1057.30261","0.00887","105.73026","0.00672"
"53.40000","0.88813","1058.03601","0.00888","105.80360","0.00673"
"53.50000","0.88994","1059.46936","0.00890","105.94694","0.00674"
"53.60000","0.89141","1060.25269","0.00891","106.02527","0.00675"
"53.70000","0.89328","1061.70825","0.00893","106.17082","0.00676"
"53.80000","0.89492","1062.88269","0.00895","106.28827","0.00677"
"53.90000","0.89647","1063.69446","0.00896","106.36945","0.00678"
"54.00000","0.89831","1065.17041","0.00898","106.51704","0.00679"
"54.10000","0.89978","1065.73901","0.00900","106.57390","0.00680"
"54.20000","0.90165","1067.34021","0.00902","106.73402","0.00681"
"54.30000","0.90305","1067.93079","0.00903","106.79308","0.00682"
"54.40000","0.90490","1069.28796","0.00905","106.92879","0.00683"
"54.50000","0.90660","1070.50757","0.00907","107.05076","0.00684"
"54.60000","0.90811","1071.35840","0.00908","107.13584","0.00684"
"54.70000","0.91000","1072.81604","0.00910","107.28160","0.00686"
"54.80000","0.91136","1073.36047","0.00911","107.33604","0.00686"
"54.90000","0.91331","1075.00891","0.00913","107.50089","0.00687"
"55.00000","0.91478","1075.79041","0.00915","107.57904","0.00688"
"55.10000","0.91655","1077.01172","0.00917","107.70117","0.00689"
"55.20000","0.91833","1078.25647","0.00918","107.82565","0.00690"
"55.30000","0.91973","1078.74634","0.00920","107.87463","0.00691"
"55.40000","0.92168","1080.44165","0.00922","108.04417","0.00692"
"55.50000","0.92303","1080.84851","0.00923","108.08485","0.00693"
"55.60000","0.92492","1082.41016","0.00925","108.24101","0.00694"
"55.70000","0.92647","1083.25818","0.00926","108.32582","0.00695"
"55.80000","0.92816","1084.37439","0.00928","108.43744","0.00696"
"55.90000","0.93000","1085.71216","0.00930","108.57121","0.00697"
"56.00000","0.93141","1086.29797","0.00931","108.62980","0.00698"
"56.10000","0.93331","1087.83240","0.00933","108.78324","0.00699"
"56.20000","0.93469","1088.41028","0.00935","108.84103","0.00699"
"56.30000","0.93653","1089.86462","0.00937","108.98647","0.00700"
"56.40000","0.93820","1090.85706","0.00938","109.08571","0.00701"
"56.50000","0.93982","1091.88428","0.00940","109.18843","0.00702"
"56.60000","0.94167","1093.24683","0.00942","109.32468","0.00703"
"56.70000","0.94311","1093.92017","0.00943","109.39201","0.00704"
"56.80000","0.94501","1095.35376","0.00945","109.53538","0.00705"
"56.90000","0.94644","1096.02832","0.00946","109.60283","0.00706"
"57.00000","0.94821","1097.24121","0.00948","109.72412","0.00707"
"57.10000","0.94988","1098.17749","0.00950","109.81775","0.00708"
"57.20000","0.95145","1099.15369","0.00951","109.91537","0.00709"
"57.30000","0.95345","1100.93872","0.00953","110.09387","0.00710"
"57.40000","0.95481","1101.21057","0.00955","110.12106","0.00710"
"57.50000","0.95662","1102.71167","0.00957","110.27116","0.00711"
"57.60000","0.95807","1103.26843","0.00958","110.32684","0.00712"
"57.70000","0.95982","1104.46960","0.00960","110.44696","0.00713"
"57.80000","0.96161","1105.65869","0.00962","110.56587","0.00714"
"57.90000","0.96311","1106.32166","0.00963","110.63216","0.00715"
"58.00000","0.96500","1107.79810","0.00965","110.77981","0.00716"
"58.10000","0.96647","1108.57520","0.00966","110.85752","0.00717"
"58.20000","0.96826","1109.84521","0.00968","110.98452","0.00718"
"58.30000","0.96977","1110.50452","0.00970","111.05045","0.00718"
"58.40000","0.97140","1111.52490","0.00971","111.15249","0.00719"
"58.50000","0.97323","1112.80627","0.00973","111.28062","0.00720"
"58.60000","0.97486","1113.72156","0.00975","111.37215","0.00721"
"58.70000","0.97663","1114.95251","0.00977","111.49525","0.00722"
"58.80000","0.97815","1115.60071","0.00978","111.56007","0.00723"
"58.90000","0.97986","1116.81360","0.00980","111.68136","0.00724"
"59.00000","0.98152","1117.85999","0.00982","111.78600","0.00725"
"59.10000","0.98307","1118.62476","0.00983","111.86247","0.00726"
"59.20000","0.98491","1119.94360","0.00985","111.99436","0.00727"
"59.30000","0.98651","1120.83667","0.00987","112.08366","0.00727"
"59.40000","0.98821","1121.92444","0.00988","112.19244","0.00728"
"59.50000","0.98990","1122.92163","0.00990","112.29216","0.00729"
"59.60000","0.99147","1123.70032","0.00991","112.37003","0.00730"
"59.70000","0.99324","1124.88037","0.00993","112.48804","0.00731"
"59.80000","0.99470","1125.49341","0.00995","112.54934","0.00732"
"59.90000","0.99656","1126.87000","0.00997","112.68700","0.00733"
"60.00000","0.99829","1127.88110","0.00998","112.78811","0.00734"
"60.10000","0.99983","1128.59839","0.01000","112.85984","0.00735"
"60.20000","1.00164","1129.91357","0.01002","112.99136","0.00736"
"60.30000","1.00310","1130.51025","0.01003","113.05103","0.00736"
"60.40000","1.00491","1131.77722","0.01005","113.17772","0.00737"
"60.50000","1.00644","1132.56848","0.01006","113.25685","0.00738"
"60.60000","1.00822","1133.78674","0.01008","113.37868","0.00739"
"60.70000","1.00998","1134.92883","0.01010","113.49288","0.00740"
"60.80000","1.01139","1135.49438","0.01011","113.54944","0.00741"
"60.90000","1.01342","1137.20593","0.01013","113.72060","0.00742"
"61.00000","1.01479","1137.59766","0.01015","113.75977","0.00743"
"61.10000","1.01656","1138.71680","0.01017","113.87168","0.00743"
"61.20000","1.01807","1139.35022","0.01018","113.93502","0.00744"
"61.30000","1.01986","1140.62048","0.01020","114.06205","0.00745"
"61.40000","1.02169","1141.97961","0.01022","114.19796","0.00746"
"61.50000","1.02305","1142.33472","0.01023","114.23347","0.00747"
"61.60000","1.02505","1143.83496","0.01025","114.38350","0.00748"
"61.70000","1.02640","1144.24658","0.01026","114.42466","0.00749"
"61.80000","1.02826","1145.54553","0.01028","114.55455","0.00749"
"61.90000","1.02978","1146.24133","0.01030","114.62413","0.00750"
"62.00000","1.03146","1147.16882","0.01031","114.71688","0.00751"
"62.10000","1.03335","1148.71619","0.01033","114.87162","0.00752"
"62.20000","1.03473","1149.02283","0.01035","114.90228","0.00753"
"62.30000","1.03678","1150.85706","0.01037","115.08571","0.00754"
"62.40000","1.03808","1151.11340","0.01038","115.11134","0.00754"
"62.50000","1.03986","1152.33936","0.01040","115.23393","0.00755"
"62.60000","1.04146","1153.06396","0.01041","115.30640","0.00756"
"62.70000","1.04312","1154.08557","0.01043","115.40855","0.00757"
"62.80000","1.04502","1155.55359","0.01045","115.55536","0.00758"
"62.90000","1.04642","1156.10620","0.01046","115.61062","0.00759"
"63.00000","1.04831","1157.42004","0.01048","115.74200","0.00760"
"63.10000","1.04975","1157.99292","0.01050","115.79929","0.00761"
"63.20000","1.05150","1159.29504","0.01051","115.92950","0.00761"
"63.30000","1.05319","1160.37292","0.01053","116.03729","0.00762"
"63.40000","1.05476","1161.08875","0.01055","116.10887","0.00763"
"63.50000","1.05667","1162.64441","0.01057","116.26444","0.00764"
"63.60000","1.05813","1163.24475","0.01058","116.32448","0.00765"
"63.70000","1.05997","1164.73865","0.01060","116.47386","0.00766"
"63.80000","1.06147","1165.28455","0.01061","116.52846","0.00767"
"63.90000","1.06312","1166.36658","0.01063","116.63666","0.00768"
"64.00000","1.06488","1167.58044","0.01065","116.75804","0.00768"
"64.10000","1.06648","1168.43970","0.01066","116.84397","0.00769"
"64.20000","1.06834","1169.81165","0.01068","116.98116","0.00770"
"64.30000","1.06985","1170.63159","0.01070","117.06316","0.00771"
"64.40000","1.07153","1171.59131","0.01072","117.15913","0.00772"
"64.50000","1.07322","1172.79211","0.01073","117.27921","0.00773"
"64.60000","1.07481","1173.60779","0.01075","117.36078","0.00774"
"64.70000","1.07657","1174.86963","0.01077","117.48696","0.00774"
"64.80000","1.07814","1175.54688","0.01078","117.55469","0.00775"
"64.90000","1.07993","1176.89319","0.01080","117.68932","0.00776"
"65.00000","1.08162","1177.93115","0.01082","117.79311","0.00777"
"65.10000","1.08316","1178.64819","0.01083","117.86482","0.00778"
"65.20000","1.08487","1179.82288","0.01085","117.98228","0.00779"
"65.30000","1.08642","1180.61682","0.01086","118.06168","0.00779"
"65.40000","1.08825","1181.87891","0.01088","118.18789","0.00780"
"65.50000","1.08983","1182.77441","0.01090","118.27744","0.00781"
"65.60000","1.09152","1183.90430","0.01092","118.39043","0.00782"
"65.70000","1.09324","1185.08801","0.01093","118.50880","0.00783"
"65.80000","1.09480","1185.80090","0.01095","118.58009","0.00784"
"65.90000","1.09662","1187.04993","0.01097","118.70499","0.00785"
"66.00000","1.09809","1187.87732","0.01098","118.78773","0.00785"
"66.10000","1.09988","1189.07483","0.01100","118.90749","0.00786"
"66.20000","1.10150","1190.09033","0.01102","119.00903","0.00787"
"66.30000","1.10314","1191.00562","0.01103","119.10056","0.00788"
"66.40000","1.10501","1192.57019","0.01105","119.25702","0.00789"
"66.50000","1.10641","1193.04028","0.01106","119.30403","0.00790"
"66.60000","1.10827","1194.62134","0.01108","119.46214","0.00791"
"66.70000","1.10973","1195.18176","0.01110","119.51817","0.00791"
"66.80000","1.11154","1196.39258","0.01112","119.63926","0.00792"
"66.90000","1.11328","1197.84473","0.01113","119.78447","0.00793"
"67.00000","1.11477","1198.48499","0.01115","119.84850","0.00794"
"67.10000","1.11667","1200.06287","0.01117","120.00629","0.00795"
"67.20000","1.11806","1200.45227","0.01118","120.04523","0.00796"
"67.30000","1.11996","1202.07153","0.01120","120.20715","0.00797"
"67.40000","1.12146","1202.69873","0.01121","120.26987","0.00798"
"67.50000","1.12320","1203.80786","0.01123","120.38078","0.00798"
"67.60000","1.12500","1205.16870","0.01125","120.51687","0.00799"
"67.70000","1.12643","1205.60901","0.01126","120.56090","0.00800"
"67.80000","1.12839","1207.26624","0.01128","120.72662","0.00801"
"67.90000","1.12975","1207.73743","0.01130","120.77374","0.00802"
"68.00000","1.13158","1209.06555","0.01132","120.90656","0.00803"
"68.10000","1.13317","1209.87109","0.01133","120.98711","0.00803"
"68.20000","1.13488","1210.91394","0.01135","121.09139","0.00804"
"68.30000","1.13666","1212.10205","0.01137","121.21021","0.00805"
"68.40000","1.13807","1212.64844","0.01138","121.26485","0.00806"
"68.50000","1.14003","1214.23511","0.01140","121.42351","0.00807"
"68.60000","1.14143","1214.49011","0.01141","121.44901","0.00807"
"68.70000","1.14321","1215.60803","0.01143","121.56081","0.00808"
"68.80000","1.14481","1216.49390","0.01145","121.64939","0.00809"
"68.90000","1.14649","1217.46265","0.01146","121.74626","0.00810"
"69.00000","1.14836","1218.86365","0.01148","121.88637","0.00811"
"69.10000","1.14976","1219.18359","0.01150","121.91836","0.00811"
"69.20000","1.15162","1220.58313","0.01152","122.05831","0.00812"
"69.30000","1.15306","1221.15393","0.01153","122.11539","0.00813"
"69.40000","1.15483","1222.25476","0.01155","122.22548","0.00814"
"69.50000","1.15659","1223.46643","0.01157","122.34664","0.00814"
"69.60000","1.15816","1223.83643","0.01158","122.38364","0.00815"
"69.70000","1.16000","1224.94116","0.01160","122.49412","0.00816"
"69.80000","1.16141","1225.22070","0.01161","122.52207","0.00816"
"69.90000","1.16325","1226.31982","0.01163","122.63198","0.00817"
"70.00000","1.16479","1226.73376","0.01165","122.67338","0.00817"
"70.10000","1.16648","1227.35229","0.01166","122.73523","0.00818"
"70.20000","1.16825","1228.05872","0.01168","122.80587","0.00819"
"70.30000","1.16979","1228.14355","0.01170","122.81435","0.00819"
"70.40000","1.17163","1214.50146","0.01172","121.45015","0.00811"
"70.47400","1.17267","1081.97668","0.01173","108.19767","0.00719"
"70.49100","1.17300","950.23773","0.01173","95.02377","0.00627"
"70.51800","1.17362","824.51154","0.01174","82.45116","0.00536"
"70.61800","1.17512","727.48218","0.01175","72.74821","0.00466"
"70.71800","1.17688","692.20569","0.01177","69.22057","0.00440"
"70.81800","1.17840","676.90887","0.01178","67.69089","0.00428"
"70.91800","1.18025","659.93701","0.01180","65.99370","0.00415"
"71.01800","1.18182","655.26849","0.01182","65.52685","0.00410"
"71.11800","1.18352","652.89746","0.01184","65.28975","0.00407"
"71.21800","1.18527","651.22186","0.01185","65.12218","0.00404"
"71.31800","1.18677","649.61792","0.01187","64.96179","0.00402"
"71.41800","1.18860","649.15747","0.01189","64.91575","0.00400"
"71.51800","1.19001","647.61133","0.01190","64.76113","0.00398"
"71.61800","1.19187","647.23663","0.01192","64.72366","0.00397"
"71.71800","1.19354","645.71344","0.01194","64.57134","0.00395"
"71.81800","1.19518","631.41956","0.01195","63.14196","0.00387"
"71.91800","1.19696","625.13068","0.01197","62.51307","0.00382"
"72.01800","1.19833","622.03625","0.01198","62.20362","0.00379"
"72.11800","1.20025","621.18976","0.01200","62.11898","0.00377"
"72.21800","1.20176","619.26019","0.01202","61.92602","0.00375"
"72.31800","1.20352","618.25525","0.01204","61.82552","0.00373"
"72.41800","1.20524","617.59375","0.01205","61.75938","0.00372"
"72.51800","1.20674","616.73254","0.01207","61.67326","0.00370"
"72.61800","1.20866","617.03094","0.01209","61.70309","0.00370"
"72.71800","1.21002","616.31812","0.01210","61.63181","0.00368"
"72.81800","1.21188","616.07617","0.01212","61.60762","0.00367"
"72.91800","1.21338","615.22284","0.01213","61.52229","0.00366"
"73.01800","1.21515","615.39209","0.01215","61.53921","0.00365"
"73.11800","1.21702","615.33118","0.01217","61.53312","0.00364"
"73.21800","1.21840","610.28613","0.01218","61.02861","0.00361"
"73.31800","1.22033","602.50861","0.01220","60.25086","0.00356"
"73.41800","1.22168","600.59686","0.01222","60.05968","0.00354"
"73.51800","1.22350","600.19159","0.01224","60.01916","0.00353"
"73.61800","1.22511","599.55707","0.01225","59.95571","0.00352"
"73.71800","1.22678","599.12726","0.01227","59.91273","0.00351"
"73.81800","1.22868","599.47028","0.01229","59.94703","0.00350"
"73.91800","1.23000","598.74597","0.01230","59.87460","0.00349"
"74.01800","1.23200","599.51251","0.01232","59.95125","0.00349"
"74.11800","1.23335","599.10236","0.01233","59.91024","0.00348"
"74.21800","1.23512","599.44385","0.01235","59.94439","0.00346"
"74.31800","1.23680","599.79633","0.01237","59.97963","0.00347"
"74.41800","1.23845","599.99823","0.01238","59.99982","0.00345"
"74.51800","1.24038","600.76025","0.01240","60.07603","0.00344"
"74.61800","1.24169","600.45740","0.01242","60.04574","0.00345"
"74.71800","1.24363","601.36499","0.01244","60.13650","0.00346"
"74.81800","1.24504","601.16901","0.01245","60.11690","0.00345"
"74.91800","1.24679","601.70068","0.01247","60.17007","0.00343"
"75.01800","1.24857","602.35114","0.01249","60.23512","0.00344"
"75.11800","1.25010","602.37903","0.01250","60.23790","0.00343"
"75.21800","1.25197","602.86578","0.01252","60.28658","0.00342"
"75.31800","1.25340","602.59576","0.01253","60.25957","0.00343"
"75.41800","1.25531","603.41193","0.01255","60.34119","0.00342"
"75.51800","1.25681","603.33276","0.01257","60.33327","0.00342"
"75.61800","1.25835","603.04480","0.01258","60.30448","0.00341"
"75.71800","1.26019","603.71387","0.01260","60.37139","0.00340"
"75.81800","1.26180","603.98761","0.01262","60.39876","0.00340"
"75.91800","1.26360","604.61780","0.01264","60.46178","0.00341"
"76.01800","1.26510","604.14069","0.01265","60.41407","0.00339"
"76.11800","1.26685","603.00647","0.01267","60.30065","0.00338"
"76.21800","1.26851","602.29675","0.01269","60.22968","0.00337"
"76.31800","1.27002","601.22394","0.01270","60.12239","0.00336"
"76.41800","1.27185","601.28198","0.01272","60.12820","0.00336"
"76.51800","1.27347","599.18201","0.01273","59.91820","0.00334"
"76.61800","1.27520","591.47406","0.01275","59.14741","0.00330"
"76.64500","1.27551","590.56146","0.01276","59.05614","0.00329"