File: Tension/Section_2_Group_2/epoxy_high_sample_1.is_tens_RawData/Specimen_RawData_1.csv
Time,Extension,Load,Tensile strain (Extension),Tensile stress,Strain-by-clip-gage
(s),(mm),(N),(mm/mm),(MPa),(mm/mm)
"0.00000","0.00000","1686.52625","0.00000","168.65262","-0.04182"
"0.20000","0.00238","1705.27795","0.00002","170.52780","-0.04182"
"0.40000","0.01103","1778.46472","0.00011","177.84647","-0.04183"
"0.60000","0.01764","1832.58521","0.00018","183.25851","-0.04183"
"0.80000","0.02429","1885.74731","0.00024","188.57474","-0.04183"
"1.00000","0.03099","1938.20544","0.00031","193.82054","-0.04183"
"1.20000","0.03756","1988.49500","0.00038","198.84950","-0.04183"
"1.40000","0.04424","2039.01941","0.00044","203.90195","-0.04183"
"1.60000","0.05089","2088.64185","0.00051","208.86418","-0.04182"
"1.80000","0.05757","2137.25757","0.00058","213.72575","-0.04182"
"2.00000","0.06434","2185.83423","0.00064","218.58342","-0.04183"
"2.20000","0.07096","2232.08936","0.00071","223.20894","-0.04184"
"2.40000","0.07769","2278.20361","0.00078","227.82036","-0.04183"
"2.60000","0.08419","2321.27588","0.00084","232.12759","-0.04183"
"2.80000","0.09104","2366.38232","0.00091","236.63823","-0.04183"
"3.00000","0.09760","2408.37085","0.00098","240.83708","-0.04183"
"3.20000","0.10415","2448.94263","0.00104","244.89426","-0.04184"
"3.40000","0.11104","2491.69946","0.00111","249.16995","-0.04183"
"3.60000","0.11753","2529.74390","0.00118","252.97440","-0.04182"
"3.80000","0.12424","2569.05493","0.00124","256.90549","-0.04183"
"4.00000","0.13094","2607.48218","0.00131","260.74823","-0.04184"
"4.20000","0.13776","2645.69751","0.00138","264.56976","-0.04183"
"4.40000","0.14432","2680.99878","0.00144","268.09988","-0.04183"
"4.60000","0.15087","2715.64819","0.00151","271.56482","-0.04183"
"4.80000","0.15762","2751.66479","0.00158","275.16647","-0.04183"
"5.00000","0.16412","2784.66846","0.00164","278.46686","-0.04183"
"5.20000","0.17103","2821.25659","0.00171","282.12567","-0.04182"
"5.40000","0.17756","2854.20654","0.00178","285.42065","-0.04183"
"5.60000","0.18428","2888.39746","0.00184","288.83975","-0.04183"
"5.80000","0.19103","2923.05005","0.00191","292.30499","-0.04183"
"6.00000","0.19766","2956.22314","0.00198","295.62231","-0.04183"
"6.20000","0.20427","2989.45239","0.00204","298.94525","-0.04182"
"6.40000","0.21081","3021.63257","0.00211","302.16327","-0.04183"
"6.60000","0.21771","3057.16284","0.00218","305.71628","-0.04182"
"6.80000","0.22426","3089.24365","0.00224","308.92438","-0.04182"
"7.00000","0.23088","3121.93994","0.00231","312.19400","-0.04183"
"7.20000","0.23763","3155.98926","0.00238","315.59894","-0.04183"
"7.40000","0.24421","3188.08032","0.00244","318.80804","-0.04183"
"7.60000","0.25101","3222.10229","0.00251","322.21024","-0.04183"
"7.80000","0.25762","3254.55322","0.00258","325.45532","-0.04183"
"8.00000","0.26435","3287.61719","0.00264","328.76172","-0.04184"
"8.20000","0.27095","3319.77832","0.00271","331.97784","-0.04184"
"8.40000","0.27758","3352.30786","0.00278","335.23077","-0.04183"
"8.60000","0.28423","3384.71558","0.00284","338.47156","-0.04183"
"8.80000","0.29082","3416.82178","0.00291","341.68219","-0.04183"
"9.00000","0.29764","3450.68457","0.00298","345.06845","-0.04183"
"9.20000","0.30433","3483.82715","0.00304","348.38272","-0.04183"
"9.40000","0.31092","3515.41040","0.00311","351.54105","-0.04183"
"9.60000","0.31774","3549.71436","0.00318","354.97144","-0.04183"
"9.80000","0.32421","3580.68018","0.00324","358.06802","-0.04183"
"10.00000","0.33091","3613.71753","0.00331","361.37177","-0.04183"
"10.20000","0.33753","3645.93384","0.00338","364.59338","-0.04182"
"10.40000","0.34433","3679.67529","0.00344","367.96753","-0.04183"
"10.60000","0.35098","3712.24951","0.00351","371.22495","-0.04183"
"10.80000","0.35757","3743.82837","0.00358","374.38284","-0.04183"
"11.00000","0.36435","3777.65332","0.00364","377.76532","-0.04182"
"11.20000","0.37083","3808.79492","0.00371","380.87949","-0.04183"
"11.40000","0.37767","3843.21631","0.00378","384.32162","-0.04183"
"11.60000","0.38427","3875.14648","0.00384","387.51465","-0.04183"
"11.80000","0.39093","3907.29785","0.00391","390.72980","-0.04183"
"12.00000","0.39768","3940.99731","0.00398","394.09973","-0.04183"
"12.20000","0.40422","3972.27637","0.00404","397.22763","-0.04183"
"12.40000","0.41095","4005.58081","0.00411","400.55807","-0.04183"
"12.60000","0.41748","4036.88062","0.00417","403.68805","-0.04183"
"12.80000","0.42443","4071.98291","0.00424","407.19830","-0.04182"
"13.00000","0.43094","4102.71680","0.00431","410.27167","-0.04183"
"13.20000","0.43759","4134.69727","0.00438","413.46973","-0.04183"
"13.40000","0.44435","4167.66943","0.00444","416.76694","-0.04183"
"13.60000","0.45080","4197.58936","0.00451","419.75894","-0.04183"
"13.80000","0.45762","4231.17480","0.00458","423.11749","-0.04183"
"14.00000","0.46424","4263.15820","0.00464","426.31583","-0.04183"
"14.20000","0.47095","4295.56982","0.00471","429.55698","-0.04183"
"14.40000","0.47768","4328.08691","0.00478","432.80869","-0.04183"
"14.60000","0.48427","4358.91211","0.00484","435.89120","-0.04183"
"14.80000","0.49098","4390.75977","0.00491","439.07599","-0.04183"
"15.00000","0.49752","4421.08887","0.00498","442.10889","-0.04183"
"15.20000","0.50432","4453.91602","0.00504","445.39160","-0.04183"
"15.40000","0.51090","4484.48682","0.00511","448.44867","-0.04183"
"15.60000","0.51752","4515.32959","0.00518","451.53296","-0.04183"
"15.80000","0.52441","4548.86865","0.00524","454.88687","-0.04183"
"16.00000","0.53087","4577.73584","0.00531","457.77359","-0.04183"
"16.20000","0.53760","4609.04590","0.00538","460.90460","-0.04182"
"16.40000","0.54426","4639.89746","0.00544","463.98975","-0.04183"
"16.60000","0.55100","4671.39453","0.00551","467.13947","-0.04183"
"16.80000","0.55757","4701.33984","0.00558","470.13397","-0.04183"
"17.00000","0.56418","4731.28955","0.00564","473.12897","-0.04183"
"17.20000","0.57100","4763.66602","0.00571","476.36661","-0.04183"
"17.40000","0.57746","4792.73193","0.00577","479.27319","-0.04183"
"17.60000","0.58430","4825.69385","0.00584","482.56940","-0.04183"
"17.80000","0.59094","4857.30420","0.00591","485.73041","-0.04182"
"18.00000","0.59759","4888.91064","0.00598","488.89105","-0.04182"
"18.20000","0.60443","4922.78809","0.00604","492.27881","-0.04183"
"18.40000","0.61087","4952.09229","0.00611","495.20923","-0.04183"
"18.60000","0.61754","4983.68604","0.00618","498.36859","-0.04183"
"18.80000","0.62417","5015.11670","0.00624","501.51166","-0.04183"
"19.00000","0.63104","5048.66992","0.00631","504.86700","-0.04183"
"19.20000","0.63755","5078.83887","0.00638","507.88388","-0.04183"
"19.40000","0.64426","5110.48438","0.00644","511.04843","-0.04183"
"19.60000","0.65104","5142.97656","0.00651","514.29767","-0.04183"
"19.80000","0.65752","5172.16748","0.00658","517.21674","-0.04183"
"20.00000","0.66431","5204.57471","0.00664","520.45746","-0.04183"
"20.20000","0.67091","5234.86279","0.00671","523.48627","-0.04183"
"20.40000","0.67761","5265.74414","0.00678","526.57440","-0.04183"
"20.60000","0.68427","5296.57861","0.00684","529.65784","-0.04183"
"20.80000","0.69089","5326.56445","0.00691","532.65643","-0.04183"
"21.00000","0.69759","5357.19922","0.00698","535.71991","-0.04183"
"21.20000","0.70421","5386.94531","0.00704","538.69452","-0.04182"
"21.40000","0.71104","5418.77344","0.00711","541.87732","-0.04183"
"21.60000","0.71759","5447.93262","0.00718","544.79327","-0.04183"
"21.80000","0.72422","5477.28711","0.00724","547.72870","-0.04183"
"22.00000","0.73104","5509.26611","0.00731","550.92664","-0.04184"
"22.20000","0.73753","5537.52246","0.00738","553.75226","-0.04183"
"22.40000","0.74421","5567.36084","0.00744","556.73608","-0.04183"
"22.60000","0.75089","5597.28369","0.00751","559.72839","-0.04182"
"22.80000","0.75764","5627.46094","0.00758","562.74609","-0.04182"
"23.00000","0.76434","5657.31396","0.00764","565.73138","-0.04183"
"23.20000","0.77087","5685.20996","0.00771","568.52100","-0.04183"
"23.40000","0.77767","5715.82666","0.00778","571.58264","-0.04183"
"23.60000","0.78414","5742.87939","0.00784","574.28796","-0.04184"
"23.80000","0.79102","5773.90283","0.00791","577.39026","-0.04183"
"24.00000","0.79762","5801.98340","0.00798","580.19836","-0.04183"
"24.20000","0.80419","5829.27441","0.00804","582.92743","-0.04183"
"24.40000","0.81101","5859.69775","0.00811","585.96979","-0.04183"
"24.60000","0.81752","5886.79932","0.00818","588.67993","-0.04183"
"24.80000","0.82426","5915.58105","0.00824","591.55811","-0.04183"
"25.00000","0.83085","5942.84473","0.00831","594.28448","-0.04183"
"25.20000","0.83773","5973.02490","0.00838","597.30249","-0.04183"
"25.40000","0.84429","5999.88281","0.00844","599.98828","-0.04184"
"25.60000","0.85085","6026.29932","0.00851","602.62994","-0.04183"
"25.80000","0.85772","6056.16162","0.00858","605.61615","-0.04183"
"26.00000","0.86411","6080.68213","0.00864","608.06824","-0.04183"
"26.20000","0.87092","6109.76514","0.00871","610.97650","-0.04183"
"26.40000","0.87755","6137.12891","0.00878","613.71289","-0.04182"
"26.60000","0.88437","6165.71924","0.00884","616.57190","-0.04182"
"26.80000","0.89095","6192.05615","0.00891","619.20563","-0.04183"
"27.00000","0.89755","6218.31592","0.00898","621.83160","-0.04183"
"27.20000","0.90425","6245.33545","0.00904","624.53357","-0.04183"
"27.40000","0.91080","6270.87939","0.00911","627.08795","-0.04183"
"27.60000","0.91775","6300.43457","0.00918","630.04346","-0.04183"
"27.80000","0.92425","6324.92139","0.00924","632.49213","-0.04183"
"28.00000","0.93085","6349.98828","0.00931","634.99884","-0.04183"
"28.20000","0.93767","6377.84326","0.00938","637.78430","-0.04182"
"28.40000","0.94422","6402.43164","0.00944","640.24316","-0.04182"
"28.60000","0.95085","6427.78955","0.00951","642.77893","-0.04183"
"28.80000","0.95758","6454.39697","0.00958","645.43970","-0.04183"
"29.00000","0.96434","6480.40186","0.00964","648.04016","-0.04183"
"29.20000","0.97099","6505.33350","0.00971","650.53333","-0.04183"
"29.40000","0.97758","6529.29297","0.00978","652.92932","-0.04183"
"29.60000","0.98428","6554.47168","0.00984","655.44714","-0.04183"
"29.80000","0.99082","6577.63477","0.00991","657.76349","-0.04183"
"30.00000","0.99762","6603.88916","0.00998","660.38892","-0.04183"
"30.20000","1.00431","6628.54297","0.01004","662.85431","-0.04183"
"30.40000","1.01088","6651.36816","0.01011","665.13684","-0.04183"
"30.60000","1.01769","6676.84912","0.01018","667.68494","-0.04183"
"30.80000","1.02418","6698.86768","0.01024","669.88678","-0.04183"
"31.00000","1.03094","6723.56055","0.01031","672.35608","-0.04183"
"31.20000","1.03759","6747.19873","0.01038","674.71985","-0.04183"
"31.40000","1.04438","6771.89551","0.01044","677.18958","-0.04183"
"31.60000","1.05097","6794.46143","0.01051","679.44617","-0.04183"
"31.80000","1.05750","6816.21582","0.01057","681.62158","-0.04183"
"32.00000","1.06443","6841.99170","0.01064","684.19916","-0.04183"
"32.20000","1.07079","6861.85449","0.01071","686.18542","-0.04183"
"32.40000","1.07756","6885.87109","0.01078","688.58710","-0.04183"
"32.60000","1.08420","6908.66553","0.01084","690.86658","-0.04183"
"32.80000","1.09099","6932.58203","0.01091","693.25818","-0.04183"
"33.00000","1.09775","6956.14062","0.01098","695.61407","-0.04183"
"33.20000","1.10424","6976.68945","0.01104","697.66895","-0.04182"
"33.40000","1.11093","6999.54102","0.01111","699.95410","-0.04183"
"33.60000","1.11750","7020.85498","0.01117","702.08551","-0.04183"
"33.80000","1.12443","7045.88721","0.01124","704.58875","-0.04183"
"34.00000","1.13085","7065.32617","0.01131","706.53259","-0.04183"
"34.20000","1.13749","7086.76123","0.01137","708.67615","-0.04182"
"34.40000","1.14437","7110.82422","0.01144","711.08240","-0.04182"
"34.60000","1.15087","7130.66699","0.01151","713.06671","-0.04183"
"34.80000","1.15767","7153.50000","0.01158","715.34998","-0.04183"
"35.00000","1.16423","7173.73730","0.01164","717.37372","-0.04183"
"35.20000","1.17105","7196.53125","0.01171","719.65314","-0.04183"
"35.40000","1.17757","7216.79053","0.01178","721.67908","-0.04183"
"35.60000","1.18426","7237.82471","0.01184","723.78247","-0.04183"
"35.80000","1.19089","7257.99512","0.01191","725.79950","-0.04183"
"36.00000","1.19751","7278.35059","0.01198","727.83508","-0.04182"
"36.20000","1.20431","7300.58691","0.01204","730.05872","-0.04183"
"36.40000","1.21095","7321.23682","0.01211","732.12366","-0.04183"
"36.60000","1.21758","7340.87988","0.01218","734.08801","-0.04183"
"36.80000","1.22442","7362.79639","0.01224","736.27966","-0.04183"
"37.00000","1.23091","7380.99756","0.01231","738.09973","-0.04183"
"37.20000","1.23755","7401.25537","0.01238","740.12555","-0.04184"
"37.40000","1.24423","7421.82520","0.01244","742.18250","-0.04182"
"37.60000","1.25101","7443.07178","0.01251","744.30719","-0.04182"
"37.80000","1.25760","7462.78516","0.01258","746.27850","-0.04183"
"38.00000","1.26413","7481.05664","0.01264","748.10565","-0.04183"
"38.20000","1.27105","7503.53271","0.01271","750.35327","-0.04183"
"38.40000","1.27754","7520.41992","0.01278","752.04199","-0.04183"
"38.60000","1.28440","7537.97217","0.01284","753.79724","-0.04183"
"38.80000","1.29097","7557.16943","0.01291","755.71692","-0.04183"
"39.00000","1.29757","7576.01562","0.01298","757.60156","-0.04183"
"39.20000","1.30443","7597.55762","0.01304","759.75574","-0.04182"
"39.40000","1.31082","7613.66553","0.01311","761.36658","-0.04182"
"39.60000","1.31756","7632.94922","0.01318","763.29492","-0.04183"
"39.80000","1.32406","7650.00488","0.01324","765.00049","-0.04183"
"40.00000","1.33111","7672.18164","0.01331","767.21814","-0.04183"
"40.20000","1.33767","7689.20996","0.01338","768.92102","-0.04183"
"40.40000","1.34433","7706.81299","0.01344","770.68127","-0.04183"
"40.60000","1.35109","7725.49072","0.01351","772.54907","-0.04183"
"40.80000","1.35750","7740.29639","0.01358","774.02966","-0.04183"
"41.00000","1.36428","7758.83105","0.01364","775.88312","-0.04182"
"41.20000","1.37085","7774.96826","0.01371","777.49683","-0.04183"
"41.40000","1.37764","7793.12256","0.01378","779.31226","-0.04183"
"41.60000","1.38428","7809.87012","0.01384","780.98700","-0.04183"
"41.80000","1.39093","7826.76123","0.01391","782.67615","-0.04183"
"42.00000","1.39769","7844.58887","0.01398","784.45886","-0.04183"
"42.20000","1.40423","7859.78809","0.01404","785.97882","-0.04183"
"42.40000","1.41112","7878.34912","0.01411","787.83490","-0.04183"
"42.60000","1.41760","7892.52686","0.01418","789.25269","-0.04182"
"42.80000","1.42426","7908.28174","0.01424","790.82819","-0.04183"
"43.00000","1.43096","7924.32227","0.01431","792.43225","-0.04183"
"43.20000","1.43754","7938.89990","0.01438","793.89001","-0.04183"
"43.40000","1.44420","7954.28662","0.01444","795.42865","-0.04183"
"43.60000","1.45089","7969.95752","0.01451","796.99573","-0.04183"
"43.80000","1.45775","7986.74609","0.01458","798.67462","-0.04183"
"44.00000","1.46438","8001.60107","0.01464","800.16010","-0.04183"
"44.20000","1.47095","8015.38281","0.01471","801.53827","-0.04183"
"44.40000","1.47768","8031.25342","0.01478","803.12537","-0.04182"
"44.60000","1.48418","8044.32861","0.01484","804.43286","-0.04183"
"44.80000","1.49087","8059.07861","0.01491","805.90784","-0.04183"
"45.00000","1.49760","8074.99219","0.01498","807.49921","-0.04183"
"45.20000","1.50421","8088.77148","0.01504","808.87714","-0.04183"
"45.40000","1.51102","8104.96680","0.01511","810.49670","-0.04182"
"45.60000","1.51759","8118.52832","0.01518","811.85284","-0.04182"
"45.80000","1.52438","8134.38818","0.01524","813.43884","-0.04183"
"46.00000","1.53088","8147.34326","0.01531","814.73431","-0.04183"
"46.20000","1.53771","8163.47314","0.01538","816.34729","-0.04182"
"46.40000","1.54433","8177.29395","0.01544","817.72937","-0.04183"
"46.60000","1.55081","8189.35498","0.01551","818.93549","-0.04183"
"46.80000","1.55772","8205.89258","0.01558","820.58923","-0.04182"
"47.00000","1.56411","8216.96387","0.01564","821.69641","-0.04182"
"47.20000","1.57093","8232.61719","0.01571","823.26172","-0.04183"
"47.40000","1.57762","8246.96387","0.01578","824.69641","-0.04183"
"47.60000","1.58445","8262.18457","0.01584","826.21844","-0.04183"
"47.80000","1.59108","8275.38770","0.01591","827.53876","-0.04183"
"48.00000","1.59757","8287.25391","0.01598","828.72540","-0.04183"
"48.20000","1.60430","8301.36719","0.01604","830.13672","-0.04183"
"48.40000","1.61075","8312.59473","0.01611","831.25946","-0.04183"
"48.60000","1.61772","8328.71777","0.01618","832.87177","-0.04183"
"48.80000","1.62424","8340.20801","0.01624","834.02081","-0.04183"
"49.00000","1.63090","8352.51855","0.01631","835.25183","-0.04183"
"49.20000","1.63777","8367.18262","0.01638","836.71826","-0.04183"
"49.40000","1.64430","8377.54102","0.01644","837.75409","-0.04183"
"49.60000","1.65096","8389.45215","0.01651","838.94519","-0.04183"
"49.80000","1.65753","8399.97168","0.01658","839.99719","-0.04183"
"50.00000","1.66436","8412.99316","0.01664","841.29932","-0.04183"
"50.20000","1.67092","8422.67871","0.01671","842.26788","-0.04183"
"50.40000","1.67755","8432.47949","0.01678","843.24792","-0.04183"
"50.60000","1.68430","8443.68164","0.01684","844.36816","-0.04183"
"50.80000","1.69085","8452.38379","0.01691","845.23840","-0.04182"
"51.00000","1.69768","8464.01758","0.01698","846.40173","-0.04183"
"51.20000","1.70433","8473.71484","0.01704","847.37146","-0.04183"
"51.40000","1.71095","8483.10645","0.01711","848.31067","-0.04183"
"51.60000","1.71768","8493.63086","0.01718","849.36310","-0.04183"
"51.80000","1.72425","8502.06641","0.01724","850.20667","-0.04183"
"52.00000","1.73086","8511.29395","0.01731","851.12939","-0.04182"
"52.20000","1.73751","8521.20996","0.01738","852.12097","-0.04183"
"52.40000","1.74433","8532.94922","0.01744","853.29492","-0.04183"
"52.60000","1.75104","8543.74512","0.01751","854.37451","-0.04183"
"52.80000","1.75752","8552.14746","0.01758","855.21472","-0.04183"
"53.00000","1.76444","8564.73633","0.01764","856.47363","-0.04183"
"53.20000","1.77087","8572.38379","0.01771","857.23840","-0.04183"
"53.40000","1.77760","8583.60547","0.01778","858.36053","-0.04184"
"53.60000","1.78421","8593.95605","0.01784","859.39563","-0.04183"
"53.80000","1.79095","8604.78613","0.01791","860.47864","-0.04182"
"54.00000","1.79770","8615.77734","0.01798","861.57776","-0.04183"
"54.20000","1.80422","8623.81934","0.01804","862.38196","-0.04183"
"54.40000","1.81097","8634.29297","0.01811","863.42932","-0.04183"
"54.60000","1.81749","8642.06543","0.01817","864.20654","-0.04183"
"54.80000","1.82442","8653.24609","0.01824","865.32458","-0.04183"
"55.00000","1.83097","8660.74902","0.01831","866.07489","-0.04183"
"55.20000","1.83755","8668.53906","0.01838","866.85388","-0.04183"
"55.40000","1.84432","8678.72754","0.01844","867.87274","-0.04183"
"55.60000","1.85084","8685.09766","0.01851","868.50977","-0.04182"
"55.80000","1.85768","8694.92773","0.01858","869.49280","-0.04183"
"56.00000","1.86418","8700.95801","0.01864","870.09583","-0.04182"
"56.20000","1.87106","8709.85645","0.01871","870.98566","-0.04183"
"56.40000","1.87765","8715.92676","0.01878","871.59265","-0.04183"
"56.60000","1.88426","8721.29102","0.01884","872.12909","-0.04183"
"56.80000","1.89100","8728.49414","0.01891","872.84943","-0.04183"
"57.00000","1.89746","8731.74316","0.01897","873.17432","-0.04183"
"57.20000","1.90430","8739.09766","0.01904","873.90979","-0.04182"
"57.40000","1.91097","8744.26562","0.01911","874.42657","-0.04183"
"57.60000","1.91762","8749.14551","0.01918","874.91455","-0.04183"
"57.80000","1.92437","8755.40039","0.01924","875.54004","-0.04183"
"58.00000","1.93089","8758.98926","0.01931","875.89893","-0.04183"
"58.20000","1.93762","8764.80176","0.01938","876.48016","-0.04182"
"58.40000","1.94423","8769.34277","0.01944","876.93427","-0.04183"
"58.60000","1.95104","8775.90039","0.01951","877.59003","-0.04183"
"58.80000","1.95760","8780.28320","0.01958","878.02832","-0.04183"
"59.00000","1.96420","8784.80762","0.01964","878.48077","-0.04183"
"59.20000","1.97104","8792.18359","0.01971","879.21838","-0.04182"
"59.40000","1.97749","8795.77832","0.01977","879.57782","-0.04183"
"59.60000","1.98428","8802.76855","0.01984","880.27686","-0.04183"
"59.80000","1.99097","8808.76562","0.01991","880.87659","-0.04183"
"60.00000","1.99768","8814.20898","0.01998","881.42090","-0.04183"
"60.20000","2.00430","8819.16895","0.02004","881.91687","-0.04183"
"60.40000","2.01086","8823.09375","0.02011","882.30939","-0.04183"
"60.60000","2.01765","8829.71094","0.02018","882.97107","-0.04183"
"60.80000","2.02410","8832.59570","0.02024","883.25958","-0.04182"
"61.00000","2.03101","8839.28320","0.02031","883.92834","-0.04183"
"61.20000","2.03763","8843.63477","0.02038","884.36346","-0.04183"
"61.40000","2.04425","8847.74805","0.02044","884.77478","-0.04183"
"61.60000","2.05110","8854.63867","0.02051","885.46387","-0.04183"
"61.80000","2.05749","8855.98633","0.02057","885.59863","-0.04183"
"62.00000","2.06427","8861.30957","0.02064","886.13098","-0.04183"
"62.20000","2.07084","8864.55273","0.02071","886.45526","-0.04183"
"62.40000","2.07771","8870.19824","0.02078","887.01984","-0.04182"
"62.60000","2.08425","8872.42090","0.02084","887.24207","-0.04183"
"62.80000","2.09092","8875.90527","0.02091","887.59052","-0.04183"
"63.00000","2.09771","8881.53711","0.02098","888.15369","-0.04182"
"63.20000","2.10415","8882.80664","0.02104","888.28064","-0.04183"
"63.40000","2.11101","8888.73828","0.02111","888.87384","-0.04183"
"63.60000","2.11758","8891.50293","0.02118","889.15027","-0.04182"
"63.80000","2.12422","8894.03613","0.02124","889.40363","-0.04182"
"64.00000","2.13103","8899.11426","0.02131","889.91144","-0.04182"
"64.20000","2.13754","8900.28125","0.02138","890.02814","-0.04182"
"64.40000","2.14422","8903.31055","0.02144","890.33105","-0.04183"
"64.60000","2.15091","8906.10742","0.02151","890.61072","-0.04184"
"64.80000","2.15772","8910.10352","0.02158","891.01038","-0.04183"
"65.00000","2.16429","8911.14062","0.02164","891.11407","-0.04182"
"65.20000","2.17087","8912.37598","0.02171","891.23761","-0.04183"
"65.40000","2.17775","8917.22070","0.02178","891.72205","-0.04183"
"65.60000","2.18420","8917.21973","0.02184","891.72198","-0.04182"
"65.80000","2.19088","8919.44141","0.02191","891.94415","-0.04182"
"66.00000","2.19760","8921.69043","0.02198","892.16907","-0.04183"
"66.20000","2.20425","8923.36914","0.02204","892.33691","-0.04183"
"66.40000","2.21105","8926.16406","0.02211","892.61639","-0.04183"
"66.60000","2.21755","8925.42383","0.02218","892.54236","-0.04183"
"66.80000","2.22432","8927.32715","0.02224","892.73273","-0.04183"
"67.00000","2.23082","8926.38672","0.02231","892.63867","-0.04183"
"67.20000","2.23772","8928.71289","0.02238","892.87128","-0.04183"
"67.40000","2.24425","8927.25391","0.02244","892.72540","-0.04183"
"67.60000","2.25083","8925.27148","0.02251","892.52716","-0.04182"
"67.80000","2.25771","8925.96289","0.02258","892.59631","-0.04183"
"68.00000","2.26418","8922.03418","0.02264","892.20343","-0.04183"
"68.20000","2.27094","8920.78906","0.02271","892.07892","-0.04182"
"68.40000","2.27752","8917.69336","0.02278","891.76935","-0.04183"
"68.60000","2.28438","8916.33301","0.02284","891.63330","-0.04183"
"68.80000","2.29101","8913.19531","0.02291","891.31952","-0.04183"
"69.00000","2.29753","8907.94238","0.02298","890.79425","-0.04183"
"69.20000","2.30434","8905.84277","0.02304","890.58429","-0.04182"
"69.40000","2.31078","8900.17383","0.02311","890.01740","-0.04182"
"69.60000","2.31764","8899.04590","0.02318","889.90460","-0.04183"
"69.80000","2.32422","8895.20605","0.02324","889.52063","-0.04183"
"70.00000","2.33099","8892.89844","0.02331","889.28986","-0.04182"
"70.20000","2.33764","8890.35645","0.02338","889.03564","-0.04183"
"70.40000","2.34423","8886.44336","0.02344","888.64435","-0.04183"
"70.60000","2.35093","8883.80469","0.02351","888.38049","-0.04183"
"70.80000","2.35751","8880.43750","0.02358","888.04376","-0.04182"
"71.00000","2.36440","8880.30273","0.02364","888.03027","-0.04183"
"71.20000","2.37091","8876.44629","0.02371","887.64465","-0.04183"
"71.40000","2.37751","8872.72070","0.02378","887.27209","-0.04183"
"71.60000","2.38432","8871.71484","0.02384","887.17151","-0.04182"
"71.80000","2.39088","8867.42578","0.02391","886.74255","-0.04183"
"72.00000","2.39757","8864.53711","0.02398","886.45374","-0.04183"
"72.20000","2.40426","8862.01758","0.02404","886.20178","-0.04183"
"72.40000","2.41096","8859.65918","0.02411","885.96594","-0.04183"
"72.60000","2.41771","8858.44922","0.02418","885.84491","-0.04183"
"72.80000","2.42424","8854.77246","0.02424","885.47723","-0.04183"
"73.00000","2.43092","8852.69531","0.02431","885.26953","-0.04183"
"73.20000","2.43752","8850.22363","0.02438","885.02234","-0.04183"
"73.40000","2.44434","8850.59277","0.02444","885.05927","-0.04182"
"73.60000","2.45099","8849.59277","0.02451","884.95929","-0.04182"
"73.80000","2.45751","8846.59766","0.02458","884.65979","-0.04183"
"74.00000","2.46439","8847.77246","0.02464","884.77722","-0.04183"
"74.20000","2.47085","8845.13574","0.02471","884.51355","-0.04183"
"74.40000","2.47763","8845.88477","0.02478","884.58850","-0.04183"
"74.60000","2.48428","8845.81543","0.02484","884.58154","-0.04183"
"74.80000","2.49099","8846.12988","0.02491","884.61298","-0.04183"
"75.00000","2.49763","8846.48340","0.02498","884.64832","-0.04183"
"75.20000","2.50417","8845.29395","0.02504","884.52942","-0.04182"
"75.40000","2.51106","8846.97461","0.02511","884.69745","-0.04183"
"75.60000","2.51744","8842.64746","0.02517","884.26477","-0.04183"
"75.80000","2.52431","8842.52734","0.02524","884.25275","-0.04182"
"76.00000","2.53092","8839.13184","0.02531","883.91321","-0.04182"
"76.20000","2.53761","8836.19531","0.02538","883.61951","-0.04183"
"76.40000","2.54444","8834.99023","0.02544","883.49902","-0.04183"
"76.60000","2.55088","8828.95410","0.02551","882.89539","-0.04183"
"76.80000","2.55757","8825.59375","0.02558","882.55939","-0.04183"
"77.00000","2.56415","8821.41309","0.02564","882.14130","-0.04183"
"77.20000","2.57112","8820.03711","0.02571","882.00372","-0.04183"
"77.40000","2.57754","8813.65723","0.02578","881.36572","-0.04183"
"77.60000","2.58416","8808.94141","0.02584","880.89417","-0.04182"
"77.80000","2.59101","8806.75977","0.02591","880.67596","-0.04183"
"78.00000","2.59753","8799.99707","0.02598","879.99969","-0.04183"
"78.20000","2.60435","8795.91113","0.02604","879.59113","-0.04183"
"78.40000","2.61093","8788.74023","0.02611","878.87402","-0.04183"
"78.60000","2.61765","8782.50879","0.02618","878.25085","-0.04183"
"78.80000","2.62431","8776.59570","0.02624","877.65955","-0.04183"
"79.00000","2.63092","8769.90527","0.02631","876.99054","-0.04183"
"79.20000","2.63753","8764.11816","0.02638","876.41180","-0.04183"
"79.40000","2.64417","8758.33887","0.02644","875.83386","-0.04182"
"79.60000","2.65102","8754.42480","0.02651","875.44250","-0.04182"
"79.80000","2.65764","8748.42871","0.02658","874.84290","-0.04183"
"80.00000","2.66422","8741.49316","0.02664","874.14929","-0.04183"
"80.20000","2.67108","8737.96094","0.02671","873.79608","-0.04183"
"80.40000","2.67753","8729.98242","0.02678","872.99823","-0.04183"
"80.60000","2.68424","8725.03027","0.02684","872.50305","-0.04183"
"80.80000","2.69093","8720.49121","0.02691","872.04913","-0.04182"
"81.00000","2.69767","8715.72852","0.02698","871.57288","-0.04182"
"81.20000","2.70430","8710.04492","0.02704","871.00452","-0.04182"
"81.40000","2.71083","8703.46191","0.02711","870.34619","-0.04183"
"81.60000","2.71770","8700.44434","0.02718","870.04443","-0.04183"
"81.80000","2.72423","8694.17871","0.02724","869.41785","-0.04183"
"82.00000","2.73107","8690.25391","0.02731","869.02539","-0.04183"
"82.20000","2.73764","8682.85938","0.02738","868.28595","-0.04183"
"82.40000","2.74423","8674.83105","0.02744","867.48309","-0.04183"
"82.60000","2.75111","8670.35352","0.02751","867.03534","-0.04183"
"82.80000","2.75749","8660.84082","0.02757","866.08411","-0.04182"
"83.00000","2.76419","8654.53320","0.02764","865.45331","-0.04181"
"83.20000","2.77078","8648.10156","0.02771","864.81018","-0.04183"
"83.40000","2.77778","8644.96973","0.02778","864.49695","-0.04184"
"83.60000","2.78433","8637.63379","0.02784","863.76337","-0.04184"
"83.80000","2.79095","8630.58301","0.02791","863.05829","-0.04183"
"84.00000","2.79774","8625.41797","0.02798","862.54181","-0.04183"
"84.20000","2.80417","8616.05762","0.02804","861.60577","-0.04183"
"84.40000","2.81094","8609.79590","0.02811","860.97961","-0.04182"
"84.60000","2.81751","8600.99219","0.02818","860.09924","-0.04182"
"84.80000","2.82426","8592.70020","0.02824","859.27002","-0.04182"
"85.00000","2.83096","8584.13770","0.02831","858.41376","-0.04183"
"85.20000","2.83759","8574.32324","0.02838","857.43231","-0.04183"
"85.40000","2.84433","8566.77441","0.02844","856.67743","-0.04183"
"85.60000","2.85088","8558.43555","0.02851","855.84357","-0.04183"
"85.80000","2.85779","8554.64648","0.02858","855.46466","-0.04183"
"86.00000","2.86427","8547.03516","0.02864","854.70349","-0.04183"
"86.20000","2.87088","8540.76465","0.02871","854.07648","-0.04182"
"86.40000","2.87764","8536.41602","0.02878","853.64160","-0.04182"
"86.60000","2.88417","8529.19336","0.02884","852.91931","-0.04183"
"86.80000","2.89089","8523.93652","0.02891","852.39368","-0.04184"
"87.00000","2.89761","8518.70898","0.02898","851.87091","-0.04182"
"87.20000","2.90437","8512.93359","0.02904","851.29333","-0.04182"
"87.40000","2.91105","8505.96680","0.02911","850.59668","-0.04182"
"87.60000","2.91758","8497.01270","0.02918","849.70129","-0.04182"
"87.80000","2.92431","8489.43066","0.02924","848.94305","-0.04182"
"88.00000","2.93084","8479.73242","0.02931","847.97327","-0.04183"
"88.20000","2.93763","8472.53613","0.02938","847.25360","-0.04183"
"88.40000","2.94429","8463.45312","0.02944","846.34534","-0.04183"
"88.60000","2.95085","8452.92969","0.02951","845.29297","-0.04183"
"88.80000","2.95772","8445.82422","0.02958","844.58240","-0.04183"
"89.00000","2.96427","8434.79883","0.02964","843.47986","-0.04182"
"89.20000","2.97107","8424.94238","0.02971","842.49426","-0.04182"
"89.40000","2.97759","8411.33887","0.02978","841.13391","-0.04183"
"89.60000","2.98439","8399.31934","0.02984","839.93195","-0.04183"
"89.80000","2.99097","8385.48438","0.02991","838.54846","-0.04183"
"90.00000","2.99747","8370.37891","0.02997","837.03790","-0.04183"
"90.20000","3.00437","8359.19531","0.03004","835.91956","-0.04183"
"90.40000","3.01077","8342.26367","0.03011","834.22638","-0.04183"
"90.60000","3.01764","8330.40332","0.03018","833.04034","-0.04183"
"90.80000","3.02432","8317.11621","0.03024","831.71161","-0.04183"
"91.00000","3.03112","8304.95312","0.03031","830.49530","-0.04183"
"91.20000","3.03773","8292.32812","0.03038","829.23279","-0.04183"
"91.40000","3.04424","8279.26074","0.03044","827.92609","-0.04183"
"91.60000","3.05093","8269.42969","0.03051","826.94299","-0.04182"
"91.80000","3.05743","8258.11719","0.03057","825.81171","-0.04182"
"92.00000","3.06440","8251.65723","0.03064","825.16571","-0.04183"
"92.20000","3.07089","8240.80469","0.03071","824.08044","-0.04183"
"92.40000","3.07755","8232.09375","0.03078","823.20935","-0.04183"
"92.60000","3.08444","8226.62891","0.03084","822.66290","-0.04183"
"92.80000","3.09096","8217.27441","0.03091","821.72742","-0.04183"
"93.00000","3.09764","8210.22656","0.03098","821.02264","-0.04183"
"93.20000","3.10422","8203.48828","0.03104","820.34882","-0.04182"
"93.40000","3.11101","8198.69531","0.03111","819.86951","-0.04182"
"93.60000","3.11758","8193.29297","0.03118","819.32928","-0.04183"
"93.80000","3.12421","8189.20410","0.03124","818.92041","-0.04183"
"94.00000","3.13095","8186.97900","0.03131","818.69788","-0.04183"
"94.20000","3.13751","8182.98389","0.03138","818.29840","-0.04183"
"94.40000","3.14438","8182.40576","0.03144","818.24060","-0.04183"
"94.60000","3.15104","8178.55469","0.03151","817.85547","-0.04183"
"94.80000","3.15763","8173.23535","0.03158","817.32355","-0.04183"
"95.00000","3.16435","8169.10352","0.03164","816.91034","-0.04182"
"95.20000","3.17089","8162.89014","0.03171","816.28900","-0.04183"
"95.40000","3.17753","8156.41748","0.03178","815.64172","-0.04183"
"95.60000","3.18420","8150.64160","0.03184","815.06415","-0.04183"
"95.80000","3.19100","8144.59766","0.03191","814.45978","-0.04182"
"96.00000","3.19770","8137.96826","0.03198","813.79681","-0.04183"
"96.20000","3.20421","8129.91797","0.03204","812.99182","-0.04183"
"96.40000","3.21113","8126.85840","0.03211","812.68585","-0.04183"
"96.60000","3.21752","8118.95947","0.03218","811.89594","-0.04183"
"96.80000","3.22428","8114.85352","0.03224","811.48535","-0.04183"
"97.00000","3.23088","8109.24756","0.03231","810.92474","-0.04183"
"97.20000","3.23758","8104.04736","0.03238","810.40472","-0.04183"
"97.40000","3.24437","8100.46484","0.03244","810.04651","-0.04183"
"97.60000","3.25090","8093.64014","0.03251","809.36401","-0.04182"
"97.80000","3.25762","8089.18164","0.03258","808.91815","-0.04183"
"98.00000","3.26420","8083.32178","0.03264","808.33215","-0.04183"
"98.20000","3.27110","8080.48633","0.03271","808.04865","-0.04183"
"98.40000","3.27764","8073.78809","0.03278","807.37878","-0.04182"
"98.60000","3.28421","8066.86523","0.03284","806.68652","-0.04182"
"98.80000","3.29105","8062.78271","0.03291","806.27826","-0.04183"
"99.00000","3.29748","8053.51367","0.03297","805.35138","-0.04183"
"99.20000","3.30434","8048.29053","0.03304","804.82904","-0.04182"
"99.40000","3.31089","8040.13770","0.03311","804.01379","-0.04182"
"99.60000","3.31770","8034.24268","0.03318","803.42426","-0.04183"
"99.80000","3.32436","8027.67822","0.03324","802.76782","-0.04183"
"100.00000","3.33097","8020.95459","0.03331","802.09546","-0.04183"
"100.20000","3.33765","8015.44336","0.03338","801.54431","-0.04183"
"100.40000","3.34414","8008.90771","0.03344","800.89075","-0.04183"
"100.60000","3.35101","8006.86768","0.03351","800.68677","-0.04183"
"100.80000","3.35761","8002.53223","0.03358","800.25323","-0.04183"
"101.00000","3.36421","7999.00830","0.03364","799.90082","-0.04183"
"101.20000","3.37105","7998.14014","0.03371","799.81403","-0.04183"
"101.40000","3.37759","7994.34912","0.03378","799.43494","-0.04183"
"101.60000","3.38430","7992.44482","0.03384","799.24451","-0.04183"
"101.80000","3.39088","7989.69189","0.03391","798.96918","-0.04182"
"102.00000","3.39771","7988.54736","0.03398","798.85474","-0.04182"
"102.20000","3.40428","7984.78369","0.03404","798.47839","-0.04183"
"102.40000","3.41088","7980.52783","0.03411","798.05280","-0.04183"
"102.60000","3.41769","7978.17090","0.03418","797.81708","-0.04183"
"102.80000","3.42414","7972.36914","0.03424","797.23694","-0.04183"
"103.00000","3.43097","7970.70947","0.03431","797.07092","-0.04183"
"103.20000","3.43767","7968.60986","0.03438","796.86096","-0.04183"
"103.40000","3.44428","7965.24805","0.03444","796.52478","-0.04182"
"103.60000","3.45097","7963.17969","0.03451","796.31799","-0.04182"
"103.80000","3.45757","7958.58447","0.03458","795.85846","-0.04183"
"104.00000","3.46429","7955.07812","0.03464","795.50781","-0.04183"
"104.20000","3.47076","7948.94482","0.03471","794.89447","-0.04182"
"104.40000","3.47769","7946.85938","0.03478","794.68591","-0.04182"
"104.60000","3.48430","7942.13916","0.03484","794.21393","-0.04183"
"104.80000","3.49090","7937.06641","0.03491","793.70667","-0.04183"
"105.00000","3.49776","7934.79150","0.03498","793.47913","-0.04183"
"105.20000","3.50417","7928.34668","0.03504","792.83466","-0.04182"
"105.40000","3.51089","7924.63867","0.03511","792.46387","-0.04182"
"105.60000","3.51757","7920.87842","0.03518","792.08783","-0.04183"
"105.80000","3.52435","7917.79834","0.03524","791.77985","-0.04183"
"106.00000","3.53091","7913.09473","0.03531","791.30945","-0.04182"
"106.20000","3.53756","7908.64014","0.03538","790.86401","-0.04182"
"106.40000","3.54438","7906.28027","0.03544","790.62805","-0.04183"
"106.60000","3.55083","7899.69873","0.03551","789.96985","-0.04184"
"106.80000","3.55773","7898.15771","0.03558","789.81580","-0.04183"
"107.00000","3.56428","7893.53857","0.03564","789.35388","-0.04182"
"107.20000","3.57089","7889.31836","0.03571","788.93182","-0.04182"
"107.40000","3.57769","7888.54639","0.03578","788.85461","-0.04182"
"107.60000","3.58422","7884.62842","0.03584","788.46283","-0.04182"
"107.80000","3.59087","7882.13525","0.03591","788.21350","-0.04182"
"108.00000","3.59756","7879.58447","0.03598","787.95844","-0.04183"
"108.20000","3.60440","7878.60400","0.03604","787.86041","-0.04184"
"108.40000","3.61099","7874.45020","0.03611","787.44501","-0.04184"
"108.60000","3.61756","7870.75830","0.03618","787.07581","-0.04183"
"108.80000","3.62438","7869.75391","0.03624","786.97540","-0.04182"
"109.00000","3.63083","7865.85352","0.03631","786.58533","-0.04183"
"109.20000","3.63758","7864.90576","0.03638","786.49060","-0.04183"
"109.40000","3.64426","7863.48340","0.03644","786.34833","-0.04182"
"109.60000","3.65092","7861.73486","0.03651","786.17346","-0.04182"
"109.80000","3.65771","7861.82373","0.03658","786.18237","-0.04183"
"110.00000","3.66418","7859.07129","0.03664","785.90710","-0.04183"
"110.20000","3.67101","7859.48193","0.03671","785.94818","-0.04182"
"110.40000","3.67749","7856.06055","0.03677","785.60608","-0.04182"
"110.60000","3.68438","7855.95996","0.03684","785.59601","-0.04183"
"110.80000","3.69092","7852.00439","0.03691","785.20044","-0.04183"
"111.00000","3.69750","7847.80811","0.03698","784.78082","-0.04182"
"111.20000","3.70438","7846.85303","0.03704","784.68530","-0.04182"
"111.40000","3.71081","7841.67773","0.03711","784.16779","-0.04182"
"111.60000","3.71760","7840.09229","0.03718","784.00922","-0.04182"
"111.80000","3.72423","7837.97217","0.03724","783.79724","-0.04183"
"112.00000","3.73103","7837.82959","0.03731","783.78296","-0.04183"
"112.20000","3.73769","7836.68701","0.03738","783.66870","-0.04183"
"112.40000","3.74420","7834.62207","0.03744","783.46222","-0.04183"
"112.60000","3.75095","7835.72217","0.03751","783.57220","-0.04183"
"112.80000","3.75745","7834.98828","0.03757","783.49884","-0.04183"
"113.00000","3.76433","7838.25439","0.03764","783.82544","-0.04182"
"113.20000","3.77088","7839.18066","0.03771","783.91809","-0.04183"
"113.40000","3.77762","7841.12793","0.03778","784.11279","-0.04183"
"113.60000","3.78436","7844.00391","0.03784","784.40039","-0.04183"
"113.80000","3.79090","7844.41162","0.03791","784.44116","-0.04182"
"114.00000","3.79757","7846.31836","0.03798","784.63184","-0.04182"
"114.20000","3.80420","7847.82031","0.03804","784.78204","-0.04183"
"114.40000","3.81103","7851.28760","0.03811","785.12878","-0.04183"
"114.60000","3.81758","7851.88916","0.03818","785.18890","-0.04182"
"114.80000","3.82419","7852.82275","0.03824","785.28229","-0.04183"
"115.00000","3.83098","7855.20312","0.03831","785.52032","-0.04183"
"115.20000","3.83754","7855.04346","0.03838","785.50433","-0.04183"
"115.40000","3.84427","7855.74023","0.03844","785.57404","-0.04182"
"115.60000","3.85093","7855.15088","0.03851","785.51508","-0.04182"
"115.80000","3.85761","7854.03564","0.03858","785.40356","-0.04183"
"116.00000","3.86439","7854.37891","0.03864","785.43787","-0.04183"
"116.20000","3.87091","7851.19922","0.03871","785.11993","-0.04183"
"116.40000","3.87755","7848.85352","0.03878","784.88538","-0.04182"
"116.60000","3.88419","7846.73779","0.03884","784.67377","-0.04183"
"116.80000","3.89100","7845.82178","0.03891","784.58215","-0.04183"
"117.00000","3.89764","7843.69092","0.03898","784.36908","-0.04183"
"117.20000","3.90418","7839.71533","0.03904","783.97156","-0.04182"
"117.40000","3.91106","7840.15283","0.03911","784.01526","-0.04182"
"117.60000","3.91751","7835.74512","0.03918","783.57452","-0.04183"
"117.80000","3.92430","7833.60303","0.03924","783.36029","-0.04183"
"118.00000","3.93093","7830.66748","0.03931","783.06677","-0.04182"
"118.20000","3.93765","7828.27734","0.03938","782.82776","-0.04183"
"118.40000","3.94429","7825.45801","0.03944","782.54578","-0.04183"
"118.60000","3.95086","7822.04053","0.03951","782.20404","-0.04183"
"118.80000","3.95767","7821.01221","0.03958","782.10120","-0.04183"
"119.00000","3.96412","7816.40039","0.03964","781.64001","-0.04182"
"119.20000","3.97100","7816.12549","0.03971","781.61255","-0.04183"
"119.40000","3.97759","7812.63574","0.03978","781.26355","-0.04183"
"119.60000","3.98425","7809.49072","0.03984","780.94910","-0.04182"
"119.80000","3.99110","7808.68359","0.03991","780.86835","-0.04182"
"120.00000","3.99751","7803.68213","0.03998","780.36823","-0.04183"
"120.20000","4.00423","7800.82031","0.04004","780.08203","-0.04184"
"120.40000","4.01087","7796.79932","0.04011","779.67993","-0.04181"
"120.60000","4.01778","7795.92188","0.04018","779.59216","-0.04181"
"120.80000","4.02422","7791.34766","0.04024","779.13477","-0.04182"
"121.00000","4.03084","7788.47803","0.04031","778.84778","-0.04182"
"121.20000","4.03765","7788.29248","0.04038","778.82922","-0.04183"
"121.28400","4.04057","7788.51367","0.04041","778.85138","-0.04182"