File: Tension/Section_1_Group_2/Sunflower_15%-2.is_tens_RawData/Specimen_RawData_1.csv
Time,Extension,Load,Tensile strain (Extension),Tensile stress,Strain-by-clip-gage
(s),(mm),(N),(mm/mm),(MPa),(mm/mm)
"0.00000","0.00000","-2.52834","0.00000","-0.25283","-0.00002"
"0.20000","0.00072","-1.22979","0.00001","-0.12298","0.00000"
"0.40000","0.00479","7.16430","0.00005","0.71643","0.00005"
"0.60000","0.00822","14.12432","0.00008","1.41243","0.00010"
"0.80000","0.01160","20.78406","0.00012","2.07841","0.00014"
"1.00000","0.01501","27.55567","0.00015","2.75557","0.00019"
"1.20000","0.01835","34.15769","0.00018","3.41577","0.00023"
"1.40000","0.02171","40.71833","0.00022","4.07183","0.00027"
"1.60000","0.02496","46.66277","0.00025","4.66628","0.00031"
"1.80000","0.02816","52.81636","0.00028","5.28164","0.00035"
"2.00000","0.03168","59.59774","0.00032","5.95977","0.00039"
"2.20000","0.03513","65.97861","0.00035","6.59786","0.00043"
"2.40000","0.03848","72.04524","0.00038","7.20452","0.00047"
"2.60000","0.04164","77.82226","0.00042","7.78223","0.00050"
"2.80000","0.04495","83.63528","0.00045","8.36353","0.00054"
"3.00000","0.04817","89.15370","0.00048","8.91537","0.00058"
"3.20000","0.05155","94.77737","0.00052","9.47774","0.00061"
"3.40000","0.05507","100.40635","0.00055","10.04064","0.00064"
"3.60000","0.05853","105.07494","0.00059","10.50749","0.00067"
"3.80000","0.06176","109.50931","0.00062","10.95093","0.00070"
"4.00000","0.06494","114.17934","0.00065","11.41793","0.00072"
"4.20000","0.06817","119.58932","0.00068","11.95893","0.00076"
"4.40000","0.07148","125.48351","0.00071","12.54835","0.00079"
"4.60000","0.07496","131.47774","0.00075","13.14777","0.00083"
"4.80000","0.07849","137.73856","0.00078","13.77386","0.00087"
"5.00000","0.08182","143.41957","0.00082","14.34196","0.00090"
"5.20000","0.08502","148.81898","0.00085","14.88190","0.00093"
"5.40000","0.08824","154.44360","0.00088","15.44436","0.00097"
"5.60000","0.09159","160.12405","0.00092","16.01241","0.00100"
"5.80000","0.09495","166.09140","0.00095","16.60914","0.00103"
"6.00000","0.09839","172.12498","0.00098","17.21250","0.00107"
"6.20000","0.10175","177.89966","0.00102","17.78997","0.00110"
"6.40000","0.10506","183.55307","0.00105","18.35531","0.00113"
"6.60000","0.10824","189.10349","0.00108","18.91035","0.00117"
"6.80000","0.11160","194.74739","0.00112","19.47474","0.00120"
"7.00000","0.11496","200.70624","0.00115","20.07062","0.00123"
"7.20000","0.11835","206.28348","0.00118","20.62835","0.00126"
"7.40000","0.12176","212.25473","0.00122","21.22547","0.00130"
"7.60000","0.12501","217.54483","0.00125","21.75448","0.00133"
"7.80000","0.12825","222.98421","0.00128","22.29842","0.00136"
"8.00000","0.13153","228.41185","0.00132","22.84118","0.00139"
"8.20000","0.13499","234.45132","0.00135","23.44513","0.00142"
"8.40000","0.13841","240.08688","0.00138","24.00869","0.00145"
"8.60000","0.14171","245.57330","0.00142","24.55733","0.00148"
"8.80000","0.14507","251.12029","0.00145","25.11203","0.00151"
"9.00000","0.14830","256.42401","0.00148","25.64240","0.00154"
"9.20000","0.15155","261.66678","0.00152","26.16668","0.00157"
"9.40000","0.15486","267.19534","0.00155","26.71953","0.00160"
"9.60000","0.15845","273.23932","0.00158","27.32393","0.00164"
"9.80000","0.16182","278.74548","0.00162","27.87455","0.00167"
"10.00000","0.16507","284.03619","0.00165","28.40362","0.00170"
"10.20000","0.16831","289.19241","0.00168","28.91924","0.00172"
"10.40000","0.17156","294.31485","0.00172","29.43148","0.00175"
"10.60000","0.17485","299.60168","0.00175","29.96017","0.00178"
"10.80000","0.17827","305.16562","0.00178","30.51656","0.00181"
"11.00000","0.18184","310.86380","0.00182","31.08638","0.00184"
"11.20000","0.18511","316.11380","0.00185","31.61138","0.00187"
"11.40000","0.18827","321.01859","0.00188","32.10186","0.00190"
"11.60000","0.19157","326.16351","0.00192","32.61635","0.00193"
"11.80000","0.19485","331.30209","0.00195","33.13021","0.00196"
"12.00000","0.19825","336.62143","0.00198","33.66214","0.00199"
"12.20000","0.20168","342.05972","0.00202","34.20597","0.00201"
"12.40000","0.20516","347.53342","0.00205","34.75334","0.00205"
"12.60000","0.20841","352.53677","0.00208","35.25368","0.00207"
"12.80000","0.21158","357.38837","0.00212","35.73884","0.00210"
"13.00000","0.21496","362.51385","0.00215","36.25138","0.00213"
"13.20000","0.21831","367.66949","0.00218","36.76695","0.00216"
"13.40000","0.22165","372.80469","0.00222","37.28047","0.00218"
"13.60000","0.22506","378.05435","0.00225","37.80544","0.00221"
"13.80000","0.22836","383.04480","0.00228","38.30448","0.00224"
"14.00000","0.23159","387.83023","0.00232","38.78302","0.00227"
"14.20000","0.23488","392.62851","0.00235","39.26285","0.00229"
"14.40000","0.23832","397.96317","0.00238","39.79632","0.00232"
"14.60000","0.24180","403.31543","0.00242","40.33154","0.00235"
"14.80000","0.24506","408.15067","0.00245","40.81507","0.00238"
"15.00000","0.24831","412.95929","0.00248","41.29593","0.00240"
"15.20000","0.25161","417.76901","0.00252","41.77690","0.00243"
"15.40000","0.25485","422.53268","0.00255","42.25327","0.00246"
"15.60000","0.25821","427.32254","0.00258","42.73225","0.00248"
"15.80000","0.26178","432.76999","0.00262","43.27700","0.00251"
"16.00000","0.26522","437.93237","0.00265","43.79324","0.00254"
"16.20000","0.26840","442.28555","0.00268","44.22855","0.00257"
"16.40000","0.27164","446.86050","0.00272","44.68605","0.00259"
"16.60000","0.27488","451.43021","0.00275","45.14302","0.00262"
"16.80000","0.27819","456.11295","0.00278","45.61129","0.00264"
"17.00000","0.28164","461.18655","0.00282","46.11866","0.00267"
"17.20000","0.28516","466.43469","0.00285","46.64347","0.00270"
"17.40000","0.28851","471.16861","0.00289","47.11686","0.00273"
"17.60000","0.29161","475.32480","0.00292","47.53248","0.00275"
"17.80000","0.29490","479.81146","0.00295","47.98115","0.00278"
"18.00000","0.29819","484.41553","0.00298","48.44155","0.00280"
"18.20000","0.30158","489.13174","0.00302","48.91317","0.00283"
"18.40000","0.30506","493.98773","0.00305","49.39877","0.00285"
"18.60000","0.30842","498.79587","0.00308","49.87959","0.00288"
"18.80000","0.31170","503.19656","0.00312","50.31966","0.00291"
"19.00000","0.31490","507.29910","0.00315","50.72991","0.00293"
"19.20000","0.31826","511.86356","0.00318","51.18636","0.00296"
"19.40000","0.32163","516.46875","0.00322","51.64687","0.00298"
"19.60000","0.32505","521.27612","0.00325","52.12761","0.00301"
"19.80000","0.32837","525.65942","0.00328","52.56594","0.00303"
"20.00000","0.33168","529.90710","0.00332","52.99071","0.00306"
"20.20000","0.33492","534.18030","0.00335","53.41803","0.00308"
"20.40000","0.33818","538.44562","0.00338","53.84456","0.00311"
"20.60000","0.34173","543.28802","0.00342","54.32880","0.00313"
"20.80000","0.34511","547.62738","0.00345","54.76274","0.00316"
"21.00000","0.34843","551.88678","0.00348","55.18868","0.00318"
"21.20000","0.35168","556.10681","0.00352","55.61068","0.00321"
"21.40000","0.35490","560.14319","0.00355","56.01432","0.00323"
"21.60000","0.35816","564.36224","0.00358","56.43623","0.00325"
"21.80000","0.36156","568.75220","0.00362","56.87522","0.00328"
"22.00000","0.36510","573.49152","0.00365","57.34915","0.00331"
"22.20000","0.36849","577.89905","0.00368","57.78991","0.00333"
"22.40000","0.37173","581.81232","0.00372","58.18123","0.00335"
"22.60000","0.37495","585.82538","0.00375","58.58254","0.00338"
"22.80000","0.37819","589.76294","0.00378","58.97630","0.00340"
"23.00000","0.38149","593.96143","0.00381","59.39614","0.00343"
"23.20000","0.38502","598.41687","0.00385","59.84169","0.00345"
"23.40000","0.38849","602.79645","0.00388","60.27964","0.00348"
"23.60000","0.39183","606.78436","0.00392","60.67844","0.00350"
"23.80000","0.39501","610.56305","0.00395","61.05630","0.00352"
"24.00000","0.39822","614.41516","0.00398","61.44152","0.00355"
"24.20000","0.40162","618.41400","0.00402","61.84140","0.00357"
"24.40000","0.40485","622.37177","0.00405","62.23717","0.00359"
"24.60000","0.40841","627.00433","0.00408","62.70043","0.00362"
"24.80000","0.41180","631.03632","0.00412","63.10363","0.00364"
"25.00000","0.41505","634.79071","0.00415","63.47907","0.00367"
"25.20000","0.41819","638.30328","0.00418","63.83033","0.00369"
"25.40000","0.42165","642.54968","0.00422","64.25497","0.00371"
"25.60000","0.42493","646.44763","0.00425","64.64476","0.00374"
"25.80000","0.42831","650.31232","0.00428","65.03123","0.00376"
"26.00000","0.43171","654.26556","0.00432","65.42656","0.00378"
"26.20000","0.43501","658.04816","0.00435","65.80482","0.00381"
"26.40000","0.43826","661.64636","0.00438","66.16463","0.00383"
"26.60000","0.44149","665.12640","0.00441","66.51264","0.00385"
"26.80000","0.44507","669.42200","0.00445","66.94220","0.00388"
"27.00000","0.44845","673.22333","0.00448","67.32233","0.00390"
"27.20000","0.45171","676.82019","0.00452","67.68202","0.00392"
"27.40000","0.45501","680.48785","0.00455","68.04878","0.00394"
"27.60000","0.45818","683.83368","0.00458","68.38337","0.00397"
"27.80000","0.46160","687.70160","0.00462","68.77016","0.00399"
"28.00000","0.46486","691.17035","0.00465","69.11703","0.00401"
"28.20000","0.46851","695.46558","0.00469","69.54655","0.00404"
"28.40000","0.47186","699.20770","0.00472","69.92077","0.00406"
"28.60000","0.47507","702.39624","0.00475","70.23962","0.00408"
"28.80000","0.47825","705.66309","0.00478","70.56631","0.00410"
"29.00000","0.48153","709.04877","0.00482","70.90488","0.00412"
"29.20000","0.48486","712.44501","0.00485","71.24450","0.00415"
"29.40000","0.48823","716.18323","0.00488","71.61832","0.00417"
"29.60000","0.49184","720.19586","0.00492","72.01958","0.00419"
"29.80000","0.49513","723.40771","0.00495","72.34077","0.00422"
"30.00000","0.49829","726.54810","0.00498","72.65481","0.00424"
"30.20000","0.50155","729.86035","0.00502","72.98604","0.00426"
"30.40000","0.50495","733.39001","0.00505","73.33900","0.00428"
"30.60000","0.50827","736.77258","0.00508","73.67726","0.00430"
"30.80000","0.51168","740.28455","0.00512","74.02846","0.00433"
"31.00000","0.51513","743.82141","0.00515","74.38214","0.00435"
"31.20000","0.51834","746.89270","0.00518","74.68927","0.00437"
"31.40000","0.52160","750.02826","0.00522","75.00282","0.00439"
"31.60000","0.52491","753.21283","0.00525","75.32128","0.00441"
"31.80000","0.52843","756.85449","0.00528","75.68545","0.00444"
"32.00000","0.53167","759.77502","0.00532","75.97750","0.00446"
"32.20000","0.53506","763.21429","0.00535","76.32143","0.00448"
"32.40000","0.53833","766.31836","0.00538","76.63184","0.00450"
"32.60000","0.54160","769.23578","0.00542","76.92358","0.00452"
"32.80000","0.54486","772.37268","0.00545","77.23727","0.00454"
"33.00000","0.54829","775.68127","0.00548","77.56813","0.00457"
"33.20000","0.55181","779.16205","0.00552","77.91621","0.00459"
"33.40000","0.55509","782.23608","0.00555","78.22361","0.00461"
"33.60000","0.55834","785.18408","0.00558","78.51841","0.00463"
"33.80000","0.56155","787.91968","0.00562","78.79197","0.00465"
"34.00000","0.56487","790.90588","0.00565","79.09059","0.00467"
"34.20000","0.56826","794.10895","0.00568","79.41090","0.00469"
"34.40000","0.57177","797.54608","0.00572","79.75461","0.00472"
"34.60000","0.57519","800.80273","0.00575","80.08028","0.00474"
"34.80000","0.57839","803.55145","0.00578","80.35515","0.00476"
"35.00000","0.58167","806.39722","0.00582","80.63972","0.00478"
"35.20000","0.58484","809.05249","0.00585","80.90525","0.00480"
"35.40000","0.58822","812.14728","0.00588","81.21473","0.00482"
"35.60000","0.59160","815.23676","0.00592","81.52367","0.00484"
"35.80000","0.59518","818.63971","0.00595","81.86397","0.00486"
"36.00000","0.59842","821.56659","0.00598","82.15666","0.00489"
"36.20000","0.60162","824.14032","0.00602","82.41403","0.00491"
"36.40000","0.60494","827.05737","0.00605","82.70573","0.00493"
"36.60000","0.60821","829.90613","0.00608","82.99062","0.00495"
"36.80000","0.61158","832.92572","0.00612","83.29257","0.00497"
"37.00000","0.61503","836.12939","0.00615","83.61294","0.00499"
"37.20000","0.61846","839.11688","0.00618","83.91169","0.00501"
"37.40000","0.62165","841.69525","0.00622","84.16953","0.00503"
"37.60000","0.62490","844.38110","0.00625","84.43811","0.00505"
"37.80000","0.62828","847.53741","0.00628","84.75374","0.00507"
"38.00000","0.63167","850.45422","0.00632","85.04543","0.00509"
"38.20000","0.63501","853.53369","0.00635","85.35337","0.00512"
"38.40000","0.63837","856.41016","0.00638","85.64101","0.00514"
"38.60000","0.64175","859.50970","0.00642","85.95097","0.00516"
"38.80000","0.64488","861.84937","0.00645","86.18494","0.00518"
"39.00000","0.64823","864.81122","0.00648","86.48112","0.00520"
"39.20000","0.65168","867.88123","0.00652","86.78812","0.00522"
"39.40000","0.65510","870.87854","0.00655","87.08785","0.00524"
"39.60000","0.65839","873.56409","0.00658","87.35641","0.00526"
"39.80000","0.66167","876.38574","0.00662","87.63857","0.00528"
"40.00000","0.66492","879.01691","0.00665","87.90169","0.00530"
"40.20000","0.66817","881.78320","0.00668","88.17832","0.00532"
"40.40000","0.67157","884.76324","0.00672","88.47633","0.00534"
"40.60000","0.67512","887.97894","0.00675","88.79790","0.00536"
"40.80000","0.67850","890.93866","0.00679","89.09386","0.00539"
"41.00000","0.68167","893.53955","0.00682","89.35396","0.00540"
"41.20000","0.68496","896.13812","0.00685","89.61382","0.00542"
"41.40000","0.68819","898.73785","0.00688","89.87379","0.00545"
"41.60000","0.69151","901.50854","0.00692","90.15086","0.00546"
"41.80000","0.69501","904.67047","0.00695","90.46705","0.00549"
"42.00000","0.69852","907.78583","0.00699","90.77858","0.00551"
"42.20000","0.70190","910.67896","0.00702","91.06789","0.00553"
"42.40000","0.70492","912.82593","0.00705","91.28259","0.00555"
"42.60000","0.70829","915.65198","0.00708","91.56520","0.00557"
"42.80000","0.71152","918.18207","0.00712","91.81821","0.00559"
"43.00000","0.71492","921.14893","0.00715","92.11489","0.00561"
"43.20000","0.71831","923.94910","0.00718","92.39491","0.00563"
"43.40000","0.72178","926.98785","0.00722","92.69878","0.00565"
"43.60000","0.72506","929.59814","0.00725","92.95982","0.00567"
"43.80000","0.72820","932.02527","0.00728","93.20253","0.00569"
"44.00000","0.73159","934.87811","0.00732","93.48781","0.00571"
"44.20000","0.73500","937.74469","0.00735","93.77447","0.00573"
"44.40000","0.73838","940.61017","0.00738","94.06102","0.00575"
"44.60000","0.74167","943.26642","0.00742","94.32664","0.00577"
"44.80000","0.74500","946.07855","0.00745","94.60786","0.00579"
"45.00000","0.74824","948.31970","0.00748","94.83197","0.00581"
"45.20000","0.75152","951.03125","0.00752","95.10313","0.00583"
"45.40000","0.75507","954.25391","0.00755","95.42539","0.00585"
"45.60000","0.75850","957.14740","0.00758","95.71474","0.00588"
"45.80000","0.76180","959.73785","0.00762","95.97379","0.00589"
"46.00000","0.76496","962.10669","0.00765","96.21067","0.00591"
"46.20000","0.76825","964.62372","0.00768","96.46237","0.00593"
"46.40000","0.77147","966.96283","0.00771","96.69628","0.00595"
"46.60000","0.77491","969.90466","0.00775","96.99046","0.00597"
"46.80000","0.77843","972.93237","0.00778","97.29324","0.00600"
"47.00000","0.78185","975.87939","0.00782","97.58794","0.00602"
"47.20000","0.78508","978.37280","0.00785","97.83728","0.00604"
"47.40000","0.78826","980.71936","0.00788","98.07194","0.00605"
"47.60000","0.79152","983.25964","0.00792","98.32597","0.00607"
"47.80000","0.79484","985.85144","0.00795","98.58514","0.00609"
"48.00000","0.79832","988.78577","0.00798","98.87858","0.00611"
"48.20000","0.80179","991.78253","0.00802","99.17825","0.00614"
"48.40000","0.80509","994.39368","0.00805","99.43937","0.00616"
"48.60000","0.80831","996.62457","0.00808","99.66246","0.00617"
"48.80000","0.81159","999.10107","0.00812","99.91011","0.00619"
"49.00000","0.81496","1001.78857","0.00815","100.17886","0.00621"
"49.20000","0.81830","1004.38513","0.00818","100.43851","0.00623"
"49.40000","0.82173","1007.21100","0.00822","100.72110","0.00625"
"49.60000","0.82507","1009.68762","0.00825","100.96877","0.00627"
"49.80000","0.82835","1012.19220","0.00828","101.21922","0.00629"
"50.00000","0.83154","1014.57526","0.00832","101.45753","0.00631"
"50.20000","0.83498","1017.27710","0.00835","101.72771","0.00633"
"50.40000","0.83833","1019.85803","0.00838","101.98580","0.00635"
"50.60000","0.84170","1022.57782","0.00842","102.25778","0.00637"
"50.80000","0.84507","1025.13318","0.00845","102.51332","0.00639"
"51.00000","0.84831","1027.43835","0.00848","102.74384","0.00641"
"51.20000","0.85156","1029.78223","0.00852","102.97823","0.00643"
"51.40000","0.85486","1032.37964","0.00855","103.23796","0.00645"
"51.60000","0.85836","1035.09143","0.00858","103.50914","0.00647"
"51.80000","0.86175","1037.83789","0.00862","103.78379","0.00649"
"52.00000","0.86505","1040.35596","0.00865","104.03560","0.00651"
"52.20000","0.86837","1042.76050","0.00868","104.27605","0.00653"
"52.40000","0.87160","1045.12720","0.00872","104.51272","0.00655"
"52.60000","0.87490","1047.52820","0.00875","104.75282","0.00657"
"52.80000","0.87826","1050.03394","0.00878","105.00340","0.00659"
"53.00000","0.88183","1052.84521","0.00882","105.28452","0.00661"
"53.20000","0.88516","1055.34351","0.00885","105.53435","0.00663"
"53.40000","0.88838","1057.55676","0.00888","105.75568","0.00665"
"53.60000","0.89161","1059.81396","0.00892","105.98140","0.00667"
"53.80000","0.89488","1062.07227","0.00895","106.20723","0.00668"
"54.00000","0.89817","1064.47522","0.00898","106.44753","0.00670"
"54.20000","0.90164","1067.20874","0.00902","106.72087","0.00672"
"54.40000","0.90516","1070.07458","0.00905","107.00746","0.00675"
"54.60000","0.90845","1072.54810","0.00908","107.25481","0.00676"
"54.80000","0.91159","1074.56030","0.00912","107.45603","0.00678"
"55.00000","0.91492","1077.02637","0.00915","107.70264","0.00680"
"55.20000","0.91824","1079.51038","0.00918","107.95103","0.00682"
"55.40000","0.92160","1081.84021","0.00922","108.18402","0.00684"
"55.60000","0.92503","1084.41382","0.00925","108.44138","0.00686"
"55.80000","0.92846","1086.99194","0.00928","108.69920","0.00688"
"56.00000","0.93168","1089.15442","0.00932","108.91544","0.00690"
"56.20000","0.93489","1091.38159","0.00935","109.13816","0.00692"
"56.40000","0.93833","1093.93323","0.00938","109.39333","0.00694"
"56.60000","0.94170","1096.38989","0.00942","109.63899","0.00696"
"56.80000","0.94503","1098.76831","0.00945","109.87683","0.00698"
"57.00000","0.94835","1101.23914","0.00948","110.12392","0.00699"
"57.20000","0.95164","1103.49634","0.00952","110.34963","0.00701"
"57.40000","0.95491","1105.73328","0.00955","110.57333","0.00703"
"57.60000","0.95819","1108.03223","0.00958","110.80322","0.00705"
"57.80000","0.96171","1110.72229","0.00962","111.07223","0.00707"
"58.00000","0.96518","1113.46924","0.00965","111.34692","0.00709"
"58.20000","0.96840","1115.45264","0.00968","111.54527","0.00711"
"58.40000","0.97165","1117.71704","0.00972","111.77171","0.00713"
"58.60000","0.97492","1119.76624","0.00975","111.97662","0.00715"
"58.80000","0.97817","1121.87598","0.00978","112.18760","0.00716"
"59.00000","0.98158","1124.48608","0.00982","112.44861","0.00718"
"59.20000","0.98511","1127.29614","0.00985","112.72961","0.00720"
"59.40000","0.98854","1129.82385","0.00989","112.98238","0.00722"
"59.60000","0.99169","1131.79163","0.00992","113.17916","0.00724"
"59.80000","0.99495","1133.93115","0.00995","113.39311","0.00726"
"60.00000","0.99824","1136.15527","0.00998","113.61552","0.00728"
"60.20000","1.00154","1138.32153","0.01002","113.83215","0.00730"
"60.40000","1.00499","1140.93176","0.01005","114.09318","0.00732"
"60.60000","1.00848","1143.63110","0.01008","114.36311","0.00734"
"60.80000","1.01180","1145.87488","0.01012","114.58749","0.00736"
"61.00000","1.01494","1147.63989","0.01015","114.76399","0.00737"
"61.20000","1.01826","1149.87097","0.01018","114.98710","0.00739"
"61.40000","1.02157","1152.10596","0.01022","115.21059","0.00741"
"61.60000","1.02497","1154.58887","0.01025","115.45889","0.00743"
"61.80000","1.02836","1156.81775","0.01028","115.68178","0.00745"
"62.00000","1.03170","1159.09302","0.01032","115.90930","0.00747"
"62.20000","1.03499","1161.35632","0.01035","116.13564","0.00748"
"62.40000","1.03820","1163.31580","0.01038","116.33158","0.00750"
"62.60000","1.04164","1165.67700","0.01042","116.56770","0.00752"
"62.80000","1.04502","1168.07983","0.01045","116.80798","0.00754"
"63.00000","1.04840","1170.43640","0.01048","117.04364","0.00756"
"63.20000","1.05171","1172.51599","0.01052","117.25160","0.00758"
"63.40000","1.05498","1174.54077","0.01055","117.45408","0.00759"
"63.60000","1.05824","1176.53857","0.01058","117.65385","0.00761"
"63.80000","1.06155","1178.75769","0.01062","117.87577","0.00763"
"64.00000","1.06508","1181.25903","0.01065","118.12590","0.00765"
"64.20000","1.06847","1183.65857","0.01068","118.36586","0.00767"
"64.40000","1.07176","1185.69849","0.01072","118.56985","0.00769"
"64.60000","1.07499","1187.64697","0.01075","118.76469","0.00770"
"64.80000","1.07821","1189.52527","0.01078","118.95253","0.00772"
"65.00000","1.08148","1191.60559","0.01081","119.16056","0.00774"
"65.20000","1.08494","1194.14148","0.01085","119.41415","0.00776"
"65.40000","1.08844","1196.46265","0.01088","119.64626","0.00778"
"65.60000","1.09181","1198.73718","0.01092","119.87372","0.00779"
"65.80000","1.09502","1200.65918","0.01095","120.06592","0.00781"
"66.00000","1.09827","1202.66980","0.01098","120.26698","0.00783"
"66.20000","1.10156","1204.60400","0.01102","120.46040","0.00785"
"66.40000","1.10485","1206.61743","0.01105","120.66174","0.00786"
"66.60000","1.10838","1209.06128","0.01108","120.90613","0.00788"
"66.80000","1.11180","1211.48828","0.01112","121.14883","0.00790"
"67.00000","1.11510","1213.49316","0.01115","121.34932","0.00792"
"67.20000","1.11830","1215.27576","0.01118","121.52757","0.00794"
"67.40000","1.12156","1217.25513","0.01122","121.72551","0.00795"
"67.60000","1.12497","1219.46741","0.01125","121.94674","0.00797"
"67.80000","1.12825","1221.44495","0.01128","122.14449","0.00799"
"68.00000","1.13175","1223.89624","0.01132","122.38963","0.00801"
"68.20000","1.13509","1225.93347","0.01135","122.59335","0.00803"
"68.40000","1.13834","1227.73376","0.01138","122.77338","0.00804"
"68.60000","1.14151","1229.45679","0.01142","122.94568","0.00806"
"68.80000","1.14502","1231.79224","0.01145","123.17922","0.00808"
"69.00000","1.14831","1233.73071","0.01148","123.37307","0.00809"
"69.20000","1.15167","1235.70410","0.01152","123.57041","0.00811"
"69.40000","1.15505","1237.88037","0.01155","123.78804","0.00813"
"69.60000","1.15830","1239.56775","0.01158","123.95677","0.00815"
"69.80000","1.16158","1241.36670","0.01162","124.13667","0.00816"
"70.00000","1.16482","1243.26965","0.01165","124.32697","0.00818"
"70.20000","1.16844","1245.76587","0.01168","124.57658","0.00820"
"70.40000","1.17180","1247.79468","0.01172","124.77946","0.00821"
"70.60000","1.17505","1249.57568","0.01175","124.95757","0.00823"
"70.80000","1.17834","1251.30066","0.01178","125.13007","0.00825"
"71.00000","1.18149","1252.87610","0.01181","125.28761","0.00826"
"71.20000","1.18491","1254.94409","0.01185","125.49441","0.00828"
"71.40000","1.18825","1256.99011","0.01188","125.69901","0.00829"
"71.60000","1.19187","1259.51501","0.01192","125.95150","0.00831"
"71.80000","1.19520","1261.52417","0.01195","126.15242","0.00833"
"72.00000","1.19837","1263.07092","0.01198","126.30709","0.00834"
"72.20000","1.20157","1264.77173","0.01202","126.47717","0.00836"
"72.40000","1.20486","1266.67383","0.01205","126.66738","0.00838"
"72.60000","1.20821","1268.79724","0.01208","126.87972","0.00839"
"72.80000","1.21161","1271.03430","0.01212","127.10343","0.00841"
"73.00000","1.21515","1273.56934","0.01215","127.35693","0.00843"
"73.20000","1.21843","1275.69141","0.01218","127.56914","0.00844"
"73.40000","1.22161","1277.27576","0.01222","127.72758","0.00846"
"73.60000","1.22492","1279.58350","0.01225","127.95835","0.00847"
"73.80000","1.22829","1281.84131","0.01228","128.18413","0.00849"
"74.00000","1.23163","1284.05054","0.01232","128.40506","0.00851"
"74.20000","1.23505","1286.47119","0.01235","128.64713","0.00852"
"74.40000","1.23843","1288.64636","0.01238","128.86464","0.00854"
"74.60000","1.24161","1290.53784","0.01242","129.05379","0.00856"
"74.80000","1.24490","1292.69226","0.01245","129.26923","0.00857"
"75.00000","1.24829","1295.29736","0.01248","129.52974","0.00859"
"75.20000","1.25180","1297.80371","0.01252","129.78036","0.00861"
"75.40000","1.25504","1300.02795","0.01255","130.00279","0.00862"
"75.60000","1.25836","1302.30286","0.01258","130.23029","0.00864"
"75.80000","1.26161","1304.36865","0.01262","130.43686","0.00866"
"76.00000","1.26489","1306.65894","0.01265","130.66589","0.00867"
"76.20000","1.26820","1308.96289","0.01268","130.89629","0.00869"
"76.40000","1.27165","1311.54639","0.01272","131.15463","0.00871"
"76.60000","1.27518","1314.47925","0.01275","131.44792","0.00873"
"76.80000","1.27843","1316.60339","0.01278","131.66034","0.00874"
"77.00000","1.28166","1318.58215","0.01282","131.85822","0.00876"
"77.20000","1.28487","1320.77222","0.01285","132.07722","0.00877"
"77.40000","1.28820","1323.12573","0.01288","132.31258","0.00879"
"77.60000","1.29160","1325.68298","0.01292","132.56830","0.00881"
"77.80000","1.29513","1328.44141","0.01295","132.84415","0.00883"
"78.00000","1.29851","1330.97876","0.01299","133.09787","0.00884"
"78.20000","1.30167","1332.95618","0.01302","133.29562","0.00886"
"78.40000","1.30500","1335.26172","0.01305","133.52617","0.00888"
"78.60000","1.30819","1337.42957","0.01308","133.74295","0.00889"
"78.80000","1.31160","1339.84253","0.01312","133.98425","0.00891"
"79.00000","1.31498","1342.31311","0.01315","134.23131","0.00893"
"79.20000","1.31847","1345.12256","0.01318","134.51225","0.00894"
"79.40000","1.32171","1347.22949","0.01322","134.72295","0.00896"
"79.60000","1.32493","1349.36865","0.01325","134.93686","0.00898"
"79.80000","1.32828","1351.91785","0.01328","135.19179","0.00899"
"80.00000","1.33158","1354.06250","0.01332","135.40625","0.00901"
"80.20000","1.33494","1356.62720","0.01335","135.66272","0.00903"
"80.40000","1.33839","1359.22864","0.01338","135.92287","0.00904"
"80.60000","1.34175","1361.53870","0.01342","136.15387","0.00906"
"80.80000","1.34497","1363.62683","0.01345","136.36269","0.00908"
"81.00000","1.34820","1365.77344","0.01348","136.57735","0.00909"
"81.20000","1.35161","1368.53638","0.01352","136.85364","0.00911"
"81.40000","1.35504","1371.00073","0.01355","137.10007","0.00913"
"81.60000","1.35839","1373.38391","0.01358","137.33839","0.00914"
"81.80000","1.36171","1375.75403","0.01362","137.57541","0.00916"
"82.00000","1.36505","1377.94580","0.01365","137.79459","0.00918"
"82.20000","1.36820","1380.06885","0.01368","138.00688","0.00919"
"82.40000","1.37159","1382.40393","0.01372","138.24039","0.00921"
"82.60000","1.37502","1384.88245","0.01375","138.48825","0.00923"
"82.80000","1.37845","1387.59790","0.01378","138.75980","0.00924"
"83.00000","1.38169","1389.73560","0.01382","138.97356","0.00926"
"83.20000","1.38500","1392.17419","0.01385","139.21742","0.00927"
"83.40000","1.38824","1394.16248","0.01388","139.41624","0.00929"
"83.60000","1.39150","1396.41602","0.01392","139.64160","0.00931"
"83.80000","1.39493","1398.89404","0.01395","139.88940","0.00932"
"84.00000","1.39848","1401.68457","0.01398","140.16846","0.00934"
"84.20000","1.40184","1404.21277","0.01402","140.42128","0.00936"
"84.40000","1.40497","1406.02771","0.01405","140.60277","0.00937"
"84.60000","1.40829","1408.41980","0.01408","140.84198","0.00939"
"84.80000","1.41153","1410.48022","0.01412","141.04802","0.00941"
"85.00000","1.41487","1412.86365","0.01415","141.28636","0.00942"
"85.20000","1.41838","1415.68738","0.01418","141.56874","0.00944"
"85.40000","1.42182","1418.19458","0.01422","141.81946","0.00946"
"85.60000","1.42518","1420.53259","0.01425","142.05325","0.00948"
"85.80000","1.42822","1422.24707","0.01428","142.22470","0.00949"
"86.00000","1.43162","1424.74097","0.01432","142.47409","0.00951"
"86.20000","1.43490","1426.98389","0.01435","142.69839","0.00952"
"86.40000","1.43829","1429.45007","0.01438","142.94501","0.00954"
"86.60000","1.44167","1431.91370","0.01442","143.19138","0.00956"
"86.80000","1.44507","1434.21558","0.01445","143.42155","0.00957"
"87.00000","1.44834","1436.33545","0.01448","143.63354","0.00959"
"87.20000","1.45152","1438.42480","0.01452","143.84248","0.00960"
"87.40000","1.45497","1441.05701","0.01455","144.10570","0.00962"
"87.60000","1.45837","1443.45886","0.01458","144.34589","0.00964"
"87.80000","1.46174","1445.78223","0.01462","144.57822","0.00966"
"88.00000","1.46499","1447.95862","0.01465","144.79587","0.00967"
"88.20000","1.46831","1450.17322","0.01468","145.01732","0.00969"
"88.40000","1.47155","1452.18140","0.01472","145.21814","0.00970"
"88.60000","1.47485","1454.47742","0.01475","145.44774","0.00972"
"88.80000","1.47844","1457.26953","0.01478","145.72696","0.00974"
"89.00000","1.48186","1459.69666","0.01482","145.96967","0.00976"
"89.20000","1.48513","1461.71838","0.01485","146.17184","0.00977"
"89.40000","1.48829","1463.73926","0.01488","146.37393","0.00979"
"89.60000","1.49158","1465.83118","0.01492","146.58311","0.00980"
"89.80000","1.49481","1467.90295","0.01495","146.79030","0.00982"
"90.00000","1.49828","1470.47485","0.01498","147.04749","0.00983"
"90.20000","1.50175","1472.81226","0.01502","147.28122","0.00985"
"90.40000","1.50519","1475.45630","0.01505","147.54562","0.00987"
"90.60000","1.50837","1477.31104","0.01508","147.73111","0.00988"
"90.80000","1.51158","1479.28674","0.01512","147.92868","0.00990"
"91.00000","1.51488","1481.32764","0.01515","148.13277","0.00992"
"91.20000","1.51819","1483.54443","0.01518","148.35445","0.00993"
"91.40000","1.52168","1486.16443","0.01522","148.61644","0.00995"
"91.60000","1.52510","1488.50354","0.01525","148.85036","0.00997"
"91.80000","1.52838","1490.53003","0.01528","149.05301","0.00998"
"92.00000","1.53162","1492.57593","0.01532","149.25760","0.01000"
"92.20000","1.53493","1494.66321","0.01535","149.46632","0.01001"
"92.40000","1.53830","1497.02051","0.01538","149.70206","0.01003"
"92.60000","1.54167","1499.36108","0.01542","149.93611","0.01005"
"92.80000","1.54509","1501.69446","0.01545","150.16945","0.01006"
"93.00000","1.54838","1503.76746","0.01548","150.37674","0.01008"
"93.20000","1.55167","1505.83484","0.01552","150.58348","0.01009"
"93.40000","1.55486","1507.63513","0.01555","150.76352","0.01011"
"93.60000","1.55833","1510.08411","0.01558","151.00841","0.01013"
"93.80000","1.56169","1512.41614","0.01562","151.24161","0.01014"
"94.00000","1.56506","1514.51270","0.01565","151.45126","0.01017"
"94.20000","1.56839","1516.72229","0.01568","151.67223","0.01018"
"94.40000","1.57159","1518.34277","0.01572","151.83427","0.01020"
"94.60000","1.57487","1520.32751","0.01575","152.03275","0.01021"
"94.73500","1.57726","1522.15552","0.01577","152.21555","0.01022"