File: Tension/Section_2_Group_2/hybrid_low_Sample_1.is_tens_RawData/Specimen_RawData_1.csv
Time,Extension,Load,Tensile strain (Extension),Tensile stress,Strain-by-clip-gage
(s),(mm),(N),(mm/mm),(MPa),(mm/mm)
"0.00000","0.00000","801.63647","0.00000","80.16365","-0.00031"
"0.20000","0.00244","821.88220","0.00002","82.18822","-0.00029"
"0.40000","0.01081","895.90839","0.00011","89.59084","-0.00029"
"0.60000","0.01772","954.48987","0.00018","95.44899","-0.00030"
"0.80000","0.02438","1009.10010","0.00024","100.91001","-0.00032"
"1.00000","0.03097","1062.15015","0.00031","106.21501","-0.00023"
"1.20000","0.03762","1113.96948","0.00038","111.39695","-0.00032"
"1.40000","0.04416","1163.90918","0.00044","116.39091","-0.00032"
"1.60000","0.05109","1215.65222","0.00051","121.56522","-0.00029"
"1.80000","0.05756","1260.72083","0.00058","126.07208","-0.00033"
"2.00000","0.06427","1305.13135","0.00064","130.51314","-0.00030"
"2.20000","0.07104","1347.16980","0.00071","134.71698","-0.00025"
"2.40000","0.07759","1383.29810","0.00078","138.32980","-0.00026"
"2.60000","0.08430","1418.61523","0.00084","141.86153","-0.00028"
"2.80000","0.09091","1451.79822","0.00091","145.17982","-0.00031"
"3.00000","0.09775","1486.33533","0.00098","148.63353","-0.00032"
"3.20000","0.10432","1517.94250","0.00104","151.79425","-0.00030"
"3.40000","0.11098","1549.76343","0.00111","154.97635","-0.00027"
"3.60000","0.11759","1581.85608","0.00118","158.18561","-0.00028"
"3.80000","0.12419","1613.64282","0.00124","161.36429","-0.00031"
"4.00000","0.13095","1647.15833","0.00131","164.71584","-0.00032"
"4.20000","0.13764","1679.68518","0.00138","167.96852","-0.00032"
"4.40000","0.14432","1712.07361","0.00144","171.20737","-0.00030"
"4.60000","0.15110","1745.80212","0.00151","174.58022","-0.00029"
"4.80000","0.15764","1777.48450","0.00158","177.74844","-0.00029"
"5.00000","0.16424","1810.29309","0.00164","181.02931","-0.00030"
"5.20000","0.17091","1843.72363","0.00171","184.37236","-0.00031"
"5.40000","0.17767","1877.63403","0.00178","187.76340","-0.00034"
"5.60000","0.18430","1911.07019","0.00184","191.10703","-0.00028"
"5.80000","0.19088","1943.48120","0.00191","194.34811","-0.00027"
"6.00000","0.19773","1978.63354","0.00198","197.86336","-0.00028"
"6.20000","0.20425","2011.11548","0.00204","201.11154","-0.00034"
"6.40000","0.21105","2046.61621","0.00211","204.66162","-0.00034"
"6.60000","0.21764","2080.72168","0.00218","208.07217","-0.00032"
"6.80000","0.22435","2115.60693","0.00224","211.56070","-0.00031"
"7.00000","0.23107","2151.17798","0.00231","215.11780","-0.00027"
"7.20000","0.23758","2184.29150","0.00238","218.42915","-0.00031"
"7.40000","0.24429","2219.55566","0.00244","221.95557","-0.00031"
"7.60000","0.25075","2252.87939","0.00251","225.28793","-0.00033"
"7.80000","0.25773","2290.86743","0.00258","229.08675","-0.00031"
"8.00000","0.26431","2325.53247","0.00264","232.55325","-0.00028"
"8.20000","0.27106","2361.26855","0.00271","236.12686","-0.00028"
"8.40000","0.27780","2397.40137","0.00278","239.74014","-0.00030"
"8.60000","0.28425","2430.16284","0.00284","243.01628","-0.00032"
"8.80000","0.29094","2466.10449","0.00291","246.61044","-0.00032"
"9.00000","0.29751","2501.03174","0.00298","250.10318","-0.00031"
"9.20000","0.30438","2538.88184","0.00304","253.88818","-0.00029"
"9.40000","0.31091","2573.66797","0.00311","257.36679","-0.00029"
"9.60000","0.31763","2610.48145","0.00318","261.04816","-0.00030"
"9.80000","0.32441","2648.10034","0.00324","264.81003","-0.00032"
"10.00000","0.33093","2682.65942","0.00331","268.26593","-0.00031"
"10.20000","0.33777","2720.66992","0.00338","272.06699","-0.00029"
"10.40000","0.34429","2755.77124","0.00344","275.57712","-0.00027"
"10.60000","0.35096","2792.32349","0.00351","279.23236","-0.00028"
"10.80000","0.35764","2829.17432","0.00358","282.91742","-0.00031"
"11.00000","0.36428","2865.49683","0.00364","286.54968","-0.00032"
"11.20000","0.37092","2902.21777","0.00371","290.22177","-0.00031"
"11.40000","0.37758","2939.28296","0.00378","293.92828","-0.00031"
"11.60000","0.38442","2978.02490","0.00384","297.80249","-0.00031"
"11.80000","0.39103","3014.34497","0.00391","301.43451","-0.00030"
"12.00000","0.39766","3051.11279","0.00398","305.11127","-0.00031"
"12.20000","0.40440","3088.81396","0.00404","308.88141","-0.00031"
"12.40000","0.41088","3124.28540","0.00411","312.42853","-0.00028"
"12.60000","0.41760","3161.52124","0.00418","316.15213","-0.00030"
"12.80000","0.42427","3198.61133","0.00424","319.86115","-0.00031"
"13.00000","0.43094","3235.82471","0.00431","323.58246","-0.00030"
"13.20000","0.43768","3273.95020","0.00438","327.39502","-0.00031"
"13.40000","0.44429","3310.68237","0.00444","331.06824","-0.00031"
"13.60000","0.45109","3349.38403","0.00451","334.93842","-0.00030"
"13.80000","0.45759","3384.74463","0.00458","338.47446","-0.00030"
"14.00000","0.46440","3423.05225","0.00464","342.30524","-0.00031"
"14.20000","0.47097","3459.08325","0.00471","345.90833","-0.00031"
"14.40000","0.47753","3494.82031","0.00478","349.48203","-0.00030"
"14.60000","0.48439","3534.10620","0.00484","353.41061","-0.00030"
"14.80000","0.49083","3568.69482","0.00491","356.86948","-0.00030"
"15.00000","0.49755","3605.95508","0.00498","360.59552","-0.00030"
"15.20000","0.50430","3643.34814","0.00504","364.33481","-0.00031"
"15.40000","0.51120","3682.08325","0.00511","368.20831","-0.00031"
"15.60000","0.51772","3717.15161","0.00518","371.71515","-0.00030"
"15.80000","0.52427","3752.15332","0.00524","375.21533","-0.00030"
"16.00000","0.53096","3788.57227","0.00531","378.85724","-0.00030"
"16.20000","0.53746","3822.55396","0.00537","382.25540","-0.00031"
"16.40000","0.54440","3860.99976","0.00544","386.09998","-0.00031"
"16.60000","0.55091","3894.97998","0.00551","389.49799","-0.00031"
"16.80000","0.55763","3930.74414","0.00558","393.07440","-0.00030"
"17.00000","0.56443","3967.97778","0.00564","396.79779","-0.00029"
"17.20000","0.57100","4001.99487","0.00571","400.19949","-0.00030"
"17.40000","0.57763","4036.65259","0.00578","403.66525","-0.00031"
"17.60000","0.58420","4070.47559","0.00584","407.04755","-0.00031"
"17.80000","0.59108","4107.45361","0.00591","410.74536","-0.00030"
"18.00000","0.59763","4140.52246","0.00598","414.05225","-0.00029"
"18.20000","0.60423","4174.04150","0.00604","417.40414","-0.00030"
"18.40000","0.61101","4209.37207","0.00611","420.93719","-0.00031"
"18.60000","0.61753","4241.70898","0.00618","424.17090","-0.00031"
"18.80000","0.62433","4276.72266","0.00624","427.67227","-0.00031"
"19.00000","0.63102","4310.51367","0.00631","431.05136","-0.00030"
"19.20000","0.63770","4343.81494","0.00638","434.38150","-0.00029"
"19.40000","0.64437","4377.04297","0.00644","437.70428","-0.00030"
"19.60000","0.65094","4409.07910","0.00651","440.90790","-0.00031"
"19.80000","0.65760","4441.76367","0.00658","444.17636","-0.00030"
"20.00000","0.66415","4473.01514","0.00664","447.30151","-0.00030"
"20.20000","0.67100","4507.49463","0.00671","450.74945","-0.00030"
"20.40000","0.67766","4525.76611","0.00678","452.57660","-0.00030"
"20.60000","0.68430","4557.05859","0.00684","455.70587","-0.00031"
"20.80000","0.69114","4590.52490","0.00691","459.05249","-0.00031"
"21.00000","0.69756","4619.01367","0.00698","461.90137","-0.00030"
"21.20000","0.70427","4650.91357","0.00704","465.09137","-0.00030"
"21.40000","0.71088","4681.89697","0.00711","468.18970","-0.00030"
"21.60000","0.71771","4714.53174","0.00718","471.45319","-0.00030"
"21.80000","0.72432","4744.63379","0.00724","474.46338","-0.00032"
"22.00000","0.73092","4773.99219","0.00731","477.39923","-0.00032"
"22.20000","0.73768","4804.98047","0.00738","480.49805","-0.00030"
"22.40000","0.74422","4833.58838","0.00744","483.35883","-0.00029"
"22.60000","0.75102","4864.07471","0.00751","486.40747","-0.00029"
"22.80000","0.75762","4892.96436","0.00758","489.29645","-0.00030"
"23.00000","0.76431","4919.76514","0.00764","491.97650","-0.00032"
"23.20000","0.77107","4947.62012","0.00771","494.76202","-0.00031"
"23.40000","0.77756","4974.06885","0.00778","497.40689","-0.00030"
"23.60000","0.78427","5003.16602","0.00784","500.31659","-0.00029"
"23.80000","0.79084","5031.52734","0.00791","503.15274","-0.00030"
"24.00000","0.79778","5063.55664","0.00798","506.35565","-0.00031"
"24.20000","0.80433","5091.60742","0.00804","509.16074","-0.00031"
"24.40000","0.81094","5119.89893","0.00811","511.98990","-0.00030"
"24.60000","0.81773","5150.07080","0.00818","515.00708","-0.00030"
"24.80000","0.82419","5176.66846","0.00824","517.66687","-0.00031"
"25.00000","0.83094","5206.48438","0.00831","520.64844","-0.00031"
"25.20000","0.83762","5235.11523","0.00838","523.51154","-0.00031"
"25.40000","0.84432","5260.01367","0.00844","526.00134","-0.00030"
"25.60000","0.85104","5284.37061","0.00851","528.43707","-0.00029"
"25.80000","0.85761","5309.14551","0.00858","530.91455","-0.00029"
"26.00000","0.86431","5335.52490","0.00864","533.55249","-0.00031"
"26.20000","0.87089","5361.58740","0.00871","536.15875","-0.00032"
"26.40000","0.87770","5390.00684","0.00878","539.00067","-0.00031"
"26.60000","0.88428","5416.12109","0.00884","541.61212","-0.00030"
"26.80000","0.89089","5442.58008","0.00891","544.25800","-0.00029"
"27.00000","0.89776","5471.60596","0.00898","547.16058","-0.00030"
"27.20000","0.90421","5495.88379","0.00904","549.58838","-0.00031"
"27.40000","0.91097","5523.18604","0.00911","552.31860","-0.00032"
"27.60000","0.91762","5550.01611","0.00918","555.00159","-0.00031"
"27.80000","0.92439","5576.93750","0.00924","557.69373","-0.00030"
"28.00000","0.93096","5602.68066","0.00931","560.26807","-0.00029"
"28.20000","0.93752","5625.63477","0.00938","562.56348","-0.00030"
"28.40000","0.94431","5651.89062","0.00944","565.18909","-0.00031"
"28.60000","0.95083","5672.71973","0.00951","567.27197","-0.00031"
"28.80000","0.95773","5641.69678","0.00958","564.16968","-0.00030"
"29.00000","0.96429","5666.60010","0.00964","566.66003","-0.00030"
"29.20000","0.97093","5694.38379","0.00971","569.43835","-0.00030"
"29.40000","0.97781","5711.24170","0.00978","571.12415","-0.00031"
"29.60000","0.98428","5711.10889","0.00984","571.11090","-0.00030"
"29.80000","0.99087","5737.08691","0.00991","573.70868","-0.00031"
"30.00000","0.99750","5763.63770","0.00998","576.36377","-0.00029"
"30.20000","1.00443","5792.99707","0.01004","579.29968","-0.00030"
"30.40000","1.01093","5817.11035","0.01011","581.71106","-0.00031"
"30.60000","1.01759","5842.01611","0.01018","584.20160","-0.00031"
"30.80000","1.02436","5868.81787","0.01024","586.88177","-0.00031"
"31.00000","1.03085","5892.29004","0.01031","589.22900","-0.00031"
"31.20000","1.03773","5919.26709","0.01038","591.92670","-0.00029"
"31.40000","1.04428","5940.46729","0.01044","594.04675","-0.00030"
"31.60000","1.05097","5962.17139","0.01051","596.21716","-0.00031"
"31.80000","1.05766","5986.19482","0.01058","598.61951","-0.00031"
"32.00000","1.06425","6008.35547","0.01064","600.83557","-0.00030"
"32.20000","1.07090","6030.99658","0.01071","603.09967","-0.00030"
"32.40000","1.07753","6050.52002","0.01078","605.05200","-0.00030"
"32.60000","1.08439","6074.35498","0.01084","607.43549","-0.00031"
"32.80000","1.09098","6094.95068","0.01091","609.49506","-0.00031"
"33.00000","1.09759","6115.79248","0.01098","611.57922","-0.00031"
"33.20000","1.10445","6139.21826","0.01104","613.92181","-0.00030"
"33.40000","1.11086","6157.60254","0.01111","615.76025","-0.00029"
"33.60000","1.11757","6178.22070","0.01118","617.82208","-0.00030"
"33.80000","1.12426","6199.33740","0.01124","619.93372","-0.00031"
"34.00000","1.13097","6220.46875","0.01131","622.04688","-0.00031"
"34.20000","1.13773","6242.03809","0.01138","624.20380","-0.00031"
"34.40000","1.14424","6260.48291","0.01144","626.04828","-0.00030"
"34.60000","1.15101","6281.59961","0.01151","628.15997","-0.00030"
"34.80000","1.15752","6300.30420","0.01158","630.03040","-0.00030"
"35.00000","1.16442","6321.68652","0.01164","632.16864","-0.00031"
"35.20000","1.17094","6339.52783","0.01171","633.95276","-0.00031"
"35.40000","1.17757","6357.61670","0.01178","635.76166","-0.00030"
"35.60000","1.18437","6377.67188","0.01184","637.76721","-0.00029"
"35.80000","1.19086","6394.35596","0.01191","639.43561","-0.00030"
"36.00000","1.19757","6412.95898","0.01198","641.29590","-0.00031"
"36.20000","1.20421","6431.34717","0.01204","643.13470","-0.00031"
"36.40000","1.21109","6451.66016","0.01211","645.16602","-0.00030"
"36.60000","1.21769","6468.63867","0.01218","646.86389","-0.00030"
"36.80000","1.22426","6484.57129","0.01224","648.45715","-0.00030"
"37.00000","1.23106","6503.39062","0.01231","650.33905","-0.00031"
"37.20000","1.23746","6518.10742","0.01237","651.81073","-0.00031"
"37.40000","1.24425","6536.75293","0.01244","653.67529","-0.00031"
"37.60000","1.25093","6554.35254","0.01251","655.43524","-0.00030"
"37.80000","1.25774","6572.52002","0.01258","657.25201","-0.00029"
"38.00000","1.26432","6588.40479","0.01264","658.84045","-0.00030"
"38.20000","1.27092","6604.04199","0.01271","660.40417","-0.00031"
"38.40000","1.27762","6620.78613","0.01278","662.07861","-0.00031"
"38.60000","1.28418","6636.02051","0.01284","663.60205","-0.00031"
"38.80000","1.29110","6654.64795","0.01291","665.46478","-0.00030"
"39.00000","1.29761","6669.32812","0.01298","666.93280","-0.00030"
"39.20000","1.30421","6684.63574","0.01304","668.46356","-0.00030"
"39.40000","1.31104","6702.70752","0.01311","670.27075","-0.00031"
"39.60000","1.31755","6716.65381","0.01318","671.66541","-0.00030"
"39.80000","1.32423","6732.44531","0.01324","673.24451","-0.00030"
"40.00000","1.33097","6748.39404","0.01331","674.83942","-0.00030"
"40.20000","1.33772","6764.79785","0.01338","676.47980","-0.00030"
"40.40000","1.34437","6779.87646","0.01344","677.98767","-0.00031"
"40.60000","1.35093","6793.49219","0.01351","679.34924","-0.00031"
"40.80000","1.35764","6808.72559","0.01358","680.87256","-0.00030"
"41.00000","1.36419","6822.18164","0.01364","682.21814","-0.00030"
"41.20000","1.37097","6838.33887","0.01371","683.83386","-0.00030"
"41.40000","1.37766","6853.71826","0.01378","685.37183","-0.00030"
"41.60000","1.38425","6867.21045","0.01384","686.72107","-0.00031"
"41.80000","1.39111","6883.81787","0.01391","688.38177","-0.00031"
"42.00000","1.39754","6895.35352","0.01398","689.53534","-0.00030"
"42.20000","1.40434","6908.88330","0.01404","690.88831","-0.00030"
"42.40000","1.41093","6921.58643","0.01411","692.15863","-0.00030"
"42.60000","1.41772","6936.64453","0.01418","693.66443","-0.00031"
"42.80000","1.42431","6949.48877","0.01424","694.94885","-0.00031"
"43.00000","1.43086","6961.11621","0.01431","696.11163","-0.00030"
"43.20000","1.43775","6976.52051","0.01438","697.65204","-0.00030"
"43.40000","1.44417","6986.98779","0.01444","698.69879","-0.00030"
"43.60000","1.45099","7001.55811","0.01451","700.15582","-0.00030"
"43.80000","1.45758","7014.13916","0.01458","701.41394","-0.00031"
"44.00000","1.46433","7026.69092","0.01464","702.66907","-0.00031"
"44.20000","1.47111","7040.80176","0.01471","704.08020","-0.00030"
"44.40000","1.47762","7051.28467","0.01478","705.12848","-0.00030"
"44.60000","1.48423","7062.95068","0.01484","706.29504","-0.00030"
"44.80000","1.49084","7074.54590","0.01491","707.45459","-0.00030"
"45.00000","1.49778","7089.32129","0.01498","708.93213","-0.00031"
"45.20000","1.50426","7099.21631","0.01504","709.92163","-0.00031"
"45.40000","1.51090","7109.94824","0.01511","710.99481","-0.00030"
"45.60000","1.51769","7122.49414","0.01518","712.24939","-0.00030"
"45.80000","1.52424","7131.98047","0.01524","713.19806","-0.00030"
"46.00000","1.53108","7143.81250","0.01531","714.38123","-0.00030"
"46.20000","1.53761","7152.33105","0.01538","715.23309","-0.00031"
"46.40000","1.54436","7162.79199","0.01544","716.27917","-0.00030"
"46.60000","1.55101","7172.57910","0.01551","717.25793","-0.00030"
"46.80000","1.55759","7180.68408","0.01558","718.06842","-0.00030"
"47.00000","1.56425","7189.94824","0.01564","718.99481","-0.00030"
"47.20000","1.57087","7198.42822","0.01571","719.84283","-0.00031"
"47.40000","1.57771","7208.67285","0.01578","720.86731","-0.00031"
"47.60000","1.58433","7216.83643","0.01584","721.68365","-0.00030"
"47.80000","1.59095","7224.31445","0.01591","722.43146","-0.00030"
"48.00000","1.59777","7222.90430","0.01598","722.29041","-0.00030"
"48.20000","1.60424","7230.21338","0.01604","723.02136","-0.00031"
"48.40000","1.61092","7238.20166","0.01611","723.82019","-0.00031"
"48.60000","1.61761","7229.66650","0.01618","722.96667","-0.00031"
"48.80000","1.62435","7240.09180","0.01624","724.00916","-0.00030"
"49.00000","1.63101","7250.61133","0.01631","725.06116","-0.00030"
"49.20000","1.63752","7259.52441","0.01638","725.95245","-0.00030"
"49.40000","1.64438","7272.40674","0.01644","727.24066","-0.00031"
"49.60000","1.65087","7281.21777","0.01651","728.12177","-0.00030"
"49.80000","1.65779","7294.28809","0.01658","729.42883","-0.00030"
"50.00000","1.66435","7303.78027","0.01664","730.37805","-0.00030"
"50.20000","1.67096","7312.81885","0.01671","731.28186","-0.00031"
"50.40000","1.67775","7324.15186","0.01678","732.41516","-0.00031"
"50.60000","1.68421","7331.42432","0.01684","733.14246","-0.00031"
"50.80000","1.69092","7341.20605","0.01691","734.12061","-0.00030"
"51.00000","1.69745","7349.27295","0.01697","734.92731","-0.00030"
"51.20000","1.70442","7361.37793","0.01704","736.13782","-0.00030"
"51.40000","1.71102","7369.35645","0.01711","736.93567","-0.00031"
"51.60000","1.71773","7377.83691","0.01718","737.78369","-0.00031"
"51.80000","1.72445","7386.83105","0.01724","738.68311","-0.00031"
"52.00000","1.73087","7392.07031","0.01731","739.20703","-0.00030"
"52.20000","1.73762","7400.30273","0.01738","740.03027","-0.00030"
"52.40000","1.74424","7406.11719","0.01744","740.61169","-0.00030"
"52.60000","1.75100","7413.35010","0.01751","741.33502","-0.00031"
"52.80000","1.75765","7419.52051","0.01758","741.95203","-0.00032"
"53.00000","1.76427","7424.52441","0.01764","742.45245","-0.00030"
"53.20000","1.77103","7431.25879","0.01771","743.12585","-0.00029"
"53.40000","1.77759","7435.13867","0.01778","743.51385","-0.00030"
"53.60000","1.78447","7441.94141","0.01784","744.19415","-0.00031"
"53.80000","1.79097","7444.39453","0.01791","744.43945","-0.00031"
"54.00000","1.79762","7447.53174","0.01798","744.75317","-0.00031"
"54.20000","1.80434","7450.86816","0.01804","745.08679","-0.00030"
"54.40000","1.81091","7451.78223","0.01811","745.17822","-0.00029"
"54.60000","1.81757","7453.27197","0.01818","745.32721","-0.00030"
"54.80000","1.82424","7454.62500","0.01824","745.46252","-0.00031"
"55.00000","1.83108","7456.58057","0.01831","745.65808","-0.00032"
"55.20000","1.83778","7456.71387","0.01838","745.67139","-0.00031"
"55.40000","1.84431","7454.59570","0.01844","745.45959","-0.00030"
"55.60000","1.85106","7455.14404","0.01851","745.51440","-0.00030"
"55.80000","1.85752","7452.65039","0.01858","745.26501","-0.00030"
"56.00000","1.86427","7453.07959","0.01864","745.30798","-0.00031"
"56.20000","1.87097","7453.50049","0.01871","745.35004","-0.00031"
"56.40000","1.87756","7451.74268","0.01878","745.17426","-0.00030"
"56.60000","1.88438","7453.54053","0.01884","745.35406","-0.00030"
"56.80000","1.89097","7452.13184","0.01891","745.21320","-0.00030"
"57.00000","1.89776","7453.14941","0.01898","745.31494","-0.00031"
"57.20000","1.90425","7451.76367","0.01904","745.17639","-0.00031"
"57.40000","1.91107","7454.00586","0.01911","745.40057","-0.00031"
"57.60000","1.91767","7454.13672","0.01918","745.41370","-0.00030"
"57.80000","1.92422","7453.58447","0.01924","745.35846","-0.00030"
"58.00000","1.93106","7456.44727","0.01931","745.64471","-0.00030"
"58.20000","1.93747","7454.77441","0.01937","745.47742","-0.00031"
"58.40000","1.94425","7457.53662","0.01944","745.75366","-0.00031"
"58.60000","1.95100","7460.71777","0.01951","746.07178","-0.00030"
"58.80000","1.95785","7464.41016","0.01958","746.44104","-0.00029"
"59.00000","1.96441","7465.70752","0.01964","746.57074","-0.00031"
"59.20000","1.97096","7466.39014","0.01971","746.63904","-0.00032"
"59.40000","1.97767","7468.64453","0.01978","746.86444","-0.00032"
"59.60000","1.98413","7468.55273","0.01984","746.85529","-0.00031"
"59.80000","1.99103","7473.33594","0.01991","747.33362","-0.00029"
"60.00000","1.99760","7474.13867","0.01998","747.41388","-0.00029"
"60.20000","2.00428","7475.56445","0.02004","747.55646","-0.00030"
"60.40000","2.01112","7478.90381","0.02011","747.89038","-0.00031"
"60.60000","2.01765","7478.22314","0.02018","747.82233","-0.00031"
"60.80000","2.02437","7479.72510","0.02024","747.97253","-0.00030"
"61.00000","2.03090","7479.46582","0.02031","747.94659","-0.00029"
"61.20000","2.03772","7482.21484","0.02038","748.22150","-0.00030"
"61.40000","2.04430","7481.99951","0.02044","748.19995","-0.00031"
"61.60000","2.05090","7481.39014","0.02051","748.13904","-0.00031"
"61.80000","2.05763","7480.96045","0.02058","748.09607","-0.00031"
"62.00000","2.06419","7477.93994","0.02064","747.79401","-0.00030"
"62.20000","2.07107","7477.82959","0.02071","747.78296","-0.00030"
"62.40000","2.07773","7475.56836","0.02078","747.55682","-0.00030"
"62.60000","2.08433","7472.63379","0.02084","747.26337","-0.00031"
"62.80000","2.09103","7471.33789","0.02091","747.13379","-0.00031"
"63.00000","2.09758","7468.57471","0.02098","746.85748","-0.00030"
"63.20000","2.10424","7466.08203","0.02104","746.60822","-0.00030"
"63.40000","2.11086","7463.23633","0.02111","746.32361","-0.00030"
"63.60000","2.11770","7462.20361","0.02118","746.22034","-0.00031"
"63.80000","2.12433","7459.10693","0.02124","745.91071","-0.00031"
"64.00000","2.13091","7455.13574","0.02131","745.51355","-0.00031"
"64.20000","2.13779","7454.53076","0.02138","745.45306","-0.00029"
"64.40000","2.14423","7449.00488","0.02144","744.90051","-0.00030"
"64.60000","2.15100","7446.42529","0.02151","744.64252","-0.00030"
"64.80000","2.15760","7442.32471","0.02158","744.23248","-0.00031"
"65.00000","2.16433","7438.28125","0.02164","743.82812","-0.00031"
"65.20000","2.17103","7435.03027","0.02171","743.50305","-0.00030"
"65.40000","2.17756","7430.23926","0.02178","743.02393","-0.00030"
"65.60000","2.18429","7428.53418","0.02184","742.85339","-0.00030"
"65.80000","2.19091","7425.76807","0.02191","742.57678","-0.00031"
"66.00000","2.19778","7425.80762","0.02198","742.58075","-0.00031"
"66.20000","2.20433","7422.76172","0.02204","742.27618","-0.00030"
"66.40000","2.21096","7420.59570","0.02211","742.05957","-0.00030"
"66.60000","2.21773","7420.72168","0.02218","742.07214","-0.00030"
"66.80000","2.22417","7416.90479","0.02224","741.69049","-0.00030"
"67.00000","2.23098","7416.93359","0.02231","741.69336","-0.00032"
"67.20000","2.23757","7414.02637","0.02238","741.40265","-0.00031"
"67.40000","2.24444","7413.00293","0.02244","741.30029","-0.00030"
"67.60000","2.25104","7408.78369","0.02251","740.87836","-0.00030"
"67.80000","2.25762","7403.63281","0.02258","740.36328","-0.00030"
"68.00000","2.26437","7400.62207","0.02264","740.06219","-0.00031"
"68.20000","2.27084","7395.24951","0.02271","739.52496","-0.00031"
"68.40000","2.27768","7394.35693","0.02278","739.43567","-0.00030"
"68.60000","2.28430","7390.52393","0.02284","739.05237","-0.00029"
"68.80000","2.29097","7387.06836","0.02291","738.70685","-0.00029"
"69.00000","2.29773","7384.70850","0.02298","738.47083","-0.00030"
"69.20000","2.30424","7379.98242","0.02304","737.99823","-0.00032"
"69.40000","2.31096","7377.42480","0.02311","737.74249","-0.00032"
"69.60000","2.31759","7374.10938","0.02318","737.41095","-0.00031"
"69.80000","2.32441","7371.14453","0.02324","737.11444","-0.00030"
"70.00000","2.33095","7365.55957","0.02331","736.55597","-0.00030"
"70.20000","2.33757","7360.38818","0.02338","736.03882","-0.00031"
"70.40000","2.34441","7357.56104","0.02344","735.75610","-0.00031"
"70.60000","2.35084","7350.27197","0.02351","735.02722","-0.00031"
"70.80000","2.35765","7346.58740","0.02358","734.65875","-0.00029"
"71.00000","2.36430","7341.13477","0.02364","734.11346","-0.00029"
"71.20000","2.37102","7335.48682","0.02371","733.54871","-0.00031"
"71.40000","2.37768","7329.48193","0.02378","732.94818","-0.00031"
"71.60000","2.38425","7321.76221","0.02384","732.17621","-0.00031"
"71.80000","2.39099","7314.84082","0.02391","731.48407","-0.00030"
"72.00000","2.39748","7304.97607","0.02397","730.49762","-0.00029"
"72.20000","2.40438","7298.90820","0.02404","729.89081","-0.00030"
"72.40000","2.41097","7289.70703","0.02411","728.97070","-0.00031"
"72.60000","2.41761","7279.03174","0.02418","727.90320","-0.00031"
"72.80000","2.42454","7271.39990","0.02425","727.14001","-0.00031"
"73.00000","2.43090","7257.22070","0.02431","725.72205","-0.00030"
"73.20000","2.43751","7245.98193","0.02438","724.59821","-0.00030"
"73.40000","2.44422","7236.40918","0.02444","723.64093","-0.00031"
"73.60000","2.45108","7229.26758","0.02451","722.92676","-0.00031"
"73.80000","2.45764","7219.12256","0.02458","721.91223","-0.00031"
"74.00000","2.46425","7208.70801","0.02464","720.87079","-0.00030"
"74.20000","2.47102","7200.05859","0.02471","720.00586","-0.00030"
"74.40000","2.47750","7188.54053","0.02478","718.85406","-0.00030"
"74.60000","2.48441","7181.57666","0.02484","718.15765","-0.00031"
"74.80000","2.49099","7171.20752","0.02491","717.12073","-0.00032"
"75.00000","2.49759","7161.42871","0.02498","716.14288","-0.00030"
"75.20000","2.50437","7154.35449","0.02504","715.43542","-0.00030"
"75.40000","2.51092","7144.66260","0.02511","714.46625","-0.00030"
"75.60000","2.51756","7136.65918","0.02518","713.66589","-0.00031"
"75.80000","2.52425","7129.72656","0.02524","712.97266","-0.00031"
"76.00000","2.53108","7123.79736","0.02531","712.37976","-0.00031"
"76.20000","2.53763","7114.78418","0.02538","711.47839","-0.00030"
"76.40000","2.54426","7105.46582","0.02544","710.54657","-0.00029"
"76.60000","2.55112","7097.80176","0.02551","709.78015","-0.00030"
"76.80000","2.55753","7085.09961","0.02558","708.50995","-0.00031"
"77.00000","2.56426","7075.05664","0.02564","707.50568","-0.00031"
"77.20000","2.57095","7065.11084","0.02571","706.51111","-0.00030"
"77.40000","2.57762","7054.10840","0.02578","705.41083","-0.00030"
"77.60000","2.58441","7045.93213","0.02584","704.59320","-0.00030"
"77.80000","2.59092","7034.09326","0.02591","703.40930","-0.00030"
"78.00000","2.59767","7023.85059","0.02598","702.38507","-0.00031"
"78.20000","2.60422","7012.32422","0.02604","701.23242","-0.00031"
"78.40000","2.61112","7004.46289","0.02611","700.44629","-0.00030"
"78.60000","2.61760","6992.20508","0.02618","699.22052","-0.00030"
"78.80000","2.62418","6979.92529","0.02624","697.99255","-0.00030"
"79.00000","2.63105","6970.79688","0.02631","697.07971","-0.00031"
"79.20000","2.63753","6957.29980","0.02638","695.72998","-0.00031"
"79.40000","2.64428","6945.24951","0.02644","694.52496","-0.00030"
"79.60000","2.65093","6932.20361","0.02651","693.22034","-0.00030"
"79.80000","2.65774","6920.33008","0.02658","692.03302","-0.00030"
"80.00000","2.66436","6906.89990","0.02664","690.69000","-0.00030"
"80.20000","2.67090","6892.36133","0.02671","689.23615","-0.00031"
"80.40000","2.67766","6880.66846","0.02678","688.06683","-0.00031"
"80.60000","2.68413","6866.99072","0.02684","686.69910","-0.00030"
"80.80000","2.69097","6857.20654","0.02691","685.72064","-0.00029"
"81.00000","2.69760","6845.95801","0.02698","684.59583","-0.00030"
"81.20000","2.70432","6835.24023","0.02704","683.52405","-0.00031"
"81.40000","2.71104","6826.11230","0.02711","682.61121","-0.00031"
"81.60000","2.71758","6815.98047","0.02718","681.59802","-0.00031"
"81.80000","2.72428","6808.41113","0.02724","680.84113","-0.00030"
"82.00000","2.73088","6801.40771","0.02731","680.14075","-0.00030"
"82.20000","2.73778","6797.69824","0.02738","679.76984","-0.00030"
"82.40000","2.74429","6790.41211","0.02744","679.04120","-0.00031"
"82.60000","2.75086","6783.28271","0.02751","678.32825","-0.00031"
"82.80000","2.75765","6778.60059","0.02758","677.86005","-0.00031"
"83.00000","2.76421","6771.48828","0.02764","677.14880","-0.00030"
"83.20000","2.77095","6766.10791","0.02771","676.61078","-0.00029"
"83.40000","2.77764","6760.55762","0.02778","676.05579","-0.00030"
"83.60000","2.78436","6755.05029","0.02784","675.50500","-0.00031"
"83.80000","2.79108","6749.59473","0.02791","674.95947","-0.00031"
"84.00000","2.79760","6740.77197","0.02798","674.07721","-0.00030"
"84.20000","2.80425","6732.70215","0.02804","673.27020","-0.00031"
"84.40000","2.81087","6723.77588","0.02811","672.37756","-0.00030"
"84.60000","2.81769","6715.70898","0.02818","671.57092","-0.00031"
"84.80000","2.82435","6703.81201","0.02824","670.38123","-0.00032"
"85.00000","2.83091","6690.35986","0.02831","669.03601","-0.00030"
"85.16500","2.83652","6680.98633","0.02837","668.09863","-0.00031"