File: Tension/Section_2_Group_2/Hybrid_High_Sample_1.is_tens_RawData/Specimen_RawData_1.csv
Time,Extension,Load,Tensile strain (Extension),Tensile stress,Strain-by-clip-gage
(s),(mm),(N),(mm/mm),(MPa),(mm/mm)
"0.00000","0.00000","0.29028","0.00000","0.02903","-0.00002"
"0.10000","0.00057","3.18429","0.00001","0.31843","0.00001"
"0.20000","0.00239","14.38271","0.00002","1.43827","0.00000"
"0.30000","0.00741","41.92852","0.00007","4.19285","0.00001"
"0.40000","0.01066","58.11953","0.00011","5.81195","0.00001"
"0.50000","0.01410","74.54263","0.00014","7.45426","-0.00001"
"0.60000","0.01743","89.63995","0.00017","8.96399","0.00001"
"0.70000","0.02073","104.10529","0.00021","10.41053","-0.00001"
"0.80000","0.02406","118.28893","0.00024","11.82889","0.00000"
"0.90000","0.02753","132.55522","0.00028","13.25552","0.00000"
"1.00000","0.03090","146.00105","0.00031","14.60011","-0.00002"
"1.10000","0.03397","157.47093","0.00034","15.74709","0.00001"
"1.20000","0.03749","170.89836","0.00037","17.08984","0.00000"
"1.30000","0.04080","182.70984","0.00041","18.27098","0.00003"
"1.40000","0.04406","194.34111","0.00044","19.43411","0.00001"
"1.50000","0.04746","206.32019","0.00047","20.63202","-0.00002"
"1.60000","0.05086","217.63556","0.00051","21.76356","-0.00002"
"1.70000","0.05428","229.23186","0.00054","22.92319","0.00001"
"1.80000","0.05733","238.97951","0.00057","23.89795","-0.00003"
"1.90000","0.06086","250.80717","0.00061","25.08072","0.00004"
"2.00000","0.06416","261.16650","0.00064","26.11665","-0.00001"
"2.10000","0.06746","271.63937","0.00067","27.16394","-0.00001"
"2.20000","0.07071","281.77722","0.00071","28.17772","0.00001"
"2.30000","0.07415","292.69965","0.00074","29.26996","-0.00003"
"2.40000","0.07749","303.29703","0.00077","30.32970","0.00002"
"2.50000","0.08062","313.30606","0.00081","31.33061","-0.00002"
"2.60000","0.08414","324.95883","0.00084","32.49588","0.00003"
"2.70000","0.08754","335.95422","0.00088","33.59542","-0.00001"
"2.80000","0.09079","346.21854","0.00091","34.62185","-0.00001"
"2.90000","0.09405","357.01556","0.00094","35.70156","0.00001"
"3.00000","0.09746","368.06851","0.00097","36.80685","-0.00004"
"3.10000","0.10080","378.79321","0.00101","37.87932","0.00004"
"3.20000","0.10401","389.22971","0.00104","38.92297","-0.00002"
"3.30000","0.10761","401.26950","0.00108","40.12695","0.00001"
"3.40000","0.11094","412.25906","0.00111","41.22591","0.00001"
"3.50000","0.11416","422.83218","0.00114","42.28322","-0.00002"
"3.60000","0.11740","433.69247","0.00117","43.36925","0.00002"
"3.70000","0.12083","445.33551","0.00121","44.53355","-0.00002"
"3.80000","0.12406","456.07196","0.00124","45.60720","0.00002"
"3.90000","0.12738","467.62158","0.00127","46.76216","0.00000"
"4.00000","0.13081","479.23572","0.00131","47.92357","-0.00001"
"4.10000","0.13421","490.91751","0.00134","49.09175","0.00001"
"4.20000","0.13741","501.35059","0.00137","50.13506","-0.00002"
"4.30000","0.14072","512.56842","0.00141","51.25684","0.00002"
"4.40000","0.14409","523.83740","0.00144","52.38374","-0.00001"
"4.50000","0.14743","534.71771","0.00147","53.47177","0.00001"
"4.60000","0.15074","545.77789","0.00151","54.57779","0.00001"
"4.70000","0.15416","556.98560","0.00154","55.69856","-0.00002"
"4.80000","0.15749","567.85004","0.00157","56.78500","0.00002"
"4.90000","0.16074","578.27484","0.00161","57.82748","-0.00002"
"5.00000","0.16417","589.42767","0.00164","58.94277","0.00001"
"5.10000","0.16754","600.16852","0.00168","60.01685","0.00000"
"5.20000","0.17079","610.56104","0.00171","61.05610","-0.00001"
"5.30000","0.17416","621.28357","0.00174","62.12836","0.00001"
"5.40000","0.17743","631.29590","0.00177","63.12959","-0.00001"
"5.50000","0.18085","642.12042","0.00181","64.21204","0.00001"
"5.60000","0.18404","651.64606","0.00184","65.16460","0.00000"
"5.70000","0.18749","662.36597","0.00187","66.23660","0.00000"
"5.80000","0.19083","672.43927","0.00191","67.24393","0.00001"
"5.90000","0.19410","681.98712","0.00194","68.19872","-0.00001"
"6.00000","0.19751","692.13989","0.00198","69.21399","0.00001"
"6.10000","0.20073","700.72290","0.00201","70.07229","-0.00001"
"6.20000","0.20401","709.88989","0.00204","70.98899","0.00000"
"6.30000","0.20739","719.29248","0.00207","71.92924","0.00001"
"6.40000","0.21089","728.68884","0.00211","72.86888","-0.00001"
"6.50000","0.21417","737.11505","0.00214","73.71150","0.00001"
"6.60000","0.21738","745.04742","0.00217","74.50475","-0.00001"
"6.70000","0.22079","753.69098","0.00221","75.36909","0.00000"
"6.80000","0.22413","761.73151","0.00224","76.17315","0.00000"
"6.90000","0.22745","769.63300","0.00227","76.96330","-0.00001"
"7.00000","0.23074","777.45691","0.00231","77.74569","0.00001"
"7.10000","0.23431","786.38745","0.00234","78.63875","-0.00001"
"7.20000","0.23752","793.49048","0.00238","79.34904","0.00001"
"7.30000","0.24076","801.01788","0.00241","80.10179","0.00000"
"7.40000","0.24415","809.90540","0.00244","80.99054","-0.00001"
"7.50000","0.24739","819.14728","0.00247","81.91473","0.00001"
"7.60000","0.25071","829.50507","0.00251","82.95051","-0.00001"
"7.70000","0.25406","840.92450","0.00254","84.09245","0.00001"
"7.80000","0.25759","853.09595","0.00258","85.30959","0.00000"
"7.90000","0.26082","864.32025","0.00261","86.43202","0.00000"
"8.00000","0.26398","875.10620","0.00264","87.51062","0.00001"
"8.10000","0.26748","888.01300","0.00267","88.80130","-0.00001"
"8.20000","0.27083","899.71161","0.00271","89.97116","0.00000"
"8.30000","0.27406","910.73969","0.00274","91.07397","0.00000"
"8.40000","0.27742","922.63647","0.00277","92.26365","-0.00001"
"8.50000","0.28083","934.27728","0.00281","93.42773","0.00001"
"8.60000","0.28411","945.28625","0.00284","94.52863","-0.00001"
"8.70000","0.28738","956.63312","0.00287","95.66331","0.00002"
"8.80000","0.29093","969.38367","0.00291","96.93837","-0.00001"
"8.90000","0.29426","980.68744","0.00294","98.06874","0.00001"
"9.00000","0.29746","990.89276","0.00297","99.08928","0.00000"
"9.10000","0.30077","1002.29950","0.00301","100.22995","-0.00001"
"9.20000","0.30411","1013.21631","0.00304","101.32163","0.00000"
"9.30000","0.30739","1024.04370","0.00307","102.40437","-0.00001"
"9.40000","0.31066","1034.94287","0.00311","103.49429","0.00000"
"9.50000","0.31423","1047.38159","0.00314","104.73816","0.00000"
"9.60000","0.31762","1058.33533","0.00318","105.83353","0.00000"
"9.70000","0.32073","1067.68176","0.00321","106.76817","0.00001"
"9.80000","0.32407","1078.45569","0.00324","107.84557","0.00000"
"9.90000","0.32741","1088.92395","0.00327","108.89240","0.00001"
"10.00000","0.33073","1099.53027","0.00331","109.95303","0.00000"
"10.10000","0.33406","1110.02686","0.00334","111.00269","-0.00001"
"10.20000","0.33752","1121.06738","0.00338","112.10674","0.00000"
"10.30000","0.34092","1131.79114","0.00341","113.17912","0.00000"
"10.40000","0.34404","1140.80737","0.00344","114.08073","0.00000"
"10.50000","0.34750","1151.81775","0.00347","115.18178","0.00001"
"10.60000","0.35086","1162.00452","0.00351","116.20045","-0.00001"
"10.70000","0.35411","1171.42639","0.00354","117.14264","0.00000"
"10.80000","0.35742","1181.20459","0.00357","118.12046","0.00000"
"10.90000","0.36088","1191.60461","0.00361","119.16046","-0.00001"
"11.00000","0.36419","1200.90771","0.00364","120.09077","0.00001"
"11.10000","0.36736","1209.52478","0.00367","120.95248","0.00000"
"11.20000","0.37079","1219.54395","0.00371","121.95439","0.00001"
"11.30000","0.37416","1229.05371","0.00374","122.90537","-0.00001"
"11.40000","0.37751","1238.03381","0.00378","123.80338","0.00000"
"11.50000","0.38072","1246.57874","0.00381","124.65788","0.00000"
"11.60000","0.38410","1255.74146","0.00384","125.57414","-0.00001"
"11.70000","0.38746","1264.46228","0.00387","126.44623","0.00001"
"11.80000","0.39066","1272.44214","0.00391","127.24422","0.00000"
"11.90000","0.39420","1282.59497","0.00394","128.25949","0.00000"
"12.00000","0.39748","1290.64746","0.00397","129.06474","0.00000"
"12.10000","0.40078","1298.73413","0.00401","129.87341","-0.00001"
"12.20000","0.40412","1306.87036","0.00404","130.68704","0.00001"
"12.30000","0.40744","1314.61377","0.00407","131.46138","-0.00001"
"12.40000","0.41081","1322.56287","0.00411","132.25629","0.00001"
"12.50000","0.41410","1330.04016","0.00414","133.00401","0.00000"
"12.60000","0.41758","1338.57043","0.00418","133.85704","0.00000"
"12.70000","0.42092","1346.07056","0.00421","134.60706","0.00001"
"12.80000","0.42413","1352.62549","0.00424","135.26254","-0.00002"
"12.90000","0.42742","1359.73389","0.00427","135.97339","0.00002"
"13.00000","0.43074","1366.78723","0.00431","136.67873","-0.00003"
"13.10000","0.43402","1373.60254","0.00434","137.36026","0.00002"
"13.20000","0.43745","1381.18945","0.00437","138.11894","0.00001"
"13.30000","0.44088","1388.72681","0.00441","138.87268","-0.00001"
"13.40000","0.44412","1394.74390","0.00444","139.47440","0.00002"
"13.50000","0.44740","1401.17737","0.00447","140.11774","-0.00003"
"13.60000","0.45078","1408.12354","0.00451","140.81235","0.00000"
"13.70000","0.45414","1414.45740","0.00454","141.44574","0.00000"
"13.80000","0.45739","1420.35071","0.00457","142.03506","0.00000"
"13.90000","0.46079","1427.06506","0.00461","142.70651","0.00001"
"14.00000","0.46419","1433.55530","0.00464","143.35553","-0.00001"
"14.10000","0.46750","1439.68738","0.00468","143.96873","0.00000"
"14.20000","0.47068","1444.91333","0.00471","144.49133","-0.00001"
"14.30000","0.47417","1452.02441","0.00474","145.20244","0.00001"
"14.40000","0.47755","1458.07886","0.00478","145.80789","0.00000"
"14.50000","0.48074","1463.19031","0.00481","146.31903","0.00000"
"14.60000","0.48416","1469.56494","0.00484","146.95650","0.00001"
"14.70000","0.48743","1474.73364","0.00487","147.47336","-0.00001"
"14.80000","0.49077","1480.18835","0.00491","148.01883","0.00000"
"14.90000","0.49400","1485.10657","0.00494","148.51065","0.00000"
"15.00000","0.49761","1492.22253","0.00498","149.22226","0.00000"
"15.10000","0.50088","1496.75623","0.00501","149.67563","0.00001"
"15.20000","0.50405","1500.90637","0.00504","150.09064","-0.00001"
"15.30000","0.50745","1506.53784","0.00507","150.65378","0.00000"
"15.40000","0.51073","1510.90125","0.00511","151.09012","-0.00001"
"15.50000","0.51407","1515.66870","0.00514","151.56686","0.00001"
"15.60000","0.51729","1520.10181","0.00517","152.01018","0.00001"
"15.70000","0.52094","1526.87488","0.00521","152.68748","0.00000"
"15.80000","0.52423","1531.26477","0.00524","153.12648","0.00001"
"15.90000","0.52740","1534.98682","0.00527","153.49869","-0.00001"
"16.00000","0.53083","1540.22644","0.00531","154.02264","0.00000"
"16.10000","0.53410","1543.97119","0.00534","154.39713","0.00000"
"16.20000","0.53752","1548.69470","0.00538","154.86948","0.00000"
"16.30000","0.54073","1552.34082","0.00541","155.23409","0.00001"
"16.40000","0.54431","1557.98181","0.00544","155.79819","-0.00001"
"16.50000","0.54752","1561.27307","0.00548","156.12730","0.00000"
"16.60000","0.55070","1564.38013","0.00551","156.43802","-0.00001"
"16.70000","0.55410","1569.03381","0.00554","156.90338","0.00000"
"16.80000","0.55750","1573.07629","0.00558","157.30763","0.00000"
"16.90000","0.56077","1576.51233","0.00561","157.65123","0.00000"
"17.00000","0.56402","1580.20984","0.00564","158.02098","0.00001"
"17.10000","0.56752","1584.78076","0.00568","158.47807","-0.00001"
"17.20000","0.57079","1587.87207","0.00571","158.78720","0.00000"
"17.30000","0.57402","1591.03760","0.00574","159.10376","0.00000"
"17.40000","0.57742","1595.34888","0.00577","159.53488","0.00000"
"17.50000","0.58090","1599.53369","0.00581","159.95337","0.00000"
"17.60000","0.58414","1602.34631","0.00584","160.23463","-0.00001"
"17.70000","0.58742","1605.72058","0.00587","160.57205","0.00000"
"17.80000","0.59085","1609.53137","0.00591","160.95314","0.00000"
"17.90000","0.59413","1612.39807","0.00594","161.23981","0.00000"
"18.00000","0.59743","1615.39746","0.00597","161.53975","0.00000"
"18.10000","0.60086","1619.47668","0.00601","161.94766","0.00000"
"18.20000","0.60431","1623.65088","0.00604","162.36508","0.00001"
"18.30000","0.60739","1625.59521","0.00607","162.55952","0.00000"
"18.40000","0.61076","1629.44128","0.00611","162.94412","0.00000"
"18.50000","0.61404","1632.68713","0.00614","163.26871","0.00000"
"18.60000","0.61743","1636.64795","0.00617","163.66479","-0.00001"
"18.70000","0.62072","1639.79248","0.00621","163.97925","0.00001"
"18.80000","0.62414","1643.95215","0.00624","164.39522","0.00000"
"18.90000","0.62757","1647.94666","0.00628","164.79466","0.00000"
"19.00000","0.63075","1649.99255","0.00631","164.99925","0.00000"
"19.10000","0.63413","1653.61377","0.00634","165.36137","-0.00001"
"19.20000","0.63739","1656.01392","0.00637","165.60139","0.00000"
"19.30000","0.64077","1659.33228","0.00641","165.93323","0.00000"
"19.40000","0.64412","1662.50256","0.00644","166.25026","0.00000"
"19.50000","0.64756","1666.00220","0.00648","166.60022","0.00001"
"19.60000","0.65088","1668.86780","0.00651","166.88678","-0.00001"
"19.70000","0.65406","1670.85291","0.00654","167.08530","0.00001"
"19.80000","0.65757","1674.83813","0.00658","167.48381","-0.00001"
"19.90000","0.66078","1676.82861","0.00661","167.68286","0.00000"
"20.00000","0.66412","1679.71863","0.00664","167.97186","0.00001"
"20.10000","0.66742","1682.31836","0.00667","168.23184","-0.00001"
"20.20000","0.67083","1685.53308","0.00671","168.55331","0.00001"
"20.30000","0.67411","1687.68481","0.00674","168.76848","-0.00001"
"20.40000","0.67740","1690.04736","0.00677","169.00473","0.00001"
"20.50000","0.68088","1693.45288","0.00681","169.34529","0.00000"
"20.60000","0.68411","1695.22766","0.00684","169.52277","-0.00001"
"20.70000","0.68742","1697.44141","0.00687","169.74414","0.00001"
"20.80000","0.69078","1700.09790","0.00691","170.00980","-0.00001"
"20.90000","0.69417","1702.52844","0.00694","170.25284","0.00001"
"21.00000","0.69737","1703.92261","0.00697","170.39226","0.00000"
"21.10000","0.70069","1706.34888","0.00701","170.63489","0.00000"
"21.20000","0.70424","1709.75146","0.00704","170.97514","0.00001"
"21.30000","0.70754","1711.35474","0.00708","171.13547","-0.00001"
"21.40000","0.71080","1713.14014","0.00711","171.31401","0.00001"
"21.50000","0.71411","1715.08655","0.00714","171.50865","-0.00001"
"21.60000","0.71754","1717.30725","0.00718","171.73073","0.00000"
"21.70000","0.72072","1718.11157","0.00721","171.81116","0.00001"
"21.80000","0.72413","1720.61194","0.00724","172.06119","-0.00001"
"21.90000","0.72754","1722.55640","0.00728","172.25565","0.00001"
"22.00000","0.73090","1724.59570","0.00731","172.45956","-0.00001"
"22.10000","0.73403","1724.83899","0.00734","172.48390","0.00000"
"22.20000","0.73750","1727.47803","0.00737","172.74780","0.00001"
"22.30000","0.74075","1728.11206","0.00741","172.81120","-0.00001"
"22.40000","0.74402","1729.40796","0.00744","172.94080","0.00001"
"22.50000","0.74742","1731.88098","0.00747","173.18810","-0.00001"
"22.60000","0.75086","1734.11523","0.00751","173.41153","0.00000"
"22.70000","0.75420","1736.04712","0.00754","173.60471","0.00000"
"22.80000","0.75731","1735.95264","0.00757","173.59526","0.00000"
"22.90000","0.76084","1738.78198","0.00761","173.87820","0.00001"
"23.00000","0.76415","1739.56641","0.00764","173.95663","-0.00001"
"23.10000","0.76740","1739.79028","0.00767","173.97903","0.00001"
"23.20000","0.77079","1741.35193","0.00771","174.13519","0.00000"
"23.30000","0.77418","1742.33081","0.00774","174.23308","0.00000"
"23.40000","0.77759","1743.61670","0.00778","174.36166","0.00000"
"23.50000","0.78064","1742.64014","0.00781","174.26401","0.00000"
"23.60000","0.78425","1745.55139","0.00784","174.55515","0.00000"
"23.70000","0.78747","1745.76086","0.00787","174.57608","0.00000"
"23.80000","0.79079","1746.50366","0.00791","174.65036","0.00000"
"23.90000","0.79407","1746.94226","0.00794","174.69423","0.00000"
"24.00000","0.79744","1747.77112","0.00797","174.77711","0.00000"
"24.10000","0.80084","1748.63660","0.00801","174.86366","0.00000"
"24.20000","0.80397","1747.96558","0.00804","174.79655","0.00000"
"24.30000","0.80750","1750.05457","0.00808","175.00546","0.00000"
"24.40000","0.81092","1750.85535","0.00811","175.08554","0.00000"
"24.50000","0.81410","1750.23730","0.00814","175.02373","0.00000"
"24.60000","0.81741","1750.77783","0.00817","175.07779","0.00001"
"24.70000","0.82079","1751.53088","0.00821","175.15309","0.00000"
"24.80000","0.82411","1751.85242","0.00824","175.18524","0.00000"
"24.90000","0.82739","1752.31262","0.00827","175.23126","0.00000"
"25.00000","0.83093","1754.19263","0.00831","175.41927","-0.00001"
"25.10000","0.83422","1754.38000","0.00834","175.43800","0.00000"
"25.20000","0.83746","1754.12524","0.00837","175.41252","0.00000"
"25.30000","0.84071","1754.66467","0.00841","175.46646","0.00000"
"25.40000","0.84417","1756.00293","0.00844","175.60030","0.00001"
"25.50000","0.84740","1756.09314","0.00847","175.60931","-0.00001"
"25.60000","0.85074","1757.31812","0.00851","175.73181","0.00001"
"25.70000","0.85419","1758.79578","0.00854","175.87958","-0.00001"
"25.80000","0.85753","1759.60498","0.00858","175.96049","0.00001"
"25.90000","0.86074","1759.27527","0.00861","175.92752","0.00001"
"26.00000","0.86408","1760.02979","0.00864","176.00298","-0.00001"
"26.10000","0.86742","1760.55225","0.00867","176.05522","0.00001"
"26.20000","0.87079","1761.07361","0.00871","176.10736","-0.00001"
"26.30000","0.87410","1761.44336","0.00874","176.14433","0.00000"
"26.40000","0.87743","1761.65137","0.00877","176.16513","0.00000"
"26.50000","0.88079","1762.31970","0.00881","176.23196","0.00000"
"26.60000","0.88405","1762.10425","0.00884","176.21042","0.00001"
"26.70000","0.88749","1763.32520","0.00887","176.33252","-0.00001"
"26.80000","0.89091","1764.14099","0.00891","176.41409","0.00001"
"26.90000","0.89414","1763.48706","0.00894","176.34871","0.00000"
"27.00000","0.89754","1764.12854","0.00898","176.41286","0.00000"
"27.10000","0.90076","1763.05603","0.00901","176.30560","0.00001"
"27.20000","0.90415","1763.06995","0.00904","176.30699","-0.00001"
"27.30000","0.90739","1762.09412","0.00907","176.20941","0.00001"
"27.40000","0.91086","1762.42883","0.00911","176.24289","-0.00001"
"27.50000","0.91420","1761.65027","0.00914","176.16502","0.00000"
"27.60000","0.91745","1760.13843","0.00917","176.01384","0.00001"
"27.70000","0.92083","1759.37134","0.00921","175.93713","-0.00001"
"27.80000","0.92407","1757.51331","0.00924","175.75133","0.00001"
"27.90000","0.92736","1756.40271","0.00927","175.64027","-0.00001"
"28.00000","0.93072","1755.94543","0.00931","175.59454","0.00000"
"28.10000","0.93422","1756.01892","0.00934","175.60190","0.00001"
"28.20000","0.93751","1754.74402","0.00938","175.47440","-0.00001"
"28.30000","0.94073","1753.14172","0.00941","175.31418","0.00001"
"28.40000","0.94415","1752.73608","0.00944","175.27361","-0.00001"
"28.50000","0.94747","1751.80664","0.00947","175.18066","0.00001"
"28.60000","0.95079","1750.66235","0.00951","175.06624","0.00000"
"28.70000","0.95411","1749.89160","0.00954","174.98917","-0.00001"
"28.80000","0.95765","1750.43494","0.00958","175.04349","0.00001"
"28.90000","0.96084","1748.88464","0.00961","174.88846","-0.00001"
"29.00000","0.96407","1748.33728","0.00964","174.83372","0.00001"
"29.10000","0.96748","1748.76672","0.00967","174.87668","-0.00001"
"29.20000","0.97078","1748.47864","0.00971","174.84787","0.00000"
"29.30000","0.97406","1748.25708","0.00974","174.82571","0.00001"
"29.40000","0.97741","1748.68921","0.00977","174.86893","-0.00001"
"29.50000","0.98087","1749.26782","0.00981","174.92679","0.00002"
"29.60000","0.98411","1748.39221","0.00984","174.83922","-0.00001"
"29.70000","0.98732","1747.75586","0.00987","174.77559","0.00000"
"29.80000","0.99085","1749.34961","0.00991","174.93497","0.00001"
"29.90000","0.99419","1749.16736","0.00994","174.91673","-0.00001"
"30.00000","0.99743","1748.24878","0.00997","174.82487","0.00002"
"30.10000","1.00075","1748.38586","0.01001","174.83859","-0.00001"
"30.20000","1.00414","1748.69202","0.01004","174.86920","0.00000"
"30.30000","1.00743","1748.59814","0.01007","174.85982","0.00000"
"30.40000","1.01068","1748.74231","0.01011","174.87424","-0.00001"
"30.50000","1.01426","1750.72583","0.01014","175.07259","0.00002"
"30.60000","1.01765","1751.25940","0.01018","175.12595","-0.00001"
"30.70000","1.02074","1749.83008","0.01021","174.98300","0.00001"
"30.80000","1.02411","1750.81824","0.01024","175.08182","0.00000"
"30.90000","1.02742","1751.01294","0.01027","175.10129","-0.00001"
"31.00000","1.03074","1751.11475","0.01031","175.11148","0.00001"
"31.10000","1.03404","1751.00867","0.01034","175.10086","-0.00001"
"31.20000","1.03756","1752.30200","0.01038","175.23019","0.00001"
"31.30000","1.04095","1752.64453","0.01041","175.26445","0.00000"
"31.40000","1.04406","1751.47620","0.01044","175.14761","-0.00001"
"31.50000","1.04741","1751.75293","0.01047","175.17529","0.00001"
"31.60000","1.05078","1751.94055","0.01051","175.19406","-0.00002"
"31.70000","1.05405","1751.56201","0.01054","175.15620","0.00001"
"31.80000","1.05739","1752.10742","0.01057","175.21074","0.00000"
"31.90000","1.06085","1753.25256","0.01061","175.32526","0.00000"
"32.00000","1.06421","1753.67859","0.01064","175.36786","0.00001"
"32.10000","1.06734","1752.81934","0.01067","175.28194","-0.00002"
"32.20000","1.07083","1754.56958","0.01071","175.45695","0.00001"
"32.30000","1.07420","1754.74756","0.01074","175.47476","-0.00001"
"32.40000","1.07748","1754.27551","0.01077","175.42755","0.00000"
"32.50000","1.08077","1753.87585","0.01081","175.38759","0.00001"
"32.60000","1.08419","1754.01550","0.01084","175.40155","-0.00001"
"32.70000","1.08749","1752.98767","0.01087","175.29877","0.00002"
"32.80000","1.09069","1751.51733","0.01091","175.15173","-0.00001"
"32.90000","1.09416","1751.51282","0.01094","175.15128","0.00000"
"33.00000","1.09749","1750.71826","0.01097","175.07182","0.00000"
"33.10000","1.10080","1749.74097","0.01101","174.97409","-0.00001"
"33.20000","1.10411","1748.34338","0.01104","174.83434","0.00002"
"33.30000","1.10739","1747.07776","0.01107","174.70778","-0.00001"
"33.40000","1.11074","1745.91931","0.01111","174.59193","0.00000"
"33.50000","1.11400","1744.54578","0.01114","174.45457","0.00000"
"33.60000","1.11756","1745.22546","0.01118","174.52255","-0.00001"
"33.70000","1.12087","1744.30200","0.01121","174.43021","0.00002"
"33.80000","1.12411","1742.44592","0.01124","174.24460","-0.00001"
"33.90000","1.12747","1741.78979","0.01127","174.17899","0.00001"
"34.00000","1.13081","1740.68811","0.01131","174.06882","0.00000"
"34.10000","1.13414","1739.48645","0.01134","173.94864","-0.00001"
"34.20000","1.13744","1737.95264","0.01137","173.79526","0.00001"
"34.30000","1.14088","1737.02356","0.01141","173.70236","-0.00001"
"34.40000","1.14421","1735.45923","0.01144","173.54593","0.00001"
"34.50000","1.14744","1732.57483","0.01147","173.25748","0.00000"
"34.60000","1.15076","1730.39233","0.01151","173.03923","-0.00001"
"34.70000","1.15407","1727.93591","0.01154","172.79359","0.00001"
"34.80000","1.15737","1725.36853","0.01157","172.53685","-0.00002"
"34.90000","1.16079","1723.75610","0.01161","172.37561","0.00001"
"35.00000","1.16421","1721.75183","0.01164","172.17519","-0.00001"
"35.10000","1.16748","1719.16296","0.01167","171.91629","0.00000"
"35.20000","1.17073","1716.63293","0.01171","171.66330","0.00001"
"35.30000","1.17414","1715.22888","0.01174","171.52289","-0.00002"
"35.40000","1.17746","1713.16003","0.01177","171.31601","0.00002"
"35.50000","1.18072","1710.86951","0.01181","171.08694","-0.00001"
"35.60000","1.18415","1710.11108","0.01184","171.01111","0.00000"
"35.70000","1.18752","1708.83032","0.01188","170.88303","0.00001"
"35.80000","1.19083","1707.35010","0.01191","170.73502","-0.00001"
"35.90000","1.19405","1705.66406","0.01194","170.56641","0.00002"
"36.00000","1.19750","1705.41052","0.01197","170.54105","-0.00001"
"36.10000","1.20089","1704.09534","0.01201","170.40953","0.00000"
"36.20000","1.20409","1701.62317","0.01204","170.16232","0.00001"
"36.30000","1.20752","1700.55774","0.01208","170.05577","-0.00001"
"36.40000","1.21077","1698.22205","0.01211","169.82220","0.00002"
"36.50000","1.21409","1696.26526","0.01214","169.62653","-0.00001"
"36.60000","1.21735","1694.05396","0.01217","169.40540","0.00000"
"36.70000","1.22093","1693.73901","0.01221","169.37390","0.00000"
"36.80000","1.22421","1691.75879","0.01224","169.17587","-0.00001"
"36.90000","1.22739","1688.99023","0.01227","168.89902","0.00002"
"37.00000","1.23076","1687.70886","0.01231","168.77089","-0.00001"
"37.10000","1.23407","1685.52161","0.01234","168.55215","0.00001"
"37.20000","1.23741","1683.68164","0.01237","168.36816","0.00000"
"37.30000","1.24064","1681.98535","0.01241","168.19853","-0.00001"
"37.40000","1.24429","1682.94019","0.01244","168.29402","0.00002"
"37.50000","1.24757","1681.41968","0.01248","168.14197","-0.00001"
"37.60000","1.25074","1679.39624","0.01251","167.93962","0.00001"
"37.70000","1.25418","1679.52893","0.01254","167.95290","0.00000"
"37.80000","1.25745","1678.49622","0.01257","167.84962","-0.00001"
"37.90000","1.26083","1678.33569","0.01261","167.83357","0.00001"
"38.00000","1.26406","1677.31287","0.01264","167.73129","-0.00002"
"38.10000","1.26758","1678.38013","0.01268","167.83801","0.00001"
"38.20000","1.27085","1678.09216","0.01271","167.80922","-0.00001"
"38.30000","1.27404","1677.49451","0.01274","167.74945","0.00000"
"38.40000","1.27742","1678.40625","0.01277","167.84062","0.00001"
"38.50000","1.28082","1678.92151","0.01281","167.89215","-0.00002"
"38.60000","1.28411","1678.55103","0.01284","167.85510","0.00002"
"38.70000","1.28737","1678.30518","0.01287","167.83052","-0.00001"
"38.80000","1.29083","1678.96667","0.01291","167.89667","0.00001"
"38.90000","1.29411","1678.15662","0.01294","167.81566","0.00001"
"39.00000","1.29736","1677.46191","0.01297","167.74619","-0.00002"
"39.10000","1.30078","1678.17944","0.01301","167.81795","0.00002"
"39.20000","1.30425","1678.85156","0.01304","167.88516","-0.00002"
"39.30000","1.30748","1677.91248","0.01307","167.79124","0.00001"
"39.40000","1.31078","1677.69397","0.01311","167.76939","0.00001"
"39.50000","1.31418","1677.80798","0.01314","167.78079","-0.00001"
"39.60000","1.31745","1677.01221","0.01317","167.70122","0.00002"
"39.70000","1.32075","1676.71948","0.01321","167.67195","-0.00002"
"39.80000","1.32416","1676.64453","0.01324","167.66446","0.00001"
"39.90000","1.32764","1676.91040","0.01328","167.69104","0.00000"
"40.00000","1.33074","1674.43213","0.01331","167.44321","-0.00001"
"40.10000","1.33409","1674.03613","0.01334","167.40361","0.00002"
"40.20000","1.33737","1672.87048","0.01337","167.28705","-0.00002"
"40.30000","1.34076","1672.72034","0.01341","167.27203","0.00001"
"40.40000","1.34406","1672.21301","0.01344","167.22130","-0.00001"
"40.50000","1.34747","1672.36047","0.01347","167.23605","0.00000"
"40.60000","1.35091","1672.72729","0.01351","167.27274","0.00001"
"40.70000","1.35405","1670.86365","0.01354","167.08636","-0.00001"
"40.80000","1.35748","1671.23279","0.01357","167.12328","0.00002"
"40.90000","1.36077","1670.46021","0.01361","167.04602","-0.00001"
"41.00000","1.36408","1669.80066","0.01364","166.98007","0.00000"
"41.10000","1.36745","1669.56165","0.01367","166.95616","0.00000"
"41.20000","1.37088","1669.23633","0.01371","166.92363","-0.00001"
"41.30000","1.37419","1667.71973","0.01374","166.77197","0.00002"
"41.40000","1.37738","1665.73474","0.01377","166.57347","-0.00001"
"41.50000","1.38086","1665.72815","0.01381","166.57281","0.00001"
"41.60000","1.38413","1663.76758","0.01384","166.37675","0.00000"
"41.70000","1.38752","1662.32825","0.01388","166.23282","-0.00001"
"41.80000","1.39076","1659.91003","0.01391","165.99100","0.00001"
"41.90000","1.39416","1658.67041","0.01394","165.86703","-0.00001"
"42.00000","1.39742","1656.10364","0.01397","165.61037","0.00001"
"42.10000","1.40071","1653.65735","0.01401","165.36574","0.00000"
"42.20000","1.40426","1652.83789","0.01404","165.28378","0.00000"
"42.30000","1.40746","1649.42908","0.01407","164.94290","0.00001"
"42.40000","1.41074","1647.31921","0.01411","164.73192","-0.00001"
"42.50000","1.41411","1645.78015","0.01414","164.57802","0.00001"
"42.60000","1.41746","1643.96021","0.01417","164.39603","0.00000"
"42.70000","1.42070","1641.56775","0.01421","164.15677","0.00000"
"42.80000","1.42404","1639.99890","0.01424","163.99989","0.00001"
"42.90000","1.42755","1639.55945","0.01428","163.95595","-0.00001"
"43.00000","1.43091","1638.21423","0.01431","163.82143","0.00001"
"43.10000","1.43414","1635.22888","0.01434","163.52289","0.00000"
"43.20000","1.43744","1632.84424","0.01437","163.28442","0.00000"
"43.30000","1.44091","1631.60437","0.01441","163.16043","0.00001"
"43.40000","1.44401","1628.50525","0.01444","162.85052","-0.00001"
"43.50000","1.44748","1628.77478","0.01447","162.87747","0.00001"
"43.60000","1.45088","1628.47131","0.01451","162.84714","-0.00001"
"43.70000","1.45419","1627.58972","0.01454","162.75897","0.00000"
"43.80000","1.45737","1626.27527","0.01457","162.62753","0.00001"
"43.90000","1.46080","1626.87866","0.01461","162.68787","-0.00001"
"44.00000","1.46410","1626.35144","0.01464","162.63515","0.00001"
"44.10000","1.46740","1626.06848","0.01467","162.60684","-0.00001"
"44.20000","1.47072","1626.59375","0.01471","162.65938","0.00000"
"44.30000","1.47420","1627.58289","0.01474","162.75829","0.00000"
"44.40000","1.47753","1627.61841","0.01478","162.76184","-0.00001"
"44.50000","1.48064","1625.95190","0.01481","162.59518","0.00001"
"44.60000","1.48422","1627.60034","0.01484","162.76004","-0.00001"
"44.70000","1.48750","1626.78662","0.01487","162.67867","0.00000"
"44.80000","1.49074","1625.91809","0.01491","162.59181","0.00000"
"44.90000","1.49415","1626.91138","0.01494","162.69113","-0.00001"
"45.00000","1.49748","1626.84167","0.01497","162.68417","0.00001"
"45.10000","1.50092","1627.53894","0.01501","162.75389","-0.00001"
"45.20000","1.50396","1625.94165","0.01504","162.59416","0.00000"
"45.30000","1.50758","1628.24561","0.01508","162.82455","0.00000"
"45.40000","1.51086","1628.14856","0.01511","162.81485","0.00000"
"45.50000","1.51411","1627.80188","0.01514","162.78018","0.00001"
"45.60000","1.51739","1628.14758","0.01517","162.81476","-0.00001"
"45.70000","1.52078","1628.75220","0.01521","162.87521","0.00001"
"45.80000","1.52415","1629.21606","0.01524","162.92160","-0.00001"
"45.90000","1.52731","1628.54736","0.01527","162.85474","-0.00001"
"46.00000","1.53086","1630.44055","0.01531","163.04405","0.00001"
"46.10000","1.53423","1630.90808","0.01534","163.09081","-0.00001"
"46.20000","1.53745","1630.50073","0.01537","163.05008","0.00001"
"46.30000","1.54072","1630.79199","0.01541","163.07919","0.00000"
"46.40000","1.54411","1631.82324","0.01544","163.18233","-0.00001"
"46.50000","1.54742","1631.78625","0.01547","163.17862","0.00001"
"46.60000","1.55071","1632.08655","0.01551","163.20865","-0.00001"
"46.70000","1.55425","1633.90649","0.01554","163.39066","0.00001"
"46.80000","1.55754","1633.65820","0.01558","163.36581","-0.00001"
"46.90000","1.56081","1633.66833","0.01561","163.36684","0.00000"
"47.00000","1.56407","1633.35876","0.01564","163.33588","0.00001"
"47.10000","1.56751","1634.14233","0.01568","163.41423","0.00000"
"47.20000","1.57074","1632.92090","0.01571","163.29208","0.00001"
"47.30000","1.57408","1632.56042","0.01574","163.25604","-0.00001"
"47.40000","1.57750","1632.29797","0.01577","163.22980","0.00000"
"47.50000","1.58088","1631.49426","0.01581","163.14943","0.00000"
"47.60000","1.58407","1629.25830","0.01584","162.92583","0.00000"
"47.70000","1.58744","1628.51843","0.01587","162.85184","0.00001"
"47.80000","1.59078","1627.55042","0.01591","162.75504","0.00000"
"47.90000","1.59409","1625.89771","0.01594","162.58977","0.00001"
"48.00000","1.59746","1624.70728","0.01597","162.47073","0.00000"
"48.10000","1.60076","1622.83411","0.01601","162.28342","0.00000"
"48.20000","1.60411","1621.49792","0.01604","162.14980","0.00001"
"48.30000","1.60739","1619.69678","0.01607","161.96968","-0.00001"
"48.40000","1.61084","1618.62146","0.01611","161.86215","0.00001"
"48.50000","1.61424","1617.00598","0.01614","161.70059","0.00000"
"48.60000","1.61745","1614.11462","0.01617","161.41147","0.00000"
"48.70000","1.62086","1613.05579","0.01621","161.30557","0.00001"
"48.80000","1.62408","1610.33740","0.01624","161.03374","-0.00001"
"48.90000","1.62748","1608.96240","0.01627","160.89624","0.00001"
"49.00000","1.63074","1606.74097","0.01631","160.67410","0.00000"
"49.10000","1.63417","1605.91846","0.01634","160.59184","0.00000"
"49.20000","1.63752","1604.47327","0.01638","160.44733","0.00000"
"49.30000","1.64076","1601.98975","0.01641","160.19897","-0.00001"
"49.40000","1.64416","1600.76636","0.01644","160.07663","0.00001"
"49.50000","1.64739","1598.12158","0.01647","159.81216","-0.00001"
"49.60000","1.65070","1596.25562","0.01651","159.62556","0.00001"
"49.70000","1.65407","1594.73291","0.01654","159.47330","0.00000"
"49.80000","1.65756","1593.43274","0.01658","159.34328","-0.00001"
"49.90000","1.66083","1590.58716","0.01661","159.05872","0.00001"
"50.00000","1.66405","1586.99097","0.01664","158.69910","-0.00001"
"50.10000","1.66751","1585.06116","0.01668","158.50612","0.00001"
"50.20000","1.67082","1582.39380","0.01671","158.23938","0.00000"
"50.30000","1.67413","1580.11914","0.01674","158.01192","0.00000"
"50.40000","1.67743","1578.29968","0.01677","157.82997","0.00001"
"50.50000","1.68094","1577.77966","0.01681","157.77797","-0.00001"
"50.60000","1.68415","1574.89368","0.01684","157.48936","0.00000"
"50.70000","1.68740","1572.55286","0.01687","157.25528","0.00000"
"50.80000","1.69081","1571.16248","0.01691","157.11624","0.00000"
"50.90000","1.69415","1569.24255","0.01694","156.92426","0.00001"
"51.00000","1.69740","1566.72424","0.01697","156.67242","0.00000"
"51.10000","1.70077","1565.07227","0.01701","156.50723","0.00000"
"51.20000","1.70419","1562.99597","0.01704","156.29959","0.00000"
"51.30000","1.70743","1559.83862","0.01707","155.98386","0.00000"
"51.40000","1.71066","1556.44922","0.01711","155.64493","0.00000"
"51.50000","1.71422","1555.50525","0.01714","155.55052","0.00000"
"51.60000","1.71756","1553.01526","0.01718","155.30153","0.00001"
"51.70000","1.72075","1549.68347","0.01721","154.96835","0.00000"
"51.80000","1.72407","1548.48242","0.01724","154.84824","0.00000"
"51.90000","1.72745","1547.25500","0.01727","154.72549","0.00001"
"52.00000","1.73077","1545.45386","0.01731","154.54538","-0.00001"
"52.10000","1.73405","1543.86047","0.01734","154.38605","0.00001"
"52.20000","1.73758","1543.16394","0.01738","154.31639","0.00000"
"52.30000","1.74097","1541.72241","0.01741","154.17224","0.00000"
"52.40000","1.74406","1537.92639","0.01744","153.79263","0.00000"
"52.50000","1.74748","1536.93860","0.01747","153.69386","-0.00001"
"52.60000","1.75075","1534.36609","0.01751","153.43661","0.00001"
"52.70000","1.75407","1532.37524","0.01754","153.23752","-0.00001"
"52.80000","1.75737","1530.12634","0.01757","153.01263","0.00001"
"52.90000","1.76087","1529.39246","0.01761","152.93924","0.00000"
"53.00000","1.76430","1527.94629","0.01764","152.79463","0.00000"
"53.10000","1.76735","1524.17651","0.01767","152.41765","0.00001"
"53.20000","1.77073","1522.82019","0.01771","152.28201","-0.00001"
"53.30000","1.77414","1521.07593","0.01774","152.10759","0.00001"
"53.40000","1.77741","1518.54187","0.01777","151.85419","-0.00001"
"53.50000","1.78072","1516.55591","0.01781","151.65559","0.00000"
"53.60000","1.78418","1515.59570","0.01784","151.55957","0.00000"
"53.70000","1.78754","1513.79822","0.01788","151.37982","-0.00001"
"53.80000","1.79070","1510.49182","0.01791","151.04918","0.00001"
"53.90000","1.79417","1509.69189","0.01794","150.96919","-0.00001"
"54.00000","1.79755","1507.61084","0.01798","150.76108","0.00001"
"54.10000","1.80083","1504.69580","0.01801","150.46957","0.00000"
"54.20000","1.80411","1501.71375","0.01804","150.17137","0.00000"
"54.30000","1.80749","1499.07019","0.01807","149.90701","0.00001"
"54.40000","1.81080","1495.34656","0.01811","149.53465","-0.00001"
"54.50000","1.81400","1491.26367","0.01814","149.12637","0.00000"
"54.60000","1.81747","1489.02307","0.01817","148.90231","0.00000"
"54.70000","1.82085","1485.80579","0.01821","148.58058","0.00000"
"54.80000","1.82413","1481.73267","0.01824","148.17326","0.00001"
"54.90000","1.82742","1477.51428","0.01827","147.75143","-0.00001"
"55.00000","1.83071","1473.34473","0.01831","147.33447","0.00001"
"55.10000","1.83410","1469.41296","0.01834","146.94130","-0.00001"
"55.20000","1.83739","1464.81787","0.01837","146.48178","0.00000"
"55.30000","1.84088","1461.66980","0.01841","146.16698","0.00001"
"55.40000","1.84421","1456.78357","0.01844","145.67836","-0.00001"
"55.50000","1.84746","1451.10986","0.01847","145.11099","0.00001"
"55.60000","1.85080","1445.85413","0.01851","144.58542","-0.00001"
"55.70000","1.85414","1439.95068","0.01854","143.99507","0.00000"
"55.80000","1.85743","1433.05981","0.01857","143.30598","0.00001"
"55.90000","1.86078","1426.43042","0.01861","142.64304","-0.00001"
"56.00000","1.86423","1420.19092","0.01864","142.01909","0.00001"
"56.10000","1.86757","1413.76270","0.01868","141.37627","0.00000"
"56.20000","1.87073","1406.26428","0.01871","140.62643","0.00000"
"56.30000","1.87409","1400.65283","0.01874","140.06528","0.00000"
"56.40000","1.87745","1394.64526","0.01877","139.46452","0.00000"
"56.50000","1.88074","1387.98523","0.01881","138.79852","0.00000"
"56.60000","1.88415","1382.69678","0.01884","138.26968","0.00001"
"56.70000","1.88752","1376.60425","0.01888","137.66043","0.00002"
"56.80000","1.89078","1370.05310","0.01891","137.00531","0.00001"
"56.90000","1.89404","1363.58997","0.01894","136.35899","-0.00001"
"57.00000","1.89748","1358.48193","0.01897","135.84819","0.00001"
"57.10000","1.90080","1353.37305","0.01901","135.33731","0.00000"
"57.20000","1.90406","1348.07068","0.01904","134.80707","0.00001"
"57.30000","1.90749","1344.24036","0.01907","134.42404","0.00001"
"57.39500","1.91070","1340.27991","0.01911","134.02798","-0.00002"