File: Tension/Section_2_Group_4/f3a_1.is_tens_RawData/Specimen_RawData_1.csv
Time,Extension,Load,Tensile strain (Extension),Tensile stress,Strain-by-clip-gage
(s),(mm),(N),(mm/mm),(MPa),(mm/mm)
"0.00000","0.00000","-2.02794","0.00000","-0.20279","0.00000"
"0.20000","0.00279","13.94301","0.00003","1.39430","-0.00001"
"0.40000","0.01093","61.48291","0.00011","6.14829","0.00001"
"0.60000","0.01759","97.03208","0.00018","9.70321","0.00001"
"0.80000","0.02433","131.34514","0.00024","13.13451","0.00000"
"1.00000","0.03090","162.81555","0.00031","16.28156","0.00000"
"1.20000","0.03755","193.37712","0.00038","19.33771","-0.00001"
"1.40000","0.04419","222.61011","0.00044","22.26101","0.00001"
"1.60000","0.05094","251.13782","0.00051","25.11378","0.00001"
"1.80000","0.05762","278.42255","0.00058","27.84225","-0.00001"
"2.00000","0.06428","304.40921","0.00064","30.44092","0.00000"
"2.20000","0.07105","330.74759","0.00071","33.07476","0.00000"
"2.40000","0.07755","354.23151","0.00078","35.42315","0.00000"
"2.60000","0.08434","379.06873","0.00084","37.90687","0.00000"
"2.80000","0.09091","402.19040","0.00091","40.21904","0.00000"
"3.00000","0.09752","424.99493","0.00098","42.49949","-0.00001"
"3.20000","0.10433","448.70685","0.00104","44.87069","0.00000"
"3.40000","0.11087","470.64874","0.00111","47.06487","0.00000"
"3.60000","0.11757","492.99588","0.00118","49.29959","0.00000"
"3.80000","0.12424","514.89337","0.00124","51.48934","0.00000"
"4.00000","0.13113","537.61676","0.00131","53.76168","0.00000"
"4.20000","0.13762","557.96216","0.00138","55.79622","0.00001"
"4.40000","0.14418","578.45441","0.00144","57.84544","0.00000"
"4.60000","0.15101","600.07635","0.00151","60.00764","0.00000"
"4.80000","0.15749","619.31799","0.00157","61.93180","0.00000"
"5.00000","0.16432","640.15326","0.00164","64.01533","0.00000"
"5.20000","0.17086","659.17273","0.00171","65.91727","0.00000"
"5.40000","0.17766","679.07288","0.00178","67.90729","0.00000"
"5.60000","0.18437","698.39050","0.00184","69.83905","0.00000"
"5.80000","0.19100","716.64081","0.00191","71.66408","0.00000"
"6.00000","0.19759","734.73926","0.00198","73.47392","0.00001"
"6.20000","0.20413","752.01593","0.00204","75.20159","0.00001"
"6.40000","0.21105","771.27887","0.00211","77.12788","0.00000"
"6.60000","0.21759","787.83789","0.00218","78.78379","-0.00001"
"6.80000","0.22420","804.39923","0.00224","80.43993","-0.00001"
"7.00000","0.23098","821.80145","0.00231","82.18015","0.00000"
"7.20000","0.23758","837.47449","0.00238","83.74745","0.00000"
"7.40000","0.24430","853.39362","0.00244","85.33936","0.00000"
"7.60000","0.25092","868.50299","0.00251","86.85030","0.00000"
"7.80000","0.25770","883.80847","0.00258","88.38084","0.00000"
"8.00000","0.26427","897.83984","0.00264","89.78398","0.00000"
"8.20000","0.27086","911.39917","0.00271","91.13992","0.00000"
"8.40000","0.27763","925.84088","0.00278","92.58409","-0.00001"
"8.60000","0.28415","938.50250","0.00284","93.85025","0.00000"
"8.80000","0.29094","952.21100","0.00291","95.22110","0.00000"
"9.00000","0.29764","965.38690","0.00298","96.53869","0.00000"
"9.20000","0.30429","977.34796","0.00304","97.73479","0.00000"
"9.40000","0.31099","989.70624","0.00311","98.97063","0.00000"
"9.60000","0.31756","1000.96820","0.00318","100.09682","-0.00001"
"9.80000","0.32423","1012.58484","0.00324","101.25848","0.00000"
"10.00000","0.33085","1023.52399","0.00331","102.35240","0.00001"
"10.20000","0.33769","1035.26440","0.00338","103.52644","0.00000"
"10.40000","0.34427","1045.67310","0.00344","104.56731","0.00000"
"10.60000","0.35089","1055.92322","0.00351","105.59232","0.00000"
"10.80000","0.35775","1068.02747","0.00358","106.80275","0.00000"
"11.00000","0.36419","1077.57166","0.00364","107.75716","0.00000"
"11.20000","0.37094","1088.64734","0.00371","108.86473","0.00000"
"11.40000","0.37755","1098.97205","0.00378","109.89720","0.00000"
"11.60000","0.38431","1110.12305","0.00384","111.01231","0.00000"
"11.80000","0.39097","1120.91565","0.00391","112.09157","0.00000"
"12.00000","0.39757","1130.93860","0.00398","113.09386","0.00000"
"12.20000","0.40431","1141.99377","0.00404","114.19938","0.00000"
"12.40000","0.41083","1151.70679","0.00411","115.17068","0.00000"
"12.60000","0.41777","1163.46826","0.00418","116.34682","0.00000"
"12.80000","0.42426","1173.10559","0.00424","117.31056","0.00000"
"13.00000","0.43090","1183.04688","0.00431","118.30469","0.00000"
"13.20000","0.43768","1193.97766","0.00438","119.39777","0.00000"
"13.40000","0.44417","1203.54614","0.00444","120.35461","-0.00001"
"13.60000","0.45088","1214.04639","0.00451","121.40464","0.00000"
"13.80000","0.45754","1224.35498","0.00458","122.43550","0.00001"
"14.00000","0.46435","1235.63733","0.00464","123.56374","0.00000"
"14.20000","0.47096","1245.58850","0.00471","124.55885","0.00000"
"14.40000","0.47759","1255.81311","0.00478","125.58131","0.00000"
"14.60000","0.48433","1266.47339","0.00484","126.64734","0.00000"
"14.80000","0.49087","1276.42371","0.00491","127.64237","0.00000"
"15.00000","0.49762","1287.43030","0.00498","128.74303","0.00000"
"15.20000","0.50420","1297.48328","0.00504","129.74832","0.00000"
"15.40000","0.51087","1307.89404","0.00511","130.78940","0.00000"
"15.60000","0.51772","1319.34766","0.00518","131.93477","0.00000"
"15.80000","0.52422","1328.98755","0.00524","132.89876","0.00000"
"16.00000","0.53092","1339.57971","0.00531","133.95798","0.00000"
"16.20000","0.53757","1350.14160","0.00538","135.01416","0.00000"
"16.40000","0.54437","1361.33362","0.00544","136.13336","0.00000"
"16.60000","0.55090","1370.99194","0.00551","137.09920","0.00000"
"16.80000","0.55749","1380.78296","0.00557","138.07829","0.00000"
"17.00000","0.56431","1392.25269","0.00564","139.22527","0.00000"
"17.20000","0.57082","1401.71631","0.00571","140.17163","-0.00001"
"17.40000","0.57761","1412.82629","0.00578","141.28262","0.00000"
"17.60000","0.58427","1423.53613","0.00584","142.35361","0.00000"
"17.80000","0.59093","1433.83484","0.00591","143.38348","0.00000"
"18.00000","0.59772","1445.10107","0.00598","144.51010","0.00000"
"18.20000","0.60423","1454.47852","0.00604","145.44785","0.00000"
"18.40000","0.61089","1464.51001","0.00611","146.45100","0.00000"
"18.60000","0.61748","1474.72693","0.00617","147.47269","0.00000"
"18.80000","0.62436","1486.58972","0.00624","148.65897","0.00000"
"19.00000","0.63086","1496.84814","0.00631","149.68481","0.00000"
"19.20000","0.63760","1508.06750","0.00638","150.80675","0.00000"
"19.40000","0.64435","1519.78967","0.00644","151.97897","0.00000"
"19.60000","0.65089","1530.16882","0.00651","153.01688","0.00000"
"19.80000","0.65762","1541.96265","0.00658","154.19626","0.00000"
"20.00000","0.66420","1552.94336","0.00664","155.29434","0.00000"
"20.20000","0.67101","1565.04321","0.00671","156.50432","0.00000"
"20.40000","0.67756","1575.95020","0.00678","157.59502","0.00000"
"20.60000","0.68422","1586.94104","0.00684","158.69411","0.00000"
"20.80000","0.69092","1598.38428","0.00691","159.83842","0.00000"
"21.00000","0.69754","1609.14124","0.00698","160.91412","0.00000"
"21.20000","0.70432","1621.10779","0.00704","162.11078","0.00000"
"21.40000","0.71092","1631.79395","0.00711","163.17940","0.00000"
"21.60000","0.71757","1642.82288","0.00718","164.28229","0.00000"
"21.80000","0.72435","1654.66760","0.00724","165.46677","0.00000"
"22.00000","0.73090","1665.18396","0.00731","166.51840","0.00000"
"22.20000","0.73755","1676.15710","0.00738","167.61571","0.00000"
"22.40000","0.74420","1687.04749","0.00744","168.70474","0.00000"
"22.60000","0.75098","1698.71802","0.00751","169.87180","0.00000"
"22.80000","0.75764","1709.75403","0.00758","170.97540","-0.00001"
"23.00000","0.76419","1720.00562","0.00764","172.00056","0.00000"
"23.20000","0.77101","1731.97388","0.00771","173.19739","0.00000"
"23.40000","0.77749","1741.94800","0.00777","174.19479","0.00000"
"23.60000","0.78431","1753.63794","0.00784","175.36380","0.00000"
"23.80000","0.79093","1764.09741","0.00791","176.40974","-0.00001"
"24.00000","0.79758","1774.46301","0.00798","177.44630","0.00000"
"24.20000","0.80431","1785.66968","0.00804","178.56697","0.00000"
"24.40000","0.81088","1795.81177","0.00811","179.58118","0.00000"
"24.60000","0.81762","1806.78857","0.00818","180.67886","0.00000"
"24.80000","0.82414","1816.82349","0.00824","181.68234","0.00000"
"25.00000","0.83104","1828.67065","0.00831","182.86707","0.00000"
"25.20000","0.83760","1838.74573","0.00838","183.87457","0.00001"
"25.40000","0.84418","1848.83435","0.00844","184.88344","0.00000"
"25.60000","0.85106","1860.75757","0.00851","186.07576","0.00000"
"25.80000","0.85752","1870.52307","0.00858","187.05231","-0.00001"
"26.00000","0.86424","1881.54260","0.00864","188.15427","0.00000"
"26.20000","0.87085","1892.05505","0.00871","189.20551","0.00001"
"26.40000","0.87771","1903.47620","0.00878","190.34763","0.00000"
"26.60000","0.88425","1913.59094","0.00884","191.35910","0.00000"
"26.80000","0.89088","1923.59424","0.00891","192.35942","0.00000"
"27.00000","0.89762","1934.47693","0.00898","193.44769","0.00001"
"27.20000","0.90414","1944.21875","0.00904","194.42188","0.00000"
"27.40000","0.91108","1956.13806","0.00911","195.61380","0.00000"
"27.60000","0.91756","1965.52576","0.00918","196.55258","-0.00001"
"27.80000","0.92422","1975.76062","0.00924","197.57607","0.00000"
"28.00000","0.93098","1986.96753","0.00931","198.69675","0.00000"
"28.20000","0.93760","1997.34082","0.00938","199.73409","0.00001"
"28.40000","0.94418","2007.56934","0.00944","200.75693","0.00000"
"28.60000","0.95086","2018.38403","0.00951","201.83841","-0.00001"
"28.80000","0.95768","2029.85986","0.00958","202.98599","0.00000"
"29.00000","0.96429","2040.09229","0.00964","204.00923","0.00000"
"29.20000","0.97089","2050.39502","0.00971","205.03951","0.00000"
"29.40000","0.97767","2061.66333","0.00978","206.16634","0.00000"
"29.60000","0.98418","2071.75757","0.00984","207.17575","0.00000"
"29.80000","0.99091","2082.72876","0.00991","208.27287","0.00000"
"30.00000","0.99762","2093.90674","0.00998","209.39067","0.00000"
"30.20000","1.00425","2104.34717","0.01004","210.43472","0.00000"
"30.40000","1.01098","2115.43213","0.01011","211.54321","-0.00001"
"30.60000","1.01754","2125.39258","0.01018","212.53926","-0.00001"
"30.80000","1.02428","2136.39136","0.01024","213.63913","0.00000"
"31.00000","1.03090","2146.85986","0.01031","214.68599","0.00001"
"31.20000","1.03774","2158.30005","0.01038","215.83000","0.00000"
"31.40000","1.04428","2168.62866","0.01044","216.86287","-0.00001"
"31.60000","1.05083","2178.66016","0.01051","217.86601","0.00000"
"31.80000","1.05775","2190.47388","0.01058","219.04739","0.00000"
"32.00000","1.06415","2199.61523","0.01064","219.96152","0.00000"
"32.20000","1.07085","2210.19067","0.01071","221.01907","0.00000"
"32.40000","1.07750","2220.74976","0.01077","222.07498","-0.00001"
"32.60000","1.08436","2232.15112","0.01084","223.21512","0.00000"
"32.80000","1.09102","2242.60815","0.01091","224.26082","0.00001"
"33.00000","1.09759","2252.61108","0.01098","225.26111","0.00000"
"33.20000","1.10431","2263.26221","0.01104","226.32622","-0.00001"
"33.40000","1.11083","2273.19434","0.01111","227.31943","0.00000"
"33.60000","1.11770","2284.90015","0.01118","228.49002","0.00000"
"33.80000","1.12417","2294.54321","0.01124","229.45432","0.00000"
"34.00000","1.13085","2304.74390","0.01131","230.47440","0.00000"
"34.20000","1.13766","2316.41895","0.01138","231.64189","-0.00001"
"34.40000","1.14425","2326.31274","0.01144","232.63127","0.00000"
"34.60000","1.15098","2337.08325","0.01151","233.70833","0.00001"
"34.80000","1.15758","2347.07251","0.01158","234.70724","0.00000"
"35.00000","1.16442","2358.33398","0.01164","235.83340","0.00000"
"35.20000","1.17089","2367.75952","0.01171","236.77596","-0.00001"
"35.40000","1.17757","2377.76514","0.01178","237.77652","0.00000"
"35.60000","1.18426","2388.27539","0.01184","238.82755","0.00001"
"35.80000","1.19084","2397.86816","0.01191","239.78682","0.00000"
"36.00000","1.19760","2408.54639","0.01198","240.85464","0.00000"
"36.20000","1.20427","2419.18652","0.01204","241.91866","0.00000"
"36.40000","1.21095","2429.45337","0.01211","242.94534","0.00000"
"36.60000","1.21772","2440.67334","0.01218","244.06734","0.00000"
"36.80000","1.22427","2450.40503","0.01224","245.04050","0.00000"
"37.00000","1.23089","2460.68091","0.01231","246.06808","-0.00001"
"37.20000","1.23754","2471.10400","0.01238","247.11040","0.00000"
"37.40000","1.24434","2482.11816","0.01244","248.21182","0.00000"
"37.60000","1.25091","2492.30933","0.01251","249.23093","0.00000"
"37.80000","1.25747","2502.45288","0.01257","250.24529","0.00000"
"38.00000","1.26436","2514.19995","0.01264","251.42000","-0.00001"
"38.20000","1.27091","2524.04468","0.01271","252.40446","0.00000"
"38.40000","1.27772","2535.19922","0.01278","253.51993","0.00000"
"38.60000","1.28431","2545.65747","0.01284","254.56575","0.00000"
"38.80000","1.29098","2556.09619","0.01291","255.60962","0.00000"
"39.00000","1.29765","2566.77832","0.01298","256.67783","0.00000"
"39.20000","1.30416","2576.62305","0.01304","257.66229","0.00000"
"39.40000","1.31094","2587.98218","0.01311","258.79822","0.00000"
"39.60000","1.31740","2597.69653","0.01317","259.76965","0.00000"
"39.80000","1.32439","2610.15918","0.01324","261.01593","-0.00001"
"40.00000","1.33100","2620.65112","0.01331","262.06512","0.00000"
"40.20000","1.33767","2631.34473","0.01338","263.13446","0.00000"
"40.40000","1.34441","2642.49829","0.01344","264.24982","0.00000"
"40.60000","1.35087","2652.16064","0.01351","265.21606","0.00000"
"40.80000","1.35758","2663.23584","0.01358","266.32358","0.00000"
"41.00000","1.36416","2673.63013","0.01364","267.36301","0.00000"
"41.20000","1.37103","2685.51587","0.01371","268.55157","0.00001"
"41.40000","1.37754","2695.65649","0.01378","269.56564","0.00000"
"41.60000","1.38424","2706.57495","0.01384","270.65750","-0.00001"
"41.80000","1.39104","2718.13110","0.01391","271.81311","0.00000"
"42.00000","1.39757","2728.19409","0.01398","272.81940","0.00000"
"42.20000","1.40437","2739.98096","0.01404","273.99811","0.00000"
"42.40000","1.41095","2750.19824","0.01411","275.01984","0.00000"
"42.60000","1.41764","2761.03320","0.01418","276.10333","-0.00001"
"42.80000","1.42425","2771.68237","0.01424","277.16824","0.00000"
"43.00000","1.43087","2782.11816","0.01431","278.21182","0.00001"
"43.20000","1.43755","2793.08960","0.01438","279.30896","0.00000"
"43.40000","1.44422","2803.81616","0.01444","280.38162","0.00000"
"43.60000","1.45107","2815.54663","0.01451","281.55466","0.00000"
"43.80000","1.45768","2826.13403","0.01458","282.61340","0.00000"
"44.00000","1.46427","2836.41187","0.01464","283.64117","0.00000"
"44.20000","1.47102","2847.81470","0.01471","284.78146","0.00000"
"44.40000","1.47753","2857.94702","0.01478","285.79471","0.00000"
"44.60000","1.48420","2868.78125","0.01484","286.87811","0.00000"
"44.80000","1.49090","2880.22583","0.01491","288.02258","0.00000"
"45.00000","1.49761","2891.16138","0.01498","289.11615","0.00000"
"45.20000","1.50430","2902.46777","0.01504","290.24677","0.00000"
"45.40000","1.51093","2913.16992","0.01511","291.31699","0.00000"
"45.60000","1.51772","2924.93042","0.01518","292.49304","0.00000"
"45.80000","1.52419","2934.78467","0.01524","293.47845","0.00000"
"46.00000","1.53101","2946.70752","0.01531","294.67075","0.00000"
"46.20000","1.53760","2957.29126","0.01538","295.72913","0.00000"
"46.40000","1.54419","2967.61792","0.01544","296.76178","-0.00001"
"46.60000","1.55104","2979.73022","0.01551","297.97302","0.00000"
"46.80000","1.55751","2989.71973","0.01558","298.97198","0.00000"
"47.00000","1.56423","3000.91943","0.01564","300.09195","0.00000"
"47.20000","1.57094","3012.19214","0.01571","301.21921","0.00000"
"47.40000","1.57781","3023.95435","0.01578","302.39545","-0.00001"
"47.60000","1.58435","3034.22876","0.01584","303.42288","0.00000"
"47.80000","1.59087","3044.31616","0.01591","304.43161","0.00000"
"48.00000","1.59767","3055.94849","0.01598","305.59485","0.00000"
"48.20000","1.60411","3065.64600","0.01604","306.56461","0.00000"
"48.40000","1.61104","3077.77271","0.01611","307.77728","-0.00001"
"48.60000","1.61751","3087.81982","0.01618","308.78198","0.00000"
"48.80000","1.62428","3099.20703","0.01624","309.92072","0.00000"
"49.00000","1.63106","3110.78296","0.01631","311.07831","0.00000"
"49.20000","1.63766","3121.06836","0.01638","312.10684","0.00000"
"49.40000","1.64428","3131.68994","0.01644","313.16901","0.00000"
"49.60000","1.65084","3142.14453","0.01651","314.21445","0.00000"
"49.80000","1.65771","3154.09375","0.01658","315.40936","0.00000"
"50.00000","1.66421","3164.15869","0.01664","316.41586","-0.00001"
"50.20000","1.67087","3174.69312","0.01671","317.46930","0.00000"
"50.40000","1.67767","3186.31934","0.01678","318.63193","0.00000"
"50.60000","1.68422","3196.35498","0.01684","319.63550","0.00000"
"50.80000","1.69097","3207.61719","0.01691","320.76172","0.00000"
"51.00000","1.69763","3218.60474","0.01698","321.86047","0.00000"
"51.20000","1.70430","3229.57812","0.01704","322.95782","0.00000"
"51.40000","1.71096","3240.66089","0.01711","324.06610","0.00000"
"51.60000","1.71756","3251.33130","0.01718","325.13312","0.00001"
"51.80000","1.72425","3262.44019","0.01724","326.24402","0.00000"
"52.00000","1.73083","3273.15552","0.01731","327.31555","0.00000"
"52.20000","1.73766","3285.05298","0.01738","328.50531","0.00000"
"52.40000","1.74431","3296.30029","0.01744","329.63004","0.00000"
"52.60000","1.75089","3307.02148","0.01751","330.70215","0.00000"
"52.80000","1.75772","3319.25220","0.01758","331.92523","0.00000"
"53.00000","1.76424","3329.51172","0.01764","332.95117","0.00000"
"53.20000","1.77091","3340.61279","0.01771","334.06128","0.00000"
"53.40000","1.77751","3351.76294","0.01778","335.17630","0.00000"
"53.60000","1.78433","3363.64331","0.01784","336.36432","0.00000"
"53.80000","1.79095","3374.92480","0.01791","337.49249","-0.00001"
"54.00000","1.79755","3385.95923","0.01798","338.59592","-0.00001"
"54.20000","1.80436","3397.89453","0.01804","339.78946","0.00000"
"54.40000","1.81085","3408.15820","0.01811","340.81583","0.00000"
"54.60000","1.81769","3419.94604","0.01818","341.99460","0.00000"
"54.80000","1.82427","3430.81128","0.01824","343.08112","0.00000"
"55.00000","1.83092","3441.94653","0.01831","344.19464","-0.00001"
"55.20000","1.83762","3453.63208","0.01838","345.36322","0.00000"
"55.40000","1.84422","3464.33105","0.01844","346.43311","0.00000"
"55.60000","1.85096","3476.15552","0.01851","347.61554","0.00000"
"55.80000","1.85748","3486.69482","0.01857","348.66949","0.00000"
"56.00000","1.86443","3499.40698","0.01864","349.94070","0.00000"
"56.20000","1.87097","3509.95557","0.01871","350.99554","0.00000"
"56.40000","1.87758","3520.75464","0.01878","352.07547","0.00000"
"56.60000","1.88433","3532.66748","0.01884","353.26675","0.00000"
"56.80000","1.89083","3543.10986","0.01891","354.31097","-0.00001"
"57.00000","1.89759","3554.83862","0.01898","355.48386","-0.00001"
"57.20000","1.90426","3565.97754","0.01904","356.59775","0.00000"
"57.40000","1.91098","3577.36450","0.01911","357.73645","0.00000"
"57.60000","1.91762","3588.58301","0.01918","358.85831","0.00000"
"57.80000","1.92425","3599.67993","0.01924","359.96799","0.00000"
"58.00000","1.93097","3611.00220","0.01931","361.10022","0.00000"
"58.20000","1.93752","3621.78540","0.01938","362.17853","0.00000"
"58.40000","1.94435","3633.79150","0.01944","363.37915","0.00000"
"58.60000","1.95090","3644.27783","0.01951","364.42780","0.00000"
"58.80000","1.95751","3655.00781","0.01958","365.50079","-0.00001"
"59.00000","1.96439","3667.56274","0.01964","366.75629","0.00000"
"59.20000","1.97087","3677.68359","0.01971","367.76837","0.00000"
"59.40000","1.97758","3689.19336","0.01978","368.91934","0.00000"
"59.60000","1.98425","3700.43481","0.01984","370.04349","-0.00001"
"59.80000","1.99104","3712.07886","0.01991","371.20789","0.00000"
"60.00000","1.99761","3722.96045","0.01998","372.29605","0.00000"
"60.20000","2.00418","3733.59058","0.02004","373.35907","0.00000"
"60.40000","2.01096","3745.56934","0.02011","374.55695","0.00000"
"60.60000","2.01744","3756.22803","0.02017","375.62280","0.00000"
"60.80000","2.02434","3768.89258","0.02024","376.88925","-0.00001"
"61.00000","2.03094","3780.01294","0.02031","378.00128","0.00000"
"61.20000","2.03761","3791.13037","0.02038","379.11304","0.00000"
"61.40000","2.04439","3803.30127","0.02044","380.33014","0.00000"
"61.60000","2.05085","3813.54736","0.02051","381.35474","0.00000"
"61.80000","2.05759","3825.17310","0.02058","382.51730","0.00000"
"62.00000","2.06413","3835.99219","0.02064","383.59921","0.00000"
"62.20000","2.07103","3848.73486","0.02071","384.87347","0.00000"
"62.40000","2.07756","3859.52588","0.02078","385.95258","-0.00001"
"62.60000","2.08426","3871.00903","0.02084","387.10089","-0.00001"
"62.80000","2.09101","3883.23169","0.02091","388.32318","0.00000"
"63.00000","2.09752","3893.93164","0.02098","389.39316","0.00000"
"63.20000","2.10430","3905.79175","0.02104","390.57916","0.00000"
"63.40000","2.11089","3917.07617","0.02111","391.70761","0.00000"
"63.60000","2.11764","3928.55298","0.02118","392.85529","0.00000"
"63.80000","2.12426","3939.86304","0.02124","393.98630","0.00000"
"64.00000","2.13089","3950.96582","0.02131","395.09659","0.00000"
"64.20000","2.13757","3962.54663","0.02138","396.25467","0.00000"
"64.40000","2.14421","3973.92554","0.02144","397.39255","0.00000"
"64.60000","2.15101","3986.49805","0.02151","398.64981","0.00000"
"64.80000","2.15760","3997.74268","0.02158","399.77426","0.00000"
"65.00000","2.16422","4008.82520","0.02164","400.88251","0.00000"
"65.20000","2.17107","4021.29150","0.02171","402.12915","-0.00001"
"65.40000","2.17756","4031.78223","0.02178","403.17822","-0.00001"
"65.60000","2.18419","4043.14062","0.02184","404.31406","0.00000"
"65.80000","2.19092","4055.03735","0.02191","405.50372","0.00000"
"66.00000","2.19761","4066.92700","0.02198","406.69269","0.00000"
"66.20000","2.20433","4079.03491","0.02204","407.90350","0.00000"
"66.40000","2.21085","4089.84717","0.02211","408.98471","-0.00001"
"66.60000","2.21769","4102.27051","0.02218","410.22705","0.00000"
"66.80000","2.22417","4112.90527","0.02224","411.29053","0.00000"
"67.00000","2.23101","4125.43164","0.02231","412.54315","-0.00001"
"67.20000","2.23759","4136.62061","0.02238","413.66205","-0.00001"
"67.40000","2.24421","4147.71484","0.02244","414.77148","-0.00001"
"67.60000","2.25097","4160.02393","0.02251","416.00238","0.00000"
"67.80000","2.25753","4170.99316","0.02258","417.09930","0.00000"
"68.00000","2.26429","4183.01123","0.02264","418.30112","0.00000"
"68.20000","2.27085","4194.06982","0.02271","419.40698","-0.00001"
"68.40000","2.27770","4206.71387","0.02278","420.67139","0.00000"
"68.60000","2.28427","4217.85596","0.02284","421.78558","0.00000"
"68.80000","2.29086","4229.08447","0.02291","422.90845","0.00000"
"69.00000","2.29770","4241.48877","0.02298","424.14886","0.00000"
"69.20000","2.30415","4251.69482","0.02304","425.16949","0.00000"
"69.40000","2.31093","4263.69482","0.02311","426.36948","0.00000"
"69.60000","2.31752","4275.13184","0.02318","427.51318","0.00000"
"69.80000","2.32437","4287.50342","0.02324","428.75034","0.00000"
"70.00000","2.33091","4298.63525","0.02331","429.86353","0.00000"
"70.20000","2.33756","4310.05811","0.02338","431.00580","0.00000"
"70.40000","2.34427","4321.73242","0.02344","432.17325","0.00000"
"70.60000","2.35080","4332.29004","0.02351","433.22900","0.00000"
"70.80000","2.35776","4345.25781","0.02358","434.52579","0.00000"
"71.00000","2.36421","4355.50049","0.02364","435.55005","0.00000"
"71.20000","2.37085","4366.64355","0.02371","436.66437","0.00000"
"71.40000","2.37764","4378.93164","0.02378","437.89316","0.00000"
"71.60000","2.38425","4389.84863","0.02384","438.98486","0.00000"
"71.80000","2.39086","4400.93311","0.02391","440.09332","-0.00001"
"72.00000","2.39759","4412.73389","0.02398","441.27338","0.00000"
"72.20000","2.40433","4424.22803","0.02404","442.42279","0.00000"
"72.40000","2.41100","4435.75928","0.02411","443.57593","0.00000"
"72.60000","2.41756","4446.53076","0.02418","444.65308","0.00001"
"72.80000","2.42428","4458.37646","0.02424","445.83765","-0.00001"
"73.00000","2.43084","4469.26562","0.02431","446.92657","0.00000"
"73.20000","2.43766","4481.60938","0.02438","448.16095","0.00000"
"73.40000","2.44431","4493.12354","0.02444","449.31235","0.00000"
"73.60000","2.45085","4503.74023","0.02451","450.37402","0.00000"
"73.80000","2.45766","4516.09961","0.02458","451.60995","-0.00001"
"74.00000","2.46420","4527.00977","0.02464","452.70099","0.00000"
"74.20000","2.47094","4538.76758","0.02471","453.87677","0.00000"
"74.40000","2.47758","4550.10400","0.02478","455.01041","0.00000"
"74.60000","2.48438","4561.95264","0.02484","456.19525","0.00000"
"74.80000","2.49096","4573.14893","0.02491","457.31488","-0.00001"
"75.00000","2.49749","4583.91943","0.02497","458.39194","0.00000"
"75.20000","2.50438","4596.67725","0.02504","459.66772","0.00000"
"75.40000","2.51079","4606.92822","0.02511","460.69281","0.00000"
"75.60000","2.51757","4618.98193","0.02518","461.89819","0.00000"
"75.80000","2.52421","4630.31250","0.02524","463.03125","-0.00001"
"76.00000","2.53099","4642.25732","0.02531","464.22574","0.00000"
"76.20000","2.53769","4654.17676","0.02538","465.41766","0.00000"
"76.40000","2.54425","4665.05420","0.02544","466.50543","0.00000"
"76.60000","2.55093","4676.78369","0.02551","467.67838","0.00000"
"76.80000","2.55747","4687.83789","0.02557","468.78378","0.00000"
"77.00000","2.56441","4700.95264","0.02564","470.09528","-0.00001"
"77.20000","2.57087","4711.39648","0.02571","471.13965","0.00000"
"77.40000","2.57752","4722.47021","0.02578","472.24701","0.00000"
"77.60000","2.58433","4734.90674","0.02584","473.49066","0.00000"
"77.80000","2.59088","4745.54346","0.02591","474.55435","-0.00001"
"78.00000","2.59761","4757.07129","0.02598","475.70712","0.00000"
"78.20000","2.60424","4768.41943","0.02604","476.84195","0.00001"
"78.40000","2.61108","4780.51172","0.02611","478.05118","-0.00001"
"78.60000","2.61759","4790.83154","0.02618","479.08316","0.00000"
"78.80000","2.62424","4802.06592","0.02624","480.20660","0.00000"
"79.00000","2.63090","4813.21289","0.02631","481.32129","0.00000"
"79.20000","2.63751","4824.39111","0.02638","482.43912","0.00001"
"79.40000","2.64431","4836.57959","0.02644","483.65796","0.00000"
"79.60000","2.65096","4848.08301","0.02651","484.80829","-0.00001"
"79.80000","2.65759","4859.00684","0.02658","485.90070","0.00000"
"80.00000","2.66438","4870.55420","0.02664","487.05542","0.00000"
"80.20000","2.67090","4881.22803","0.02671","488.12280","0.00000"
"80.40000","2.67757","4892.69287","0.02678","489.26929","0.00000"
"80.60000","2.68422","4904.11865","0.02684","490.41187","-0.00001"
"80.80000","2.69101","4916.17969","0.02691","491.61798","0.00000"
"81.00000","2.69756","4926.85010","0.02698","492.68500","0.00001"
"81.20000","2.70414","4937.35645","0.02704","493.73566","0.00000"
"81.40000","2.71105","4950.00146","0.02711","495.00015","0.00000"
"81.60000","2.71757","4960.19141","0.02718","496.01913","0.00000"
"81.80000","2.72436","4972.16260","0.02724","497.21625","0.00000"
"82.00000","2.73096","4983.32666","0.02731","498.33267","0.00000"
"82.20000","2.73762","4994.14453","0.02738","499.41446","-0.00001"
"82.40000","2.74439","5005.95117","0.02744","500.59512","-0.00001"
"82.60000","2.75084","5015.87598","0.02751","501.58759","0.00000"
"82.80000","2.75757","5027.43848","0.02758","502.74384","0.00000"
"83.00000","2.76408","5038.22852","0.02764","503.82285","0.00000"
"83.20000","2.77108","5051.29395","0.02771","505.12939","0.00000"
"83.40000","2.77764","5062.30713","0.02778","506.23071","-0.00001"
"83.60000","2.78430","5073.41895","0.02784","507.34189","-0.00001"
"83.80000","2.79110","5085.46484","0.02791","508.54648","0.00000"
"84.00000","2.79754","5095.42822","0.02798","509.54282","0.00000"
"84.20000","2.80421","5106.83887","0.02804","510.68390","-0.00001"
"84.40000","2.81081","5117.87939","0.02811","511.78793","0.00000"
"84.60000","2.81766","5130.00098","0.02818","513.00012","0.00000"
"84.80000","2.82424","5141.06445","0.02824","514.10645","-0.00001"
"85.00000","2.83090","5152.06299","0.02831","515.20630","0.00001"
"85.20000","2.83768","5162.88721","0.02838","516.28870","-0.00001"
"85.40000","2.84423","5172.98633","0.02844","517.29865","0.00000"
"85.60000","2.85109","5184.99902","0.02851","518.49988","0.00001"
"85.80000","2.85758","5194.78125","0.02858","519.47815","-0.00001"
"86.00000","2.86423","5205.36768","0.02864","520.53674","0.00000"
"86.20000","2.87093","5216.48926","0.02871","521.64893","0.00000"
"86.40000","2.87755","5226.30420","0.02878","522.63043","0.00000"
"86.60000","2.88422","5236.85645","0.02884","523.68567","0.00000"
"86.80000","2.89091","5246.63477","0.02891","524.66345","0.00001"
"87.00000","2.89771","5256.80420","0.02898","525.68042","-0.00001"
"87.20000","2.90435","5266.30713","0.02904","526.63074","0.00000"
"87.40000","2.91091","5275.76855","0.02911","527.57684","0.00000"
"87.60000","2.91768","5286.58740","0.02918","528.65875","0.00000"
"87.80000","2.92418","5294.43750","0.02924","529.44373","0.00001"
"88.00000","2.93091","5303.97119","0.02931","530.39709","-0.00001"
"88.20000","2.93760","5312.51367","0.02938","531.25134","-0.00001"
"88.40000","2.94420","5319.56250","0.02944","531.95624","0.00000"
"88.60000","2.95101","5314.45557","0.02951","531.44556","0.00000"
"88.80000","2.95760","5301.32471","0.02958","530.13245","0.00000"
"89.00000","2.96439","5261.32422","0.02964","526.13245","0.00000"
"89.20000","2.97089","5253.50928","0.02971","525.35095","-0.00001"
"89.40000","2.97772","5223.90625","0.02978","522.39062","0.00000"
"89.60000","2.98429","5206.10986","0.02984","520.61096","0.00000"
"89.80000","2.99081","5127.06445","0.02991","512.70642","0.00000"
"89.84700","2.99242","4863.87646","0.02992","486.38763","0.00000"
"89.85200","2.99259","4506.67773","0.02993","450.66779","-0.00001"
"89.85600","2.99273","4045.12061","0.02993","404.51205","-0.00001"
"89.85800","2.99280","3781.97388","0.02993","378.19739","0.00000"
"89.86000","2.99288","3506.78442","0.02993","350.67844","0.00002"
"89.86200","2.99297","3225.53516","0.02993","322.55353","0.00004"
"89.86300","2.99301","3084.28442","0.02993","308.42844","0.00005"