File: Tension/Section_2_Group_2/epoxy_low_Sample_1.is_tens_RawData/Specimen_RawData_1.csv
Time,Extension,Load,Tensile strain (Extension),Tensile stress,Strain-by-clip-gage
(s),(mm),(N),(mm/mm),(MPa),(mm/mm)
"0.00000","0.00000","873.29840","0.00000","87.32984","0.00026"
"0.30000","0.00734","934.82739","0.00007","93.48274","0.00026"
"0.60000","0.01738","1016.33173","0.00017","101.63317","0.00028"
"0.90000","0.02750","1093.99280","0.00028","109.39928","0.00029"
"1.20000","0.03742","1165.95459","0.00037","116.59546","0.00026"
"1.50000","0.04756","1235.46948","0.00048","123.54695","0.00025"
"1.80000","0.05751","1297.93457","0.00058","129.79346","0.00027"
"2.10000","0.06768","1359.09485","0.00068","135.90948","0.00029"
"2.40000","0.07750","1415.17908","0.00078","141.51791","0.00027"
"2.70000","0.08743","1470.29736","0.00087","147.02974","0.00025"
"3.00000","0.09736","1522.72302","0.00097","152.27231","0.00026"
"3.30000","0.10748","1573.90942","0.00107","157.39095","0.00029"
"3.60000","0.11752","1621.74963","0.00118","162.17496","0.00028"
"3.90000","0.12760","1669.38159","0.00128","166.93816","0.00026"
"4.20000","0.13747","1715.70093","0.00137","171.57010","0.00025"
"4.50000","0.14757","1765.32007","0.00148","176.53201","0.00028"
"4.80000","0.15744","1812.36584","0.00157","181.23659","0.00029"
"5.10000","0.16741","1860.33826","0.00167","186.03383","0.00027"
"5.40000","0.17743","1909.14612","0.00177","190.91461","0.00025"
"5.70000","0.18751","1958.85413","0.00188","195.88541","0.00026"
"6.00000","0.19759","2008.42786","0.00198","200.84279","0.00029"
"6.30000","0.20752","2057.16333","0.00208","205.71634","0.00028"
"6.60000","0.21744","2105.87891","0.00217","210.58789","0.00023"
"6.90000","0.22758","2156.98975","0.00228","215.69897","0.00028"
"7.20000","0.23751","2206.06152","0.00238","220.60616","0.00026"
"7.50000","0.24744","2254.66064","0.00247","225.46606","0.00030"
"7.80000","0.25749","2304.40137","0.00257","230.44014","0.00027"
"8.10000","0.26741","2352.97925","0.00267","235.29793","0.00026"
"8.40000","0.27756","2403.59912","0.00278","240.35991","0.00028"
"8.70000","0.28752","2451.77759","0.00288","245.17776","0.00030"
"9.00000","0.29761","2500.82349","0.00298","250.08235","0.00029"
"9.30000","0.30751","2548.03882","0.00308","254.80388","0.00025"
"9.60000","0.31752","2595.88110","0.00318","259.58810","0.00027"
"9.90000","0.32734","2641.06030","0.00327","264.10602","0.00029"
"10.20000","0.33742","2687.91309","0.00337","268.79132","0.00029"
"10.50000","0.34747","2734.09326","0.00347","273.40933","0.00026"
"10.80000","0.35765","2781.42236","0.00358","278.14224","0.00025"
"11.10000","0.36742","2824.21387","0.00367","282.42139","0.00027"
"11.40000","0.37767","2870.78638","0.00378","287.07864","0.00029"
"11.70000","0.38748","2912.91187","0.00387","291.29120","0.00027"
"12.00000","0.39740","2955.73975","0.00397","295.57397","0.00025"
"12.30000","0.40739","2998.31250","0.00407","299.83124","0.00026"
"12.60000","0.41750","3041.91187","0.00418","304.19119","0.00029"
"12.90000","0.42751","3083.05713","0.00428","308.30573","0.00028"
"13.20000","0.43765","3125.58496","0.00438","312.55850","0.00024"
"13.50000","0.44742","3164.08936","0.00447","316.40894","0.00026"
"13.80000","0.45750","3204.82812","0.00457","320.48282","0.00028"
"14.10000","0.46752","3244.42383","0.00468","324.44238","0.00029"
"14.40000","0.47749","3283.20068","0.00477","328.32007","0.00027"
"14.70000","0.48742","3321.25586","0.00487","332.12558","0.00025"
"15.00000","0.49752","3360.98218","0.00498","336.09821","0.00026"
"15.30000","0.50751","3398.77612","0.00508","339.87762","0.00028"
"15.60000","0.51752","3436.03833","0.00518","343.60382","0.00028"
"15.90000","0.52757","3473.59180","0.00528","347.35919","0.00025"
"16.20000","0.53756","3509.70850","0.00538","350.97086","0.00025"
"16.50000","0.54749","3544.86328","0.00547","354.48633","0.00028"
"16.80000","0.55748","3579.93652","0.00557","357.99365","0.00029"
"17.10000","0.56741","3614.57568","0.00567","361.45758","0.00026"
"17.40000","0.57739","3648.99121","0.00577","364.89911","0.00025"
"17.70000","0.58760","3685.03076","0.00588","368.50308","0.00027"
"18.00000","0.59752","3717.57227","0.00598","371.75723","0.00031"
"18.30000","0.60756","3750.58472","0.00608","375.05847","0.00027"
"18.60000","0.61763","3784.22095","0.00618","378.42209","0.00024"
"18.90000","0.62742","3814.71802","0.00627","381.47180","0.00026"
"19.20000","0.63733","3845.71436","0.00637","384.57144","0.00029"
"19.50000","0.64749","3878.67993","0.00647","387.86798","0.00028"
"19.80000","0.65747","3909.33496","0.00657","390.93350","0.00025"
"20.10000","0.66762","3941.57275","0.00668","394.15729","0.00025"
"20.40000","0.67756","3971.56934","0.00678","397.15692","0.00028"
"20.70000","0.68754","4001.69531","0.00688","400.16953","0.00028"
"21.00000","0.69746","4030.82471","0.00697","403.08246","0.00027"
"21.30000","0.70745","4060.08691","0.00707","406.00870","0.00026"
"21.60000","0.71743","4088.65747","0.00717","408.86575","0.00027"
"21.90000","0.72750","4117.56445","0.00727","411.75644","0.00029"
"22.20000","0.73754","4145.12842","0.00738","414.51285","0.00027"
"22.50000","0.74755","4173.16797","0.00748","417.31680","0.00026"
"22.80000","0.75744","4199.19775","0.00757","419.91977","0.00026"
"23.10000","0.76760","4227.72266","0.00768","422.77228","0.00028"
"23.40000","0.77755","4253.60156","0.00778","425.36017","0.00029"
"23.70000","0.78747","4278.71777","0.00787","427.87177","0.00026"
"24.00000","0.79744","4304.13428","0.00797","430.41342","0.00026"
"24.30000","0.80741","4329.06641","0.00807","432.90665","0.00027"
"24.60000","0.81750","4354.58252","0.00818","435.45825","0.00029"
"24.90000","0.82752","4379.29980","0.00828","437.92999","0.00027"
"25.20000","0.83751","4403.69971","0.00838","440.36996","0.00026"
"25.50000","0.84765","4429.28320","0.00848","442.92831","0.00026"
"25.80000","0.85753","4451.90576","0.00858","445.19058","0.00028"
"26.10000","0.86740","4474.34570","0.00867","447.43457","0.00027"
"26.40000","0.87740","4497.87695","0.00877","449.78769","0.00026"
"26.70000","0.88739","4521.88428","0.00887","452.18842","0.00026"
"27.00000","0.89765","4548.04883","0.00898","454.80487","0.00027"
"27.30000","0.90761","4570.88184","0.00908","457.08820","0.00028"
"27.60000","0.91757","4593.83984","0.00918","459.38397","0.00027"
"27.90000","0.92751","4616.76025","0.00928","461.67603","0.00026"
"28.20000","0.93748","4639.60986","0.00937","463.96100","0.00027"
"28.50000","0.94737","4661.14990","0.00947","466.11499","0.00028"
"28.80000","0.95748","4684.50098","0.00957","468.45010","0.00027"
"29.10000","0.96748","4706.34619","0.00967","470.63461","0.00025"
"29.40000","0.97760","4729.89453","0.00978","472.98944","0.00026"
"29.70000","0.98747","4750.58008","0.00987","475.05801","0.00028"
"30.00000","0.99761","4773.17188","0.00998","477.31720","0.00028"
"30.30000","1.00751","4792.84375","0.01008","479.28436","0.00026"
"30.60000","1.01753","4813.37109","0.01018","481.33710","0.00026"
"30.90000","1.02743","4831.89990","0.01027","483.19000","0.00027"
"31.20000","1.03746","4851.20898","0.01037","485.12091","0.00028"
"31.50000","1.04747","4869.94629","0.01047","486.99463","0.00027"
"31.80000","1.05756","4889.74512","0.01058","488.97452","0.00024"
"32.10000","1.06742","4906.99316","0.01067","490.69931","0.00026"
"32.40000","1.07768","4927.57812","0.01078","492.75781","0.00026"
"32.70000","1.08756","4943.59766","0.01088","494.35977","0.00030"
"33.00000","1.09743","4959.51611","0.01097","495.95160","0.00025"
"33.30000","1.10740","4976.05420","0.01107","497.60541","0.00026"
"33.60000","1.11748","4993.07178","0.01117","499.30719","0.00027"
"33.90000","1.12749","5008.14453","0.01127","500.81445","0.00027"
"34.20000","1.13762","5023.87158","0.01138","502.38715","0.00027"
"34.50000","1.14757","5036.66748","0.01148","503.66675","0.00024"
"34.80000","1.15755","5050.09033","0.01158","505.00903","0.00029"
"35.10000","1.16750","5061.94629","0.01168","506.19464","0.00028"
"35.40000","1.17747","5073.25146","0.01177","507.32513","0.00027"
"35.70000","1.18743","5083.60498","0.01187","508.36050","0.00025"
"36.00000","1.19743","5093.94189","0.01197","509.39420","0.00027"
"36.30000","1.20762","5106.92969","0.01208","510.69296","0.00028"
"36.60000","1.21748","5116.58447","0.01217","511.65845","0.00027"
"36.90000","1.22758","5127.90625","0.01228","512.79065","0.00026"
"37.20000","1.23758","5137.96191","0.01238","513.79620","0.00026"
"37.50000","1.24748","5147.17480","0.01247","514.71747","0.00028"
"37.80000","1.25742","5156.55322","0.01257","515.65533","0.00028"
"38.10000","1.26754","5166.34375","0.01268","516.63440","0.00026"
"38.40000","1.27737","5172.94189","0.01277","517.29419","0.00026"
"38.70000","1.28759","5183.89551","0.01288","518.38953","0.00027"
"39.00000","1.29750","5191.98047","0.01298","519.19806","0.00029"
"39.30000","1.30760","5200.94092","0.01308","520.09412","0.00027"
"39.60000","1.31758","5208.47314","0.01318","520.84729","0.00025"
"39.90000","1.32752","5215.40283","0.01328","521.54028","0.00026"
"40.20000","1.33732","5220.07666","0.01337","522.00769","0.00028"
"40.50000","1.34750","5227.99658","0.01348","522.79968","0.00028"
"40.80000","1.35754","5233.62549","0.01358","523.36255","0.00026"
"41.10000","1.36760","5239.47021","0.01368","523.94702","0.00026"
"41.40000","1.37749","5243.76611","0.01377","524.37659","0.00027"
"41.70000","1.38766","5251.44434","0.01388","525.14441","0.00029"
"42.00000","1.39748","5254.63574","0.01397","525.46356","0.00027"
"42.30000","1.40748","5259.03125","0.01407","525.90314","0.00025"
"42.60000","1.41745","5263.52344","0.01417","526.35236","0.00027"
"42.90000","1.42746","5267.64355","0.01427","526.76434","0.00029"
"43.20000","1.43752","5271.23193","0.01438","527.12317","0.00027"
"43.50000","1.44758","5273.62549","0.01448","527.36255","0.00025"
"43.80000","1.45748","5274.14551","0.01457","527.41455","0.00026"
"44.10000","1.46758","5275.37891","0.01468","527.53790","0.00028"
"44.40000","1.47756","5274.35352","0.01478","527.43536","0.00028"
"44.70000","1.48746","5271.66553","0.01487","527.16656","0.00026"
"45.00000","1.49743","5270.03613","0.01497","527.00360","0.00026"
"45.30000","1.50747","5268.00049","0.01507","526.80005","0.00027"
"45.60000","1.51753","5265.33594","0.01518","526.53357","0.00028"
"45.90000","1.52752","5260.68506","0.01528","526.06848","0.00027"
"46.20000","1.53763","5257.02832","0.01538","525.70282","0.00025"
"46.50000","1.54757","5251.47217","0.01548","525.14722","0.00026"
"46.80000","1.55748","5244.91064","0.01557","524.49109","0.00028"
"47.10000","1.56743","5238.43555","0.01567","523.84357","0.00028"
"47.40000","1.57743","5233.05469","0.01577","523.30548","0.00025"
"47.70000","1.58745","5228.23535","0.01587","522.82355","0.00025"
"48.00000","1.59767","5225.53564","0.01598","522.55359","0.00028"
"48.30000","1.60751","5218.18994","0.01608","521.81897","0.00029"
"48.60000","1.61759","5213.02051","0.01618","521.30206","0.00027"
"48.90000","1.62754","5205.78271","0.01628","520.57825","0.00025"
"49.20000","1.63748","5198.49561","0.01637","519.84955","0.00027"
"49.50000","1.64737","5190.09033","0.01647","519.00903","0.00029"
"49.80000","1.65750","5181.99219","0.01657","518.19922","0.00028"
"50.10000","1.66748","5170.45898","0.01667","517.04590","0.00025"
"50.40000","1.67761","5160.02832","0.01678","516.00281","0.00026"
"50.70000","1.68750","5145.77979","0.01687","514.57800","0.00028"
"51.00000","1.69763","5132.49219","0.01698","513.24921","0.00029"
"51.30000","1.70748","5115.78076","0.01707","511.57806","0.00026"
"51.60000","1.71754","5100.79004","0.01718","510.07901","0.00025"
"51.90000","1.72741","5084.16504","0.01727","508.41650","0.00026"
"52.20000","1.73739","5068.44775","0.01737","506.84479","0.00029"
"52.50000","1.74754","5054.55957","0.01748","505.45596","0.00028"
"52.80000","1.75765","5038.93555","0.01758","503.89355","0.00025"
"53.10000","1.76752","5020.14209","0.01768","502.01422","0.00026"
"53.40000","1.77765","5002.90674","0.01778","500.29068","0.00028"
"53.70000","1.78753","4984.19482","0.01788","498.41949","0.00028"
"54.00000","1.79735","4964.86377","0.01797","496.48639","0.00026"
"54.30000","1.80743","4946.12061","0.01807","494.61206","0.00025"
"54.60000","1.81751","4927.88428","0.01818","492.78842","0.00027"
"54.90000","1.82755","4910.66553","0.01828","491.06656","0.00029"
"55.20000","1.83754","4892.25635","0.01838","489.22565","0.00027"
"55.50000","1.84758","4873.80908","0.01848","487.38092","0.00025"
"55.80000","1.85754","4856.11670","0.01858","485.61166","0.00027"
"56.10000","1.86751","4838.81201","0.01868","483.88120","0.00029"
"56.40000","1.87749","4820.39990","0.01877","482.03998","0.00027"
"56.70000","1.88744","4800.20264","0.01887","480.02026","0.00026"
"57.00000","1.89744","4780.13477","0.01897","478.01349","0.00025"
"57.30000","1.90761","4759.89014","0.01908","475.98901","0.00028"
"57.60000","1.91742","4734.73096","0.01917","473.47308","0.00029"
"57.90000","1.92760","4711.85840","0.01928","471.18585","0.00027"
"58.20000","1.93764","4686.20459","0.01938","468.62045","0.00025"
"58.50000","1.94751","4656.62012","0.01948","465.66202","0.00027"
"58.80000","1.95739","4625.70752","0.01957","462.57074","0.00028"
"59.10000","1.96747","4593.20215","0.01967","459.32022","0.00027"
"59.40000","1.97739","4556.64307","0.01977","455.66431","0.00026"
"59.70000","1.98763","4521.23877","0.01988","452.12387","0.00027"
"60.00000","1.99761","4480.89111","0.01998","448.08911","0.00028"
"60.30000","2.00759","4439.64014","0.02008","443.96402","0.00028"
"60.60000","2.01756","4395.10449","0.02018","439.51044","0.00026"
"60.90000","2.02749","4350.47852","0.02027","435.04785","0.00026"
"61.20000","2.03732","4305.34424","0.02037","430.53442","0.00027"
"61.50000","2.04745","4263.15234","0.02047","426.31525","0.00028"
"61.80000","2.05766","4222.20752","0.02058","422.22076","0.00026"
"62.10000","2.06758","4180.95947","0.02068","418.09595","0.00026"
"62.40000","2.07751","4141.53613","0.02078","414.15363","0.00027"
"62.70000","2.08758","4105.08643","0.02088","410.50864","0.00028"
"63.00000","2.09744","4068.42310","0.02097","406.84232","0.00027"
"63.30000","2.10744","4032.79858","0.02107","403.27985","0.00026"
"63.60000","2.11754","3996.50195","0.02118","399.65021","0.00026"
"63.90000","2.12742","3958.12915","0.02127","395.81293","0.00028"
"64.20000","2.13757","3922.84839","0.02138","392.28485","0.00028"
"64.50000","2.14751","3887.98120","0.02148","388.79813","0.00026"
"64.80000","2.15751","3856.12573","0.02158","385.61258","0.00026"
"65.10000","2.16760","3827.68726","0.02168","382.76874","0.00028"
"65.40000","2.17759","3801.83569","0.02178","380.18356","0.00028"
"65.70000","2.18741","3777.52271","0.02187","377.75226","0.00027"
"66.00000","2.19746","3758.90869","0.02197","375.89087","0.00026"
"66.30000","2.20739","3741.27661","0.02207","374.12766","0.00027"
"66.60000","2.21755","3725.50928","0.02218","372.55093","0.00028"
"66.90000","2.22751","3708.08813","0.02228","370.80881","0.00027"
"67.20000","2.23769","3693.24194","0.02238","369.32419","0.00026"
"67.50000","2.24755","3675.99585","0.02248","367.59958","0.00026"
"67.80000","2.25749","3661.83813","0.02257","366.18381","0.00028"
"68.10000","2.26737","3649.75098","0.02267","364.97510","0.00028"
"68.40000","2.27742","3639.86987","0.02277","363.98700","0.00026"
"68.70000","2.28746","3631.15454","0.02287","363.11545","0.00025"
"69.00000","2.29771","3626.57764","0.02298","362.65778","0.00027"
"69.30000","2.30745","3615.98315","0.02307","361.59833","0.00029"
"69.60000","2.31761","3609.62231","0.02318","360.96222","0.00027"
"69.90000","2.32746","3600.38770","0.02327","360.03876","0.00025"
"70.20000","2.33746","3593.85229","0.02337","359.38522","0.00026"
"70.50000","2.34741","3587.96118","0.02347","358.79611","0.00029"
"70.80000","2.35753","3584.41138","0.02358","358.44113","0.00028"
"71.10000","2.36750","3579.20044","0.02367","357.92004","0.00025"
"71.40000","2.37760","3575.39209","0.02378","357.53922","0.00025"
"71.70000","2.38742","3568.18652","0.02387","356.81866","0.00028"
"72.00000","2.39760","3566.32544","0.02398","356.63254","0.00028"
"72.30000","2.40751","3561.88818","0.02408","356.18881","0.00027"
"72.60000","2.41750","3557.73633","0.02418","355.77362","0.00025"
"72.90000","2.42746","3553.07617","0.02427","355.30762","0.00027"
"73.20000","2.43743","3548.74536","0.02437","354.87454","0.00028"
"73.50000","2.44750","3545.50708","0.02447","354.55072","0.00027"
"73.80000","2.45753","3543.15088","0.02458","354.31509","0.00025"
"74.10000","2.46756","3538.21582","0.02468","353.82159","0.00026"
"74.40000","2.47761","3532.61865","0.02478","353.26187","0.00028"
"74.70000","2.48753","3524.39062","0.02488","352.43906","0.00028"
"75.00000","2.49738","3516.72534","0.02497","351.67255","0.00026"
"75.30000","2.50742","3510.46997","0.02507","351.04700","0.00025"
"75.60000","2.51746","3505.41846","0.02517","350.54184","0.00027"
"75.90000","2.52763","3502.97510","0.02528","350.29752","0.00029"
"76.20000","2.53745","3498.47485","0.02537","349.84747","0.00027"
"76.50000","2.54760","3496.79736","0.02548","349.67975","0.00025"
"76.80000","2.55752","3493.27368","0.02558","349.32736","0.00026"
"77.10000","2.56746","3488.76123","0.02567","348.87613","0.00028"
"77.40000","2.57742","3482.20728","0.02577","348.22073","0.00028"
"77.70000","2.58751","3475.79468","0.02588","347.57947","0.00026"
"78.00000","2.59746","3468.42285","0.02597","346.84229","0.00025"
"78.30000","2.60769","3464.60913","0.02608","346.46091","0.00028"
"78.60000","2.61743","3457.39722","0.02617","345.73972","0.00028"
"78.90000","2.62752","3454.33813","0.02628","345.43381","0.00027"
"79.20000","2.63752","3449.81763","0.02638","344.98175","0.00025"
"79.50000","2.64753","3444.32812","0.02648","344.43280","0.00027"
"79.80000","2.65742","3436.63647","0.02657","343.66364","0.00029"
"80.10000","2.66750","3429.67139","0.02668","342.96713","0.00028"
"80.40000","2.67744","3420.73584","0.02677","342.07358","0.00026"
"80.70000","2.68754","3414.75562","0.02688","341.47556","0.00026"
"81.00000","2.69753","3408.44727","0.02698","340.84473","0.00028"
"81.30000","2.70761","3403.95239","0.02708","340.39523","0.00028"
"81.60000","2.71749","3399.18140","0.02717","339.91815","0.00026"
"81.90000","2.72751","3397.67407","0.02728","339.76740","0.00025"
"82.20000","2.73737","3395.67261","0.02737","339.56726","0.00027"
"82.50000","2.74741","3396.48462","0.02747","339.64847","0.00029"
"82.80000","2.75758","3398.25610","0.02758","339.82562","0.00027"
"83.10000","2.76755","3398.36768","0.02768","339.83676","0.00026"
"83.40000","2.77749","3396.32446","0.02777","339.63245","0.00026"
"83.70000","2.78767","3395.19019","0.02788","339.51901","0.00028"
"84.00000","2.79746","3389.97314","0.02797","338.99731","0.00028"
"84.30000","2.80736","3384.39526","0.02807","338.43951","0.00026"
"84.60000","2.81744","3380.66846","0.02817","338.06683","0.00025"
"84.90000","2.82749","3376.64038","0.02827","337.66403","0.00028"
"85.20000","2.83760","3371.59668","0.02838","337.15967","0.00029"
"85.50000","2.84758","3365.52563","0.02848","336.55255","0.00027"
"85.80000","2.85751","3358.98462","0.02858","335.89847","0.00025"
"86.10000","2.86749","3352.18042","0.02867","335.21805","0.00026"
"86.40000","2.87751","3344.85352","0.02878","334.48535","0.00029"
"86.70000","2.88744","3335.89233","0.02887","333.58923","0.00027"
"87.00000","2.89747","3328.24170","0.02897","332.82416","0.00026"
"87.30000","2.90750","3321.39160","0.02908","332.13916","0.00025"
"87.60000","2.91756","3315.40527","0.02918","331.54053","0.00028"
"87.90000","2.92745","3309.13062","0.02927","330.91306","0.00028"
"88.20000","2.93761","3305.72314","0.02938","330.57233","0.00026"
"88.50000","2.94752","3299.27173","0.02948","329.92719","0.00025"
"88.80000","2.95751","3293.21069","0.02958","329.32108","0.00027"
"89.10000","2.96746","3287.56567","0.02967","328.75656","0.00028"
"89.40000","2.97743","3283.90112","0.02977","328.39011","0.00027"
"89.70000","2.98745","3280.56372","0.02987","328.05637","0.00025"
"90.00000","2.99759","3279.52197","0.02998","327.95221","0.00026"
"90.30000","3.00749","3275.68091","0.03007","327.56808","0.00028"
"90.60000","3.01766","3273.48560","0.03018","327.34857","0.00028"
"90.90000","3.02754","3268.93506","0.03028","326.89349","0.00026"
"91.20000","3.03741","3264.47778","0.03037","326.44778","0.00026"
"91.50000","3.04738","3261.39600","0.03047","326.13959","0.00027"
"91.80000","3.05745","3259.33740","0.03057","325.93375","0.00028"
"92.10000","3.06756","3257.42993","0.03068","325.74298","0.00027"
"92.40000","3.07764","3254.57422","0.03078","325.45743","0.00026"
"92.70000","3.08754","3249.39478","0.03088","324.93948","0.00026"
"93.00000","3.09754","3244.90210","0.03098","324.49020","0.00028"
"93.30000","3.10747","3239.36646","0.03107","323.93665","0.00027"
"93.60000","3.11740","3233.47754","0.03117","323.34775","0.00026"
"93.90000","3.12747","3228.80420","0.03127","322.88043","0.00026"
"94.20000","3.13749","3222.65625","0.03137","322.26562","0.00028"
"94.50000","3.14762","3215.34937","0.03148","321.53494","0.00027"
"94.80000","3.15748","3206.38745","0.03157","320.63873","0.00026"
"95.10000","3.16755","3198.49780","0.03168","319.84979","0.00026"
"95.40000","3.17751","3189.07275","0.03178","318.90729","0.00027"
"95.70000","3.18753","3178.49878","0.03188","317.84988","0.00028"
"96.00000","3.19743","3167.69629","0.03197","316.76962","0.00027"
"96.30000","3.20747","3159.58960","0.03207","315.95895","0.00026"
"96.60000","3.21743","3151.82031","0.03217","315.18204","0.00026"
"96.90000","3.22759","3146.24487","0.03228","314.62448","0.00028"
"97.20000","3.23743","3136.55591","0.03237","313.65558","0.00028"
"97.50000","3.24763","3130.24121","0.03248","313.02411","0.00026"
"97.80000","3.25759","3121.84668","0.03258","312.18466","0.00025"
"98.10000","3.26751","3112.56519","0.03268","311.25653","0.00028"
"98.40000","3.27740","3104.11230","0.03277","310.41122","0.00028"
"98.70000","3.28748","3098.30933","0.03287","309.83093","0.00027"
"99.00000","3.29744","3090.87329","0.03297","309.08734","0.00026"
"99.30000","3.30766","3085.58228","0.03308","308.55823","0.00027"
"99.60000","3.31755","3075.91382","0.03318","307.59137","0.00028"
"99.90000","3.32760","3065.77002","0.03328","306.57700","0.00027"
"100.20000","3.33748","3052.42529","0.03337","305.24252","0.00027"
"100.50000","3.34745","3037.87646","0.03347","303.78766","0.00026"
"100.80000","3.35740","3022.70361","0.03357","302.27036","0.00028"
"101.10000","3.36751","3010.02368","0.03368","301.00238","0.00028"
"101.40000","3.37755","2997.13306","0.03378","299.71332","0.00027"
"101.70000","3.38754","2985.08789","0.03388","298.50879","0.00026"
"102.00000","3.39750","2974.34351","0.03398","297.43436","0.00027"
"102.30000","3.40760","2964.64111","0.03408","296.46411","0.00028"
"102.60000","3.41750","2952.76855","0.03417","295.27686","0.00027"
"102.90000","3.42744","2940.85278","0.03427","294.08527","0.00026"
"103.20000","3.43752","2931.12891","0.03438","293.11288","0.00026"
"103.50000","3.44740","2919.79517","0.03447","291.97952","0.00028"
"103.80000","3.45758","2911.95215","0.03458","291.19522","0.00028"
"104.10000","3.46750","2903.91870","0.03467","290.39188","0.00026"
"104.40000","3.47752","2897.01514","0.03478","289.70151","0.00026"
"104.70000","3.48761","2891.88354","0.03488","289.18835","0.00028"
"105.00000","3.49753","2884.50073","0.03498","288.45007","0.00028"
"105.30000","3.50737","2876.46680","0.03507","287.64667","0.00026"
"105.60000","3.51749","2870.84180","0.03517","287.08417","0.00026"
"105.90000","3.52756","2866.00073","0.03528","286.60007","0.00027"
"106.20000","3.53763","2860.94702","0.03538","286.09470","0.00028"
"106.50000","3.54750","2852.67822","0.03548","285.26782","0.00027"
"106.80000","3.55764","2848.23096","0.03558","284.82309","0.00025"
"107.10000","3.56747","2841.42285","0.03567","284.14227","0.00026"
"107.40000","3.57748","2836.45142","0.03577","283.64514","0.00028"
"107.70000","3.58745","2832.50146","0.03587","283.25015","0.00028"
"108.00000","3.59750","2830.02759","0.03598","283.00275","0.00025"
"108.30000","3.60745","2825.82764","0.03607","282.58276","0.00026"
"108.60000","3.61764","2823.49609","0.03618","282.34961","0.00028"
"108.90000","3.62744","2817.15942","0.03627","281.71594","0.00028"
"109.20000","3.63761","2814.98071","0.03638","281.49808","0.00027"
"109.50000","3.64753","2812.22900","0.03648","281.22290","0.00026"
"109.80000","3.65746","2808.61548","0.03657","280.86154","0.00027"
"110.10000","3.66742","2803.33228","0.03667","280.33322","0.00028"
"110.40000","3.67751","2799.68164","0.03678","279.96817","0.00028"
"110.70000","3.68749","2794.56348","0.03687","279.45636","0.00025"
"111.00000","3.69755","2791.26562","0.03698","279.12656","0.00027"
"111.30000","3.70753","2787.95142","0.03708","278.79514","0.00028"
"111.60000","3.71764","2785.16895","0.03718","278.51691","0.00029"
"111.90000","3.72749","2779.04883","0.03727","277.90488","0.00026"
"112.20000","3.73742","2773.30469","0.03737","277.33047","0.00026"
"112.50000","3.74739","2766.92603","0.03747","276.69260","0.00027"
"112.80000","3.75747","2761.41748","0.03757","276.14175","0.00029"
"113.10000","3.76765","2756.53784","0.03768","275.65378","0.00027"
"113.40000","3.77755","2749.44629","0.03778","274.94464","0.00025"
"113.70000","3.78754","2743.48364","0.03788","274.34836","0.00027"
"114.00000","3.79758","2740.16357","0.03798","274.01636","0.00028"
"114.30000","3.80747","2735.86426","0.03807","273.58643","0.00028"
"114.60000","3.81742","2732.38062","0.03817","273.23807","0.00026"
"114.90000","3.82750","2729.88037","0.03827","272.98804","0.00026"
"115.20000","3.83741","2725.46021","0.03837","272.54602","0.00028"
"115.50000","3.84759","2723.66748","0.03848","272.36676","0.00029"
"115.80000","3.85752","2719.20166","0.03858","271.92017","0.00026"
"116.10000","3.86757","2715.30078","0.03868","271.53009","0.00026"
"116.40000","3.87750","2710.03467","0.03877","271.00348","0.00027"
"116.70000","3.88752","2705.68945","0.03888","270.56894","0.00028"
"117.00000","3.89743","2700.70898","0.03897","270.07089","0.00028"
"117.30000","3.90746","2698.37134","0.03907","269.83713","0.00026"
"117.60000","3.91749","2697.37280","0.03917","269.73727","0.00025"
"117.90000","3.92762","2698.32666","0.03928","269.83267","0.00027"
"118.20000","3.93746","2695.49658","0.03937","269.54965","0.00028"
"118.50000","3.94764","2695.04346","0.03948","269.50433","0.00026"
"118.80000","3.95752","2691.90112","0.03958","269.19012","0.00026"
"119.10000","3.96742","2688.46069","0.03967","268.84607","0.00027"
"119.40000","3.97744","2684.86035","0.03977","268.48602","0.00030"
"119.70000","3.98753","2681.09839","0.03988","268.10983","0.00028"
"120.00000","3.99751","2676.80884","0.03998","267.68088","0.00026"
"120.30000","4.00760","2674.02393","0.04008","267.40240","0.00026"
"120.60000","4.01754","2669.21533","0.04018","266.92154","0.00029"
"120.90000","4.02756","2663.13696","0.04028","266.31369","0.00028"
"121.20000","4.03751","2655.27002","0.04038","265.52701","0.00025"
"121.50000","4.04746","2647.36719","0.04047","264.73672","0.00027"
"121.80000","4.05742","2640.35669","0.04057","264.03568","0.00027"
"122.10000","4.06747","2634.90649","0.04067","263.49066","0.00029"
"122.40000","4.07759","2630.67480","0.04078","263.06747","0.00026"
"122.70000","4.08752","2624.03809","0.04088","262.40381","0.00026"
"123.00000","4.09756","2617.67944","0.04098","261.76794","0.00027"
"123.30000","4.10758","2611.50293","0.04108","261.15030","0.00028"
"123.60000","4.11747","2603.92554","0.04117","260.39255","0.00028"
"123.90000","4.12744","2597.95996","0.04127","259.79599","0.00026"
"124.20000","4.13744","2592.55713","0.04137","259.25571","0.00026"
"124.50000","4.14738","2585.96997","0.04147","258.59698","0.00028"
"124.80000","4.15762","2582.83618","0.04158","258.28363","0.00028"
"125.10000","4.16764","2577.71729","0.04168","257.77173","0.00026"
"125.40000","4.17759","2573.45410","0.04178","257.34540","0.00025"
"125.70000","4.18753","2569.98682","0.04188","256.99869","0.00027"
"126.00000","4.19747","2566.76270","0.04197","256.67627","0.00028"
"126.30000","4.20732","2561.94067","0.04207","256.19406","0.00028"
"126.60000","4.21746","2559.24243","0.04217","255.92424","0.00025"
"126.90000","4.22761","2556.18018","0.04228","255.61801","0.00026"
"127.20000","4.23760","2551.34521","0.04238","255.13452","0.00029"
"127.50000","4.24747","2545.48901","0.04247","254.54890","0.00028"
"127.80000","4.25760","2541.33276","0.04258","254.13327","0.00026"
"128.10000","4.26744","2535.43433","0.04267","253.54343","0.00026"
"128.40000","4.27746","2531.07031","0.04277","253.10703","0.00027"
"128.70000","4.28748","2527.32568","0.04287","252.73257","0.00028"
"129.00000","4.29747","2523.46802","0.04297","252.34680","0.00027"
"129.30000","4.30752","2518.47144","0.04308","251.84714","0.00026"
"129.60000","4.31755","2513.65308","0.04318","251.36531","0.00026"
"129.90000","4.32745","2507.59595","0.04327","250.75960","0.00028"
"130.20000","4.33759","2502.87085","0.04338","250.28708","0.00028"
"130.50000","4.34761","2497.28296","0.04348","249.72830","0.00026"
"130.80000","4.35746","2491.98926","0.04357","249.19893","0.00026"
"131.10000","4.36744","2487.92676","0.04367","248.79268","0.00028"
"131.40000","4.37742","2483.31494","0.04377","248.33150","0.00029"
"131.70000","4.38750","2479.36621","0.04388","247.93661","0.00027"
"132.00000","4.39756","2476.25391","0.04398","247.62540","0.00025"
"132.30000","4.40765","2473.94189","0.04408","247.39420","0.00028"
"132.60000","4.41754","2469.71631","0.04418","246.97163","0.00027"
"132.90000","4.42749","2465.57007","0.04427","246.55701","0.00027"
"133.20000","4.43741","2460.12891","0.04437","246.01289","0.00025"
"133.50000","4.44741","2456.86328","0.04447","245.68633","0.00026"
"133.80000","4.45744","2453.65698","0.04457","245.36569","0.00028"
"134.10000","4.46771","2452.56787","0.04468","245.25679","0.00028"
"134.40000","4.47746","2446.34033","0.04477","244.63403","0.00026"
"134.70000","4.48757","2443.04980","0.04488","244.30498","0.00026"
"135.00000","4.49746","2437.91162","0.04497","243.79117","0.00027"
"135.30000","4.50745","2431.43433","0.04507","243.14343","0.00028"
"135.60000","4.51739","2423.50439","0.04517","242.35043","0.00027"
"135.90000","4.52756","2417.94849","0.04528","241.79485","0.00025"
"136.20000","4.53744","2410.19165","0.04537","241.01917","0.00026"
"136.50000","4.54760","2405.65308","0.04548","240.56531","0.00029"
"136.80000","4.55741","2398.50000","0.04557","239.85001","0.00028"
"137.10000","4.56758","2394.99243","0.04568","239.49924","0.00026"
"137.40000","4.57754","2388.79053","0.04578","238.87906","0.00026"
"137.70000","4.58756","2383.40381","0.04588","238.34038","0.00028"
"138.00000","4.59740","2376.44019","0.04597","237.64401","0.00028"
"138.30000","4.60745","2371.90405","0.04607","237.19040","0.00028"
"138.60000","4.61747","2367.33521","0.04617","236.73352","0.00026"
"138.90000","4.62754","2364.97290","0.04628","236.49728","0.00027"
"139.20000","4.63753","2362.15063","0.04638","236.21506","0.00028"
"139.50000","4.64765","2359.74634","0.04648","235.97464","0.00028"
"139.80000","4.65754","2353.48901","0.04658","235.34891","0.00026"
"140.10000","4.66740","2346.18652","0.04667","234.61865","0.00026"
"140.40000","4.67739","2340.26733","0.04677","234.02673","0.00028"
"140.70000","4.68744","2334.65649","0.04687","233.46565","0.00028"
"141.00000","4.69760","2328.51514","0.04698","232.85152","0.00026"
"141.30000","4.70753","2321.17188","0.04708","232.11719","0.00026"
"141.60000","4.71755","2313.58984","0.04718","231.35898","0.00027"
"141.90000","4.72755","2305.24927","0.04728","230.52493","0.00028"
"142.20000","4.73745","2296.47314","0.04737","229.64731","0.00027"
"142.50000","4.74741","2289.90308","0.04747","228.99031","0.00026"
"142.80000","4.75749","2284.04297","0.04757","228.40430","0.00027"
"143.10000","4.76746","2276.84937","0.04767","227.68494","0.00028"
"143.40000","4.77762","2272.38037","0.04778","227.23804","0.00027"
"143.70000","4.78747","2268.05811","0.04787","226.80582","0.00026"
"144.00000","4.79750","2265.62793","0.04797","226.56279","0.00026"
"144.30000","4.80753","2263.38965","0.04808","226.33896","0.00028"
"144.60000","4.81751","2260.19165","0.04818","226.01917","0.00028"
"144.90000","4.82744","2256.00317","0.04827","225.60031","0.00026"
"145.20000","4.83752","2253.70068","0.04838","225.37007","0.00026"
"145.50000","4.84741","2249.97681","0.04847","224.99768","0.00027"
"145.80000","4.85756","2247.64990","0.04858","224.76498","0.00028"
"146.10000","4.86748","2243.40918","0.04867","224.34091","0.00027"
"146.40000","4.87763","2239.71899","0.04878","223.97189","0.00026"
"146.70000","4.88750","2233.49243","0.04888","223.34924","0.00027"
"147.00000","4.89754","2228.72144","0.04898","222.87215","0.00028"
"147.30000","4.90735","2222.53882","0.04907","222.25388","0.00028"
"147.60000","4.91742","2217.99243","0.04917","221.79924","0.00026"
"147.90000","4.92753","2214.91357","0.04928","221.49136","0.00026"
"148.20000","4.93762","2212.87402","0.04938","221.28740","0.00028"
"148.50000","4.94743","2209.32397","0.04947","220.93240","0.00028"
"148.80000","4.95767","2209.34570","0.04958","220.93457","0.00026"
"149.10000","4.96747","2206.97241","0.04967","220.69724","0.00026"
"149.40000","4.97740","2204.12207","0.04977","220.41220","0.00027"
"149.70000","4.98743","2202.09619","0.04987","220.20963","0.00029"
"150.00000","4.99743","2198.99146","0.04997","219.89914","0.00027"
"150.30000","5.00755","2196.56274","0.05008","219.65628","0.00026"
"150.60000","5.01765","2194.24048","0.05018","219.42404","0.00027"
"150.90000","5.02749","2189.73608","0.05027","218.97360","0.00028"
"151.20000","5.03751","2187.50000","0.05038","218.75000","0.00027"
"151.50000","5.04752","2186.66040","0.05048","218.66605","0.00026"
"151.80000","5.05744","2186.13281","0.05057","218.61328","0.00026"
"152.10000","5.06745","2187.58667","0.05067","218.75867","0.00028"
"152.40000","5.07749","2189.88696","0.05077","218.98869","0.00028"
"152.70000","5.08753","2191.55713","0.05088","219.15572","0.00027"
"153.00000","5.09745","2190.91089","0.05097","219.09109","0.00026"
"153.30000","5.10760","2191.40063","0.05108","219.14006","0.00027"
"153.60000","5.11757","2190.76831","0.05118","219.07683","0.00028"
"153.90000","5.12752","2189.04565","0.05128","218.90457","0.00027"
"154.20000","5.13744","2185.92725","0.05137","218.59273","0.00026"
"154.50000","5.14743","2183.68701","0.05147","218.36870","0.00026"
"154.80000","5.15740","2180.91919","0.05157","218.09192","0.00028"
"155.10000","5.16760","2180.14111","0.05168","218.01411","0.00028"
"155.40000","5.17747","2175.29712","0.05177","217.52971","0.00026"
"155.70000","5.18764","2173.75537","0.05188","217.37553","0.00026"
"156.00000","5.19758","2170.92432","0.05198","217.09244","0.00028"
"156.30000","5.20744","2167.94751","0.05207","216.79475","0.00028"
"156.60000","5.21735","2165.09595","0.05217","216.50960","0.00027"
"156.90000","5.22746","2163.79468","0.05227","216.37947","0.00026"
"157.20000","5.23752","2160.50586","0.05238","216.05058","0.00027"
"157.50000","5.24767","2158.50391","0.05248","215.85039","0.00028"
"157.80000","5.25753","2154.65991","0.05258","215.46599","0.00027"
"158.10000","5.26753","2151.51855","0.05268","215.15186","0.00027"
"158.40000","5.27746","2147.62158","0.05277","214.76216","0.00026"
"158.70000","5.28747","2145.13257","0.05287","214.51326","0.00029"
"159.00000","5.29746","2141.92432","0.05297","214.19243","0.00028"
"159.30000","5.30748","2139.06592","0.05307","213.90659","0.00028"
"159.60000","5.31758","2136.07446","0.05318","213.60745","0.00026"
"159.90000","5.32753","2132.39697","0.05328","213.23970","0.00028"
"160.20000","5.33750","2128.77173","0.05338","212.87717","0.00029"
"160.50000","5.34754","2126.07642","0.05348","212.60764","0.00027"
"160.80000","5.35752","2123.36694","0.05358","212.33670","0.00025"
"161.10000","5.36745","2118.01318","0.05367","211.80132","0.00027"
"161.40000","5.37749","2112.32520","0.05377","211.23251","0.00029"
"161.70000","5.38741","2105.10376","0.05387","210.51038","0.00027"
"162.00000","5.39756","2099.08643","0.05398","209.90865","0.00026"
"162.30000","5.40744","2091.48706","0.05407","209.14871","0.00026"
"162.60000","5.41762","2088.63794","0.05418","208.86380","0.00028"
"162.90000","5.42764","2084.68433","0.05428","208.46843","0.00028"
"163.20000","5.43751","2081.08862","0.05438","208.10886","0.00027"
"163.50000","5.44735","2078.69360","0.05447","207.86935","0.00026"
"163.80000","5.45746","2079.53418","0.05457","207.95341","0.00027"
"164.10000","5.46743","2080.21875","0.05467","208.02188","0.00028"
"164.40000","5.47766","2084.04907","0.05478","208.40491","0.00028"
"164.70000","5.48754","2085.11475","0.05488","208.51147","0.00026"
"165.00000","5.49759","2087.46484","0.05498","208.74649","0.00026"
"165.30000","5.50750","2088.57251","0.05508","208.85725","0.00028"
"165.60000","5.51751","2089.06982","0.05518","208.90698","0.00029"
"165.90000","5.52739","2087.20630","0.05527","208.72063","0.00027"
"166.20000","5.53747","2083.92529","0.05537","208.39253","0.00026"
"166.50000","5.54751","2078.93970","0.05548","207.89397","0.00028"
"166.80000","5.55760","2074.25342","0.05558","207.42534","0.00029"
"167.10000","5.56748","2068.43921","0.05567","206.84392","0.00028"
"167.40000","5.57759","2065.08447","0.05578","206.50845","0.00025"
"167.70000","5.58748","2060.43799","0.05587","206.04379","0.00026"
"168.00000","5.59751","2056.82275","0.05598","205.68228","0.00028"
"168.30000","5.60745","2051.29712","0.05607","205.12971","0.00028"
"168.60000","5.61742","2047.72742","0.05617","204.77274","0.00026"
"168.90000","5.62753","2048.01831","0.05628","204.80183","0.00026"
"169.20000","5.63754","2048.69116","0.05638","204.86911","0.00027"
"169.50000","5.64749","2047.89526","0.05647","204.78952","0.00029"
"169.80000","5.65765","2049.35767","0.05658","204.93576","0.00027"
"170.10000","5.66755","2049.19922","0.05668","204.91992","0.00026"
"170.40000","5.67738","2046.95691","0.05677","204.69569","0.00027"
"170.70000","5.68746","2044.64124","0.05687","204.46413","0.00030"
"171.00000","5.69748","2041.19458","0.05697","204.11946","0.00027"
"171.30000","5.70755","2038.56458","0.05708","203.85646","0.00025"
"171.60000","5.71755","2035.67444","0.05718","203.56744","0.00026"
"171.90000","5.72761","2032.50745","0.05728","203.25075","0.00028"
"172.20000","5.73753","2027.46899","0.05738","202.74690","0.00029"
"172.50000","5.74748","2021.28479","0.05747","202.12848","0.00026"
"172.80000","5.75746","2016.30127","0.05757","201.63013","0.00026"
"173.10000","5.76747","2012.38489","0.05767","201.23849","0.00027"
"173.40000","5.77744","2006.79138","0.05777","200.67914","0.00029"
"173.70000","5.78763","2002.08630","0.05788","200.20863","0.00027"
"174.00000","5.79744","1994.24365","0.05797","199.42436","0.00026"
"174.30000","5.80758","1987.66724","0.05808","198.76672","0.00026"
"174.60000","5.81760","1980.07751","0.05818","198.00775","0.00029"
"174.90000","5.82752","1972.45947","0.05828","197.24594","0.00028"
"175.20000","5.83742","1965.71033","0.05837","196.57103","0.00027"
"175.50000","5.84751","1963.40332","0.05848","196.34033","0.00025"
"175.80000","5.85743","1960.72388","0.05857","196.07239","0.00028"
"176.10000","5.86762","1961.00244","0.05868","196.10025","0.00029"
"176.40000","5.87750","1959.22180","0.05877","195.92218","0.00027"
"176.70000","5.88760","1959.82104","0.05888","195.98210","0.00026"
"177.00000","5.89750","1960.27380","0.05898","196.02737","0.00027"
"177.30000","5.90751","1959.56812","0.05908","195.95682","0.00029"
"177.60000","5.91737","1957.00708","0.05917","195.70071","0.00028"
"177.90000","5.92746","1957.89526","0.05927","195.78952","0.00026"
"178.20000","5.93761","1957.88281","0.05938","195.78828","0.00026"
"178.50000","5.94761","1955.83813","0.05948","195.58382","0.00028"
"178.80000","5.95752","1952.67834","0.05958","195.26784","0.00029"
"179.10000","5.96764","1949.86719","0.05968","194.98672","0.00026"
"179.40000","5.97745","1941.92590","0.05977","194.19260","0.00025"
"179.70000","5.98742","1936.02966","0.05987","193.60297","0.00028"
"180.00000","5.99748","1929.58801","0.05997","192.95880","0.00028"
"180.30000","6.00748","1922.32202","0.06007","192.23221","0.00027"
"180.60000","6.01756","1915.51074","0.06018","191.55107","0.00026"
"180.90000","6.02757","1907.06213","0.06028","190.70621","0.00027"
"181.20000","6.03753","1897.82080","0.06038","189.78207","0.00028"
"181.50000","6.04755","1891.36511","0.06048","189.13651","0.00028"
"181.80000","6.05752","1886.74634","0.06058","188.67464","0.00027"
"182.10000","6.06741","1882.48767","0.06067","188.24876","0.00026"
"182.40000","6.07743","1879.74500","0.06077","187.97450","0.00027"
"182.70000","6.08750","1877.50342","0.06088","187.75034","0.00029"
"183.00000","6.09761","1874.99878","0.06098","187.49988","0.00027"
"183.30000","6.10748","1871.17493","0.06107","187.11749","0.00026"
"183.60000","6.11764","1869.85010","0.06118","186.98502","0.00027"
"183.90000","6.12754","1866.30261","0.06128","186.63026","0.00028"
"184.20000","6.13745","1863.00708","0.06137","186.30070","0.00027"
"184.50000","6.14741","1858.27161","0.06147","185.82716","0.00026"
"184.80000","6.15748","1854.15710","0.06157","185.41571","0.00027"
"185.10000","6.16748","1849.40845","0.06167","184.94084","0.00028"
"185.40000","6.17769","1846.40417","0.06178","184.64041","0.00028"
"185.70000","6.18750","1841.02991","0.06188","184.10300","0.00026"
"186.00000","6.19759","1838.25122","0.06198","183.82512","0.00026"
"186.30000","6.20752","1831.62451","0.06208","183.16245","0.00027"
"186.60000","6.21748","1826.25354","0.06217","182.62535","0.00028"
"186.90000","6.22743","1820.16882","0.06227","182.01688","0.00027"
"187.20000","6.23750","1815.85254","0.06237","181.58525","0.00026"
"187.50000","6.24753","1811.70007","0.06248","181.17001","0.00027"
"187.80000","6.25754","1808.36194","0.06258","180.83620","0.00028"
"188.10000","6.26750","1806.19434","0.06267","180.61943","0.00028"
"188.40000","6.27763","1806.89185","0.06278","180.68918","0.00027"
"188.70000","6.28747","1806.02710","0.06287","180.60271","0.00025"
"189.00000","6.29748","1807.60193","0.06297","180.76019","0.00028"
"189.30000","6.30746","1808.12903","0.06307","180.81290","0.00028"
"189.60000","6.31741","1807.79700","0.06317","180.77969","0.00027"
"189.90000","6.32759","1809.54211","0.06328","180.95421","0.00026"
"190.20000","6.33761","1810.43701","0.06338","181.04370","0.00028"
"190.50000","6.34753","1810.13159","0.06348","181.01315","0.00028"
"190.80000","6.35760","1810.46338","0.06358","181.04634","0.00027"
"191.10000","6.36750","1808.85657","0.06368","180.88565","0.00026"
"191.40000","6.37732","1804.78687","0.06377","180.47868","0.00027"
"191.70000","6.38745","1801.45239","0.06387","180.14523","0.00028"
"192.00000","6.39757","1797.79822","0.06398","179.77982","0.00028"
"192.30000","6.40762","1794.36560","0.06408","179.43655","0.00026"
"192.60000","6.41747","1790.08228","0.06417","179.00822","0.00026"
"192.90000","6.42757","1788.37122","0.06428","178.83713","0.00028"
"193.20000","6.43747","1784.07129","0.06437","178.40714","0.00028"
"193.50000","6.44749","1781.75232","0.06447","178.17523","0.00027"
"193.80000","6.45746","1778.54468","0.06457","177.85446","0.00026"
"194.10000","6.46748","1775.35095","0.06467","177.53510","0.00026"
"194.40000","6.47748","1773.60779","0.06477","177.36078","0.00028"
"194.70000","6.48759","1773.30835","0.06488","177.33084","0.00028"
"195.00000","6.49744","1770.99634","0.06497","177.09964","0.00025"
"195.30000","6.50763","1770.40027","0.06508","177.04002","0.00027"
"195.60000","6.51758","1769.14758","0.06518","176.91476","0.00027"
"195.90000","6.52746","1767.27063","0.06527","176.72707","0.00028"
"196.20000","6.53744","1765.88794","0.06537","176.58879","0.00026"
"196.50000","6.54743","1764.32874","0.06547","176.43288","0.00026"
"196.80000","6.55746","1762.30127","0.06557","176.23013","0.00028"
"197.10000","6.56762","1760.55017","0.06568","176.05502","0.00028"
"197.40000","6.57760","1757.82947","0.06578","175.78294","0.00027"
"197.70000","6.58759","1755.44214","0.06588","175.54422","0.00026"
"198.00000","6.59752","1754.30481","0.06598","175.43048","0.00027"
"198.30000","6.60743","1752.92175","0.06607","175.29218","0.00028"
"198.60000","6.61738","1750.98462","0.06617","175.09846","0.00027"
"198.90000","6.62746","1750.23584","0.06627","175.02359","0.00026"
"199.20000","6.63768","1751.14441","0.06638","175.11444","0.00025"
"199.50000","6.64749","1747.95874","0.06647","174.79587","0.00028"
"199.80000","6.65753","1746.91858","0.06658","174.69186","0.00028"
"200.10000","6.66750","1745.22437","0.06668","174.52243","0.00027"
"200.40000","6.67745","1743.46924","0.06677","174.34692","0.00026"
"200.70000","6.68741","1740.99036","0.06687","174.09903","0.00028"
"201.00000","6.69757","1740.67017","0.06698","174.06702","0.00028"
"201.30000","6.70743","1738.25269","0.06707","173.82527","0.00027"
"201.60000","6.71762","1739.43188","0.06718","173.94319","0.00026"
"201.90000","6.72744","1737.68494","0.06727","173.76849","0.00027"
"202.20000","6.73752","1737.13245","0.06738","173.71324","0.00028"
"202.50000","6.74752","1736.68860","0.06748","173.66885","0.00028"
"202.80000","6.75756","1737.35974","0.06758","173.73598","0.00026"
"203.10000","6.76744","1736.27136","0.06767","173.62714","0.00026"
"203.40000","6.77748","1735.76343","0.06777","173.57634","0.00028"
"203.70000","6.78742","1732.67944","0.06787","173.26794","0.00029"
"204.00000","6.79758","1731.07874","0.06798","173.10788","0.00027"
"204.30000","6.80751","1727.60828","0.06808","172.76083","0.00025"
"204.60000","6.81766","1725.82104","0.06818","172.58211","0.00027"
"204.90000","6.82749","1721.51550","0.06827","172.15155","0.00029"
"205.20000","6.83747","1718.06604","0.06837","171.80661","0.00028"
"205.50000","6.84738","1714.53137","0.06847","171.45314","0.00026"
"205.80000","6.85746","1712.56812","0.06857","171.25681","0.00026"
"206.10000","6.86754","1710.74548","0.06868","171.07455","0.00028"
"206.40000","6.87763","1710.10327","0.06878","171.01033","0.00029"
"206.70000","6.88749","1706.39478","0.06887","170.63948","0.00026"
"207.00000","6.89760","1704.71252","0.06898","170.47125","0.00025"
"207.30000","6.90744","1701.35681","0.06907","170.13568","0.00027"
"207.60000","6.91742","1700.16760","0.06917","170.01675","0.00029"
"207.90000","6.92745","1699.55273","0.06927","169.95528","0.00028"
"208.20000","6.93752","1696.78333","0.06938","169.67833","0.00025"
"208.50000","6.94758","1692.32520","0.06948","169.23251","0.00026"
"208.80000","6.95755","1688.27380","0.06958","168.82738","0.00029"
"209.10000","6.96745","1684.25220","0.06967","168.42522","0.00028"
"209.40000","6.97758","1682.63464","0.06978","168.26346","0.00026"
"209.70000","6.98753","1679.22827","0.06988","167.92282","0.00026"
"210.00000","6.99747","1675.89392","0.06997","167.58939","0.00028"
"210.30000","7.00749","1672.24487","0.07007","167.22449","0.00028"
"210.60000","7.01739","1667.19531","0.07017","166.71953","0.00027"
"210.90000","7.02756","1663.64966","0.07028","166.36496","0.00025"
"211.20000","7.03751","1659.44397","0.07038","165.94440","0.00027"
"211.50000","7.04759","1656.04907","0.07048","165.60490","0.00029"
"211.80000","7.05752","1652.20459","0.07058","165.22046","0.00028"
"212.10000","7.06755","1650.55957","0.07068","165.05595","0.00026"
"212.40000","7.07739","1646.93909","0.07077","164.69391","0.00026"
"212.70000","7.08743","1645.33276","0.07087","164.53328","0.00028"
"213.00000","7.09746","1644.43384","0.07097","164.44339","0.00029"
"213.30000","7.10763","1644.81287","0.07108","164.48129","0.00027"
"213.60000","7.11743","1642.02454","0.07117","164.20245","0.00025"
"213.90000","7.12765","1642.32166","0.07128","164.23216","0.00027"
"214.20000","7.13745","1638.28540","0.07137","163.82854","0.00029"
"214.50000","7.14742","1634.12427","0.07147","163.41243","0.00029"
"214.80000","7.15744","1629.43970","0.07157","162.94397","0.00025"
"215.10000","7.16750","1622.63647","0.07168","162.26364","0.00026"
"215.40000","7.17750","1615.90076","0.07178","161.59007","0.00027"
"215.70000","7.18766","1609.82458","0.07188","160.98245","0.00028"
"216.00000","7.19746","1601.78577","0.07197","160.17857","0.00026"
"216.30000","7.20752","1599.07251","0.07208","159.90726","0.00026"
"216.60000","7.21748","1596.65027","0.07217","159.66502","0.00026"
"216.90000","7.22748","1594.82080","0.07227","159.48209","0.00029"
"217.20000","7.23745","1593.29785","0.07237","159.32979","0.00028"
"217.50000","7.24752","1593.30371","0.07248","159.33037","0.00026"
"217.80000","7.25751","1592.19165","0.07258","159.21916","0.00026"
"218.10000","7.26751","1591.79065","0.07268","159.17906","0.00029"
"218.40000","7.27753","1591.77966","0.07278","159.17796","0.00028"
"218.70000","7.28758","1591.65149","0.07288","159.16515","0.00026"
"219.00000","7.29750","1588.95789","0.07297","158.89578","0.00026"
"219.30000","7.30747","1585.74829","0.07307","158.57483","0.00028"
"219.60000","7.31741","1581.34473","0.07317","158.13448","0.00029"
"219.90000","7.32743","1577.37598","0.07327","157.73759","0.00027"
"220.20000","7.33762","1573.49719","0.07338","157.34972","0.00026"
"220.50000","7.34749","1567.50330","0.07347","156.75034","0.00027"
"220.80000","7.35756","1564.22095","0.07358","156.42209","0.00028"
"221.10000","7.36757","1560.02319","0.07368","156.00232","0.00027"
"221.40000","7.37745","1554.12000","0.07377","155.41200","0.00027"
"221.70000","7.38735","1547.98511","0.07387","154.79851","0.00026"
"222.00000","7.39748","1545.44946","0.07397","154.54495","0.00028"
"222.30000","7.40749","1542.22217","0.07407","154.22221","0.00028"
"222.60000","7.41764","1539.99194","0.07418","153.99919","0.00027"
"222.90000","7.42756","1535.04297","0.07428","153.50430","0.00026"
"223.20000","7.43753","1530.86633","0.07438","153.08664","0.00027"
"223.50000","7.44746","1527.73120","0.07447","152.77312","0.00029"
"223.80000","7.45746","1525.98413","0.07457","152.59842","0.00028"
"224.10000","7.46745","1523.98145","0.07467","152.39815","0.00026"
"224.40000","7.47751","1521.93677","0.07478","152.19368","0.00025"
"224.70000","7.48751","1519.22351","0.07488","151.92235","0.00028"
"225.00000","7.49754","1518.47131","0.07498","151.84714","0.00028"
"225.30000","7.50744","1516.04028","0.07507","151.60403","0.00026"
"225.30500","7.50759","1515.95422","0.07508","151.59543","0.00026"