File: Tension/Section_1_Group_4/control/Sample_12_0_days_tension.is_tens_RawData/Specimen_RawData_1.csv
Time,Extension,Load,Tensile strain (Extension),Axial Video,Tensile stress,Transverse Video
(s),(mm),(N),(mm/mm),(mm/mm),(MPa),(mm/mm)
"0.00000","0.00000","-0.32546","0.00000","0.00000","-0.03255","-0.00001"
"0.20000","0.00167","7.46550","0.00002","-0.00001","0.74655","0.00000"
"0.40000","0.01024","53.40147","0.00010","0.00002","5.34015","0.00001"
"0.60000","0.01695","88.19498","0.00017","0.00011","8.81950","-0.00005"
"0.80000","0.02376","122.77937","0.00024","0.00017","12.27794","-0.00011"
"1.00000","0.03039","155.87898","0.00030","0.00022","15.58790","-0.00010"
"1.20000","0.03695","188.30598","0.00037","0.00024","18.83060","-0.00009"
"1.40000","0.04383","221.72968","0.00044","0.00029","22.17297","-0.00018"
"1.60000","0.05029","252.07417","0.00050","0.00034","25.20742","-0.00009"
"1.80000","0.05707","283.41217","0.00057","0.00037","28.34122","-0.00009"
"2.00000","0.06369","313.36508","0.00064","0.00042","31.33651","-0.00009"
"2.20000","0.07037","342.96170","0.00070","0.00047","34.29617","-0.00005"
"2.40000","0.07705","372.17310","0.00077","0.00050","37.21731","-0.00009"
"2.60000","0.08362","400.27356","0.00084","0.00054","40.02736","-0.00007"
"2.80000","0.09046","429.29282","0.00090","0.00057","42.92928","-0.00009"
"3.00000","0.09691","455.70325","0.00097","0.00061","45.57032","-0.00009"
"3.20000","0.10379","483.97015","0.00104","0.00065","48.39701","-0.00012"
"3.40000","0.11034","510.12878","0.00110","0.00067","51.01288","-0.00005"
"3.60000","0.11700","536.20795","0.00117","0.00071","53.62080","-0.00009"
"3.80000","0.12387","563.16608","0.00124","0.00074","56.31661","-0.00003"
"4.00000","0.13029","587.08002","0.00130","0.00078","58.70800","-0.00002"
"4.20000","0.13698","612.10419","0.00137","0.00082","61.21042","-0.00004"
"4.40000","0.14363","636.61877","0.00144","0.00084","63.66188","-0.00004"
"4.60000","0.15050","661.77728","0.00150","0.00088","66.17773","-0.00003"
"4.80000","0.15700","684.48407","0.00157","0.00091","68.44841","-0.00005"
"5.00000","0.16366","707.68298","0.00164","0.00095","70.76830","-0.00009"
"5.20000","0.17043","731.24078","0.00170","0.00097","73.12408","-0.00002"
"5.40000","0.17691","752.77600","0.00177","0.00100","75.27760","-0.00008"
"5.60000","0.18383","776.46075","0.00184","0.00103","77.64607","-0.00005"
"5.80000","0.19033","797.99957","0.00190","0.00106","79.79996","-0.00005"
"6.00000","0.19702","819.88397","0.00197","0.00109","81.98840","-0.00003"
"6.20000","0.20374","841.83661","0.00204","0.00112","84.18366","-0.00010"
"6.40000","0.21039","862.69287","0.00210","0.00115","86.26929","-0.00014"
"6.60000","0.21698","883.36627","0.00217","0.00119","88.33662","-0.00014"
"6.80000","0.22360","903.82452","0.00224","0.00122","90.38245","-0.00006"
"7.00000","0.23044","925.14020","0.00230","0.00124","92.51402","-0.00005"
"7.20000","0.23703","944.86072","0.00237","0.00127","94.48607","-0.00005"
"7.40000","0.24370","964.85278","0.00244","0.00131","96.48528","-0.00011"
"7.60000","0.25044","985.02002","0.00250","0.00134","98.50200","-0.00014"
"7.80000","0.25699","1003.97931","0.00257","0.00137","100.39793","-0.00012"
"8.00000","0.26368","1023.50238","0.00264","0.00140","102.35023","-0.00005"
"8.20000","0.27036","1042.79529","0.00270","0.00144","104.27953","-0.00006"
"8.40000","0.27701","1061.59082","0.00277","0.00147","106.15908","-0.00004"
"8.60000","0.28376","1080.80298","0.00284","0.00150","108.08030","-0.00014"
"8.80000","0.29031","1098.47107","0.00290","0.00153","109.84711","-0.00014"
"9.00000","0.29706","1116.98193","0.00297","0.00156","111.69820","-0.00022"
"9.20000","0.30364","1134.36768","0.00304","0.00158","113.43677","-0.00017"
"9.40000","0.31049","1153.05505","0.00310","0.00160","115.30550","-0.00017"
"9.60000","0.31706","1170.38428","0.00317","0.00164","117.03843","-0.00015"
"9.80000","0.32365","1187.25220","0.00324","0.00167","118.72522","-0.00017"
"10.00000","0.33053","1205.41650","0.00331","0.00170","120.54165","-0.00014"
"10.20000","0.33697","1221.35669","0.00337","0.00173","122.13567","-0.00012"
"10.40000","0.34368","1238.58325","0.00344","0.00176","123.85832","-0.00014"
"10.60000","0.35026","1255.17700","0.00350","0.00179","125.51770","-0.00014"
"10.80000","0.35712","1272.79407","0.00357","0.00182","127.27940","-0.00014"
"11.00000","0.36377","1289.49170","0.00364","0.00185","128.94917","-0.00014"
"11.20000","0.37043","1306.18738","0.00370","0.00188","130.61874","-0.00028"
"11.40000","0.37711","1322.49707","0.00377","0.00191","132.24971","-0.00026"
"11.60000","0.38361","1337.95679","0.00384","0.00194","133.79568","-0.00021"
"11.80000","0.39045","1354.60669","0.00390","0.00196","135.46066","-0.00027"
"12.00000","0.39695","1369.30518","0.00397","0.00199","136.93051","-0.00025"
"12.20000","0.40367","1384.90295","0.00404","0.00201","138.49030","-0.00018"
"12.40000","0.41040","1400.88782","0.00410","0.00204","140.08878","-0.00016"
"12.60000","0.41704","1415.81030","0.00417","0.00206","141.58102","-0.00017"
"12.80000","0.42377","1431.18738","0.00424","0.00208","143.11874","-0.00014"
"13.00000","0.43032","1445.51892","0.00430","0.00211","144.55190","-0.00006"
"13.20000","0.43721","1461.72437","0.00437","0.00214","146.17244","-0.00007"
"13.40000","0.44367","1475.45886","0.00444","0.00217","147.54588","-0.00005"
"13.60000","0.45034","1490.02917","0.00450","0.00219","149.00291","0.00000"
"13.80000","0.45707","1504.53198","0.00457","0.00221","150.45320","-0.00009"
"14.00000","0.46364","1518.01270","0.00464","0.00223","151.80127","-0.00007"
"14.20000","0.47036","1531.71313","0.00470","0.00225","153.17131","-0.00004"
"14.40000","0.47702","1544.96057","0.00477","0.00228","154.49606","0.00003"
"14.60000","0.48374","1558.82227","0.00484","0.00230","155.88223","0.00000"
"14.80000","0.49046","1572.51416","0.00490","0.00233","157.25142","0.00000"
"15.00000","0.49708","1585.53064","0.00497","0.00235","158.55307","0.00001"
"15.20000","0.50372","1598.66772","0.00504","0.00238","159.86678","0.00000"
"15.40000","0.51031","1611.23145","0.00510","0.00240","161.12314","-0.00005"
"15.60000","0.51708","1624.86121","0.00517","0.00242","162.48611","-0.00005"
"15.80000","0.52369","1637.55847","0.00524","0.00245","163.75584","0.00000"
"16.00000","0.53025","1650.25500","0.00530","0.00248","165.02550","0.00009"
"16.20000","0.53715","1664.57349","0.00537","0.00250","166.45735","0.00007"
"16.40000","0.54370","1676.38879","0.00544","0.00252","167.63889","0.00014"
"16.60000","0.55052","1689.55518","0.00551","0.00254","168.95552","0.00016"
"16.80000","0.55706","1700.92297","0.00557","0.00257","170.09230","0.00018"
"17.00000","0.56376","1713.04211","0.00564","0.00259","171.30421","0.00014"
"17.20000","0.57041","1725.03308","0.00570","0.00259","172.50331","0.00017"
"17.40000","0.57697","1736.68726","0.00577","0.00261","173.66873","0.00014"
"17.60000","0.58374","1749.43286","0.00584","0.00262","174.94328","0.00017"
"17.80000","0.59021","1760.08704","0.00590","0.00264","176.00870","0.00017"
"18.00000","0.59710","1772.81763","0.00597","0.00266","177.28177","0.00015"
"18.20000","0.60374","1784.40381","0.00604","0.00268","178.44038","0.00016"
"18.40000","0.61050","1796.70105","0.00611","0.00270","179.67010","0.00023"
"18.60000","0.61719","1808.68054","0.00617","0.00271","180.86806","0.00018"
"18.80000","0.62367","1819.36487","0.00624","0.00273","181.93649","0.00019"
"19.00000","0.63036","1830.72131","0.00630","0.00274","183.07213","0.00019"
"19.20000","0.63691","1841.03943","0.00637","0.00276","184.10394","0.00027"
"19.40000","0.64381","1853.23877","0.00644","0.00278","185.32388","0.00027"
"19.60000","0.65030","1863.44250","0.00650","0.00280","186.34425","0.00028"
"19.80000","0.65701","1874.21033","0.00657","0.00282","187.42104","0.00024"
"20.00000","0.66383","1885.40515","0.00664","0.00282","188.54051","0.00024"
"20.20000","0.67038","1894.40771","0.00670","0.00284","189.44077","0.00024"
"20.40000","0.67715","1904.56616","0.00677","0.00285","190.45662","0.00019"
"20.60000","0.68369","1913.33765","0.00684","0.00286","191.33377","0.00014"
"20.80000","0.69042","1922.58008","0.00690","0.00287","192.25801","0.00017"
"21.00000","0.69701","1931.44531","0.00697","0.00289","193.14453","0.00019"
"21.20000","0.70370","1940.35938","0.00704","0.00291","194.03593","0.00019"
"21.40000","0.71033","1948.70813","0.00710","0.00292","194.87082","0.00019"
"21.60000","0.71698","1957.00781","0.00717","0.00293","195.70078","0.00009"
"21.80000","0.72385","1966.16760","0.00724","0.00294","196.61676","0.00000"
"22.00000","0.73047","1974.13733","0.00730","0.00296","197.41373","0.00005"
"22.20000","0.73705","1981.16138","0.00737","0.00298","198.11613","0.00007"
"22.40000","0.74378","1989.56116","0.00744","0.00299","198.95612","0.00009"
"22.60000","0.75035","1997.00635","0.00750","0.00300","199.70064","0.00007"
"22.80000","0.75697","2003.94519","0.00757","0.00301","200.39452","0.00007"
"23.00000","0.76365","2010.95459","0.00764","0.00301","201.09546","0.00009"
"23.20000","0.77038","2017.61914","0.00770","0.00303","201.76192","0.00014"
"23.40000","0.77709","2024.41418","0.00777","0.00304","202.44142","0.00008"
"23.60000","0.78369","2030.96924","0.00784","0.00305","203.09692","0.00007"
"23.80000","0.79054","2039.07825","0.00791","0.00306","203.90782","0.00006"
"24.00000","0.79699","2044.39941","0.00797","0.00307","204.43994","0.00009"
"24.20000","0.80378","2051.00269","0.00804","0.00309","205.10027","0.00004"
"24.40000","0.81036","2056.68018","0.00810","0.00309","205.66801","0.00008"
"24.60000","0.81700","2062.71851","0.00817","0.00310","206.27185","0.00005"
"24.80000","0.82380","2069.81982","0.00824","0.00311","206.98198","0.00001"
"25.00000","0.83031","2075.45288","0.00830","0.00311","207.54529","0.00005"
"25.20000","0.83705","2081.37476","0.00837","0.00313","208.13748","0.00009"
"25.40000","0.84364","2086.61914","0.00844","0.00314","208.66191","0.00009"
"25.60000","0.85056","2093.41040","0.00851","0.00315","209.34103","0.00010"
"25.80000","0.85709","2097.04492","0.00857","0.00316","209.70450","0.00013"
"26.00000","0.86368","2099.90137","0.00864","0.00316","209.99014","0.00014"
"26.20000","0.87046","2103.83960","0.00870","0.00316","210.38396","0.00013"
"26.40000","0.87690","2105.13647","0.00877","0.00318","210.51364","0.00023"
"26.60000","0.88376","2107.48096","0.00884","0.00318","210.74809","0.00018"
"26.80000","0.89029","2107.43408","0.00890","0.00318","210.74341","0.00019"
"27.00000","0.89710","2108.58667","0.00897","0.00318","210.85867","0.00019"
"27.20000","0.90377","2109.51855","0.00904","0.00319","210.95186","0.00023"
"27.40000","0.91043","2110.50317","0.00910","0.00319","211.05032","0.00023"
"27.60000","0.91709","2112.33691","0.00917","0.00319","211.23369","0.00018"
"27.80000","0.92360","2114.16162","0.00924","0.00319","211.41617","0.00019"
"28.00000","0.93045","2117.86206","0.00930","0.00319","211.78621","0.00019"
"28.20000","0.93698","2119.32056","0.00937","0.00320","211.93205","0.00023"
"28.40000","0.94364","2121.83765","0.00944","0.00319","212.18376","0.00028"
"28.60000","0.95046","2125.73975","0.00950","0.00320","212.57397","0.00028"
"28.80000","0.95704","2127.57373","0.00957","0.00322","212.75737","0.00033"
"29.00000","0.96372","2130.07153","0.00964","0.00322","213.00716","0.00033"
"29.20000","0.97040","2133.38599","0.00970","0.00323","213.33859","0.00029"
"29.40000","0.97711","2137.81006","0.00977","0.00324","213.78101","0.00027"
"29.60000","0.98370","2141.73169","0.00984","0.00325","214.17317","0.00022"
"29.80000","0.99031","2145.69653","0.00990","0.00326","214.56966","0.00020"
"30.00000","0.99711","2151.29907","0.00997","0.00326","215.12991","0.00023"
"30.20000","1.00362","2155.37695","0.01004","0.00327","215.53769","0.00019"
"30.40000","1.01039","2161.05322","0.01010","0.00328","216.10532","0.00022"
"30.60000","1.01709","2166.30176","0.01017","0.00329","216.63017","0.00023"
"30.80000","1.02371","2170.79761","0.01024","0.00330","217.07976","0.00019"
"31.00000","1.03049","2176.74854","0.01030","0.00331","217.67485","0.00018"
"31.20000","1.03701","2180.83447","0.01037","0.00332","218.08345","0.00014"
"31.40000","1.04368","2186.15942","0.01044","0.00334","218.61594","0.00020"
"31.60000","1.05026","2191.47437","0.01050","0.00335","219.14743","0.00022"
"31.80000","1.05712","2198.26880","0.01057","0.00335","219.82687","0.00019"
"32.00000","1.06369","2203.19287","0.01064","0.00336","220.31929","0.00019"
"32.20000","1.07033","2208.60474","0.01070","0.00336","220.86047","0.00023"
"32.40000","1.07720","2215.14600","0.01077","0.00338","221.51460","0.00019"
"32.60000","1.08364","2218.91992","0.01084","0.00338","221.89200","0.00018"
"32.80000","1.09038","2224.05054","0.01090","0.00339","222.40506","0.00016"
"33.00000","1.09700","2228.33447","0.01097","0.00340","222.83345","0.00013"
"33.20000","1.10376","2233.50610","0.01104","0.00341","223.35062","0.00013"
"33.40000","1.11038","2238.05078","0.01110","0.00341","223.80508","0.00014"
"33.60000","1.11701","2241.84326","0.01117","0.00341","224.18433","0.00014"
"33.80000","1.12374","2245.83594","0.01124","0.00342","224.58359","0.00018"
"34.00000","1.13029","2248.56201","0.01130","0.00342","224.85620","0.00014"
"34.20000","1.13722","2253.00293","0.01137","0.00343","225.30029","0.00009"
"34.40000","1.14368","2255.46362","0.01144","0.00344","225.54636","0.00009"
"34.60000","1.15032","2258.28125","0.01150","0.00344","225.82812","0.00015"
"34.80000","1.15710","2262.43335","0.01157","0.00344","226.24333","0.00009"
"35.00000","1.16365","2265.44214","0.01164","0.00345","226.54422","0.00014"
"35.20000","1.17030","2269.36255","0.01170","0.00345","226.93625","0.00018"
"35.40000","1.17699","2273.55371","0.01177","0.00346","227.35538","0.00023"
"35.60000","1.18378","2278.10278","0.01184","0.00347","227.81027","0.00019"
"35.80000","1.19041","2282.00806","0.01190","0.00348","228.20081","0.00014"
"36.00000","1.19702","2285.63574","0.01197","0.00348","228.56357","0.00018"
"36.20000","1.20376","2289.28638","0.01204","0.00349","228.92863","0.00016"
"36.40000","1.21029","2291.95044","0.01210","0.00350","229.19504","0.00010"
"36.60000","1.21710","2296.01099","0.01217","0.00350","229.60110","0.00009"
"36.80000","1.22368","2298.61328","0.01224","0.00352","229.86133","0.00015"
"37.00000","1.23028","2300.80518","0.01230","0.00352","230.08052","0.00014"
"37.20000","1.23717","2304.06665","0.01237","0.00352","230.40666","0.00019"
"37.40000","1.24366","2304.01562","0.01244","0.00352","230.40157","0.00019"
"37.60000","1.25038","2304.92725","0.01250","0.00353","230.49272","0.00018"
"37.80000","1.25702","2305.37866","0.01257","0.00353","230.53787","0.00016"
"38.00000","1.26382","2306.48218","0.01264","0.00353","230.64822","0.00023"
"38.20000","1.27035","2306.87622","0.01270","0.00353","230.68762","0.00024"
"38.40000","1.27693","2307.55249","0.01277","0.00353","230.75525","0.00028"
"38.60000","1.28379","2305.60986","0.01284","0.00353","230.56099","0.00028"
"38.80000","1.29023","2301.30786","0.01290","0.00352","230.13078","0.00027"
"39.00000","1.29705","2303.59473","0.01297","0.00352","230.35947","0.00023"
"39.20000","1.30367","2306.07715","0.01304","0.00353","230.60771","0.00024"
"39.40000","1.31041","2309.70020","0.01310","0.00353","230.97002","0.00028"
"39.60000","1.31717","2314.54419","0.01317","0.00355","231.45442","0.00028"
"39.80000","1.32365","2318.25903","0.01324","0.00355","231.82590","0.00033"
"40.00000","1.33033","2322.69995","0.01330","0.00356","232.26999","0.00032"
"40.20000","1.33688","2326.86621","0.01337","0.00357","232.68661","0.00033"
"40.40000","1.34381","2332.55786","0.01344","0.00358","233.25578","0.00033"
"40.60000","1.35030","2336.59351","0.01350","0.00358","233.65935","0.00028"
"40.80000","1.35707","2341.88916","0.01357","0.00359","234.18892","0.00021"
"41.00000","1.36381","2347.31592","0.01364","0.00360","234.73160","0.00019"
"41.20000","1.37031","2351.49707","0.01370","0.00362","235.14970","0.00018"
"41.40000","1.37707","2356.92822","0.01377","0.00363","235.69283","0.00014"
"41.60000","1.38363","2362.03345","0.01384","0.00363","236.20334","0.00018"
"41.80000","1.39043","2367.59741","0.01390","0.00364","236.75974","0.00026"
"42.00000","1.39700","2372.56494","0.01397","0.00365","237.25650","0.00028"
"42.20000","1.40367","2377.82666","0.01404","0.00366","237.78267","0.00028"
"42.40000","1.41038","2383.02393","0.01410","0.00367","238.30240","0.00030"
"42.60000","1.41693","2387.54272","0.01417","0.00368","238.75427","0.00023"
"42.80000","1.42375","2393.03198","0.01424","0.00369","239.30319","0.00018"
"43.00000","1.43037","2396.67090","0.01430","0.00369","239.66708","0.00019"
"43.20000","1.43702","2399.40039","0.01437","0.00370","239.94003","0.00017"
"43.40000","1.44379","2402.41577","0.01444","0.00371","240.24158","0.00019"
"43.60000","1.45035","2402.28784","0.01450","0.00372","240.22879","0.00019"
"43.80000","1.45698","2401.65845","0.01457","0.00372","240.16585","0.00022"
"44.00000","1.46364","2400.59180","0.01464","0.00370","240.05917","0.00023"
"44.20000","1.47041","2400.16333","0.01470","0.00371","240.01633","0.00025"
"44.40000","1.47709","2398.49121","0.01477","0.00370","239.84912","0.00023"
"44.60000","1.48362","2395.04639","0.01484","0.00371","239.50464","0.00025"
"44.80000","1.49049","2393.04248","0.01490","0.00371","239.30424","0.00024"
"45.00000","1.49696","2389.06104","0.01497","0.00371","238.90610","0.00026"
"45.20000","1.50377","2386.74292","0.01504","0.00369","238.67429","0.00018"
"45.40000","1.51038","2384.86499","0.01510","0.00368","238.48650","0.00014"
"45.60000","1.51701","2382.37964","0.01517","0.00369","238.23796","0.00017"
"45.80000","1.52373","2381.30957","0.01524","0.00369","238.13095","0.00015"
"46.00000","1.53028","2379.25439","0.01530","0.00369","237.92545","0.00014"
"46.20000","1.53709","2378.84326","0.01537","0.00368","237.88432","0.00017"
"46.40000","1.54361","2377.16309","0.01544","0.00369","237.71631","0.00015"
"46.60000","1.55045","2379.02002","0.01550","0.00370","237.90201","0.00019"
"46.80000","1.55702","2380.29272","0.01557","0.00371","238.02927","0.00024"
"47.00000","1.56365","2382.13135","0.01564","0.00371","238.21313","0.00028"
"47.20000","1.57051","2385.22754","0.01571","0.00371","238.52275","0.00028"
"47.40000","1.57694","2386.03735","0.01577","0.00373","238.60373","0.00028"
"47.60000","1.58366","2389.07031","0.01584","0.00374","238.90703","0.00028"
"47.80000","1.59030","2391.55640","0.01590","0.00374","239.15564","0.00028"
"48.00000","1.59717","2395.01270","0.01597","0.00374","239.50127","0.00028"
"48.20000","1.60366","2396.77222","0.01604","0.00375","239.67722","0.00033"
"48.40000","1.61033","2399.61865","0.01610","0.00376","239.96187","0.00030"
"48.60000","1.61709","2403.73071","0.01617","0.00376","240.37308","0.00033"
"48.80000","1.62360","2406.95459","0.01624","0.00376","240.69547","0.00034"
"49.00000","1.63053","2412.09619","0.01631","0.00377","241.20963","0.00028"
"49.20000","1.63698","2415.37720","0.01637","0.00378","241.53772","0.00033"
"49.40000","1.64364","2419.81030","0.01644","0.00378","241.98103","0.00037"
"49.60000","1.65041","2425.27026","0.01650","0.00380","242.52702","0.00032"
"49.80000","1.65706","2428.77515","0.01657","0.00380","242.87752","0.00033"
"50.00000","1.66365","2432.21802","0.01664","0.00381","243.22180","0.00035"
"50.20000","1.67033","2434.67163","0.01670","0.00382","243.46716","0.00032"
"50.40000","1.67713","2433.62622","0.01677","0.00383","243.36263","0.00030"
"50.60000","1.68370","2430.72119","0.01684","0.00383","243.07211","0.00033"
"50.80000","1.69035","2428.01318","0.01690","0.00383","242.80132","0.00035"
"51.00000","1.69710","2424.37842","0.01697","0.00382","242.43784","0.00034"
"51.20000","1.70362","2416.58936","0.01704","0.00382","241.65894","0.00036"
"51.40000","1.71039","2409.38672","0.01710","0.00381","240.93867","0.00033"
"51.60000","1.71708","2402.46582","0.01717","0.00380","240.24658","0.00037"
"51.80000","1.72370","2397.68750","0.01724","0.00379","239.76875","0.00037"
"52.00000","1.73042","2393.18457","0.01730","0.00378","239.31845","0.00039"
"52.20000","1.73696","2387.57983","0.01737","0.00379","238.75798","0.00033"
"52.40000","1.74373","2384.95117","0.01744","0.00378","238.49512","0.00034"
"52.60000","1.75032","2381.11304","0.01750","0.00379","238.11130","0.00042"
"52.80000","1.75715","2380.12720","0.01757","0.00378","238.01273","0.00042"
"53.00000","1.76371","2378.25659","0.01764","0.00378","237.82565","0.00046"
"53.20000","1.77028","2374.73145","0.01770","0.00377","237.47314","0.00042"
"53.40000","1.77720","2373.08521","0.01777","0.00378","237.30852","0.00045"
"53.60000","1.78360","2367.14697","0.01784","0.00378","236.71469","0.00043"
"53.80000","1.79035","2364.33667","0.01790","0.00377","236.43367","0.00052"
"54.00000","1.79693","2362.01489","0.01797","0.00377","236.20149","0.00051"
"54.20000","1.80379","2356.86646","0.01804","0.00377","235.68665","0.00055"
"54.40000","1.81049","2350.08203","0.01810","0.00375","235.00821","0.00051"
"54.60000","1.81707","2342.30347","0.01817","0.00375","234.23035","0.00056"
"54.80000","1.82376","2334.33887","0.01824","0.00374","233.43388","0.00060"
"55.00000","1.83023","2329.13428","0.01830","0.00373","232.91342","0.00057"
"55.20000","1.83716","2327.89478","0.01837","0.00373","232.78947","0.00053"
"55.40000","1.84365","2323.84741","0.01844","0.00373","232.38474","0.00055"
"55.60000","1.85032","2319.23047","0.01850","0.00372","231.92305","0.00051"
"55.80000","1.85709","2315.36914","0.01857","0.00371","231.53691","0.00060"
"56.00000","1.86368","2309.77954","0.01864","0.00373","230.97795","0.00065"
"56.20000","1.87042","2292.15601","0.01870","0.00371","229.21561","0.00056"
"56.40000","1.87700","2273.03149","0.01877","0.00368","227.30315","0.00056"
"56.60000","1.88384","2254.77881","0.01884","0.00364","225.47787","0.00056"
"56.80000","1.89038","2233.64404","0.01890","0.00362","223.36441","0.00056"
"57.00000","1.89705","2218.68213","0.01897","0.00360","221.86821","0.00056"
"57.20000","1.90372","2210.55273","0.01904","0.00359","221.05527","0.00056"
"57.40000","1.91028","2208.66333","0.01910","0.00358","220.86633","0.00061"
"57.60000","1.91703","2208.23218","0.01917","0.00359","220.82321","0.00060"
"57.80000","1.92370","2207.19312","0.01924","0.00359","220.71931","0.00062"
"58.00000","1.93040","2206.09448","0.01930","0.00358","220.60945","0.00065"
"58.20000","1.93718","2203.12769","0.01937","0.00360","220.31277","0.00059"
"58.40000","1.94374","2201.48364","0.01944","0.00359","220.14836","0.00065"
"58.60000","1.95037","2196.92212","0.01950","0.00359","219.69221","0.00069"
"58.80000","1.95698","2190.30151","0.01957","0.00358","219.03015","0.00062"
"59.00000","1.96374","2187.01294","0.01964","0.00357","218.70129","0.00058"
"59.20000","1.97035","2186.18726","0.01970","0.00357","218.61873","0.00062"
"59.40000","1.97694","2186.85376","0.01977","0.00358","218.68538","0.00066"
"59.60000","1.98382","2186.12036","0.01984","0.00358","218.61203","0.00063"
"59.80000","1.99035","2183.29639","0.01990","0.00357","218.32964","0.00060"
"60.00000","1.99717","2175.97241","0.01997","0.00357","217.59724","0.00062"
"60.20000","2.00374","2155.96509","0.02004","0.00357","215.59651","0.00059"
"60.40000","2.01041","2136.93018","0.02010","0.00353","213.69302","0.00061"
"60.60000","2.01714","2124.77344","0.02017","0.00352","212.47734","0.00056"
"60.80000","2.02363","2117.29565","0.02024","0.00351","211.72957","0.00056"
"61.00000","2.03040","2114.74487","0.02030","0.00351","211.47449","0.00059"
"61.20000","2.03688","2110.18994","0.02037","0.00351","211.01900","0.00061"
"61.40000","2.04380","2104.68188","0.02044","0.00351","210.46819","0.00060"
"61.60000","2.05040","2097.91235","0.02050","0.00350","209.79123","0.00061"
"61.80000","2.05714","2091.82959","0.02057","0.00349","209.18295","0.00065"
"62.00000","2.06387","2087.27710","0.02064","0.00348","208.72771","0.00066"
"62.20000","2.07036","2076.85205","0.02070","0.00347","207.68521","0.00064"
"62.40000","2.07705","2064.61914","0.02077","0.00346","206.46191","0.00060"
"62.60000","2.08357","2054.41602","0.02084","0.00345","205.44160","0.00058"
"62.80000","2.09044","2045.40247","0.02090","0.00344","204.54025","0.00056"
"63.00000","2.09698","2026.05225","0.02097","0.00343","202.60522","0.00060"
"63.20000","2.10372","2007.62378","0.02104","0.00342","200.76237","0.00058"
"63.40000","2.11050","1995.76843","0.02110","0.00341","199.57684","0.00065"
"63.60000","2.11705","1986.04016","0.02117","0.00339","198.60402","0.00061"
"63.80000","2.12385","1982.06470","0.02124","0.00338","198.20647","0.00061"
"64.00000","2.13036","1977.61768","0.02130","0.00337","197.76176","0.00060"
"64.20000","2.13704","1969.66003","0.02137","0.00337","196.96600","0.00068"
"64.40000","2.14368","1956.15161","0.02144","0.00335","195.61516","0.00068"
"64.60000","2.15036","1942.87097","0.02150","0.00334","194.28709","0.00070"
"64.80000","2.15700","1925.26038","0.02157","0.00334","192.52603","0.00070"
"65.00000","2.16369","1913.34790","0.02164","0.00332","191.33479","0.00061"
"65.20000","2.17048","1905.39526","0.02170","0.00331","190.53952","0.00065"
"65.40000","2.17713","1893.41321","0.02177","0.00329","189.34132","0.00060"
"65.60000","2.18373","1881.91882","0.02184","0.00327","188.19188","0.00067"
"65.80000","2.19047","1874.22729","0.02190","0.00326","187.42273","0.00070"
"66.00000","2.19699","1862.66150","0.02197","0.00325","186.26614","0.00069"
"66.20000","2.20366","1849.28723","0.02204","0.00325","184.92873","0.00065"
"66.40000","2.21036","1840.20825","0.02210","0.00325","184.02083","0.00075"
"66.60000","2.21703","1831.16382","0.02217","0.00324","183.11638","0.00071"
"66.80000","2.22375","1820.78088","0.02224","0.00323","182.07809","0.00071"
"67.00000","2.23037","1801.32263","0.02230","0.00321","180.13226","0.00070"
"67.20000","2.23719","1775.81384","0.02237","0.00319","177.58139","0.00073"
"67.40000","2.24370","1740.79333","0.02244","0.00316","174.07933","0.00074"
"67.60000","2.25048","1716.44336","0.02250","0.00313","171.64433","0.00082"
"67.80000","2.25701","1695.92419","0.02257","0.00311","169.59242","0.00088"
"68.00000","2.26363","1679.28137","0.02264","0.00309","167.92813","0.00093"
"68.20000","2.27049","1668.22168","0.02270","0.00307","166.82217","0.00091"
"68.40000","2.27694","1654.19324","0.02277","0.00306","165.41933","0.00089"
"68.60000","2.28368","1644.36218","0.02284","0.00305","164.43622","0.00098"
"68.80000","2.29036","1632.07202","0.02290","0.00304","163.20720","0.00098"
"69.00000","2.29725","1612.07629","0.02297","0.00304","161.20763","0.00098"
"69.20000","2.30379","1581.38904","0.02304","0.00300","158.13890","0.00103"
"69.40000","2.31036","1547.98584","0.02310","0.00298","154.79858","0.00107"
"69.60000","2.31709","1515.86511","0.02317","0.00295","151.58652","0.00116"
"69.80000","2.32358","1472.40173","0.02324","0.00291","147.24017","0.00115"
"70.00000","2.33044","1446.84338","0.02330","0.00286","144.68434","0.00116"
"70.20000","2.33699","1429.43384","0.02337","0.00284","142.94339","0.00113"
"70.40000","2.34373","1412.88196","0.02344","0.00283","141.28819","0.00115"
"70.60000","2.35046","1396.32629","0.02350","0.00283","139.63263","0.00111"
"70.80000","2.35710","1377.25122","0.02357","0.00281","137.72513","0.00099"
"71.00000","2.36374","1357.42798","0.02364","0.00279","135.74280","0.00096"
"71.20000","2.37029","1334.25525","0.02370","0.00277","133.42552","0.00093"
"71.40000","2.37714","1314.21960","0.02377","0.00275","131.42197","0.00090"
"71.60000","2.38368","1295.00354","0.02384","0.00273","129.50035","0.00094"
"71.80000","2.39031","1272.28320","0.02390","0.00271","127.22832","0.00098"
"72.00000","2.39709","1249.69153","0.02397","0.00268","124.96915","0.00091"
"72.20000","2.40368","1224.48389","0.02404","0.00266","122.44839","0.00084"
"72.40000","2.41042","1189.85474","0.02410","0.00263","118.98547","0.00081"
"72.60000","2.41710","1143.73816","0.02417","0.00260","114.37382","0.00074"
"72.80000","2.42379","1104.72400","0.02424","0.00257","110.47240","0.00070"
"73.00000","2.43040","1066.19836","0.02430","0.00255","106.61983","0.00065"
"73.20000","2.43703","1023.75073","0.02437","0.00252","102.37508","0.00065"
"73.40000","2.44372","979.64191","0.02444","0.00249","97.96419","0.00055"
"73.60000","2.45027","938.77148","0.02450","0.00245","93.87715","0.00046"
"73.80000","2.45708","905.11560","0.02457","0.00242","90.51156","0.00042"
"74.00000","2.46374","880.76770","0.02464","0.00239","88.07677","0.00037"
"74.20000","2.47036","859.60443","0.02470","0.00236","85.96044","0.00023"
"74.40000","2.47719","844.25677","0.02477","0.00234","84.42567","0.00018"
"74.60000","2.48369","832.66956","0.02484","0.00233","83.26695","0.00010"
"74.80000","2.49037","822.69086","0.02490","0.00232","82.26909","0.00014"
"75.00000","2.49694","811.85291","0.02497","0.00231","81.18529","0.00017"
"75.20000","2.50376","796.77802","0.02504","0.00230","79.67780","0.00021"
"75.40000","2.51038","781.70795","0.02510","0.00230","78.17079","0.00027"
"75.60000","2.51699","767.20648","0.02517","0.00228","76.72065","0.00028"
"75.80000","2.52382","755.55133","0.02524","0.00225","75.55513","0.00037"
"76.00000","2.53029","741.67877","0.02530","0.00224","74.16788","0.00037"
"76.20000","2.53711","729.60956","0.02537","0.00222","72.96095","0.00042"
"76.40000","2.54367","721.36761","0.02544","0.00221","72.13676","0.00042"
"76.60000","2.55039","715.56232","0.02550","0.00220","71.55623","0.00043"
"76.80000","2.55711","712.39990","0.02557","0.00219","71.23999","0.00046"
"77.00000","2.56371","709.71490","0.02564","0.00217","70.97149","0.00038"
"77.20000","2.57039","708.89130","0.02570","0.00217","70.88913","0.00037"
"77.40000","2.57695","706.55927","0.02577","0.00216","70.65593","0.00037"
"77.60000","2.58386","703.22168","0.02584","0.00215","70.32217","0.00042"
"77.80000","2.59037","697.52698","0.02590","0.00215","69.75270","0.00042"
"78.00000","2.59701","693.34412","0.02597","0.00214","69.33441","0.00042"
"78.20000","2.60382","690.08466","0.02604","0.00213","69.00847","0.00042"
"78.40000","2.61031","684.17334","0.02610","0.00212","68.41734","0.00041"
"78.60000","2.61699","681.16907","0.02617","0.00210","68.11691","0.00042"
"78.80000","2.62367","679.52222","0.02624","0.00209","67.95222","0.00041"
"79.00000","2.63040","680.01965","0.02630","0.00210","68.00197","0.00053"
"79.20000","2.63709","678.31946","0.02637","0.00209","67.83195","0.00058"
"79.40000","2.64369","674.74066","0.02644","0.00208","67.47407","0.00060"
"79.60000","2.65042","672.27203","0.02650","0.00208","67.22720","0.00056"
"79.80000","2.65698","669.24390","0.02657","0.00207","66.92439","0.00060"
"80.00000","2.66378","667.30908","0.02664","0.00205","66.73091","0.00065"
"80.20000","2.67035","664.90576","0.02670","0.00204","66.49058","0.00065"
"80.40000","2.67693","664.98120","0.02677","0.00204","66.49812","0.00066"
"80.60000","2.68384","668.11578","0.02684","0.00204","66.81158","0.00066"
"80.80000","2.69035","669.72943","0.02690","0.00203","66.97295","0.00067"
"81.00000","2.69701","670.94318","0.02697","0.00202","67.09431","0.00070"
"81.20000","2.70369","671.66772","0.02704","0.00203","67.16677","0.00071"
"81.40000","2.71049","672.31250","0.02710","0.00203","67.23125","0.00073"
"81.60000","2.71702","673.00580","0.02717","0.00203","67.30058","0.00068"
"81.80000","2.72359","674.81842","0.02724","0.00202","67.48184","0.00070"
"82.00000","2.73041","678.42413","0.02730","0.00202","67.84241","0.00070"
"82.20000","2.73691","680.42694","0.02737","0.00203","68.04269","0.00068"
"82.40000","2.74378","683.19507","0.02744","0.00203","68.31950","0.00074"
"82.60000","2.75033","684.27979","0.02750","0.00201","68.42798","0.00071"
"82.80000","2.75703","686.31219","0.02757","0.00201","68.63122","0.00071"
"83.00000","2.76385","689.04028","0.02764","0.00201","68.90403","0.00079"
"83.20000","2.77033","689.07269","0.02770","0.00201","68.90727","0.00083"
"83.40000","2.77699","689.44751","0.02777","0.00201","68.94475","0.00081"
"83.60000","2.78355","689.59082","0.02784","0.00200","68.95908","0.00079"
"83.80000","2.79048","691.46564","0.02790","0.00201","69.14656","0.00079"
"84.00000","2.79696","692.06073","0.02797","0.00200","69.20607","0.00079"
"84.20000","2.80368","694.13947","0.02804","0.00199","69.41395","0.00079"
"84.40000","2.81049","697.25763","0.02810","0.00199","69.72576","0.00079"
"84.60000","2.81697","698.46625","0.02817","0.00200","69.84663","0.00083"
"84.80000","2.82379","698.80316","0.02824","0.00200","69.88032","0.00079"
"85.00000","2.83033","696.91479","0.02830","0.00200","69.69148","0.00088"
"85.20000","2.83707","694.19012","0.02837","0.00201","69.41901","0.00088"
"85.40000","2.84366","692.59888","0.02844","0.00200","69.25989","0.00089"
"85.60000","2.85035","692.29950","0.02850","0.00200","69.22995","0.00093"
"85.80000","2.85702","691.86169","0.02857","0.00200","69.18617","0.00088"
"86.00000","2.86363","691.04913","0.02864","0.00199","69.10491","0.00089"
"86.20000","2.87044","692.48572","0.02870","0.00199","69.24857","0.00088"
"86.40000","2.87702","692.94958","0.02877","0.00200","69.29496","0.00093"
"86.60000","2.88368","691.57208","0.02884","0.00199","69.15721","0.00098"
"86.80000","2.89049","693.18451","0.02890","0.00199","69.31845","0.00093"
"87.00000","2.89700","692.21954","0.02897","0.00200","69.22195","0.00096"
"87.20000","2.90363","693.15784","0.02904","0.00199","69.31578","0.00094"
"87.40000","2.91032","695.37518","0.02910","0.00199","69.53752","0.00098"
"87.60000","2.91706","697.46808","0.02917","0.00198","69.74681","0.00088"
"87.80000","2.92379","699.35474","0.02924","0.00198","69.93547","0.00088"
"88.00000","2.93032","699.89398","0.02930","0.00199","69.98940","0.00093"
"88.20000","2.93712","701.84698","0.02937","0.00199","70.18470","0.00093"
"88.40000","2.94361","701.85626","0.02944","0.00199","70.18562","0.00097"
"88.60000","2.95046","703.50287","0.02950","0.00198","70.35029","0.00096"
"88.80000","2.95702","704.77112","0.02957","0.00199","70.47711","0.00096"
"89.00000","2.96364","705.53955","0.02964","0.00199","70.55396","0.00102"
"89.20000","2.97044","707.26642","0.02970","0.00200","70.72664","0.00102"
"89.40000","2.97697","707.33246","0.02977","0.00200","70.73325","0.00093"
"89.60000","2.98371","708.51080","0.02984","0.00200","70.85108","0.00092"
"89.80000","2.99028","709.77032","0.02990","0.00200","70.97704","0.00094"
"90.00000","2.99714","711.70758","0.02997","0.00201","71.17076","0.00097"
"90.20000","3.00367","711.07446","0.03004","0.00201","71.10744","0.00100"
"90.40000","3.01033","709.81879","0.03010","0.00201","70.98188","0.00102"
"90.60000","3.01715","709.73492","0.03017","0.00201","70.97350","0.00102"
"90.80000","3.02356","707.61707","0.03024","0.00200","70.76170","0.00102"
"91.00000","3.03033","706.22418","0.03030","0.00201","70.62242","0.00097"
"91.20000","3.03698","705.36749","0.03037","0.00201","70.53675","0.00101"
"91.40000","3.04382","706.16321","0.03044","0.00201","70.61632","0.00098"
"91.60000","3.05034","708.22491","0.03050","0.00201","70.82249","0.00098"
"91.80000","3.05700","711.72821","0.03057","0.00201","71.17282","0.00099"
"92.00000","3.06373","713.72900","0.03064","0.00201","71.37290","0.00100"
"92.20000","3.07027","713.29608","0.03070","0.00202","71.32961","0.00099"
"92.40000","3.07719","713.43872","0.03077","0.00202","71.34387","0.00100"
"92.60000","3.08363","713.76147","0.03084","0.00202","71.37614","0.00101"
"92.80000","3.09031","714.07684","0.03090","0.00202","71.40768","0.00102"
"93.00000","3.09710","715.13367","0.03097","0.00202","71.51337","0.00101"
"93.20000","3.10370","715.02423","0.03104","0.00202","71.50243","0.00100"
"93.40000","3.11030","712.50476","0.03110","0.00201","71.25047","0.00102"
"93.60000","3.11701","711.64703","0.03117","0.00201","71.16470","0.00102"
"93.80000","3.12378","709.74615","0.03124","0.00201","70.97462","0.00099"
"94.00000","3.13035","706.91003","0.03130","0.00202","70.69100","0.00107"
"94.20000","3.13704","706.95801","0.03137","0.00201","70.69580","0.00098"
"94.40000","3.14372","708.17444","0.03144","0.00201","70.81744","0.00102"
"94.60000","3.15031","708.74316","0.03150","0.00202","70.87431","0.00107"
"94.80000","3.15706","710.32611","0.03157","0.00202","71.03261","0.00106"
"95.00000","3.16373","710.82635","0.03164","0.00201","71.08263","0.00105"
"95.20000","3.17033","710.89923","0.03170","0.00201","71.08992","0.00107"
"95.40000","3.17714","712.34033","0.03177","0.00202","71.23403","0.00107"
"95.60000","3.18363","711.49969","0.03184","0.00201","71.14997","0.00107"
"95.80000","3.19040","711.46527","0.03190","0.00200","71.14653","0.00107"
"96.00000","3.19699","711.54089","0.03197","0.00200","71.15409","0.00109"
"96.20000","3.20379","711.20404","0.03204","0.00201","71.12041","0.00106"
"96.40000","3.21037","711.33917","0.03210","0.00201","71.13392","0.00107"
"96.60000","3.21694","711.06079","0.03217","0.00201","71.10608","0.00107"
"96.80000","3.22386","711.46527","0.03224","0.00200","71.14653","0.00111"
"97.00000","3.23027","709.38983","0.03230","0.00199","70.93898","0.00108"
"97.20000","3.23703","709.59625","0.03237","0.00200","70.95963","0.00105"
"97.40000","3.24363","710.16772","0.03244","0.00200","71.01677","0.00107"
"97.60000","3.25041","709.42651","0.03250","0.00200","70.94265","0.00102"
"97.62800","3.25124","708.73865","0.03251","0.00200","70.87386","0.00102"