File: Tension/Section_2_Group_2/Rivets_low_Sample_1.is_tens_RawData/Specimen_RawData_1.csv
Time,Extension,Load,Tensile strain (Extension),Tensile stress,Strain-by-clip-gage
(s),(mm),(N),(mm/mm),(MPa),(mm/mm)
"0.00000","0.00000","-6.48480","0.00000","-0.64848","0.00000"
"0.30000","0.00759","30.77857","0.00008","3.07786","0.00000"
"0.60000","0.01757","75.73434","0.00018","7.57343","0.00002"
"0.90000","0.02766","117.06596","0.00028","11.70660","0.00000"
"1.20000","0.03760","153.80875","0.00038","15.38087","-0.00001"
"1.50000","0.04754","187.51457","0.00048","18.75146","-0.00002"
"1.80000","0.05748","218.54329","0.00057","21.85433","0.00000"
"2.10000","0.06762","248.29762","0.00068","24.82976","0.00002"
"2.40000","0.07760","274.89328","0.00078","27.48933","0.00002"
"2.70000","0.08762","299.29321","0.00088","29.92932","-0.00006"
"3.00000","0.09760","321.58435","0.00098","32.15844","-0.00003"
"3.30000","0.10771","342.73895","0.00108","34.27390","0.00001"
"3.60000","0.11755","360.34683","0.00118","36.03468","-0.00001"
"3.90000","0.12756","377.24756","0.00128","37.72475","-0.00002"
"4.20000","0.13754","392.98795","0.00138","39.29879","-0.00002"
"4.50000","0.14749","407.31485","0.00147","40.73148","0.00001"
"4.80000","0.15766","422.02374","0.00158","42.20237","0.00000"
"5.10000","0.16768","435.20871","0.00168","43.52087","0.00001"
"5.40000","0.17763","446.74039","0.00178","44.67404","-0.00003"
"5.70000","0.18767","458.23590","0.00188","45.82359","0.00001"
"6.00000","0.19757","468.47012","0.00198","46.84701","0.00001"
"6.30000","0.20744","477.97150","0.00207","47.79715","0.00001"
"6.60000","0.21755","487.26566","0.00218","48.72657","-0.00002"
"6.90000","0.22760","495.85733","0.00228","49.58573","0.00000"
"7.20000","0.23766","504.52765","0.00238","50.45277","0.00000"
"7.50000","0.24759","512.05463","0.00248","51.20546","0.00001"
"7.80000","0.25766","519.80603","0.00258","51.98060","-0.00001"
"8.10000","0.26756","526.61902","0.00268","52.66190","-0.00001"
"8.40000","0.27758","533.60388","0.00278","53.36039","0.00000"
"8.70000","0.28754","540.15143","0.00288","54.01514","0.00001"
"9.00000","0.29756","546.84265","0.00298","54.68427","0.00000"
"9.30000","0.30759","552.69196","0.00308","55.26920","-0.00001"
"9.60000","0.31769","556.69159","0.00318","55.66916","0.00000"
"9.90000","0.32749","556.84790","0.00327","55.68479","0.00000"
"10.20000","0.33767","559.50830","0.00338","55.95083","0.00001"
"10.50000","0.34767","562.29224","0.00348","56.22923","0.00000"
"10.80000","0.35756","563.99072","0.00358","56.39907","-0.00002"
"11.10000","0.36749","565.06635","0.00367","56.50663","0.00001"
"11.40000","0.37756","566.24597","0.00378","56.62460","0.00001"
"11.70000","0.38754","567.96332","0.00388","56.79633","0.00000"
"12.00000","0.39768","571.76080","0.00398","57.17608","-0.00001"
"12.30000","0.40769","570.88147","0.00408","57.08815","-0.00001"
"12.60000","0.41767","572.10962","0.00418","57.21096","0.00001"
"12.90000","0.42759","574.22382","0.00428","57.42238","0.00001"
"13.20000","0.43751","576.75293","0.00438","57.67529","0.00000"
"13.50000","0.44746","579.61627","0.00447","57.96163","-0.00001"
"13.80000","0.45755","582.49164","0.00458","58.24916","0.00000"
"14.10000","0.46776","584.29858","0.00468","58.42986","0.00001"
"14.40000","0.47762","583.71399","0.00478","58.37140","0.00001"
"14.70000","0.48761","581.50427","0.00488","58.15043","-0.00002"
"15.00000","0.49762","578.73108","0.00498","57.87311","-0.00001"
"15.30000","0.50751","574.75238","0.00508","57.47524","0.00001"
"15.60000","0.51746","570.06927","0.00517","57.00693","0.00001"
"15.90000","0.52763","567.83673","0.00528","56.78367","-0.00001"
"16.20000","0.53753","565.07434","0.00538","56.50743","-0.00001"
"16.50000","0.54771","565.09198","0.00548","56.50920","0.00000"
"16.80000","0.55753","563.65955","0.00558","56.36596","0.00002"
"17.10000","0.56761","563.59082","0.00568","56.35908","0.00000"
"17.40000","0.57766","564.46313","0.00578","56.44631","-0.00001"
"17.70000","0.58765","565.47577","0.00588","56.54758","-0.00001"
"18.00000","0.59749","565.65088","0.00597","56.56509","0.00001"
"18.30000","0.60756","565.44543","0.00608","56.54454","0.00001"
"18.60000","0.61749","564.85706","0.00617","56.48571","-0.00001"
"18.90000","0.62764","566.53931","0.00628","56.65393","-0.00001"
"19.20000","0.63758","568.34973","0.00638","56.83497","0.00000"
"19.50000","0.64778","573.07019","0.00648","57.30702","0.00001"
"19.80000","0.65763","576.85919","0.00658","57.68592","0.00000"
"20.10000","0.66754","581.97882","0.00668","58.19788","-0.00001"
"20.40000","0.67745","587.53021","0.00677","58.75302","-0.00001"
"20.70000","0.68755","594.33179","0.00688","59.43318","0.00001"
"21.00000","0.69759","601.45618","0.00698","60.14562","0.00001"
"21.30000","0.70775","609.27948","0.00708","60.92795","-0.00001"
"21.60000","0.71757","614.31677","0.00718","61.43168","-0.00001"
"21.90000","0.72764","620.48962","0.00728","62.04896","0.00000"
"22.20000","0.73751","624.01703","0.00738","62.40170","0.00001"
"22.50000","0.74753","628.35144","0.00748","62.83514","0.00000"
"22.80000","0.75752","632.39667","0.00758","63.23967","-0.00001"
"23.10000","0.76761","636.09216","0.00768","63.60921","-0.00001"
"23.40000","0.77766","638.76068","0.00778","63.87607","0.00001"
"23.70000","0.78761","639.98889","0.00788","63.99889","0.00000"
"24.00000","0.79753","639.60455","0.00798","63.96046","0.00000"
"24.30000","0.80764","640.01019","0.00808","64.00102","-0.00001"
"24.60000","0.81760","641.26154","0.00818","64.12615","0.00000"
"24.90000","0.82755","642.59863","0.00828","64.25986","0.00001"
"25.20000","0.83758","645.09369","0.00838","64.50937","0.00000"
"25.50000","0.84753","647.64685","0.00848","64.76469","-0.00001"
"25.80000","0.85763","651.03796","0.00858","65.10380","-0.00001"
"26.10000","0.86756","652.98218","0.00868","65.29822","0.00001"
"26.40000","0.87768","653.77002","0.00878","65.37700","0.00001"
"26.70000","0.88766","654.14386","0.00888","65.41438","0.00000"
"27.00000","0.89758","656.05243","0.00898","65.60524","-0.00002"
"27.30000","0.90747","657.68365","0.00907","65.76836","0.00000"
"27.60000","0.91753","659.20825","0.00918","65.92082","0.00001"
"27.90000","0.92756","660.95782","0.00928","66.09578","0.00000"
"28.20000","0.93773","665.40564","0.00938","66.54057","-0.00001"
"28.50000","0.94753","670.08295","0.00948","67.00829","0.00000"
"28.80000","0.95772","677.07349","0.00958","67.70735","0.00000"
"29.10000","0.96757","682.30035","0.00968","68.23003","0.00001"
"29.40000","0.97751","687.00897","0.00978","68.70090","-0.00001"
"29.70000","0.98753","692.43359","0.00988","69.24336","-0.00001"
"30.00000","0.99763","697.64655","0.00998","69.76466","0.00000"
"30.30000","1.00759","699.56470","0.01008","69.95647","0.00001"
"30.60000","1.01774","703.23297","0.01018","70.32330","0.00000"
"30.90000","1.02750","705.36359","0.01028","70.53636","-0.00001"
"31.20000","1.03760","706.19543","0.01038","70.61954","0.00000"
"31.50000","1.04759","704.35028","0.01048","70.43503","0.00000"
"31.80000","1.05758","701.81903","0.01058","70.18190","0.00001"
"32.10000","1.06753","698.77411","0.01068","69.87741","0.00000"
"32.40000","1.07761","696.24786","0.01078","69.62479","0.00000"
"32.70000","1.08756","693.29736","0.01088","69.32973","-0.00001"
"33.00000","1.09760","691.58209","0.01098","69.15821","0.00001"
"33.30000","1.10763","690.35846","0.01108","69.03584","0.00000"
"33.60000","1.11770","690.77277","0.01118","69.07728","0.00000"
"33.90000","1.12756","690.35052","0.01128","69.03505","0.00000"
"34.20000","1.13757","689.49054","0.01138","68.94905","0.00001"
"34.50000","1.14752","686.11646","0.01148","68.61165","0.00000"
"34.80000","1.15751","684.04169","0.01158","68.40417","0.00000"
"35.10000","1.16768","683.09052","0.01168","68.30905","-0.00001"
"35.40000","1.17759","676.93390","0.01178","67.69339","0.00000"
"35.70000","1.18765","671.84552","0.01188","67.18456","0.00001"
"36.00000","1.19770","669.91772","0.01198","66.99178","0.00000"
"36.30000","1.20754","667.11169","0.01208","66.71117","-0.00001"
"36.60000","1.21743","665.11945","0.01217","66.51195","0.00000"
"36.90000","1.22759","664.73743","0.01228","66.47374","0.00001"
"37.20000","1.23760","663.98187","0.01238","66.39819","0.00000"
"37.50000","1.24772","664.99542","0.01248","66.49954","-0.00001"
"37.80000","1.25762","664.96216","0.01258","66.49622","0.00000"
"38.10000","1.26761","662.98779","0.01268","66.29878","0.00000"
"38.40000","1.27754","656.67987","0.01278","65.66798","0.00000"
"38.70000","1.28758","651.20660","0.01288","65.12066","0.00000"
"39.00000","1.29752","641.15448","0.01298","64.11545","-0.00001"
"39.30000","1.30760","630.75171","0.01308","63.07517","0.00000"
"39.60000","1.31761","621.41290","0.01318","62.14129","0.00000"
"39.90000","1.32764","613.63025","0.01328","61.36303","-0.00001"
"40.20000","1.33751","594.30560","0.01338","59.43056","-0.00001"
"40.50000","1.34768","573.85443","0.01348","57.38544","0.00000"
"40.80000","1.35762","568.60675","0.01358","56.86068","0.00000"
"41.10000","1.36756","566.54541","0.01368","56.65454","0.00000"
"41.40000","1.37757","565.65692","0.01378","56.56569","-0.00001"
"41.70000","1.38752","566.23035","0.01388","56.62304","-0.00001"
"42.00000","1.39758","569.05774","0.01398","56.90577","0.00000"
"42.30000","1.40763","572.46692","0.01408","57.24669","0.00001"
"42.60000","1.41762","575.20593","0.01418","57.52059","0.00000"
"42.90000","1.42774","579.29077","0.01428","57.92908","-0.00001"
"43.20000","1.43758","582.62408","0.01438","58.26241","0.00000"
"43.50000","1.44748","586.79382","0.01447","58.67938","0.00001"
"43.80000","1.45751","590.50793","0.01458","59.05079","0.00000"
"44.10000","1.46753","593.70868","0.01468","59.37087","-0.00001"
"44.40000","1.47772","595.76410","0.01478","59.57641","-0.00001"
"44.70000","1.48766","596.44177","0.01488","59.64418","0.00000"
"45.00000","1.49764","598.83685","0.01498","59.88369","0.00001"
"45.30000","1.50761","601.73242","0.01508","60.17324","0.00000"
"45.60000","1.51755","604.51080","0.01518","60.45108","-0.00001"
"45.90000","1.52747","607.85773","0.01527","60.78577","0.00000"
"46.20000","1.53758","584.16675","0.01538","58.41668","0.00001"
"46.50000","1.54758","580.44318","0.01548","58.04432","0.00001"
"46.80000","1.55774","579.65576","0.01558","57.96558","-0.00001"
"47.10000","1.56753","579.99585","0.01568","57.99958","-0.00001"
"47.40000","1.57765","582.01257","0.01578","58.20126","0.00001"
"47.70000","1.58758","583.87604","0.01588","58.38760","0.00001"
"48.00000","1.59758","587.17841","0.01598","58.71784","-0.00001"
"48.30000","1.60749","589.98157","0.01607","58.99816","-0.00001"
"48.60000","1.61756","593.80560","0.01618","59.38056","0.00000"
"48.90000","1.62755","597.94995","0.01628","59.79499","0.00001"
"49.20000","1.63767","603.23511","0.01638","60.32351","0.00001"
"49.50000","1.64752","606.54401","0.01648","60.65440","-0.00001"
"49.80000","1.65774","610.55194","0.01658","61.05519","-0.00001"
"50.10000","1.66765","612.69861","0.01668","61.26986","-0.00001"
"50.40000","1.67754","615.67133","0.01678","61.56713","0.00002"
"50.70000","1.68752","619.79987","0.01688","61.97999","0.00000"
"51.00000","1.69760","624.97528","0.01698","62.49753","-0.00001"
"51.30000","1.70757","629.84991","0.01708","62.98499","-0.00001"
"51.60000","1.71769","635.23834","0.01718","63.52383","0.00001"
"51.90000","1.72764","640.67352","0.01728","64.06735","0.00001"
"52.20000","1.73767","646.35449","0.01738","64.63545","-0.00002"
"52.50000","1.74757","650.81116","0.01748","65.08112","-0.00001"
"52.80000","1.75752","655.22894","0.01758","65.52290","0.00000"
"53.10000","1.76752","659.36206","0.01768","65.93620","0.00001"
"53.40000","1.77758","662.60150","0.01778","66.26015","-0.00001"
"53.70000","1.78769","666.86847","0.01788","66.68684","-0.00001"
"54.00000","1.79756","670.42609","0.01798","67.04261","0.00000"
"54.30000","1.80761","673.86053","0.01808","67.38605","0.00001"
"54.60000","1.81768","676.23865","0.01818","67.62386","0.00001"
"54.90000","1.82758","674.67316","0.01828","67.46732","-0.00001"
"55.20000","1.83748","673.00641","0.01837","67.30064","-0.00001"
"55.50000","1.84760","673.07886","0.01848","67.30788","0.00001"
"55.80000","1.85751","675.12378","0.01858","67.51237","0.00001"
"56.10000","1.86769","679.14453","0.01868","67.91445","0.00000"
"56.40000","1.87757","681.67090","0.01878","68.16709","-0.00001"
"56.70000","1.88763","685.48694","0.01888","68.54869","0.00000"
"57.00000","1.89767","689.05023","0.01898","68.90502","0.00001"
"57.30000","1.90760","692.19318","0.01908","69.21931","0.00000"
"57.60000","1.91745","693.71167","0.01917","69.37117","-0.00001"
"57.90000","1.92758","696.33588","0.01928","69.63359","-0.00001"
"58.20000","1.93763","693.96503","0.01938","69.39650","0.00000"
"58.50000","1.94770","690.16156","0.01948","69.01616","0.00002"
"58.80000","1.95759","686.85840","0.01958","68.68584","-0.00001"
"59.10000","1.96771","681.59467","0.01968","68.15947","-0.00001"
"59.40000","1.97753","678.26489","0.01978","67.82649","0.00000"
"59.70000","1.98755","677.67938","0.01988","67.76794","0.00001"
"60.00000","1.99754","672.55042","0.01998","67.25504","0.00001"
"60.30000","2.00758","671.13757","0.02008","67.11375","-0.00001"
"60.60000","2.01758","670.86078","0.02018","67.08607","-0.00001"
"60.90000","2.02769","670.93658","0.02028","67.09366","0.00000"
"61.20000","2.03754","669.30511","0.02038","66.93051","0.00001"
"61.50000","2.04768","668.73157","0.02048","66.87315","0.00000"
"61.80000","2.05764","663.87177","0.02058","66.38718","-0.00001"
"62.10000","2.06753","657.15448","0.02068","65.71545","-0.00001"
"62.40000","2.07752","653.97498","0.02078","65.39750","0.00001"
"62.70000","2.08761","653.04816","0.02088","65.30482","0.00000"
"63.00000","2.09762","653.91095","0.02098","65.39110","-0.00001"
"63.30000","2.10759","654.86920","0.02108","65.48692","-0.00001"
"63.60000","2.11766","653.38422","0.02118","65.33842","0.00000"
"63.90000","2.12767","653.30487","0.02128","65.33049","0.00001"
"64.20000","2.13757","653.25348","0.02138","65.32535","0.00000"
"64.50000","2.14750","653.57611","0.02147","65.35761","-0.00001"
"64.80000","2.15751","654.01904","0.02158","65.40190","0.00000"
"65.10000","2.16754","628.86359","0.02168","62.88636","0.00001"
"65.40000","2.17775","624.80811","0.02178","62.48081","0.00001"
"65.70000","2.18760","625.22644","0.02188","62.52264","-0.00001"
"66.00000","2.19763","628.83344","0.02198","62.88334","-0.00001"
"66.30000","2.20764","632.60162","0.02208","63.26016","0.00000"
"66.60000","2.21755","635.27441","0.02218","63.52744","0.00001"
"66.90000","2.22751","637.72443","0.02228","63.77244","0.00000"
"67.20000","2.23762","622.47089","0.02238","62.24709","-0.00001"
"67.50000","2.24753","614.95837","0.02248","61.49584","-0.00001"
"67.80000","2.25766","611.11414","0.02258","61.11141","0.00001"
"68.10000","2.26758","608.76257","0.02268","60.87626","0.00001"
"68.40000","2.27767","605.42371","0.02278","60.54237","-0.00001"
"68.70000","2.28759","603.99945","0.02288","60.39994","-0.00001"
"69.00000","2.29759","603.49811","0.02298","60.34981","0.00000"
"69.30000","2.30750","602.05133","0.02307","60.20513","0.00001"
"69.60000","2.31755","601.32532","0.02318","60.13253","0.00000"
"69.90000","2.32761","601.60565","0.02328","60.16056","-0.00001"
"70.20000","2.33772","603.07397","0.02338","60.30740","-0.00001"
"70.50000","2.34756","604.60077","0.02348","60.46008","0.00001"
"70.80000","2.35772","607.61243","0.02358","60.76124","0.00000"
"71.10000","2.36760","609.84546","0.02368","60.98455","-0.00001"
"71.40000","2.37745","612.34064","0.02377","61.23406","-0.00001"
"71.70000","2.38752","616.56744","0.02388","61.65675","0.00000"
"72.00000","2.39763","620.92633","0.02398","62.09263","0.00001"
"72.30000","2.40766","624.86255","0.02408","62.48626","0.00000"
"72.60000","2.41763","628.83514","0.02418","62.88351","-0.00001"
"72.90000","2.42763","617.05164","0.02428","61.70516","0.00000"
"73.20000","2.43760","619.05200","0.02438","61.90520","0.00001"
"73.50000","2.44759","621.54205","0.02448","62.15421","0.00000"
"73.80000","2.45755","623.79541","0.02458","62.37954","0.00000"
"74.10000","2.46754","626.34039","0.02468","62.63404","-0.00001"
"74.40000","2.47755","627.92163","0.02478","62.79216","0.00000"
"74.70000","2.48771","628.78931","0.02488","62.87893","0.00001"
"75.00000","2.49757","627.91620","0.02498","62.79162","0.00000"
"75.30000","2.50767","628.68695","0.02508","62.86869","0.00000"
"75.60000","2.51766","628.06042","0.02518","62.80604","0.00000"
"75.90000","2.52757","626.64844","0.02528","62.66484","0.00001"
"76.20000","2.53751","626.26495","0.02538","62.62650","0.00000"
"76.50000","2.54756","627.51917","0.02548","62.75191","0.00000"
"76.80000","2.55749","625.88293","0.02557","62.58829","-0.00001"
"77.10000","2.56771","625.68793","0.02568","62.56879","0.00000"
"77.40000","2.57769","624.40674","0.02578","62.44067","0.00001"
"77.70000","2.58769","622.86414","0.02588","62.28642","0.00000"
"78.00000","2.59761","620.79236","0.02598","62.07924","-0.00001"
"78.30000","2.60753","617.64172","0.02608","61.76417","0.00000"
"78.60000","2.61741","613.19116","0.02617","61.31911","0.00000"
"78.90000","2.62755","613.30664","0.02628","61.33067","0.00000"
"79.20000","2.63771","614.77899","0.02638","61.47790","0.00000"
"79.50000","2.64767","615.72369","0.02648","61.57237","0.00000"
"79.80000","2.65754","616.78632","0.02658","61.67863","0.00000"
"80.10000","2.66766","617.61469","0.02668","61.76147","0.00001"
"80.40000","2.67753","616.37653","0.02678","61.63765","0.00000"
"80.70000","2.68752","613.92316","0.02688","61.39231","-0.00001"
"81.00000","2.69758","613.98700","0.02698","61.39870","0.00000"
"81.30000","2.70756","613.33667","0.02708","61.33367","0.00001"
"81.60000","2.71765","612.87500","0.02718","61.28750","0.00000"
"81.90000","2.72758","606.65265","0.02728","60.66526","-0.00001"
"82.20000","2.73756","605.19366","0.02738","60.51937","0.00000"
"82.50000","2.74767","605.59656","0.02748","60.55965","0.00001"
"82.80000","2.75767","605.59839","0.02758","60.55984","0.00000"
"83.10000","2.76753","605.37555","0.02768","60.53756","0.00000"
"83.40000","2.77754","606.20337","0.02778","60.62034","-0.00001"
"83.70000","2.78752","586.20520","0.02788","58.62052","0.00001"
"84.00000","2.79764","582.08582","0.02798","58.20858","0.00001"
"84.30000","2.80761","581.08044","0.02808","58.10804","0.00000"
"84.60000","2.81775","582.64343","0.02818","58.26434","-0.00001"
"84.90000","2.82760","583.37842","0.02828","58.33784","0.00000"
"85.20000","2.83757","584.65802","0.02838","58.46580","0.00001"
"85.50000","2.84746","586.16510","0.02847","58.61651","0.00000"
"85.80000","2.85754","587.92786","0.02858","58.79279","-0.00001"
"86.10000","2.86754","590.13470","0.02868","59.01347","0.00000"
"86.40000","2.87777","594.04608","0.02878","59.40461","0.00001"
"86.70000","2.88755","595.78571","0.02888","59.57857","0.00001"
"87.00000","2.89766","600.15076","0.02898","60.01508","0.00000"
"87.30000","2.90753","603.17090","0.02908","60.31709","-0.00001"
"87.60000","2.91753","606.16003","0.02918","60.61600","0.00000"
"87.90000","2.92749","608.56689","0.02927","60.85669","0.00000"
"88.20000","2.93764","611.41791","0.02938","61.14179","0.00000"
"88.50000","2.94759","612.77264","0.02948","61.27726","-0.00001"
"88.80000","2.95764","614.72980","0.02958","61.47298","-0.00001"
"89.10000","2.96750","614.56024","0.02967","61.45602","0.00001"
"89.40000","2.97771","615.04260","0.02978","61.50426","0.00000"
"89.70000","2.98761","613.27380","0.02988","61.32738","-0.00001"
"90.00000","2.99758","611.04663","0.02998","61.10466","-0.00001"
"90.30000","3.00753","608.86188","0.03008","60.88619","0.00001"
"90.60000","3.01752","608.26538","0.03018","60.82654","0.00001"
"90.90000","3.02760","608.45032","0.03028","60.84503","0.00000"
"91.20000","3.03760","609.20581","0.03038","60.92058","0.00000"
"91.50000","3.04763","609.39355","0.03048","60.93935","0.00000"
"91.80000","3.05769","609.58527","0.03058","60.95853","0.00001"
"92.10000","3.06764","609.22827","0.03068","60.92283","0.00001"
"92.40000","3.07748","609.33691","0.03077","60.93369","0.00000"
"92.70000","3.08750","610.97986","0.03088","61.09798","-0.00001"
"93.00000","3.09753","612.97504","0.03098","61.29750","0.00000"
"93.30000","3.10769","612.65942","0.03108","61.26594","0.00001"
"93.60000","3.11759","604.39679","0.03118","60.43968","0.00000"
"93.90000","3.12768","601.36530","0.03128","60.13653","-0.00001"
"94.20000","3.13759","600.23352","0.03138","60.02335","-0.00001"
"94.50000","3.14752","600.67297","0.03148","60.06730","0.00001"
"94.80000","3.15750","601.72815","0.03157","60.17281","0.00001"
"95.10000","3.16761","605.21863","0.03168","60.52186","0.00000"
"95.40000","3.17757","608.36304","0.03178","60.83630","-0.00001"
"95.70000","3.18775","612.62140","0.03188","61.26214","0.00000"
"96.00000","3.19752","614.46692","0.03198","61.44669","0.00001"
"96.30000","3.20760","615.89130","0.03208","61.58913","0.00000"
"96.60000","3.21761","616.80994","0.03218","61.68099","-0.00001"
"96.90000","3.22760","617.48260","0.03228","61.74826","-0.00001"
"97.20000","3.23752","615.97394","0.03238","61.59739","0.00001"
"97.50000","3.24763","614.85754","0.03248","61.48576","0.00001"
"97.80000","3.25753","613.49359","0.03258","61.34936","0.00000"
"98.10000","3.26762","613.62390","0.03268","61.36239","-0.00001"
"98.40000","3.27759","613.20392","0.03278","61.32039","0.00000"
"98.70000","3.28771","614.21033","0.03288","61.42103","0.00001"
"99.00000","3.29761","613.38904","0.03298","61.33891","0.00000"
"99.30000","3.30759","614.00104","0.03308","61.40010","-0.00001"
"99.60000","3.31747","614.39978","0.03317","61.43998","-0.00001"
"99.90000","3.32751","615.75854","0.03328","61.57586","0.00001"
"100.20000","3.33764","616.92706","0.03338","61.69271","0.00001"
"100.50000","3.34766","618.62488","0.03348","61.86249","0.00000"
"100.80000","3.35757","620.53485","0.03358","62.05349","-0.00001"
"101.10000","3.36774","624.10919","0.03368","62.41092","0.00000"
"101.40000","3.37754","626.25793","0.03378","62.62579","0.00001"
"101.70000","3.38748","628.30157","0.03387","62.83016","0.00001"
"102.00000","3.39754","631.37091","0.03398","63.13709","-0.00001"
"102.30000","3.40755","634.17676","0.03408","63.41768","-0.00001"
"102.60000","3.41768","637.20935","0.03418","63.72094","0.00001"
"102.90000","3.42767","635.46234","0.03428","63.54623","0.00001"
"103.20000","3.43759","634.50330","0.03438","63.45033","0.00000"
"103.50000","3.44759","633.44891","0.03448","63.34489","-0.00001"
"103.80000","3.45760","632.35760","0.03458","63.23576","0.00000"
"104.10000","3.46755","631.74542","0.03468","63.17454","0.00001"
"104.40000","3.47758","631.31403","0.03478","63.13140","0.00001"
"104.70000","3.48758","631.26160","0.03488","63.12616","-0.00001"
"105.00000","3.49763","631.91974","0.03498","63.19197","-0.00001"
"105.30000","3.50750","631.32666","0.03507","63.13267","0.00001"
"105.60000","3.51770","632.23047","0.03518","63.22305","0.00001"
"105.90000","3.52765","631.57910","0.03528","63.15791","0.00000"
"106.20000","3.53761","631.97308","0.03538","63.19731","-0.00001"
"106.50000","3.54753","631.85284","0.03548","63.18528","0.00000"
"106.80000","3.55752","630.89221","0.03558","63.08922","0.00001"
"107.10000","3.56754","630.47296","0.03568","63.04729","0.00001"
"107.40000","3.57767","631.52905","0.03578","63.15290","-0.00001"
"107.70000","3.58755","631.24646","0.03588","63.12465","-0.00001"
"108.00000","3.59775","633.16028","0.03598","63.31603","0.00001"
"108.30000","3.60762","633.49030","0.03608","63.34903","0.00001"
"108.60000","3.61752","633.31000","0.03618","63.33100","0.00000"
"108.90000","3.62746","633.42761","0.03627","63.34276","-0.00001"
"109.20000","3.63756","634.41656","0.03638","63.44166","0.00000"
"109.50000","3.64767","635.22510","0.03648","63.52251","0.00001"
"109.80000","3.65772","633.97772","0.03658","63.39777","0.00001"
"110.10000","3.66761","631.83588","0.03668","63.18359","-0.00001"
"110.40000","3.67760","630.64722","0.03678","63.06472","-0.00001"
"110.70000","3.68755","627.20715","0.03688","62.72071","0.00001"
"111.00000","3.69752","623.15143","0.03698","62.31514","0.00001"
"111.30000","3.70757","621.45081","0.03708","62.14508","0.00000"
"111.60000","3.71757","620.98334","0.03718","62.09834","-0.00001"
"111.90000","3.72769","620.00110","0.03728","62.00011","0.00000"
"112.20000","3.73758","618.47516","0.03738","61.84752","0.00001"
"112.50000","3.74761","618.32794","0.03748","61.83279","0.00001"
"112.80000","3.75761","618.40765","0.03758","61.84077","0.00000"
"113.10000","3.76761","619.13098","0.03768","61.91310","-0.00001"
"113.40000","3.77752","619.27960","0.03778","61.92796","0.00001"
"113.70000","3.78758","620.18512","0.03788","62.01851","0.00001"
"114.00000","3.79751","620.07739","0.03798","62.00774","0.00000"
"114.30000","3.80765","619.97998","0.03808","61.99800","0.00000"
"114.60000","3.81753","618.50055","0.03818","61.85006","0.00000"
"114.90000","3.82772","613.37531","0.03828","61.33753","0.00002"
"115.20000","3.83769","611.97125","0.03838","61.19712","0.00000"
"115.50000","3.84758","611.49078","0.03848","61.14908","0.00000"
"115.80000","3.85744","612.26782","0.03857","61.22678","-0.00001"
"116.10000","3.86757","614.37164","0.03868","61.43716","0.00001"
"116.40000","3.87754","614.17114","0.03878","61.41711","0.00001"
"116.70000","3.88772","615.39661","0.03888","61.53966","0.00000"
"117.00000","3.89759","615.61847","0.03898","61.56185","-0.00001"
"117.30000","3.90767","617.19122","0.03908","61.71912","0.00000"
"117.60000","3.91760","617.81934","0.03918","61.78193","0.00001"
"117.90000","3.92758","618.81488","0.03928","61.88149","0.00001"
"118.20000","3.93749","619.17542","0.03937","61.91754","-0.00001"
"118.50000","3.94756","620.49908","0.03948","62.04991","-0.00001"
"118.80000","3.95764","622.02985","0.03958","62.20298","0.00001"
"119.10000","3.96765","623.25690","0.03968","62.32569","0.00001"
"119.40000","3.97758","622.60760","0.03978","62.26076","0.00000"
"119.70000","3.98770","623.66083","0.03988","62.36608","-0.00001"
"120.00000","3.99756","607.05243","0.03998","60.70524","0.00000"
"120.30000","4.00755","604.66968","0.04008","60.46697","0.00001"
"120.60000","4.01757","604.24481","0.04018","60.42448","0.00000"
"120.90000","4.02751","604.04529","0.04028","60.40453","-0.00001"
"121.20000","4.03765","605.47760","0.04038","60.54776","-0.00001"
"121.50000","4.04760","606.72742","0.04048","60.67274","0.00001"
"121.80000","4.05763","607.83679","0.04058","60.78368","0.00001"
"122.10000","4.06770","609.17383","0.04068","60.91738","0.00000"
"122.40000","4.07761","609.93250","0.04078","60.99325","-0.00001"
"122.70000","4.08748","609.91443","0.04087","60.99144","0.00000"
"123.00000","4.09756","610.75812","0.04098","61.07581","0.00001"
"123.30000","4.10757","611.58490","0.04108","61.15849","0.00000"
"123.60000","4.11768","612.63245","0.04118","61.26324","0.00000"
"123.90000","4.12759","611.80341","0.04128","61.18034","0.00000"
"124.20000","4.13772","608.12140","0.04138","60.81214","0.00001"
"124.50000","4.14759","598.78162","0.04148","59.87816","0.00000"
"124.80000","4.15758","593.69104","0.04158","59.36910","0.00000"
"125.10000","4.16751","591.99866","0.04168","59.19987","-0.00001"
"125.40000","4.17758","592.32568","0.04178","59.23257","0.00000"
"125.70000","4.18755","592.35498","0.04188","59.23550","0.00001"
"126.00000","4.19771","592.86139","0.04198","59.28614","0.00001"
"126.30000","4.20751","591.26678","0.04208","59.12668","-0.00001"
"126.60000","4.21767","590.87433","0.04218","59.08743","0.00000"
"126.90000","4.22766","589.93085","0.04228","58.99308","0.00001"
"127.20000","4.23758","588.70251","0.04238","58.87025","0.00000"
"127.50000","4.24749","587.53577","0.04247","58.75358","0.00000"
"127.80000","4.25760","586.89087","0.04258","58.68909","0.00000"
"128.10000","4.26758","585.49872","0.04268","58.54987","0.00000"
"128.40000","4.27767","585.76691","0.04278","58.57669","0.00001"
"128.70000","4.28760","584.91980","0.04288","58.49198","0.00000"
"129.00000","4.29768","585.27667","0.04298","58.52767","0.00000"
"129.30000","4.30757","584.01129","0.04308","58.40113","0.00000"
"129.60000","4.31758","572.41199","0.04318","57.24120","0.00001"
"129.90000","4.32751","563.65106","0.04328","56.36510","0.00001"
"130.20000","4.33754","530.82977","0.04338","53.08298","-0.00001"
"130.50000","4.34775","487.50079","0.04348","48.75008","0.00000"
"130.80000","4.35765","462.90366","0.04358","46.29037","0.00000"
"131.10000","4.36760","443.97046","0.04368","44.39705","0.00001"
"131.40000","4.37766","436.83643","0.04378","43.68364","0.00000"
"131.70000","4.38756","432.13330","0.04388","43.21333","-0.00001"
"132.00000","4.39749","429.34186","0.04397","42.93419","0.00000"
"132.30000","4.40759","426.76837","0.04408","42.67684","0.00001"
"132.60000","4.41755","424.44012","0.04418","42.44401","0.00000"
"132.90000","4.42767","423.61865","0.04428","42.36187","-0.00001"
"133.20000","4.43759","422.29794","0.04438","42.22979","0.00000"
"133.50000","4.44765","420.35947","0.04448","42.03595","0.00001"
"133.80000","4.45760","418.29013","0.04458","41.82901","0.00001"
"134.10000","4.46760","416.48190","0.04468","41.64819","-0.00002"
"134.40000","4.47748","415.15314","0.04477","41.51531","0.00000"
"134.70000","4.48753","414.87961","0.04488","41.48796","0.00000"
"135.00000","4.49759","414.16510","0.04498","41.41651","0.00001"
"135.30000","4.50771","414.07651","0.04508","41.40765","0.00000"
"135.60000","4.51758","412.98285","0.04518","41.29829","-0.00001"
"135.90000","4.52773","413.42065","0.04528","41.34206","0.00000"
"136.20000","4.53760","412.78525","0.04538","41.27853","0.00001"
"136.50000","4.54749","412.16086","0.04547","41.21609","0.00001"
"136.80000","4.55752","411.73422","0.04558","41.17342","-0.00001"
"137.10000","4.56758","411.01361","0.04568","41.10136","-0.00001"
"137.40000","4.57760","409.76190","0.04578","40.97619","0.00001"
"137.70000","4.58772","409.52390","0.04588","40.95239","0.00001"
"138.00000","4.59760","408.40338","0.04598","40.84034","0.00000"
"138.30000","4.60763","408.23141","0.04608","40.82314","-0.00001"
"138.60000","4.61758","407.58160","0.04618","40.75816","0.00000"
"138.90000","4.62756","407.39117","0.04628","40.73912","0.00001"
"139.20000","4.63751","406.86014","0.04638","40.68601","0.00001"
"139.50000","4.64759","407.90909","0.04648","40.79091","0.00000"
"139.80000","4.65765","408.57858","0.04658","40.85786","-0.00001"
"140.10000","4.66759","408.36652","0.04668","40.83665","0.00001"
"140.40000","4.67761","407.88467","0.04678","40.78847","0.00001"
"140.70000","4.68768","407.71851","0.04688","40.77185","0.00000"
"141.00000","4.69756","406.42987","0.04698","40.64299","-0.00001"
"141.30000","4.70752","405.93292","0.04708","40.59329","0.00000"
"141.60000","4.71757","406.19135","0.04718","40.61913","0.00001"
"141.90000","4.72751","405.51685","0.04728","40.55169","0.00001"
"142.20000","4.73770","406.69296","0.04738","40.66930","-0.00001"
"142.50000","4.74764","406.08984","0.04748","40.60899","-0.00001"
"142.80000","4.75764","405.76514","0.04758","40.57652","0.00000"
"143.10000","4.76765","402.92023","0.04768","40.29202","0.00001"
"143.40000","4.77756","400.99234","0.04778","40.09924","0.00000"
"143.70000","4.78744","399.92435","0.04787","39.99244","-0.00001"
"144.00000","4.79757","400.24283","0.04798","40.02428","-0.00001"
"144.30000","4.80767","399.90106","0.04808","39.99010","0.00001"
"144.60000","4.81771","399.36978","0.04818","39.93698","0.00001"
"144.90000","4.82755","398.07092","0.04828","39.80709","-0.00001"
"145.20000","4.83767","375.00247","0.04838","37.50025","-0.00001"
"145.50000","4.84754","368.00970","0.04848","36.80097","0.00000"
"145.80000","4.85755","365.76248","0.04858","36.57625","0.00002"
"146.10000","4.86756","364.63571","0.04868","36.46357","0.00000"
"146.40000","4.87755","364.60037","0.04878","36.46004","-0.00001"
"146.70000","4.88761","364.80081","0.04888","36.48008","0.00000"
"147.00000","4.89765","364.86118","0.04898","36.48612","0.00001"
"147.30000","4.90753","363.43423","0.04908","36.34342","0.00001"
"147.60000","4.91770","363.30298","0.04918","36.33030","-0.00001"
"147.90000","4.92765","362.76886","0.04928","36.27689","-0.00001"
"148.20000","4.93753","358.94852","0.04938","35.89485","0.00001"
"148.50000","4.94755","355.84415","0.04948","35.58442","0.00001"
"148.80000","4.95753","353.78159","0.04958","35.37816","0.00000"
"149.10000","4.96757","352.35062","0.04968","35.23506","-0.00001"
"149.40000","4.97764","350.71234","0.04978","35.07124","0.00000"
"149.70000","4.98771","349.23660","0.04988","34.92366","0.00001"
"150.00000","4.99765","347.42493","0.04998","34.74249","0.00001"
"150.30000","5.00758","345.95221","0.05008","34.59522","-0.00001"
"150.60000","5.01747","343.71570","0.05017","34.37157","-0.00001"
"150.90000","5.02750","341.23282","0.05028","34.12328","0.00001"
"151.20000","5.03755","339.81476","0.05038","33.98148","0.00001"
"151.50000","5.04779","340.17563","0.05048","34.01756","0.00000"
"151.80000","5.05755","337.82532","0.05058","33.78253","0.00000"
"152.10000","5.06764","336.67056","0.05068","33.66706","0.00000"
"152.40000","5.07755","334.58548","0.05078","33.45855","0.00001"
"152.70000","5.08754","333.27487","0.05088","33.32749","0.00000"
"153.00000","5.09748","331.34424","0.05097","33.13442","-0.00001"
"153.30000","5.10766","331.14786","0.05108","33.11478","0.00000"
"153.60000","5.11755","329.16876","0.05118","32.91688","0.00001"
"153.90000","5.12770","328.62146","0.05128","32.86214","0.00001"
"154.20000","5.13750","326.56384","0.05137","32.65638","-0.00001"
"154.50000","5.14762","317.76059","0.05148","31.77606","-0.00001"
"154.80000","5.15759","302.76984","0.05158","30.27698","0.00000"
"155.10000","5.16762","297.99121","0.05168","29.79912","0.00001"
"155.40000","5.17753","294.73746","0.05178","29.47375","0.00000"
"155.70000","5.18755","293.70453","0.05188","29.37045","-0.00001"
"156.00000","5.19755","293.17526","0.05198","29.31753","0.00000"
"156.30000","5.20764","293.25186","0.05208","29.32519","0.00001"
"156.60000","5.21762","291.50946","0.05218","29.15095","0.00001"
"156.90000","5.22772","291.72598","0.05228","29.17260","0.00000"
"157.20000","5.23758","290.77185","0.05238","29.07718","-0.00001"
"157.50000","5.24749","290.81778","0.05247","29.08178","0.00000"
"157.80000","5.25750","290.83484","0.05257","29.08348","0.00001"
"158.10000","5.26756","289.36749","0.05268","28.93675","0.00000"
"158.40000","5.27766","289.06641","0.05278","28.90664","-0.00001"
"158.70000","5.28765","288.56174","0.05288","28.85617","0.00000"
"159.00000","5.29760","287.22623","0.05298","28.72262","0.00001"
"159.30000","5.30765","286.32693","0.05308","28.63269","0.00001"
"159.60000","5.31751","284.99527","0.05318","28.49953","-0.00001"
"159.90000","5.32749","284.95569","0.05327","28.49557","0.00000"
"160.20000","5.33757","285.26968","0.05338","28.52697","0.00001"
"160.50000","5.34759","284.75491","0.05348","28.47549","0.00001"
"160.80000","5.35773","284.96298","0.05358","28.49630","0.00000"
"161.10000","5.36760","283.99539","0.05368","28.39954","-0.00001"
"161.40000","5.37756","282.77219","0.05378","28.27722","0.00001"
"161.70000","5.38764","281.78714","0.05388","28.17871","0.00001"
"162.00000","5.39762","280.72876","0.05398","28.07288","0.00000"
"162.30000","5.40753","278.02280","0.05408","27.80228","-0.00001"
"162.60000","5.41758","277.00958","0.05418","27.70096","0.00000"
"162.90000","5.42749","275.76151","0.05427","27.57615","0.00001"
"163.20000","5.43765","275.46469","0.05438","27.54647","0.00000"
"163.50000","5.44758","273.53516","0.05448","27.35352","0.00000"
"163.80000","5.45768","272.84293","0.05458","27.28429","0.00000"
"164.10000","5.46759","272.29080","0.05468","27.22908","0.00001"
"164.40000","5.47762","271.72198","0.05478","27.17220","0.00001"
"164.70000","5.48746","270.25455","0.05487","27.02546","0.00000"
"165.00000","5.49752","270.03223","0.05498","27.00322","-0.00001"
"165.30000","5.50757","269.76065","0.05508","26.97606","0.00000"
"165.60000","5.51769","269.71255","0.05518","26.97126","0.00001"
"165.90000","5.52753","267.68771","0.05528","26.76877","0.00000"
"166.20000","5.53774","266.65359","0.05538","26.66536","-0.00001"
"166.50000","5.54755","263.75220","0.05548","26.37522","0.00000"
"166.80000","5.55748","262.58008","0.05557","26.25801","0.00001"
"167.10000","5.56753","262.06131","0.05568","26.20613","0.00001"
"167.40000","5.57759","261.40021","0.05578","26.14002","0.00000"
"167.70000","5.58762","251.10660","0.05588","25.11066","-0.00001"
"168.00000","5.59772","249.39717","0.05598","24.93972","0.00001"
"168.30000","5.60755","247.97508","0.05608","24.79751","0.00001"
"168.60000","5.61759","246.82530","0.05618","24.68253","0.00000"
"168.90000","5.62757","245.45386","0.05628","24.54539","-0.00001"
"169.20000","5.63755","244.88692","0.05638","24.48869","0.00000"
"169.50000","5.64756","244.50882","0.05648","24.45088","0.00001"
"169.80000","5.65759","243.40085","0.05658","24.34008","0.00001"
"170.10000","5.66763","242.68248","0.05668","24.26825","-0.00001"
"170.40000","5.67755","241.03964","0.05678","24.10396","0.00000"
"170.70000","5.68764","239.11412","0.05688","23.91141","0.00001"
"171.00000","5.69766","237.55161","0.05698","23.75516","0.00001"
"171.30000","5.70760","235.57164","0.05708","23.55716","0.00000"
"171.60000","5.71753","233.88837","0.05718","23.38884","-0.00001"
"171.90000","5.72753","232.91060","0.05728","23.29106","0.00001"
"172.20000","5.73751","231.99840","0.05738","23.19984","0.00000"
"172.50000","5.74773","231.92523","0.05748","23.19252","0.00000"
"172.80000","5.75757","230.14867","0.05758","23.01487","-0.00001"
"173.10000","5.76769","229.66739","0.05768","22.96674","0.00000"
"173.40000","5.77761","228.31982","0.05778","22.83198","0.00001"
"173.70000","5.78753","227.35980","0.05788","22.73598","0.00000"
"174.00000","5.79746","226.30783","0.05797","22.63078","0.00000"
"174.30000","5.80757","225.84209","0.05808","22.58421","-0.00001"
"174.60000","5.81761","224.33023","0.05818","22.43302","0.00001"
"174.90000","5.82773","225.00018","0.05828","22.50002","0.00001"
"175.20000","5.83760","224.48538","0.05838","22.44854","0.00000"
"175.50000","5.84765","224.73372","0.05848","22.47337","-0.00001"
"175.80000","5.85754","223.85574","0.05858","22.38557","0.00000"
"176.10000","5.86752","223.13397","0.05868","22.31340","0.00001"
"176.40000","5.87756","222.18282","0.05878","22.21828","0.00000"
"176.70000","5.88758","220.62315","0.05888","22.06231","-0.00001"
"177.00000","5.89765","219.85483","0.05898","21.98548","0.00000"
"177.30000","5.90759","219.43922","0.05908","21.94392","0.00001"
"177.60000","5.91756","219.40363","0.05918","21.94036","0.00001"
"177.90000","5.92765","219.53729","0.05928","21.95373","-0.00001"
"178.20000","5.93762","218.79045","0.05938","21.87905","-0.00001"
"178.50000","5.94754","218.22148","0.05948","21.82215","0.00001"
"178.80000","5.95755","217.95451","0.05958","21.79545","0.00001"
"179.10000","5.96752","217.52431","0.05968","21.75243","0.00000"
"179.40000","5.97765","218.04373","0.05978","21.80437","-0.00001"
"179.70000","5.98755","217.18910","0.05988","21.71891","0.00000"
"180.00000","5.99764","217.38806","0.05998","21.73881","0.00001"
"180.30000","6.00771","217.63295","0.06008","21.76329","0.00001"
"180.60000","6.01760","217.82098","0.06018","21.78210","-0.00001"
"180.90000","6.02747","217.25024","0.06027","21.72503","-0.00001"
"181.20000","6.03754","217.35326","0.06038","21.73532","0.00001"
"181.50000","6.04751","217.13255","0.06048","21.71325","0.00001"
"181.80000","6.05774","215.56683","0.06058","21.55668","0.00000"
"182.10000","6.06763","211.02914","0.06068","21.10291","-0.00001"
"182.40000","6.07766","208.18869","0.06078","20.81887","0.00000"
"182.70000","6.08756","205.54543","0.06088","20.55454","0.00001"
"183.00000","6.09758","203.10567","0.06098","20.31057","0.00000"
"183.30000","6.10748","201.40344","0.06107","20.14034","-0.00001"
"183.60000","6.11758","200.36986","0.06118","20.03699","0.00000"
"183.90000","6.12760","198.77606","0.06128","19.87761","0.00001"
"184.20000","6.13770","196.99472","0.06138","19.69947","0.00001"
"184.50000","6.14755","191.21866","0.06148","19.12187","-0.00001"
"184.80000","6.15770","188.60458","0.06158","18.86046","0.00000"
"185.10000","6.16757","185.73111","0.06168","18.57311","0.00000"
"185.40000","6.17757","183.37933","0.06178","18.33793","0.00001"
"185.70000","6.18754","178.88188","0.06188","17.88819","0.00000"
"186.00000","6.19754","174.26186","0.06198","17.42619","-0.00001"
"186.30000","6.20761","170.03461","0.06208","17.00346","0.00000"
"186.60000","6.21763","162.38116","0.06218","16.23812","0.00001"
"186.90000","6.22754","156.79883","0.06228","15.67988","0.00001"
"187.20000","6.23775","155.18365","0.06238","15.51837","-0.00001"
"187.50000","6.24763","152.16829","0.06248","15.21683","-0.00001"
"187.80000","6.25750","150.45552","0.06257","15.04555","0.00001"
"188.10000","6.26751","150.41423","0.06268","15.04142","0.00002"
"188.40000","6.27758","150.70752","0.06278","15.07075","0.00000"
"188.70000","6.28765","150.92210","0.06288","15.09221","-0.00001"
"189.00000","6.29766","151.71472","0.06298","15.17147","0.00001"
"189.30000","6.30768","152.16672","0.06308","15.21667","0.00001"
"189.60000","6.31761","152.92343","0.06318","15.29234","0.00000"
"189.90000","6.32761","149.98265","0.06328","14.99827","-0.00001"
"190.20000","6.33752","145.43369","0.06338","14.54337","0.00000"
"190.50000","6.34751","141.91544","0.06348","14.19154","0.00001"
"190.80000","6.35752","117.80452","0.06358","11.78045","0.00001"
"191.10000","6.36774","73.08162","0.06368","7.30816","0.00000"
"191.40000","6.37754","64.29288","0.06378","6.42929","-0.00001"
"191.70000","6.38766","60.35534","0.06388","6.03553","0.00001"
"192.00000","6.39766","54.92717","0.06398","5.49272","0.00001"
"192.30000","6.40757","30.37151","0.06408","3.03715","0.00000"
"192.60000","6.41748","24.29173","0.06417","2.42917","-0.00001"
"192.90000","6.42760","22.53294","0.06428","2.25329","0.00000"
"193.20000","6.43750","21.03044","0.06437","2.10304","0.00001"
"193.50000","6.44768","21.77499","0.06448","2.17750","0.00001"
"193.80000","6.45760","21.19230","0.06458","2.11923","-0.00001"
"194.10000","6.46770","21.06983","0.06468","2.10698","0.00000"
"194.40000","6.47761","19.69402","0.06478","1.96940","0.00001"
"194.70000","6.48759","18.25115","0.06488","1.82512","0.00001"
"195.00000","6.49744","17.60910","0.06497","1.76091","0.00000"
"195.30000","6.50756","18.58665","0.06508","1.85866","-0.00001"
"195.60000","6.51767","18.53213","0.06518","1.85321","0.00000"
"195.90000","6.52769","18.03165","0.06528","1.80316","0.00001"
"196.20000","6.53759","17.54357","0.06538","1.75436","0.00001"
"196.50000","6.54774","18.13006","0.06548","1.81301","-0.00001"
"196.80000","6.55755","16.79191","0.06558","1.67919","0.00000"
"197.10000","6.56751","15.39711","0.06568","1.53971","0.00001"
"197.40000","6.57755","14.24282","0.06578","1.42428","0.00001"
"197.70000","6.58754","13.20073","0.06588","1.32007","-0.00001"
"198.00000","6.59766","13.08790","0.06598","1.30879","-0.00001"
"198.30000","6.60766","13.01475","0.06608","1.30147","0.00001"
"198.60000","6.61760","12.76009","0.06618","1.27601","0.00001"
"198.90000","6.62764","13.33687","0.06628","1.33369","0.00000"
"199.20000","6.63764","12.96795","0.06638","1.29680","-0.00001"
"199.50000","6.64750","11.90861","0.06648","1.19086","0.00000"
"199.80000","6.65750","11.32137","0.06658","1.13214","0.00001"
"200.10000","6.66754","11.00389","0.06668","1.10039","0.00000"
"200.40000","6.67768","11.55907","0.06678","1.15591","-0.00001"
"200.70000","6.68756","11.61454","0.06688","1.16145","0.00000"
"201.00000","6.69773","12.54162","0.06698","1.25416","0.00001"
"201.30000","6.70762","11.98372","0.06708","1.19837","0.00000"
"201.60000","6.71755","11.72064","0.06718","1.17206","-0.00001"
"201.90000","6.72750","10.48892","0.06727","1.04889","0.00000"
"202.20000","6.73757","6.52554","0.06738","0.65255","0.00000"
"202.50000","6.74755","1.78261","0.06748","0.17826","0.00001"
"202.80000","6.75773","-0.19834","0.06758","-0.01983","0.00000"
"203.10000","6.76761","-3.01298","0.06768","-0.30130","-0.00001"
"203.40000","6.77767","-4.56324","0.06778","-0.45632","0.00000"
"203.70000","6.78761","-6.32652","0.06788","-0.63265","0.00001"
"204.00000","6.79754","-8.02287","0.06798","-0.80229","0.00001"
"204.30000","6.80750","-9.64905","0.06808","-0.96491","-0.00001"
"204.60000","6.81759","-11.01800","0.06818","-1.10180","0.00000"
"204.90000","6.82761","-12.59200","0.06828","-1.25920","0.00001"
"205.20000","6.83764","-13.89436","0.06838","-1.38944","0.00000"
"205.50000","6.84757","-16.30091","0.06848","-1.63009","0.00000"
"205.80000","6.85770","-21.16548","0.06858","-2.11655","-0.00001"
"206.10000","6.86755","-24.30289","0.06868","-2.43029","-0.00001"
"206.40000","6.87755","-25.51296","0.06878","-2.55130","0.00001"
"206.70000","6.88752","-25.52511","0.06888","-2.55251","0.00001"
"207.00000","6.89751","-25.98361","0.06898","-2.59836","-0.00001"
"207.30000","6.90768","-26.22568","0.06908","-2.62257","0.00000"
"207.60000","6.91772","-26.93567","0.06918","-2.69357","0.00001"
"207.90000","6.92761","-27.96235","0.06928","-2.79623","0.00000"
"208.20000","6.93766","-27.28890","0.06938","-2.72889","-0.00001"
"208.50000","6.94758","-26.78765","0.06948","-2.67876","0.00000"
"208.80000","6.95744","-27.17769","0.06957","-2.71777","0.00000"
"209.10000","6.96750","-27.31473","0.06967","-2.73147","0.00001"
"209.40000","6.97760","-27.26547","0.06978","-2.72655","0.00000"
"209.70000","6.98769","-26.20411","0.06988","-2.62041","0.00000"
"210.00000","6.99759","-26.05919","0.06998","-2.60592","0.00000"
"210.30000","7.00767","-25.13947","0.07008","-2.51395","0.00001"
"210.60000","7.01756","-25.11277","0.07018","-2.51128","0.00001"
"210.90000","7.02756","-24.75783","0.07028","-2.47578","-0.00001"
"211.20000","7.03756","-24.92584","0.07038","-2.49258","0.00000"
"211.50000","7.04757","-24.53802","0.07048","-2.45380","0.00001"
"211.80000","7.05757","-24.49611","0.07058","-2.44961","0.00001"
"212.10000","7.06770","-23.28659","0.07068","-2.32866","0.00000"
"212.40000","7.07754","-23.13557","0.07078","-2.31356","-0.00001"
"212.70000","7.08770","-21.22277","0.07088","-2.12228","0.00001"
"213.00000","7.09769","-20.08633","0.07098","-2.00863","0.00009"
"213.30000","7.10756","-19.93289","0.07108","-1.99329","-0.00001"
"213.60000","7.11751","-18.63400","0.07118","-1.86340","0.00003"
"213.90000","7.12753","-17.43052","0.07128","-1.74305","-0.00003"
"214.20000","7.13754","-16.51414","0.07138","-1.65141","0.00002"
"214.50000","7.14769","-15.20339","0.07148","-1.52034","0.00002"
"214.80000","7.15771","-14.95572","0.07158","-1.49557","-0.00001"
"215.10000","7.16767","-14.73162","0.07168","-1.47316","0.00000"
"215.40000","7.17760","-14.14872","0.07178","-1.41487","0.00001"
"215.70000","7.18750","-12.83522","0.07188","-1.28352","0.00001"
"216.00000","7.19746","-11.50985","0.07197","-1.15098","-0.00001"
"216.30000","7.20753","-10.34183","0.07208","-1.03418","-0.00004"
"216.60000","7.21780","-8.60722","0.07218","-0.86072","-0.00001"
"216.90000","7.22762","-8.29393","0.07228","-0.82939","0.00003"
"217.20000","7.23760","-7.32155","0.07238","-0.73216","0.00001"
"217.50000","7.24759","-5.80946","0.07248","-0.58095","-0.00001"
"217.80000","7.25754","-5.35379","0.07258","-0.53538","0.00001"
"218.10000","7.26748","-4.16524","0.07267","-0.41652","0.00002"
"218.40000","7.27763","-2.33786","0.07278","-0.23379","0.00000"
"218.70000","7.28752","-1.17509","0.07288","-0.11751","0.00002"
"219.00000","7.29769","1.46568","0.07298","0.14657","-0.00001"
"219.30000","7.30756","2.82588","0.07308","0.28259","0.00001"
"219.60000","7.31762","5.03169","0.07318","0.50317","0.00002"
"219.90000","7.32766","7.72985","0.07328","0.77298","0.00001"
"220.20000","7.33766","9.29944","0.07338","0.92994","0.00001"
"220.50000","7.34751","9.33526","0.07348","0.93353","0.00001"
"220.80000","7.35755","9.74286","0.07358","0.97429","0.00002"
"221.10000","7.36750","9.47995","0.07368","0.94800","0.00002"
"221.40000","7.37766","10.71676","0.07378","1.07168","0.00000"
"221.70000","7.38759","11.13815","0.07388","1.11381","0.00001"
"222.00000","7.39779","12.99534","0.07398","1.29953","0.00001"
"222.30000","7.40762","12.82311","0.07408","1.28231","0.00002"
"222.60000","7.41753","12.77554","0.07418","1.27755","0.00001"
"222.90000","7.42744","11.98685","0.07427","1.19868","0.00001"
"223.20000","7.43752","11.69383","0.07438","1.16938","0.00001"
"223.50000","7.44759","12.01097","0.07448","1.20110","0.00002"
"223.80000","7.45773","13.60071","0.07458","1.36007","0.00001"
"224.10000","7.46756","11.77727","0.07468","1.17773","0.00001"
"224.40000","7.47767","12.42555","0.07478","1.24255","0.00001"
"224.70000","7.48752","12.45109","0.07488","1.24511","0.00002"
"225.00000","7.49752","11.46839","0.07498","1.14684","0.00001"
"225.30000","7.50751","11.19670","0.07508","1.11967","0.00002"
"225.60000","7.51759","12.52403","0.07518","1.25240","0.00000"
"225.90000","7.52768","14.24996","0.07528","1.42500","0.00001"
"226.20000","7.53761","15.78996","0.07538","1.57900","0.00002"
"226.50000","7.54752","16.76670","0.07548","1.67667","0.00001"
"226.80000","7.55764","18.51175","0.07558","1.85118","0.00000"
"227.10000","7.56759","19.87890","0.07568","1.98789","0.00001"
"227.40000","7.57757","22.19640","0.07578","2.21964","0.00001"
"227.70000","7.58759","23.47488","0.07588","2.34749","0.00002"
"227.95100","7.59600","24.76381","0.07596","2.47638","0.00001"