File: Tension/Section_2_Group_2/epoxy_low_Sample_1_redonewiththepowerofAnton_2.is_tens_RawData/Specimen_RawData_1.csv
Time,Extension,Load,Tensile strain (Extension),Tensile stress,Strain-by-clip-gage
(s),(mm),(N),(mm/mm),(MPa),(mm/mm)
"0.00000","0.00000","-43.54091","0.00000","-4.35409","-0.00019"
"0.30000","0.00701","18.37891","0.00007","1.83789","-0.00021"
"0.60000","0.01742","109.70219","0.00017","10.97022","-0.00022"
"0.90000","0.02736","195.08266","0.00027","19.50827","-0.00021"
"1.20000","0.03729","279.58679","0.00037","27.95868","-0.00021"
"1.50000","0.04738","365.05997","0.00047","36.50600","-0.00022"
"1.80000","0.05729","447.55731","0.00057","44.75573","-0.00024"
"2.10000","0.06747","531.59235","0.00067","53.15923","-0.00020"
"2.40000","0.07735","611.51483","0.00077","61.15148","-0.00020"
"2.70000","0.08741","692.95105","0.00087","69.29510","-0.00022"
"3.00000","0.09746","773.80676","0.00097","77.38068","-0.00023"
"3.30000","0.10742","852.39557","0.00107","85.23956","-0.00020"
"3.60000","0.11722","929.13013","0.00117","92.91301","-0.00020"
"3.90000","0.12735","1008.62665","0.00127","100.86266","-0.00023"
"4.20000","0.13737","1086.61011","0.00137","108.66101","-0.00022"
"4.50000","0.14747","1164.40356","0.00147","116.44035","-0.00019"
"4.80000","0.15736","1239.96692","0.00157","123.99669","-0.00022"
"5.10000","0.16751","1318.08337","0.00168","131.80833","-0.00023"
"5.40000","0.17734","1392.99988","0.00177","139.29999","-0.00021"
"5.70000","0.18736","1470.26953","0.00187","147.02695","-0.00020"
"6.00000","0.19729","1547.79309","0.00197","154.77931","-0.00023"
"6.30000","0.20735","1627.69836","0.00207","162.76984","-0.00022"
"6.60000","0.21733","1707.33167","0.00217","170.73317","-0.00020"
"6.90000","0.22748","1789.02014","0.00227","178.90201","-0.00021"
"7.20000","0.23733","1867.20508","0.00237","186.72050","-0.00023"
"7.50000","0.24747","1948.38647","0.00247","194.83865","-0.00021"
"7.80000","0.25741","2027.44775","0.00257","202.74478","-0.00020"
"8.10000","0.26732","2106.72632","0.00267","210.67264","-0.00022"
"8.40000","0.27729","2186.38208","0.00277","218.63821","-0.00023"
"8.70000","0.28735","2266.81152","0.00287","226.68115","-0.00021"
"9.00000","0.29737","2346.78003","0.00297","234.67801","-0.00021"
"9.30000","0.30739","2427.45093","0.00307","242.74509","-0.00023"
"9.60000","0.31741","2507.73047","0.00317","250.77304","-0.00022"
"9.90000","0.32749","2588.46436","0.00327","258.84644","-0.00020"
"10.20000","0.33736","2666.32129","0.00337","266.63214","-0.00021"
"10.50000","0.34734","2745.95020","0.00347","274.59503","-0.00023"
"10.80000","0.35728","2824.89624","0.00357","282.48962","-0.00021"
"11.10000","0.36733","2904.89600","0.00367","290.48959","-0.00020"
"11.40000","0.37754","2986.15894","0.00378","298.61591","-0.00022"
"11.70000","0.38742","3064.05957","0.00387","306.40594","-0.00023"
"12.00000","0.39740","3143.12085","0.00397","314.31207","-0.00021"
"12.30000","0.40748","3222.95386","0.00407","322.29538","-0.00020"
"12.60000","0.41735","3299.28540","0.00417","329.92853","-0.00023"
"12.90000","0.42725","3376.32812","0.00427","337.63281","-0.00022"
"13.20000","0.43736","3455.99683","0.00437","345.59967","-0.00020"
"13.50000","0.44733","3533.62671","0.00447","353.36267","-0.00022"
"13.80000","0.45747","3612.77490","0.00457","361.27750","-0.00022"
"14.10000","0.46737","3688.71582","0.00467","368.87158","-0.00021"
"14.40000","0.47748","3767.51611","0.00477","376.75162","-0.00020"
"14.70000","0.48739","3844.19775","0.00487","384.41977","-0.00022"
"15.00000","0.49741","3921.43652","0.00497","392.14365","-0.00022"
"15.30000","0.50727","3996.50708","0.00507","399.65070","-0.00020"
"15.60000","0.51725","4072.92236","0.00517","407.29224","-0.00021"
"15.90000","0.52737","4150.84814","0.00527","415.08481","-0.00022"
"16.20000","0.53752","4228.60059","0.00538","422.86005","-0.00021"
"16.50000","0.54736","4302.53516","0.00547","430.25351","-0.00021"
"16.80000","0.55755","4380.41699","0.00558","438.04169","-0.00022"
"17.10000","0.56738","4453.77100","0.00567","445.37711","-0.00022"
"17.40000","0.57726","4527.89941","0.00577","452.78995","-0.00021"
"17.70000","0.58729","4603.32275","0.00587","460.33228","-0.00021"
"18.00000","0.59739","4679.13770","0.00597","467.91376","-0.00022"
"18.30000","0.60742","4754.25439","0.00607","475.42545","-0.00022"
"18.60000","0.61742","4829.17529","0.00617","482.91754","-0.00020"
"18.90000","0.62743","4903.59863","0.00627","490.35986","-0.00022"
"19.20000","0.63746","4978.00684","0.00637","497.80069","-0.00022"
"19.50000","0.64739","5050.88672","0.00647","505.08868","-0.00020"
"19.80000","0.65733","5123.65723","0.00657","512.36572","-0.00021"
"20.10000","0.66731","5197.40576","0.00667","519.74060","-0.00023"
"20.40000","0.67734","5271.07178","0.00677","527.10718","-0.00023"
"20.70000","0.68747","5345.28516","0.00687","534.52850","-0.00020"
"21.00000","0.69734","5417.12598","0.00697","541.71259","-0.00021"
"21.30000","0.70746","5491.65576","0.00707","549.16559","-0.00023"
"21.60000","0.71752","5564.84180","0.00718","556.48419","-0.00022"
"21.90000","0.72736","5634.79980","0.00727","563.47998","-0.00019"
"22.20000","0.73728","5705.38086","0.00737","570.53809","-0.00020"
"22.50000","0.74731","5777.85059","0.00747","577.78503","-0.00023"
"22.80000","0.75726","5849.14697","0.00757","584.91467","-0.00021"
"23.10000","0.76753","5923.72363","0.00768","592.37238","-0.00021"
"23.40000","0.77751","5994.10107","0.00778","599.41010","-0.00022"
"23.70000","0.78744","6064.29150","0.00787","606.42914","-0.00022"
"24.00000","0.79744","6135.60254","0.00797","613.56024","-0.00020"
"24.30000","0.80735","6205.06543","0.00807","620.50653","-0.00021"
"24.60000","0.81719","6272.84033","0.00817","627.28406","-0.00023"
"24.90000","0.82731","6343.93750","0.00827","634.39374","-0.00021"
"25.20000","0.83751","6415.97217","0.00838","641.59723","-0.00020"
"25.50000","0.84746","6485.17969","0.00847","648.51794","-0.00021"
"25.80000","0.85733","6552.52051","0.00857","655.25208","-0.00023"
"26.10000","0.86748","6623.85156","0.00867","662.38513","-0.00021"
"26.40000","0.87732","6690.83203","0.00877","669.08319","-0.00021"
"26.70000","0.88730","6759.31738","0.00887","675.93176","-0.00022"
"27.00000","0.89737","6827.65625","0.00897","682.76562","-0.00022"
"27.30000","0.90732","6895.09424","0.00907","689.50940","-0.00020"
"27.60000","0.91741","6964.39307","0.00917","696.43933","-0.00021"
"27.90000","0.92743","7032.21240","0.00927","703.22125","-0.00023"
"28.20000","0.93733","7098.28516","0.00937","709.82849","-0.00021"
"28.50000","0.94754","7167.32812","0.00948","716.73279","-0.00020"
"28.80000","0.95748","7233.06006","0.00957","723.30603","-0.00022"
"29.10000","0.96731","7297.30859","0.00967","729.73083","-0.00023"
"29.40000","0.97730","7363.48242","0.00977","736.34827","-0.00020"
"29.70000","0.98729","7429.10059","0.00987","742.91003","-0.00020"
"30.00000","0.99739","7495.42188","0.00997","749.54218","-0.00023"
"30.30000","1.00744","7560.93115","0.01007","756.09314","-0.00022"
"30.60000","1.01752","7626.63770","0.01018","762.66376","-0.00020"
"30.90000","1.02743","7690.55615","0.01027","769.05560","-0.00021"
"31.20000","1.03741","7754.35059","0.01037","775.43506","-0.00023"
"31.50000","1.04723","7815.80225","0.01047","781.58020","-0.00021"
"31.80000","1.05729","7879.72510","0.01057","787.97253","-0.00020"
"32.10000","1.06735","7943.69141","0.01067","794.36914","-0.00023"
"32.40000","1.07761","8009.14307","0.01078","800.91431","-0.00024"
"32.70000","1.08729","8066.90674","0.01087","806.69067","-0.00021"
"33.00000","1.09747","8131.20752","0.01097","813.12073","-0.00019"
"33.30000","1.10736","8191.05518","0.01107","819.10553","-0.00023"
"33.60000","1.11732","8251.15039","0.01117","825.11505","-0.00022"
"33.90000","1.12724","8310.06445","0.01127","831.00647","-0.00020"
"34.20000","1.13742","8372.20020","0.01137","837.22003","-0.00021"
"34.50000","1.14730","8430.06055","0.01147","843.00604","-0.00023"
"34.80000","1.15746","8491.37891","0.01157","849.13788","-0.00022"
"35.10000","1.16729","8547.79883","0.01167","854.77991","-0.00020"
"35.40000","1.17751","8608.19629","0.01178","860.81964","-0.00022"
"35.70000","1.18745","8665.08008","0.01187","866.50800","-0.00023"
"36.00000","1.19737","8721.12109","0.01197","872.11212","-0.00021"
"36.30000","1.20726","8776.54688","0.01207","877.65466","-0.00020"
"36.60000","1.21731","8833.64160","0.01217","883.36414","-0.00023"
"36.90000","1.22736","8889.65527","0.01227","888.96552","-0.00022"
"37.20000","1.23740","8945.93750","0.01237","894.59375","-0.00019"
"37.50000","1.24741","9000.78711","0.01247","900.07874","-0.00021"
"37.80000","1.25751","9056.95410","0.01258","905.69543","-0.00023"
"38.10000","1.26748","9110.29688","0.01267","911.02966","-0.00022"
"38.40000","1.27724","9161.01855","0.01277","916.10187","-0.00020"
"38.70000","1.28725","9214.26367","0.01287","921.42639","-0.00022"
"39.00000","1.29731","9267.58398","0.01297","926.75842","-0.00023"
"39.30000","1.30746","9321.34375","0.01307","932.13440","-0.00021"
"39.60000","1.31737","9371.39648","0.01317","937.13965","-0.00020"
"39.90000","1.32742","9422.62988","0.01327","942.26300","-0.00022"
"40.20000","1.33744","9473.70801","0.01337","947.37079","-0.00022"
"40.50000","1.34735","9521.52539","0.01347","952.15253","-0.00020"
"40.80000","1.35727","9568.89355","0.01357","956.88934","-0.00021"
"41.10000","1.36735","9618.01367","0.01367","961.80139","-0.00023"
"41.40000","1.37733","9664.92871","0.01377","966.49286","-0.00022"
"41.70000","1.38756","9714.70020","0.01388","971.47003","-0.00020"
"42.00000","1.39736","9758.01758","0.01397","975.80176","-0.00022"
"42.30000","1.40738","9803.74414","0.01407","980.37439","-0.00023"
"42.60000","1.41742","9849.13965","0.01417","984.91394","-0.00021"
"42.90000","1.42740","9893.22754","0.01427","989.32275","-0.00020"
"43.20000","1.43729","9934.63281","0.01437","993.46326","-0.00023"
"43.50000","1.44736","9977.15332","0.01447","997.71533","-0.00023"
"43.80000","1.45730","10018.00977","0.01457","1001.80096","-0.00020"
"44.10000","1.46742","10060.07031","0.01467","1006.00702","-0.00021"
"44.40000","1.47739","10099.12012","0.01477","1009.91199","-0.00022"
"44.70000","1.48751","10139.14453","0.01488","1013.91443","-0.00022"
"45.00000","1.49734","10174.33496","0.01497","1017.43347","-0.00020"
"45.30000","1.50739","10211.91113","0.01507","1021.19110","-0.00021"
"45.60000","1.51724","10245.76367","0.01517","1024.57642","-0.00022"
"45.90000","1.52730","10280.28320","0.01527","1028.02832","-0.00022"
"46.20000","1.53741","10315.14453","0.01537","1031.51440","-0.00020"
"46.50000","1.54745","10348.95508","0.01547","1034.89551","-0.00021"
"46.80000","1.55728","10379.42188","0.01557","1037.94214","-0.00023"
"47.10000","1.56755","10414.33496","0.01568","1041.43347","-0.00021"
"47.40000","1.57735","10442.68555","0.01577","1044.26855","-0.00020"
"47.70000","1.58726","10471.21582","0.01587","1047.12158","-0.00022"
"48.00000","1.59728","10500.19531","0.01597","1050.01953","-0.00022"
"48.30000","1.60734","10528.29590","0.01607","1052.82959","-0.00020"
"48.60000","1.61744","10555.89648","0.01617","1055.58960","-0.00021"
"48.90000","1.62750","10582.36328","0.01628","1058.23633","-0.00023"
"49.20000","1.63737","10605.71289","0.01637","1060.57129","-0.00022"
"49.50000","1.64737","10629.57422","0.01647","1062.95740","-0.00020"
"49.80000","1.65739","10652.54883","0.01657","1065.25488","-0.00022"
"50.10000","1.66731","10673.02930","0.01667","1067.30298","-0.00023"
"50.40000","1.67731","10693.98535","0.01677","1069.39856","-0.00021"
"50.70000","1.68736","10714.77637","0.01687","1071.47766","-0.00021"
"51.00000","1.69742","10735.52930","0.01697","1073.55298","-0.00022"
"51.30000","1.70732","10752.87207","0.01707","1075.28723","-0.00022"
"51.60000","1.71747","10773.76953","0.01717","1077.37695","-0.00020"
"51.90000","1.72740","10791.63379","0.01727","1079.16333","-0.00021"
"52.20000","1.73739","10809.69336","0.01737","1080.96936","-0.00022"
"52.50000","1.74732","10825.62891","0.01747","1082.56287","-0.00022"
"52.80000","1.75731","10841.77637","0.01757","1084.17761","-0.00020"
"53.10000","1.76728","10857.42383","0.01767","1085.74243","-0.00021"
"53.40000","1.77748","10876.02148","0.01777","1087.60217","-0.00023"
"53.70000","1.78734","10888.61816","0.01787","1088.86182","-0.00021"
"54.00000","1.79753","10904.77051","0.01798","1090.47705","-0.00021"
"54.30000","1.80742","10917.14551","0.01807","1091.71460","-0.00022"
"54.60000","1.81728","10928.60449","0.01817","1092.86047","-0.00022"
"54.90000","1.82722","10940.16406","0.01827","1094.01636","-0.00020"
"55.20000","1.83732","10953.55469","0.01837","1095.35547","-0.00021"
"55.50000","1.84739","10965.95312","0.01847","1096.59534","-0.00023"
"55.80000","1.85753","10979.02539","0.01858","1097.90259","-0.00021"
"56.10000","1.86741","10988.78516","0.01867","1098.87854","-0.00020"
"56.40000","1.87746","11000.32227","0.01877","1100.03223","-0.00022"
"56.70000","1.88736","11009.09668","0.01887","1100.90967","-0.00022"
"57.00000","1.89730","11017.97168","0.01897","1101.79712","-0.00021"
"57.30000","1.90728","11026.92773","0.01907","1102.69275","-0.00021"
"57.60000","1.91733","11036.66699","0.01917","1103.66675","-0.00022"
"57.90000","1.92749","11047.25488","0.01927","1104.72546","-0.00022"
"58.20000","1.93737","11054.74707","0.01937","1105.47473","-0.00020"
"58.50000","1.94739","11063.67578","0.01947","1106.36755","-0.00021"
"58.80000","1.95747","11073.35645","0.01957","1107.33569","-0.00023"
"59.10000","1.96746","11081.60059","0.01967","1108.16003","-0.00021"
"59.40000","1.97735","11087.92383","0.01977","1108.79236","-0.00020"
"59.70000","1.98731","11094.99902","0.01987","1109.49988","-0.00022"
"60.00000","1.99727","11102.70020","0.01997","1110.27002","-0.00022"
"60.30000","2.00746","11112.86328","0.02007","1111.28638","-0.00020"
"60.60000","2.01733","11119.01660","0.02017","1111.90161","-0.00021"
"60.90000","2.02749","11128.43848","0.02027","1112.84387","-0.00022"
"61.20000","2.03750","11136.75684","0.02037","1113.67566","-0.00022"
"61.50000","2.04738","11143.72754","0.02047","1114.37280","-0.00020"
"61.80000","2.05723","11149.59082","0.02057","1114.95911","-0.00022"
"62.10000","2.06733","11157.86328","0.02067","1115.78638","-0.00022"
"62.40000","2.07727","11164.24609","0.02077","1116.42456","-0.00021"
"62.70000","2.08751","11174.14941","0.02088","1117.41492","-0.00020"
"63.00000","2.09745","11179.83789","0.02097","1117.98376","-0.00022"
"63.30000","2.10748","11186.90918","0.02107","1118.69092","-0.00022"
"63.60000","2.11740","11192.51953","0.02117","1119.25195","-0.00020"
"63.90000","2.12736","11198.37207","0.02127","1119.83716","-0.00021"
"64.20000","2.13727","11203.65820","0.02137","1120.36584","-0.00022"
"64.50000","2.14734","11210.83691","0.02147","1121.08374","-0.00022"
"64.80000","2.15741","11218.09766","0.02157","1121.80981","-0.00020"
"65.10000","2.16741","11224.33105","0.02167","1122.43311","-0.00022"
"65.40000","2.17735","11229.39941","0.02177","1122.93994","-0.00023"
"65.70000","2.18750","11236.82520","0.02188","1123.68250","-0.00021"
"66.00000","2.19739","11241.52539","0.02197","1124.15259","-0.00020"
"66.30000","2.20737","11247.38477","0.02207","1124.73853","-0.00022"
"66.60000","2.21740","11253.30859","0.02217","1125.33081","-0.00023"
"66.90000","2.22727","11257.25000","0.02227","1125.72498","-0.00020"
"67.20000","2.23741","11264.54590","0.02237","1126.45459","-0.00021"
"67.50000","2.24742","11270.33496","0.02247","1127.03345","-0.00022"
"67.80000","2.25739","11275.37012","0.02257","1127.53699","-0.00022"
"68.10000","2.26755","11282.72363","0.02268","1128.27234","-0.00020"
"68.40000","2.27745","11286.03320","0.02277","1128.60327","-0.00022"
"68.70000","2.28724","11287.68945","0.02287","1128.76892","-0.00023"
"69.00000","2.29734","11293.58301","0.02297","1129.35828","-0.00021"
"69.30000","2.30730","11297.91406","0.02307","1129.79138","-0.00020"
"69.60000","2.31746","11304.87109","0.02317","1130.48706","-0.00022"
"69.90000","2.32744","11309.52832","0.02327","1130.95288","-0.00023"
"70.20000","2.33751","11314.62500","0.02338","1131.46252","-0.00020"
"70.50000","2.34739","11317.66309","0.02347","1131.76636","-0.00021"
"70.80000","2.35737","11321.93164","0.02357","1132.19312","-0.00022"
"71.10000","2.36730","11324.95020","0.02367","1132.49500","-0.00022"
"71.40000","2.37734","11329.36816","0.02377","1132.93677","-0.00020"
"71.70000","2.38731","11331.98633","0.02387","1133.19861","-0.00022"
"72.00000","2.39748","11336.70703","0.02397","1133.67065","-0.00023"
"72.30000","2.40728","11337.17773","0.02407","1133.71777","-0.00021"
"72.60000","2.41748","11342.09180","0.02417","1134.20923","-0.00020"
"72.90000","2.42747","11343.96191","0.02427","1134.39624","-0.00022"
"73.20000","2.43735","11345.24023","0.02437","1134.52405","-0.00023"
"73.50000","2.44725","11345.21777","0.02447","1134.52173","-0.00020"
"73.80000","2.45734","11348.08203","0.02457","1134.80823","-0.00020"
"74.10000","2.46728","11349.08691","0.02467","1134.90869","-0.00023"
"74.40000","2.47745","11354.21289","0.02477","1135.42126","-0.00022"
"74.70000","2.48739","11356.37500","0.02487","1135.63745","-0.00020"
"75.00000","2.49752","11360.71191","0.02498","1136.07117","-0.00020"
"75.30000","2.50742","11361.71777","0.02507","1136.17175","-0.00024"
"75.60000","2.51738","11361.99902","0.02517","1136.19995","-0.00021"
"75.90000","2.52722","11361.21875","0.02527","1136.12183","-0.00020"
"76.20000","2.53733","11364.13770","0.02537","1136.41382","-0.00022"
"76.50000","2.54742","11366.65527","0.02547","1136.66553","-0.00023"
"76.80000","2.55747","11368.65039","0.02557","1136.86499","-0.00020"
"77.10000","2.56739","11368.96191","0.02567","1136.89624","-0.00020"
"77.40000","2.57750","11371.19336","0.02577","1137.11938","-0.00022"
"77.70000","2.58735","11370.73633","0.02587","1137.07361","-0.00023"
"78.00000","2.59733","11372.24121","0.02597","1137.22412","-0.00020"
"78.30000","2.60735","11373.62012","0.02607","1137.36206","-0.00021"
"78.60000","2.61731","11375.47461","0.02617","1137.54749","-0.00023"
"78.90000","2.62745","11379.77246","0.02627","1137.97729","-0.00021"
"79.20000","2.63737","11379.83496","0.02637","1137.98352","-0.00020"
"79.50000","2.64742","11381.41309","0.02647","1138.14136","-0.00021"
"79.80000","2.65742","11383.47559","0.02657","1138.34753","-0.00023"
"80.10000","2.66742","11384.95996","0.02667","1138.49597","-0.00021"
"80.40000","2.67728","11384.72363","0.02677","1138.47241","-0.00020"
"80.70000","2.68730","11386.09277","0.02687","1138.60925","-0.00022"
"81.00000","2.69733","11387.15039","0.02697","1138.71509","-0.00023"
"81.30000","2.70750","11389.91309","0.02708","1138.99133","-0.00020"
"81.60000","2.71737","11388.76367","0.02717","1138.87634","-0.00021"
"81.90000","2.72752","11391.06641","0.02728","1139.10669","-0.00023"
"82.20000","2.73742","11389.87402","0.02737","1138.98743","-0.00022"
"82.50000","2.74731","11387.94141","0.02747","1138.79419","-0.00020"
"82.80000","2.75728","11386.64062","0.02757","1138.66406","-0.00022"
"83.10000","2.76738","11386.11133","0.02767","1138.61108","-0.00023"
"83.40000","2.77742","11385.01465","0.02777","1138.50146","-0.00021"
"83.70000","2.78750","11383.83105","0.02788","1138.38306","-0.00020"
"84.00000","2.79742","11380.80566","0.02797","1138.08057","-0.00022"
"84.30000","2.80744","11379.20801","0.02807","1137.92078","-0.00022"
"84.60000","2.81740","11376.90723","0.02817","1137.69067","-0.00020"
"84.90000","2.82737","11374.60254","0.02827","1137.46021","-0.00020"
"85.20000","2.83729","11372.08984","0.02837","1137.20898","-0.00023"
"85.50000","2.84732","11370.91797","0.02847","1137.09180","-0.00022"
"85.80000","2.85743","11370.91992","0.02857","1137.09204","-0.00020"
"86.10000","2.86746","11369.15625","0.02867","1136.91565","-0.00022"
"86.40000","2.87739","11364.73828","0.02877","1136.47388","-0.00023"
"86.70000","2.88753","11363.12793","0.02888","1136.31274","-0.00021"
"87.00000","2.89735","11357.34570","0.02897","1135.73462","-0.00020"
"87.30000","2.90732","11352.81445","0.02907","1135.28149","-0.00022"
"87.60000","2.91730","11348.32715","0.02917","1134.83276","-0.00023"
"87.90000","2.92725","11343.52441","0.02927","1134.35242","-0.00020"
"88.20000","2.93748","11342.11816","0.02937","1134.21179","-0.00021"
"88.50000","2.94755","11339.24023","0.02948","1133.92407","-0.00022"
"88.80000","2.95746","11334.51270","0.02957","1133.45129","-0.00022"
"89.10000","2.96748","11331.55762","0.02967","1133.15576","-0.00020"
"89.40000","2.97737","11327.82129","0.02977","1132.78210","-0.00022"
"89.70000","2.98715","11321.79395","0.02987","1132.17944","-0.00023"
"90.00000","2.99734","11321.44824","0.02997","1132.14478","-0.00021"
"90.30000","3.00746","11320.54590","0.03007","1132.05457","-0.00021"
"90.60000","3.01751","11319.58594","0.03018","1131.95862","-0.00021"
"90.90000","3.02736","11315.89844","0.03027","1131.58984","-0.00023"
"91.20000","3.03751","11315.37402","0.03038","1131.53735","-0.00020"
"91.50000","3.04737","11311.39648","0.03047","1131.13965","-0.00021"
"91.80000","3.05734","11308.07129","0.03057","1130.80713","-0.00022"
"92.10000","3.06735","11305.55176","0.03067","1130.55518","-0.00022"
"92.40000","3.07730","11302.57520","0.03077","1130.25757","-0.00020"
"92.70000","3.08736","11299.93555","0.03087","1129.99353","-0.00022"
"93.00000","3.09750","11298.50488","0.03097","1129.85046","-0.00022"
"93.30000","3.10733","11292.99023","0.03107","1129.29907","-0.00021"
"93.60000","3.11756","11292.47754","0.03118","1129.24780","-0.00021"
"93.90000","3.12753","11288.69727","0.03128","1128.86975","-0.00022"
"94.20000","3.13736","11282.10059","0.03137","1128.21008","-0.00021"
"94.50000","3.14727","11276.66602","0.03147","1127.66663","-0.00020"
"94.80000","3.15729","11270.96094","0.03157","1127.09607","-0.00021"
"95.10000","3.16732","11264.15918","0.03167","1126.41589","-0.00022"
"95.40000","3.17752","11260.31836","0.03178","1126.03186","-0.00021"
"95.70000","3.18754","11253.00000","0.03188","1125.30005","-0.00021"
"96.00000","3.19748","11245.53418","0.03197","1124.55347","-0.00022"
"96.30000","3.20741","11238.50391","0.03207","1123.85034","-0.00022"
"96.60000","3.21729","11230.63379","0.03217","1123.06335","-0.00021"
"96.90000","3.22724","11223.19531","0.03227","1122.31958","-0.00018"
"97.20000","3.23731","11217.07617","0.03237","1121.70764","-0.00023"
"97.50000","3.24760","11213.83789","0.03248","1121.38379","-0.00021"
"97.80000","3.25735","11203.58398","0.03257","1120.35840","-0.00021"
"98.10000","3.26748","11197.53906","0.03267","1119.75391","-0.00021"
"98.40000","3.27740","11189.79395","0.03277","1118.97937","-0.00022"
"98.70000","3.28735","11181.38770","0.03287","1118.13879","-0.00021"
"99.00000","3.29725","11171.22363","0.03297","1117.12231","-0.00020"
"99.30000","3.30741","11163.31934","0.03307","1116.33191","-0.00023"
"99.60000","3.31726","11152.07227","0.03317","1115.20728","-0.00022"
"99.90000","3.32746","11145.97656","0.03327","1114.59766","-0.00020"
"100.20000","3.33734","11135.40039","0.03337","1113.54004","-0.00020"
"100.50000","3.34748","11127.68848","0.03347","1112.76880","-0.00023"
"100.80000","3.35751","11119.34180","0.03358","1111.93420","-0.00022"
"101.10000","3.36746","11111.24121","0.03367","1111.12415","-0.00020"
"101.40000","3.37727","11100.35059","0.03377","1110.03503","-0.00022"
"101.70000","3.38734","11092.23438","0.03387","1109.22339","-0.00023"
"102.00000","3.39732","11079.95605","0.03397","1107.99561","-0.00021"
"102.30000","3.40746","11068.55469","0.03407","1106.85547","-0.00020"
"102.60000","3.41743","11052.81836","0.03417","1105.28186","-0.00022"
"102.90000","3.42755","11037.27930","0.03428","1103.72791","-0.00022"
"103.20000","3.43738","11016.88184","0.03437","1101.68823","-0.00020"
"103.50000","3.44732","10996.62891","0.03447","1099.66284","-0.00020"
"103.80000","3.45727","10974.98145","0.03457","1097.49817","-0.00023"
"104.10000","3.46734","10954.45215","0.03467","1095.44519","-0.00022"
"104.40000","3.47744","10935.30469","0.03477","1093.53052","-0.00020"
"104.70000","3.48745","10916.89160","0.03487","1091.68921","-0.00021"
"105.00000","3.49738","10898.22754","0.03497","1089.82275","-0.00023"
"105.30000","3.50746","10881.26953","0.03507","1088.12695","-0.00021"
"105.60000","3.51735","10861.15430","0.03517","1086.11548","-0.00020"
"105.90000","3.52730","10841.60547","0.03527","1084.16052","-0.00022"
"106.20000","3.53733","10822.94531","0.03537","1082.29456","-0.00023"
"106.50000","3.54731","10805.05664","0.03547","1080.50562","-0.00020"
"106.80000","3.55745","10789.79297","0.03557","1078.97925","-0.00020"
"107.10000","3.56740","10774.26562","0.03567","1077.42651","-0.00023"
"107.40000","3.57736","10758.75293","0.03577","1075.87524","-0.00022"
"107.70000","3.58750","10746.52051","0.03588","1074.65210","-0.00019"
"108.00000","3.59741","10732.90039","0.03597","1073.29004","-0.00021"
"108.30000","3.60728","10718.09668","0.03607","1071.80969","-0.00023"
"108.60000","3.61735","10704.68945","0.03617","1070.46899","-0.00022"
"108.90000","3.62731","10690.29395","0.03627","1069.02942","-0.00019"
"109.20000","3.63744","10677.18164","0.03637","1067.71814","-0.00022"
"109.50000","3.64738","10661.00586","0.03647","1066.10059","-0.00023"
"109.80000","3.65748","10647.93262","0.03657","1064.79321","-0.00021"
"110.10000","3.66738","10631.47559","0.03667","1063.14758","-0.00020"
"110.40000","3.67744","10617.43750","0.03677","1061.74377","-0.00022"
"110.70000","3.68721","10601.58496","0.03687","1060.15845","-0.00023"
"111.00000","3.69729","10588.76953","0.03697","1058.87695","-0.00020"
"111.30000","3.70739","10576.22559","0.03707","1057.62256","-0.00020"
"111.60000","3.71752","10565.17773","0.03718","1056.51782","-0.00023"
"111.90000","3.72730","10550.28027","0.03727","1055.02808","-0.00022"
"112.20000","3.73755","10541.09375","0.03738","1054.10938","-0.00019"
"112.50000","3.74738","10527.29590","0.03747","1052.72961","-0.00021"
"112.80000","3.75729","10517.40039","0.03757","1051.73999","-0.00023"
"113.10000","3.76725","10508.85156","0.03767","1050.88513","-0.00022"
"113.40000","3.77734","10502.51074","0.03777","1050.25110","-0.00019"
"113.70000","3.78736","10495.46387","0.03787","1049.54639","-0.00022"
"114.00000","3.79755","10490.86426","0.03798","1049.08643","-0.00023"
"114.30000","3.80737","10481.21191","0.03807","1048.12122","-0.00021"
"114.60000","3.81742","10474.42383","0.03817","1047.44238","-0.00020"
"114.90000","3.82741","10467.21582","0.03827","1046.72156","-0.00023"
"115.20000","3.83733","10459.45508","0.03837","1045.94556","-0.00022"
"115.50000","3.84727","10452.19336","0.03847","1045.21936","-0.00020"
"115.80000","3.85737","10447.10156","0.03857","1044.71021","-0.00021"
"116.10000","3.86738","10440.60840","0.03867","1044.06079","-0.00023"
"116.40000","3.87735","10432.22461","0.03877","1043.22241","-0.00021"
"116.70000","3.88746","10425.48828","0.03887","1042.54883","-0.00020"
"117.00000","3.89746","10416.87988","0.03897","1041.68799","-0.00021"
"117.30000","3.90738","10407.26953","0.03907","1040.72693","-0.00024"
"117.60000","3.91732","10396.71094","0.03917","1039.67114","-0.00020"
"117.90000","3.92732","10386.83105","0.03927","1038.68311","-0.00020"
"118.20000","3.93728","10377.65039","0.03937","1037.76501","-0.00022"
"118.50000","3.94748","10372.08496","0.03947","1037.20850","-0.00023"
"118.80000","3.95734","10362.89746","0.03957","1036.28979","-0.00020"
"119.10000","3.96745","10356.07617","0.03967","1035.60767","-0.00021"
"119.40000","3.97746","10349.42676","0.03977","1034.94263","-0.00023"
"119.70000","3.98733","10341.47852","0.03987","1034.14783","-0.00022"
"120.00000","3.99722","10332.99219","0.03997","1033.29919","-0.00020"
"120.30000","4.00731","10326.91113","0.04007","1032.69116","-0.00021"
"120.60000","4.01735","10319.97070","0.04017","1031.99707","-0.00023"
"120.90000","4.02753","10315.70117","0.04028","1031.57007","-0.00020"
"121.20000","4.03746","10308.72949","0.04037","1030.87292","-0.00020"
"121.50000","4.04746","10303.43359","0.04047","1030.34338","-0.00022"
"121.80000","4.05735","10297.64355","0.04057","1029.76440","-0.00022"
"122.10000","4.06733","10293.05176","0.04067","1029.30518","-0.00020"
"122.40000","4.07729","10286.45996","0.04077","1028.64600","-0.00020"
"122.70000","4.08735","10281.56445","0.04087","1028.15649","-0.00023"
"123.00000","4.09742","10277.28125","0.04097","1027.72815","-0.00022"
"123.30000","4.10743","10272.18652","0.04107","1027.21863","-0.00020"
"123.60000","4.11734","10265.36914","0.04117","1026.53687","-0.00021"
"123.90000","4.12751","10261.75977","0.04128","1026.17603","-0.00023"
"124.20000","4.13741","10254.83008","0.04137","1025.48303","-0.00021"
"124.50000","4.14734","10246.25000","0.04147","1024.62500","-0.00020"
"124.80000","4.15732","10237.53027","0.04157","1023.75305","-0.00022"
"125.10000","4.16731","10229.27051","0.04167","1022.92706","-0.00022"
"125.40000","4.17740","10222.04590","0.04177","1022.20459","-0.00021"
"125.70000","4.18736","10215.24414","0.04187","1021.52441","-0.00021"
"126.00000","4.19746","10209.36914","0.04197","1020.93689","-0.00022"
"126.30000","4.20755","10202.66309","0.04208","1020.26630","-0.00022"
"126.60000","4.21738","10193.11133","0.04217","1019.31116","-0.00021"
"126.90000","4.22722","10184.02344","0.04227","1018.40234","-0.00021"
"127.20000","4.23729","10178.00488","0.04237","1017.80048","-0.00022"
"127.50000","4.24727","10170.54883","0.04247","1017.05487","-0.00021"
"127.80000","4.25751","10167.48535","0.04258","1016.74854","-0.00021"
"128.10000","4.26750","10161.04102","0.04268","1016.10413","-0.00022"
"128.40000","4.27746","10154.00293","0.04277","1015.40027","-0.00021"
"128.70000","4.28746","10146.72656","0.04287","1014.67267","-0.00021"
"129.00000","4.29739","10139.13770","0.04297","1013.91376","-0.00021"
"129.30000","4.30723","10130.96094","0.04307","1013.09607","-0.00022"
"129.60000","4.31733","10126.35059","0.04317","1012.63507","-0.00021"
"129.90000","4.32737","10120.45898","0.04327","1012.04590","-0.00020"
"130.20000","4.33746","10115.11621","0.04337","1011.51160","-0.00022"
"130.50000","4.34735","10107.01660","0.04347","1010.70166","-0.00022"
"130.80000","4.35749","10101.30664","0.04357","1010.13068","-0.00021"
"131.10000","4.36739","10094.37305","0.04367","1009.43732","-0.00020"
"131.40000","4.37742","10087.89453","0.04377","1008.78943","-0.00022"
"131.70000","4.38733","10079.90723","0.04387","1007.99072","-0.00022"
"132.00000","4.39729","10073.15527","0.04397","1007.31555","-0.00021"
"132.30000","4.40733","10066.89746","0.04407","1006.68976","-0.00021"
"132.60000","4.41747","10061.96387","0.04417","1006.19641","-0.00022"
"132.90000","4.42735","10052.84375","0.04427","1005.28436","-0.00021"
"133.20000","4.43758","10048.32715","0.04438","1004.83270","-0.00021"
"133.50000","4.44745","10039.80176","0.04447","1003.98016","-0.00022"
"133.80000","4.45731","10030.86914","0.04457","1003.08691","-0.00022"
"134.10000","4.46730","10023.76562","0.04467","1002.37659","-0.00021"
"134.40000","4.47733","10016.05273","0.04477","1001.60529","-0.00022"
"134.70000","4.48735","10008.24316","0.04487","1000.82434","-0.00022"
"135.00000","4.49748","10002.32520","0.04497","1000.23254","-0.00021"
"135.30000","4.50747","9996.07031","0.04507","999.60706","-0.00020"
"135.60000","4.51744","9991.04395","0.04517","999.10437","-0.00022"
"135.90000","4.52740","9985.86133","0.04527","998.58612","-0.00022"
"136.20000","4.53733","9979.35352","0.04537","997.93536","-0.00021"
"136.50000","4.54731","9971.92188","0.04547","997.19220","-0.00020"
"136.80000","4.55733","9963.14258","0.04557","996.31427","-0.00022"
"137.10000","4.56748","9955.19531","0.04567","995.51953","-0.00022"
"137.40000","4.57734","9944.59961","0.04577","994.45996","-0.00020"
"137.70000","4.58741","9937.64062","0.04587","993.76404","-0.00021"
"138.00000","4.59749","9932.96289","0.04597","993.29626","-0.00022"
"138.30000","4.60740","9926.22559","0.04607","992.62256","-0.00021"
"138.60000","4.61730","9918.35938","0.04617","991.83594","-0.00020"
"138.90000","4.62739","9911.32227","0.04627","991.13220","-0.00022"
"139.20000","4.63728","9902.31641","0.04637","990.23163","-0.00023"
"139.50000","4.64746","9897.94824","0.04647","989.79480","-0.00020"
"139.80000","4.65735","9890.37793","0.04657","989.03778","-0.00021"
"140.10000","4.66746","9885.44629","0.04667","988.54462","-0.00023"
"140.40000","4.67743","9879.14062","0.04677","987.91406","-0.00022"
"140.70000","4.68741","9872.95996","0.04687","987.29602","-0.00020"
"141.00000","4.69723","9865.01758","0.04697","986.50177","-0.00021"
"141.30000","4.70738","9860.62988","0.04707","986.06299","-0.00023"
"141.60000","4.71739","9854.25879","0.04717","985.42590","-0.00022"
"141.90000","4.72749","9848.83105","0.04727","984.88312","-0.00019"
"142.20000","4.73739","9839.75781","0.04737","983.97577","-0.00021"
"142.50000","4.74753","9833.12402","0.04748","983.31238","-0.00023"
"142.80000","4.75734","9823.17480","0.04757","982.31750","-0.00021"
"143.10000","4.76733","9815.11426","0.04767","981.51141","-0.00019"
"143.40000","4.77731","9806.53809","0.04777","980.65381","-0.00022"
"143.70000","4.78735","9798.53906","0.04787","979.85388","-0.00023"
"144.00000","4.79740","9790.64160","0.04797","979.06415","-0.00020"
"144.30000","4.80746","9782.72363","0.04807","978.27234","-0.00020"
"144.60000","4.81736","9771.99316","0.04817","977.19934","-0.00023"
"144.90000","4.82745","9763.95801","0.04827","976.39581","-0.00022"
"145.20000","4.83742","9753.88867","0.04837","975.38885","-0.00020"
"145.50000","4.84732","9743.04102","0.04847","974.30408","-0.00022"
"145.80000","4.85731","9732.11133","0.04857","973.21112","-0.00023"
"146.10000","4.86736","9721.25488","0.04867","972.12549","-0.00021"
"146.40000","4.87748","9710.28223","0.04877","971.02820","-0.00020"
"146.70000","4.88739","9697.19629","0.04887","969.71960","-0.00024"
"147.00000","4.89746","9684.92090","0.04897","968.49207","-0.00022"
"147.30000","4.90744","9672.24707","0.04907","967.22473","-0.00019"
"147.60000","4.91737","9658.96289","0.04917","965.89630","-0.00020"
"147.90000","4.92733","9645.72754","0.04927","964.57275","-0.00024"
"148.20000","4.93731","9634.00977","0.04937","963.40100","-0.00022"
"148.50000","4.94734","9623.35547","0.04947","962.33557","-0.00018"
"148.80000","4.95751","9612.25586","0.04958","961.22559","-0.00020"
"149.10000","4.96740","9597.34473","0.04967","959.73450","-0.00024"
"149.40000","4.97744","9585.03809","0.04977","958.50378","-0.00022"
"149.70000","4.98742","9571.78027","0.04987","957.17804","-0.00019"
"150.00000","4.99735","9557.88965","0.04997","955.78894","-0.00022"
"150.30000","5.00726","9543.32910","0.05007","954.33289","-0.00024"
"150.60000","5.01734","9531.98340","0.05017","953.19836","-0.00020"
"150.90000","5.02735","9519.41699","0.05027","951.94171","-0.00020"
"151.20000","5.03746","9508.90137","0.05037","950.89014","-0.00023"
"151.50000","5.04738","9495.05176","0.05047","949.50519","-0.00024"
"151.80000","5.05753","9483.78125","0.05058","948.37811","-0.00019"
"152.10000","5.06736","9469.05273","0.05067","946.90527","-0.00022"
"152.40000","5.07738","9456.28223","0.05077","945.62823","-0.00023"
"152.70000","5.08730","9442.39160","0.05087","944.23914","-0.00021"
"153.00000","5.09725","9430.39062","0.05097","943.03906","-0.00019"
"153.30000","5.10742","9420.81836","0.05107","942.08185","-0.00022"
"153.60000","5.11755","9410.65820","0.05118","941.06580","-0.00023"
"153.90000","5.12741","9397.86328","0.05127","939.78632","-0.00020"
"154.20000","5.13753","9388.92871","0.05138","938.89288","-0.00020"
"154.50000","5.14738","9377.66699","0.05147","937.76672","-0.00023"
"154.80000","5.15725","9365.97949","0.05157","936.59796","-0.00023"
"155.10000","5.16731","9354.16504","0.05167","935.41650","-0.00019"
"155.40000","5.17741","9341.37891","0.05177","934.13788","-0.00020"
"155.70000","5.18747","9328.56738","0.05187","932.85675","-0.00023"
"156.00000","5.19741","9314.11426","0.05197","931.41144","-0.00022"
"156.30000","5.20747","9300.03809","0.05207","930.00378","-0.00019"
"156.60000","5.21741","9285.01172","0.05217","928.50116","-0.00021"
"156.90000","5.22737","9269.69336","0.05227","926.96936","-0.00023"
"157.20000","5.23735","9253.93164","0.05237","925.39319","-0.00021"
"157.50000","5.24729","9239.21875","0.05247","923.92188","-0.00019"
"157.80000","5.25731","9225.56641","0.05257","922.55664","-0.00022"
"158.10000","5.26751","9214.68457","0.05268","921.46844","-0.00023"
"158.40000","5.27734","9198.64258","0.05277","919.86426","-0.00021"
"158.70000","5.28754","9186.61328","0.05288","918.66132","-0.00023"
"159.00000","5.29760","9173.69434","0.05298","917.36945","-0.00021"
"159.30000","5.30733","9158.84473","0.05307","915.88446","-0.00022"
"159.60000","5.31730","9147.07715","0.05317","914.70770","-0.00020"
"159.90000","5.32732","9135.14746","0.05327","913.51477","-0.00019"
"160.20000","5.33726","9120.71875","0.05337","912.07190","-0.00023"
"160.50000","5.34748","9109.83105","0.05347","910.98309","-0.00021"
"160.80000","5.35757","9097.96777","0.05358","909.79675","-0.00021"
"161.10000","5.36748","9086.21484","0.05367","908.62146","-0.00020"
"161.40000","5.37743","9074.76562","0.05377","907.47656","-0.00023"
"161.70000","5.38735","9064.61523","0.05387","906.46155","-0.00020"
"162.00000","5.39722","9054.02344","0.05397","905.40234","-0.00021"
"162.30000","5.40728","9045.34570","0.05407","904.53455","-0.00021"
"162.60000","5.41759","9039.26758","0.05418","903.92676","-0.00022"
"162.90000","5.42737","9027.67578","0.05427","902.76758","-0.00020"
"163.20000","5.43737","9018.84570","0.05437","901.88458","-0.00021"
"163.50000","5.44744","9011.51562","0.05447","901.15155","-0.00023"
"163.80000","5.45735","9002.14062","0.05457","900.21405","-0.00021"
"164.10000","5.46730","8993.40137","0.05467","899.34015","-0.00019"
"164.40000","5.47737","8986.15820","0.05477","898.61584","-0.00016"
"164.70000","5.48726","8975.81543","0.05487","897.58154","-0.00024"
"165.00000","5.49750","8967.82520","0.05497","896.78253","-0.00027"
"165.30000","5.50735","8954.37109","0.05507","895.43713","-0.00021"
"165.60000","5.51741","8945.32617","0.05517","894.53259","-0.00017"
"165.90000","5.52747","8935.56543","0.05527","893.55652","-0.00020"
"166.20000","5.53753","8925.95410","0.05538","892.59540","-0.00024"
"166.50000","5.54723","8911.06250","0.05547","891.10626","-0.00022"
"166.80000","5.55731","8901.82129","0.05557","890.18213","-0.00019"
"167.10000","5.56730","8891.25195","0.05567","889.12518","-0.00021"
"167.40000","5.57744","8883.03320","0.05577","888.30334","-0.00022"
"167.70000","5.58742","8873.25684","0.05587","887.32568","-0.00022"
"168.00000","5.59760","8865.78320","0.05598","886.57831","-0.00021"
"168.30000","5.60736","8853.53418","0.05607","885.35339","-0.00021"
"168.60000","5.61736","8843.93945","0.05617","884.39392","-0.00021"
"168.90000","5.62726","8832.06836","0.05627","883.20685","-0.00022"
"169.20000","5.63731","8822.60840","0.05637","882.26086","-0.00021"
"169.50000","5.64738","8814.53125","0.05647","881.45312","-0.00021"
"169.80000","5.65759","8808.84570","0.05658","880.88458","-0.00021"
"170.10000","5.66733","8798.92969","0.05667","879.89294","-0.00022"
"170.40000","5.67753","8794.43555","0.05678","879.44354","-0.00020"
"170.70000","5.68735","8785.57031","0.05687","878.55701","-0.00021"
"171.00000","5.69730","8776.07715","0.05697","877.60773","-0.00022"
"171.30000","5.70727","8767.00977","0.05707","876.70099","-0.00021"
"171.60000","5.71736","8759.69043","0.05717","875.96906","-0.00019"
"171.90000","5.72735","8752.32031","0.05727","875.23206","-0.00021"
"172.20000","5.73740","8748.23730","0.05737","874.82373","-0.00023"
"172.50000","5.74732","8740.78125","0.05747","874.07812","-0.00021"
"172.80000","5.75750","8736.05371","0.05757","873.60535","-0.00019"
"173.10000","5.76743","8727.30176","0.05767","872.73016","-0.00022"
"173.40000","5.77734","8717.65039","0.05777","871.76501","-0.00022"
"173.70000","5.78732","8708.93555","0.05787","870.89355","-0.00021"
"174.00000","5.79725","8700.40234","0.05797","870.04022","-0.00020"
"174.30000","5.80740","8695.35449","0.05807","869.53546","-0.00022"
"174.60000","5.81742","8689.11523","0.05817","868.91150","-0.00023"
"174.89300","5.82726","8682.99902","0.05827","868.29993","-0.00021"