File: Tension/Section_1_Group3/sawdust_tension_per3.is_tens_RawData/Specimen_RawData_1.csv
Time,Extension,Load,Tensile strain (Extension),Axial Video,Tensile stress,Transverse Video
(s),(mm),(N),(mm/mm),(mm/mm),(MPa),(mm/mm)
"0.00000","74.96642","0.09311","0.00000","0.00002","0.00931","0.00001"
"0.20000","74.96825","3.94492","0.00002","0.00003","0.39449","0.00002"
"0.40000","74.97685","25.21080","0.00010","0.00004","2.52108","0.00000"
"0.60000","74.98376","41.66713","0.00017","0.00009","4.16671","-0.00004"
"0.80000","74.99033","56.89742","0.00024","0.00013","5.68974","-0.00013"
"1.00000","74.99693","71.60829","0.00031","0.00019","7.16083","-0.00020"
"1.20000","75.00376","86.72515","0.00037","0.00026","8.67251","-0.00028"
"1.40000","75.01020","100.53025","0.00044","0.00033","10.05303","-0.00031"
"1.60000","75.01697","115.06191","0.00051","0.00036","11.50619","-0.00033"
"1.80000","75.02367","129.04796","0.00057","0.00043","12.90480","-0.00033"
"2.00000","75.03051","143.39665","0.00064","0.00051","14.33967","-0.00032"
"2.20000","75.03706","156.82278","0.00071","0.00059","15.68228","-0.00031"
"2.40000","75.04363","170.22922","0.00077","0.00065","17.02292","-0.00029"
"2.60000","75.05035","183.84081","0.00084","0.00071","18.38408","-0.00029"
"2.80000","75.05684","196.56502","0.00090","0.00077","19.65650","-0.00022"
"3.00000","75.06375","210.32263","0.00097","0.00080","21.03226","-0.00017"
"3.20000","75.07023","222.74594","0.00104","0.00083","22.27459","-0.00017"
"3.40000","75.07703","235.71884","0.00111","0.00081","23.57188","-0.00012"
"3.60000","75.08382","248.63097","0.00117","0.00080","24.86310","-0.00010"
"3.80000","75.09039","260.64548","0.00124","0.00083","26.06455","-0.00007"
"4.00000","75.09697","272.62952","0.00131","0.00086","27.26295","-0.00006"
"4.20000","75.10357","284.30139","0.00137","0.00088","28.43014","-0.00009"
"4.40000","75.11044","296.68698","0.00144","0.00092","29.66870","-0.00014"
"4.60000","75.11694","307.97076","0.00151","0.00096","30.79708","-0.00017"
"4.80000","75.12363","319.36423","0.00157","0.00103","31.93642","-0.00024"
"5.00000","75.13039","330.84448","0.00164","0.00107","33.08445","-0.00028"
"5.20000","75.13692","341.45779","0.00170","0.00113","34.14578","-0.00038"
"5.40000","75.14371","352.64621","0.00177","0.00118","35.26462","-0.00038"
"5.60000","75.15034","362.88104","0.00184","0.00124","36.28811","-0.00043"
"5.80000","75.15707","373.20804","0.00191","0.00129","37.32080","-0.00045"
"6.00000","75.16367","382.97278","0.00197","0.00133","38.29728","-0.00031"
"6.20000","75.17031","392.59628","0.00204","0.00135","39.25963","-0.00025"
"6.40000","75.17697","402.03006","0.00211","0.00138","40.20301","-0.00017"
"6.60000","75.18353","410.92398","0.00217","0.00133","41.09240","-0.00024"
"6.80000","75.19038","420.22107","0.00224","0.00133","42.02211","-0.00039"
"7.00000","75.19701","428.75345","0.00231","0.00127","42.87534","-0.00052"
"7.20000","75.20364","437.25864","0.00237","0.00124","43.72586","-0.00052"
"7.40000","75.21046","446.43213","0.00244","0.00124","44.64321","-0.00040"
"7.60000","75.21694","454.90698","0.00251","0.00125","45.49070","-0.00029"
"7.80000","75.22362","463.99060","0.00257","0.00127","46.39906","-0.00020"
"8.00000","75.23025","472.72174","0.00264","0.00128","47.27217","-0.00013"
"8.20000","75.23704","481.78598","0.00271","0.00126","48.17860","-0.00011"
"8.40000","75.24370","490.57819","0.00277","0.00124","49.05782","-0.00017"
"8.60000","75.25025","498.95807","0.00284","0.00130","49.89581","-0.00025"
"8.80000","75.25708","507.82297","0.00291","0.00132","50.78230","-0.00031"
"9.00000","75.26360","515.89337","0.00297","0.00130","51.58934","-0.00031"
"9.20000","75.27043","524.75726","0.00304","0.00136","52.47573","-0.00034"
"9.40000","75.27700","532.78442","0.00311","0.00141","53.27844","-0.00035"
"9.60000","75.28360","540.74878","0.00317","0.00146","54.07488","-0.00031"
"9.80000","75.29039","549.36554","0.00324","0.00153","54.93655","-0.00028"
"10.00000","75.29694","556.99408","0.00331","0.00160","55.69941","-0.00022"
"10.20000","75.30368","564.90179","0.00337","0.00169","56.49018","-0.00020"
"10.40000","75.31021","572.57385","0.00344","0.00174","57.25739","-0.00016"
"10.60000","75.31715","580.96796","0.00351","0.00178","58.09679","-0.00010"
"10.80000","75.32370","588.42194","0.00357","0.00181","58.84219","-0.00014"
"11.00000","75.33031","595.86584","0.00364","0.00183","59.58659","-0.00024"
"11.20000","75.33702","603.67456","0.00371","0.00184","60.36745","-0.00028"
"11.40000","75.34354","610.80139","0.00377","0.00185","61.08014","-0.00044"
"11.60000","75.35033","618.61926","0.00384","0.00184","61.86193","-0.00052"
"11.80000","75.35699","625.79193","0.00391","0.00185","62.57919","-0.00052"
"12.00000","75.36369","633.23059","0.00397","0.00184","63.32306","-0.00057"
"12.20000","75.37036","640.24219","0.00404","0.00185","64.02422","-0.00059"
"12.40000","75.37698","647.25537","0.00411","0.00186","64.72554","-0.00048"
"12.60000","75.38367","654.35168","0.00417","0.00193","65.43517","-0.00042"
"12.80000","75.39027","661.20996","0.00424","0.00198","66.12099","-0.00038"
"13.00000","75.39709","668.35138","0.00431","0.00203","66.83514","-0.00038"
"13.20000","75.40365","674.75757","0.00437","0.00205","67.47575","-0.00035"
"13.40000","75.41024","681.28345","0.00444","0.00206","68.12834","-0.00035"
"13.60000","75.41708","688.32355","0.00451","0.00204","68.83235","-0.00046"
"13.80000","75.42358","694.57300","0.00457","0.00209","69.45730","-0.00053"
"14.00000","75.43030","701.13623","0.00464","0.00213","70.11362","-0.00063"
"14.20000","75.43700","707.73645","0.00471","0.00215","70.77364","-0.00063"
"14.40000","75.44377","714.39819","0.00477","0.00219","71.43982","-0.00061"
"14.60000","75.45033","720.74945","0.00484","0.00220","72.07494","-0.00062"
"14.80000","75.45695","726.98724","0.00491","0.00225","72.69872","-0.00066"
"15.00000","75.46364","733.44275","0.00497","0.00227","73.34428","-0.00062"
"15.20000","75.47016","739.42993","0.00504","0.00231","73.94299","-0.00059"
"15.40000","75.47707","746.43463","0.00511","0.00235","74.64346","-0.00052"
"15.60000","75.48368","752.55066","0.00517","0.00237","75.25507","-0.00048"
"15.80000","75.49033","758.60687","0.00524","0.00240","75.86069","-0.00043"
"16.00000","75.49713","765.34650","0.00531","0.00241","76.53465","-0.00045"
"16.20000","75.50359","771.15448","0.00537","0.00245","77.11545","-0.00054"
"16.40000","75.51022","777.62939","0.00544","0.00247","77.76294","-0.00058"
"16.60000","75.51686","783.96222","0.00550","0.00250","78.39622","-0.00059"
"16.80000","75.52379","790.72174","0.00557","0.00248","79.07217","-0.00061"
"17.00000","75.53028","796.49231","0.00564","0.00249","79.64923","-0.00066"
"17.20000","75.53698","802.55243","0.00571","0.00245","80.25524","-0.00073"
"17.40000","75.54374","809.00134","0.00577","0.00251","80.90013","-0.00073"
"17.60000","75.55024","814.45490","0.00584","0.00253","81.44549","-0.00069"
"17.80000","75.55704","820.82648","0.00591","0.00254","82.08265","-0.00069"
"18.00000","75.56364","826.57562","0.00597","0.00254","82.65756","-0.00066"
"18.20000","75.57036","832.65027","0.00604","0.00258","83.26503","-0.00057"
"18.40000","75.57702","838.49347","0.00611","0.00258","83.84935","-0.00051"
"18.60000","75.58361","844.23761","0.00617","0.00258","84.42376","-0.00053"
"18.80000","75.59026","850.01056","0.00624","0.00259","85.00105","-0.00045"
"19.00000","75.59689","855.79211","0.00630","0.00260","85.57921","-0.00046"
"19.20000","75.60377","862.26135","0.00637","0.00258","86.22614","-0.00051"
"19.40000","75.61030","867.66473","0.00644","0.00259","86.76647","-0.00051"
"19.60000","75.61697","873.28247","0.00651","0.00263","87.32825","-0.00055"
"19.80000","75.62376","879.14111","0.00657","0.00266","87.91411","-0.00055"
"20.00000","75.63026","884.38867","0.00664","0.00268","88.43887","-0.00062"
"20.20000","75.63689","889.97980","0.00670","0.00271","88.99798","-0.00066"
"20.40000","75.64361","895.71692","0.00677","0.00269","89.57169","-0.00066"
"20.60000","75.65036","901.45227","0.00684","0.00271","90.14523","-0.00066"
"20.80000","75.65707","906.93182","0.00691","0.00276","90.69318","-0.00059"
"21.00000","75.66361","912.06329","0.00697","0.00279","91.20633","-0.00059"
"21.20000","75.67037","917.65625","0.00704","0.00282","91.76562","-0.00047"
"21.40000","75.67689","922.91876","0.00710","0.00280","92.29188","-0.00042"
"21.60000","75.68376","928.87878","0.00717","0.00282","92.88788","-0.00038"
"21.80000","75.69031","934.09064","0.00724","0.00283","93.40907","-0.00042"
"22.00000","75.69691","939.31586","0.00730","0.00283","93.93159","-0.00039"
"22.20000","75.70375","945.23865","0.00737","0.00281","94.52386","-0.00046"
"22.40000","75.71025","950.03259","0.00744","0.00283","95.00326","-0.00051"
"22.60000","75.71697","955.62433","0.00751","0.00281","95.56243","-0.00055"
"22.80000","75.72356","960.99597","0.00757","0.00276","96.09959","-0.00053"
"23.00000","75.73043","966.82373","0.00764","0.00278","96.68237","-0.00059"
"23.20000","75.73701","971.92310","0.00771","0.00280","97.19231","-0.00064"
"23.40000","75.74358","976.62628","0.00777","0.00277","97.66263","-0.00063"
"23.60000","75.75040","981.88885","0.00784","0.00277","98.18889","-0.00065"
"23.80000","75.75684","986.29993","0.00790","0.00280","98.62999","-0.00070"
"24.00000","75.76368","991.77399","0.00797","0.00287","99.17740","-0.00070"
"24.20000","75.77024","996.89215","0.00804","0.00289","99.68922","-0.00061"
"24.40000","75.77705","1002.44861","0.00811","0.00293","100.24486","-0.00056"
"24.60000","75.78365","1008.00647","0.00817","0.00295","100.80064","-0.00053"
"24.80000","75.79031","1013.26971","0.00824","0.00298","101.32697","-0.00045"
"25.00000","75.79697","1018.88812","0.00831","0.00301","101.88881","-0.00047"
"25.20000","75.80357","1024.14624","0.00837","0.00305","102.41463","-0.00042"
"25.40000","75.81046","1030.20239","0.00844","0.00310","103.02024","-0.00045"
"25.60000","75.81695","1035.36292","0.00851","0.00310","103.53629","-0.00044"
"25.80000","75.82362","1040.95154","0.00857","0.00313","104.09515","-0.00044"
"26.00000","75.83035","1046.86267","0.00864","0.00314","104.68626","-0.00046"
"26.20000","75.83694","1052.04785","0.00871","0.00318","105.20479","-0.00052"
"26.40000","75.84361","1057.70557","0.00877","0.00319","105.77055","-0.00055"
"26.60000","75.85031","1063.37854","0.00884","0.00320","106.33785","-0.00055"
"26.80000","75.85703","1068.69568","0.00891","0.00322","106.86957","-0.00057"
"27.00000","75.86369","1074.26367","0.00897","0.00319","107.42637","-0.00064"
"27.20000","75.87031","1079.40027","0.00904","0.00326","107.94003","-0.00070"
"27.40000","75.87700","1084.66504","0.00911","0.00330","108.46651","-0.00071"
"27.60000","75.88358","1089.80457","0.00917","0.00331","108.98045","-0.00076"
"27.80000","75.89037","1095.31213","0.00924","0.00334","109.53121","-0.00076"
"28.00000","75.89700","1100.44641","0.00931","0.00333","110.04464","-0.00072"
"28.20000","75.90358","1105.43311","0.00937","0.00336","110.54331","-0.00069"
"28.40000","75.91040","1111.10999","0.00944","0.00343","111.11100","-0.00063"
"28.60000","75.91693","1116.17175","0.00951","0.00345","111.61717","-0.00063"
"28.80000","75.92367","1121.48157","0.00957","0.00347","112.14816","-0.00062"
"29.00000","75.93031","1126.91553","0.00964","0.00349","112.69155","-0.00055"
"29.20000","75.93711","1132.40234","0.00971","0.00350","113.24023","-0.00050"
"29.40000","75.94368","1137.47290","0.00977","0.00354","113.74729","-0.00049"
"29.60000","75.95025","1142.50635","0.00984","0.00351","114.25063","-0.00055"
"29.80000","75.95712","1148.41565","0.00991","0.00356","114.84157","-0.00057"
"30.00000","75.96352","1153.10681","0.00997","0.00354","115.31068","-0.00063"
"30.20000","75.97032","1158.69812","0.01004","0.00361","115.86981","-0.00066"
"30.40000","75.97695","1163.81873","0.01011","0.00367","116.38187","-0.00069"
"30.60000","75.98369","1168.84424","0.01017","0.00370","116.88442","-0.00073"
"30.80000","75.99044","1174.27820","0.01024","0.00371","117.42782","-0.00073"
"31.00000","75.99697","1179.11133","0.01031","0.00373","117.91113","-0.00079"
"31.20000","76.00362","1184.33057","0.01037","0.00376","118.43306","-0.00080"
"31.40000","76.01019","1189.45898","0.01044","0.00380","118.94590","-0.00084"
"31.60000","76.01719","1195.20984","0.01051","0.00387","119.52098","-0.00087"
"31.80000","76.02358","1199.73621","0.01057","0.00389","119.97362","-0.00079"
"32.00000","76.03025","1204.70361","0.01064","0.00391","120.47036","-0.00080"
"32.20000","76.03706","1210.38867","0.01071","0.00393","121.03886","-0.00082"
"32.40000","76.04357","1215.02478","0.01077","0.00398","121.50248","-0.00073"
"32.60000","76.05035","1220.65527","0.01084","0.00397","122.06553","-0.00074"
"32.80000","76.05696","1225.68066","0.01091","0.00396","122.56807","-0.00070"
"33.00000","76.06377","1231.11108","0.01097","0.00398","123.11111","-0.00066"
"33.20000","76.07034","1236.29846","0.01104","0.00399","123.62984","-0.00057"
"33.40000","76.07699","1241.37024","0.01111","0.00397","124.13702","-0.00061"
"33.60000","76.08359","1246.07361","0.01117","0.00395","124.60736","-0.00064"
"33.80000","76.09026","1251.33569","0.01124","0.00392","125.13357","-0.00061"
"34.00000","76.09704","1256.86182","0.01131","0.00389","125.68618","-0.00061"
"34.20000","76.10365","1261.88159","0.01137","0.00389","126.18816","-0.00072"
"34.40000","76.11032","1266.90527","0.01144","0.00391","126.69053","-0.00072"
"34.60000","76.11713","1272.32959","0.01151","0.00392","127.23296","-0.00073"
"34.80000","76.12363","1277.06689","0.01157","0.00395","127.70669","-0.00069"
"35.00000","76.13023","1282.20752","0.01164","0.00394","128.22075","-0.00075"
"35.20000","76.13697","1287.55725","0.01171","0.00400","128.75572","-0.00082"
"35.40000","76.14374","1293.02576","0.01177","0.00405","129.30258","-0.00086"
"35.60000","76.15031","1297.98840","0.01184","0.00407","129.79884","-0.00090"
"35.80000","76.15689","1302.75061","0.01190","0.00411","130.27505","-0.00084"
"36.00000","76.16375","1308.29858","0.01197","0.00415","130.82986","-0.00087"
"36.20000","76.17028","1313.15027","0.01204","0.00421","131.31503","-0.00078"
"36.40000","76.17709","1318.60071","0.01211","0.00421","131.86008","-0.00075"
"36.60000","76.18368","1323.46924","0.01217","0.00422","132.34692","-0.00069"
"36.80000","76.19035","1328.17322","0.01224","0.00426","132.81732","-0.00069"
"37.00000","76.19712","1333.49121","0.01231","0.00427","133.34912","-0.00061"
"37.20000","76.20355","1337.88171","0.01237","0.00429","133.78818","-0.00059"
"37.40000","76.21024","1342.87817","0.01244","0.00429","134.28781","-0.00060"
"37.60000","76.21680","1347.41650","0.01250","0.00431","134.74165","-0.00055"
"37.80000","76.22384","1353.08667","0.01257","0.00427","135.30867","-0.00052"
"38.00000","76.23036","1357.84253","0.01264","0.00424","135.78426","-0.00063"
"38.20000","76.23698","1362.51355","0.01271","0.00424","136.25136","-0.00062"
"38.40000","76.24380","1367.76221","0.01277","0.00423","136.77621","-0.00066"
"38.60000","76.25027","1372.11279","0.01284","0.00426","137.21127","-0.00070"
"38.80000","76.25697","1377.02637","0.01291","0.00428","137.70264","-0.00073"
"39.00000","76.26358","1382.02063","0.01297","0.00431","138.20206","-0.00076"
"39.20000","76.27036","1387.09485","0.01304","0.00433","138.70949","-0.00076"
"39.40000","76.27698","1391.85779","0.01311","0.00434","139.18578","-0.00081"
"39.60000","76.28365","1396.62244","0.01317","0.00439","139.66225","-0.00083"
"39.80000","76.29037","1401.66443","0.01324","0.00441","140.16644","-0.00087"
"40.00000","76.29693","1406.04956","0.01331","0.00446","140.60495","-0.00083"
"40.20000","76.30386","1411.49182","0.01337","0.00449","141.14919","-0.00080"
"40.40000","76.31031","1415.93616","0.01344","0.00457","141.59361","-0.00076"
"40.60000","76.31696","1420.77173","0.01351","0.00458","142.07718","-0.00073"
"40.80000","76.32365","1425.81885","0.01357","0.00460","142.58188","-0.00069"
"41.00000","76.33028","1430.45557","0.01364","0.00464","143.04556","-0.00063"
"41.20000","76.33692","1435.18945","0.01370","0.00467","143.51895","-0.00068"
"41.40000","76.34365","1440.15100","0.01377","0.00466","144.01511","-0.00067"
"41.60000","76.35045","1445.26379","0.01384","0.00470","144.52638","-0.00065"
"41.80000","76.35704","1449.71204","0.01391","0.00473","144.97121","-0.00068"
"42.00000","76.36363","1454.23193","0.01397","0.00473","145.42319","-0.00068"
"42.20000","76.37035","1459.14722","0.01404","0.00470","145.91472","-0.00067"
"42.40000","76.37692","1463.58252","0.01410","0.00468","146.35825","-0.00069"
"42.60000","76.38367","1468.56201","0.01417","0.00467","146.85620","-0.00076"
"42.80000","76.39030","1473.01379","0.01424","0.00466","147.30138","-0.00077"
"43.00000","76.39693","1477.45959","0.01431","0.00470","147.74596","-0.00081"
"43.20000","76.40372","1482.57092","0.01437","0.00467","148.25710","-0.00089"
"43.40000","76.41035","1487.14307","0.01444","0.00469","148.71431","-0.00095"
"43.60000","76.41708","1491.86218","0.01451","0.00470","149.18622","-0.00096"
"43.80000","76.42361","1496.04041","0.01457","0.00472","149.60403","-0.00094"
"44.00000","76.43047","1501.10254","0.01464","0.00476","150.11026","-0.00097"
"44.20000","76.43700","1505.41797","0.01471","0.00479","150.54179","-0.00099"
"44.40000","76.44355","1509.34106","0.01477","0.00482","150.93411","-0.00097"
"44.60000","76.45039","1514.27380","0.01484","0.00485","151.42738","-0.00096"
"44.80000","76.45685","1517.26953","0.01490","0.00488","151.72696","-0.00093"
"45.00000","76.46368","1521.87231","0.01497","0.00487","152.18723","-0.00088"
"45.20000","76.47037","1526.09143","0.01504","0.00487","152.60915","-0.00087"
"45.40000","76.47716","1530.70435","0.01511","0.00486","153.07043","-0.00088"
"45.60000","76.48373","1534.78967","0.01517","0.00491","153.47897","-0.00091"
"45.80000","76.49030","1539.08618","0.01524","0.00497","153.90862","-0.00090"
"46.00000","76.49696","1543.35437","0.01531","0.00496","154.33543","-0.00091"
"46.20000","76.50349","1547.07300","0.01537","0.00495","154.70731","-0.00099"
"46.40000","76.51044","1552.27026","0.01544","0.00496","155.22702","-0.00101"
"46.60000","76.51694","1556.16968","0.01551","0.00491","155.61697","-0.00101"
"46.80000","76.52366","1560.55225","0.01557","0.00488","156.05522","-0.00107"
"47.00000","76.53046","1565.45789","0.01564","0.00487","156.54579","-0.00114"
"47.20000","76.53699","1569.41772","0.01571","0.00486","156.94177","-0.00117"
"47.40000","76.54366","1573.84949","0.01577","0.00487","157.38495","-0.00124"
"47.60000","76.55029","1578.28943","0.01584","0.00490","157.82895","-0.00129"
"47.80000","76.55709","1582.98877","0.01591","0.00491","158.29887","-0.00129"
"48.00000","76.56363","1586.96826","0.01597","0.00493","158.69682","-0.00132"
"48.20000","76.57027","1591.46802","0.01604","0.00493","159.14680","-0.00132"
"48.40000","76.57700","1596.01624","0.01611","0.00492","159.60162","-0.00132"
"48.60000","76.58359","1600.18835","0.01617","0.00491","160.01883","-0.00134"
"48.80000","76.59043","1605.00684","0.01624","0.00494","160.50069","-0.00131"
"49.00000","76.59705","1609.33008","0.01631","0.00497","160.93301","-0.00131"
"49.20000","76.60369","1613.58655","0.01637","0.00495","161.35866","-0.00126"
"49.40000","76.61037","1618.25977","0.01644","0.00498","161.82597","-0.00127"
"49.60000","76.61696","1622.42981","0.01651","0.00498","162.24298","-0.00128"
"49.80000","76.62357","1626.62915","0.01657","0.00501","162.66292","-0.00129"
"50.00000","76.63025","1631.06604","0.01664","0.00503","163.10660","-0.00133"
"50.20000","76.63706","1635.71130","0.01671","0.00505","163.57114","-0.00134"
"50.40000","76.64369","1639.78430","0.01677","0.00503","163.97842","-0.00134"
"50.60000","76.65031","1643.99182","0.01684","0.00503","164.39919","-0.00143"
"50.80000","76.65713","1648.86951","0.01691","0.00506","164.88695","-0.00145"
"51.00000","76.66359","1652.44153","0.01697","0.00507","165.24416","-0.00146"
"51.20000","76.67033","1657.02051","0.01704","0.00508","165.70206","-0.00153"
"51.40000","76.67693","1661.43811","0.01711","0.00508","166.14381","-0.00155"
"51.60000","76.68366","1665.80383","0.01717","0.00508","166.58038","-0.00156"
"51.80000","76.69039","1670.68579","0.01724","0.00511","167.06857","-0.00158"
"52.00000","76.69694","1674.84204","0.01731","0.00510","167.48421","-0.00160"
"52.20000","76.70367","1679.58679","0.01737","0.00513","167.95868","-0.00166"
"52.40000","76.71024","1683.92322","0.01744","0.00517","168.39232","-0.00163"
"52.60000","76.71714","1689.04529","0.01751","0.00517","168.90453","-0.00159"
"52.80000","76.72370","1693.26379","0.01757","0.00521","169.32639","-0.00157"
"53.00000","76.73029","1697.57275","0.01764","0.00521","169.75728","-0.00152"
"53.20000","76.73707","1702.49963","0.01771","0.00524","170.24997","-0.00145"
"53.40000","76.74357","1706.53870","0.01777","0.00526","170.65387","-0.00142"
"53.60000","76.75032","1711.33875","0.01784","0.00529","171.13388","-0.00142"
"53.80000","76.75692","1715.79834","0.01790","0.00530","171.57983","-0.00139"
"54.00000","76.76378","1720.83606","0.01797","0.00533","172.08360","-0.00132"
"54.20000","76.77036","1725.21082","0.01804","0.00540","172.52109","-0.00128"
"54.40000","76.77700","1729.53845","0.01811","0.00542","172.95384","-0.00134"
"54.60000","76.78370","1733.95959","0.01817","0.00545","173.39597","-0.00135"
"54.80000","76.79023","1738.04150","0.01824","0.00548","173.80415","-0.00136"
"55.00000","76.79701","1742.53174","0.01831","0.00552","174.25317","-0.00142"
"55.20000","76.80363","1746.32336","0.01837","0.00558","174.63234","-0.00144"
"55.40000","76.81031","1750.63330","0.01844","0.00561","175.06332","-0.00152"
"55.60000","76.81704","1755.17737","0.01851","0.00562","175.51773","-0.00154"
"55.80000","76.82365","1759.45068","0.01857","0.00562","175.94507","-0.00149"
"56.00000","76.83030","1763.79016","0.01864","0.00565","176.37901","-0.00151"
"56.20000","76.83696","1768.08215","0.01871","0.00570","176.80821","-0.00137"
"56.40000","76.84377","1773.10461","0.01877","0.00576","177.31046","-0.00139"
"56.60000","76.85028","1776.23779","0.01884","0.00577","177.62378","-0.00136"
"56.80000","76.85690","1779.76550","0.01890","0.00580","177.97655","-0.00139"
"57.00000","76.86372","1784.31128","0.01897","0.00580","178.43112","-0.00131"
"57.20000","76.87025","1788.07410","0.01904","0.00583","178.80740","-0.00132"
"57.40000","76.87700","1792.34131","0.01911","0.00584","179.23413","-0.00129"
"57.60000","76.88367","1796.51196","0.01917","0.00587","179.65120","-0.00123"
"57.80000","76.89037","1800.89490","0.01924","0.00589","180.08949","-0.00114"
"58.00000","76.89701","1805.22375","0.01931","0.00586","180.52237","-0.00113"
"58.20000","76.90364","1809.26953","0.01937","0.00591","180.92696","-0.00110"
"58.40000","76.91029","1813.49292","0.01944","0.00592","181.34929","-0.00109"
"58.60000","76.91685","1817.50342","0.01950","0.00592","181.75034","-0.00115"
"58.80000","76.92373","1822.19617","0.01957","0.00594","182.21962","-0.00111"
"59.00000","76.93034","1826.35767","0.01964","0.00599","182.63577","-0.00120"
"59.20000","76.93695","1830.08093","0.01971","0.00604","183.00809","-0.00123"
"59.40000","76.94381","1834.71521","0.01977","0.00606","183.47153","-0.00129"
"59.60000","76.95025","1838.16968","0.01984","0.00609","183.81697","-0.00139"
"59.80000","76.95694","1842.39966","0.01991","0.00610","184.23996","-0.00150"
"60.00000","76.96360","1846.87061","0.01997","0.00615","184.68706","-0.00152"
"60.20000","76.97041","1851.43506","0.02004","0.00620","185.14351","-0.00146"
"60.40000","76.97697","1855.65002","0.02011","0.00623","185.56500","-0.00149"
"60.60000","76.98363","1860.07971","0.02017","0.00624","186.00797","-0.00146"
"60.80000","76.99039","1864.86951","0.02024","0.00627","186.48695","-0.00151"
"61.00000","76.99686","1868.86194","0.02030","0.00630","186.88620","-0.00147"
"61.20000","77.00375","1873.78247","0.02037","0.00633","187.37825","-0.00146"
"61.40000","77.01035","1877.95801","0.02044","0.00635","187.79581","-0.00149"
"61.60000","77.01699","1881.55664","0.02051","0.00639","188.15567","-0.00142"
"61.80000","77.02371","1885.61157","0.02057","0.00641","188.56116","-0.00143"
"62.00000","77.03028","1889.07715","0.02064","0.00641","188.90771","-0.00136"
"62.20000","77.03691","1892.84753","0.02070","0.00639","189.28476","-0.00133"
"62.40000","77.04359","1896.95288","0.02077","0.00635","189.69528","-0.00134"
"62.60000","77.05046","1901.28052","0.02084","0.00636","190.12805","-0.00135"
"62.80000","77.05699","1904.82153","0.02091","0.00637","190.48215","-0.00129"
"63.00000","77.06361","1908.52075","0.02097","0.00634","190.85208","-0.00135"
"63.20000","77.07039","1912.79541","0.02104","0.00633","191.27954","-0.00132"
"63.40000","77.07693","1915.77783","0.02111","0.00633","191.57779","-0.00132"
"63.60000","77.08365","1918.73035","0.02117","0.00633","191.87303","-0.00135"
"63.80000","77.09033","1921.88586","0.02124","0.00630","192.18858","-0.00142"
"64.00000","77.09699","1924.10669","0.02131","0.00630","192.41068","-0.00141"
"64.20000","77.10373","1927.17554","0.02137","0.00629","192.71756","-0.00142"
"64.40000","77.11027","1930.11646","0.02144","0.00634","193.01164","-0.00145"
"64.60000","77.11702","1933.80566","0.02151","0.00633","193.38057","-0.00147"
"64.80000","77.12354","1936.85278","0.02157","0.00638","193.68527","-0.00150"
"65.00000","77.13046","1940.75049","0.02164","0.00636","194.07504","-0.00159"
"65.20000","77.13699","1944.05750","0.02171","0.00640","194.40575","-0.00160"
"65.40000","77.14356","1946.96301","0.02177","0.00645","194.69630","-0.00159"
"65.60000","77.15039","1949.03516","0.02184","0.00650","194.90352","-0.00157"
"65.80000","77.15687","1950.75354","0.02190","0.00654","195.07535","-0.00163"
"66.00000","77.16364","1952.25647","0.02197","0.00651","195.22565","-0.00160"
"66.20000","77.17027","1954.99377","0.02204","0.00655","195.49937","-0.00160"
"66.40000","77.17711","1958.02063","0.02211","0.00657","195.80206","-0.00160"
"66.60000","77.18372","1960.76477","0.02217","0.00657","196.07648","-0.00161"
"66.80000","77.19024","1962.59338","0.02224","0.00658","196.25934","-0.00162"
"67.00000","77.19701","1963.29565","0.02231","0.00662","196.32956","-0.00160"
"67.20000","77.20349","1963.41968","0.02237","0.00661","196.34196","-0.00156"
"67.40000","77.21037","1965.65002","0.02244","0.00661","196.56500","-0.00156"
"67.60000","77.21695","1967.31067","0.02251","0.00662","196.73106","-0.00155"
"67.80000","77.22373","1968.85205","0.02257","0.00664","196.88521","-0.00155"
"68.00000","77.23035","1969.73389","0.02264","0.00662","196.97339","-0.00151"
"68.20000","77.23696","1970.60461","0.02271","0.00657","197.06046","-0.00142"
"68.40000","77.24361","1970.08630","0.02277","0.00660","197.00864","-0.00142"
"68.60000","77.25022","1971.08350","0.02284","0.00661","197.10835","-0.00140"
"68.80000","77.25713","1972.54285","0.02291","0.00664","197.25429","-0.00142"
"69.00000","77.26363","1971.95947","0.02297","0.00662","197.19595","-0.00139"
"69.20000","77.27028","1971.47632","0.02304","0.00659","197.14763","-0.00140"
"69.40000","77.27702","1971.75012","0.02311","0.00658","197.17502","-0.00142"
"69.60000","77.28362","1972.07776","0.02317","0.00654","197.20778","-0.00144"
"69.80000","77.29030","1972.67664","0.02324","0.00654","197.26767","-0.00140"
"70.00000","77.29698","1972.75562","0.02331","0.00657","197.27556","-0.00142"
"70.20000","77.30368","1970.07056","0.02337","0.00656","197.00705","-0.00139"
"70.40000","77.31040","1967.25574","0.02344","0.00658","196.72557","-0.00142"
"70.60000","77.31697","1961.69800","0.02351","0.00658","196.16980","-0.00143"
"70.80000","77.32361","1952.51758","0.02357","0.00655","195.25175","-0.00139"
"71.00000","77.33024","1927.64734","0.02364","0.00655","192.76474","-0.00138"
"71.20000","77.33706","1833.60730","0.02371","0.00655","183.36073","-0.00136"
"71.21000","77.33740","1543.46033","0.02371","0.00653","154.34604","-0.00136"
"71.21700","77.33763","1250.06482","0.02371","0.00622","125.00648","-0.00134"
"71.22000","77.33774","1124.32263","0.02371","0.00596","112.43227","-0.00133"