File: Tension/Section_1_Group_4/3_days/Sample_9_3_days_tension.is_tens_RawData/Specimen_RawData_1.csv
Time,Extension,Load,Tensile strain (Extension),Axial Video,Tensile stress,Transverse Video
(s),(mm),(N),(mm/mm),(mm/mm),(MPa),(mm/mm)
"0.00000","0.00000","-0.43930","0.00000","0.00001","-0.04393","-0.00005"
"0.20000","0.00178","7.09371","0.00002","0.00001","0.70937","-0.00001"
"0.40000","0.01054","49.51331","0.00011","0.00004","4.95133","-0.00005"
"0.60000","0.01731","79.86638","0.00017","0.00013","7.98664","-0.00002"
"0.80000","0.02391","106.17488","0.00024","0.00016","10.61749","-0.00005"
"1.00000","0.03068","131.50816","0.00031","0.00018","13.15082","-0.00010"
"1.20000","0.03735","156.13295","0.00037","0.00018","15.61329","-0.00016"
"1.40000","0.04393","183.98416","0.00044","0.00020","18.39842","-0.00015"
"1.60000","0.05070","212.62819","0.00051","0.00024","21.26282","-0.00015"
"1.80000","0.05726","239.73021","0.00057","0.00028","23.97302","-0.00021"
"2.00000","0.06411","267.69125","0.00064","0.00033","26.76912","-0.00021"
"2.20000","0.07062","293.64706","0.00071","0.00037","29.36471","-0.00015"
"2.40000","0.07730","320.10284","0.00077","0.00041","32.01028","-0.00016"
"2.60000","0.08408","346.70654","0.00084","0.00044","34.67065","-0.00020"
"2.80000","0.09059","371.69318","0.00091","0.00048","37.16932","-0.00020"
"3.00000","0.09728","397.15250","0.00097","0.00052","39.71525","-0.00020"
"3.20000","0.10392","422.08972","0.00104","0.00056","42.20897","-0.00021"
"3.40000","0.11078","447.41776","0.00111","0.00061","44.74178","-0.00021"
"3.60000","0.11734","471.08307","0.00117","0.00065","47.10831","-0.00021"
"3.80000","0.12399","494.75607","0.00124","0.00069","49.47561","-0.00021"
"4.00000","0.13074","518.65540","0.00131","0.00073","51.86554","-0.00021"
"4.20000","0.13723","540.93140","0.00137","0.00076","54.09314","-0.00026"
"4.40000","0.14402","564.48926","0.00144","0.00079","56.44893","-0.00026"
"4.60000","0.15060","586.43903","0.00151","0.00085","58.64390","-0.00031"
"4.80000","0.15728","608.64282","0.00157","0.00088","60.86428","-0.00031"
"5.00000","0.16406","630.87402","0.00164","0.00090","63.08740","-0.00029"
"5.20000","0.17066","652.00763","0.00171","0.00093","65.20076","-0.00026"
"5.40000","0.17732","673.09412","0.00177","0.00097","67.30941","-0.00026"
"5.60000","0.18394","693.67242","0.00184","0.00099","69.36724","-0.00026"
"5.80000","0.19074","714.83661","0.00191","0.00101","71.48366","-0.00026"
"6.00000","0.19729","734.59863","0.00197","0.00105","73.45986","-0.00025"
"6.20000","0.20391","754.23480","0.00204","0.00108","75.42348","-0.00026"
"6.40000","0.21076","774.59833","0.00211","0.00111","77.45983","-0.00026"
"6.60000","0.21723","792.97321","0.00217","0.00113","79.29732","-0.00026"
"6.80000","0.22399","812.54059","0.00224","0.00117","81.25406","-0.00031"
"7.00000","0.23068","831.56366","0.00231","0.00120","83.15636","-0.00031"
"7.20000","0.23737","849.89014","0.00237","0.00123","84.98901","-0.00036"
"7.40000","0.24402","867.67273","0.00244","0.00126","86.76727","-0.00036"
"7.60000","0.25060","885.12421","0.00251","0.00129","88.51242","-0.00036"
"7.80000","0.25734","903.20764","0.00257","0.00131","90.32076","-0.00041"
"8.00000","0.26384","919.94855","0.00264","0.00135","91.99486","-0.00040"
"8.20000","0.27073","938.18939","0.00271","0.00137","93.81894","-0.00041"
"8.40000","0.27729","954.62964","0.00277","0.00140","95.46297","-0.00036"
"8.60000","0.28394","971.09760","0.00284","0.00142","97.10976","-0.00036"
"8.80000","0.29084","988.61121","0.00291","0.00144","98.86112","-0.00036"
"9.00000","0.29729","1003.39233","0.00297","0.00147","100.33923","-0.00035"
"9.20000","0.30389","1018.84418","0.00304","0.00149","101.88441","-0.00031"
"9.40000","0.31057","1034.59680","0.00311","0.00151","103.45968","-0.00036"
"9.60000","0.31742","1050.85303","0.00317","0.00154","105.08530","-0.00036"
"9.80000","0.32395","1065.49060","0.00324","0.00156","106.54906","-0.00036"
"10.00000","0.33062","1080.30042","0.00331","0.00158","108.03004","-0.00031"
"10.20000","0.33738","1095.47241","0.00337","0.00161","109.54724","-0.00036"
"10.40000","0.34391","1109.43079","0.00344","0.00163","110.94308","-0.00036"
"10.60000","0.35077","1124.72668","0.00351","0.00165","112.47267","-0.00035"
"10.80000","0.35726","1138.47021","0.00357","0.00167","113.84702","-0.00036"
"11.00000","0.36394","1152.83118","0.00364","0.00169","115.28312","-0.00036"
"11.20000","0.37071","1167.56104","0.00371","0.00171","116.75610","-0.00035"
"11.40000","0.37729","1181.37146","0.00377","0.00174","118.13715","-0.00036"
"11.60000","0.38391","1195.19360","0.00384","0.00177","119.51936","-0.00031"
"11.80000","0.39060","1209.26538","0.00391","0.00180","120.92654","-0.00031"
"12.00000","0.39739","1223.66626","0.00397","0.00181","122.36662","-0.00025"
"12.20000","0.40398","1237.19067","0.00404","0.00183","123.71907","-0.00026"
"12.40000","0.41062","1250.67639","0.00411","0.00185","125.06764","-0.00020"
"12.60000","0.41744","1264.87097","0.00417","0.00187","126.48710","-0.00020"
"12.80000","0.42392","1277.11584","0.00424","0.00189","127.71159","-0.00018"
"13.00000","0.43064","1290.50305","0.00431","0.00190","129.05031","-0.00020"
"13.20000","0.43728","1303.64087","0.00437","0.00193","130.36409","-0.00020"
"13.40000","0.44394","1316.52490","0.00444","0.00196","131.65250","-0.00017"
"13.60000","0.45073","1330.24878","0.00451","0.00197","133.02487","-0.00021"
"13.80000","0.45725","1342.28247","0.00457","0.00198","134.22824","-0.00021"
"14.00000","0.46402","1355.05566","0.00464","0.00200","135.50557","-0.00021"
"14.20000","0.47059","1366.88403","0.00471","0.00202","136.68840","-0.00022"
"14.40000","0.47743","1379.96069","0.00477","0.00202","137.99606","-0.00021"
"14.60000","0.48394","1391.23438","0.00484","0.00203","139.12344","-0.00021"
"14.80000","0.49055","1403.45642","0.00491","0.00206","140.34564","-0.00021"
"15.00000","0.49741","1417.46545","0.00497","0.00209","141.74655","-0.00021"
"15.20000","0.50387","1430.08289","0.00504","0.00210","143.00829","-0.00015"
"15.40000","0.51063","1444.60352","0.00511","0.00213","144.46036","-0.00015"
"15.60000","0.51728","1459.23767","0.00517","0.00215","145.92377","-0.00015"
"15.80000","0.52406","1475.04834","0.00524","0.00217","147.50484","-0.00015"
"16.00000","0.53068","1490.32288","0.00531","0.00219","149.03229","-0.00015"
"16.20000","0.53728","1505.69739","0.00537","0.00221","150.56973","-0.00015"
"16.40000","0.54401","1521.64441","0.00544","0.00223","152.16444","-0.00020"
"16.60000","0.55051","1536.55286","0.00551","0.00224","153.65529","-0.00020"
"16.80000","0.55738","1552.73523","0.00557","0.00226","155.27353","-0.00021"
"17.00000","0.56391","1567.42407","0.00564","0.00229","156.74240","-0.00018"
"17.20000","0.57068","1583.16345","0.00571","0.00230","158.31635","-0.00021"
"17.40000","0.57735","1598.43420","0.00577","0.00233","159.84341","-0.00025"
"17.60000","0.58395","1613.06982","0.00584","0.00236","161.30698","-0.00026"
"17.80000","0.59067","1628.25867","0.00591","0.00237","162.82587","-0.00026"
"18.00000","0.59724","1642.24670","0.00597","0.00238","164.22467","-0.00026"
"18.20000","0.60410","1657.38867","0.00604","0.00240","165.73886","-0.00021"
"18.40000","0.61059","1671.05774","0.00611","0.00243","167.10577","-0.00021"
"18.60000","0.61725","1685.10693","0.00617","0.00244","168.51070","-0.00021"
"18.80000","0.62401","1699.69763","0.00624","0.00246","169.96976","-0.00021"
"19.00000","0.63060","1712.79810","0.00631","0.00250","171.27982","-0.00019"
"19.20000","0.63731","1726.24939","0.00637","0.00251","172.62494","-0.00015"
"19.40000","0.64399","1739.02942","0.00644","0.00253","173.90294","-0.00015"
"19.60000","0.65066","1751.52966","0.00651","0.00254","175.15297","-0.00015"
"19.80000","0.65735","1764.37793","0.00657","0.00255","176.43779","-0.00015"
"20.00000","0.66397","1776.38293","0.00664","0.00256","177.63829","-0.00015"
"20.20000","0.67061","1788.49878","0.00671","0.00259","178.84988","-0.00015"
"20.40000","0.67722","1799.94067","0.00677","0.00262","179.99406","-0.00010"
"20.60000","0.68404","1812.68567","0.00684","0.00263","181.26857","-0.00015"
"20.80000","0.69069","1824.31140","0.00691","0.00264","182.43114","-0.00010"
"21.00000","0.69723","1835.06055","0.00697","0.00265","183.50606","-0.00010"
"21.20000","0.70409","1847.23499","0.00704","0.00267","184.72350","-0.00013"
"21.40000","0.71057","1857.01697","0.00711","0.00267","185.70169","-0.00010"
"21.60000","0.71734","1868.15332","0.00717","0.00269","186.81534","-0.00015"
"21.80000","0.72396","1878.32617","0.00724","0.00270","187.83261","-0.00015"
"22.00000","0.73070","1888.64172","0.00731","0.00271","188.86417","-0.00021"
"22.20000","0.73734","1898.73340","0.00737","0.00272","189.87334","-0.00021"
"22.40000","0.74390","1908.29797","0.00744","0.00275","190.82980","-0.00021"
"22.60000","0.75074","1918.85474","0.00751","0.00277","191.88547","-0.00021"
"22.80000","0.75717","1927.17700","0.00757","0.00277","192.71770","-0.00021"
"23.00000","0.76403","1937.13196","0.00764","0.00278","193.71320","-0.00021"
"23.20000","0.77060","1945.35400","0.00771","0.00279","194.53540","-0.00025"
"23.40000","0.77730","1953.66687","0.00777","0.00280","195.36668","-0.00025"
"23.60000","0.78415","1962.95850","0.00784","0.00283","196.29585","-0.00021"
"23.80000","0.79060","1969.65955","0.00791","0.00284","196.96596","-0.00021"
"24.00000","0.79725","1977.48315","0.00797","0.00285","197.74832","-0.00015"
"24.20000","0.80388","1985.08374","0.00804","0.00285","198.50838","-0.00015"
"24.40000","0.81081","1993.89514","0.00811","0.00285","199.38951","-0.00014"
"24.60000","0.81727","2000.64050","0.00817","0.00285","200.06406","-0.00015"
"24.80000","0.82393","2007.58276","0.00824","0.00287","200.75827","-0.00015"
"25.00000","0.83072","2015.30396","0.00831","0.00288","201.53040","-0.00015"
"25.20000","0.83723","2021.29224","0.00837","0.00289","202.12923","-0.00012"
"25.40000","0.84408","2029.00317","0.00844","0.00290","202.90031","-0.00011"
"25.60000","0.85062","2034.70740","0.00851","0.00291","203.47073","-0.00010"
"25.80000","0.85732","2041.16199","0.00857","0.00291","204.11620","-0.00010"
"26.00000","0.86403","2047.82043","0.00864","0.00292","204.78204","-0.00011"
"26.20000","0.87069","2053.79028","0.00871","0.00292","205.37903","-0.00010"
"26.40000","0.87727","2059.10425","0.00877","0.00294","205.91043","-0.00010"
"26.60000","0.88389","2064.05347","0.00884","0.00295","206.40535","-0.00010"
"26.80000","0.89070","2069.87500","0.00891","0.00296","206.98750","-0.00008"
"27.00000","0.89729","2074.90259","0.00897","0.00297","207.49026","-0.00010"
"27.20000","0.90397","2079.86694","0.00904","0.00297","207.98669","-0.00010"
"27.40000","0.91078","2085.61279","0.00911","0.00298","208.56128","-0.00010"
"27.60000","0.91729","2089.70312","0.00917","0.00298","208.97031","-0.00016"
"27.80000","0.92392","2094.24219","0.00924","0.00298","209.42422","-0.00015"
"28.00000","0.93065","2099.58618","0.00931","0.00300","209.95862","-0.00018"
"28.20000","0.93733","2104.66455","0.00937","0.00300","210.46646","-0.00015"
"28.40000","0.94399","2109.64355","0.00944","0.00301","210.96436","-0.00015"
"28.60000","0.95056","2113.94556","0.00951","0.00302","211.39456","-0.00015"
"28.80000","0.95738","2119.48462","0.00957","0.00303","211.94846","-0.00015"
"29.00000","0.96391","2123.65332","0.00964","0.00303","212.36533","-0.00015"
"29.20000","0.97080","2129.60718","0.00971","0.00304","212.96072","-0.00018"
"29.40000","0.97733","2134.28149","0.00977","0.00304","213.42815","-0.00016"
"29.60000","0.98393","2138.78931","0.00984","0.00306","213.87894","-0.00015"
"29.80000","0.99082","2144.70581","0.00991","0.00306","214.47058","-0.00015"
"30.00000","0.99724","2148.31274","0.00997","0.00307","214.83127","-0.00020"
"30.20000","1.00393","2152.98218","0.01004","0.00306","215.29822","-0.00021"
"30.40000","1.01049","2157.42798","0.01010","0.00307","215.74280","-0.00016"
"30.60000","1.01743","2163.32495","0.01017","0.00309","216.33249","-0.00015"
"30.80000","1.02404","2167.57666","0.01024","0.00310","216.75766","-0.00015"
"31.00000","1.03070","2171.68286","0.01031","0.00311","217.16829","-0.00011"
"31.20000","1.03746","2176.61792","0.01037","0.00311","217.66179","-0.00011"
"31.40000","1.04392","2179.53052","0.01044","0.00311","217.95305","-0.00015"
"31.60000","1.05070","2183.46069","0.01051","0.00311","218.34607","-0.00016"
"31.80000","1.05724","2183.83008","0.01057","0.00312","218.38301","-0.00015"
"32.00000","1.06398","2185.89185","0.01064","0.00313","218.58919","-0.00015"
"32.20000","1.07066","2188.82153","0.01071","0.00313","218.88216","-0.00013"
"32.40000","1.07732","2191.82446","0.01077","0.00313","219.18245","-0.00010"
"32.60000","1.08405","2195.69458","0.01084","0.00314","219.56946","-0.00010"
"32.80000","1.09065","2198.22534","0.01091","0.00314","219.82254","-0.00010"
"33.00000","1.09752","2202.59790","0.01098","0.00315","220.25980","-0.00010"
"33.20000","1.10395","2205.30957","0.01104","0.00315","220.53096","-0.00010"
"33.40000","1.11062","2209.45923","0.01111","0.00316","220.94592","-0.00005"
"33.60000","1.11734","2213.96240","0.01117","0.00316","221.39624","-0.00005"
"33.80000","1.12391","2217.61475","0.01124","0.00316","221.76147","-0.00005"
"34.00000","1.13060","2221.60913","0.01131","0.00317","222.16092","-0.00005"
"34.20000","1.13732","2225.55591","0.01137","0.00317","222.55559","-0.00005"
"34.40000","1.14406","2229.31738","0.01144","0.00317","222.93173","-0.00005"
"34.60000","1.15078","2233.04028","0.01151","0.00318","223.30403","-0.00010"
"34.80000","1.15731","2235.58203","0.01157","0.00319","223.55820","-0.00010"
"35.00000","1.16403","2239.22607","0.01164","0.00318","223.92261","-0.00013"
"35.20000","1.17059","2242.02734","0.01171","0.00319","224.20273","-0.00010"
"35.40000","1.17733","2245.55908","0.01177","0.00319","224.55591","-0.00013"
"35.60000","1.18396","2248.23267","0.01184","0.00320","224.82327","-0.00015"
"35.80000","1.19054","2250.46777","0.01191","0.00320","225.04678","-0.00015"
"36.00000","1.19743","2254.82031","0.01197","0.00321","225.48203","-0.00015"
"36.20000","1.20400","2257.17554","0.01204","0.00321","225.71756","-0.00015"
"36.40000","1.21077","2260.17407","0.01211","0.00321","226.01741","-0.00017"
"36.60000","1.21732","2262.03613","0.01217","0.00321","226.20361","-0.00015"
"36.80000","1.22408","2264.30835","0.01224","0.00321","226.43083","-0.00015"
"37.00000","1.23068","2265.16772","0.01231","0.00322","226.51677","-0.00012"
"37.20000","1.23721","2266.03369","0.01237","0.00322","226.60336","-0.00015"
"37.40000","1.24407","2268.88403","0.01244","0.00323","226.88840","-0.00013"
"37.60000","1.25050","2270.00708","0.01250","0.00323","227.00070","-0.00015"
"37.80000","1.25735","2273.35181","0.01257","0.00323","227.33517","-0.00011"
"38.00000","1.26399","2275.37646","0.01264","0.00323","227.53764","-0.00016"
"38.20000","1.27081","2277.39453","0.01271","0.00325","227.73946","-0.00010"
"38.40000","1.27748","2279.50806","0.01277","0.00326","227.95081","-0.00010"
"38.60000","1.28399","2280.36816","0.01284","0.00325","228.03682","-0.00005"
"38.80000","1.29062","2282.15283","0.01291","0.00326","228.21529","-0.00010"
"39.00000","1.29717","2283.43896","0.01297","0.00325","228.34390","-0.00010"
"39.20000","1.30410","2286.68921","0.01304","0.00326","228.66891","-0.00005"
"39.40000","1.31060","2288.45068","0.01311","0.00326","228.84506","-0.00010"
"39.60000","1.31728","2291.26465","0.01317","0.00326","229.12646","-0.00010"
"39.80000","1.32412","2295.02954","0.01324","0.00327","229.50296","-0.00007"
"40.00000","1.33069","2297.27954","0.01331","0.00328","229.72795","-0.00005"
"40.20000","1.33741","2299.44531","0.01337","0.00329","229.94453","-0.00005"
"40.40000","1.34393","2300.39893","0.01344","0.00330","230.03989","-0.00005"
"40.60000","1.35071","2302.97168","0.01351","0.00330","230.29716","-0.00003"
"40.80000","1.35728","2304.76880","0.01357","0.00330","230.47688","-0.00005"
"41.00000","1.36397","2307.25854","0.01364","0.00328","230.72586","-0.00005"
"41.20000","1.37066","2309.44702","0.01371","0.00328","230.94470","-0.00005"
"41.40000","1.37724","2310.78125","0.01377","0.00330","231.07812","-0.00002"
"41.60000","1.38410","2312.82300","0.01384","0.00330","231.28230","-0.00005"
"41.80000","1.39074","2314.03979","0.01391","0.00332","231.40398","-0.00005"
"42.00000","1.39733","2314.50464","0.01397","0.00331","231.45047","-0.00005"
"42.20000","1.40409","2315.65601","0.01404","0.00331","231.56560","-0.00005"
"42.40000","1.41062","2315.38306","0.01411","0.00331","231.53830","-0.00010"
"42.60000","1.41726","2314.97168","0.01417","0.00332","231.49716","-0.00009"
"42.80000","1.42390","2315.74780","0.01424","0.00332","231.57478","-0.00007"
"43.00000","1.43069","2317.51709","0.01431","0.00332","231.75171","-0.00010"
"43.20000","1.43735","2318.10278","0.01437","0.00332","231.81027","-0.00010"
"43.40000","1.44398","2317.17358","0.01444","0.00334","231.71736","-0.00010"
"43.60000","1.45085","2316.38745","0.01451","0.00333","231.63875","-0.00010"
"43.80000","1.45729","2312.31396","0.01457","0.00333","231.23140","-0.00010"
"44.00000","1.46401","2309.56909","0.01464","0.00333","230.95691","-0.00008"
"44.20000","1.47060","2307.08447","0.01471","0.00332","230.70845","-0.00010"
"44.40000","1.47729","2303.50781","0.01477","0.00332","230.35078","-0.00010"
"44.60000","1.48405","2300.38257","0.01484","0.00332","230.03825","-0.00010"
"44.80000","1.49064","2296.56006","0.01491","0.00331","229.65601","-0.00010"
"45.00000","1.49732","2293.73267","0.01497","0.00331","229.37326","-0.00008"
"45.20000","1.50390","2289.18115","0.01504","0.00330","228.91812","-0.00009"
"45.40000","1.51086","2286.26343","0.01511","0.00329","228.62634","-0.00010"
"45.60000","1.51731","2282.21631","0.01517","0.00329","228.22163","-0.00010"
"45.80000","1.52395","2280.78027","0.01524","0.00328","228.07803","-0.00005"
"46.00000","1.53075","2280.50586","0.01531","0.00328","228.05058","-0.00005"
"46.20000","1.53722","2278.51099","0.01537","0.00328","227.85110","-0.00005"
"46.40000","1.54400","2278.61938","0.01544","0.00329","227.86194","-0.00005"
"46.60000","1.55058","2278.36060","0.01551","0.00328","227.83606","0.00000"
"46.80000","1.55740","2280.68384","0.01557","0.00328","228.06839","0.00000"
"47.00000","1.56404","2282.24414","0.01564","0.00328","228.22441","0.00000"
"47.20000","1.57069","2283.57373","0.01571","0.00329","228.35738","0.00000"
"47.40000","1.57738","2285.53296","0.01577","0.00329","228.55330","0.00000"
"47.60000","1.58389","2286.45996","0.01584","0.00329","228.64600","0.00000"
"47.80000","1.59071","2289.19556","0.01591","0.00330","228.91956","0.00000"
"48.00000","1.59729","2290.60645","0.01597","0.00330","229.06064","0.00000"
"48.20000","1.60392","2291.66162","0.01604","0.00330","229.16617","0.00000"
"48.40000","1.61073","2294.11084","0.01611","0.00331","229.41109","0.00004"
"48.60000","1.61730","2295.33057","0.01617","0.00332","229.53305","0.00004"
"48.80000","1.62401","2297.85181","0.01624","0.00332","229.78519","0.00005"
"49.00000","1.63068","2299.49194","0.01631","0.00332","229.94919","0.00000"
"49.20000","1.63742","2299.50854","0.01637","0.00332","229.95085","0.00000"
"49.40000","1.64398","2297.68091","0.01644","0.00332","229.76810","0.00000"
"49.60000","1.65056","2295.99951","0.01651","0.00332","229.59995","0.00000"
"49.80000","1.65741","2295.05200","0.01657","0.00332","229.50520","0.00000"
"50.00000","1.66390","2292.85132","0.01664","0.00332","229.28513","0.00000"
"50.20000","1.67070","2291.76831","0.01671","0.00333","229.17683","0.00000"
"50.40000","1.67735","2290.60303","0.01677","0.00332","229.06030","-0.00005"
"50.60000","1.68400","2289.90332","0.01684","0.00332","228.99033","-0.00005"
"50.80000","1.69070","2289.73633","0.01691","0.00332","228.97363","-0.00005"
"51.00000","1.69727","2288.55786","0.01697","0.00332","228.85579","-0.00006"
"51.20000","1.70399","2287.42944","0.01704","0.00331","228.74295","-0.00005"
"51.40000","1.71052","2284.63745","0.01711","0.00331","228.46375","-0.00005"
"51.60000","1.71740","2282.94824","0.01717","0.00331","228.29483","-0.00005"
"51.80000","1.72396","2281.29004","0.01724","0.00331","228.12900","-0.00005"
"52.00000","1.73061","2277.84619","0.01731","0.00331","227.78462","-0.00005"
"52.20000","1.73748","2275.33765","0.01737","0.00330","227.53377","-0.00005"
"52.40000","1.74392","2271.56836","0.01744","0.00329","227.15683","-0.00005"
"52.60000","1.75060","2269.56860","0.01751","0.00329","226.95686","-0.00005"
"52.80000","1.75728","2267.07886","0.01757","0.00329","226.70789","0.00000"
"53.00000","1.76406","2264.17578","0.01764","0.00329","226.41757","0.00000"
"53.20000","1.77065","2259.34326","0.01771","0.00328","225.93433","0.00000"
"53.40000","1.77730","2255.28955","0.01777","0.00328","225.52896","0.00000"
"53.60000","1.78403","2252.20972","0.01784","0.00327","225.22098","0.00000"
"53.80000","1.79056","2246.97803","0.01791","0.00326","224.69780","0.00000"
"54.00000","1.79748","2241.98608","0.01797","0.00326","224.19861","0.00005"
"54.20000","1.80397","2234.92188","0.01804","0.00325","223.49219","0.00005"
"54.40000","1.81060","2228.53955","0.01811","0.00324","222.85396","0.00005"
"54.60000","1.81739","2224.24146","0.01817","0.00323","222.42415","0.00005"
"54.80000","1.82394","2216.96265","0.01824","0.00322","221.69626","0.00005"
"55.00000","1.83057","2208.24487","0.01831","0.00321","220.82449","0.00005"
"55.20000","1.83728","2195.30713","0.01837","0.00321","219.53072","0.00007"
"55.40000","1.84409","2182.84961","0.01844","0.00319","218.28496","0.00005"
"55.60000","1.85067","2172.72144","0.01851","0.00317","217.27214","0.00010"
"55.80000","1.85728","2166.51343","0.01857","0.00315","216.65134","0.00010"
"56.00000","1.86408","2163.33179","0.01864","0.00315","216.33318","0.00005"
"56.20000","1.87057","2158.12744","0.01871","0.00315","215.81274","0.00005"
"56.40000","1.87733","2150.87573","0.01877","0.00314","215.08757","0.00005"
"56.60000","1.88395","2145.94360","0.01884","0.00313","214.59436","0.00000"
"56.80000","1.89059","2140.77905","0.01891","0.00314","214.07791","0.00000"
"57.00000","1.89745","2139.60522","0.01897","0.00313","213.96053","-0.00004"
"57.20000","1.90395","2140.21826","0.01904","0.00313","214.02182","-0.00005"
"57.40000","1.91065","2143.72900","0.01911","0.00313","214.37289","-0.00005"
"57.60000","1.91726","2146.91895","0.01917","0.00313","214.69189","-0.00005"
"57.80000","1.92410","2150.93848","0.01924","0.00313","215.09384","-0.00006"
"58.00000","1.93062","2152.72998","0.01931","0.00313","215.27299","-0.00005"
"58.20000","1.93719","2154.38721","0.01937","0.00314","215.43872","-0.00005"
"58.40000","1.94406","2156.75513","0.01944","0.00315","215.67551","-0.00005"
"58.60000","1.95055","2157.02319","0.01951","0.00314","215.70232","-0.00005"
"58.80000","1.95732","2158.63208","0.01957","0.00315","215.86320","-0.00005"
"59.00000","1.96391","2158.29175","0.01964","0.00314","215.82918","-0.00006"
"59.20000","1.97069","2152.49805","0.01971","0.00315","215.24980","-0.00005"
"59.40000","1.97742","2143.53784","0.01977","0.00313","214.35379","-0.00005"
"59.60000","1.98395","2135.88525","0.01984","0.00312","213.58853","0.00000"
"59.80000","1.99063","2131.97510","0.01991","0.00311","213.19751","0.00000"
"60.00000","1.99715","2127.96436","0.01997","0.00311","212.79643","0.00000"
"60.20000","2.00404","2121.98218","0.02004","0.00311","212.19821","0.00000"
"60.40000","2.01058","2112.06885","0.02011","0.00310","211.20688","0.00001"
"60.60000","2.01732","2104.25220","0.02017","0.00309","210.42522","0.00000"
"60.80000","2.02409","2100.23145","0.02024","0.00307","210.02315","0.00000"
"61.00000","2.03063","2094.51562","0.02031","0.00306","209.45157","0.00000"
"61.20000","2.03734","2092.63452","0.02037","0.00306","209.26346","0.00000"
"61.40000","2.04390","2091.20410","0.02044","0.00305","209.12041","0.00000"
"61.60000","2.05072","2093.48145","0.02051","0.00305","209.34814","-0.00003"
"61.80000","2.05725","2095.21436","0.02057","0.00307","209.52144","-0.00005"
"62.00000","2.06395","2097.61353","0.02064","0.00307","209.76135","-0.00005"
"62.20000","2.07068","2098.97559","0.02071","0.00308","209.89755","-0.00005"
"62.40000","2.07727","2096.99341","0.02077","0.00308","209.69934","-0.00005"
"62.60000","2.08400","2093.59985","0.02084","0.00309","209.35999","-0.00005"
"62.80000","2.09063","2090.18091","0.02091","0.00309","209.01810","-0.00007"
"63.00000","2.09731","2087.09937","0.02097","0.00307","208.70993","-0.00005"
"63.20000","2.10405","2082.63257","0.02104","0.00307","208.26326","-0.00005"
"63.40000","2.11066","2077.53784","0.02111","0.00306","207.75378","-0.00005"
"63.60000","2.11726","2073.24536","0.02117","0.00304","207.32454","-0.00010"
"63.80000","2.12391","2067.96362","0.02124","0.00304","206.79636","-0.00010"
"64.00000","2.13071","2065.54272","0.02131","0.00302","206.55428","-0.00007"
"64.20000","2.13734","2064.47485","0.02137","0.00303","206.44748","-0.00005"
"64.40000","2.14390","2063.97852","0.02144","0.00304","206.39786","-0.00005"
"64.60000","2.15077","2065.61621","0.02151","0.00304","206.56161","-0.00003"
"64.80000","2.15723","2064.31250","0.02157","0.00304","206.43124","-0.00004"
"65.00000","2.16405","2065.49536","0.02164","0.00304","206.54953","-0.00005"
"65.20000","2.17065","2066.52612","0.02171","0.00304","206.65262","0.00000"
"65.40000","2.17731","2067.71899","0.02177","0.00304","206.77190","0.00000"
"65.60000","2.18400","2069.77637","0.02184","0.00304","206.97763","0.00000"
"65.80000","2.19057","2071.90479","0.02191","0.00305","207.19048","0.00005"
"66.00000","2.19738","2075.39917","0.02197","0.00305","207.53992","0.00003"
"66.20000","2.20387","2079.18750","0.02204","0.00305","207.91875","0.00003"
"66.40000","2.21074","2084.68604","0.02211","0.00306","208.46860","0.00000"
"66.60000","2.21727","2087.64575","0.02217","0.00307","208.76457","0.00000"
"66.80000","2.22395","2086.37158","0.02224","0.00307","208.63716","0.00000"
"67.00000","2.23080","2082.53613","0.02231","0.00307","208.25362","0.00002"
"67.20000","2.23722","2071.14111","0.02237","0.00307","207.11411","0.00005"
"67.40000","2.24393","2059.35938","0.02244","0.00305","205.93594","0.00005"
"67.60000","2.25056","2048.98462","0.02251","0.00303","204.89847","0.00005"
"67.80000","2.25748","2041.49426","0.02257","0.00300","204.14943","0.00003"
"68.00000","2.26392","2034.88208","0.02264","0.00301","203.48820","0.00000"
"68.20000","2.27059","2027.46265","0.02271","0.00300","202.74626","0.00002"
"68.40000","2.27737","2014.87708","0.02277","0.00299","201.48770","0.00005"
"68.60000","2.28389","1997.95667","0.02284","0.00298","199.79567","0.00005"
"68.80000","2.29078","1984.90271","0.02291","0.00296","198.49026","0.00005"
"69.00000","2.29728","1974.62720","0.02297","0.00295","197.46272","0.00005"
"69.20000","2.30396","1965.41675","0.02304","0.00292","196.54167","0.00005"
"69.40000","2.31070","1958.51062","0.02311","0.00292","195.85106","0.00006"
"69.60000","2.31733","1948.49707","0.02317","0.00290","194.84970","0.00009"
"69.80000","2.32391","1935.81433","0.02324","0.00290","193.58144","0.00010"
"70.00000","2.33060","1921.58887","0.02331","0.00289","192.15889","0.00010"
"70.20000","2.33741","1907.28357","0.02337","0.00287","190.72836","0.00010"
"70.40000","2.34400","1894.17932","0.02344","0.00285","189.41794","0.00011"
"70.60000","2.35063","1879.95325","0.02351","0.00284","187.99533","0.00010"
"70.80000","2.35742","1870.42358","0.02357","0.00283","187.04236","0.00012"
"71.00000","2.36390","1859.05737","0.02364","0.00282","185.90573","0.00013"
"71.20000","2.37064","1844.02612","0.02371","0.00282","184.40262","0.00010"
"71.40000","2.37735","1828.80383","0.02377","0.00280","182.88039","0.00015"
"71.60000","2.38399","1812.78528","0.02384","0.00277","181.27853","0.00015"
"71.80000","2.39070","1797.80884","0.02391","0.00275","179.78088","0.00015"
"72.00000","2.39725","1779.23853","0.02397","0.00272","177.92386","0.00016"
"72.20000","2.40403","1762.39624","0.02404","0.00269","176.23962","0.00015"
"72.40000","2.41059","1743.26917","0.02411","0.00268","174.32692","0.00015"
"72.60000","2.41745","1726.68298","0.02417","0.00266","172.66830","0.00021"
"72.80000","2.42400","1712.11865","0.02424","0.00265","171.21187","0.00021"
"73.00000","2.43060","1697.13965","0.02431","0.00264","169.71396","0.00021"
"73.20000","2.43748","1684.16394","0.02437","0.00262","168.41640","0.00021"
"73.40000","2.44390","1670.30640","0.02444","0.00260","167.03064","0.00023"
"73.60000","2.45060","1654.37048","0.02451","0.00258","165.43704","0.00024"
"73.80000","2.45719","1637.96436","0.02457","0.00256","163.79643","0.00026"
"74.00000","2.46408","1620.35547","0.02464","0.00254","162.03555","0.00026"
"74.20000","2.47073","1601.04395","0.02471","0.00252","160.10440","0.00027"
"74.40000","2.47738","1585.29846","0.02477","0.00250","158.52985","0.00026"
"74.60000","2.48405","1573.09583","0.02484","0.00247","157.30959","0.00028"
"74.80000","2.49054","1557.28748","0.02491","0.00246","155.72874","0.00027"
"75.00000","2.49740","1542.83704","0.02497","0.00245","154.28371","0.00031"
"75.20000","2.50391","1526.05151","0.02504","0.00243","152.60515","0.00030"
"75.40000","2.51062","1503.19189","0.02511","0.00241","150.31918","0.00031"
"75.60000","2.51737","1480.32397","0.02517","0.00238","148.03239","0.00031"
"75.80000","2.52400","1456.60266","0.02524","0.00235","145.66026","0.00036"
"76.00000","2.53069","1436.53723","0.02531","0.00232","143.65372","0.00036"
"76.20000","2.53730","1412.31091","0.02537","0.00230","141.23109","0.00036"
"76.40000","2.54415","1389.55139","0.02544","0.00226","138.95514","0.00040"
"76.60000","2.55062","1365.77417","0.02551","0.00223","136.57742","0.00041"
"76.80000","2.55732","1342.60742","0.02557","0.00221","134.26074","0.00041"
"77.00000","2.56401","1316.43762","0.02564","0.00217","131.64377","0.00041"
"77.20000","2.57058","1291.10999","0.02571","0.00215","129.11099","0.00041"
"77.40000","2.57730","1271.86938","0.02577","0.00213","127.18694","0.00041"
"77.60000","2.58396","1253.39734","0.02584","0.00211","125.33974","0.00041"
"77.80000","2.59070","1236.71802","0.02591","0.00211","123.67180","0.00045"
"78.00000","2.59746","1217.94934","0.02597","0.00208","121.79494","0.00046"
"78.20000","2.60402","1200.00818","0.02604","0.00206","120.00082","0.00046"
"78.40000","2.61066","1181.20288","0.02611","0.00205","118.12029","0.00046"
"78.60000","2.61727","1163.01978","0.02617","0.00202","116.30198","0.00042"
"78.80000","2.62403","1143.78186","0.02624","0.00200","114.37819","0.00043"
"79.00000","2.63062","1121.98828","0.02631","0.00197","112.19883","0.00041"
"79.20000","2.63722","1102.12244","0.02637","0.00197","110.21224","0.00041"
"79.40000","2.64410","1083.96326","0.02644","0.00193","108.39632","0.00038"
"79.60000","2.65067","1066.37000","0.02651","0.00191","106.63700","0.00038"
"79.80000","2.65744","1051.56116","0.02657","0.00189","105.15611","0.00036"
"80.00000","2.66399","1038.79077","0.02664","0.00187","103.87907","0.00036"
"80.20000","2.67073","1028.52356","0.02671","0.00186","102.85236","0.00036"
"80.40000","2.67736","1016.89471","0.02677","0.00185","101.68947","0.00036"
"80.60000","2.68390","1003.39514","0.02684","0.00181","100.33952","0.00036"
"80.80000","2.69070","993.50360","0.02691","0.00180","99.35036","0.00036"
"81.00000","2.69717","982.64496","0.02697","0.00180","98.26450","0.00036"
"81.20000","2.70405","973.55750","0.02704","0.00180","97.35575","0.00035"
"81.40000","2.71067","964.92590","0.02711","0.00179","96.49259","0.00031"
"81.60000","2.71744","956.26514","0.02717","0.00178","95.62651","0.00036"
"81.80000","2.72412","948.40063","0.02724","0.00178","94.84007","0.00036"
"82.00000","2.73063","942.50507","0.02731","0.00177","94.25050","0.00036"
"82.20000","2.73729","937.60815","0.02737","0.00178","93.76082","0.00035"
"82.40000","2.74387","930.49036","0.02744","0.00176","93.04903","0.00036"
"82.60000","2.75075","924.27704","0.02751","0.00175","92.42770","0.00036"
"82.80000","2.75725","918.38080","0.02757","0.00175","91.83808","0.00041"
"83.00000","2.76393","912.90399","0.02764","0.00175","91.29040","0.00041"
"83.20000","2.77076","907.61932","0.02771","0.00174","90.76193","0.00041"
"83.40000","2.77736","900.98010","0.02777","0.00175","90.09801","0.00041"
"83.60000","2.78412","895.29230","0.02784","0.00175","89.52923","0.00041"
"83.80000","2.79062","890.69708","0.02791","0.00175","89.06971","0.00041"
"84.00000","2.79734","888.63635","0.02797","0.00173","88.86363","0.00036"
"84.20000","2.80397","887.21692","0.02804","0.00173","88.72169","0.00036"
"84.40000","2.81062","884.89178","0.02811","0.00173","88.48918","0.00041"
"84.60000","2.81728","881.56665","0.02817","0.00173","88.15666","0.00036"
"84.80000","2.82394","877.19904","0.02824","0.00173","87.71990","0.00041"
"85.00000","2.83080","873.76086","0.02831","0.00173","87.37608","0.00036"
"85.20000","2.83738","869.59076","0.02837","0.00173","86.95908","0.00041"
"85.40000","2.84396","865.32831","0.02844","0.00173","86.53283","0.00041"
"85.60000","2.85076","861.08411","0.02851","0.00173","86.10841","0.00041"
"85.80000","2.85729","856.05371","0.02857","0.00173","85.60537","0.00041"
"86.00000","2.86392","851.92358","0.02864","0.00173","85.19236","0.00041"
"86.20000","2.87059","847.97906","0.02871","0.00172","84.79790","0.00040"
"86.40000","2.87733","844.41772","0.02877","0.00172","84.44177","0.00041"
"86.60000","2.88405","840.27087","0.02884","0.00172","84.02708","0.00041"
"86.80000","2.89065","835.46472","0.02891","0.00173","83.54647","0.00041"
"87.00000","2.89747","832.37823","0.02897","0.00174","83.23782","0.00041"
"87.20000","2.90395","827.19055","0.02904","0.00173","82.71906","0.00041"
"87.40000","2.91076","822.36176","0.02911","0.00173","82.23618","0.00038"
"87.60000","2.91730","817.96844","0.02917","0.00173","81.79684","0.00041"
"87.80000","2.92392","814.45520","0.02924","0.00173","81.44552","0.00041"
"88.00000","2.93073","814.07642","0.02931","0.00173","81.40764","0.00041"
"88.20000","2.93726","811.99072","0.02937","0.00174","81.19907","0.00036"
"88.40000","2.94397","810.18604","0.02944","0.00173","81.01860","0.00036"
"88.60000","2.95061","809.27985","0.02951","0.00172","80.92799","0.00040"
"88.80000","2.95752","809.51154","0.02958","0.00172","80.95116","0.00041"
"89.00000","2.96400","808.24274","0.02964","0.00172","80.82427","0.00041"
"89.20000","2.97063","806.49274","0.02971","0.00171","80.64928","0.00036"
"89.40000","2.97740","805.93329","0.02977","0.00171","80.59333","0.00036"
"89.60000","2.98386","803.30988","0.02984","0.00171","80.33099","0.00036"
"89.68700","2.98681","803.07758","0.02987","0.00171","80.30775","0.00038"