File: Tension/Section_1_Group3/avocado_tension_per5.is_tens_RawData/Specimen_RawData_1.csv
Time,Extension,Load,Tensile strain (Extension),Axial Video,Tensile stress,Transverse Video
(s),(mm),(N),(mm/mm),(mm/mm),(MPa),(mm/mm)
"0.00000","0.00000","-0.29756","0.00000","0.00004","-0.02976","-0.00011"
"0.20000","0.00249","8.40661","0.00002","0.00002","0.84066","-0.00004"
"0.40000","0.01076","36.49445","0.00011","0.00001","3.64945","-0.00015"
"0.60000","0.01746","57.28417","0.00017","-0.00005","5.72842","-0.00026"
"0.80000","0.02405","75.51434","0.00024","-0.00004","7.55143","-0.00034"
"1.00000","0.03090","95.59756","0.00031","0.00005","9.55976","-0.00040"
"1.20000","0.03744","115.85571","0.00037","0.00017","11.58557","-0.00045"
"1.40000","0.04417","137.32677","0.00044","0.00026","13.73268","-0.00043"
"1.60000","0.05092","158.99161","0.00051","0.00045","15.89916","-0.00042"
"1.80000","0.05745","179.80278","0.00057","0.00053","17.98028","-0.00041"
"2.00000","0.06432","201.99870","0.00064","0.00063","20.19987","-0.00039"
"2.20000","0.07079","222.53238","0.00071","0.00075","22.25324","-0.00041"
"2.40000","0.07750","243.85887","0.00077","0.00080","24.38589","-0.00046"
"2.60000","0.08418","264.82104","0.00084","0.00086","26.48211","-0.00045"
"2.80000","0.09082","285.94653","0.00091","0.00087","28.59465","-0.00045"
"3.00000","0.09741","306.76025","0.00097","0.00091","30.67603","-0.00049"
"3.20000","0.10412","327.75662","0.00104","0.00095","32.77566","-0.00049"
"3.40000","0.11099","349.23880","0.00111","0.00102","34.92388","-0.00056"
"3.60000","0.11756","369.54584","0.00118","0.00108","36.95458","-0.00060"
"3.80000","0.12418","389.82184","0.00124","0.00115","38.98219","-0.00064"
"4.00000","0.13090","410.39191","0.00131","0.00121","41.03919","-0.00064"
"4.20000","0.13743","430.13190","0.00137","0.00127","43.01319","-0.00068"
"4.40000","0.14413","450.23743","0.00144","0.00133","45.02374","-0.00067"
"4.60000","0.15079","470.38416","0.00151","0.00140","47.03841","-0.00074"
"4.80000","0.15747","490.19208","0.00157","0.00149","49.01921","-0.00076"
"5.00000","0.16421","510.12445","0.00164","0.00155","51.01244","-0.00075"
"5.20000","0.17089","529.48218","0.00171","0.00163","52.94822","-0.00079"
"5.40000","0.17760","549.11548","0.00178","0.00168","54.91155","-0.00080"
"5.60000","0.18410","567.73071","0.00184","0.00171","56.77307","-0.00081"
"5.80000","0.19091","587.41589","0.00191","0.00175","58.74159","-0.00088"
"6.00000","0.19752","606.09503","0.00198","0.00178","60.60950","-0.00094"
"6.20000","0.20407","624.28448","0.00204","0.00186","62.42845","-0.00096"
"6.40000","0.21093","643.60907","0.00211","0.00192","64.36091","-0.00097"
"6.60000","0.21739","661.09381","0.00217","0.00194","66.10938","-0.00101"
"6.80000","0.22417","679.81732","0.00224","0.00199","67.98174","-0.00101"
"7.00000","0.23086","698.26099","0.00231","0.00205","69.82610","-0.00101"
"7.20000","0.23769","716.87079","0.00238","0.00207","71.68708","-0.00109"
"7.40000","0.24422","734.46936","0.00244","0.00217","73.44694","-0.00109"
"7.60000","0.25083","751.96844","0.00251","0.00227","75.19685","-0.00112"
"7.80000","0.25755","769.71722","0.00258","0.00238","76.97173","-0.00112"
"8.00000","0.26402","786.50879","0.00264","0.00246","78.65088","-0.00119"
"8.20000","0.27091","804.78473","0.00271","0.00249","80.47847","-0.00120"
"8.40000","0.27741","821.47845","0.00277","0.00257","82.14784","-0.00123"
"8.60000","0.28418","839.13708","0.00284","0.00261","83.91371","-0.00123"
"8.80000","0.29095","856.50830","0.00291","0.00263","85.65083","-0.00124"
"9.00000","0.29756","872.98694","0.00298","0.00265","87.29869","-0.00128"
"9.20000","0.30420","889.65454","0.00304","0.00270","88.96545","-0.00132"
"9.40000","0.31069","905.62024","0.00311","0.00270","90.56203","-0.00132"
"9.60000","0.31761","923.06976","0.00318","0.00272","92.30698","-0.00128"
"9.80000","0.32412","938.83484","0.00324","0.00278","93.88348","-0.00126"
"10.00000","0.33077","954.89874","0.00331","0.00277","95.48988","-0.00128"
"10.20000","0.33754","971.10413","0.00338","0.00279","97.11041","-0.00130"
"10.40000","0.34412","986.64453","0.00344","0.00286","98.66445","-0.00127"
"10.60000","0.35091","1002.87933","0.00351","0.00297","100.28793","-0.00131"
"10.80000","0.35753","1018.29785","0.00358","0.00304","101.82979","-0.00127"
"11.00000","0.36423","1033.89124","0.00364","0.00311","103.38912","-0.00132"
"11.20000","0.37085","1048.90918","0.00371","0.00322","104.89091","-0.00131"
"11.40000","0.37747","1063.84265","0.00377","0.00328","106.38426","-0.00131"
"11.60000","0.38416","1078.63965","0.00384","0.00332","107.86397","-0.00132"
"11.80000","0.39074","1093.17810","0.00391","0.00336","109.31781","-0.00130"
"12.00000","0.39755","1108.37891","0.00398","0.00343","110.83789","-0.00131"
"12.20000","0.40420","1122.69226","0.00404","0.00347","112.26923","-0.00134"
"12.40000","0.41082","1136.81262","0.00411","0.00349","113.68126","-0.00133"
"12.60000","0.41763","1151.59045","0.00418","0.00352","115.15904","-0.00138"
"12.80000","0.42412","1164.91553","0.00424","0.00354","116.49155","-0.00139"
"13.00000","0.43082","1178.96338","0.00431","0.00355","117.89634","-0.00139"
"13.20000","0.43744","1192.42639","0.00437","0.00354","119.24264","-0.00138"
"13.40000","0.44421","1206.66638","0.00444","0.00358","120.66664","-0.00137"
"13.60000","0.45088","1220.08521","0.00451","0.00362","122.00852","-0.00139"
"13.80000","0.45745","1233.06787","0.00457","0.00363","123.30679","-0.00142"
"14.00000","0.46424","1246.69128","0.00464","0.00364","124.66913","-0.00142"
"14.20000","0.47077","1259.32373","0.00471","0.00369","125.93237","-0.00142"
"14.40000","0.47763","1272.87866","0.00478","0.00376","127.28786","-0.00141"
"14.60000","0.48418","1285.09229","0.00484","0.00380","128.50923","-0.00144"
"14.80000","0.49080","1297.60974","0.00491","0.00388","129.76097","-0.00143"
"15.00000","0.49754","1310.53882","0.00498","0.00395","131.05388","-0.00142"
"15.20000","0.50412","1322.70227","0.00504","0.00404","132.27023","-0.00150"
"15.40000","0.51086","1335.30151","0.00511","0.00410","133.53015","-0.00148"
"15.60000","0.51742","1347.24939","0.00517","0.00415","134.72495","-0.00161"
"15.80000","0.52432","1360.32410","0.00524","0.00422","136.03241","-0.00169"
"16.00000","0.53086","1371.89050","0.00531","0.00423","137.18906","-0.00172"
"16.20000","0.53750","1383.62158","0.00538","0.00425","138.36215","-0.00176"
"16.40000","0.54420","1395.70496","0.00544","0.00428","139.57050","-0.00185"
"16.60000","0.55072","1406.88879","0.00551","0.00430","140.68887","-0.00191"
"16.80000","0.55752","1419.11792","0.00558","0.00431","141.91179","-0.00191"
"17.00000","0.56416","1430.73523","0.00564","0.00429","143.07352","-0.00195"
"17.20000","0.57087","1442.45850","0.00571","0.00429","144.24585","-0.00198"
"17.40000","0.57753","1454.26758","0.00578","0.00430","145.42676","-0.00202"
"17.60000","0.58417","1465.98511","0.00584","0.00428","146.59851","-0.00201"
"17.80000","0.59085","1477.80457","0.00591","0.00428","147.78046","-0.00204"
"18.00000","0.59744","1489.43225","0.00597","0.00435","148.94322","-0.00205"
"18.20000","0.60426","1501.65491","0.00604","0.00439","150.16550","-0.00203"
"18.40000","0.61080","1512.85889","0.00611","0.00445","151.28589","-0.00198"
"18.60000","0.61743","1524.19849","0.00617","0.00448","152.41985","-0.00198"
"18.80000","0.62425","1536.28406","0.00624","0.00456","153.62840","-0.00198"
"19.00000","0.63078","1546.98706","0.00631","0.00458","154.69870","-0.00198"
"19.20000","0.63748","1558.52588","0.00637","0.00466","155.85258","-0.00201"
"19.40000","0.64418","1569.77173","0.00644","0.00475","156.97717","-0.00191"
"19.60000","0.65093","1580.81506","0.00651","0.00480","158.08151","-0.00191"
"19.80000","0.65749","1591.50562","0.00657","0.00484","159.15056","-0.00195"
"20.00000","0.66412","1602.05176","0.00664","0.00490","160.20517","-0.00198"
"20.20000","0.67086","1612.99109","0.00671","0.00494","161.29910","-0.00199"
"20.40000","0.67735","1623.14087","0.00677","0.00501","162.31409","-0.00203"
"20.60000","0.68422","1634.43201","0.00684","0.00503","163.44321","-0.00202"
"20.80000","0.69083","1644.67712","0.00691","0.00506","164.46771","-0.00202"
"21.00000","0.69749","1655.02490","0.00697","0.00509","165.50249","-0.00198"
"21.20000","0.70434","1665.85596","0.00704","0.00512","166.58560","-0.00198"
"21.40000","0.71078","1675.05933","0.00711","0.00513","167.50594","-0.00193"
"21.60000","0.71745","1684.69922","0.00717","0.00518","168.46992","-0.00194"
"21.80000","0.72409","1694.35254","0.00724","0.00518","169.43526","-0.00191"
"22.00000","0.73094","1704.71057","0.00731","0.00521","170.47105","-0.00191"
"22.20000","0.73745","1713.54248","0.00737","0.00523","171.35425","-0.00191"
"22.40000","0.74414","1723.01013","0.00744","0.00523","172.30101","-0.00195"
"22.60000","0.75094","1732.74890","0.00751","0.00527","173.27489","-0.00194"
"22.80000","0.75741","1741.35901","0.00757","0.00533","174.13589","-0.00197"
"23.00000","0.76424","1751.33679","0.00764","0.00537","175.13368","-0.00195"
"23.20000","0.77079","1760.24512","0.00771","0.00540","176.02451","-0.00191"
"23.40000","0.77751","1769.28601","0.00778","0.00546","176.92860","-0.00191"
"23.60000","0.78418","1778.58496","0.00784","0.00553","177.85849","-0.00192"
"23.80000","0.79081","1787.70703","0.00791","0.00562","178.77071","-0.00192"
"24.00000","0.79746","1796.91968","0.00797","0.00566","179.69197","-0.00196"
"24.20000","0.80409","1806.09229","0.00804","0.00571","180.60922","-0.00195"
"24.40000","0.81094","1816.26562","0.00811","0.00576","181.62656","-0.00198"
"24.60000","0.81748","1825.17578","0.00817","0.00581","182.51758","-0.00199"
"24.80000","0.82416","1834.51733","0.00824","0.00585","183.45174","-0.00199"
"25.00000","0.83093","1844.34131","0.00831","0.00589","184.43413","-0.00194"
"25.20000","0.83746","1853.27441","0.00837","0.00589","185.32744","-0.00195"
"25.40000","0.84412","1862.76636","0.00844","0.00591","186.27664","-0.00200"
"25.60000","0.85080","1872.39124","0.00851","0.00591","187.23912","-0.00198"
"25.80000","0.85750","1882.18042","0.00857","0.00593","188.21805","-0.00199"
"26.00000","0.86420","1891.99524","0.00864","0.00592","189.19952","-0.00206"
"26.20000","0.87080","1901.33752","0.00871","0.00592","190.13376","-0.00202"
"26.40000","0.87758","1911.34741","0.00878","0.00594","191.13474","-0.00199"
"26.60000","0.88407","1920.38660","0.00884","0.00594","192.03867","-0.00206"
"26.80000","0.89092","1930.83691","0.00891","0.00596","193.08369","-0.00206"
"27.00000","0.89750","1940.23511","0.00897","0.00599","194.02351","-0.00206"
"27.20000","0.90411","1949.73523","0.00904","0.00604","194.97353","-0.00210"
"27.40000","0.91089","1959.91248","0.00911","0.00609","195.99124","-0.00209"
"27.60000","0.91742","1969.22253","0.00917","0.00613","196.92226","-0.00208"
"27.80000","0.92416","1979.25305","0.00924","0.00617","197.92531","-0.00206"
"28.00000","0.93077","1988.84265","0.00931","0.00621","198.88426","-0.00202"
"28.20000","0.93762","1999.30969","0.00938","0.00625","199.93097","-0.00206"
"28.40000","0.94416","2008.48193","0.00944","0.00630","200.84819","-0.00206"
"28.60000","0.95076","2018.02222","0.00951","0.00635","201.80222","-0.00206"
"28.80000","0.95760","2028.50757","0.00958","0.00639","202.85075","-0.00207"
"29.00000","0.96404","2037.36218","0.00964","0.00641","203.73622","-0.00206"
"29.20000","0.97086","2047.59839","0.00971","0.00642","204.75984","-0.00210"
"29.40000","0.97745","2057.15918","0.00977","0.00642","205.71591","-0.00210"
"29.60000","0.98425","2067.35571","0.00984","0.00641","206.73557","-0.00213"
"29.80000","0.99080","2076.70093","0.00991","0.00641","207.67009","-0.00210"
"30.00000","0.99748","2086.36475","0.00997","0.00642","208.63647","-0.00211"
"30.20000","1.00417","2096.10547","0.01004","0.00643","209.61055","-0.00212"
"30.40000","1.01073","2105.31909","0.01011","0.00643","210.53191","-0.00217"
"30.60000","1.01763","2115.65869","0.01018","0.00643","211.56587","-0.00217"
"30.80000","1.02411","2124.71143","0.01024","0.00641","212.47115","-0.00214"
"31.00000","1.03078","2134.28955","0.01031","0.00648","213.42896","-0.00224"
"31.20000","1.03754","2144.41968","0.01038","0.00648","214.44197","-0.00219"
"31.40000","1.04412","2153.71362","0.01044","0.00653","215.37137","-0.00223"
"31.60000","1.05077","2163.26465","0.01051","0.00658","216.32646","-0.00225"
"31.80000","1.05750","2173.12964","0.01057","0.00663","217.31296","-0.00225"
"32.00000","1.06420","2182.68774","0.01064","0.00669","218.26877","-0.00228"
"32.20000","1.07083","2192.18945","0.01071","0.00675","219.21895","-0.00229"
"32.40000","1.07749","2201.66626","0.01077","0.00681","220.16663","-0.00232"
"32.60000","1.08416","2211.13794","0.01084","0.00685","221.11380","-0.00229"
"32.80000","1.09076","2220.31641","0.01091","0.00689","222.03165","-0.00228"
"33.00000","1.09753","2230.10864","0.01098","0.00689","223.01086","-0.00227"
"33.20000","1.10421","2239.71802","0.01104","0.00691","223.97180","-0.00225"
"33.40000","1.11074","2248.58130","0.01111","0.00693","224.85812","-0.00226"
"33.60000","1.11759","2258.47314","0.01118","0.00694","225.84732","-0.00228"
"33.80000","1.12408","2267.15576","0.01124","0.00695","226.71558","-0.00229"
"34.00000","1.13083","2276.81665","0.01131","0.00693","227.68167","-0.00229"
"34.20000","1.13748","2286.11304","0.01137","0.00695","228.61130","-0.00232"
"34.40000","1.14426","2295.89136","0.01144","0.00696","229.58914","-0.00236"
"34.60000","1.15085","2305.10303","0.01151","0.00694","230.51030","-0.00236"
"34.80000","1.15740","2314.00244","0.01157","0.00696","231.40024","-0.00235"
"35.00000","1.16431","2324.25098","0.01164","0.00698","232.42509","-0.00236"
"35.20000","1.17067","2332.42358","0.01171","0.00704","233.24236","-0.00240"
"35.40000","1.17749","2341.80518","0.01177","0.00711","234.18051","-0.00247"
"35.60000","1.18411","2350.96094","0.01184","0.00717","235.09610","-0.00247"
"35.80000","1.19086","2360.45264","0.01191","0.00721","236.04526","-0.00251"
"36.00000","1.19763","2370.16675","0.01198","0.00727","237.01668","-0.00250"
"36.20000","1.20415","2379.06592","0.01204","0.00732","237.90659","-0.00255"
"36.40000","1.21081","2388.29883","0.01211","0.00740","238.82988","-0.00255"
"36.60000","1.21738","2397.31250","0.01217","0.00745","239.73125","-0.00255"
"36.80000","1.22435","2407.51367","0.01224","0.00747","240.75137","-0.00250"
"37.00000","1.23076","2415.69067","0.01231","0.00745","241.56906","-0.00251"
"37.20000","1.23741","2424.68115","0.01237","0.00750","242.46811","-0.00247"
"37.40000","1.24422","2434.44873","0.01244","0.00749","243.44487","-0.00250"
"37.60000","1.25077","2443.10474","0.01251","0.00749","244.31047","-0.00246"
"37.80000","1.25756","2452.65723","0.01258","0.00747","245.26572","-0.00247"
"38.00000","1.26416","2461.55151","0.01264","0.00749","246.15515","-0.00251"
"38.20000","1.27090","2470.82886","0.01271","0.00747","247.08289","-0.00254"
"38.40000","1.27752","2479.80029","0.01278","0.00748","247.98003","-0.00251"
"38.60000","1.28420","2488.89404","0.01284","0.00747","248.88940","-0.00255"
"38.80000","1.29078","2497.91724","0.01291","0.00753","249.79172","-0.00255"
"39.00000","1.29739","2506.77637","0.01297","0.00758","250.67764","-0.00257"
"39.20000","1.30422","2516.72144","0.01304","0.00764","251.67215","-0.00258"
"39.40000","1.31082","2525.50195","0.01311","0.00772","252.55020","-0.00262"
"39.60000","1.31751","2534.63745","0.01318","0.00780","253.46375","-0.00264"
"39.80000","1.32431","2544.23999","0.01324","0.00786","254.42400","-0.00266"
"40.00000","1.33082","2552.64697","0.01331","0.00793","255.26469","-0.00271"
"40.20000","1.33744","2561.66821","0.01337","0.00796","256.16681","-0.00273"
"40.40000","1.34416","2570.87207","0.01344","0.00799","257.08722","-0.00273"
"40.60000","1.35089","2580.16431","0.01351","0.00803","258.01642","-0.00271"
"40.80000","1.35747","2588.88257","0.01357","0.00805","258.88824","-0.00269"
"41.00000","1.36405","2597.45264","0.01364","0.00807","259.74527","-0.00270"
"41.20000","1.37093","2607.13672","0.01371","0.00808","260.71368","-0.00270"
"41.40000","1.37744","2615.43848","0.01377","0.00807","261.54385","-0.00273"
"41.60000","1.38428","2624.91602","0.01384","0.00807","262.49161","-0.00274"
"41.80000","1.39086","2633.52686","0.01391","0.00807","263.35269","-0.00275"
"42.00000","1.39749","2642.25342","0.01397","0.00805","264.22534","-0.00273"
"42.20000","1.40430","2651.53369","0.01404","0.00808","265.15338","-0.00276"
"42.40000","1.41074","2659.23975","0.01411","0.00809","265.92398","-0.00277"
"42.60000","1.41744","2667.90479","0.01417","0.00817","266.79047","-0.00275"
"42.80000","1.42398","2676.18359","0.01424","0.00825","267.61835","-0.00274"
"43.00000","1.43099","2685.95508","0.01431","0.00830","268.59552","-0.00270"
"43.20000","1.43756","2693.94556","0.01438","0.00840","269.39456","-0.00273"
"43.40000","1.44418","2702.06421","0.01444","0.00851","270.20642","-0.00276"
"43.60000","1.45098","2710.96436","0.01451","0.00856","271.09644","-0.00281"
"43.80000","1.45744","2718.34106","0.01457","0.00861","271.83411","-0.00279"
"44.00000","1.46417","2727.02954","0.01464","0.00863","272.70294","-0.00280"
"44.20000","1.47074","2735.12891","0.01471","0.00866","273.51288","-0.00287"
"44.40000","1.47752","2743.90015","0.01478","0.00866","274.39001","-0.00288"
"44.60000","1.48414","2752.17554","0.01484","0.00865","275.21756","-0.00288"
"44.80000","1.49082","2760.21582","0.01491","0.00865","276.02158","-0.00288"
"45.00000","1.49756","2768.52612","0.01498","0.00862","276.85260","-0.00288"
"45.20000","1.50414","2776.52173","0.01504","0.00861","277.65216","-0.00281"
"45.40000","1.51101","2785.68286","0.01511","0.00863","278.56830","-0.00285"
"45.60000","1.51749","2793.49365","0.01517","0.00861","279.34937","-0.00288"
"45.80000","1.52412","2801.72485","0.01524","0.00865","280.17249","-0.00288"
"46.00000","1.53084","2810.41724","0.01531","0.00870","281.04172","-0.00290"
"46.20000","1.53745","2818.65161","0.01537","0.00876","281.86517","-0.00296"
"46.40000","1.54411","2827.00610","0.01544","0.00882","282.70062","-0.00292"
"46.60000","1.55082","2835.60059","0.01551","0.00887","283.56006","-0.00292"
"46.80000","1.55763","2844.39966","0.01558","0.00891","284.43997","-0.00291"
"47.00000","1.56426","2852.62769","0.01564","0.00896","285.26276","-0.00295"
"47.20000","1.57081","2860.76416","0.01571","0.00898","286.07642","-0.00296"
"47.40000","1.57755","2869.60156","0.01578","0.00902","286.96014","-0.00298"
"47.60000","1.58411","2877.53271","0.01584","0.00904","287.75327","-0.00295"
"47.80000","1.59084","2886.32886","0.01591","0.00902","288.63287","-0.00300"
"48.00000","1.59748","2894.78833","0.01597","0.00902","289.47882","-0.00295"
"48.20000","1.60407","2902.80591","0.01604","0.00903","290.28058","-0.00294"
"48.40000","1.61094","2912.06714","0.01611","0.00905","291.20673","-0.00292"
"48.60000","1.61750","2920.04614","0.01617","0.00905","292.00461","-0.00288"
"48.80000","1.62426","2928.80005","0.01624","0.00907","292.88000","-0.00290"
"49.00000","1.63079","2936.68042","0.01631","0.00909","293.66803","-0.00299"
"49.20000","1.63762","2945.59277","0.01638","0.00913","294.55927","-0.00297"
"49.40000","1.64418","2953.65015","0.01644","0.00921","295.36502","-0.00300"
"49.60000","1.65073","2961.63965","0.01651","0.00926","296.16397","-0.00301"
"49.80000","1.65759","2970.60376","0.01658","0.00933","297.06036","-0.00301"
"50.00000","1.66401","2978.10913","0.01664","0.00937","297.81091","-0.00303"
"50.20000","1.67084","2987.08325","0.01671","0.00940","298.70831","-0.00303"
"50.40000","1.67751","2995.46094","0.01678","0.00941","299.54608","-0.00306"
"50.60000","1.68434","3004.52832","0.01684","0.00946","300.45282","-0.00311"
"50.80000","1.69095","3012.79980","0.01691","0.00946","301.27997","-0.00311"
"51.00000","1.69748","3020.67725","0.01697","0.00949","302.06772","-0.00311"
"51.20000","1.70413","3029.13550","0.01704","0.00950","302.91354","-0.00311"
"51.40000","1.71066","3037.18408","0.01711","0.00953","303.71841","-0.00315"
"51.60000","1.71765","3046.64331","0.01718","0.00956","304.66434","-0.00318"
"51.80000","1.72411","3054.30200","0.01724","0.00961","305.43021","-0.00317"
"52.00000","1.73081","3062.74609","0.01731","0.00961","306.27460","-0.00313"
"52.20000","1.73763","3071.82764","0.01738","0.00967","307.18277","-0.00314"
"52.40000","1.74420","3079.91284","0.01744","0.00972","307.99127","-0.00315"
"52.60000","1.75087","3088.49341","0.01751","0.00974","308.84933","-0.00322"
"52.80000","1.75744","3096.70752","0.01757","0.00978","309.67075","-0.00326"
"53.00000","1.76425","3105.43701","0.01764","0.00984","310.54370","-0.00326"
"53.20000","1.77080","3113.36304","0.01771","0.00987","311.33630","-0.00323"
"53.40000","1.77748","3121.68188","0.01777","0.00988","312.16818","-0.00329"
"53.60000","1.78418","3130.06372","0.01784","0.00989","313.00638","-0.00333"
"53.80000","1.79075","3138.16919","0.01791","0.00992","313.81693","-0.00330"
"54.00000","1.79759","3147.09570","0.01798","0.00996","314.70956","-0.00332"
"54.20000","1.80424","3155.22583","0.01804","0.00995","315.52258","-0.00333"
"54.40000","1.81088","3163.40112","0.01811","0.00998","316.34012","-0.00341"
"54.60000","1.81755","3171.76392","0.01818","0.00999","317.17639","-0.00339"
"54.80000","1.82415","3179.71606","0.01824","0.01006","317.97162","-0.00338"
"55.00000","1.83079","3187.89893","0.01831","0.01007","318.78989","-0.00339"
"55.20000","1.83741","3196.16235","0.01837","0.01014","319.61624","-0.00343"
"55.40000","1.84422","3205.06104","0.01844","0.01019","320.50610","-0.00342"
"55.60000","1.85085","3213.30396","0.01851","0.01025","321.33038","-0.00346"
"55.80000","1.85749","3221.39600","0.01857","0.01030","322.13959","-0.00345"
"56.00000","1.86435","3229.90039","0.01864","0.01032","322.99005","-0.00348"
"56.20000","1.87077","3237.13354","0.01871","0.01036","323.71335","-0.00354"
"56.40000","1.87748","3245.63525","0.01877","0.01040","324.56354","-0.00354"
"56.60000","1.88411","3253.95679","0.01884","0.01041","325.39569","-0.00356"
"56.80000","1.89085","3262.42041","0.01891","0.01043","326.24203","-0.00363"
"57.00000","1.89756","3270.97583","0.01898","0.01045","327.09760","-0.00365"
"57.20000","1.90413","3278.92334","0.01904","0.01045","327.89233","-0.00363"
"57.40000","1.91089","3287.70581","0.01911","0.01047","328.77057","-0.00370"
"57.60000","1.91738","3295.56421","0.01917","0.01050","329.55643","-0.00369"
"57.80000","1.92436","3305.07861","0.01924","0.01056","330.50787","-0.00366"
"58.00000","1.93085","3312.99072","0.01931","0.01062","331.29907","-0.00363"
"58.20000","1.93745","3321.05908","0.01937","0.01071","332.10590","-0.00369"
"58.40000","1.94424","3330.07007","0.01944","0.01075","333.00702","-0.00374"
"58.60000","1.95078","3337.96826","0.01951","0.01083","333.79681","-0.00378"
"58.80000","1.95754","3346.67236","0.01958","0.01090","334.66724","-0.00382"
"59.00000","1.96408","3354.78418","0.01964","0.01093","335.47842","-0.00380"
"59.20000","1.97095","3363.99365","0.01971","0.01096","336.39935","-0.00380"
"59.40000","1.97752","3372.19873","0.01978","0.01099","337.21988","-0.00382"
"59.60000","1.98419","3380.55981","0.01984","0.01101","338.05597","-0.00387"
"59.80000","1.99090","3388.91382","0.01991","0.01101","338.89139","-0.00389"
"60.00000","1.99738","3396.48242","0.01997","0.01101","339.64825","-0.00393"
"60.20000","2.00416","3405.23047","0.02004","0.01104","340.52304","-0.00395"
"60.40000","2.01085","3413.52271","0.02011","0.01103","341.35226","-0.00393"
"60.60000","2.01747","3421.82300","0.02017","0.01107","342.18231","-0.00393"
"60.80000","2.02422","3430.18774","0.02024","0.01109","343.01877","-0.00397"
"61.00000","2.03081","3438.02539","0.02031","0.01114","343.80255","-0.00397"
"61.20000","2.03753","3446.12256","0.02038","0.01119","344.61224","-0.00403"
"61.40000","2.04414","3454.02319","0.02044","0.01126","345.40231","-0.00403"
"61.60000","2.05092","3462.70581","0.02051","0.01134","346.27057","-0.00399"
"61.80000","2.05749","3470.62695","0.02057","0.01140","347.06268","-0.00405"
"62.00000","2.06406","3478.49731","0.02064","0.01147","347.84973","-0.00401"
"62.20000","2.07094","3487.65503","0.02071","0.01150","348.76550","-0.00404"
"62.40000","2.07741","3495.27979","0.02077","0.01153","349.52798","-0.00404"
"62.60000","2.08419","3503.91528","0.02084","0.01157","350.39154","-0.00405"
"62.80000","2.09087","3512.12354","0.02091","0.01157","351.21234","-0.00412"
"63.00000","2.09755","3520.61475","0.02098","0.01159","352.06146","-0.00419"
"63.20000","2.10418","3528.87695","0.02104","0.01159","352.88770","-0.00420"
"63.40000","2.11079","3536.80151","0.02111","0.01155","353.68015","-0.00423"
"63.60000","2.11753","3545.37915","0.02118","0.01161","354.53790","-0.00423"
"63.80000","2.12403","3552.77954","0.02124","0.01164","355.27795","-0.00419"
"64.00000","2.13090","3561.01123","0.02131","0.01168","356.10114","-0.00423"
"64.20000","2.13749","3568.99658","0.02137","0.01173","356.89966","-0.00423"
"64.40000","2.14414","3577.20898","0.02144","0.01180","357.72089","-0.00422"
"64.60000","2.15098","3586.19434","0.02151","0.01188","358.61945","-0.00421"
"64.80000","2.15743","3593.14038","0.02157","0.01194","359.31403","-0.00419"
"65.00000","2.16415","3601.68042","0.02164","0.01198","360.16803","-0.00419"
"65.20000","2.17080","3609.66406","0.02171","0.01204","360.96640","-0.00423"
"65.40000","2.17758","3617.83276","0.02178","0.01208","361.78326","-0.00430"
"65.60000","2.18413","3625.00317","0.02184","0.01211","362.50031","-0.00426"
"65.80000","2.19080","3632.94263","0.02191","0.01211","363.29425","-0.00432"
"66.00000","2.19755","3641.62842","0.02198","0.01209","364.16284","-0.00434"
"66.20000","2.20407","3649.29297","0.02204","0.01209","364.92929","-0.00436"
"66.40000","2.21095","3658.24316","0.02211","0.01210","365.82431","-0.00435"
"66.60000","2.21749","3666.08765","0.02217","0.01209","366.60876","-0.00438"
"66.80000","2.22415","3674.16553","0.02224","0.01212","367.41656","-0.00438"
"67.00000","2.23088","3682.83472","0.02231","0.01213","368.28348","-0.00440"
"67.20000","2.23744","3690.55298","0.02237","0.01221","369.05530","-0.00443"
"67.40000","2.24410","3698.99097","0.02244","0.01226","369.89911","-0.00442"
"67.60000","2.25078","3707.48071","0.02251","0.01230","370.74808","-0.00442"
"67.80000","2.25764","3716.58398","0.02258","0.01238","371.65839","-0.00443"
"68.00000","2.26419","3724.65356","0.02264","0.01245","372.46536","-0.00442"
"68.20000","2.27079","3732.48633","0.02271","0.01251","373.24863","-0.00445"
"68.40000","2.27759","3741.37085","0.02278","0.01254","374.13708","-0.00447"
"68.60000","2.28409","3749.31470","0.02284","0.01253","374.93146","-0.00446"
"68.80000","2.29080","3757.74097","0.02291","0.01256","375.77411","-0.00447"
"69.00000","2.29746","3765.94287","0.02297","0.01257","376.59430","-0.00456"
"69.20000","2.30417","3773.94409","0.02304","0.01257","377.39441","-0.00457"
"69.40000","2.31092","3782.46680","0.02311","0.01255","378.24667","-0.00461"
"69.60000","2.31743","3790.13599","0.02317","0.01254","379.01361","-0.00459"
"69.80000","2.32418","3798.80811","0.02324","0.01258","379.88080","-0.00460"
"70.00000","2.33074","3806.76733","0.02331","0.01258","380.67673","-0.00459"
"70.20000","2.33763","3815.98779","0.02338","0.01264","381.59879","-0.00462"
"70.40000","2.34416","3823.60742","0.02344","0.01268","382.36075","-0.00460"
"70.60000","2.35074","3831.63062","0.02351","0.01271","383.16306","-0.00461"
"70.80000","2.35757","3840.52100","0.02358","0.01278","384.05209","-0.00461"
"71.00000","2.36405","3848.15698","0.02364","0.01287","384.81570","-0.00462"
"71.20000","2.37082","3856.87549","0.02371","0.01291","385.68756","-0.00462"
"71.40000","2.37743","3865.07666","0.02377","0.01294","386.50766","-0.00465"
"71.60000","2.38427","3873.61279","0.02384","0.01299","387.36127","-0.00472"
"71.80000","2.39089","3881.64746","0.02391","0.01298","388.16473","-0.00468"
"72.00000","2.39743","3889.35693","0.02397","0.01301","388.93570","-0.00472"
"72.20000","2.40417","3897.80078","0.02404","0.01302","389.78009","-0.00474"
"72.40000","2.41067","3905.47925","0.02411","0.01300","390.54791","-0.00476"
"72.60000","2.41755","3914.73315","0.02418","0.01301","391.47333","-0.00479"
"72.80000","2.42412","3922.54883","0.02424","0.01301","392.25488","-0.00479"
"73.00000","2.43090","3931.11816","0.02431","0.01306","393.11182","-0.00480"
"73.20000","2.43753","3939.11938","0.02438","0.01310","393.91193","-0.00482"
"73.40000","2.44415","3947.08447","0.02444","0.01315","394.70844","-0.00479"
"73.60000","2.45083","3955.08081","0.02451","0.01319","395.50809","-0.00481"
"73.80000","2.45740","3962.71021","0.02457","0.01324","396.27103","-0.00483"
"74.00000","2.46429","3971.58569","0.02464","0.01326","397.15857","-0.00485"
"74.20000","2.47080","3979.32690","0.02471","0.01330","397.93268","-0.00484"
"74.40000","2.47745","3987.44482","0.02477","0.01332","398.74448","-0.00488"
"74.60000","2.48421","3996.05322","0.02484","0.01336","399.60532","-0.00487"
"74.80000","2.49077","4004.05298","0.02491","0.01338","400.40530","-0.00487"
"75.00000","2.49746","4012.07617","0.02497","0.01340","401.20761","-0.00484"
"75.20000","2.50418","4020.01782","0.02504","0.01340","402.00177","-0.00486"
"75.40000","2.51087","4028.08643","0.02511","0.01338","402.80865","-0.00496"
"75.60000","2.51755","4035.83569","0.02518","0.01338","403.58356","-0.00498"
"75.80000","2.52415","4043.63867","0.02524","0.01341","404.36386","-0.00501"
"76.00000","2.53079","4051.60107","0.02531","0.01345","405.16010","-0.00502"
"76.20000","2.53743","4059.84937","0.02537","0.01350","405.98492","-0.00506"
"76.40000","2.54423","4068.49829","0.02544","0.01356","406.84982","-0.00503"
"76.60000","2.55085","4076.80347","0.02551","0.01359","407.68036","-0.00504"
"76.80000","2.55742","4084.48291","0.02557","0.01363","408.44830","-0.00502"
"77.00000","2.56428","4093.18628","0.02564","0.01367","409.31863","-0.00506"
"77.20000","2.57075","4100.57031","0.02571","0.01372","410.05704","-0.00504"
"77.40000","2.57753","4109.01270","0.02578","0.01378","410.90128","-0.00501"
"77.60000","2.58418","4117.01416","0.02584","0.01382","411.70142","-0.00501"
"77.80000","2.59090","4125.62109","0.02591","0.01383","412.56210","-0.00508"
"78.00000","2.59749","4133.97559","0.02597","0.01390","413.39755","-0.00512"
"78.20000","2.60409","4141.98926","0.02604","0.01394","414.19891","-0.00513"
"78.40000","2.61092","4151.02783","0.02611","0.01397","415.10278","-0.00517"
"78.60000","2.61736","4158.65967","0.02617","0.01399","415.86597","-0.00517"
"78.80000","2.62420","4167.83252","0.02624","0.01403","416.78326","-0.00521"
"79.00000","2.63079","4175.81152","0.02631","0.01409","417.58115","-0.00524"
"79.20000","2.63750","4184.37305","0.02637","0.01414","418.43732","-0.00523"
"79.40000","2.64429","4193.41602","0.02644","0.01421","419.34161","-0.00527"
"79.60000","2.65075","4200.97803","0.02651","0.01427","420.09781","-0.00527"
"79.80000","2.65745","4209.48291","0.02657","0.01431","420.94830","-0.00520"
"80.00000","2.66410","4218.08887","0.02664","0.01438","421.80890","-0.00522"
"80.20000","2.67101","4227.40332","0.02671","0.01440","422.74033","-0.00525"
"80.40000","2.67740","4234.37744","0.02677","0.01444","423.43774","-0.00523"
"80.60000","2.68405","4242.91357","0.02684","0.01446","424.29135","-0.00526"
"80.80000","2.69089","4251.82275","0.02691","0.01448","425.18228","-0.00529"
"81.00000","2.69741","4259.65771","0.02697","0.01449","425.96576","-0.00532"
"81.20000","2.70424","4268.73584","0.02704","0.01450","426.87360","-0.00535"
"81.40000","2.71082","4276.69873","0.02711","0.01453","427.66986","-0.00535"
"81.60000","2.71753","4285.27539","0.02718","0.01455","428.52753","-0.00540"
"81.80000","2.72419","4293.70312","0.02724","0.01459","429.37030","-0.00541"
"82.00000","2.73084","4301.62256","0.02731","0.01465","430.16226","-0.00543"
"82.20000","2.73741","4309.53564","0.02737","0.01470","430.95355","-0.00539"
"82.40000","2.74407","4317.83252","0.02744","0.01478","431.78326","-0.00539"
"82.60000","2.75093","4326.70215","0.02751","0.01483","432.67023","-0.00537"
"82.80000","2.75751","4334.61670","0.02758","0.01487","433.46167","-0.00539"
"83.00000","2.76414","4342.59521","0.02764","0.01487","434.25952","-0.00539"
"83.20000","2.77097","4351.31006","0.02771","0.01493","435.13101","-0.00538"
"83.40000","2.77744","4358.71436","0.02777","0.01495","435.87143","-0.00539"
"83.60000","2.78414","4366.80713","0.02784","0.01496","436.68073","-0.00543"
"83.80000","2.79083","4375.02295","0.02791","0.01496","437.50229","-0.00542"
"84.00000","2.79754","4383.28369","0.02798","0.01497","438.32837","-0.00545"
"84.20000","2.80417","4391.34619","0.02804","0.01500","439.13461","-0.00547"
"84.40000","2.81074","4399.13281","0.02811","0.01503","439.91327","-0.00554"
"84.60000","2.81756","4407.61572","0.02818","0.01509","440.76157","-0.00558"
"84.80000","2.82411","4415.32617","0.02824","0.01513","441.53262","-0.00562"
"85.00000","2.83097","4423.58643","0.02831","0.01519","442.35864","-0.00567"
"85.20000","2.83755","4430.98926","0.02838","0.01529","443.09894","-0.00562"
"85.40000","2.84413","4438.70898","0.02844","0.01537","443.87091","-0.00565"
"85.60000","2.85099","4447.17090","0.02851","0.01546","444.71710","-0.00569"
"85.80000","2.85738","4454.06006","0.02857","0.01553","445.40601","-0.00572"
"86.00000","2.86409","4462.32812","0.02864","0.01554","446.23282","-0.00571"
"86.20000","2.87070","4470.10693","0.02871","0.01556","447.01068","-0.00569"
"86.40000","2.87763","4479.04736","0.02878","0.01554","447.90472","-0.00571"
"86.60000","2.88422","4486.87061","0.02884","0.01556","448.68707","-0.00569"
"86.80000","2.89089","4494.96924","0.02891","0.01557","449.49692","-0.00573"
"87.00000","2.89762","4503.07080","0.02898","0.01556","450.30707","-0.00575"
"87.20000","2.90406","4510.03467","0.02904","0.01558","451.00348","-0.00578"
"87.40000","2.91086","4518.12549","0.02911","0.01561","451.81256","-0.00580"
"87.60000","2.91741","4525.16748","0.02917","0.01563","452.51675","-0.00587"
"87.80000","2.92414","4531.87988","0.02924","0.01569","453.18799","-0.00587"
"88.00000","2.93086","4539.03271","0.02931","0.01577","453.90326","-0.00586"
"88.20000","2.93749","4545.76807","0.02937","0.01585","454.57681","-0.00584"
"88.40000","2.94420","4552.57129","0.02944","0.01591","455.25714","-0.00589"
"88.60000","2.95079","4557.71045","0.02951","0.01601","455.77106","-0.00591"
"88.80000","2.95768","4564.62744","0.02958","0.01606","456.46274","-0.00596"
"89.00000","2.96415","4570.75000","0.02964","0.01611","457.07501","-0.00600"
"89.20000","2.97078","4576.73730","0.02971","0.01614","457.67374","-0.00607"
"89.40000","2.97751","4582.86426","0.02978","0.01617","458.28644","-0.00610"
"89.60000","2.98409","4588.92627","0.02984","0.01619","458.89264","-0.00606"
"89.80000","2.99079","4595.21387","0.02991","0.01619","459.52139","-0.00610"
"90.00000","2.99749","4601.80811","0.02997","0.01621","460.18082","-0.00610"
"90.20000","3.00426","4608.78369","0.03004","0.01617","460.87836","-0.00611"
"90.40000","3.01095","4615.42480","0.03011","0.01618","461.54248","-0.00614"
"90.60000","3.01752","4621.97168","0.03018","0.01615","462.19717","-0.00617"
"90.80000","3.02420","4628.57910","0.03024","0.01615","462.85791","-0.00619"
"91.00000","3.03072","4634.17383","0.03031","0.01618","463.41739","-0.00622"
"91.20000","3.03754","4640.66309","0.03038","0.01624","464.06631","-0.00625"
"91.40000","3.04415","4646.38232","0.03044","0.01632","464.63824","-0.00627"
"91.60000","3.05072","4651.87061","0.03051","0.01638","465.18707","-0.00632"
"91.80000","3.05763","4659.10645","0.03058","0.01645","465.91064","-0.00633"
"92.00000","3.06417","4664.41406","0.03064","0.01649","466.44141","-0.00641"
"92.20000","3.07094","4670.68311","0.03071","0.01654","467.06830","-0.00643"
"92.40000","3.07747","4676.13037","0.03077","0.01658","467.61304","-0.00640"
"92.60000","3.08428","4682.66699","0.03084","0.01665","468.26669","-0.00645"
"92.80000","3.09087","4688.11816","0.03091","0.01664","468.81183","-0.00643"
"93.00000","3.09739","4691.98633","0.03097","0.01668","469.19864","-0.00645"
"93.20000","3.10424","4696.72949","0.03104","0.01673","469.67294","-0.00648"
"93.40000","3.11066","4697.97949","0.03111","0.01669","469.79794","-0.00648"
"93.60000","3.11757","4701.56738","0.03118","0.01669","470.15674","-0.00648"
"93.80000","3.12421","4700.73633","0.03124","0.01670","470.07364","-0.00644"
"94.00000","3.13096","4695.60498","0.03131","0.01669","469.56049","-0.00648"
"94.20000","3.13763","4672.14111","0.03138","0.01669","467.21411","-0.00659"
"94.23400","3.13874","4383.60986","0.03139","0.01669","438.36099","-0.00659"
"94.23800","3.13886","3982.77197","0.03139","0.01669","398.27719","-0.00659"
"94.24100","3.13895","3619.76172","0.03139","0.01669","361.97617","-0.00659"
"94.24300","3.13902","3361.28516","0.03139","0.01669","336.12851","-0.00659"
"94.24500","3.13909","3096.35693","0.03139","0.01669","309.63568","-0.00659"
"94.24700","3.13917","2829.85400","0.03139","0.01669","282.98541","-0.00659"
"94.24800","3.13921","2697.31421","0.03139","0.01669","269.73141","-0.00659"