File: Tension/Section_1_Group_2/PEanut_5%_2.is_tens_RawData/Specimen_RawData_1.csv
Time,Extension,Load,Tensile strain (Extension),Tensile stress,Strain-by-clip-gage
(s),(mm),(N),(mm/mm),(MPa),(mm/mm)
"0.00000","0.00000","-8.71419","0.00000","-0.87142","-0.00002"
"0.20000","0.00091","-7.26130","0.00001","-0.72613","-0.00001"
"0.40000","0.00463","-0.84125","0.00005","-0.08412","0.00001"
"0.60000","0.00849","5.98241","0.00008","0.59824","0.00003"
"0.80000","0.01183","11.95748","0.00012","1.19575","0.00005"
"1.00000","0.01508","17.60517","0.00015","1.76052","0.00008"
"1.20000","0.01827","23.28349","0.00018","2.32835","0.00011"
"1.40000","0.02173","29.36354","0.00022","2.93635","0.00014"
"1.60000","0.02507","35.36502","0.00025","3.53650","0.00017"
"1.80000","0.02843","41.25772","0.00028","4.12577","0.00020"
"2.00000","0.03177","47.08223","0.00032","4.70822","0.00022"
"2.20000","0.03506","52.85640","0.00035","5.28564","0.00026"
"2.40000","0.03830","58.45699","0.00038","5.84570","0.00029"
"2.60000","0.04155","64.07055","0.00042","6.40705","0.00032"
"2.80000","0.04517","70.43262","0.00045","7.04326","0.00035"
"3.00000","0.04854","76.10777","0.00049","7.61078","0.00038"
"3.20000","0.05185","81.91406","0.00052","8.19141","0.00041"
"3.40000","0.05507","87.37882","0.00055","8.73788","0.00044"
"3.60000","0.05826","92.76941","0.00058","9.27694","0.00047"
"3.80000","0.06167","98.43549","0.00062","9.84355","0.00050"
"4.00000","0.06497","103.98924","0.00065","10.39892","0.00053"
"4.20000","0.06860","110.16666","0.00069","11.01667","0.00057"
"4.40000","0.07190","115.69797","0.00072","11.56980","0.00060"
"4.60000","0.07514","121.09038","0.00075","12.10904","0.00063"
"4.80000","0.07830","126.28081","0.00078","12.62808","0.00065"
"5.00000","0.08162","131.87231","0.00082","13.18723","0.00068"
"5.20000","0.08496","137.36040","0.00085","13.73604","0.00071"
"5.40000","0.08835","142.84305","0.00088","14.28430","0.00074"
"5.60000","0.09195","148.82922","0.00092","14.88292","0.00077"
"5.80000","0.09516","154.08365","0.00095","15.40837","0.00080"
"6.00000","0.09837","159.08347","0.00098","15.90835","0.00083"
"6.20000","0.10160","164.24812","0.00102","16.42481","0.00086"
"6.40000","0.10500","169.81799","0.00105","16.98180","0.00089"
"6.60000","0.10839","175.17741","0.00108","17.51774","0.00092"
"6.80000","0.11178","180.57361","0.00112","18.05736","0.00095"
"7.00000","0.11520","186.11241","0.00115","18.61124","0.00098"
"7.20000","0.11837","191.01933","0.00118","19.10193","0.00100"
"7.40000","0.12167","196.16443","0.00122","19.61644","0.00103"
"7.60000","0.12501","201.41472","0.00125","20.14147","0.00106"
"7.80000","0.12853","207.02003","0.00129","20.70200","0.00109"
"8.00000","0.13179","212.18904","0.00132","21.21890","0.00112"
"8.20000","0.13510","217.20726","0.00135","21.72073","0.00115"
"8.40000","0.13838","222.18758","0.00138","22.21876","0.00117"
"8.60000","0.14165","227.34953","0.00142","22.73495","0.00120"
"8.80000","0.14497","232.42093","0.00145","23.24209","0.00123"
"9.00000","0.14840","237.63380","0.00148","23.76338","0.00126"
"9.20000","0.15193","243.26559","0.00152","24.32656","0.00129"
"9.40000","0.15518","248.26517","0.00155","24.82652","0.00131"
"9.60000","0.15838","252.90176","0.00158","25.29018","0.00134"
"9.80000","0.16161","257.83707","0.00162","25.78371","0.00137"
"10.00000","0.16491","262.94467","0.00165","26.29447","0.00140"
"10.20000","0.16834","268.01846","0.00168","26.80185","0.00142"
"10.40000","0.17189","273.42093","0.00172","27.34209","0.00146"
"10.60000","0.17525","278.58813","0.00175","27.85881","0.00148"
"10.80000","0.17844","283.28534","0.00178","28.32853","0.00151"
"11.00000","0.18176","288.19562","0.00182","28.81956","0.00154"
"11.20000","0.18495","292.92560","0.00185","29.29256","0.00156"
"11.40000","0.18835","297.98538","0.00188","29.79854","0.00159"
"11.60000","0.19173","302.89899","0.00192","30.28990","0.00162"
"11.80000","0.19522","308.16974","0.00195","30.81697","0.00165"
"12.00000","0.19847","312.93765","0.00198","31.29377","0.00168"
"12.20000","0.20169","317.54935","0.00202","31.75493","0.00170"
"12.40000","0.20500","322.51212","0.00205","32.25121","0.00173"
"12.60000","0.20832","327.20279","0.00208","32.72028","0.00176"
"12.80000","0.21171","332.23566","0.00212","33.22356","0.00178"
"13.00000","0.21514","337.30182","0.00215","33.73018","0.00181"
"13.20000","0.21852","342.24936","0.00219","34.22494","0.00184"
"13.40000","0.22169","346.61871","0.00222","34.66187","0.00186"
"13.60000","0.22495","351.26230","0.00225","35.12623","0.00189"
"13.80000","0.22836","356.11313","0.00228","35.61131","0.00192"
"14.00000","0.23179","361.08487","0.00232","36.10849","0.00195"
"14.20000","0.23515","365.82556","0.00235","36.58256","0.00197"
"14.40000","0.23846","370.44226","0.00238","37.04423","0.00200"
"14.60000","0.24180","375.22766","0.00242","37.52277","0.00203"
"14.80000","0.24496","379.51215","0.00245","37.95121","0.00205"
"15.00000","0.24832","384.11935","0.00248","38.41193","0.00208"
"15.20000","0.25176","389.16705","0.00252","38.91671","0.00211"
"15.40000","0.25520","393.95428","0.00255","39.39543","0.00213"
"15.60000","0.25845","398.46844","0.00258","39.84684","0.00216"
"15.80000","0.26175","403.03616","0.00262","40.30362","0.00219"
"16.00000","0.26501","407.61115","0.00265","40.76112","0.00221"
"16.20000","0.26827","411.99649","0.00268","41.19965","0.00224"
"16.40000","0.27166","416.78082","0.00272","41.67808","0.00226"
"16.60000","0.27524","421.78217","0.00275","42.17822","0.00229"
"16.80000","0.27860","426.34726","0.00279","42.63473","0.00232"
"17.00000","0.28175","430.52295","0.00282","43.05230","0.00234"
"17.20000","0.28503","434.96384","0.00285","43.49638","0.00237"
"17.40000","0.28829","439.31482","0.00288","43.93148","0.00239"
"17.60000","0.29160","443.76642","0.00292","44.37664","0.00242"
"17.80000","0.29509","448.57581","0.00295","44.85758","0.00245"
"18.00000","0.29859","453.40234","0.00299","45.34023","0.00247"
"18.20000","0.30194","457.80237","0.00302","45.78024","0.00250"
"18.40000","0.30496","461.79736","0.00305","46.17974","0.00252"
"18.60000","0.30837","466.40277","0.00308","46.64028","0.00255"
"18.80000","0.31163","470.81226","0.00312","47.08123","0.00258"
"19.00000","0.31506","475.20526","0.00315","47.52053","0.00260"
"19.20000","0.31842","479.56897","0.00318","47.95690","0.00263"
"19.40000","0.32185","484.17807","0.00322","48.41781","0.00265"
"19.60000","0.32511","488.46466","0.00325","48.84647","0.00268"
"19.80000","0.32824","492.42880","0.00328","49.24288","0.00270"
"20.00000","0.33171","497.08978","0.00332","49.70898","0.00273"
"20.20000","0.33510","501.47430","0.00335","50.14743","0.00276"
"20.40000","0.33848","506.08856","0.00338","50.60886","0.00278"
"20.60000","0.34173","510.29889","0.00342","51.02989","0.00281"
"20.80000","0.34507","514.54950","0.00345","51.45495","0.00283"
"21.00000","0.34831","518.69501","0.00348","51.86950","0.00286"
"21.20000","0.35160","523.05450","0.00352","52.30545","0.00288"
"21.40000","0.35518","527.63416","0.00355","52.76342","0.00291"
"21.60000","0.35861","532.05670","0.00359","53.20567","0.00293"
"21.80000","0.36190","536.22363","0.00362","53.62236","0.00296"
"22.00000","0.36502","540.09888","0.00365","54.00989","0.00298"
"22.20000","0.36833","544.38110","0.00368","54.43811","0.00300"
"22.40000","0.37157","548.29419","0.00372","54.82942","0.00303"
"22.60000","0.37499","552.74561","0.00375","55.27456","0.00305"
"22.80000","0.37855","557.36542","0.00379","55.73654","0.00308"
"23.00000","0.38192","561.59662","0.00382","56.15966","0.00311"
"23.20000","0.38515","565.71948","0.00385","56.57195","0.00313"
"23.40000","0.38831","569.43079","0.00388","56.94308","0.00315"
"23.60000","0.39163","573.57733","0.00392","57.35773","0.00318"
"23.80000","0.39494","577.56018","0.00395","57.75602","0.00320"
"24.00000","0.39842","582.20398","0.00398","58.22040","0.00323"
"24.20000","0.40187","586.40533","0.00402","58.64053","0.00326"
"24.40000","0.40516","590.47394","0.00405","59.04739","0.00328"
"24.60000","0.40839","594.37695","0.00408","59.43769","0.00330"
"24.80000","0.41169","598.33087","0.00412","59.83309","0.00333"
"25.00000","0.41505","602.52747","0.00415","60.25275","0.00335"
"25.20000","0.41841","606.61621","0.00418","60.66162","0.00338"
"25.40000","0.42183","610.90619","0.00422","61.09062","0.00340"
"25.60000","0.42513","614.75488","0.00425","61.47549","0.00343"
"25.80000","0.42841","618.71686","0.00428","61.87169","0.00345"
"26.00000","0.43161","622.51312","0.00432","62.25131","0.00348"
"26.20000","0.43503","626.64801","0.00435","62.66480","0.00350"
"26.40000","0.43843","630.70660","0.00438","63.07066","0.00352"
"26.60000","0.44182","634.95819","0.00442","63.49582","0.00355"
"26.80000","0.44515","638.89038","0.00445","63.88904","0.00357"
"27.00000","0.44839","642.53613","0.00448","64.25362","0.00360"
"27.20000","0.45160","646.28088","0.00452","64.62809","0.00362"
"27.40000","0.45498","650.23938","0.00455","65.02394","0.00365"
"27.60000","0.45848","654.56500","0.00458","65.45650","0.00367"
"27.80000","0.46185","658.50085","0.00462","65.85008","0.00370"
"28.00000","0.46515","662.27673","0.00465","66.22768","0.00372"
"28.20000","0.46844","666.03918","0.00468","66.60392","0.00374"
"28.40000","0.47166","669.77173","0.00472","66.97717","0.00377"
"28.60000","0.47495","673.57172","0.00475","67.35717","0.00379"
"28.80000","0.47834","677.55267","0.00478","67.75526","0.00381"
"29.00000","0.48195","681.88599","0.00482","68.18860","0.00384"
"29.20000","0.48520","685.45605","0.00485","68.54561","0.00386"
"29.40000","0.48847","689.19653","0.00488","68.91965","0.00389"
"29.60000","0.49169","692.78058","0.00492","69.27806","0.00391"
"29.80000","0.49497","696.52008","0.00495","69.65201","0.00393"
"30.00000","0.49827","700.14233","0.00498","70.01424","0.00395"
"30.20000","0.50173","704.19891","0.00502","70.41989","0.00398"
"30.40000","0.50527","708.26257","0.00505","70.82626","0.00400"
"30.60000","0.50850","711.85461","0.00509","71.18546","0.00402"
"30.80000","0.51166","715.26544","0.00512","71.52654","0.00405"
"31.00000","0.51500","719.15222","0.00515","71.91522","0.00407"
"31.20000","0.51834","722.80707","0.00518","72.28071","0.00409"
"31.40000","0.52170","726.58044","0.00522","72.65804","0.00412"
"31.60000","0.52509","730.39490","0.00525","73.03949","0.00414"
"31.80000","0.52853","734.30634","0.00529","73.43063","0.00416"
"32.00000","0.53171","737.65070","0.00532","73.76507","0.00418"
"32.20000","0.53498","741.16541","0.00535","74.11654","0.00421"
"32.40000","0.53844","744.99115","0.00538","74.49911","0.00423"
"32.60000","0.54183","748.76489","0.00542","74.87649","0.00425"
"32.80000","0.54516","752.22852","0.00545","75.22285","0.00428"
"33.00000","0.54844","755.77386","0.00548","75.57738","0.00430"
"33.20000","0.55172","759.19531","0.00552","75.91953","0.00432"
"33.40000","0.55498","762.63196","0.00555","76.26320","0.00435"
"33.60000","0.55826","766.14685","0.00558","76.61469","0.00437"
"33.80000","0.56183","770.17230","0.00562","77.01723","0.00439"
"34.00000","0.56528","773.83264","0.00565","77.38326","0.00442"
"34.20000","0.56849","777.15527","0.00568","77.71553","0.00444"
"34.40000","0.57169","780.43097","0.00572","78.04310","0.00446"
"34.60000","0.57496","783.89124","0.00575","78.38912","0.00448"
"34.80000","0.57826","787.30292","0.00578","78.73029","0.00451"
"35.00000","0.58168","790.90436","0.00582","79.09044","0.00453"
"35.20000","0.58521","794.62805","0.00585","79.46281","0.00455"
"35.40000","0.58865","798.31091","0.00589","79.83109","0.00458"
"35.60000","0.59176","801.40662","0.00592","80.14066","0.00460"
"35.80000","0.59503","804.50128","0.00595","80.45013","0.00462"
"36.00000","0.59830","807.80743","0.00598","80.78075","0.00464"
"36.20000","0.60163","811.32214","0.00602","81.13222","0.00466"
"36.40000","0.60509","814.88434","0.00605","81.48843","0.00469"
"36.60000","0.60857","818.58270","0.00609","81.85827","0.00471"
"36.80000","0.61182","821.73950","0.00612","82.17395","0.00473"
"37.00000","0.61502","824.86115","0.00615","82.48611","0.00475"
"37.20000","0.61830","828.22461","0.00618","82.82246","0.00478"
"37.40000","0.62166","831.41772","0.00622","83.14177","0.00480"
"37.60000","0.62508","834.90460","0.00625","83.49046","0.00482"
"37.80000","0.62842","838.26501","0.00628","83.82650","0.00484"
"38.00000","0.63178","841.64368","0.00632","84.16437","0.00487"
"38.20000","0.63503","844.75409","0.00635","84.47541","0.00489"
"38.40000","0.63828","847.80402","0.00638","84.78040","0.00491"
"38.60000","0.64175","851.32104","0.00642","85.13210","0.00493"
"38.80000","0.64513","854.60834","0.00645","85.46083","0.00496"
"39.00000","0.64851","857.90857","0.00649","85.79086","0.00498"
"39.20000","0.65175","861.00928","0.00652","86.10093","0.00500"
"39.40000","0.65503","863.91895","0.00655","86.39189","0.00502"
"39.60000","0.65829","867.03937","0.00658","86.70393","0.00504"
"39.80000","0.66164","870.30658","0.00662","87.03065","0.00506"
"40.00000","0.66519","873.83575","0.00665","87.38358","0.00509"
"40.20000","0.66857","876.83221","0.00669","87.68322","0.00511"
"40.40000","0.67187","879.92865","0.00672","87.99287","0.00513"
"40.60000","0.67506","882.72083","0.00675","88.27208","0.00515"
"40.80000","0.67831","885.74066","0.00678","88.57407","0.00517"
"41.00000","0.68157","888.63580","0.00682","88.86358","0.00519"
"41.20000","0.68504","891.84698","0.00685","89.18470","0.00521"
"41.40000","0.68857","895.34644","0.00689","89.53465","0.00524"
"41.60000","0.69187","898.24963","0.00692","89.82497","0.00526"
"41.80000","0.69509","901.08264","0.00695","90.10826","0.00528"
"42.00000","0.69835","903.98853","0.00698","90.39885","0.00530"
"42.20000","0.70165","906.80945","0.00702","90.68095","0.00532"
"42.40000","0.70494","909.82819","0.00705","90.98282","0.00534"
"42.60000","0.70849","913.22174","0.00708","91.32217","0.00536"
"42.80000","0.71187","916.26831","0.00712","91.62683","0.00539"
"43.00000","0.71515","919.16296","0.00715","91.91630","0.00541"
"43.20000","0.71838","921.77942","0.00718","92.17794","0.00543"
"43.40000","0.72166","924.62573","0.00722","92.46257","0.00545"
"43.60000","0.72508","927.68420","0.00725","92.76842","0.00547"
"43.80000","0.72833","930.48865","0.00728","93.04887","0.00549"
"44.00000","0.73185","933.60626","0.00732","93.36063","0.00551"
"44.20000","0.73519","936.62488","0.00735","93.66249","0.00553"
"44.40000","0.73839","939.34906","0.00738","93.93491","0.00555"
"44.60000","0.74160","942.02533","0.00742","94.20253","0.00557"
"44.80000","0.74511","945.15265","0.00745","94.51527","0.00559"
"45.00000","0.74843","948.05212","0.00748","94.80521","0.00562"
"45.20000","0.75177","950.79156","0.00752","95.07915","0.00564"
"45.40000","0.75508","953.52911","0.00755","95.35291","0.00566"
"45.60000","0.75836","956.19019","0.00758","95.61902","0.00568"
"45.80000","0.76162","958.92847","0.00762","95.89285","0.00570"
"46.00000","0.76494","961.62885","0.00765","96.16289","0.00572"
"46.20000","0.76857","964.82831","0.00769","96.48283","0.00574"
"46.40000","0.77190","967.75439","0.00772","96.77544","0.00576"
"46.60000","0.77514","970.23334","0.00775","97.02333","0.00578"
"46.80000","0.77839","972.74072","0.00778","97.27407","0.00580"
"47.00000","0.78156","975.23315","0.00782","97.52332","0.00582"
"47.20000","0.78498","978.01733","0.00785","97.80173","0.00584"
"47.40000","0.78832","980.65222","0.00788","98.06522","0.00586"
"47.60000","0.79196","983.86127","0.00792","98.38612","0.00588"
"47.80000","0.79526","986.37677","0.00795","98.63768","0.00590"
"48.00000","0.79844","988.76550","0.00798","98.87655","0.00592"
"48.20000","0.80165","991.07574","0.00802","99.10757","0.00594"
"48.40000","0.80495","993.63110","0.00805","99.36311","0.00596"
"48.60000","0.80830","996.02264","0.00808","99.60226","0.00598"
"48.80000","0.81171","998.76208","0.00812","99.87621","0.00600"
"49.00000","0.81526","1001.66071","0.00815","100.16607","0.00602"
"49.20000","0.81847","1004.02332","0.00818","100.40233","0.00603"
"49.40000","0.82166","1006.12659","0.00822","100.61266","0.00605"
"49.60000","0.82498","1008.78479","0.00825","100.87848","0.00607"
"49.80000","0.82842","1011.41315","0.00828","101.14131","0.00609"
"50.00000","0.83172","1014.02405","0.00832","101.40240","0.00611"
"50.20000","0.83512","1016.68115","0.00835","101.66811","0.00613"
"50.40000","0.83849","1019.15131","0.00838","101.91513","0.00615"
"50.60000","0.84166","1021.25256","0.00842","102.12526","0.00617"
"50.80000","0.84498","1023.66779","0.00845","102.36678","0.00619"
"51.00000","0.84839","1026.38196","0.00848","102.63820","0.00620"
"51.20000","0.85192","1029.09863","0.00852","102.90987","0.00622"
"51.40000","0.85517","1031.28918","0.00855","103.12892","0.00624"
"51.60000","0.85844","1033.47729","0.00858","103.34773","0.00626"
"51.80000","0.86169","1035.48694","0.00862","103.54869","0.00628"
"52.00000","0.86495","1037.60974","0.00865","103.76097","0.00629"
"52.20000","0.86829","1040.10571","0.00868","104.01057","0.00631"
"52.40000","0.87178","1042.65869","0.00872","104.26587","0.00633"
"52.60000","0.87524","1045.19202","0.00875","104.51920","0.00635"
"52.80000","0.87848","1047.14734","0.00878","104.71474","0.00637"
"53.00000","0.88173","1049.16516","0.00882","104.91652","0.00638"
"53.20000","0.88497","1051.27307","0.00885","105.12730","0.00640"
"53.40000","0.88831","1053.43518","0.00888","105.34352","0.00642"
"53.60000","0.89171","1055.69678","0.00892","105.56968","0.00644"
"53.80000","0.89521","1057.97009","0.00895","105.79701","0.00645"
"54.00000","0.89857","1060.13757","0.00899","106.01376","0.00647"
"54.20000","0.90173","1062.00720","0.00902","106.20072","0.00649"
"54.40000","0.90508","1064.19019","0.00905","106.41902","0.00651"
"54.60000","0.90827","1066.08142","0.00908","106.60814","0.00652"
"54.80000","0.91167","1068.03650","0.00912","106.80365","0.00654"
"55.00000","0.91508","1070.33740","0.00915","107.03374","0.00656"
"55.20000","0.91855","1072.43494","0.00919","107.24349","0.00657"
"55.40000","0.92177","1073.96582","0.00922","107.39658","0.00659"
"55.60000","0.92499","1075.50635","0.00925","107.55064","0.00660"
"55.80000","0.92838","1077.45691","0.00928","107.74569","0.00662"
"56.00000","0.93168","1079.18408","0.00932","107.91841","0.00663"
"56.20000","0.93505","1081.16125","0.00935","108.11613","0.00665"
"56.40000","0.93846","1083.14929","0.00938","108.31493","0.00667"
"56.60000","0.94182","1084.89856","0.00942","108.48985","0.00668"
"56.80000","0.94500","1086.33423","0.00945","108.63342","0.00670"
"57.00000","0.94829","1088.09009","0.00948","108.80901","0.00671"
"57.20000","0.95173","1090.16443","0.00952","109.01644","0.00673"
"57.40000","0.95513","1092.01953","0.00955","109.20195","0.00674"
"57.60000","0.95850","1093.83337","0.00959","109.38334","0.00676"
"57.80000","0.96176","1095.48694","0.00962","109.54869","0.00677"
"58.00000","0.96508","1096.98950","0.00965","109.69895","0.00679"
"58.20000","0.96827","1098.52563","0.00968","109.85256","0.00680"
"58.40000","0.97167","1100.32251","0.00972","110.03225","0.00682"
"58.60000","0.97513","1102.22107","0.00975","110.22211","0.00683"
"58.80000","0.97857","1104.05615","0.00979","110.40562","0.00685"
"59.00000","0.98177","1105.57068","0.00982","110.55707","0.00686"
"59.20000","0.98507","1107.18994","0.00985","110.71899","0.00688"
"59.40000","0.98831","1108.42688","0.00988","110.84269","0.00689"
"59.60000","0.99158","1109.79553","0.00992","110.97955","0.00691"
"59.80000","0.99504","1111.49146","0.00995","111.14915","0.00692"
"60.00000","0.99857","1113.13953","0.00999","111.31395","0.00693"
"60.20000","1.00190","1114.40491","0.01002","111.44049","0.00695"
"60.40000","1.00504","1114.54724","0.01005","111.45473","0.00695"
"60.60000","1.00835","1114.90381","0.01008","111.49038","0.00696"
"60.80000","1.01165","1115.13855","0.01012","111.51385","0.00697"
"61.00000","1.01498","1113.71240","0.01015","111.37124","0.00696"
"61.20000","1.01846","1111.94177","0.01018","111.19418","0.00696"
"61.40000","1.02189","1110.14026","0.01022","111.01402","0.00695"
"61.60000","1.02524","1108.34265","0.01025","110.83427","0.00695"
"61.80000","1.02830","1105.48682","0.01028","110.54868","0.00694"
"62.00000","1.03173","1102.99023","0.01032","110.29903","0.00693"
"62.20000","1.03500","1100.01624","0.01035","110.00163","0.00691"
"62.40000","1.03843","1097.06555","0.01038","109.70656","0.00690"
"62.60000","1.04173","1094.00464","0.01042","109.40047","0.00689"
"62.80000","1.04512","1089.47656","0.01045","108.94765","0.00687"
"63.00000","1.04839","1083.61462","0.01048","108.36147","0.00684"
"63.20000","1.05159","1068.45044","0.01052","106.84505","0.00677"
"63.40000","1.05506","1058.02600","0.01055","105.80260","0.00672"
"63.60000","1.05848","1049.44189","0.01058","104.94419","0.00668"
"63.80000","1.06184","1042.29651","0.01062","104.22965","0.00664"
"64.00000","1.06505","1035.88794","0.01065","103.58879","0.00661"
"64.20000","1.06838","1030.96460","0.01068","103.09646","0.00659"
"64.40000","1.07163","1026.25208","0.01072","102.62521","0.00656"
"64.60000","1.07495","1022.11249","0.01075","102.21125","0.00654"
"64.80000","1.07855","1019.22723","0.01079","101.92272","0.00653"
"65.00000","1.08195","1016.47394","0.01082","101.64739","0.00652"
"65.20000","1.08521","1013.96649","0.01085","101.39665","0.00650"
"65.40000","1.08834","1011.47565","0.01088","101.14757","0.00649"
"65.60000","1.09167","1009.70294","0.01092","100.97029","0.00648"
"65.80000","1.09488","1007.72351","0.01095","100.77235","0.00647"
"66.00000","1.09837","1006.52563","0.01098","100.65257","0.00647"
"66.20000","1.10187","1004.77393","0.01102","100.47739","0.00646"
"66.40000","1.10523","1002.70453","0.01105","100.27045","0.00645"
"66.60000","1.10844","1000.44592","0.01108","100.04459","0.00644"
"66.80000","1.11165","998.63373","0.01112","99.86337","0.00643"
"67.00000","1.11498","997.14880","0.01115","99.71488","0.00643"
"67.20000","1.11831","996.06525","0.01118","99.60652","0.00642"
"67.40000","1.12179","995.16089","0.01122","99.51609","0.00642"
"67.60000","1.12518","994.44250","0.01125","99.44425","0.00641"
"67.80000","1.12845","993.43683","0.01128","99.34368","0.00641"
"68.00000","1.13169","992.25568","0.01132","99.22557","0.00640"
"68.20000","1.13503","991.41498","0.01135","99.14149","0.00640"
"68.40000","1.13843","990.82233","0.01138","99.08223","0.00640"
"68.60000","1.14178","990.28253","0.01142","99.02825","0.00639"
"68.80000","1.14513","989.71631","0.01145","98.97163","0.00639"
"69.00000","1.14843","989.04669","0.01148","98.90467","0.00639"
"69.20000","1.15170","988.08112","0.01152","98.80811","0.00638"
"69.40000","1.15494","987.23694","0.01155","98.72369","0.00638"
"69.60000","1.15843","987.12292","0.01158","98.71230","0.00638"
"69.80000","1.16181","986.84576","0.01162","98.68458","0.00638"
"70.00000","1.16519","986.73065","0.01165","98.67307","0.00638"
"70.20000","1.16846","986.17383","0.01168","98.61739","0.00638"
"70.40000","1.17168","985.59912","0.01172","98.55991","0.00637"
"70.60000","1.17494","984.98932","0.01175","98.49893","0.00637"
"70.80000","1.17829","984.48840","0.01178","98.44884","0.00637"
"71.00000","1.18184","984.39307","0.01182","98.43931","0.00637"
"71.20000","1.18520","983.90448","0.01185","98.39045","0.00637"
"71.40000","1.18845","983.38062","0.01188","98.33806","0.00636"
"71.60000","1.19175","982.90350","0.01192","98.29035","0.00636"
"71.80000","1.19499","982.36066","0.01195","98.23607","0.00636"
"72.00000","1.19831","981.78925","0.01198","98.17892","0.00636"
"72.20000","1.20172","980.61768","0.01202","98.06177","0.00635"
"72.40000","1.20529","979.79138","0.01205","97.97914","0.00635"
"72.60000","1.20855","978.25024","0.01209","97.82503","0.00634"
"72.80000","1.21177","976.53058","0.01212","97.65306","0.00633"
"73.00000","1.21499","974.64502","0.01215","97.46450","0.00632"
"73.20000","1.21829","973.21484","0.01218","97.32149","0.00632"
"73.40000","1.22161","971.99231","0.01222","97.19923","0.00631"
"73.60000","1.22508","971.10455","0.01225","97.11046","0.00631"
"73.80000","1.22858","970.35419","0.01229","97.03542","0.00630"
"74.00000","1.23179","968.83990","0.01232","96.88399","0.00630"
"74.20000","1.23498","967.49200","0.01235","96.74920","0.00629"
"74.40000","1.23834","966.61670","0.01238","96.66167","0.00629"
"74.60000","1.24171","965.78992","0.01242","96.57899","0.00628"
"74.80000","1.24508","964.80426","0.01245","96.48042","0.00628"
"75.00000","1.24843","963.96112","0.01248","96.39611","0.00627"
"75.20000","1.25181","963.21936","0.01252","96.32194","0.00627"
"75.40000","1.25502","961.41241","0.01255","96.14124","0.00626"
"75.60000","1.25832","959.60229","0.01258","95.96023","0.00625"
"75.80000","1.26181","958.00555","0.01262","95.80055","0.00624"
"76.00000","1.26520","956.69000","0.01265","95.66900","0.00624"
"76.20000","1.26848","955.07458","0.01268","95.50746","0.00623"
"76.40000","1.27177","953.84790","0.01272","95.38479","0.00622"
"76.60000","1.27498","952.57721","0.01275","95.25772","0.00622"
"76.80000","1.27827","951.67578","0.01278","95.16758","0.00621"
"77.00000","1.28162","951.14709","0.01282","95.11471","0.00621"
"77.20000","1.28518","951.05969","0.01285","95.10597","0.00621"
"77.40000","1.28864","950.87158","0.01289","95.08716","0.00621"
"77.60000","1.29179","950.26868","0.01292","95.02687","0.00621"
"77.80000","1.29502","949.85571","0.01295","94.98557","0.00620"
"78.00000","1.29831","949.59100","0.01298","94.95910","0.00619"
"78.20000","1.30160","949.47955","0.01302","94.94795","0.00620"
"78.40000","1.30504","949.73267","0.01305","94.97327","0.00620"
"78.41400","1.30531","949.75018","0.01305","94.97502","0.00620"