File: Tension/Section_2_Group_2/hybrid_high_Sample_1_redonewiththepowerofAnton_2.is_tens_RawData/Specimen_RawData_1.csv
Time,Extension,Load,Tensile strain (Extension),Tensile stress,Strain-by-clip-gage
(s),(mm),(N),(mm/mm),(MPa),(mm/mm)
"0.00000","0.00000","-683.94684","0.00000","-68.39468","-0.00026"
"0.10000","0.00069","-679.29260","0.00001","-67.92926","-0.00028"
"0.20000","0.00327","-657.76642","0.00003","-65.77664","-0.00028"
"0.30000","0.00775","-620.71802","0.00008","-62.07180","-0.00028"
"0.40000","0.01117","-593.16028","0.00011","-59.31603","-0.00027"
"0.50000","0.01457","-566.18652","0.00015","-56.61865","-0.00027"
"0.60000","0.01780","-540.62964","0.00018","-54.06297","-0.00027"
"0.70000","0.02115","-514.41382","0.00021","-51.44138","-0.00028"
"0.80000","0.02464","-487.08246","0.00025","-48.70824","-0.00027"
"0.90000","0.02801","-461.09125","0.00028","-46.10912","-0.00026"
"1.00000","0.03122","-436.44150","0.00031","-43.64415","-0.00027"
"1.10000","0.03450","-411.43265","0.00034","-41.14326","-0.00027"
"1.20000","0.03795","-385.18759","0.00038","-38.51876","-0.00030"
"1.30000","0.04113","-361.61191","0.00041","-36.16119","-0.00027"
"1.40000","0.04454","-335.94919","0.00045","-33.59492","-0.00028"
"1.50000","0.04799","-310.37567","0.00048","-31.03757","-0.00028"
"1.60000","0.05132","-285.93137","0.00051","-28.59314","-0.00025"
"1.70000","0.05446","-263.54202","0.00054","-26.35420","-0.00029"
"1.80000","0.05792","-238.64397","0.00058","-23.86440","-0.00027"
"1.90000","0.06116","-215.63689","0.00061","-21.56369","-0.00028"
"2.00000","0.06448","-192.26961","0.00064","-19.22696","-0.00027"
"2.10000","0.06784","-168.51677","0.00068","-16.85168","-0.00028"
"2.20000","0.07126","-144.35193","0.00071","-14.43519","-0.00027"
"2.30000","0.07463","-120.86419","0.00075","-12.08642","-0.00028"
"2.40000","0.07773","-99.49893","0.00078","-9.94989","-0.00028"
"2.50000","0.08127","-74.50803","0.00081","-7.45080","-0.00026"
"2.60000","0.08458","-51.87313","0.00085","-5.18731","-0.00028"
"2.70000","0.08784","-29.50820","0.00088","-2.95082","-0.00027"
"2.80000","0.09124","-5.71302","0.00091","-0.57130","-0.00027"
"2.90000","0.09458","17.02119","0.00095","1.70212","-0.00028"
"3.00000","0.09801","40.63019","0.00098","4.06302","-0.00027"
"3.10000","0.10109","61.25645","0.00101","6.12565","-0.00027"
"3.20000","0.10466","86.01262","0.00105","8.60126","-0.00027"
"3.30000","0.10795","108.18891","0.00108","10.81889","-0.00027"
"3.40000","0.11121","130.29254","0.00111","13.02925","-0.00028"
"3.50000","0.11446","152.14044","0.00114","15.21404","-0.00026"
"3.60000","0.11787","175.38667","0.00118","17.53867","-0.00030"
"3.70000","0.12121","197.92621","0.00121","19.79262","-0.00026"
"3.80000","0.12440","219.42429","0.00124","21.94243","-0.00028"
"3.90000","0.12794","243.78882","0.00128","24.37888","-0.00026"
"4.00000","0.13131","266.51340","0.00131","26.65134","-0.00027"
"4.10000","0.13452","287.87268","0.00135","28.78727","-0.00029"
"4.20000","0.13780","309.67157","0.00138","30.96716","-0.00027"
"4.30000","0.14121","332.62036","0.00141","33.26204","-0.00029"
"4.40000","0.14452","354.69022","0.00145","35.46902","-0.00026"
"4.50000","0.14780","376.27652","0.00148","37.62765","-0.00027"
"4.60000","0.15135","400.23819","0.00151","40.02382","-0.00027"
"4.70000","0.15466","422.07922","0.00155","42.20792","-0.00027"
"4.80000","0.15790","443.25943","0.00158","44.32594","-0.00028"
"4.90000","0.16117","464.91324","0.00161","46.49133","-0.00026"
"5.00000","0.16461","487.74878","0.00165","48.77488","-0.00028"
"5.10000","0.16782","508.71429","0.00168","50.87143","-0.00026"
"5.20000","0.17117","530.85333","0.00171","53.08533","-0.00027"
"5.30000","0.17455","553.10785","0.00175","55.31078","-0.00029"
"5.40000","0.17796","575.68994","0.00178","57.56899","-0.00026"
"5.50000","0.18114","596.04535","0.00181","59.60453","-0.00028"
"5.60000","0.18453","618.35309","0.00185","61.83531","-0.00026"
"5.70000","0.18792","640.57532","0.00188","64.05753","-0.00027"
"5.80000","0.19120","661.60352","0.00191","66.16035","-0.00028"
"5.90000","0.19454","683.36682","0.00195","68.33669","-0.00028"
"6.00000","0.19788","704.67792","0.00198","70.46779","-0.00029"
"6.10000","0.20118","725.91412","0.00201","72.59142","-0.00027"
"6.20000","0.20448","747.14960","0.00204","74.71496","-0.00027"
"6.30000","0.20796","769.90417","0.00208","76.99042","-0.00027"
"6.40000","0.21131","791.56189","0.00211","79.15619","-0.00026"
"6.50000","0.21454","811.89563","0.00215","81.18956","-0.00029"
"6.60000","0.21792","833.79095","0.00218","83.37910","-0.00027"
"6.70000","0.22117","854.23486","0.00221","85.42348","-0.00028"
"6.80000","0.22459","876.65131","0.00225","87.66513","-0.00027"
"6.90000","0.22780","896.95715","0.00228","89.69572","-0.00026"
"7.00000","0.23132","920.21210","0.00231","92.02121","-0.00029"
"7.10000","0.23462","941.41382","0.00235","94.14138","-0.00027"
"7.20000","0.23785","962.40564","0.00238","96.24056","-0.00028"
"7.30000","0.24126","984.98676","0.00241","98.49867","-0.00026"
"7.40000","0.24449","1006.13098","0.00244","100.61310","-0.00027"
"7.50000","0.24780","1028.08423","0.00248","102.80843","-0.00026"
"7.60000","0.25116","1050.58545","0.00251","105.05855","-0.00027"
"7.70000","0.25463","1073.98840","0.00255","107.39884","-0.00029"
"7.80000","0.25791","1095.86841","0.00258","109.58684","-0.00027"
"7.90000","0.26116","1117.53394","0.00261","111.75340","-0.00029"
"8.00000","0.26457","1140.90955","0.00265","114.09096","-0.00026"
"8.10000","0.26792","1163.39343","0.00268","116.33934","-0.00027"
"8.20000","0.27123","1185.48682","0.00271","118.54868","-0.00027"
"8.30000","0.27455","1207.81177","0.00275","120.78117","-0.00027"
"8.40000","0.27807","1232.04419","0.00278","123.20442","-0.00028"
"8.50000","0.28122","1252.56482","0.00281","125.25648","-0.00028"
"8.60000","0.28453","1274.97266","0.00285","127.49727","-0.00028"
"8.70000","0.28792","1297.97437","0.00288","129.79744","-0.00028"
"8.80000","0.29122","1320.17297","0.00291","132.01730","-0.00027"
"8.90000","0.29450","1342.38049","0.00294","134.23805","-0.00027"
"9.00000","0.29786","1365.42676","0.00298","136.54268","-0.00027"
"9.10000","0.30124","1388.09436","0.00301","138.80943","-0.00028"
"9.20000","0.30455","1410.40674","0.00305","141.04068","-0.00028"
"9.30000","0.30773","1431.54590","0.00308","143.15459","-0.00027"
"9.40000","0.31129","1456.26611","0.00311","145.62662","-0.00028"
"9.50000","0.31463","1478.97522","0.00315","147.89752","-0.00027"
"9.60000","0.31782","1500.05457","0.00318","150.00546","-0.00027"
"9.70000","0.32119","1522.82422","0.00321","152.28242","-0.00027"
"9.80000","0.32454","1545.21741","0.00325","154.52174","-0.00027"
"9.90000","0.32786","1567.51782","0.00328","156.75179","-0.00028"
"10.00000","0.33120","1590.24695","0.00331","159.02469","-0.00028"
"10.10000","0.33469","1614.29016","0.00335","161.42902","-0.00028"
"10.20000","0.33806","1637.26941","0.00338","163.72694","-0.00027"
"10.30000","0.34115","1657.48950","0.00341","165.74895","-0.00027"
"10.40000","0.34457","1681.14917","0.00345","168.11491","-0.00028"
"10.50000","0.34784","1703.05701","0.00348","170.30569","-0.00026"
"10.60000","0.35117","1725.82959","0.00351","172.58296","-0.00028"
"10.70000","0.35443","1747.91736","0.00354","174.79173","-0.00027"
"10.80000","0.35798","1772.63391","0.00358","177.26340","-0.00028"
"10.90000","0.36136","1795.52600","0.00361","179.55260","-0.00028"
"11.00000","0.36446","1815.92737","0.00364","181.59274","-0.00026"
"11.10000","0.36783","1839.13245","0.00368","183.91324","-0.00027"
"11.20000","0.37127","1862.56970","0.00371","186.25697","-0.00026"
"11.30000","0.37450","1884.14453","0.00375","188.41446","-0.00027"
"11.40000","0.37782","1906.45813","0.00378","190.64581","-0.00027"
"11.50000","0.38126","1930.04797","0.00381","193.00479","-0.00027"
"11.60000","0.38462","1952.77258","0.00385","195.27725","-0.00028"
"11.70000","0.38777","1973.77710","0.00388","197.37772","-0.00027"
"11.80000","0.39128","1998.24890","0.00391","199.82489","-0.00027"
"11.90000","0.39464","2021.19666","0.00395","202.11966","-0.00027"
"12.00000","0.39791","2043.20862","0.00398","204.32086","-0.00026"
"12.10000","0.40118","2065.33789","0.00401","206.53378","-0.00029"
"12.20000","0.40459","2088.60498","0.00405","208.86050","-0.00026"
"12.30000","0.40790","2111.09424","0.00408","211.10942","-0.00028"
"12.40000","0.41112","2132.86108","0.00411","213.28610","-0.00028"
"12.50000","0.41459","2156.73682","0.00415","215.67368","-0.00027"
"12.60000","0.41798","2179.84644","0.00418","217.98465","-0.00028"
"12.70000","0.42122","2201.69604","0.00421","220.16960","-0.00026"
"12.80000","0.42453","2224.15967","0.00425","222.41597","-0.00029"
"12.90000","0.42778","2246.15552","0.00428","224.61555","-0.00027"
"13.00000","0.43116","2269.42896","0.00431","226.94290","-0.00029"
"13.10000","0.43447","2291.83350","0.00434","229.18335","-0.00027"
"13.20000","0.43797","2316.18945","0.00438","231.61894","-0.00026"
"13.30000","0.44130","2339.02783","0.00441","233.90279","-0.00028"
"13.40000","0.44452","2360.65454","0.00445","236.06546","-0.00026"
"13.50000","0.44790","2383.87622","0.00448","238.38762","-0.00029"
"13.60000","0.45123","2406.29688","0.00451","240.62968","-0.00027"
"13.70000","0.45452","2428.54272","0.00455","242.85428","-0.00027"
"13.80000","0.45785","2451.26904","0.00458","245.12691","-0.00028"
"13.90000","0.46132","2475.03076","0.00461","247.50308","-0.00026"
"14.00000","0.46466","2497.73315","0.00465","249.77332","-0.00029"
"14.10000","0.46783","2518.70386","0.00468","251.87039","-0.00026"
"14.20000","0.47120","2541.84888","0.00471","254.18489","-0.00028"
"14.30000","0.47452","2564.08276","0.00475","256.40826","-0.00027"
"14.40000","0.47781","2586.33936","0.00478","258.63394","-0.00027"
"14.50000","0.48123","2609.84473","0.00481","260.98447","-0.00028"
"14.60000","0.48461","2632.71606","0.00485","263.27161","-0.00027"
"14.70000","0.48789","2654.64282","0.00488","265.46429","-0.00028"
"14.80000","0.49110","2675.88721","0.00491","267.58871","-0.00027"
"14.90000","0.49456","2699.72681","0.00495","269.97269","-0.00027"
"15.00000","0.49790","2722.12891","0.00498","272.21289","-0.00027"
"15.10000","0.50114","2743.63672","0.00501","274.36368","-0.00027"
"15.20000","0.50460","2767.30273","0.00505","276.73029","-0.00027"
"15.30000","0.50794","2789.54736","0.00508","278.95474","-0.00028"
"15.40000","0.51123","2811.39941","0.00511","281.13995","-0.00028"
"15.50000","0.51450","2833.44702","0.00514","283.34470","-0.00027"
"15.60000","0.51795","2857.05542","0.00518","285.70554","-0.00027"
"15.70000","0.52134","2879.91333","0.00521","287.99133","-0.00028"
"15.80000","0.52450","2900.60742","0.00524","290.06073","-0.00027"
"15.90000","0.52789","2923.52905","0.00528","292.35291","-0.00028"
"16.00000","0.53121","2945.75317","0.00531","294.57532","-0.00028"
"16.10000","0.53449","2967.67529","0.00534","296.76752","-0.00028"
"16.20000","0.53776","2989.66821","0.00538","298.96683","-0.00027"
"16.30000","0.54137","3014.77295","0.00541","301.47729","-0.00028"
"16.40000","0.54465","3036.38940","0.00545","303.63895","-0.00026"
"16.50000","0.54780","3056.77734","0.00548","305.67773","-0.00028"
"16.60000","0.55122","3080.09570","0.00551","308.00958","-0.00027"
"16.70000","0.55449","3101.64160","0.00554","310.16415","-0.00027"
"16.80000","0.55784","3124.18506","0.00558","312.41852","-0.00027"
"16.90000","0.56108","3145.98633","0.00561","314.59863","-0.00027"
"17.00000","0.56471","3171.07812","0.00565","317.10782","-0.00028"
"17.10000","0.56802","3193.10620","0.00568","319.31061","-0.00027"
"17.20000","0.57115","3213.41162","0.00571","321.34116","-0.00028"
"17.30000","0.57462","3237.27271","0.00575","323.72726","-0.00027"
"17.40000","0.57788","3258.79932","0.00578","325.87994","-0.00028"
"17.50000","0.58124","3281.36353","0.00581","328.13635","-0.00028"
"17.60000","0.58452","3303.28467","0.00585","330.32846","-0.00027"
"17.70000","0.58798","3326.53906","0.00588","332.65390","-0.00028"
"17.80000","0.59129","3348.26831","0.00591","334.82684","-0.00027"
"17.90000","0.59444","3368.60938","0.00594","336.86093","-0.00028"
"18.00000","0.59790","3392.26172","0.00598","339.22617","-0.00027"
"18.10000","0.60126","3414.55420","0.00601","341.45541","-0.00028"
"18.20000","0.60450","3435.90405","0.00604","343.59039","-0.00027"
"18.30000","0.60781","3458.00195","0.00608","345.80020","-0.00027"
"18.40000","0.61127","3481.35522","0.00611","348.13553","-0.00028"
"18.50000","0.61450","3502.45166","0.00614","350.24518","-0.00027"
"18.60000","0.61777","3524.20483","0.00618","352.42047","-0.00028"
"18.70000","0.62125","3547.91553","0.00621","354.79156","-0.00027"
"18.80000","0.62470","3571.24023","0.00625","357.12402","-0.00028"
"18.90000","0.62789","3591.76953","0.00628","359.17694","-0.00027"
"19.00000","0.63122","3613.83740","0.00631","361.38373","-0.00027"
"19.10000","0.63459","3636.11084","0.00635","363.61108","-0.00028"
"19.20000","0.63786","3657.53662","0.00638","365.75366","-0.00027"
"19.30000","0.64118","3679.46631","0.00641","367.94662","-0.00028"
"19.40000","0.64464","3702.70166","0.00645","370.27017","-0.00027"
"19.50000","0.64806","3725.47217","0.00648","372.54721","-0.00027"
"19.60000","0.65116","3745.23315","0.00651","374.52332","-0.00028"
"19.70000","0.65455","3768.06494","0.00655","376.80649","-0.00027"
"19.80000","0.65781","3789.14844","0.00658","378.91486","-0.00027"
"19.90000","0.66117","3811.44873","0.00661","381.14487","-0.00028"
"20.00000","0.66448","3833.50952","0.00664","383.35095","-0.00027"
"20.10000","0.66789","3856.24292","0.00668","385.62430","-0.00028"
"20.20000","0.67135","3879.39966","0.00671","387.93997","-0.00027"
"20.30000","0.67449","3899.23535","0.00674","389.92352","-0.00027"
"20.40000","0.67789","3921.87524","0.00678","392.18753","-0.00027"
"20.50000","0.68119","3943.44629","0.00681","394.34464","-0.00027"
"20.60000","0.68452","3965.13379","0.00685","396.51337","-0.00027"
"20.70000","0.68790","3987.59888","0.00688","398.75989","-0.00028"
"20.80000","0.69130","4009.92969","0.00691","400.99298","-0.00028"
"20.90000","0.69461","4031.55908","0.00695","403.15591","-0.00027"
"21.00000","0.69779","4052.17188","0.00698","405.21719","-0.00027"
"21.10000","0.70136","4076.25171","0.00701","407.62518","-0.00027"
"21.20000","0.70457","4096.93506","0.00705","409.69351","-0.00027"
"21.30000","0.70789","4118.58301","0.00708","411.85831","-0.00028"
"21.40000","0.71119","4140.11523","0.00711","414.01154","-0.00028"
"21.50000","0.71457","4162.14600","0.00715","416.21460","-0.00028"
"21.60000","0.71782","4183.09326","0.00718","418.30933","-0.00027"
"21.70000","0.72114","4204.75732","0.00721","420.47574","-0.00027"
"21.80000","0.72466","4228.43066","0.00725","422.84308","-0.00027"
"21.90000","0.72792","4249.28027","0.00728","424.92804","-0.00027"
"22.00000","0.73119","4270.45068","0.00731","427.04507","-0.00027"
"22.10000","0.73457","4292.56738","0.00735","429.25674","-0.00027"
"22.20000","0.73787","4313.93213","0.00738","431.39322","-0.00028"
"22.30000","0.74109","4334.32666","0.00741","433.43268","-0.00028"
"22.40000","0.74450","4356.93506","0.00745","435.69351","-0.00028"
"22.50000","0.74799","4380.05469","0.00748","438.00546","-0.00027"
"22.60000","0.75135","4402.12695","0.00751","440.21271","-0.00026"
"22.70000","0.75454","4422.24951","0.00755","442.22495","-0.00027"
"22.80000","0.75787","4443.63672","0.00758","444.36368","-0.00027"
"22.90000","0.76133","4466.34229","0.00761","446.63422","-0.00028"
"23.00000","0.76443","4485.43506","0.00764","448.54352","-0.00027"
"23.10000","0.76790","4508.64062","0.00768","450.86407","-0.00027"
"23.20000","0.77131","4530.70898","0.00771","453.07089","-0.00027"
"23.30000","0.77462","4552.04883","0.00775","455.20490","-0.00027"
"23.40000","0.77777","4571.70996","0.00778","457.17099","-0.00028"
"23.50000","0.78128","4594.84180","0.00781","459.48419","-0.00027"
"23.60000","0.78453","4615.25977","0.00785","461.52597","-0.00027"
"23.70000","0.78779","4636.06152","0.00788","463.60614","-0.00028"
"23.80000","0.79117","4658.01855","0.00791","465.80185","-0.00027"
"23.90000","0.79460","4680.44531","0.00795","468.04453","-0.00028"
"24.00000","0.79794","4701.79883","0.00798","470.17987","-0.00028"
"24.10000","0.80104","4720.81982","0.00801","472.08197","-0.00027"
"24.20000","0.80467","4745.32812","0.00805","474.53281","-0.00027"
"24.30000","0.80792","4765.44141","0.00808","476.54413","-0.00026"
"24.40000","0.81115","4785.54980","0.00811","478.55499","-0.00027"
"24.50000","0.81459","4807.91455","0.00815","480.79144","-0.00027"
"24.60000","0.81785","4828.22412","0.00818","482.82242","-0.00028"
"24.70000","0.82136","4851.54932","0.00821","485.15494","-0.00028"
"24.80000","0.82439","4869.70947","0.00824","486.97095","-0.00027"
"24.90000","0.82803","4894.41748","0.00828","489.44174","-0.00027"
"25.00000","0.83132","4915.14209","0.00831","491.51422","-0.00026"
"25.10000","0.83453","4935.12842","0.00835","493.51285","-0.00028"
"25.20000","0.83782","4956.07764","0.00838","495.60776","-0.00028"
"25.30000","0.84119","4977.51855","0.00841","497.75186","-0.00028"
"25.40000","0.84449","4998.35596","0.00844","499.83560","-0.00028"
"25.50000","0.84776","5019.02197","0.00848","501.90219","-0.00027"
"25.60000","0.85129","5042.23584","0.00851","504.22357","-0.00028"
"25.70000","0.85467","5063.57275","0.00855","506.35727","-0.00027"
"25.80000","0.85788","5083.53467","0.00858","508.35345","-0.00028"
"25.90000","0.86120","5104.43018","0.00861","510.44302","-0.00028"
"26.00000","0.86459","5126.07227","0.00865","512.60724","-0.00027"
"26.10000","0.86785","5146.33105","0.00868","514.63312","-0.00028"
"26.20000","0.87112","5167.04004","0.00871","516.70398","-0.00027"
"26.30000","0.87468","5190.34619","0.00875","519.03461","-0.00028"
"26.40000","0.87797","5210.78125","0.00878","521.07812","-0.00028"
"26.50000","0.88121","5230.94434","0.00881","523.09442","-0.00027"
"26.60000","0.88452","5251.80566","0.00885","525.18054","-0.00028"
"26.70000","0.88796","5274.07471","0.00888","527.40747","-0.00026"
"26.80000","0.89116","5293.52441","0.00891","529.35242","-0.00028"
"26.90000","0.89453","5315.02344","0.00895","531.50232","-0.00027"
"27.00000","0.89790","5336.18018","0.00898","533.61804","-0.00028"
"27.10000","0.90126","5357.40430","0.00901","535.74042","-0.00028"
"27.20000","0.90444","5376.52686","0.00904","537.65271","-0.00028"
"27.30000","0.90787","5398.64453","0.00908","539.86444","-0.00028"
"27.40000","0.91126","5420.12793","0.00911","542.01282","-0.00027"
"27.50000","0.91449","5439.82959","0.00914","543.98297","-0.00026"
"27.60000","0.91786","5461.24805","0.00918","546.12482","-0.00028"
"27.70000","0.92120","5481.99463","0.00921","548.19946","-0.00027"
"27.80000","0.92452","5502.85254","0.00925","550.28528","-0.00029"
"27.90000","0.92781","5523.35254","0.00928","552.33527","-0.00028"
"28.00000","0.93135","5546.31836","0.00931","554.63184","-0.00027"
"28.10000","0.93467","5566.92480","0.00935","556.69250","-0.00027"
"28.20000","0.93787","5586.21777","0.00938","558.62177","-0.00026"
"28.30000","0.94133","5608.25635","0.00941","560.82562","-0.00028"
"28.40000","0.94449","5626.81201","0.00944","562.68121","-0.00027"
"28.50000","0.94788","5648.32520","0.00948","564.83252","-0.00029"
"28.60000","0.95114","5668.44189","0.00951","566.84418","-0.00027"
"28.70000","0.95465","5690.87598","0.00955","569.08759","-0.00026"
"28.80000","0.95792","5711.10938","0.00958","571.11096","-0.00027"
"28.90000","0.96115","5730.71973","0.00961","573.07196","-0.00026"
"29.00000","0.96460","5752.71631","0.00965","575.27161","-0.00029"
"29.10000","0.96784","5772.27490","0.00968","577.22748","-0.00028"
"29.20000","0.97113","5792.65820","0.00971","579.26581","-0.00027"
"29.30000","0.97451","5813.83984","0.00975","581.38397","-0.00028"
"29.40000","0.97800","5836.04150","0.00978","583.60413","-0.00027"
"29.50000","0.98125","5855.50537","0.00981","585.55054","-0.00029"
"29.60000","0.98446","5874.84814","0.00984","587.48480","-0.00027"
"29.70000","0.98794","5896.79346","0.00988","589.67932","-0.00028"
"29.80000","0.99124","5916.63184","0.00991","591.66321","-0.00027"
"29.90000","0.99452","5936.57568","0.00995","593.65759","-0.00026"
"30.00000","0.99790","5957.37744","0.00998","595.73773","-0.00028"
"30.10000","1.00139","5979.72168","0.01001","597.97217","-0.00027"
"30.20000","1.00454","5998.10596","0.01005","599.81061","-0.00028"
"30.30000","1.00781","6018.19238","0.01008","601.81921","-0.00027"
"30.40000","1.01126","6039.59619","0.01011","603.95959","-0.00027"
"30.50000","1.01461","6060.42090","0.01015","606.04211","-0.00028"
"30.60000","1.01781","6079.36963","0.01018","607.93695","-0.00027"
"30.70000","1.02121","6100.83691","0.01021","610.08368","-0.00029"
"30.80000","1.02457","6121.27734","0.01025","612.12775","-0.00027"
"30.90000","1.02785","6140.75000","0.01028","614.07501","-0.00028"
"31.00000","1.03110","6160.60889","0.01031","616.06091","-0.00027"
"31.10000","1.03467","6183.25146","0.01035","618.32513","-0.00027"
"31.20000","1.03794","6202.92041","0.01038","620.29205","-0.00027"
"31.30000","1.04114","6221.65723","0.01041","622.16571","-0.00027"
"31.40000","1.04456","6242.93848","0.01045","624.29382","-0.00028"
"31.50000","1.04785","6262.62598","0.01048","626.26257","-0.00027"
"31.60000","1.05118","6282.78613","0.01051","628.27863","-0.00028"
"31.70000","1.05448","6302.75391","0.01054","630.27539","-0.00027"
"31.80000","1.05803","6325.24707","0.01058","632.52472","-0.00027"
"31.90000","1.06142","6346.16553","0.01061","634.61658","-0.00028"
"32.00000","1.06444","6362.90625","0.01064","636.29065","-0.00027"
"32.10000","1.06793","6384.91895","0.01068","638.49188","-0.00027"
"32.20000","1.07116","6403.63184","0.01071","640.36316","-0.00027"
"32.30000","1.07451","6423.87061","0.01075","642.38708","-0.00026"
"32.40000","1.07780","6443.60840","0.01078","644.36084","-0.00028"
"32.50000","1.08132","6465.46777","0.01081","646.54675","-0.00027"
"32.60000","1.08468","6485.56201","0.01085","648.55621","-0.00029"
"32.70000","1.08777","6503.14746","0.01088","650.31476","-0.00028"
"32.80000","1.09117","6524.09863","0.01091","652.40985","-0.00026"
"32.90000","1.09461","6544.84277","0.01095","654.48425","-0.00028"
"33.00000","1.09783","6563.71094","0.01098","656.37109","-0.00027"
"33.10000","1.10117","6583.79492","0.01101","658.37952","-0.00028"
"33.20000","1.10462","6604.67822","0.01105","660.46783","-0.00028"
"33.30000","1.10789","6623.98584","0.01108","662.39856","-0.00029"
"33.40000","1.11110","6642.77100","0.01111","664.27710","-0.00028"
"33.50000","1.11466","6664.64795","0.01115","666.46478","-0.00028"
"33.60000","1.11802","6684.59814","0.01118","668.45984","-0.00028"
"33.70000","1.12126","6703.39551","0.01121","670.33954","-0.00025"
"33.80000","1.12452","6722.43457","0.01125","672.24347","-0.00028"
"33.90000","1.12793","6742.97070","0.01128","674.29706","-0.00027"
"34.00000","1.13119","6761.66504","0.01131","676.16650","-0.00027"
"34.10000","1.13443","6780.57080","0.01134","678.05707","-0.00029"
"34.20000","1.13794","6802.23486","0.01138","680.22351","-0.00026"
"34.30000","1.14130","6821.98047","0.01141","682.19806","-0.00027"
"34.40000","1.14450","6840.32812","0.01144","684.03284","-0.00027"
"34.50000","1.14790","6860.68018","0.01148","686.06799","-0.00028"
"34.60000","1.15114","6879.23584","0.01151","687.92358","-0.00028"
"34.70000","1.15446","6898.63770","0.01154","689.86377","-0.00027"
"34.80000","1.15782","6918.51514","0.01158","691.85150","-0.00028"
"34.90000","1.16134","6939.79199","0.01161","693.97919","-0.00027"
"35.00000","1.16466","6959.00928","0.01165","695.90094","-0.00027"
"35.10000","1.16784","6976.78857","0.01168","697.67883","-0.00028"
"35.20000","1.17122","6996.75879","0.01171","699.67590","-0.00027"
"35.30000","1.17456","7015.88477","0.01175","701.58850","-0.00028"
"35.40000","1.17786","7034.90137","0.01178","703.49011","-0.00027"
"35.50000","1.18122","7054.51123","0.01181","705.45111","-0.00027"
"35.60000","1.18467","7074.62207","0.01185","707.46222","-0.00028"
"35.70000","1.18796","7093.62793","0.01188","709.36279","-0.00027"
"35.80000","1.19114","7111.23047","0.01191","711.12305","-0.00027"
"35.90000","1.19458","7131.52295","0.01195","713.15228","-0.00027"
"36.00000","1.19784","7149.75244","0.01198","714.97522","-0.00028"
"36.10000","1.20117","7168.88379","0.01201","716.88837","-0.00028"
"36.20000","1.20459","7188.84229","0.01205","718.88422","-0.00027"
"36.30000","1.20792","7207.43408","0.01208","720.74341","-0.00028"
"36.40000","1.21122","7226.04541","0.01211","722.60455","-0.00027"
"36.50000","1.21443","7243.66455","0.01214","724.36646","-0.00028"
"36.60000","1.21794","7264.30029","0.01218","726.43005","-0.00028"
"36.70000","1.22129","7282.97900","0.01221","728.29791","-0.00027"
"36.80000","1.22443","7300.14746","0.01224","730.01477","-0.00028"
"36.90000","1.22795","7320.78613","0.01228","732.07861","-0.00026"
"37.00000","1.23126","7338.97607","0.01231","733.89758","-0.00028"
"37.10000","1.23451","7357.09668","0.01235","735.70966","-0.00027"
"37.20000","1.23787","7376.07764","0.01238","737.60779","-0.00027"
"37.30000","1.24130","7395.69238","0.01241","739.56921","-0.00028"
"37.40000","1.24469","7415.00391","0.01245","741.50037","-0.00026"
"37.50000","1.24786","7431.79834","0.01248","743.17981","-0.00028"
"37.60000","1.25122","7450.64600","0.01251","745.06458","-0.00027"
"37.70000","1.25458","7469.00146","0.01255","746.90015","-0.00028"
"37.80000","1.25780","7485.81445","0.01258","748.58142","-0.00028"
"37.90000","1.26109","7503.83057","0.01261","750.38306","-0.00027"
"38.00000","1.26474","7525.00391","0.01265","752.50037","-0.00028"
"38.10000","1.26797","7542.40088","0.01268","754.24011","-0.00026"
"38.20000","1.27111","7558.55811","0.01271","755.85583","-0.00028"
"38.30000","1.27456","7578.19092","0.01275","757.81909","-0.00027"
"38.40000","1.27780","7595.38721","0.01278","759.53870","-0.00027"
"38.50000","1.28117","7613.65820","0.01281","761.36584","-0.00028"
"38.60000","1.28443","7631.26611","0.01284","763.12659","-0.00027"
"38.70000","1.28801","7651.74756","0.01288","765.17474","-0.00028"
"38.80000","1.29135","7669.80420","0.01291","766.98041","-0.00027"
"38.90000","1.29445","7685.34619","0.01294","768.53461","-0.00027"
"39.00000","1.29800","7705.49902","0.01298","770.54993","-0.00028"
"39.10000","1.30120","7721.82568","0.01301","772.18256","-0.00026"
"39.20000","1.30456","7739.62207","0.01305","773.96222","-0.00028"
"39.30000","1.30787","7757.05859","0.01308","775.70587","-0.00027"
"39.40000","1.31129","7774.93359","0.01311","777.49335","-0.00028"
"39.50000","1.31461","7792.51904","0.01315","779.25189","-0.00028"
"39.60000","1.31777","7808.64062","0.01318","780.86407","-0.00026"
"39.70000","1.32125","7827.85840","0.01321","782.78583","-0.00028"
"39.80000","1.32461","7845.86377","0.01325","784.58636","-0.00026"
"39.90000","1.32782","7862.33398","0.01328","786.23340","-0.00028"
"40.00000","1.33116","7880.32764","0.01331","788.03278","-0.00027"
"40.10000","1.33462","7899.15869","0.01335","789.91589","-0.00027"
"40.20000","1.33780","7915.23828","0.01338","791.52380","-0.00028"
"40.30000","1.34112","7933.04004","0.01341","793.30402","-0.00026"
"40.40000","1.34463","7952.12158","0.01345","795.21216","-0.00028"
"40.50000","1.34805","7970.21680","0.01348","797.02167","-0.00027"
"40.60000","1.35120","7985.58057","0.01351","798.55804","-0.00027"
"40.70000","1.35456","8003.03467","0.01355","800.30347","-0.00028"
"40.80000","1.35794","8020.54932","0.01358","802.05493","-0.00026"
"40.90000","1.36117","8036.57031","0.01361","803.65704","-0.00028"
"41.00000","1.36452","8054.02344","0.01365","805.40234","-0.00026"
"41.10000","1.36800","8072.66211","0.01368","807.26624","-0.00027"
"41.20000","1.37137","8089.85547","0.01371","808.98553","-0.00028"
"41.30000","1.37447","8104.42480","0.01374","810.44250","-0.00027"
"41.40000","1.37788","8122.32568","0.01378","812.23254","-0.00028"
"41.50000","1.38115","8138.55469","0.01381","813.85547","-0.00026"
"41.60000","1.38452","8155.59766","0.01385","815.55975","-0.00028"
"41.70000","1.38785","8172.52393","0.01388","817.25238","-0.00027"
"41.80000","1.39123","8189.74072","0.01391","818.97406","-0.00027"
"41.90000","1.39464","8206.98828","0.01395","820.69885","-0.00028"
"42.00000","1.39778","8221.51855","0.01398","822.15186","-0.00027"
"42.10000","1.40128","8239.77246","0.01401","823.97723","-0.00029"
"42.20000","1.40458","8255.70703","0.01405","825.57068","-0.00027"
"42.30000","1.40784","8271.34961","0.01408","827.13495","-0.00027"
"42.40000","1.41121","8288.08691","0.01411","828.80872","-0.00028"
"42.50000","1.41463","8304.87109","0.01415","830.48712","-0.00027"
"42.60000","1.41793","8320.67480","0.01418","832.06750","-0.00028"
"42.70000","1.42111","8335.22559","0.01421","833.52258","-0.00027"
"42.80000","1.42468","8353.54297","0.01425","835.35431","-0.00028"
"42.90000","1.42791","8368.37402","0.01428","836.83740","-0.00027"
"43.00000","1.43123","8384.12598","0.01431","838.41260","-0.00027"
"43.10000","1.43455","8399.64453","0.01435","839.96448","-0.00027"
"43.20000","1.43789","8415.22070","0.01438","841.52209","-0.00026"
"43.30000","1.44115","8429.80566","0.01441","842.98059","-0.00028"
"43.40000","1.44448","8445.07324","0.01444","844.50732","-0.00027"
"43.50000","1.44801","8462.32129","0.01448","846.23212","-0.00027"
"43.60000","1.45128","8476.62793","0.01451","847.66278","-0.00028"
"43.70000","1.45447","8490.41309","0.01454","849.04132","-0.00026"
"43.80000","1.45790","8506.40723","0.01458","850.64075","-0.00028"
"43.90000","1.46128","8521.29688","0.01461","852.12970","-0.00027"
"44.00000","1.46436","8533.29492","0.01464","853.32947","-0.00028"
"44.10000","1.46781","8549.40723","0.01468","854.94073","-0.00027"
"44.20000","1.47132","8565.33789","0.01471","856.53381","-0.00027"
"44.30000","1.47467","8579.49512","0.01475","857.94952","-0.00028"
"44.40000","1.47788","8592.37207","0.01478","859.23718","-0.00027"
"44.50000","1.48119","8605.71094","0.01481","860.57111","-0.00028"
"44.60000","1.48470","8620.74512","0.01485","862.07452","-0.00027"
"44.70000","1.48777","8629.31738","0.01488","862.93176","-0.00027"
"44.80000","1.49126","8643.19922","0.01491","864.31995","-0.00027"
"44.90000","1.49465","8656.48730","0.01495","865.64874","-0.00027"
"45.00000","1.49794","8668.95508","0.01498","866.89551","-0.00029"
"45.10000","1.50106","8679.21973","0.01501","867.92200","-0.00027"
"45.20000","1.50467","8694.31836","0.01505","869.43182","-0.00029"
"45.30000","1.50784","8704.48535","0.01508","870.44855","-0.00026"
"45.40000","1.51110","8715.27441","0.01511","871.52747","-0.00028"
"45.50000","1.51450","8727.43457","0.01514","872.74347","-0.00027"
"45.60000","1.51795","8739.62012","0.01518","873.96204","-0.00027"
"45.70000","1.52127","8750.06738","0.01521","875.00671","-0.00028"
"45.80000","1.52436","8757.56543","0.01524","875.75653","-0.00026"
"45.90000","1.52807","8770.98145","0.01528","877.09814","-0.00027"
"46.00000","1.53132","8779.37793","0.01531","877.93781","-0.00027"
"46.10000","1.53449","8787.33789","0.01534","878.73376","-0.00027"
"46.20000","1.53793","8797.61230","0.01538","879.76123","-0.00028"
"46.30000","1.54115","8805.20020","0.01541","880.52002","-0.00028"
"46.40000","1.54471","8816.29980","0.01545","881.63000","-0.00027"
"46.50000","1.54770","8821.34375","0.01548","882.13440","-0.00027"
"46.60000","1.55145","8833.38086","0.01551","883.33807","-0.00027"
"46.70000","1.55460","8839.12695","0.01555","883.91272","-0.00027"
"46.80000","1.55783","8845.33203","0.01558","884.53320","-0.00028"
"46.90000","1.56114","8852.22559","0.01561","885.22253","-0.00027"
"47.00000","1.56455","8859.54688","0.01565","885.95471","-0.00028"
"47.10000","1.56782","8865.09082","0.01568","886.50909","-0.00027"
"47.20000","1.57109","8870.99902","0.01571","887.09991","-0.00027"
"47.30000","1.57473","8879.91211","0.01575","887.99121","-0.00028"
"47.40000","1.57800","8884.62988","0.01578","888.46301","-0.00026"
"47.50000","1.58116","8888.47461","0.01581","888.84747","-0.00029"
"47.60000","1.58452","8893.99023","0.01585","889.39905","-0.00026"
"47.70000","1.58790","8899.14551","0.01588","889.91455","-0.00028"
"47.80000","1.59116","8903.04004","0.01591","890.30402","-0.00027"
"47.90000","1.59450","8908.07031","0.01595","890.80701","-0.00027"
"48.00000","1.59806","8914.65137","0.01598","891.46515","-0.00028"
"48.10000","1.60127","8917.55859","0.01601","891.75586","-0.00026"
"48.20000","1.60455","8921.20410","0.01605","892.12042","-0.00028"
"48.30000","1.60788","8890.62305","0.01608","889.06232","-0.00026"
"48.33200","1.60910","8760.57715","0.01609","876.05774","-0.00029"
"48.33500","1.60921","8623.46875","0.01609","862.34686","-0.00030"
"48.33700","1.60928","8459.67188","0.01609","845.96716","-0.00030"
"48.33900","1.60935","8251.55566","0.01609","825.15558","-0.00031"
"48.34100","1.60942","8010.61377","0.01609","801.06140","-0.00033"
"48.34200","1.60946","7880.75635","0.01609","788.07562","-0.00034"
"48.34300","1.60950","7745.99219","0.01609","774.59924","-0.00036"
"48.34400","1.60954","7607.22754","0.01610","760.72278","-0.00037"
"48.34500","1.60958","7465.30078","0.01610","746.53009","-0.00037"
"48.34600","1.60962","7320.99951","0.01610","732.09998","-0.00037"
"48.34700","1.60966","7175.05664","0.01610","717.50568","-0.00036"
"48.34800","1.60971","7028.15820","0.01610","702.81580","-0.00034"
"48.34900","1.60975","6880.93506","0.01610","688.09351","-0.00031"
"48.35000","1.60980","6733.97998","0.01610","673.39801","-0.00028"
"48.35100","1.60985","6587.83691","0.01610","658.78369","-0.00024"
"48.35200","1.60990","6442.99609","0.01610","644.29962","-0.00021"
"48.35300","1.60995","6299.89111","0.01610","629.98914","-0.00019"
"48.35400","1.61001","6158.90674","0.01610","615.89069","-0.00018"
"48.35500","1.61006","6020.39746","0.01610","602.03973","-0.00018"
"48.35600","1.61012","5884.67822","0.01610","588.46783","-0.00019"
"48.35700","1.61018","5752.03320","0.01610","575.20331","-0.00021"
"48.35800","1.61024","5622.71143","0.01610","562.27112","-0.00024"
"48.35900","1.61031","5496.92285","0.01610","549.69226","-0.00028"
"48.36100","1.61044","5256.61084","0.01610","525.66107","-0.00034"