File: nofiller_8ply.is_comp_RawData/Specimen_RawData_1.csv
Test : Rate 1,"1.50000",mm/min
Test : Rate 2,"-5.00000",mm/min

Time,Extension,Load
(s),(mm),(N)
"0.00000","0.00000","0.26888"
"0.10000","0.00057","0.27744"
"0.20000","0.00402","0.30446"
"0.30000","0.00748","0.30374"
"0.40000","0.01009","0.28233"
"0.50000","0.01247","0.26545"
"0.60000","0.01502","0.29169"
"0.70000","0.01745","0.33337"
"0.80000","0.02006","0.31843"
"0.90000","0.02255","0.33522"
"1.00000","0.02488","0.34639"
"1.10000","0.02760","0.31365"
"1.20000","0.03003","0.33609"
"1.30000","0.03258","0.32420"
"1.40000","0.03502","0.39354"
"1.50000","0.03746","0.36348"
"1.60000","0.04001","0.32809"
"1.70000","0.04261","0.30351"
"1.80000","0.04499","0.40666"
"1.90000","0.04743","0.38962"
"2.00000","0.05009","0.38046"
"2.10000","0.05259","0.36061"
"2.20000","0.05508","0.35847"
"2.30000","0.05752","0.39219"
"2.40000","0.06001","0.38622"
"2.50000","0.06262","0.37602"
"2.60000","0.06511","0.38821"
"2.70000","0.06749","0.38182"
"2.80000","0.06998","0.39671"
"2.90000","0.07248","0.37259"
"3.00000","0.07503","0.38685"
"3.10000","0.07758","0.38605"
"3.20000","0.08001","0.39811"
"3.30000","0.08251","0.43163"
"3.40000","0.08511","0.40472"
"3.50000","0.08761","0.41035"
"3.60000","0.08999","0.43510"
"3.70000","0.09248","0.44790"
"3.80000","0.09503","0.41183"
"3.90000","0.09758","0.46073"
"4.00000","0.09996","0.42785"
"4.10000","0.10245","0.45282"
"4.20000","0.10500","0.45057"
"4.30000","0.10755","0.36895"
"4.40000","0.11005","0.45845"
"4.50000","0.11254","0.44137"
"4.60000","0.11503","0.45520"
"4.70000","0.11758","0.43237"
"4.80000","0.12008","0.47918"
"4.90000","0.12257","0.46923"
"5.00000","0.12501","0.43744"
"5.10000","0.12756","0.50980"
"5.20000","0.13005","0.47728"
"5.30000","0.13254","0.44917"
"5.40000","0.13509","0.49046"
"5.50000","0.13753","0.45177"
"5.60000","0.14014","0.46429"
"5.70000","0.14246","0.48296"
"5.80000","0.14501","0.46690"
"5.90000","0.14750","0.48880"
"6.00000","0.15005","0.50500"
"6.10000","0.15249","0.46870"
"6.20000","0.15504","0.50624"
"6.30000","0.15753","0.51212"
"6.40000","0.16003","0.50522"
"6.50000","0.16258","0.50014"
"6.60000","0.16496","0.48619"
"6.70000","0.16751","0.50147"
"6.80000","0.17006","0.52161"
"6.90000","0.17255","0.52801"
"7.00000","0.17499","0.49461"
"7.10000","0.17748","0.52216"
"7.20000","0.18009","0.53617"
"7.30000","0.18258","0.51868"
"7.40000","0.18507","0.52860"
"7.50000","0.18751","0.55256"
"7.60000","0.19006","0.51440"
"7.70000","0.19267","0.56451"
"7.80000","0.19505","0.54550"
"7.90000","0.19760","0.53393"
"8.00000","0.20003","0.55346"
"8.10000","0.20258","0.57554"
"8.20000","0.20508","0.56836"
"8.30000","0.20746","0.56441"
"8.40000","0.21001","0.54473"
"8.50000","0.21256","0.57581"
"8.60000","0.21511","0.59544"
"8.70000","0.21754","0.56193"
"8.80000","0.22004","0.60633"
"8.90000","0.22253","0.59865"
"9.00000","0.22514","0.60556"
"9.10000","0.22757","0.60980"
"9.20000","0.22995","0.59430"
"9.30000","0.23250","0.59828"
"9.40000","0.23511","0.62124"
"9.50000","0.23755","0.60242"
"9.60000","0.23993","0.58758"
"9.70000","0.24253","0.59214"
"9.80000","0.24508","0.66652"
"9.90000","0.24763","0.61754"
"10.00000","0.25007","0.58341"
"10.10000","0.25251","0.64202"
"10.20000","0.25506","0.61404"
"10.30000","0.25766","0.65518"
"10.40000","0.26004","0.64714"
"10.50000","0.26248","0.61495"
"10.60000","0.26503","0.63698"
"10.70000","0.26758","0.61538"
"10.80000","0.27007","0.66533"
"10.90000","0.27245","0.64418"
"11.00000","0.27500","0.64389"
"11.10000","0.27755","0.66095"
"11.20000","0.28010","0.63235"
"11.30000","0.28254","0.65572"
"11.40000","0.28498","0.64826"
"11.50000","0.28753","0.66015"
"11.60000","0.29013","0.61726"
"11.70000","0.29257","0.70917"
"11.80000","0.29501","0.71886"
"11.90000","0.29750","0.65412"
"12.00000","0.29999","0.62652"
"12.10000","0.30254","0.68257"
"12.20000","0.30504","0.66540"
"12.30000","0.30747","0.71378"
"12.40000","0.31002","0.70283"
"12.50000","0.31257","0.67257"
"12.60000","0.31507","0.70833"
"12.70000","0.31750","0.68766"
"12.80000","0.32000","0.68466"
"12.90000","0.32255","0.70053"
"13.00000","0.32510","0.68426"
"13.10000","0.32748","0.71344"
"13.20000","0.32997","0.70712"
"13.30000","0.33258","0.70887"
"13.40000","0.33507","0.72508"
"13.50000","0.33745","0.68999"
"13.60000","0.34006","0.73330"
"13.70000","0.34249","0.69859"
"13.80000","0.34504","0.73963"
"13.90000","0.34759","0.71554"
"14.00000","0.35009","0.73605"
"14.10000","0.35252","0.75334"
"14.20000","0.35513","0.76086"
"14.30000","0.35751","0.75734"
"14.40000","0.36006","0.74799"
"14.50000","0.36261","0.72299"
"14.60000","0.36505","0.75133"
"14.70000","0.36760","0.77503"
"14.80000","0.36998","0.76439"
"14.90000","0.37247","0.75204"
"15.00000","0.37496","0.74379"
"15.10000","0.37751","0.76337"
"15.20000","0.37995","0.75710"
"15.30000","0.38256","0.78477"
"15.40000","0.38505","0.77061"
"15.50000","0.38754","0.78811"
"15.60000","0.39009","0.76741"
"15.70000","0.39253","0.79290"
"15.80000","0.39502","0.76910"
"15.90000","0.39757","0.77755"
"16.00000","0.40001","0.79285"
"16.10000","0.40245","0.77530"
"16.20000","0.40511","0.79907"
"16.30000","0.40760","0.79813"
"16.40000","0.41010","0.77821"
"16.50000","0.41253","0.80425"
"16.60000","0.41497","0.77834"
"16.70000","0.41758","0.80301"
"16.80000","0.42007","0.82704"
"16.90000","0.42251","0.79845"
"17.00000","0.42506","0.81101"
"17.10000","0.42755","0.78692"
"17.20000","0.43004","0.82421"
"17.30000","0.43259","0.80785"
"17.40000","0.43492","0.86883"
"17.50000","0.43752","0.82458"
"17.60000","0.44007","0.86020"
"17.70000","0.44251","0.83496"
"17.80000","0.44500","0.79200"
"17.90000","0.44750","0.85117"
"18.00000","0.44999","0.87314"
"18.10000","0.45260","0.83851"
"18.20000","0.45503","0.88438"
"18.30000","0.45747","0.79973"
"18.40000","0.46008","0.82888"
"18.50000","0.46263","0.84898"
"18.60000","0.46506","0.83317"
"18.70000","0.46750","0.84632"
"18.80000","0.46999","0.86210"
"18.90000","0.47254","0.84557"
"19.00000","0.47515","0.87539"
"19.10000","0.47747","0.86583"
"19.20000","0.48002","0.89955"
"19.30000","0.48252","0.85323"
"19.40000","0.48507","0.88394"
"19.50000","0.48756","0.86158"
"19.60000","0.49000","0.88649"
"19.70000","0.49249","0.86518"
"19.80000","0.49510","0.89377"
"19.90000","0.49753","0.89911"
"20.00000","0.49991","0.89898"
"20.10000","0.50258","0.89232"
"20.20000","0.50507","0.91040"
"20.30000","0.50762","0.92411"
"20.40000","0.51006","0.92891"
"20.50000","0.51244","0.94584"
"20.60000","0.51504","0.89585"
"20.70000","0.51759","0.90402"
"20.80000","0.52003","0.89941"
"20.90000","0.52252","0.94162"
"21.00000","0.52502","0.89589"
"21.10000","0.52751","0.90654"
"21.20000","0.53012","0.89482"
"21.30000","0.53255","0.92396"
"21.40000","0.53505","0.92085"
"21.50000","0.53760","0.92592"
"21.60000","0.54009","0.92400"
"21.70000","0.54253","0.93694"
"21.80000","0.54502","0.94633"
"21.90000","0.54746","0.94174"
"22.00000","0.55006","0.94269"
"22.10000","0.55256","0.95431"
"22.20000","0.55494","0.92523"
"22.30000","0.55749","0.96397"
"22.40000","0.56009","0.93722"
"22.50000","0.56259","0.94255"
"22.60000","0.56497","0.92704"
"22.70000","0.56752","0.94354"
"22.80000","0.57007","0.97221"
"22.90000","0.57262","0.95843"
"23.00000","0.57511","0.97093"
"23.10000","0.57755","0.91470"
"23.20000","0.57998","0.94982"
"23.30000","0.58253","0.97013"
"23.40000","0.58503","0.96434"
"23.50000","0.58758","0.97195"
"23.60000","0.59007","1.00066"
"23.70000","0.59262","1.00463"
"23.80000","0.59506","0.98822"
"23.90000","0.59749","0.96019"
"24.00000","0.60004","0.99725"
"24.10000","0.60248","1.03195"
"24.20000","0.60497","1.01103"
"24.30000","0.60747","1.03620"
"24.40000","0.61002","0.98933"
"24.50000","0.61245","1.00708"
"24.60000","0.61500","0.98739"
"24.70000","0.61750","0.98777"
"24.80000","0.61999","1.02940"
"24.90000","0.62254","1.04000"
"25.00000","0.62503","0.97306"
"25.10000","0.62747","1.01246"
"25.20000","0.62996","1.05561"
"25.30000","0.63263","1.02078"
"25.40000","0.63512","1.01537"
"25.50000","0.63756","1.04048"
"25.60000","0.63999","1.06224"
"25.70000","0.64254","1.06205"
"25.80000","0.64509","1.04578"
"25.90000","0.64753","1.00410"
"26.00000","0.65002","1.04526"
"26.10000","0.65252","1.05810"
"26.20000","0.65507","1.04047"
"26.30000","0.65762","1.04911"
"26.40000","0.66005","1.05048"
"26.50000","0.66243","1.08709"
"26.60000","0.66510","1.10082"
"26.70000","0.66753","1.08283"
"26.80000","0.67003","1.12465"
"26.90000","0.67252","1.06582"
"27.00000","0.67501","1.09316"
"27.10000","0.67751","1.07926"
"27.20000","0.68011","1.07262"
"27.30000","0.68244","1.07145"
"27.40000","0.68499","1.06761"
"27.50000","0.68759","1.13994"
"27.60000","0.69009","1.11271"
"27.70000","0.69252","1.10264"
"27.80000","0.69507","1.08702"
"27.90000","0.69751","1.06803"
"28.00000","0.70017","1.08034"
"28.10000","0.70261","1.10973"
"28.20000","0.70493","1.07152"
"28.30000","0.70760","1.08815"
"28.40000","0.71003","1.11856"
"28.50000","0.71258","1.11169"
"28.60000","0.71502","1.14785"
"28.70000","0.71746","1.11348"
"28.80000","0.72001","1.09388"
"28.90000","0.72261","1.12362"
"29.00000","0.72499","1.12025"
"29.10000","0.72749","1.12936"
"29.20000","0.73009","1.14367"
"29.30000","0.73253","1.10123"
"29.40000","0.73508","1.16550"
"29.50000","0.73752","1.13056"
"29.60000","0.74001","1.14149"
"29.70000","0.74256","1.20566"
"29.80000","0.74511","1.14559"
"29.90000","0.74749","1.15875"
"30.00000","0.74998","1.11826"
"30.10000","0.75248","1.14673"
"30.20000","0.75503","1.16465"
"30.30000","0.75763","1.18834"
"30.40000","0.76001","1.16296"
"30.50000","0.76256","1.17647"
"30.60000","0.76517","1.21153"
"30.70000","0.76761","1.16165"
"30.80000","0.76999","1.17927"
"30.90000","0.77248","1.15793"
"31.00000","0.77503","1.16677"
"31.10000","0.77764","1.16159"
"31.20000","0.78002","1.19424"
"31.30000","0.78245","1.21437"
"31.40000","0.78500","1.19645"
"31.50000","0.78755","1.21086"
"31.60000","0.78999","1.20913"
"31.70000","0.79248","1.19858"
"31.80000","0.79498","1.19362"
"31.90000","0.79753","1.22936"
"32.00000","0.80008","1.21105"
"32.10000","0.80257","1.20655"
"32.20000","0.80506","1.23890"
"32.30000","0.80756","1.20404"
"32.40000","0.80999","1.25575"
"32.50000","0.81249","1.27915"
"32.60000","0.81504","1.24507"
"32.70000","0.81753","1.22026"
"32.80000","0.82014","1.21559"
"32.90000","0.82252","1.22225"
"33.00000","0.82501","1.21894"
"33.10000","0.82756","1.23791"
"33.20000","0.83005","1.27337"
"33.30000","0.83249","1.26739"
"33.40000","0.83510","1.21687"
"33.50000","0.83753","1.26637"
"33.60000","0.84003","1.28883"
"33.70000","0.84258","1.27960"
"33.80000","0.84496","1.23767"
"33.90000","0.84751","1.24486"
"34.00000","0.85006","1.24306"
"34.10000","0.85255","1.26628"
"34.20000","0.85499","1.25467"
"34.30000","0.85748","1.29854"
"34.40000","0.86009","1.31046"
"34.50000","0.86258","1.29593"
"34.60000","0.86507","1.28703"
"34.70000","0.86751","1.30406"
"34.80000","0.87006","1.28730"
"34.90000","0.87267","1.28041"
"35.00000","0.87505","1.30280"
"35.10000","0.87760","1.28356"
"35.20000","0.88003","1.28547"
"35.30000","0.88258","1.30218"
"35.40000","0.88513","1.27891"
"35.50000","0.88746","1.29623"
"35.60000","0.89001","1.30809"
"35.70000","0.89261","1.34904"
"35.80000","0.89505","1.28604"
"35.90000","0.89754","1.34830"
"36.00000","0.90004","1.32565"
"36.10000","0.90253","1.31798"
"36.20000","0.90508","1.33715"
"36.30000","0.90757","1.31825"
"36.40000","0.90995","1.36211"
"36.50000","0.91250","1.35758"
"36.60000","0.91511","1.36115"
"36.70000","0.91755","1.34733"
"36.80000","0.91993","1.34776"
"36.90000","0.92253","1.37467"
"37.00000","0.92503","1.35129"
"37.10000","0.92763","1.34398"
"37.20000","0.93007","1.39582"
"37.30000","0.93251","1.37962"
"37.40000","0.93506","1.37279"
"37.50000","0.93761","1.37851"
"37.60000","0.94004","1.36000"
"37.70000","0.94248","1.40824"
"37.80000","0.94503","1.38470"
"37.90000","0.94758","1.40285"
"38.00000","0.95007","1.40081"
"38.10000","0.95251","1.40418"
"38.20000","0.95500","1.42385"
"38.30000","0.95755","1.36626"
"38.40000","0.96010","1.40521"
"38.50000","0.96254","1.40959"
"38.60000","0.96498","1.39695"
"38.70000","0.96753","1.41965"
"38.80000","0.97008","1.39059"
"38.90000","0.97257","1.41682"
"39.00000","0.97501","1.42062"
"39.10000","0.97750","1.40002"
"39.20000","0.98005","1.43836"
"39.30000","0.98260","1.40061"
"39.40000","0.98504","1.42621"
"39.50000","0.98747","1.38017"
"39.60000","0.99002","1.42009"
"39.70000","0.99252","1.43984"
"39.80000","0.99507","1.44684"
"39.90000","0.99750","1.44418"
"40.00000","1.00000","1.44634"
"40.10000","1.00255","1.44481"
"40.20000","1.00510","1.44187"
"40.30000","1.00742","1.43430"
"40.40000","1.01003","1.46948"
"40.50000","1.01258","1.45932"
"40.60000","1.01507","1.46032"
"40.70000","1.01751","1.48633"
"40.80000","1.02000","1.45574"
"40.90000","1.02249","1.44969"
"41.00000","1.02499","1.48143"
"41.10000","1.02754","1.46865"
"41.20000","1.03009","1.47905"
"41.30000","1.03252","1.46654"
"41.40000","1.03507","1.48220"
"41.50000","1.03751","1.49423"
"41.60000","1.04000","1.50442"
"41.70000","1.04255","1.47956"
"41.80000","1.04505","1.51338"
"41.90000","1.04765","1.50894"
"42.00000","1.04998","1.50649"
"42.10000","1.05253","1.51353"
"42.20000","1.05502","1.53251"
"42.30000","1.05751","1.52365"
"42.40000","1.05995","1.47677"
"42.50000","1.06256","1.48477"
"42.60000","1.06499","1.51069"
"42.70000","1.06760","1.49701"
"42.80000","1.07009","1.52146"
"42.90000","1.07253","1.50171"
"43.00000","1.07502","1.48785"
"43.10000","1.07757","1.51012"
"43.20000","1.08007","1.55921"
"43.30000","1.08250","1.52460"
"43.40000","1.08511","1.51029"
"43.50000","1.08755","1.52171"
"43.60000","1.09010","1.53762"
"43.70000","1.09253","1.57201"
"43.80000","1.09497","1.55213"
"43.90000","1.09758","1.54164"
"44.00000","1.10013","1.52724"
"44.10000","1.10251","1.57051"
"44.20000","1.10506","1.55177"
"44.30000","1.10749","1.50467"
"44.40000","1.11010","1.56069"
"44.50000","1.11259","1.55603"
"44.60000","1.11492","1.54413"
"44.70000","1.11752","1.60416"
"44.80000","1.12007","1.56782"
"44.90000","1.12251","1.58134"
"45.00000","1.12500","1.57144"
"45.10000","1.12750","1.54708"
"45.20000","1.12999","1.57839"
"45.30000","1.13260","1.60618"
"45.40000","1.13503","1.60965"
"45.50000","1.13747","1.56241"
"45.60000","1.14008","1.59145"
"45.70000","1.14263","1.60074"
"45.80000","1.14506","1.57967"
"45.90000","1.14744","1.60323"
"46.00000","1.15005","1.66941"
"46.10000","1.15254","1.58314"
"46.20000","1.15515","1.59888"
"46.30000","1.15747","1.58153"
"46.40000","1.16002","1.60293"
"46.50000","1.16252","1.59194"
"46.60000","1.16507","1.60367"
"46.70000","1.16750","1.61770"
"46.80000","1.17000","1.61597"
"46.90000","1.17249","1.63720"
"47.00000","1.17510","1.65021"
"47.10000","1.17753","1.60451"
"47.20000","1.17991","1.67904"
"47.30000","1.18258","1.64230"
"47.40000","1.18507","1.64881"
"47.50000","1.18762","1.66330"
"47.60000","1.19006","1.62005"
"47.70000","1.19249","1.63591"
"47.80000","1.19504","1.62599"
"47.90000","1.19759","1.67557"
"48.00000","1.20003","1.64647"
"48.10000","1.20252","1.66182"
"48.20000","1.20502","1.63251"
"48.30000","1.20751","1.69204"
"48.40000","1.21012","1.66062"
"48.50000","1.21255","1.69209"
"48.60000","1.21505","1.67498"
"48.70000","1.21760","1.68609"
"48.80000","1.22009","1.68951"
"48.90000","1.22253","1.67949"
"49.00000","1.22502","1.67424"
"49.10000","1.22746","1.62998"
"49.20000","1.23001","1.66817"
"49.30000","1.23256","1.68876"
"49.40000","1.23494","1.67959"
"49.50000","1.23754","1.69306"
"49.60000","1.24009","1.70063"
"49.70000","1.24253","1.69849"
"49.80000","1.24497","1.71787"
"49.90000","1.24752","1.69314"
"50.00000","1.25001","1.69752"
"50.10000","1.25256","1.73127"
"50.20000","1.25511","1.70538"
"50.30000","1.25755","1.74044"
"50.40000","1.26004","1.70577"
"50.50000","1.26259","1.72868"
"50.60000","1.26503","1.71066"
"50.70000","1.26758","1.71597"
"50.80000","1.27007","1.73949"
"50.90000","1.27262","1.73382"
"51.00000","1.27506","1.72040"
"51.10000","1.27749","1.73153"
"51.20000","1.28004","1.74992"
"51.30000","1.28254","1.73791"
"51.40000","1.28503","1.72089"
"51.50000","1.28752","1.73699"
"51.60000","1.29002","1.71121"
"51.70000","1.29245","1.74972"
"51.80000","1.29500","1.79459"
"51.90000","1.29755","1.79574"
"52.00000","1.29999","1.78323"
"52.10000","1.30254","1.73867"
"52.20000","1.30509","1.79775"
"52.30000","1.30747","1.78322"
"52.40000","1.31002","1.76947"
"52.50000","1.31263","1.76132"
"52.60000","1.31506","1.76413"
"52.70000","1.31761","1.77155"
"52.80000","1.31999","1.76160"
"52.90000","1.32249","1.79069"
"53.00000","1.32515","1.79895"
"53.10000","1.32753","1.78707"
"53.20000","1.33002","1.80267"
"53.30000","1.33252","1.81461"
"53.40000","1.33501","1.78336"
"53.50000","1.33762","1.84498"
"53.60000","1.34000","1.80748"
"53.70000","1.34249","1.82894"
"53.80000","1.34515","1.81706"
"53.90000","1.34753","1.81152"
"54.00000","1.35003","1.81885"
"54.10000","1.35252","1.80091"
"54.20000","1.35501","1.82036"
"54.30000","1.35756","1.82266"
"54.40000","1.36006","1.83471"
"54.50000","1.36249","1.80799"
"54.60000","1.36499","1.80471"
"54.70000","1.36759","1.82024"
"54.80000","1.37009","1.84648"
"54.90000","1.37252","1.85018"
"55.00000","1.37502","1.81687"
"55.10000","1.37751","1.87119"
"55.20000","1.38012","1.83495"
"55.30000","1.38261","1.88083"
"55.40000","1.38493","1.88975"
"55.50000","1.38760","1.84543"
"55.60000","1.39003","1.88287"
"55.70000","1.39258","1.87975"
"55.80000","1.39502","1.83748"
"55.90000","1.39746","1.87795"
"56.00000","1.40001","1.88998"
"56.10000","1.40261","1.89326"
"56.20000","1.40499","1.86093"
"56.30000","1.40749","1.87694"
"56.40000","1.41004","1.86932"
"56.50000","1.41259","1.87786"
"56.60000","1.41508","1.89021"
"56.70000","1.41746","1.92770"
"56.80000","1.42007","1.91146"
"56.90000","1.42256","1.91195"
"57.00000","1.42511","1.94131"
"57.10000","1.42749","1.87042"
"57.20000","1.42998","1.91862"
"57.30000","1.43248","1.90476"
"57.40000","1.43503","1.92709"
"57.50000","1.43758","1.89041"
"57.60000","1.44007","1.92326"
"57.70000","1.44256","1.92743"
"57.80000","1.44511","1.92076"
"57.90000","1.44761","1.89723"
"58.00000","1.44999","1.89793"
"58.10000","1.45248","1.92857"
"58.20000","1.45503","1.95430"
"58.30000","1.45758","1.93582"
"58.40000","1.45996","1.94191"
"58.50000","1.46245","1.93119"
"58.60000","1.46500","1.93095"
"58.70000","1.46761","1.93431"
"58.80000","1.47005","1.93995"
"58.90000","1.47248","1.91633"
"59.00000","1.47498","1.94922"
"59.10000","1.47753","1.93222"
"59.20000","1.48008","1.90913"
"59.30000","1.48257","1.95038"
"59.40000","1.48501","1.95382"
"59.50000","1.48756","1.93614"
"59.60000","1.49005","1.93976"
"59.70000","1.49249","1.95682"
"59.80000","1.49504","1.94374"
"59.90000","1.49753","1.95235"
"60.00000","1.50014","2.00365"
"60.10000","1.50246","1.97876"
"60.20000","1.50501","1.98346"
"60.30000","1.50750","1.96881"
"60.40000","1.51011","2.02216"
"60.50000","1.51255","1.96470"
"60.60000","1.51504","1.96776"
"60.70000","1.51753","2.00089"
"60.80000","1.52003","1.99482"
"60.90000","1.52258","2.02158"
"61.00000","1.52501","1.99200"
"61.10000","1.52751","2.00727"
"61.20000","1.53000","1.96130"
"61.30000","1.53255","1.99042"
"61.40000","1.53499","2.03768"
"61.50000","1.53748","2.03012"
"61.60000","1.54009","1.99908"
"61.70000","1.54258","1.98731"
"61.80000","1.54502","1.99495"
"61.90000","1.54751","1.99851"
"62.00000","1.55006","2.02845"
"62.10000","1.55267","2.06382"
"62.20000","1.55505","2.02720"
"62.30000","1.55754","1.99527"
"62.40000","1.56003","2.00797"
"62.50000","1.56253","2.03312"
"62.60000","1.56508","2.01534"
"62.70000","1.56751","2.03153"
"62.80000","1.56995","1.99573"
"62.90000","1.57261","2.00250"
"63.00000","1.57511","2.03586"
"63.10000","1.57754","2.05010"
"63.20000","1.57998","2.03181"
"63.30000","1.58253","2.03209"
"63.40000","1.58508","2.05032"
"63.50000","1.58757","2.04400"
"63.60000","1.58995","2.02560"
"63.70000","1.59250","2.07313"
"63.80000","1.59517","2.06538"
"63.90000","1.59755","2.05294"
"64.00000","1.59993","2.06792"
"64.10000","1.60253","2.05778"
"64.20000","1.60497","2.07026"
"64.30000","1.60763","2.05699"
"64.40000","1.61007","2.06130"
"64.50000","1.61251","2.12132"
"64.60000","1.61506","2.09502"
"64.70000","1.61761","2.08957"
"64.80000","1.62004","2.08586"
"64.90000","1.62248","2.13735"
"65.00000","1.62497","2.07791"
"65.10000","1.62758","2.11376"
"65.20000","1.63007","2.06707"
"65.30000","1.63245","2.06885"
"65.40000","1.63500","2.12658"
"65.50000","1.63761","2.11531"
"65.60000","1.64010","2.12533"
"65.70000","1.64254","2.13257"
"65.80000","1.64498","2.09439"
"65.90000","1.64753","2.09446"
"66.00000","1.65013","2.10096"
"66.10000","1.65257","2.14354"
"66.20000","1.65501","2.14317"
"66.30000","1.65750","2.12433"
"66.40000","1.66005","2.13521"
"66.50000","1.66254","2.13913"
"66.60000","1.66504","2.14461"
"66.70000","1.66747","2.13569"
"66.80000","1.67002","2.17146"
"66.90000","1.67257","2.12164"
"67.00000","1.67507","2.15631"
"67.10000","1.67750","2.14577"
"67.20000","1.68000","2.15856"
"67.30000","1.68255","2.15522"
"67.40000","1.68510","2.18219"
"67.50000","1.68748","2.16461"
"67.60000","1.68997","2.15357"
"67.70000","1.69258","2.14540"
"67.80000","1.69507","2.16468"
"67.90000","1.69751","2.18624"
"68.00000","1.70006","2.15952"
"68.10000","1.70255","2.21788"
"68.20000","1.70504","2.18183"
"68.30000","1.70759","2.19233"
"68.40000","1.71009","2.17458"
"68.50000","1.71252","2.19339"
"68.60000","1.71513","2.18599"
"68.70000","1.71751","2.17425"
"68.80000","1.72006","2.21044"
"68.90000","1.72261","2.21555"
"69.00000","1.72505","2.20366"
"69.10000","1.72760","2.20366"
"69.20000","1.72998","2.20991"
"69.30000","1.73247","2.19557"
"69.40000","1.73502","2.20212"
"69.50000","1.73751","2.19422"
"69.60000","1.73995","2.22404"
"69.70000","1.74256","2.22535"
"69.80000","1.74494","2.21944"
"69.90000","1.74754","2.22235"
"70.00000","1.75009","2.22950"
"70.10000","1.75247","2.25866"
"70.20000","1.75502","2.23414"
"70.30000","1.75757","2.21691"
"70.40000","1.76007","2.23932"
"70.50000","1.76250","2.24057"
"70.60000","1.76511","2.24757"
"70.70000","1.76755","2.24764"
"70.80000","1.77004","2.25472"
"70.90000","1.77253","2.24422"
"71.00000","1.77497","2.27485"
"71.10000","1.77758","2.28810"
"71.20000","1.78013","2.24153"
"71.30000","1.78251","2.28907"
"71.40000","1.78506","2.28996"
"71.50000","1.78749","2.32010"
"71.60000","1.79004","2.28832"
"71.70000","1.79259","2.27805"
"71.80000","1.79492","2.25916"
"71.90000","1.79752","2.30468"
"72.00000","1.80007","2.29528"
"72.10000","1.80251","2.28286"
"72.20000","1.80500","2.29714"
"72.30000","1.80744","2.30153"
"72.40000","1.80999","2.28977"
"72.50000","1.81260","2.32239"
"72.60000","1.81509","2.33314"
"72.70000","1.81747","2.29128"
"72.80000","1.82008","2.32128"
"72.90000","1.82268","2.30825"
"73.00000","1.82506","2.34883"
"73.10000","1.82744","2.30812"
"73.20000","1.83005","2.33043"
"73.30000","1.83260","2.31557"
"73.40000","1.83515","2.33068"
"73.50000","1.83747","2.34413"
"73.60000","1.84002","2.32805"
"73.70000","1.84252","2.34341"
"73.80000","1.84512","2.33296"
"73.90000","1.84750","2.37217"
"74.00000","1.85000","2.37428"
"74.10000","1.85249","2.33321"
"74.20000","1.85510","2.33712"
"74.30000","1.85753","2.36471"
"74.40000","1.85991","2.37021"
"74.50000","1.86252","2.36535"
"74.60000","1.86507","2.37245"
"74.70000","1.86762","2.31999"
"74.80000","1.87000","2.36757"
"74.90000","1.87249","2.38131"
"75.00000","1.87504","2.39074"
"75.10000","1.87759","2.34776"
"75.20000","1.88003","2.35016"
"75.30000","1.88252","2.37445"
"75.40000","1.88496","2.37156"
"75.50000","1.88757","2.38755"
"75.60000","1.89012","2.41697"
"75.70000","1.89255","2.42751"
"75.80000","1.89505","2.36890"
"75.90000","1.89760","2.38796"
"76.00000","1.90009","2.39815"
"76.10000","1.90253","2.42263"
"76.20000","1.90496","2.39161"
"76.30000","1.90751","2.39329"
"76.40000","1.91006","2.40147"
"76.50000","1.91256","2.40131"
"76.60000","1.91499","2.40945"
"76.70000","1.91749","2.41768"
"76.80000","1.92009","2.44191"
"76.90000","1.92259","2.44592"
"77.00000","1.92497","2.45073"
"77.10000","1.92752","2.43793"
"77.20000","1.93001","2.42454"
"77.30000","1.93256","2.40330"
"77.40000","1.93505","2.39716"
"77.50000","1.93755","2.41056"
"77.60000","1.93998","2.42914"
"77.70000","1.94259","2.49319"
"77.80000","1.94503","2.44540"
"77.90000","1.94758","2.45571"
"78.00000","1.95007","2.45786"
"78.10000","1.95262","2.45576"
"78.20000","1.95506","2.44315"
"78.30000","1.95749","2.45130"
"78.40000","1.95999","2.47710"
"78.50000","1.96254","2.44337"
"78.60000","1.96503","2.43328"
"78.70000","1.96752","2.48351"
"78.80000","1.97002","2.50127"
"78.90000","1.97245","2.49391"
"79.00000","1.97500","2.49824"
"79.10000","1.97755","2.47029"
"79.20000","1.97999","2.53511"
"79.30000","1.98254","2.45209"
"79.40000","1.98509","2.49382"
"79.50000","1.98747","2.50240"
"79.60000","1.99002","2.48296"
"79.70000","1.99263","2.50810"
"79.80000","1.99506","2.45902"
"79.90000","1.99756","2.49196"
"80.00000","1.99999","2.52086"
"80.10000","2.00249","2.50428"
"80.20000","2.00515","2.47169"
"80.30000","2.00753","2.50988"
"80.40000","2.01002","2.56959"
"80.50000","2.01252","2.51736"
"80.60000","2.01501","2.54179"
"80.70000","2.01762","2.49253"
"80.80000","2.02005","2.52505"
"80.90000","2.02243","2.50376"
"81.00000","2.02515","2.53056"
"81.10000","2.02759","2.55405"
"81.20000","2.03003","2.55051"
"81.30000","2.03252","2.55116"
"81.40000","2.03501","2.53282"
"81.50000","2.03751","2.53557"
"81.60000","2.04011","2.57092"
"81.70000","2.04249","2.56722"
"81.80000","2.04499","2.58348"
"81.90000","2.04759","2.54852"
"82.00000","2.05009","2.57561"
"82.10000","2.05252","2.55082"
"82.20000","2.05502","2.50710"
"82.30000","2.05745","2.58601"
"82.40000","2.06012","2.53447"
"82.50000","2.06261","2.56310"
"82.60000","2.06493","2.54458"
"82.70000","2.06760","2.55516"
"82.80000","2.07003","2.58206"
"82.90000","2.07258","2.58817"
"83.00000","2.07502","2.56548"
"83.10000","2.07746","2.57186"
"83.20000","2.08001","2.60114"
"83.30000","2.08261","2.57741"
"83.40000","2.08499","2.59461"
"83.50000","2.08749","2.58400"
"83.60000","2.09004","2.58704"
"83.70000","2.09259","2.60112"
"83.80000","2.09508","2.59998"
"83.90000","2.09746","2.56471"
"84.00000","2.10007","2.62485"
"84.10000","2.10262","2.63299"
"84.20000","2.10505","2.60511"
"84.30000","2.10749","2.60238"
"84.40000","2.10998","2.61554"
"84.50000","2.11248","2.64217"
"84.60000","2.11497","2.61811"
"84.70000","2.11758","2.58794"
"84.80000","2.12001","2.62574"
"84.90000","2.12251","2.63084"
"85.00000","2.12511","2.59336"
"85.10000","2.12761","2.61911"
"85.20000","2.12999","2.61987"
"85.30000","2.13254","2.64671"
"85.40000","2.13503","2.61432"
"85.50000","2.13764","2.62913"
"85.60000","2.14002","2.62802"
"85.70000","2.14245","2.65687"
"85.80000","2.14500","2.62099"
"85.90000","2.14761","2.65130"
"86.00000","2.15005","2.65914"
"86.10000","2.15248","2.65595"
"86.20000","2.15503","2.64972"
"86.30000","2.15753","2.65529"
"86.40000","2.16008","2.68888"
"86.50000","2.16257","2.63744"
"86.60000","2.16501","2.66597"
"86.70000","2.16756","2.66314"
"86.80000","2.16999","2.68192"
"86.90000","2.17249","2.71267"
"87.00000","2.17498","2.68657"
"87.10000","2.17747","2.65672"
"87.20000","2.18014","2.73868"
"87.30000","2.18246","2.68798"
"87.40000","2.18501","2.68986"
"87.50000","2.18756","2.67141"
"87.60000","2.19011","2.67398"
"87.70000","2.19249","2.69110"
"87.80000","2.19504","2.70613"
"87.90000","2.19753","2.70384"
"88.00000","2.20003","2.67908"
"88.10000","2.20258","2.67465"
"88.20000","2.20501","2.72170"
"88.30000","2.20756","2.72538"
"88.40000","2.21006","2.73868"
"88.50000","2.21255","2.73016"
"88.60000","2.21499","2.76150"
"88.70000","2.21748","2.72186"
"88.80000","2.22009","2.76464"
"88.90000","2.22258","2.73952"
"89.00000","2.22502","2.75867"
"89.10000","2.22751","2.76325"
"89.20000","2.23006","2.72221"
"89.30000","2.23261","2.75205"
"89.40000","2.23510","2.71834"
"89.50000","2.23760","2.69261"
"89.60000","2.23998","2.74931"
"89.70000","2.24258","2.76693"
"89.80000","2.24508","2.74082"
"89.90000","2.24746","2.73141"
"90.00000","2.24995","2.72959"
"90.10000","2.25256","2.81145"
"90.20000","2.25511","2.76067"
"90.30000","2.25754","2.76695"
"90.40000","2.26004","2.77753"
"90.50000","2.26253","2.79070"
"90.60000","2.26514","2.79108"
"90.70000","2.26763","2.79194"
"90.80000","2.26995","2.76730"
"90.90000","2.27250","2.81030"
"91.00000","2.27511","2.81669"
"91.10000","2.27755","2.78180"
"91.20000","2.27993","2.82438"
"91.30000","2.28253","2.82299"
"91.40000","2.28497","2.84420"
"91.50000","2.28763","2.80342"
"91.60000","2.29007","2.83610"
"91.70000","2.29245","2.79056"
"91.80000","2.29506","2.79735"
"91.90000","2.29761","2.80558"
"92.00000","2.30004","2.84166"
"92.10000","2.30248","2.80709"
"92.20000","2.30497","2.81458"
"92.30000","2.30758","2.79952"
"92.40000","2.31007","2.81447"
"92.50000","2.31245","2.85775"
"92.60000","2.31500","2.83599"
"92.70000","2.31755","2.80247"
"92.80000","2.32010","2.84961"
"92.90000","2.32254","2.85409"
"93.00000","2.32503","2.87832"
"93.10000","2.32753","2.83695"
"93.20000","2.33008","2.84621"
"93.30000","2.33257","2.86335"
"93.40000","2.33501","2.85143"
"93.50000","2.33756","2.85857"
"93.60000","2.33999","2.85946"
"93.70000","2.34260","2.87861"
"93.80000","2.34509","2.86114"
"93.90000","2.34747","2.86402"
"94.00000","2.35002","2.87379"
"94.10000","2.35252","2.86194"
"94.20000","2.35507","2.88277"
"94.30000","2.35750","2.87990"
"94.40000","2.36000","2.87056"
"94.50000","2.36255","2.89686"
"94.60000","2.36510","2.88497"
"94.70000","2.36742","2.90278"
"94.80000","2.36997","2.89840"
"94.90000","2.37258","2.91750"
"95.00000","2.37507","2.91393"
"95.10000","2.37745","2.88888"
"95.20000","2.38006","2.95715"
"95.30000","2.38255","2.88606"
"95.40000","2.38504","2.89959"
"95.50000","2.38759","2.88941"
"95.60000","2.39009","2.94598"
"95.70000","2.39252","2.92461"
"95.80000","2.39507","2.92989"
"95.90000","2.39751","2.94665"
"96.00000","2.40006","2.91557"
"96.10000","2.40261","2.93315"
"96.20000","2.40505","2.96086"
"96.30000","2.40760","2.96343"
"96.40000","2.40998","2.96751"
"96.50000","2.41253","2.95451"
"96.60000","2.41502","2.93775"
"96.70000","2.41751","2.98767"
"96.80000","2.41995","2.95491"
"96.90000","2.42256","2.98108"
"97.00000","2.42499","2.96835"
"97.10000","2.42760","2.95035"
"97.20000","2.43009","2.95937"
"97.30000","2.43247","2.97397"
"97.40000","2.43502","2.99089"
"97.50000","2.43757","2.97020"
"97.60000","2.44007","3.01449"
"97.70000","2.44245","2.95899"
"97.80000","2.44505","2.97752"
"97.90000","2.44760","2.98695"
"98.00000","2.45010","3.03391"
"98.10000","2.45248","3.00995"
"98.20000","2.45497","2.97824"
"98.30000","2.45763","2.99463"
"98.40000","2.46013","2.99683"
"98.50000","2.46256","3.00673"
"98.60000","2.46506","2.98920"
"98.70000","2.46749","2.99879"
"98.80000","2.47010","3.01369"
"98.90000","2.47259","3.01916"
"99.00000","2.47492","3.01775"
"99.10000","2.47758","3.03507"
"99.20000","2.48007","3.04609"
"99.30000","2.48251","3.03306"
"99.40000","2.48500","3.05631"
"99.50000","2.48744","3.03811"
"99.60000","2.48999","3.01846"
"99.70000","2.49260","3.03029"
"99.80000","2.49503","3.03894"
"99.90000","2.49747","3.07471"
"99.99800","2.50002","3.03436"
"100.00000","2.50008","3.03522"
"100.10000","2.49605","3.03977"
"100.20000","2.48398","3.00601"
"100.30000","2.47509","2.94656"
"100.40000","2.46670","3.00261"
"100.50000","2.45843","2.94482"
"100.60000","2.44998","2.93892"
"100.70000","2.44160","2.95797"
"100.80000","2.43332","2.90524"
"100.90000","2.42505","2.89584"
"101.00000","2.41672","2.86888"
"101.10000","2.40839","2.89532"
"101.20000","2.39995","2.88552"
"101.30000","2.39162","2.85839"
"101.40000","2.38329","2.83837"
"101.50000","2.37501","2.82520"
"101.60000","2.36663","2.82283"
"101.70000","2.35830","2.82560"
"101.80000","2.35002","2.77336"
"101.90000","2.34169","2.78893"
"102.00000","2.33336","2.83010"
"102.10000","2.32486","2.76698"
"102.20000","2.31670","2.79134"
"102.30000","2.30843","2.74537"
"102.40000","2.29999","2.71366"
"102.50000","2.29166","2.71819"
"102.60000","2.28327","2.69278"
"102.70000","2.27505","2.67509"
"102.80000","2.26667","2.73108"
"102.90000","2.25828","2.65270"
"103.00000","2.24995","2.66566"
"103.10000","2.24173","2.62919"
"103.20000","2.23340","2.61476"
"103.30000","2.22496","2.59086"
"103.40000","2.21657","2.58346"
"103.50000","2.20830","2.55367"
"103.60000","2.20008","2.59155"
"103.70000","2.19170","2.57335"
"103.80000","2.18331","2.53070"
"103.90000","2.17492","2.56084"
"104.00000","2.16671","2.55476"
"104.10000","2.15832","2.53897"
"104.20000","2.14993","2.53515"
"104.30000","2.14166","2.50979"
"104.40000","2.13333","2.48800"
"104.50000","2.12506","2.50157"
"104.60000","2.11661","2.47146"
"104.70000","2.10834","2.48220"
"104.80000","2.09995","2.42698"
"104.90000","2.09174","2.42434"
"105.00000","2.08335","2.42643"
"105.10000","2.07496","2.39135"
"105.20000","2.06658","2.38552"
"105.30000","2.05830","2.36042"
"105.40000","2.05003","2.34238"
"105.50000","2.04159","2.34923"
"105.60000","2.03331","2.34154"
"105.70000","2.02510","2.32113"
"105.80000","2.01671","2.31601"
"105.90000","2.00827","2.29160"
"106.00000","1.99988","2.31021"
"106.10000","1.99161","2.31745"
"106.20000","1.98339","2.26028"
"106.30000","1.97512","2.25571"
"106.40000","1.96667","2.22841"
"106.50000","1.95834","2.24194"
"106.60000","1.95001","2.21377"
"106.70000","1.94168","2.22576"
"106.80000","1.93330","2.17421"
"106.90000","1.92491","2.15928"
"107.00000","1.91675","2.17252"
"107.10000","1.90848","2.17148"
"107.20000","1.90003","2.13901"
"107.30000","1.89165","2.17328"
"107.40000","1.88320","2.13832"
"107.50000","1.87499","2.11352"
"107.60000","1.86666","2.09808"
"107.70000","1.85838","2.11304"
"107.80000","1.85000","2.06922"
"107.90000","1.84167","2.07408"
"108.00000","1.83328","2.02716"
"108.10000","1.82495","2.04976"
"108.20000","1.81656","2.05188"
"108.30000","1.80835","2.01064"
"108.40000","1.80007","1.98405"
"108.50000","1.79174","2.02712"
"108.60000","1.78330","1.97622"
"108.70000","1.77491","1.98560"
"108.80000","1.76670","1.94152"
"108.90000","1.75831","1.88183"
"109.00000","1.74998","1.95502"
"109.10000","1.74165","1.92976"
"109.20000","1.73338","1.92107"
"109.30000","1.72510","1.87564"
"109.40000","1.71660","1.90964"
"109.50000","1.70833","1.88292"
"109.60000","1.69994","1.86207"
"109.70000","1.69173","1.86111"
"109.80000","1.68345","1.81114"
"109.90000","1.67495","1.83122"
"110.00000","1.66662","1.81342"
"110.10000","1.65835","1.84972"
"110.20000","1.65008","1.79168"
"110.30000","1.64163","1.78462"
"110.40000","1.63330","1.76665"
"110.50000","1.62503","1.77934"
"110.60000","1.61676","1.74175"
"110.70000","1.60837","1.70996"
"110.80000","1.59993","1.72955"
"110.90000","1.59154","1.70874"
"111.00000","1.58321","1.72023"
"111.10000","1.57499","1.69431"
"111.20000","1.56655","1.68321"
"111.30000","1.55828","1.69299"
"111.40000","1.54989","1.64654"
"111.50000","1.54167","1.64716"
"111.60000","1.53329","1.62300"
"111.70000","1.52496","1.58524"
"111.80000","1.51668","1.61358"
"111.90000","1.50835","1.62157"
"112.00000","1.50008","1.60017"
"112.10000","1.49164","1.60281"
"112.20000","1.48331","1.57196"
"112.30000","1.47498","1.56858"
"112.40000","1.46676","1.53606"
"112.50000","1.45837","1.54614"
"112.60000","1.44999","1.52802"
"112.70000","1.44166","1.51171"
"112.80000","1.43333","1.48397"
"112.90000","1.42500","1.50805"
"113.00000","1.41655","1.43389"
"113.10000","1.40834","1.44017"
"113.20000","1.40006","1.42894"
"113.30000","1.39173","1.44409"
"113.40000","1.38335","1.41120"
"113.50000","1.37490","1.40192"
"113.60000","1.36657","1.39046"
"113.70000","1.35836","1.37314"
"113.80000","1.35003","1.39853"
"113.90000","1.34164","1.36311"
"114.00000","1.33331","1.32632"
"114.10000","1.32504","1.35763"
"114.20000","1.31659","1.33373"
"114.30000","1.30826","1.32879"
"114.40000","1.29993","1.29677"
"114.50000","1.29172","1.28288"
"114.60000","1.28344","1.26990"
"114.70000","1.27500","1.26286"
"114.80000","1.26661","1.27564"
"114.90000","1.25823","1.22984"
"115.00000","1.24995","1.23057"
"115.10000","1.24168","1.24962"
"115.20000","1.23329","1.25908"
"115.30000","1.22496","1.21462"
"115.40000","1.21675","1.19298"
"115.50000","1.20830","1.21394"
"115.60000","1.19997","1.14671"
"115.70000","1.19153","1.20158"
"115.80000","1.18331","1.13052"
"115.90000","1.17504","1.12761"
"116.00000","1.16671","1.12434"
"116.10000","1.15838","1.12926"
"116.20000","1.14994","1.10964"
"116.30000","1.14172","1.09810"
"116.40000","1.13328","1.09712"
"116.50000","1.12500","1.06980"
"116.60000","1.11662","1.07280"
"116.70000","1.10840","1.07444"
"116.80000","1.10007","1.03166"
"116.90000","1.09163","1.03107"
"117.00000","1.08324","1.05332"
"117.10000","1.07497","1.01558"
"117.20000","1.06669","1.01382"
"117.30000","1.05831","0.98684"
"117.40000","1.05003","0.98650"
"117.50000","1.04159","0.96651"
"117.60000","1.03337","0.93406"
"117.70000","1.02499","0.93263"
"117.80000","1.01660","0.94972"
"117.90000","1.00827","0.93993"
"118.00000","1.00000","0.93580"
"118.10000","0.99178","0.86594"
"118.20000","0.98334","0.87006"
"118.30000","0.97501","0.87477"
"118.40000","0.96662","0.88613"
"118.50000","0.95835","0.81124"
"118.60000","0.95002","0.84089"
"118.70000","0.94163","0.87558"
"118.80000","0.93330","0.89301"
"118.90000","0.92491","0.81629"
"119.00000","0.91670","0.80296"
"119.10000","0.90831","0.78914"
"119.20000","0.89998","0.82434"
"119.30000","0.89165","0.75489"
"119.40000","0.88332","0.76024"
"119.50000","0.87499","0.75685"
"119.60000","0.86660","0.71727"
"119.70000","0.85833","0.71738"
"119.80000","0.85000","0.72305"
"119.90000","0.84173","0.75617"
"120.00000","0.83334","0.67908"
"120.10000","0.82495","0.68728"
"120.20000","0.81662","0.65032"
"120.30000","0.80829","0.67846"
"120.40000","0.80002","0.63082"
"120.50000","0.79169","0.69214"
"120.60000","0.78342","0.63984"
"120.70000","0.77514","0.61822"
"120.80000","0.76664","0.63524"
"120.90000","0.75826","0.58582"
"121.00000","0.74993","0.59346"
"121.10000","0.74160","0.55128"
"121.20000","0.73332","0.60207"
"121.30000","0.72505","0.51030"
"121.40000","0.71666","0.55201"
"121.50000","0.70839","0.51360"
"121.60000","0.70000","0.50138"
"121.70000","0.69162","0.49382"
"121.80000","0.68323","0.53234"
"121.90000","0.67501","0.51628"
"122.00000","0.66668","0.46389"
"122.10000","0.65835","0.46252"
"122.20000","0.65002","0.44482"
"122.30000","0.64158","0.46049"
"122.40000","0.63336","0.46729"
"122.50000","0.62498","0.42852"
"122.60000","0.61665","0.40924"
"122.70000","0.60837","0.40358"
"122.80000","0.59999","0.37866"
"122.90000","0.59171","0.41456"
"123.00000","0.58327","0.36732"
"123.10000","0.57500","0.36603"
"123.20000","0.56661","0.39094"
"123.30000","0.55839","0.37412"
"123.40000","0.55006","0.32950"
"123.50000","0.54173","0.34521"
"123.60000","0.53329","0.33236"
"123.70000","0.52496","0.31914"
"123.80000","0.51663","0.30534"
"123.90000","0.50824","0.30850"
"124.00000","0.50003","0.30264"
"124.10000","0.49170","0.31022"
"124.20000","0.48342","0.27829"
"124.30000","0.47504","0.25968"
"124.40000","0.46659","0.24281"
"124.50000","0.45826","0.24295"
"124.60000","0.44993","0.22278"
"124.70000","0.44166","0.20386"
"124.80000","0.43327","0.22070"
"124.90000","0.42494","0.17106"
"125.00000","0.41661","0.18825"
"125.10000","0.40834","0.15545"
"125.20000","0.39995","0.20493"
"125.30000","0.39162","0.12328"
"125.40000","0.38329","0.15451"
"125.50000","0.37508","0.13254"
"125.60000","0.36675","0.11711"
"125.70000","0.35830","0.10363"
"125.80000","0.34997","0.11075"
"125.90000","0.34164","0.12351"
"126.00000","0.33343","0.09389"
"126.10000","0.32504","0.11794"
"126.20000","0.31665","0.04911"
"126.30000","0.30832","0.08782"
"126.40000","0.29999","0.03204"
"126.50000","0.29172","0.07326"
"126.60000","0.28328","0.05203"
"126.70000","0.27506","0.03585"
"126.80000","0.26673","0.03485"
"126.90000","0.25834","-0.01326"
"127.00000","0.24996","0.01290"
"127.10000","0.24151","0.01631"
"127.20000","0.23335","0.06806"
"127.30000","0.22497","0.04237"
"127.40000","0.21669","-0.00750"
"127.50000","0.20831","0.03969"
"127.60000","0.20003","0.00557"
"127.70000","0.19159","0.01933"
"127.80000","0.18332","0.03711"
"127.90000","0.17493","0.01770"
"128.00000","0.16666","0.03157"
"128.10000","0.15838","-0.00934"
"128.20000","0.15011","0.04595"
"128.30000","0.14172","0.03634"
"128.40000","0.13317","0.04200"
"128.50000","0.12495","0.01346"
"128.60000","0.11662","0.00930"
"128.70000","0.10835","0.04588"
"128.80000","0.10002","0.02218"
"128.90000","0.09169","0.02299"
"129.00000","0.08341","0.00073"
"129.10000","0.07497","0.02671"
"129.20000","0.06664","0.06122"
"129.30000","0.05820","0.02511"
"129.40000","0.05004","0.03645"
"129.50000","0.04176","0.05101"
"129.60000","0.03338","0.02174"
"129.70000","0.02493","0.00810"
"129.80000","0.01660","0.06928"
"129.90000","0.00833","0.02053"
"130.00000","-0.00006","-0.00830"
"130.10000","-0.00833","0.01326"
"130.20000","-0.01666","0.03745"
"130.30000","-0.02493","-0.00811"
"130.40000","-0.03326","0.06646"
"130.50000","-0.04171","0.00198"
"130.60000","-0.05009","0.01094"
"130.70000","-0.05842","0.02815"
"130.80000","-0.06658","0.00787"
"130.90000","-0.07497","0.03517"
"131.00000","-0.08324","0.02480"
"131.10000","-0.09174","0.03582"
"131.20000","-0.09996","0.00623"
"131.30000","-0.10835","-0.02300"
"131.40000","-0.11673","0.03836"
"131.50000","-0.12501","0.04193"
"131.60000","-0.13328","0.02452"
"131.65200","-0.13764","0.02718"