File: Tension/Orientation45_Specimen_RawData_1.csv
Time,Extension,Load,Tensile strain (Extension),Axial Video,Tensile stress,Transverse Video
(s),(mm),(N),(mm/mm),(mm/mm),(MPa),(mm/mm)
"0.00000","0.00000","0.03888","0.00000","-0.00001","0.00389","0.00005"
"0.70000","0.02049","63.76654","0.00020","0.00019","6.37665","-0.00009"
"1.40000","0.04382","135.61382","0.00044","0.00037","13.56138","-0.00024"
"2.10000","0.06729","206.20148","0.00067","0.00058","20.62015","-0.00034"
"2.80000","0.09056","274.62540","0.00091","0.00079","27.46254","-0.00060"
"3.50000","0.11388","341.82086","0.00114","0.00100","34.18209","-0.00067"
"4.20000","0.13715","407.51453","0.00137","0.00118","40.75145","-0.00087"
"4.90000","0.16047","472.14194","0.00160","0.00137","47.21420","-0.00101"
"5.60000","0.18384","535.82111","0.00184","0.00159","53.58211","-0.00117"
"6.30000","0.20708","597.59601","0.00207","0.00177","59.75960","-0.00134"
"7.00000","0.23044","658.79095","0.00230","0.00200","65.87910","-0.00137"
"7.70000","0.25385","718.44116","0.00254","0.00218","71.84412","-0.00151"
"8.40000","0.27713","776.34375","0.00277","0.00237","77.63438","-0.00169"
"9.10000","0.30056","832.99103","0.00301","0.00257","83.29910","-0.00175"
"9.80000","0.32384","888.09467","0.00324","0.00274","88.80946","-0.00185"
"10.50000","0.34722","941.73438","0.00347","0.00294","94.17344","-0.00208"
"11.20000","0.37064","994.42285","0.00371","0.00313","99.44228","-0.00219"
"11.90000","0.39399","1045.26147","0.00394","0.00331","104.52615","-0.00234"
"12.60000","0.41731","1094.98682","0.00417","0.00350","109.49868","-0.00249"
"13.30000","0.44061","1143.15649","0.00441","0.00370","114.31565","-0.00274"
"14.00000","0.46390","1190.55969","0.00464","0.00392","119.05597","-0.00286"
"14.70000","0.48725","1237.03198","0.00487","0.00414","123.70320","-0.00302"
"15.40000","0.51051","1281.96057","0.00511","0.00433","128.19606","-0.00317"
"16.10000","0.53389","1326.33704","0.00534","0.00453","132.63370","-0.00331"
"16.80000","0.55732","1369.78723","0.00557","0.00472","136.97873","-0.00340"
"17.50000","0.58059","1411.82227","0.00581","0.00490","141.18222","-0.00341"
"18.20000","0.60402","1453.14819","0.00604","0.00510","145.31482","-0.00366"
"18.90000","0.62725","1492.92896","0.00627","0.00527","149.29289","-0.00379"
"19.60000","0.65058","1531.94067","0.00651","0.00548","153.19406","-0.00390"
"20.30000","0.67387","1570.07849","0.00674","0.00568","157.00784","-0.00400"
"21.00000","0.69717","1606.97363","0.00697","0.00588","160.69736","-0.00420"
"21.70000","0.72047","1643.20691","0.00720","0.00609","164.32069","-0.00443"
"22.40000","0.74384","1678.54431","0.00744","0.00629","167.85443","-0.00459"
"23.10000","0.76715","1712.66199","0.00767","0.00648","171.26620","-0.00481"
"23.80000","0.79060","1745.97852","0.00791","0.00669","174.59785","-0.00507"
"24.50000","0.81389","1778.14062","0.00814","0.00689","177.81406","-0.00520"
"25.20000","0.83716","1809.19934","0.00837","0.00709","180.91994","-0.00555"
"25.90000","0.86049","1839.34009","0.00860","0.00728","183.93401","-0.00581"
"26.60000","0.88379","1868.38733","0.00884","0.00748","186.83873","-0.00590"
"27.30000","0.90716","1896.45435","0.00907","0.00765","189.64543","-0.00615"
"28.00000","0.93045","1923.24561","0.00930","0.00788","192.32455","-0.00641"
"28.70000","0.95379","1949.48035","0.00954","0.00811","194.94803","-0.00654"
"29.40000","0.97719","1974.87939","0.00977","0.00832","197.48795","-0.00673"
"30.10000","1.00048","1999.02429","0.01000","0.00854","199.90244","-0.00702"
"30.80000","1.02391","2022.57080","0.01024","0.00878","202.25708","-0.00715"
"31.50000","1.04718","2044.55457","0.01047","0.00902","204.45546","-0.00722"
"32.20000","1.07056","2066.11035","0.01071","0.00924","206.61104","-0.00743"
"32.90000","1.09395","2086.70361","0.01094","0.00946","208.67036","-0.00766"
"33.60000","1.11732","2106.47876","0.01117","0.00969","210.64787","-0.00785"
"34.30000","1.14066","2125.30811","0.01141","0.00994","212.53081","-0.00821"
"35.00000","1.16393","2142.93701","0.01164","0.01018","214.29370","-0.00848"
"35.70000","1.18723","2160.29492","0.01187","0.01043","216.02950","-0.00867"
"36.40000","1.21051","2176.80103","0.01211","0.01070","217.68010","-0.00907"
"37.10000","1.23380","2192.58716","0.01234","0.01095","219.25871","-0.00932"
"37.80000","1.25725","2208.41772","0.01257","0.01123","220.84177","-0.00950"
"38.50000","1.28066","2223.22729","0.01281","0.01148","222.32272","-0.00975"
"39.20000","1.30395","2237.51880","0.01304","0.01173","223.75188","-0.01007"
"39.90000","1.32733","2251.03491","0.01327","0.01202","225.10349","-0.01024"
"40.60000","1.35062","2264.22217","0.01351","0.01227","226.42221","-0.01047"
"41.30000","1.37389","2276.54565","0.01374","0.01255","227.65457","-0.01078"
"42.00000","1.39719","2288.76196","0.01397","0.01281","228.87619","-0.01107"
"42.70000","1.42047","2300.19409","0.01420","0.01307","230.01941","-0.01140"
"43.40000","1.44381","2311.63696","0.01444","0.01337","231.16370","-0.01160"
"44.10000","1.46715","2322.63647","0.01467","0.01364","232.26364","-0.01201"
"44.80000","1.49053","2333.45190","0.01491","0.01392","233.34518","-0.01238"
"45.50000","1.51393","2343.64771","0.01514","0.01422","234.36478","-0.01258"
"46.20000","1.53719","2353.31470","0.01537","0.01450","235.33147","-0.01299"
"46.90000","1.56049","2362.53027","0.01560","0.01480","236.25302","-0.01330"
"47.60000","1.58382","2371.23926","0.01584","0.01509","237.12393","-0.01356"
"48.30000","1.60712","2379.69092","0.01607","0.01538","237.96909","-0.01401"
"49.00000","1.63052","2387.90576","0.01631","0.01568","238.79057","-0.01443"
"49.70000","1.65377","2395.15527","0.01654","0.01600","239.51553","-0.01481"
"50.40000","1.67715","2402.31445","0.01677","0.01629","240.23145","-0.01518"
"51.10000","1.70053","2408.86646","0.01701","0.01660","240.88664","-0.01565"
"51.80000","1.72380","2414.09619","0.01724","0.01697","241.40962","-0.01600"
"52.50000","1.74722","2418.75317","0.01747","0.01736","241.87532","-0.01646"
"53.20000","1.77052","2422.12305","0.01771","0.01774","242.21231","-0.01693"
"53.90000","1.79393","2424.95581","0.01794","0.01814","242.49557","-0.01744"
"54.60000","1.81733","2426.94629","0.01817","0.01855","242.69463","-0.01803"
"55.30000","1.84066","2428.35400","0.01841","0.01899","242.83540","-0.01861"
"56.00000","1.86398","2429.17798","0.01864","0.01941","242.91780","-0.01917"
"56.70000","1.88725","2428.62402","0.01887","0.01992","242.86240","-0.01997"
"57.40000","1.91049","2426.51172","0.01910","0.02044","242.65117","-0.02093"
"58.10000","1.93387","2423.80786","0.01934","0.02100","242.38078","-0.02174"
"58.80000","1.95714","2419.31982","0.01957","0.02160","241.93198","-0.02266"
"59.50000","1.98059","2412.54004","0.01981","0.02219","241.25400","-0.02373"
"60.20000","2.00401","2404.76978","0.02004","0.02293","240.47697","-0.02494"
"60.90000","2.02732","2398.67578","0.02027","0.02358","239.86758","-0.02592"
"61.60000","2.05068","2393.74902","0.02051","0.02432","239.37491","-0.02711"
"62.30000","2.07394","2389.95654","0.02074","0.02502","238.99565","-0.02840"
"63.00000","2.09720","2386.77661","0.02097","0.02574","238.67766","-0.02947"
"63.70000","2.12052","2384.52417","0.02121","0.02645","238.45242","-0.03072"
"64.40000","2.14380","2383.05542","0.02144","0.02717","238.30554","-0.03197"
"65.10000","2.16713","2382.01172","0.02167","0.02783","238.20117","-0.03311"
"65.80000","2.19049","2381.17554","0.02190","0.02854","238.11755","-0.03442"
"66.50000","2.21385","2380.05762","0.02214","0.02922","238.00577","-0.03547"
"67.20000","2.23725","2378.74561","0.02237","0.02991","237.87456","-0.03663"
"67.90000","2.26055","2377.81006","0.02261","0.03060","237.78101","-0.03762"
"68.60000","2.28383","2377.01099","0.02284","0.03130","237.70110","-0.03847"
"69.30000","2.30712","2376.04858","0.02307","0.03203","237.60486","-0.03914"
"70.00000","2.33047","2376.01294","0.02330","0.03270","237.60129","-0.03990"
"70.70000","2.35383","2376.03345","0.02354","0.03342","237.60335","-0.04075"
"71.40000","2.37712","2376.51978","0.02377","0.03406","237.65198","-0.04149"
"72.10000","2.40048","2377.25879","0.02400","0.03476","237.72588","-0.04207"
"72.80000","2.42388","2378.40088","0.02424","0.03538","237.84009","-0.04276"
"73.50000","2.44713","2379.08594","0.02447","0.03599","237.90860","-0.04339"
"74.20000","2.47056","2380.69800","0.02471","0.03654","238.06979","-0.04393"
"74.90000","2.49385","2381.88721","0.02494","0.03713","238.18872","-0.04436"
"75.60000","2.51726","2383.13330","0.02517","0.03773","238.31332","-0.04494"
"76.30000","2.54064","2384.32202","0.02541","0.03831","238.43221","-0.04554"
"77.00000","2.56401","2385.80957","0.02564","0.03887","238.58096","-0.04618"
"77.70000","2.58732","2387.23096","0.02587","0.03941","238.72310","-0.04684"
"78.40000","2.61057","2388.00879","0.02611","0.03995","238.80087","-0.04729"
"79.10000","2.63381","2388.83252","0.02634","0.04042","238.88326","-0.04779"
"79.80000","2.65721","2390.31104","0.02657","0.04095","239.03110","-0.04822"
"80.50000","2.68046","2390.97632","0.02680","0.04141","239.09763","-0.04861"
"81.20000","2.70391","2392.06396","0.02704","0.04190","239.20639","-0.04895"
"81.90000","2.72735","2392.43335","0.02727","0.04235","239.24333","-0.04944"
"82.60000","2.75066","2392.48657","0.02751","0.04281","239.24866","-0.04974"
"83.30000","2.77401","2392.85767","0.02774","0.04326","239.28577","-0.04987"
"84.00000","2.79726","2393.11743","0.02797","0.04367","239.31174","-0.05031"
"84.70000","2.82054","2393.67993","0.02821","0.04408","239.36800","-0.05051"
"85.40000","2.84383","2394.04199","0.02844","0.04444","239.40421","-0.05066"
"86.10000","2.86712","2394.45605","0.02867","0.04483","239.44560","-0.05095"
"86.80000","2.89045","2394.51636","0.02890","0.04520","239.45163","-0.05133"
"87.50000","2.91385","2395.12085","0.02914","0.04555","239.51208","-0.05153"
"88.20000","2.93717","2395.74316","0.02937","0.04593","239.57431","-0.05180"
"88.90000","2.96059","2396.87793","0.02961","0.04623","239.68779","-0.05197"
"89.60000","2.98387","2397.70532","0.02984","0.04660","239.77054","-0.05197"
"90.30000","3.00715","2398.63672","0.03007","0.04691","239.86368","-0.05219"
"91.00000","3.03047","2399.71851","0.03030","0.04723","239.97185","-0.05236"
"91.70000","3.05381","2400.86914","0.03054","0.04751","240.08691","-0.05256"
"92.40000","3.07718","2402.10938","0.03077","0.04784","240.21094","-0.05285"
"93.10000","3.10050","2403.28296","0.03100","0.04813","240.32829","-0.05313"
"93.80000","3.12382","2404.26904","0.03124","0.04841","240.42691","-0.05330"
"94.50000","3.14718","2405.61060","0.03147","0.04869","240.56107","-0.05368"
"95.20000","3.17043","2406.43896","0.03170","0.04895","240.64389","-0.05393"
"95.90000","3.19390","2407.82129","0.03194","0.04924","240.78214","-0.05409"
"96.60000","3.21718","2408.81006","0.03217","0.04949","240.88101","-0.05430"
"97.30000","3.24061","2409.96484","0.03241","0.04974","240.99649","-0.05432"
"98.00000","3.26398","2411.09351","0.03264","0.04998","241.10934","-0.05449"
"98.70000","3.28733","2411.99023","0.03287","0.05019","241.19902","-0.05462"
"99.40000","3.31062","2412.93579","0.03311","0.05041","241.29358","-0.05480"
"100.10000","3.33390","2413.86060","0.03334","0.05063","241.38606","-0.05499"
"100.80000","3.35715","2414.92993","0.03357","0.05086","241.49300","-0.05514"
"101.50000","3.38053","2416.27100","0.03381","0.05106","241.62711","-0.05522"
"102.20000","3.40383","2417.34155","0.03404","0.05130","241.73416","-0.05543"
"102.90000","3.42729","2418.66602","0.03427","0.05151","241.86661","-0.05562"
"103.60000","3.45071","2419.76343","0.03451","0.05170","241.97635","-0.05573"
"104.30000","3.47398","2420.58032","0.03474","0.05193","242.05803","-0.05597"
"105.00000","3.49736","2421.59375","0.03497","0.05212","242.15938","-0.05603"
"105.70000","3.52057","2422.21899","0.03521","0.05234","242.22189","-0.05627"
"106.40000","3.54383","2423.17383","0.03544","0.05251","242.31738","-0.05631"
"107.10000","3.56714","2424.02319","0.03567","0.05270","242.40231","-0.05660"
"107.80000","3.59044","2425.36353","0.03590","0.05290","242.53635","-0.05676"
"108.50000","3.61379","2426.67310","0.03614","0.05307","242.66731","-0.05697"
"109.20000","3.63718","2428.29419","0.03637","0.05324","242.82942","-0.05725"
"109.90000","3.66051","2429.45020","0.03661","0.05338","242.94502","-0.05737"
"110.60000","3.68395","2431.25806","0.03684","0.05360","243.12581","-0.05753"
"111.30000","3.70719","2432.65234","0.03707","0.05377","243.26523","-0.05773"
"112.00000","3.73048","2434.19824","0.03730","0.05399","243.41983","-0.05780"
"112.70000","3.75377","2435.63916","0.03754","0.05420","243.56392","-0.05815"
"113.40000","3.77715","2437.27124","0.03777","0.05441","243.72713","-0.05836"
"114.10000","3.80051","2438.99365","0.03801","0.05462","243.89937","-0.05836"
"114.80000","3.82383","2440.63184","0.03824","0.05477","244.06319","-0.05865"
"115.50000","3.84717","2442.83423","0.03847","0.05494","244.28342","-0.05879"
"116.20000","3.87056","2444.90405","0.03871","0.05507","244.49040","-0.05894"
"116.90000","3.89379","2446.64209","0.03894","0.05525","244.66422","-0.05914"
"117.60000","3.91724","2449.12476","0.03917","0.05542","244.91248","-0.05927"
"118.30000","3.94053","2451.06006","0.03941","0.05557","245.10600","-0.05943"
"119.00000","3.96393","2453.59473","0.03964","0.05576","245.35947","-0.05967"
"119.70000","3.98733","2456.14966","0.03987","0.05591","245.61496","-0.05972"
"120.40000","4.01064","2458.26050","0.04011","0.05611","245.82605","-0.05992"
"121.10000","4.03394","2460.52563","0.04034","0.05630","246.05257","-0.06011"
"121.80000","4.05720","2462.43091","0.04057","0.05645","246.24309","-0.06018"
"122.50000","4.08049","2464.82520","0.04080","0.05662","246.48251","-0.06033"
"123.20000","4.10384","2467.24072","0.04104","0.05677","246.72408","-0.06045"
"123.90000","4.12722","2469.82007","0.04127","0.05690","246.98201","-0.06053"
"124.60000","4.15064","2472.53638","0.04151","0.05705","247.25363","-0.06062"
"125.30000","4.17405","2475.13696","0.04174","0.05718","247.51370","-0.06078"
"126.00000","4.19733","2477.40063","0.04197","0.05736","247.74007","-0.06089"
"126.70000","4.22067","2479.68262","0.04221","0.05753","247.96826","-0.06102"
"127.40000","4.24388","2482.11890","0.04244","0.05770","248.21188","-0.06118"
"128.10000","4.26716","2484.79492","0.04267","0.05787","248.47949","-0.06127"
"128.80000","4.29049","2487.53491","0.04290","0.05802","248.75349","-0.06137"
"129.50000","4.31378","2490.21362","0.04314","0.05822","249.02136","-0.06148"
"130.20000","4.33711","2492.89771","0.04337","0.05840","249.28976","-0.06162"
"130.90000","4.36054","2495.56104","0.04361","0.05858","249.55611","-0.06181"
"131.60000","4.38385","2497.77246","0.04384","0.05874","249.77725","-0.06188"
"132.30000","4.40726","2499.95410","0.04407","0.05890","249.99541","-0.06196"
"133.00000","4.43052","2501.83862","0.04431","0.05906","250.18387","-0.06221"
"133.70000","4.45378","2503.56494","0.04454","0.05925","250.35649","-0.06230"
"134.40000","4.47712","2506.07886","0.04477","0.05939","250.60788","-0.06240"
"135.10000","4.50047","2509.01074","0.04500","0.05956","250.90108","-0.06260"
"135.80000","4.52387","2511.96460","0.04524","0.05971","251.19646","-0.06274"
"136.50000","4.54715","2514.71777","0.04547","0.05987","251.47177","-0.06285"
"137.20000","4.57050","2517.85718","0.04571","0.06002","251.78572","-0.06302"
"137.90000","4.59389","2520.85376","0.04594","0.06018","252.08537","-0.06322"
"138.60000","4.61713","2524.01270","0.04617","0.06032","252.40128","-0.06332"
"139.30000","4.64058","2527.67700","0.04641","0.06051","252.76770","-0.06346"
"140.00000","4.66387","2530.97461","0.04664","0.06067","253.09746","-0.06362"
"140.70000","4.68729","2534.47437","0.04687","0.06085","253.44743","-0.06367"
"141.40000","4.71065","2537.75708","0.04711","0.06102","253.77571","-0.06374"
"142.10000","4.73395","2541.01465","0.04734","0.06117","254.10147","-0.06392"
"142.80000","4.75726","2544.46948","0.04757","0.06135","254.44695","-0.06406"
"143.50000","4.78053","2547.75537","0.04781","0.06156","254.77554","-0.06419"
"144.20000","4.80380","2551.22900","0.04804","0.06174","255.12289","-0.06435"
"144.90000","4.82719","2554.98755","0.04827","0.06191","255.49875","-0.06443"
"145.60000","4.85056","2558.43970","0.04851","0.06209","255.84396","-0.06469"
"146.30000","4.87400","2562.24243","0.04874","0.06226","256.22424","-0.06480"
"147.00000","4.89740","2565.91919","0.04897","0.06243","256.59192","-0.06494"
"147.70000","4.92068","2569.65308","0.04921","0.06259","256.96530","-0.06513"
"148.40000","4.94399","2572.98120","0.04944","0.06279","257.29813","-0.06518"
"149.10000","4.96721","2576.37427","0.04967","0.06297","257.63742","-0.06538"
"149.80000","4.99045","2579.56104","0.04990","0.06313","257.95612","-0.06557"
"150.50000","5.01381","2583.27734","0.05014","0.06332","258.32773","-0.06582"
"151.20000","5.03710","2586.62549","0.05037","0.06350","258.66254","-0.06605"
"151.90000","5.06045","2590.30396","0.05060","0.06367","259.03040","-0.06630"
"152.60000","5.08385","2593.85913","0.05084","0.06385","259.38593","-0.06650"
"153.30000","5.10716","2597.34839","0.05107","0.06401","259.73483","-0.06664"
"154.00000","5.13057","2601.02490","0.05131","0.06419","260.10248","-0.06684"
"154.70000","5.15382","2604.52148","0.05154","0.06439","260.45215","-0.06710"
"155.40000","5.17714","2607.79883","0.05177","0.06457","260.77988","-0.06728"
"156.10000","5.20048","2611.54175","0.05200","0.06471","261.15417","-0.06757"
"156.80000","5.22381","2615.14478","0.05224","0.06491","261.51447","-0.06770"
"157.50000","5.24722","2619.11182","0.05247","0.06510","261.91119","-0.06796"
"158.20000","5.27052","2622.66333","0.05271","0.06528","262.26633","-0.06812"
"158.90000","5.29385","2626.25732","0.05294","0.06548","262.62573","-0.06830"
"159.60000","5.31721","2630.27075","0.05317","0.06568","263.02707","-0.06859"
"160.30000","5.34047","2633.63379","0.05340","0.06588","263.36337","-0.06879"
"161.00000","5.36394","2637.59961","0.05364","0.06607","263.75995","-0.06899"
"161.70000","5.38724","2640.85986","0.05387","0.06626","264.08600","-0.06918"
"162.40000","5.41063","2644.55615","0.05411","0.06645","264.45563","-0.06937"
"163.10000","5.43398","2647.95996","0.05434","0.06665","264.79599","-0.06939"
"163.80000","5.45729","2651.56860","0.05457","0.06685","265.15686","-0.06957"
"164.50000","5.48059","2654.99707","0.05481","0.06705","265.49969","-0.06980"
"165.20000","5.50385","2658.45557","0.05504","0.06723","265.84555","-0.06991"
"165.90000","5.52711","2661.57642","0.05527","0.06741","266.15765","-0.07001"
"166.60000","5.55055","2665.63867","0.05551","0.06758","266.56387","-0.07029"
"167.30000","5.57392","2669.47144","0.05574","0.06778","266.94714","-0.07064"
"168.00000","5.59735","2674.14062","0.05597","0.06798","267.41406","-0.07082"
"168.70000","5.62072","2678.19800","0.05621","0.06814","267.81979","-0.07108"
"169.40000","5.64402","2682.34766","0.05644","0.06832","268.23477","-0.07127"
"170.10000","5.66728","2686.12573","0.05667","0.06848","268.61258","-0.07142"
"170.80000","5.69054","2689.94409","0.05691","0.06868","268.99442","-0.07164"
"171.50000","5.71379","2693.66553","0.05714","0.06885","269.36655","-0.07194"
"172.20000","5.73711","2697.65430","0.05737","0.06904","269.76544","-0.07212"
"172.90000","5.76046","2701.75220","0.05760","0.06925","270.17523","-0.07225"
"173.60000","5.78382","2706.01221","0.05784","0.06946","270.60123","-0.07244"
"174.30000","5.80717","2710.11035","0.05807","0.06964","271.01105","-0.07261"
"175.00000","5.83051","2714.18750","0.05831","0.06981","271.41876","-0.07272"
"175.70000","5.85389","2718.36914","0.05854","0.07003","271.83691","-0.07298"
"176.40000","5.87717","2722.26343","0.05877","0.07025","272.22635","-0.07318"
"177.10000","5.90047","2726.24146","0.05900","0.07043","272.62415","-0.07336"
"177.80000","5.92384","2730.48022","0.05924","0.07063","273.04803","-0.07357"
"178.50000","5.94717","2734.35938","0.05947","0.07083","273.43594","-0.07375"
"179.20000","5.97054","2738.31958","0.05971","0.07103","273.83197","-0.07396"
"179.90000","5.99386","2742.31372","0.05994","0.07120","274.23138","-0.07411"
"180.60000","6.01718","2745.94849","0.06017","0.07139","274.59485","-0.07439"
"181.30000","6.04055","2750.20825","0.06041","0.07160","275.02081","-0.07455"
"182.00000","6.06379","2753.89941","0.06064","0.07177","275.38995","-0.07482"
"182.70000","6.08728","2758.38330","0.06087","0.07197","275.83832","-0.07504"
"183.40000","6.11056","2762.00488","0.06111","0.07216","276.20050","-0.07537"
"184.10000","6.13396","2766.37695","0.06134","0.07237","276.63770","-0.07550"
"184.80000","6.15730","2770.15015","0.06157","0.07256","277.01501","-0.07571"
"185.50000","6.18061","2774.07983","0.06181","0.07276","277.40799","-0.07605"
"186.20000","6.20391","2777.88013","0.06204","0.07293","277.78802","-0.07610"
"186.90000","6.22718","2781.60693","0.06227","0.07308","278.16071","-0.07642"
"187.60000","6.25042","2785.48804","0.06250","0.07328","278.54880","-0.07679"
"188.30000","6.27387","2789.97046","0.06274","0.07346","278.99704","-0.07688"
"189.00000","6.29725","2794.40649","0.06297","0.07365","279.44064","-0.07703"
"189.70000","6.32074","2799.04688","0.06321","0.07384","279.90469","-0.07741"
"190.40000","6.34406","2803.14209","0.06344","0.07402","280.31421","-0.07752"
"191.10000","6.36734","2807.25806","0.06367","0.07421","280.72580","-0.07777"
"191.80000","6.39062","2811.35059","0.06391","0.07442","281.13507","-0.07795"
"192.50000","6.41386","2815.11768","0.06414","0.07462","281.51178","-0.07820"
"193.20000","6.43711","2819.07666","0.06437","0.07479","281.90765","-0.07837"
"193.90000","6.46048","2823.40649","0.06460","0.07499","282.34064","-0.07859"
"194.60000","6.48379","2827.61914","0.06484","0.07517","282.76190","-0.07878"
"195.30000","6.50715","2832.05005","0.06507","0.07536","283.20502","-0.07893"
"196.00000","6.53051","2836.19287","0.06531","0.07557","283.61929","-0.07913"
"196.70000","6.55381","2840.28809","0.06554","0.07574","284.02881","-0.07927"
"197.40000","6.57724","2844.48901","0.06577","0.07592","284.44891","-0.07946"
"198.10000","6.60047","2848.35815","0.06600","0.07611","284.83582","-0.07961"
"198.80000","6.62380","2852.61670","0.06624","0.07629","285.26166","-0.07981"
"199.50000","6.64718","2856.80396","0.06647","0.07647","285.68039","-0.08000"
"200.20000","6.67049","2861.01636","0.06670","0.07667","286.10162","-0.08020"
"200.90000","6.69390","2865.37866","0.06694","0.07687","286.53787","-0.08039"
"201.60000","6.71718","2869.34497","0.06717","0.07707","286.93451","-0.08063"
"202.30000","6.74050","2873.48755","0.06741","0.07727","287.34875","-0.08089"
"203.00000","6.76389","2877.84326","0.06764","0.07745","287.78433","-0.08109"
"203.70000","6.78711","2881.73364","0.06787","0.07767","288.17337","-0.08122"
"204.40000","6.81061","2886.28467","0.06811","0.07786","288.62848","-0.08155"
"205.10000","6.83390","2890.61938","0.06834","0.07806","289.06195","-0.08180"
"205.80000","6.85732","2894.95312","0.06857","0.07824","289.49530","-0.08196"
"206.50000","6.88061","2898.87231","0.06881","0.07845","289.88724","-0.08223"
"207.20000","6.90393","2902.89087","0.06904","0.07863","290.28909","-0.08258"
"207.90000","6.92722","2907.02515","0.06927","0.07883","290.70251","-0.08283"
"208.60000","6.95049","2910.66260","0.06950","0.07900","291.06625","-0.08302"
"209.30000","6.97378","2914.92969","0.06974","0.07921","291.49298","-0.08336"
"210.00000","6.99722","2919.51611","0.06997","0.07940","291.95160","-0.08356"
"210.70000","7.02063","2923.86670","0.07021","0.07959","292.38666","-0.08381"
"211.40000","7.04403","2928.28101","0.07044","0.07979","292.82809","-0.08405"
"212.10000","7.06738","2932.50635","0.07067","0.08000","293.25064","-0.08428"
"212.80000","7.09068","2936.61353","0.07091","0.08021","293.66135","-0.08441"
"213.50000","7.11394","2940.53931","0.07114","0.08040","294.05392","-0.08464"
"214.20000","7.13717","2944.25659","0.07137","0.08058","294.42566","-0.08478"
"214.90000","7.16044","2948.26880","0.07160","0.08077","294.82687","-0.08502"
"215.60000","7.18379","2952.54346","0.07184","0.08099","295.25433","-0.08521"
"216.30000","7.20711","2956.56396","0.07207","0.08115","295.65640","-0.08543"
"217.00000","7.23048","2960.77148","0.07230","0.08135","296.07715","-0.08561"
"217.70000","7.25385","2965.00464","0.07254","0.08155","296.50046","-0.08580"
"218.40000","7.27715","2969.01587","0.07277","0.08169","296.90158","-0.08605"
"219.10000","7.30054","2973.20166","0.07301","0.08190","297.32016","-0.08634"
"219.80000","7.32381","2977.07324","0.07324","0.08208","297.70734","-0.08653"
"220.50000","7.34716","2981.02612","0.07347","0.08226","298.10260","-0.08673"
"221.20000","7.37047","2985.10132","0.07370","0.08246","298.51013","-0.08702"
"221.90000","7.39384","2989.01465","0.07394","0.08264","298.90146","-0.08732"
"222.60000","7.41721","2993.16138","0.07417","0.08278","299.31613","-0.08736"
"223.30000","7.44051","2996.84692","0.07441","0.08300","299.68469","-0.08760"
"224.00000","7.46385","3000.85303","0.07464","0.08318","300.08530","-0.08774"
"224.70000","7.48727","3005.00537","0.07487","0.08334","300.50055","-0.08800"
"225.40000","7.51046","3008.64478","0.07510","0.08352","300.86447","-0.08817"
"226.10000","7.53397","3013.23096","0.07534","0.08369","301.32309","-0.08843"
"226.80000","7.55726","3017.11621","0.07557","0.08387","301.71161","-0.08853"
"227.50000","7.58061","3021.06982","0.07581","0.08405","302.10699","-0.08873"
"228.20000","7.60394","3025.09692","0.07604","0.08424","302.50970","-0.08887"
"228.90000","7.62724","3028.73633","0.07627","0.08443","302.87363","-0.08908"
"229.60000","7.65057","3032.57349","0.07651","0.08461","303.25735","-0.08922"
"230.30000","7.67384","3036.09790","0.07674","0.08479","303.60980","-0.08937"
"231.00000","7.69710","3040.08765","0.07697","0.08498","304.00876","-0.08971"
"231.70000","7.72058","3044.23853","0.07721","0.08513","304.42386","-0.08990"
"232.40000","7.74398","3048.33398","0.07744","0.08533","304.83340","-0.09004"
"233.10000","7.76737","3052.36865","0.07767","0.08552","305.23688","-0.09024"
"233.80000","7.79071","3056.15967","0.07791","0.08566","305.61597","-0.09058"
"234.50000","7.81398","3059.84595","0.07814","0.08584","305.98459","-0.09064"
"235.20000","7.83724","3063.42578","0.07837","0.08603","306.34259","-0.09081"
"235.90000","7.86049","3066.89087","0.07860","0.08619","306.68909","-0.09102"
"236.60000","7.88379","3070.43604","0.07884","0.08638","307.04361","-0.09123"
"237.30000","7.90713","3074.17700","0.07907","0.08656","307.41769","-0.09129"
"238.00000","7.93046","3077.87500","0.07930","0.08672","307.78751","-0.09146"
"238.70000","7.95382","3081.99609","0.07954","0.08688","308.19962","-0.09165"
"239.40000","7.97716","3085.72437","0.07977","0.08708","308.57245","-0.09180"
"240.10000","8.00048","3089.47656","0.08000","0.08725","308.94766","-0.09191"
"240.80000","8.02386","3093.14941","0.08024","0.08740","309.31494","-0.09209"
"241.50000","8.04715","3096.91431","0.08047","0.08759","309.69144","-0.09229"
"242.20000","8.07046","3100.58716","0.08070","0.08781","310.05872","-0.09253"
"242.90000","8.09384","3104.75073","0.08094","0.08793","310.47507","-0.09268"
"243.60000","8.11717","3108.44824","0.08117","0.08814","310.84482","-0.09287"
"244.30000","8.14054","3112.35327","0.08141","0.08834","311.23532","-0.09316"
"245.00000","8.16387","3115.93311","0.08164","0.08849","311.59332","-0.09336"
"245.70000","8.18719","3119.48804","0.08187","0.08866","311.94879","-0.09356"
"246.40000","8.21061","3123.28296","0.08211","0.08885","312.32831","-0.09367"
"247.10000","8.23380","3126.61182","0.08234","0.08900","312.66119","-0.09393"
"247.80000","8.25733","3131.11328","0.08257","0.08913","313.11133","-0.09419"
"248.50000","8.28060","3134.43994","0.08281","0.08932","313.44400","-0.09434"
"249.20000","8.30392","3138.07422","0.08304","0.08950","313.80743","-0.09450"
"249.90000","8.32728","3141.22363","0.08327","0.08963","314.12238","-0.09478"
"250.60000","8.35055","3144.83154","0.08351","0.08978","314.48315","-0.09498"
"251.30000","8.37389","3148.32544","0.08374","0.08995","314.83255","-0.09507"
"252.00000","8.39716","3151.81982","0.08397","0.09012","315.18198","-0.09526"
"252.70000","8.42048","3155.34839","0.08420","0.09027","315.53485","-0.09554"
"253.40000","8.44395","3159.42993","0.08444","0.09043","315.94299","-0.09570"
"254.10000","8.46735","3163.26196","0.08467","0.09059","316.32620","-0.09578"
"254.80000","8.49071","3167.25073","0.08491","0.09074","316.72507","-0.09599"
"255.50000","8.51402","3170.84424","0.08514","0.09091","317.08441","-0.09624"
"256.20000","8.53727","3174.53589","0.08537","0.09106","317.45358","-0.09648"
"256.90000","8.56056","3178.08008","0.08561","0.09124","317.80801","-0.09653"
"257.60000","8.58381","3181.83984","0.08584","0.09139","318.18399","-0.09673"
"258.30000","8.60709","3185.25684","0.08607","0.09157","318.52570","-0.09697"
"259.00000","8.63047","3189.27026","0.08630","0.09174","318.92703","-0.09720"
"259.70000","8.65379","3193.07812","0.08654","0.09190","319.30780","-0.09728"
"260.40000","8.67718","3197.23438","0.08677","0.09206","319.72345","-0.09744"
"261.10000","8.70049","3200.88306","0.08700","0.09223","320.08832","-0.09755"
"261.80000","8.72381","3204.56055","0.08724","0.09240","320.45605","-0.09786"
"262.50000","8.74719","3208.30640","0.08747","0.09256","320.83063","-0.09808"
"263.20000","8.77050","3211.74438","0.08770","0.09270","321.17444","-0.09819"
"263.90000","8.79382","3215.18823","0.08794","0.09288","321.51883","-0.09828"
"264.60000","8.81718","3218.60059","0.08817","0.09303","321.86005","-0.09864"
"265.30000","8.84052","3222.04858","0.08841","0.09320","322.20486","-0.09881"
"266.00000","8.86390","3225.32056","0.08864","0.09333","322.53204","-0.09897"
"266.70000","8.88719","3228.62964","0.08887","0.09346","322.86298","-0.09921"
"267.40000","8.91055","3232.06519","0.08911","0.09363","323.20651","-0.09931"
"268.10000","8.93391","3235.75073","0.08934","0.09377","323.57507","-0.09948"
"268.80000","8.95719","3238.97412","0.08957","0.09394","323.89740","-0.09965"
"269.50000","8.98065","3242.62598","0.08981","0.09412","324.26260","-0.09976"
"270.20000","9.00393","3245.86328","0.09004","0.09427","324.58633","-0.09998"
"270.90000","9.02726","3249.76587","0.09027","0.09443","324.97659","-0.10019"
"271.60000","9.05058","3253.52539","0.09051","0.09459","325.35254","-0.10031"
"272.30000","9.07384","3257.36304","0.09074","0.09476","325.73630","-0.10048"
"273.00000","9.09720","3261.37256","0.09097","0.09490","326.13727","-0.10062"
"273.70000","9.12052","3265.57056","0.09121","0.09507","326.55707","-0.10092"
"274.40000","9.14381","3269.53613","0.09144","0.09521","326.95361","-0.10101"
"275.10000","9.16731","3273.99683","0.09167","0.09538","327.39969","-0.10116"
"275.80000","9.19068","3278.16821","0.09191","0.09554","327.81683","-0.10136"
"276.50000","9.21406","3282.42822","0.09214","0.09569","328.24283","-0.10160"
"277.20000","9.23734","3286.04248","0.09237","0.09589","328.60425","-0.10179"
"277.90000","9.26064","3290.07251","0.09261","0.09605","329.00726","-0.10190"
"278.60000","9.28386","3293.80444","0.09284","0.09620","329.38043","-0.10217"
"279.30000","9.30714","3297.85303","0.09307","0.09635","329.78531","-0.10243"
"280.00000","9.33044","3301.88428","0.09330","0.09649","330.18842","-0.10248"
"280.70000","9.35383","3306.04688","0.09354","0.09668","330.60468","-0.10262"
"281.40000","9.37711","3310.16846","0.09377","0.09681","331.01685","-0.10287"
"282.10000","9.40051","3314.48462","0.09401","0.09698","331.44846","-0.10310"
"282.80000","9.42381","3318.66187","0.09424","0.09716","331.86618","-0.10333"
"283.50000","9.44715","3322.79248","0.09447","0.09729","332.27924","-0.10346"
"284.20000","9.47052","3327.01685","0.09471","0.09747","332.70169","-0.10373"
"284.90000","9.49382","3331.13403","0.09494","0.09764","333.11340","-0.10389"
"285.60000","9.51717","3335.47998","0.09517","0.09781","333.54800","-0.10414"
"286.30000","9.54051","3339.30957","0.09541","0.09799","333.93097","-0.10430"
"287.00000","9.56384","3343.62695","0.09564","0.09816","334.36270","-0.10452"
"287.70000","9.58720","3347.89502","0.09587","0.09834","334.78949","-0.10482"
"288.40000","9.61055","3352.00269","0.09611","0.09851","335.20026","-0.10492"
"289.10000","9.63389","3356.11060","0.09634","0.09868","335.61105","-0.10511"
"289.80000","9.65731","3360.63208","0.09657","0.09885","336.06320","-0.10535"
"290.50000","9.68053","3364.17676","0.09681","0.09897","336.41766","-0.10552"
"291.20000","9.70402","3368.86206","0.09704","0.09915","336.88620","-0.10569"
"291.90000","9.72728","3372.67554","0.09727","0.09931","337.26755","-0.10579"
"292.60000","9.75057","3376.65674","0.09751","0.09947","337.66568","-0.10601"
"293.30000","9.77389","3380.47192","0.09774","0.09963","338.04718","-0.10623"
"294.00000","9.79718","3384.26782","0.09797","0.09979","338.42679","-0.10635"
"294.70000","9.82053","3388.31665","0.09821","0.09997","338.83167","-0.10652"
"295.40000","9.84385","3392.35400","0.09844","0.10016","339.23541","-0.10677"
"296.10000","9.86715","3396.26514","0.09867","0.10030","339.62653","-0.10695"
"296.80000","9.89070","3400.91504","0.09891","0.10047","340.09149","-0.10721"
"297.50000","9.91403","3405.22681","0.09914","0.10062","340.52267","-0.10730"
"298.20000","9.93737","3409.03442","0.09937","0.10079","340.90344","-0.10760"
"298.90000","9.96067","3413.19995","0.09961","0.10097","341.32001","-0.10779"
"299.60000","9.98393","3416.86377","0.09984","0.10112","341.68637","-0.10796"
"300.30000","10.00719","3420.76245","0.10007","0.10126","342.07623","-0.10818"
"301.00000","10.03049","3424.59521","0.10030","0.10142","342.45953","-0.10842"
"301.70000","10.05378","3428.58325","0.10054","0.10156","342.85834","-0.10857"
"302.40000","10.07715","3432.67725","0.10077","0.10174","343.26773","-0.10865"
"303.10000","10.10046","3436.94604","0.10100","0.10190","343.69461","-0.10896"
"303.80000","10.12380","3441.19360","0.10124","0.10206","344.11935","-0.10915"
"304.50000","10.14714","3445.30566","0.10147","0.10223","344.53058","-0.10935"
"305.20000","10.17043","3449.48730","0.10170","0.10242","344.94873","-0.10948"
"305.90000","10.19384","3453.85791","0.10194","0.10259","345.38580","-0.10971"
"306.60000","10.21718","3457.96973","0.10217","0.10275","345.79697","-0.10994"
"307.30000","10.24052","3462.14185","0.10241","0.10292","346.21417","-0.11016"
"308.00000","10.26387","3466.26147","0.10264","0.10310","346.62616","-0.11033"
"308.70000","10.28720","3470.53589","0.10287","0.10324","347.05359","-0.11062"
"309.40000","10.31054","3474.56738","0.10311","0.10341","347.45673","-0.11086"
"310.10000","10.33388","3478.85352","0.10334","0.10359","347.88535","-0.11100"
"310.80000","10.35723","3483.09863","0.10357","0.10373","348.30988","-0.11115"
"311.50000","10.38062","3487.44312","0.10381","0.10392","348.74432","-0.11140"
"312.20000","10.40387","3491.58789","0.10404","0.10410","349.15878","-0.11169"
"312.90000","10.42736","3496.17676","0.10427","0.10428","349.61768","-0.11182"
"313.60000","10.45058","3500.04663","0.10451","0.10448","350.00467","-0.11203"
"314.30000","10.47393","3504.23486","0.10474","0.10466","350.42349","-0.11235"
"315.00000","10.49720","3508.13037","0.10497","0.10482","350.81305","-0.11236"
"315.70000","10.52051","3512.31982","0.10521","0.10497","351.23199","-0.11257"
"316.40000","10.54387","3516.58130","0.10544","0.10515","351.65814","-0.11284"
"317.10000","10.56717","3520.48169","0.10567","0.10531","352.04816","-0.11310"
"317.80000","10.59052","3524.87231","0.10591","0.10548","352.48724","-0.11325"
"318.50000","10.61401","3529.45435","0.10614","0.10563","352.94543","-0.11349"
"319.20000","10.63740","3533.84497","0.10637","0.10585","353.38449","-0.11376"
"319.90000","10.66069","3537.93433","0.10661","0.10603","353.79343","-0.11406"
"320.60000","10.68400","3542.19482","0.10684","0.10620","354.21948","-0.11422"
"321.30000","10.70723","3546.04639","0.10707","0.10638","354.60464","-0.11438"
"322.00000","10.73051","3549.82495","0.10731","0.10658","354.98248","-0.11471"
"322.70000","10.75382","3553.90088","0.10754","0.10676","355.39008","-0.11486"
"323.40000","10.77710","3557.81250","0.10777","0.10696","355.78125","-0.11506"
"324.10000","10.80048","3561.97510","0.10800","0.10715","356.19751","-0.11532"
"324.80000","10.82378","3565.81519","0.10824","0.10732","356.58151","-0.11549"
"325.50000","10.84715","3570.17041","0.10847","0.10752","357.01703","-0.11569"
"326.20000","10.87047","3574.10620","0.10870","0.10770","357.41061","-0.11589"
"326.90000","10.89377","3578.30713","0.10894","0.10785","357.83072","-0.11603"
"327.60000","10.91717","3582.54053","0.10917","0.10803","358.25406","-0.11625"
"328.30000","10.94049","3586.92847","0.10940","0.10823","358.69284","-0.11647"
"329.00000","10.96387","3591.01099","0.10964","0.10839","359.10110","-0.11665"
"329.70000","10.98718","3595.08765","0.10987","0.10855","359.50876","-0.11691"
"330.40000","11.01053","3599.29272","0.11011","0.10871","359.92926","-0.11715"
"331.10000","11.03389","3603.42798","0.11034","0.10887","360.34280","-0.11730"
"331.80000","11.05719","3607.44141","0.11057","0.10904","360.74414","-0.11754"
"332.50000","11.08061","3611.85254","0.11081","0.10922","361.18524","-0.11784"
"333.20000","11.10394","3615.95679","0.11104","0.10939","361.59567","-0.11803"
"333.90000","11.12720","3619.77417","0.11127","0.10960","361.97742","-0.11822"
"334.60000","11.15067","3624.14990","0.11151","0.10978","362.41498","-0.11847"
"335.30000","11.17392","3627.86646","0.11174","0.11001","362.78665","-0.11871"
"336.00000","11.19722","3631.80933","0.11197","0.11017","363.18094","-0.11891"
"336.70000","11.22055","3635.74316","0.11221","0.11034","363.57431","-0.11906"
"337.40000","11.24382","3639.40063","0.11244","0.11056","363.94006","-0.11940"
"338.10000","11.26719","3643.60034","0.11267","0.11074","364.36005","-0.11954"
"338.80000","11.29055","3647.51660","0.11291","0.11091","364.75165","-0.11964"
"339.50000","11.31387","3651.58740","0.11314","0.11110","365.15875","-0.11996"
"340.20000","11.33736","3655.96118","0.11337","0.11128","365.59613","-0.12017"
"340.90000","11.36075","3660.21143","0.11361","0.11149","366.02115","-0.12028"
"341.60000","11.38399","3663.66797","0.11384","0.11167","366.36679","-0.12052"
"342.30000","11.40729","3667.70337","0.11407","0.11186","366.77032","-0.12080"
"343.00000","11.43054","3671.24756","0.11431","0.11205","367.12476","-0.12103"
"343.70000","11.45385","3675.08789","0.11454","0.11225","367.50879","-0.12120"
"344.40000","11.47717","3679.00244","0.11477","0.11241","367.90024","-0.12155"
"345.10000","11.50042","3682.66406","0.11500","0.11259","368.26642","-0.12182"
"345.80000","11.52385","3686.71118","0.11524","0.11276","368.67111","-0.12181"
"346.50000","11.54710","3690.36792","0.11547","0.11290","369.03680","-0.12212"
"347.20000","11.57049","3694.50562","0.11570","0.11311","369.45056","-0.12250"
"347.90000","11.59379","3698.07251","0.11594","0.11333","369.80725","-0.12268"
"348.60000","11.61710","3702.02734","0.11617","0.11354","370.20273","-0.12285"
"349.30000","11.64050","3705.71606","0.11641","0.11373","370.57159","-0.12314"
"350.00000","11.66383","3709.40259","0.11664","0.11397","370.94025","-0.12344"
"350.70000","11.68720","3713.26465","0.11687","0.11417","371.32648","-0.12359"
"351.40000","11.71054","3716.98242","0.11711","0.11438","371.69824","-0.12379"
"352.10000","11.73384","3720.43701","0.11734","0.11459","372.04370","-0.12412"
"352.80000","11.75722","3724.39185","0.11757","0.11478","372.43918","-0.12417"
"353.50000","11.78055","3727.97388","0.11781","0.11501","372.79739","-0.12445"
"354.20000","11.80394","3731.72461","0.11804","0.11522","373.17245","-0.12480"
"354.90000","11.82733","3735.17041","0.11827","0.11542","373.51703","-0.12497"
"355.60000","11.85059","3738.76733","0.11851","0.11562","373.87674","-0.12515"
"356.30000","11.87401","3742.20947","0.11874","0.11585","374.22095","-0.12549"
"357.00000","11.89725","3744.85303","0.11897","0.11606","374.48529","-0.12573"
"357.70000","11.92053","3747.71240","0.11921","0.11630","374.77124","-0.12593"
"358.40000","11.94385","3749.97070","0.11944","0.11653","374.99707","-0.12612"
"359.10000","11.96715","3752.18774","0.11967","0.11676","375.21878","-0.12638"
"359.80000","11.99055","3754.64258","0.11991","0.11702","375.46426","-0.12651"
"360.50000","12.01390","3756.89014","0.12014","0.11725","375.68903","-0.12666"
"361.20000","12.03726","3759.22852","0.12037","0.11751","375.92285","-0.12693"
"361.90000","12.06071","3762.02197","0.12061","0.11777","376.20221","-0.12716"
"362.60000","12.08405","3764.55518","0.12084","0.11805","376.45551","-0.12734"
"363.30000","12.10733","3767.27588","0.12107","0.11830","376.72760","-0.12758"
"364.00000","12.13056","3770.03589","0.12131","0.11859","377.00360","-0.12797"
"364.70000","12.15387","3773.30151","0.12154","0.11886","377.33014","-0.12807"
"365.40000","12.17717","3776.53955","0.12177","0.11910","377.65396","-0.12832"
"366.10000","12.20047","3779.87500","0.12200","0.11937","377.98749","-0.12866"
"366.80000","12.22379","3783.24512","0.12224","0.11961","378.32452","-0.12886"
"367.50000","12.24719","3786.69385","0.12247","0.11988","378.66937","-0.12908"
"368.20000","12.27042","3789.50391","0.12270","0.12012","378.95038","-0.12934"
"368.90000","12.29382","3792.87378","0.12294","0.12038","379.28738","-0.12968"
"369.60000","12.31713","3795.49072","0.12317","0.12063","379.54907","-0.12988"
"370.30000","12.34041","3797.87158","0.12340","0.12091","379.78717","-0.13012"
"371.00000","12.36382","3800.12354","0.12364","0.12118","380.01236","-0.13047"
"371.70000","12.38718","3802.09058","0.12387","0.12145","380.20905","-0.13070"
"372.40000","12.41053","3803.72656","0.12411","0.12171","380.37265","-0.13094"
"373.10000","12.43388","3805.45190","0.12434","0.12203","380.54520","-0.13131"
"373.80000","12.45718","3807.30396","0.12457","0.12234","380.73041","-0.13151"
"374.50000","12.48056","3809.59473","0.12481","0.12264","380.95947","-0.13173"
"375.20000","12.50389","3811.91479","0.12504","0.12295","381.19147","-0.13204"
"375.90000","12.52732","3814.46655","0.12527","0.12323","381.44666","-0.13231"
"376.60000","12.55067","3816.21899","0.12551","0.12357","381.62189","-0.13253"
"377.30000","12.57393","3817.59521","0.12574","0.12388","381.75952","-0.13282"
"378.00000","12.59735","3820.08740","0.12597","0.12420","382.00873","-0.13307"
"378.70000","12.62056","3822.10840","0.12621","0.12453","382.21085","-0.13339"
"379.40000","12.64388","3824.49927","0.12644","0.12482","382.44992","-0.13355"
"380.10000","12.66719","3826.33594","0.12667","0.12511","382.63361","-0.13384"
"380.80000","12.69048","3828.61060","0.12690","0.12542","382.86105","-0.13417"
"381.50000","12.71391","3830.86938","0.12714","0.12570","383.08694","-0.13439"
"382.20000","12.73725","3832.94482","0.12737","0.12599","383.29449","-0.13459"
"382.90000","12.76058","3834.63306","0.12761","0.12629","383.46332","-0.13478"
"383.60000","12.78408","3836.81470","0.12784","0.12660","383.68146","-0.13504"
"384.30000","12.80739","3838.54614","0.12807","0.12690","383.85461","-0.13524"
"385.00000","12.83063","3840.63867","0.12831","0.12724","384.06387","-0.13553"
"385.70000","12.85388","3842.60718","0.12854","0.12756","384.26071","-0.13583"
"386.40000","12.87719","3845.52808","0.12877","0.12787","384.55280","-0.13607"
"387.10000","12.90050","3848.14844","0.12901","0.12817","384.81485","-0.13641"
"387.80000","12.92383","3850.96753","0.12924","0.12845","385.09674","-0.13670"
"388.50000","12.94711","3853.26074","0.12947","0.12878","385.32608","-0.13700"
"389.20000","12.97051","3855.52124","0.12971","0.12907","385.55212","-0.13733"
"389.90000","12.99374","3857.42627","0.12994","0.12938","385.74261","-0.13756"
"390.60000","13.01715","3859.59229","0.13017","0.12969","385.95923","-0.13788"
"391.30000","13.04044","3861.16431","0.13040","0.13005","386.11642","-0.13815"
"392.00000","13.06376","3862.50610","0.13064","0.13038","386.25061","-0.13848"
"392.70000","13.08718","3864.10767","0.13087","0.13071","386.41077","-0.13883"
"393.40000","13.11054","3865.57959","0.13111","0.13103","386.55795","-0.13922"
"394.10000","13.13387","3867.02417","0.13134","0.13139","386.70242","-0.13962"
"394.80000","13.15723","3868.50757","0.13157","0.13170","386.85077","-0.14001"
"395.50000","13.18052","3869.45874","0.13181","0.13208","386.94586","-0.14045"
"396.20000","13.20389","3870.97754","0.13204","0.13242","387.09775","-0.14093"
"396.90000","13.22722","3872.48779","0.13227","0.13277","387.24878","-0.14125"
"397.60000","13.25065","3874.33813","0.13251","0.13312","387.43381","-0.14163"
"398.30000","13.27400","3875.50781","0.13274","0.13348","387.55078","-0.14198"
"399.00000","13.29726","3876.16895","0.13297","0.13387","387.61688","-0.14240"
"399.70000","13.32068","3877.20752","0.13321","0.13422","387.72076","-0.14289"
"400.40000","13.34391","3876.80542","0.13344","0.13457","387.68054","-0.14343"
"401.10000","13.36717","3874.10400","0.13367","0.13496","387.41040","-0.14392"
"401.80000","13.39047","3871.34253","0.13390","0.13531","387.13425","-0.14444"
"402.50000","13.41383","3868.89771","0.13414","0.13574","386.88977","-0.14476"
"403.20000","13.43723","3866.48022","0.13437","0.13617","386.64801","-0.14509"
"403.90000","13.46060","3862.51538","0.13461","0.13655","386.25153","-0.14548"
"404.60000","13.48395","3854.39771","0.13484","0.13695","385.43976","-0.14583"
"405.30000","13.50742","3845.27661","0.13507","0.13733","384.52765","-0.14651"
"406.00000","13.53070","3832.64990","0.13531","0.13773","383.26498","-0.14702"
"406.70000","13.55396","3812.75903","0.13554","0.13814","381.27591","-0.14741"
"407.40000","13.57719","3765.80420","0.13577","0.13888","376.58041","-0.14767"
"407.87000","13.59291","3208.54883","0.13593","0.13985","320.85489","-0.14743"
"407.88200","13.59338","2132.22607","0.13593","0.13985","213.22261","-0.14743"