File: Tension/Orientation0_Specimen_RawData_1.csv
Time,Extension,Load,Tensile strain (Extension),Axial Video,Tensile stress,Transverse Video
(s),(mm),(N),(mm/mm),(mm/mm),(MPa),(mm/mm)
"0.00000","1.99875","0.38798","0.00000","-0.00003","0.03880","-0.00004"
"0.20000","2.00205","48.63231","0.00003","-0.00003","4.86323","-0.00002"
"0.40000","2.00990","163.18230","0.00011","0.00001","16.31823","0.00000"
"0.60000","2.01673","254.65605","0.00018","0.00003","25.46560","0.00000"
"0.80000","2.02327","337.29855","0.00025","0.00006","33.72985","0.00000"
"1.00000","2.02989","418.10693","0.00031","0.00009","41.81069","-0.00004"
"1.20000","2.03673","500.94226","0.00038","0.00011","50.09423","-0.00004"
"1.40000","2.04325","576.93109","0.00045","0.00009","57.69311","-0.00004"
"1.60000","2.04993","653.88831","0.00051","0.00013","65.38883","-0.00013"
"1.80000","2.05666","729.65448","0.00058","0.00015","72.96545","-0.00016"
"2.00000","2.06341","803.17993","0.00065","0.00018","80.31799","-0.00021"
"2.20000","2.07001","872.86292","0.00071","0.00019","87.28629","-0.00017"
"2.40000","2.07659","939.81995","0.00078","0.00020","93.98199","-0.00025"
"2.60000","2.08333","1006.94525","0.00085","0.00023","100.69453","-0.00034"
"2.80000","2.08985","1068.41626","0.00091","0.00027","106.84163","-0.00036"
"3.00000","2.09671","1132.08716","0.00098","0.00031","113.20872","-0.00038"
"3.20000","2.10333","1190.76392","0.00105","0.00033","119.07639","-0.00036"
"3.40000","2.10997","1246.77795","0.00111","0.00035","124.67780","-0.00029"
"3.60000","2.11682","1304.41113","0.00118","0.00037","130.44112","-0.00025"
"3.80000","2.12327","1353.52734","0.00125","0.00037","135.35274","-0.00025"
"4.00000","2.12994","1403.64929","0.00131","0.00038","140.36493","-0.00017"
"4.20000","2.13655","1451.40015","0.00138","0.00039","145.14001","-0.00009"
"4.40000","2.14345","1499.86865","0.00145","0.00037","149.98686","-0.00013"
"4.60000","2.14993","1542.51770","0.00151","0.00038","154.25177","-0.00017"
"4.80000","2.15659","1584.67236","0.00158","0.00040","158.46724","-0.00018"
"5.00000","2.16338","1628.20654","0.00165","0.00044","162.82065","-0.00017"
"5.20000","2.16991","1665.98914","0.00171","0.00046","166.59891","-0.00025"
"5.40000","2.17678","1706.90173","0.00178","0.00047","170.69017","-0.00030"
"5.60000","2.18330","1741.37927","0.00185","0.00051","174.13792","-0.00031"
"5.80000","2.18999","1776.53357","0.00191","0.00053","177.65335","-0.00038"
"6.00000","2.19667","1811.47620","0.00198","0.00055","181.14761","-0.00042"
"6.20000","2.20328","1843.66736","0.00205","0.00054","184.36673","-0.00042"
"6.40000","2.20992","1875.28455","0.00211","0.00056","187.52846","-0.00046"
"6.60000","2.21659","1906.06421","0.00218","0.00055","190.60641","-0.00051"
"6.80000","2.22344","1938.06238","0.00225","0.00054","193.80624","-0.00051"
"7.00000","2.22998","1964.68005","0.00231","0.00057","196.46800","-0.00046"
"7.20000","2.23660","1990.82349","0.00238","0.00058","199.08235","-0.00049"
"7.40000","2.24343","2019.22522","0.00245","0.00059","201.92252","-0.00047"
"7.60000","2.24993","2042.11865","0.00251","0.00061","204.21187","-0.00046"
"7.80000","2.25663","2066.92041","0.00258","0.00065","206.69205","-0.00038"
"8.00000","2.26332","2090.74707","0.00265","0.00066","209.07471","-0.00039"
"8.20000","2.27000","2112.85547","0.00271","0.00068","211.28555","-0.00034"
"8.40000","2.27675","2135.69482","0.00278","0.00069","213.56949","-0.00034"
"8.60000","2.28328","2154.00171","0.00285","0.00067","215.40018","-0.00033"
"8.80000","2.29002","2174.20532","0.00291","0.00068","217.42053","-0.00030"
"9.00000","2.29655","2191.01831","0.00298","0.00065","219.10184","-0.00030"
"9.20000","2.30342","2211.14185","0.00305","0.00062","221.11418","-0.00030"
"9.40000","2.31002","2226.12500","0.00311","0.00065","222.61250","-0.00032"
"9.60000","2.31661","2239.55420","0.00318","0.00064","223.95541","-0.00031"
"9.80000","2.32342","2256.17554","0.00325","0.00065","225.61755","-0.00034"
"10.00000","2.32991","2267.27856","0.00331","0.00067","226.72786","-0.00033"
"10.20000","2.33665","2280.78076","0.00338","0.00070","228.07808","-0.00035"
"10.40000","2.34325","2292.31519","0.00344","0.00072","229.23152","-0.00038"
"10.60000","2.35010","2306.08350","0.00351","0.00074","230.60835","-0.00039"
"10.80000","2.35670","2315.73853","0.00358","0.00071","231.57385","-0.00043"
"11.00000","2.36326","2322.72192","0.00365","0.00069","232.27219","-0.00042"
"11.20000","2.37005","2332.83960","0.00371","0.00069","233.28397","-0.00039"
"11.40000","2.37651","2337.41968","0.00378","0.00070","233.74197","-0.00043"
"11.60000","2.38336","2346.35962","0.00385","0.00072","234.63596","-0.00048"
"11.80000","2.38993","2351.39941","0.00391","0.00076","235.13994","-0.00051"
"12.00000","2.39675","2358.04663","0.00398","0.00080","235.80466","-0.00046"
"12.20000","2.40335","2362.05078","0.00405","0.00080","236.20508","-0.00042"
"12.40000","2.40998","2364.65137","0.00411","0.00081","236.46513","-0.00042"
"12.60000","2.41667","2368.19873","0.00418","0.00080","236.81987","-0.00043"
"12.80000","2.42322","2369.24780","0.00424","0.00076","236.92477","-0.00046"
"13.00000","2.43014","2374.36792","0.00431","0.00081","237.43680","-0.00046"
"13.20000","2.43661","2373.10449","0.00438","0.00084","237.31046","-0.00047"
"13.40000","2.44327","2373.78467","0.00445","0.00086","237.37846","-0.00047"
"13.60000","2.45005","2376.59619","0.00451","0.00088","237.65962","-0.00047"
"13.80000","2.45662","2376.14233","0.00458","0.00088","237.61423","-0.00051"
"14.00000","2.46324","2376.78711","0.00464","0.00090","237.67871","-0.00045"
"14.20000","2.46999","2378.53638","0.00471","0.00089","237.85364","-0.00046"
"14.40000","2.47671","2379.23120","0.00478","0.00086","237.92313","-0.00043"
"14.60000","2.48337","2379.66382","0.00485","0.00087","237.96638","-0.00042"
"14.80000","2.48998","2378.96289","0.00491","0.00087","237.89629","-0.00045"
"15.00000","2.49665","2379.48364","0.00498","0.00089","237.94836","-0.00046"
"15.20000","2.50326","2379.65552","0.00505","0.00090","237.96555","-0.00046"
"15.40000","2.51003","2381.90576","0.00511","0.00088","238.19058","-0.00043"
"15.60000","2.51670","2382.02710","0.00518","0.00085","238.20271","-0.00039"
"15.80000","2.52325","2379.31226","0.00525","0.00083","237.93123","-0.00042"
"16.00000","2.53007","2380.24414","0.00531","0.00079","238.02441","-0.00038"
"16.20000","2.53657","2375.54150","0.00538","0.00078","237.55415","-0.00032"
"16.40000","2.54330","2374.15869","0.00545","0.00079","237.41586","-0.00032"
"16.60000","2.55000","2372.56885","0.00551","0.00080","237.25688","-0.00034"
"16.80000","2.55675","2370.70679","0.00558","0.00082","237.07068","-0.00037"
"17.00000","2.56331","2367.64429","0.00565","0.00080","236.76443","-0.00032"
"17.20000","2.56992","2365.69482","0.00571","0.00075","236.56949","-0.00030"
"17.40000","2.57680","2367.56323","0.00578","0.00073","236.75632","-0.00034"
"17.60000","2.58319","2362.39771","0.00584","0.00073","236.23978","-0.00034"
"17.80000","2.58997","2362.87964","0.00591","0.00074","236.28796","-0.00033"
"18.00000","2.59661","2361.93018","0.00598","0.00075","236.19302","-0.00036"
"18.20000","2.60332","2360.45044","0.00605","0.00076","236.04504","-0.00038"
"18.40000","2.61012","2361.33887","0.00611","0.00076","236.13388","-0.00034"
"18.60000","2.61661","2357.24805","0.00618","0.00072","235.72481","-0.00025"
"18.80000","2.62330","2356.56152","0.00625","0.00071","235.65616","-0.00022"
"19.00000","2.62991","2354.68042","0.00631","0.00071","235.46805","-0.00029"
"19.20000","2.63682","2357.23438","0.00638","0.00070","235.72343","-0.00026"
"19.40000","2.64325","2352.99438","0.00644","0.00075","235.29944","-0.00029"
"19.60000","2.64990","2350.78882","0.00651","0.00078","235.07889","-0.00031"
"19.80000","2.65673","2351.77490","0.00658","0.00078","235.17749","-0.00032"
"20.00000","2.66326","2347.92163","0.00665","0.00075","234.79216","-0.00029"
"20.20000","2.67006","2347.84546","0.00671","0.00075","234.78455","-0.00026"
"20.40000","2.67664","2345.00635","0.00678","0.00075","234.50064","-0.00029"
"20.60000","2.68338","2344.19727","0.00685","0.00070","234.41972","-0.00027"
"20.80000","2.68997","2342.40479","0.00691","0.00075","234.24048","-0.00029"
"21.00000","2.69666","2340.91797","0.00698","0.00079","234.09180","-0.00035"
"21.20000","2.70327","2338.71826","0.00705","0.00079","233.87183","-0.00034"
"21.40000","2.70989","2336.36035","0.00711","0.00079","233.63603","-0.00032"
"21.60000","2.71675","2336.58154","0.00718","0.00077","233.65816","-0.00022"
"21.80000","2.72334","2333.24316","0.00725","0.00079","233.32431","-0.00025"
"22.00000","2.72997","2329.55444","0.00731","0.00078","232.95544","-0.00025"
"22.20000","2.73675","2328.34399","0.00738","0.00080","232.83440","-0.00026"
"22.40000","2.74331","2323.19702","0.00745","0.00086","232.31970","-0.00030"
"22.60000","2.74994","2319.32373","0.00751","0.00087","231.93237","-0.00030"
"22.80000","2.75668","2316.85718","0.00758","0.00084","231.68571","-0.00037"
"23.00000","2.76340","2313.51660","0.00765","0.00082","231.35165","-0.00031"
"23.20000","2.76995","2308.68896","0.00771","0.00077","230.86890","-0.00025"
"23.40000","2.77655","2302.83154","0.00778","0.00078","230.28316","-0.00020"
"23.60000","2.78340","2300.66187","0.00785","0.00078","230.06619","-0.00016"
"23.80000","2.78994","2294.20312","0.00791","0.00078","229.42032","-0.00022"
"24.00000","2.79676","2290.97485","0.00798","0.00080","229.09749","-0.00023"
"24.20000","2.80338","2285.92896","0.00805","0.00077","228.59290","-0.00017"
"24.40000","2.80997","2279.64331","0.00811","0.00073","227.96432","-0.00013"
"24.60000","2.81675","2276.55786","0.00818","0.00071","227.65579","-0.00019"
"24.80000","2.82323","2268.63110","0.00824","0.00066","226.86311","-0.00021"
"25.00000","2.82990","2263.45947","0.00831","0.00067","226.34595","-0.00019"
"25.20000","2.83649","2257.79980","0.00838","0.00070","225.77998","-0.00025"
"25.40000","2.84350","2256.74072","0.00845","0.00072","225.67407","-0.00022"
"25.60000","2.85005","2249.57324","0.00851","0.00071","224.95732","-0.00025"
"25.80000","2.85666","2242.90869","0.00858","0.00070","224.29086","-0.00014"
"26.00000","2.86347","2240.28687","0.00865","0.00068","224.02869","-0.00017"
"26.20000","2.86991","2232.19263","0.00871","0.00065","223.21927","-0.00013"
"26.40000","2.87664","2228.61426","0.00878","0.00070","222.86142","-0.00017"
"26.60000","2.88326","2223.62451","0.00885","0.00073","222.36246","-0.00015"
"26.80000","2.89000","2218.97754","0.00891","0.00076","221.89775","-0.00017"
"27.00000","2.89665","2214.74487","0.00898","0.00078","221.47449","-0.00013"
"27.20000","2.90331","2209.88672","0.00905","0.00074","220.98868","-0.00008"
"27.40000","2.91002","2206.42798","0.00911","0.00071","220.64279","-0.00008"
"27.60000","2.91662","2201.64673","0.00918","0.00068","220.16467","-0.00004"
"27.80000","2.92348","2200.63281","0.00925","0.00071","220.06328","-0.00004"
"28.00000","2.92997","2195.29614","0.00931","0.00072","219.52962","-0.00009"
"28.20000","2.93665","2192.32056","0.00938","0.00073","219.23206","-0.00011"
"28.40000","2.94334","2190.27295","0.00945","0.00076","219.02730","-0.00010"
"28.60000","2.94992","2185.95630","0.00951","0.00073","218.59563","-0.00004"
"28.80000","2.95658","2183.79663","0.00958","0.00073","218.37967","-0.00002"
"29.00000","2.96332","2182.60254","0.00965","0.00070","218.26025","-0.00001"
"29.20000","2.97011","2181.74097","0.00971","0.00074","218.17410","-0.00004"
"29.40000","2.97674","2179.26685","0.00978","0.00078","217.92668","-0.00008"
"29.60000","2.98335","2176.13330","0.00985","0.00078","217.61333","-0.00009"
"29.80000","2.99003","2173.79883","0.00991","0.00077","217.37988","-0.00005"
"30.00000","2.99657","2169.73804","0.00998","0.00076","216.97380","-0.00002"
"30.20000","3.00333","2168.70654","0.01005","0.00074","216.87065","-0.00004"
"30.40000","3.00997","2166.07959","0.01011","0.00072","216.60796","-0.00004"
"30.60000","3.01660","2162.80005","0.01018","0.00072","216.28000","-0.00004"
"30.80000","3.02342","2161.85815","0.01025","0.00074","216.18582","-0.00007"
"31.00000","3.03000","2156.84668","0.01031","0.00077","215.68466","-0.00009"
"31.20000","3.03672","2153.73755","0.01038","0.00076","215.37375","-0.00012"
"31.40000","3.04330","2149.77930","0.01045","0.00077","214.97794","-0.00007"
"31.60000","3.05009","2149.15552","0.01051","0.00076","214.91556","-0.00010"
"31.80000","3.05664","2146.12354","0.01058","0.00075","214.61235","-0.00004"
"32.00000","3.06324","2143.46582","0.01064","0.00078","214.34659","-0.00005"
"32.20000","3.07011","2144.46924","0.01071","0.00082","214.44693","-0.00007"
"32.40000","3.07652","2139.58130","0.01078","0.00084","213.95813","-0.00008"
"32.60000","3.08333","2141.04272","0.01085","0.00085","214.10428","-0.00010"
"32.80000","3.09001","2141.60962","0.01091","0.00085","214.16096","-0.00004"
"33.00000","3.09679","2141.74976","0.01098","0.00085","214.17497","-0.00004"
"33.20000","3.10341","2140.30884","0.01105","0.00084","214.03088","-0.00004"
"33.40000","3.10999","2137.33545","0.01111","0.00085","213.73355","-0.00005"
"33.60000","3.11667","2135.55371","0.01118","0.00086","213.55537","-0.00011"
"33.80000","3.12318","2131.43311","0.01124","0.00089","213.14331","-0.00017"
"34.00000","3.13011","2133.07812","0.01131","0.00093","213.30782","-0.00009"
"34.20000","3.13658","2128.82349","0.01138","0.00092","212.88235","-0.00003"
"34.40000","3.14332","2127.05444","0.01145","0.00090","212.70544","-0.00004"
"34.60000","3.15012","2127.06616","0.01151","0.00085","212.70662","-0.00002"
"34.80000","3.15669","2122.61157","0.01158","0.00085","212.26115","-0.00009"
"35.00000","3.16336","2119.81714","0.01165","0.00087","211.98172","-0.00013"
"35.20000","3.16998","2116.71509","0.01171","0.00086","211.67151","-0.00017"
"35.40000","3.17673","2115.10034","0.01178","0.00086","211.51004","-0.00013"
"35.60000","3.18326","2110.32153","0.01185","0.00085","211.03215","-0.00007"
"35.80000","3.18994","2106.17603","0.01191","0.00082","210.61760","-0.00001"
"36.00000","3.19669","2103.54785","0.01198","0.00078","210.35478","-0.00001"
"36.20000","3.20326","2097.98755","0.01205","0.00075","209.79875","-0.00004"
"36.40000","3.21007","2095.20044","0.01211","0.00077","209.52005","-0.00004"
"36.60000","3.21674","2090.13867","0.01218","0.00079","209.01387","-0.00010"
"36.80000","3.22336","2083.48926","0.01225","0.00080","208.34892","-0.00008"
"37.00000","3.23006","2078.51685","0.01231","0.00080","207.85168","-0.00012"
"37.20000","3.23662","2071.21289","0.01238","0.00078","207.12129","-0.00012"
"37.40000","3.24329","2065.52515","0.01245","0.00077","206.55252","-0.00008"
"37.60000","3.24994","2060.77173","0.01251","0.00077","206.07718","-0.00012"
"37.80000","3.25672","2057.65674","0.01258","0.00078","205.76567","-0.00017"
"38.00000","3.26336","2053.17456","0.01265","0.00080","205.31746","-0.00018"
"38.20000","3.26997","2047.91357","0.01271","0.00081","204.79135","-0.00021"
"38.40000","3.27680","2046.18298","0.01278","0.00079","204.61830","-0.00017"
"38.60000","3.28328","2040.02686","0.01285","0.00079","204.00269","-0.00017"
"38.80000","3.29000","2038.31287","0.01291","0.00074","203.83128","-0.00017"
"39.00000","3.29662","2035.50012","0.01298","0.00073","203.55002","-0.00019"
"39.20000","3.30333","2032.68396","0.01305","0.00072","203.26840","-0.00021"
"39.40000","3.31007","2031.86182","0.01311","0.00075","203.18619","-0.00025"
"39.60000","3.31660","2027.60571","0.01318","0.00075","202.76057","-0.00025"
"39.80000","3.32334","2025.50220","0.01325","0.00075","202.55022","-0.00025"
"40.00000","3.32996","2021.41455","0.01331","0.00073","202.14145","-0.00021"
"40.20000","3.33686","2020.66138","0.01338","0.00070","202.06613","-0.00021"
"40.40000","3.34336","2015.30127","0.01345","0.00071","201.53012","-0.00021"
"40.60000","3.34992","2011.09998","0.01351","0.00071","201.11000","-0.00030"
"40.80000","3.35673","2011.57629","0.01358","0.00072","201.15762","-0.00030"
"41.00000","3.36326","2006.36853","0.01365","0.00072","200.63686","-0.00025"
"41.20000","3.37006","2004.60742","0.01371","0.00069","200.46074","-0.00025"
"41.40000","3.37656","1998.49976","0.01378","0.00064","199.84998","-0.00022"
"41.60000","3.38344","1996.99500","0.01385","0.00063","199.69949","-0.00023"
"41.80000","3.39004","1991.43030","0.01391","0.00064","199.14304","-0.00018"
"42.00000","3.39669","1986.01685","0.01398","0.00065","198.60168","-0.00029"
"42.20000","3.40338","1982.12268","0.01405","0.00067","198.21227","-0.00026"
"42.40000","3.40990","1975.85913","0.01411","0.00068","197.58591","-0.00028"
"42.60000","3.41671","1974.40503","0.01418","0.00069","197.44051","-0.00021"
"42.80000","3.42331","1969.50269","0.01425","0.00065","196.95027","-0.00017"
"43.00000","3.43001","1965.86401","0.01431","0.00064","196.58640","-0.00017"
"43.20000","3.43672","1962.70068","0.01438","0.00064","196.27007","-0.00014"
"43.40000","3.44331","1957.11389","0.01445","0.00067","195.71140","-0.00017"
"43.60000","3.44999","1953.05774","0.01451","0.00070","195.30577","-0.00017"
"43.80000","3.45667","1949.31812","0.01458","0.00072","194.93181","-0.00016"
"44.00000","3.46344","1946.76392","0.01465","0.00073","194.67639","-0.00013"
"44.20000","3.46998","1941.73621","0.01471","0.00069","194.17361","-0.00012"
"44.40000","3.47659","1938.10876","0.01478","0.00068","193.81088","-0.00008"
"44.60000","3.48339","1938.04089","0.01485","0.00070","193.80409","-0.00013"
"44.80000","3.48993","1935.12158","0.01491","0.00071","193.51216","-0.00009"
"45.00000","3.49664","1934.88452","0.01498","0.00076","193.48845","-0.00013"
"45.20000","3.50337","1935.58313","0.01505","0.00076","193.55832","-0.00019"
"45.40000","3.51005","1934.09900","0.01511","0.00078","193.40990","-0.00014"
"45.60000","3.51675","1933.90747","0.01518","0.00077","193.39075","-0.00016"
"45.80000","3.52331","1931.27148","0.01525","0.00074","193.12715","-0.00017"
"46.00000","3.52996","1929.75806","0.01531","0.00073","192.97580","-0.00013"
"46.20000","3.53653","1927.49792","0.01538","0.00075","192.74979","-0.00013"
"46.40000","3.54342","1928.94763","0.01545","0.00075","192.89476","-0.00017"
"46.60000","3.54999","1926.25842","0.01551","0.00078","192.62584","-0.00017"
"46.80000","3.55661","1922.90491","0.01558","0.00079","192.29050","-0.00017"
"47.00000","3.56350","1924.02197","0.01565","0.00077","192.40219","-0.00014"
"47.20000","3.56995","1918.47229","0.01571","0.00075","191.84723","-0.00008"
"47.40000","3.57665","1916.70618","0.01578","0.00074","191.67062","-0.00013"
"47.60000","3.58324","1914.75037","0.01584","0.00076","191.47504","-0.00017"
"47.80000","3.59008","1914.79028","0.01591","0.00076","191.47903","-0.00018"
"48.00000","3.59664","1911.35071","0.01598","0.00078","191.13507","-0.00025"
"48.20000","3.60334","1908.64209","0.01605","0.00079","190.86421","-0.00022"
"48.40000","3.61008","1907.33032","0.01611","0.00078","190.73303","-0.00017"
"48.60000","3.61654","1901.86218","0.01618","0.00074","190.18622","-0.00015"
"48.80000","3.62342","1901.98547","0.01625","0.00076","190.19855","-0.00013"
"49.00000","3.63000","1897.31592","0.01631","0.00077","189.73160","-0.00015"
"49.20000","3.63664","1891.99023","0.01638","0.00079","189.19902","-0.00020"
"49.40000","3.64340","1889.74500","0.01645","0.00082","188.97450","-0.00017"
"49.60000","3.64996","1884.69995","0.01651","0.00085","188.47000","-0.00025"
"49.80000","3.65659","1881.89539","0.01658","0.00083","188.18954","-0.00021"
"50.00000","3.66328","1880.27734","0.01665","0.00079","188.02774","-0.00017"
"50.20000","3.67012","1880.51086","0.01671","0.00075","188.05109","-0.00016"
"50.40000","3.67666","1876.05212","0.01678","0.00074","187.60521","-0.00013"
"50.60000","3.68328","1872.42627","0.01685","0.00078","187.24263","-0.00021"
"50.80000","3.69010","1871.56018","0.01691","0.00085","187.15602","-0.00026"
"51.00000","3.69662","1866.42896","0.01698","0.00084","186.64290","-0.00025"
"51.20000","3.70334","1864.68555","0.01705","0.00082","186.46855","-0.00025"
"51.40000","3.70999","1861.60596","0.01711","0.00080","186.16060","-0.00018"
"51.60000","3.71665","1858.38867","0.01718","0.00079","185.83887","-0.00015"
"51.80000","3.72340","1856.96423","0.01725","0.00078","185.69643","-0.00020"
"52.00000","3.72997","1852.78992","0.01731","0.00078","185.27899","-0.00021"
"52.20000","3.73665","1849.98730","0.01738","0.00080","184.99873","-0.00025"
"52.40000","3.74327","1846.31128","0.01745","0.00079","184.63113","-0.00025"
"52.60000","3.75012","1844.82507","0.01751","0.00078","184.48251","-0.00021"
"52.80000","3.75666","1839.54517","0.01758","0.00075","183.95451","-0.00017"
"53.00000","3.76323","1834.10254","0.01764","0.00072","183.41025","-0.00017"
"53.20000","3.77006","1832.92834","0.01771","0.00071","183.29283","-0.00013"
"53.40000","3.77659","1827.79333","0.01778","0.00072","182.77933","-0.00013"
"53.60000","3.78335","1825.64368","0.01785","0.00074","182.56436","-0.00017"
"53.80000","3.78998","1822.85828","0.01791","0.00074","182.28583","-0.00017"
"54.00000","3.79674","1821.31360","0.01798","0.00075","182.13136","-0.00021"
"54.20000","3.80336","1818.56213","0.01805","0.00074","181.85622","-0.00017"
"54.40000","3.80993","1813.75281","0.01811","0.00073","181.37527","-0.00017"
"54.60000","3.81670","1811.80408","0.01818","0.00070","181.18040","-0.00011"
"54.80000","3.82315","1806.53503","0.01824","0.00074","180.65350","-0.00017"
"55.00000","3.83004","1807.34692","0.01831","0.00077","180.73470","-0.00021"
"55.20000","3.83660","1804.16406","0.01838","0.00079","180.41641","-0.00021"
"55.40000","3.84337","1802.42676","0.01845","0.00079","180.24268","-0.00020"
"55.60000","3.85004","1800.68152","0.01851","0.00079","180.06815","-0.00017"
"55.80000","3.85663","1796.46240","0.01858","0.00076","179.64624","-0.00013"
"56.00000","3.86332","1794.83057","0.01865","0.00074","179.48306","-0.00013"
"56.20000","3.86994","1791.77136","0.01871","0.00074","179.17714","-0.00016"
"56.40000","3.87679","1790.82935","0.01878","0.00076","179.08293","-0.00021"
"56.60000","3.88328","1785.56348","0.01885","0.00076","178.55635","-0.00024"
"56.80000","3.88991","1781.36230","0.01891","0.00078","178.13623","-0.00018"
"57.00000","3.89667","1779.98022","0.01898","0.00076","177.99802","-0.00017"
"57.20000","3.90329","1775.15210","0.01905","0.00072","177.51521","-0.00017"
"57.40000","3.90996","1771.01160","0.01911","0.00069","177.10117","-0.00013"
"57.60000","3.91666","1767.00183","0.01918","0.00067","176.70018","-0.00012"
"57.80000","3.92336","1763.03027","0.01925","0.00069","176.30302","-0.00014"
"58.00000","3.93005","1760.60986","0.01931","0.00072","176.06099","-0.00013"
"58.20000","3.93665","1756.72607","0.01938","0.00071","175.67261","-0.00013"
"58.40000","3.94328","1753.55615","0.01945","0.00068","175.35562","-0.00009"
"58.60000","3.94994","1751.20667","0.01951","0.00065","175.12067","-0.00004"
"58.80000","3.95673","1751.00696","0.01958","0.00065","175.10069","-0.00001"
"59.00000","3.96339","1748.71924","0.01965","0.00066","174.87192","-0.00004"
"59.20000","3.96992","1744.39124","0.01971","0.00070","174.43912","-0.00008"
"59.40000","3.97672","1744.62976","0.01978","0.00071","174.46298","-0.00008"
"59.60000","3.98322","1741.24646","0.01984","0.00073","174.12465","-0.00007"
"59.80000","3.99000","1740.38684","0.01991","0.00074","174.03868","-0.00008"
"60.00000","3.99666","1738.37415","0.01998","0.00072","173.83742","0.00000"
"60.20000","4.00340","1736.81458","0.02005","0.00072","173.68146","0.00000"
"60.40000","4.01002","1734.74976","0.02011","0.00074","173.47498","0.00000"
"60.60000","4.01660","1731.67810","0.02018","0.00075","173.16782","-0.00009"
"60.80000","4.02340","1732.39136","0.02025","0.00077","173.23914","-0.00004"
"61.00000","4.02985","1728.70081","0.02031","0.00078","172.87009","-0.00004"
"61.20000","4.03671","1730.05273","0.02038","0.00078","173.00528","-0.00008"
"61.40000","4.04330","1727.63110","0.02045","0.00073","172.76311","-0.00004"
"61.60000","4.04996","1725.38013","0.02051","0.00071","172.53801","0.00000"
"61.80000","4.05678","1726.42773","0.02058","0.00067","172.64278","0.00003"
"62.00000","4.06324","1722.27979","0.02064","0.00066","172.22798","0.00004"
"62.20000","4.06994","1721.53601","0.02071","0.00069","172.15359","0.00000"
"62.40000","4.07661","1720.76501","0.02078","0.00071","172.07651","-0.00004"
"62.60000","4.08352","1722.33252","0.02085","0.00071","172.23325","-0.00008"
"62.80000","4.08989","1717.32568","0.02091","0.00067","171.73257","-0.00008"
"63.00000","4.09659","1715.93018","0.02098","0.00064","171.59302","-0.00008"
"63.20000","4.10341","1717.21802","0.02105","0.00061","171.72180","0.00000"
"63.40000","4.10992","1713.48450","0.02111","0.00063","171.34845","0.00000"
"63.60000","4.11671","1713.68872","0.02118","0.00066","171.36887","-0.00004"
"63.80000","4.12331","1710.82117","0.02125","0.00067","171.08212","-0.00003"
"64.00000","4.13002","1708.56580","0.02131","0.00070","170.85658","-0.00004"
"64.20000","4.13666","1706.58398","0.02138","0.00069","170.65840","0.00000"
"64.40000","4.14332","1703.78796","0.02145","0.00066","170.37880","0.00004"
"64.60000","4.14989","1700.17151","0.02151","0.00066","170.01715","0.00004"
"64.80000","4.15658","1698.57202","0.02158","0.00068","169.85721","0.00003"
"65.00000","4.16340","1699.42456","0.02165","0.00067","169.94246","-0.00001"
"65.20000","4.17000","1696.75476","0.02171","0.00074","169.67548","-0.00004"
"65.40000","4.17662","1693.65857","0.02178","0.00077","169.36586","-0.00008"
"65.60000","4.18343","1694.63379","0.02185","0.00077","169.46338","-0.00004"
"65.80000","4.18994","1691.66211","0.02191","0.00075","169.16621","0.00000"
"66.00000","4.19660","1690.86646","0.02198","0.00076","169.08664","0.00004"
"66.20000","4.20333","1691.18884","0.02205","0.00074","169.11888","0.00000"
"66.40000","4.21002","1690.62805","0.02211","0.00076","169.06281","-0.00004"
"66.60000","4.21665","1689.24219","0.02218","0.00078","168.92422","-0.00008"
"66.80000","4.22325","1687.26318","0.02225","0.00077","168.72632","-0.00008"
"67.00000","4.23005","1687.36255","0.02231","0.00077","168.73625","-0.00006"
"67.20000","4.23661","1685.03003","0.02238","0.00075","168.50301","-0.00009"
"67.40000","4.24344","1686.33667","0.02245","0.00071","168.63367","-0.00008"
"67.60000","4.25001","1685.01404","0.02251","0.00069","168.50140","0.00000"
"67.80000","4.25662","1683.55933","0.02258","0.00071","168.35593","-0.00004"
"68.00000","4.26344","1685.74231","0.02265","0.00074","168.57423","-0.00012"
"68.20000","4.26991","1683.07605","0.02271","0.00076","168.30760","-0.00015"
"68.40000","4.27656","1682.89453","0.02278","0.00080","168.28946","-0.00012"
"68.60000","4.28321","1683.27563","0.02284","0.00079","168.32756","-0.00014"
"68.80000","4.29012","1686.15039","0.02291","0.00078","168.61504","-0.00020"
"69.00000","4.29667","1685.02197","0.02298","0.00077","168.50220","-0.00010"
"69.20000","4.30334","1684.90405","0.02305","0.00077","168.49040","-0.00008"
"69.40000","4.31009","1686.59961","0.02311","0.00078","168.65996","-0.00012"
"69.60000","4.31656","1684.42090","0.02318","0.00079","168.44209","-0.00017"
"69.80000","4.32338","1686.81299","0.02325","0.00080","168.68130","-0.00017"
"70.00000","4.32991","1685.70239","0.02331","0.00080","168.57024","-0.00017"
"70.20000","4.33662","1685.77808","0.02338","0.00078","168.57780","-0.00017"
"70.40000","4.34334","1687.19568","0.02345","0.00079","168.71957","-0.00013"
"70.60000","4.34999","1686.31970","0.02351","0.00078","168.63197","-0.00008"
"70.80000","4.35668","1686.31165","0.02358","0.00079","168.63116","-0.00008"
"71.00000","4.36331","1684.99890","0.02365","0.00081","168.49989","-0.00012"
"71.20000","4.37020","1687.35815","0.02371","0.00083","168.73581","-0.00021"
"71.40000","4.37661","1684.08728","0.02378","0.00081","168.40872","-0.00021"
"71.60000","4.38329","1683.76636","0.02385","0.00078","168.37663","-0.00017"
"71.80000","4.39001","1684.37488","0.02391","0.00074","168.43748","-0.00017"
"72.00000","4.39657","1681.87866","0.02398","0.00073","168.18787","-0.00013"
"72.20000","4.40329","1681.77673","0.02405","0.00073","168.17767","-0.00017"
"72.40000","4.41000","1681.18494","0.02411","0.00075","168.11850","-0.00019"
"72.60000","4.41673","1680.11243","0.02418","0.00075","168.01125","-0.00020"
"72.80000","4.42339","1679.34106","0.02425","0.00077","167.93411","-0.00020"
"73.00000","4.42999","1676.87146","0.02431","0.00076","167.68715","-0.00022"
"73.20000","4.43666","1675.40759","0.02438","0.00072","167.54076","-0.00021"
"73.40000","4.44324","1672.83411","0.02444","0.00071","167.28342","-0.00017"
"73.60000","4.45005","1673.10718","0.02451","0.00070","167.31071","-0.00015"
"73.80000","4.45664","1671.13916","0.02458","0.00071","167.11392","-0.00021"
"74.00000","4.46323","1668.64417","0.02464","0.00074","166.86441","-0.00021"
"74.20000","4.47010","1670.59009","0.02471","0.00074","167.05901","-0.00021"
"74.40000","4.47664","1667.73962","0.02478","0.00075","166.77396","-0.00020"
"74.60000","4.48338","1667.28101","0.02485","0.00072","166.72810","-0.00018"
"74.80000","4.48999","1665.27258","0.02491","0.00069","166.52725","-0.00019"
"75.00000","4.49678","1664.65552","0.02498","0.00070","166.46555","-0.00013"
"75.20000","4.50337","1662.07214","0.02505","0.00071","166.20721","-0.00013"
"75.40000","4.50991","1658.30811","0.02511","0.00071","165.83081","-0.00017"
"75.60000","4.51670","1658.04993","0.02518","0.00071","165.80499","-0.00017"
"75.80000","4.52317","1654.18201","0.02524","0.00072","165.41820","-0.00017"
"76.00000","4.53005","1655.10901","0.02531","0.00069","165.51089","-0.00017"
"76.20000","4.53671","1653.17017","0.02538","0.00067","165.31702","-0.00012"
"76.40000","4.54344","1651.58459","0.02545","0.00067","165.15846","-0.00008"
"76.60000","4.55014","1650.74097","0.02551","0.00068","165.07410","-0.00008"
"76.80000","4.55662","1646.58899","0.02558","0.00069","164.65891","-0.00013"
"77.00000","4.56326","1645.07288","0.02565","0.00070","164.50729","-0.00016"
"77.20000","4.56984","1642.65686","0.02571","0.00071","164.26569","-0.00015"
"77.40000","4.57679","1644.77771","0.02578","0.00072","164.47777","-0.00013"
"77.60000","4.58326","1640.37500","0.02585","0.00071","164.03751","-0.00008"
"77.80000","4.58997","1638.45422","0.02591","0.00071","163.84543","-0.00009"
"78.00000","4.59678","1639.30212","0.02598","0.00071","163.93021","-0.00008"
"78.20000","4.60333","1636.73743","0.02605","0.00073","163.67374","-0.00009"
"78.40000","4.61004","1637.32825","0.02611","0.00077","163.73282","-0.00008"
"78.60000","4.61664","1636.75098","0.02618","0.00077","163.67509","-0.00008"
"78.80000","4.62340","1637.48975","0.02625","0.00078","163.74898","-0.00008"
"79.00000","4.62997","1636.88916","0.02631","0.00074","163.68892","-0.00002"
"79.20000","4.63662","1637.20459","0.02638","0.00072","163.72046","-0.00005"
"79.40000","4.64328","1637.81824","0.02645","0.00073","163.78183","-0.00008"
"79.60000","4.64992","1637.52905","0.02651","0.00073","163.75290","-0.00010"
"79.80000","4.65679","1639.60583","0.02658","0.00075","163.96059","-0.00015"
"80.00000","4.66339","1637.92432","0.02665","0.00077","163.79243","-0.00017"
"80.20000","4.67000","1636.07788","0.02671","0.00079","163.60779","-0.00017"
"80.40000","4.67674","1637.20496","0.02678","0.00076","163.72049","-0.00014"
"80.60000","4.68327","1635.28064","0.02685","0.00073","163.52806","-0.00013"
"80.64500","4.68478","1635.38586","0.02686","0.00073","163.53859","-0.00013"