File: Tension/Section_1_Group_2/Walnut_5%-2.is_tens_RawData/Specimen_RawData_1.csv
Time,Extension,Load,Tensile strain (Extension),Tensile stress,Strain-by-clip-gage
(s),(mm),(N),(mm/mm),(MPa),(mm/mm)
"0.00000","0.00000","-0.99075","0.00000","-0.09907","-0.00004"
"0.10000","0.00023","-0.59600","0.00000","-0.05960","-0.00006"
"0.20000","0.00064","-0.40498","0.00001","-0.04050","-0.00003"
"0.30000","0.00177","1.14169","0.00002","0.11417","-0.00006"
"0.40000","0.00486","5.44128","0.00005","0.54413","-0.00006"
"0.50000","0.00648","7.41324","0.00006","0.74132","-0.00003"
"0.60000","0.00846","10.33930","0.00008","1.03393","-0.00005"
"0.70000","0.00984","12.24130","0.00010","1.22413","-0.00003"
"0.80000","0.01163","14.56526","0.00012","1.45653","-0.00002"
"0.90000","0.01329","16.97492","0.00013","1.69749","-0.00003"
"1.00000","0.01495","19.23864","0.00015","1.92386","-0.00001"
"1.10000","0.01676","21.83601","0.00017","2.18360","-0.00001"
"1.20000","0.01814","23.59875","0.00018","2.35988","0.00000"
"1.30000","0.02008","26.35524","0.00020","2.63552","0.00001"
"1.40000","0.02155","28.47655","0.00022","2.84765","0.00001"
"1.50000","0.02324","30.75027","0.00023","3.07503","0.00003"
"1.60000","0.02494","33.13976","0.00025","3.31398","0.00004"
"1.70000","0.02654","35.38196","0.00027","3.53820","0.00004"
"1.80000","0.02844","37.97941","0.00028","3.79794","0.00005"
"1.90000","0.02985","39.90670","0.00030","3.99067","0.00006"
"2.00000","0.03165","42.39867","0.00032","4.23987","0.00007"
"2.10000","0.03322","44.59597","0.00033","4.45960","0.00008"
"2.20000","0.03487","46.69458","0.00035","4.66946","0.00009"
"2.30000","0.03670","49.00192","0.00037","4.90019","0.00009"
"2.40000","0.03822","50.52894","0.00038","5.05289","0.00009"
"2.50000","0.04003","49.57420","0.00040","4.95742","0.00008"
"2.60000","0.04152","50.91081","0.00042","5.09108","0.00008"
"2.70000","0.04328","53.37817","0.00043","5.33782","0.00008"
"2.80000","0.04493","55.63206","0.00045","5.56321","0.00009"
"2.90000","0.04651","57.73589","0.00047","5.77359","0.00010"
"3.00000","0.04833","60.22811","0.00048","6.02281","0.00011"
"3.10000","0.04988","62.24480","0.00050","6.22448","0.00011"
"3.20000","0.05171","64.54392","0.00052","6.45439","0.00012"
"3.30000","0.05326","66.28018","0.00053","6.62802","0.00013"
"3.40000","0.05489","68.08932","0.00055","6.80893","0.00014"
"3.50000","0.05658","70.05171","0.00057","7.00517","0.00015"
"3.60000","0.05813","72.00471","0.00058","7.20047","0.00015"
"3.70000","0.06008","74.52524","0.00060","7.45252","0.00016"
"3.80000","0.06158","76.37212","0.00062","7.63721","0.00017"
"3.90000","0.06333","78.78621","0.00063","7.87862","0.00018"
"4.00000","0.06500","80.79594","0.00065","8.07959","0.00019"
"4.10000","0.06653","82.97247","0.00067","8.29725","0.00019"
"4.20000","0.06837","85.36459","0.00068","8.53646","0.00020"
"4.30000","0.06983","87.20667","0.00070","8.72067","0.00021"
"4.40000","0.07169","89.65376","0.00072","8.96538","0.00022"
"4.50000","0.07330","91.89275","0.00073","9.18927","0.00023"
"4.60000","0.07499","94.04553","0.00075","9.40455","0.00024"
"4.70000","0.07674","96.44286","0.00077","9.64429","0.00025"
"4.80000","0.07815","98.19579","0.00078","9.81958","0.00026"
"4.90000","0.08004","100.94740","0.00080","10.09474","0.00027"
"5.00000","0.08153","102.69205","0.00082","10.26921","0.00028"
"5.10000","0.08329","105.27697","0.00083","10.52770","0.00029"
"5.20000","0.08498","107.44518","0.00085","10.74452","0.00030"
"5.30000","0.08654","109.40321","0.00087","10.94032","0.00031"
"5.40000","0.08843","112.00615","0.00088","11.20061","0.00032"
"5.50000","0.08981","113.77673","0.00090","11.37767","0.00033"
"5.60000","0.09164","116.25821","0.00092","11.62582","0.00033"
"5.70000","0.09312","118.16748","0.00093","11.81675","0.00034"
"5.80000","0.09497","120.79089","0.00095","12.07909","0.00035"
"5.90000","0.09679","123.12039","0.00097","12.31204","0.00036"
"6.00000","0.09818","124.78946","0.00098","12.47895","0.00036"
"6.10000","0.10008","127.60738","0.00100","12.76074","0.00037"
"6.20000","0.10144","129.26645","0.00101","12.92665","0.00038"
"6.30000","0.10330","131.71443","0.00103","13.17144","0.00039"
"6.40000","0.10488","133.80797","0.00105","13.38080","0.00039"
"6.50000","0.10656","136.04788","0.00107","13.60479","0.00039"
"6.60000","0.10844","138.69193","0.00108","13.86919","0.00040"
"6.70000","0.10977","140.30685","0.00110","14.03069","0.00040"
"6.80000","0.11181","143.23227","0.00112","14.32323","0.00040"
"6.90000","0.11314","144.64543","0.00113","14.46454","0.00040"
"7.00000","0.11493","147.13292","0.00115","14.71329","0.00040"
"7.10000","0.11656","149.38446","0.00117","14.93845","0.00040"
"7.20000","0.11824","151.57986","0.00118","15.15799","0.00039"
"7.30000","0.12017","154.19977","0.00120","15.41998","0.00039"
"7.40000","0.12147","155.85251","0.00121","15.58525","0.00039"
"7.50000","0.12345","158.49033","0.00123","15.84903","0.00039"
"7.60000","0.12480","160.09500","0.00125","16.00950","0.00039"
"7.70000","0.12657","162.52489","0.00127","16.25249","0.00039"
"7.80000","0.12831","164.73882","0.00128","16.47388","0.00039"
"7.90000","0.12989","166.88797","0.00130","16.68880","0.00039"
"8.00000","0.13180","169.55379","0.00132","16.95538","0.00039"
"8.10000","0.13317","171.14507","0.00133","17.11451","0.00039"
"8.20000","0.13512","173.81114","0.00135","17.38111","0.00039"
"8.30000","0.13658","175.68706","0.00137","17.56871","0.00039"
"8.40000","0.13815","177.67578","0.00138","17.76758","0.00039"
"8.50000","0.14002","180.10408","0.00140","18.01041","0.00039"
"8.60000","0.14161","182.13924","0.00142","18.21392","0.00039"
"8.70000","0.14340","184.55089","0.00143","18.45509","0.00039"
"8.80000","0.14485","186.32062","0.00145","18.63206","0.00039"
"8.90000","0.14665","188.72832","0.00147","18.87283","0.00039"
"9.00000","0.14829","190.86096","0.00148","19.08610","0.00039"
"9.10000","0.14985","192.90868","0.00150","19.29087","0.00039"
"9.20000","0.15164","195.17400","0.00152","19.51740","0.00039"
"9.30000","0.15320","197.27219","0.00153","19.72722","0.00039"
"9.40000","0.15501","199.56264","0.00155","19.95626","0.00039"
"9.50000","0.15662","201.65150","0.00157","20.16515","0.00038"
"9.60000","0.15830","203.72169","0.00158","20.37217","0.00039"
"9.70000","0.15999","205.98599","0.00160","20.59860","0.00038"
"9.80000","0.16146","207.79617","0.00161","20.77962","0.00038"
"9.90000","0.16329","210.35797","0.00163","21.03580","0.00038"
"10.00000","0.16489","212.31757","0.00165","21.23176","0.00038"
"10.10000","0.16666","214.67599","0.00167","21.46760","0.00038"
"10.20000","0.16837","216.79715","0.00168","21.67971","0.00037"
"10.30000","0.16985","218.75282","0.00170","21.87528","0.00037"
"10.40000","0.17169","221.13647","0.00172","22.11365","0.00037"
"10.50000","0.17313","222.84248","0.00173","22.28425","0.00036"
"10.60000","0.17494","225.23070","0.00175","22.52307","0.00036"
"10.70000","0.17667","227.55334","0.00177","22.75533","0.00035"
"10.80000","0.17823","229.48659","0.00178","22.94866","0.00035"
"10.90000","0.18013","232.02924","0.00180","23.20292","0.00034"
"11.00000","0.18150","233.55130","0.00181","23.35513","0.00033"
"11.10000","0.18338","236.10042","0.00183","23.61004","0.00033"
"11.20000","0.18479","237.72661","0.00185","23.77266","0.00031"
"11.30000","0.18664","240.07875","0.00187","24.00788","0.00031"
"11.40000","0.18840","242.37424","0.00188","24.23742","0.00030"
"11.50000","0.18987","244.09953","0.00190","24.40995","0.00029"
"11.60000","0.19183","246.86502","0.00192","24.68650","0.00029"
"11.70000","0.19312","248.25691","0.00193","24.82569","0.00028"
"11.80000","0.19508","250.75774","0.00195","25.07577","0.00027"
"11.90000","0.19653","252.51761","0.00197","25.25176","0.00027"
"12.00000","0.19821","254.64748","0.00198","25.46475","0.00026"
"12.10000","0.20007","257.16269","0.00200","25.71627","0.00026"
"12.20000","0.20151","258.93649","0.00202","25.89365","0.00025"
"12.30000","0.20354","261.63474","0.00204","26.16347","0.00025"
"12.40000","0.20477","262.96274","0.00205","26.29627","0.00025"
"12.50000","0.20664","265.32339","0.00207","26.53234","0.00025"
"12.60000","0.20821","267.24353","0.00208","26.72435","0.00024"
"12.70000","0.20990","269.49615","0.00210","26.94962","0.00024"
"12.80000","0.21175","271.77402","0.00212","27.17740","0.00024"
"12.90000","0.21312","273.36328","0.00213","27.33633","0.00024"
"13.00000","0.21513","276.10797","0.00215","27.61080","0.00024"
"13.10000","0.21647","277.58777","0.00216","27.75878","0.00024"
"13.20000","0.21831","279.92291","0.00218","27.99229","0.00024"
"13.30000","0.21995","281.91541","0.00220","28.19154","0.00025"
"13.40000","0.22152","283.86011","0.00222","28.38601","0.00025"
"13.50000","0.22341","286.23962","0.00223","28.62396","0.00025"
"13.60000","0.22482","287.92752","0.00225","28.79275","0.00025"
"13.70000","0.22676","290.40149","0.00227","29.04015","0.00026"
"13.80000","0.22816","292.08591","0.00228","29.20859","0.00027"
"13.90000","0.22991","294.17886","0.00230","29.41789","0.00027"
"14.00000","0.23166","296.39035","0.00232","29.63903","0.00027"
"14.10000","0.23320","298.25674","0.00233","29.82567","0.00027"
"14.20000","0.23508","300.62192","0.00235","30.06219","0.00028"
"14.30000","0.23651","302.27408","0.00237","30.22741","0.00028"
"14.40000","0.23833","304.51950","0.00238","30.45195","0.00028"
"14.50000","0.23989","306.31760","0.00240","30.63176","0.00028"
"14.60000","0.24154","308.32571","0.00242","30.83257","0.00029"
"14.70000","0.24329","310.49539","0.00243","31.04954","0.00029"
"14.80000","0.24489","312.47818","0.00245","31.24782","0.00029"
"14.90000","0.24673","314.70157","0.00247","31.47016","0.00030"
"15.00000","0.24829","316.53995","0.00248","31.65400","0.00030"
"15.10000","0.24995","318.62769","0.00250","31.86277","0.00030"
"15.20000","0.25163","320.71368","0.00252","32.07137","0.00030"
"15.30000","0.25315","322.42526","0.00253","32.24253","0.00030"
"15.40000","0.25507","324.89252","0.00255","32.48925","0.00031"
"15.50000","0.25662","326.64029","0.00257","32.66403","0.00031"
"15.60000","0.25831","328.59204","0.00258","32.85920","0.00032"
"15.70000","0.25998","330.62500","0.00260","33.06250","0.00032"
"15.80000","0.26159","332.49124","0.00262","33.24912","0.00032"
"15.90000","0.26336","334.72018","0.00263","33.47202","0.00032"
"16.00000","0.26483","336.28033","0.00265","33.62803","0.00032"
"16.10000","0.26666","338.54257","0.00267","33.85426","0.00033"
"16.20000","0.26827","340.42667","0.00268","34.04267","0.00033"
"16.30000","0.26993","342.39810","0.00270","34.23981","0.00033"
"16.40000","0.27168","344.53601","0.00272","34.45360","0.00033"
"16.50000","0.27317","346.17700","0.00273","34.61770","0.00033"
"16.60000","0.27506","348.38760","0.00275","34.83876","0.00034"
"16.70000","0.27648","350.08499","0.00276","35.00850","0.00034"
"16.80000","0.27836","352.22208","0.00278","35.22221","0.00034"
"16.90000","0.28001","354.31708","0.00280","35.43171","0.00035"
"17.00000","0.28155","356.02319","0.00282","35.60232","0.00035"
"17.10000","0.28338","358.24149","0.00283","35.82415","0.00035"
"17.20000","0.28481","359.77148","0.00285","35.97715","0.00036"
"17.30000","0.28671","362.23184","0.00287","36.22318","0.00036"
"17.40000","0.28815","363.71021","0.00288","36.37102","0.00036"
"17.50000","0.28995","365.88089","0.00290","36.58809","0.00037"
"17.60000","0.29170","367.96906","0.00292","36.79691","0.00037"
"17.70000","0.29318","369.64822","0.00293","36.96482","0.00037"
"17.80000","0.29509","371.85593","0.00295","37.18559","0.00037"
"17.90000","0.29644","373.36060","0.00296","37.33606","0.00037"
"18.00000","0.29835","375.61618","0.00298","37.56162","0.00037"
"18.10000","0.29988","377.30637","0.00300","37.73064","0.00037"
"18.20000","0.30161","379.25034","0.00302","37.92503","0.00037"
"18.30000","0.30339","381.32098","0.00303","38.13210","0.00038"
"18.40000","0.30485","382.94824","0.00305","38.29482","0.00037"
"18.50000","0.30681","385.31339","0.00307","38.53134","0.00038"
"18.60000","0.30814","386.74594","0.00308","38.67459","0.00038"
"18.70000","0.31005","388.93716","0.00310","38.89371","0.00038"
"18.80000","0.31156","390.57455","0.00312","39.05746","0.00037"
"18.90000","0.31323","392.56757","0.00313","39.25676","0.00037"
"19.00000","0.31520","394.96561","0.00315","39.49656","0.00037"
"19.10000","0.31657","396.22247","0.00317","39.62225","0.00037"
"19.20000","0.31840","398.40872","0.00318","39.84087","0.00037"
"19.30000","0.31978","399.80402","0.00320","39.98040","0.00036"
"19.40000","0.32164","401.95029","0.00322","40.19503","0.00036"
"19.50000","0.32331","403.81616","0.00323","40.38161","0.00036"
"19.60000","0.32487","405.59814","0.00325","40.55981","0.00035"
"19.70000","0.32676","407.72162","0.00327","40.77216","0.00035"
"19.80000","0.32817","409.14752","0.00328","40.91475","0.00035"
"19.90000","0.33006","411.51279","0.00330","41.15128","0.00034"
"20.00000","0.33149","412.88202","0.00331","41.28820","0.00034"
"20.10000","0.33320","414.88153","0.00333","41.48815","0.00034"
"20.20000","0.33496","416.82166","0.00335","41.68217","0.00033"
"20.30000","0.33658","418.65317","0.00337","41.86532","0.00033"
"20.40000","0.33845","420.80988","0.00338","42.08099","0.00033"
"20.50000","0.33985","422.13953","0.00340","42.21395","0.00032"
"20.60000","0.34168","424.21530","0.00342","42.42153","0.00032"
"20.70000","0.34320","425.90625","0.00343","42.59063","0.00032"
"20.80000","0.34483","427.67603","0.00345","42.76760","0.00032"
"20.90000","0.34668","429.79385","0.00347","42.97939","0.00032"
"21.00000","0.34820","431.35648","0.00348","43.13565","0.00032"
"21.10000","0.35006","433.51492","0.00350","43.35149","0.00032"
"21.20000","0.35155","435.02640","0.00352","43.50264","0.00032"
"21.30000","0.35331","436.99899","0.00353","43.69990","0.00032"
"21.40000","0.35496","438.80475","0.00355","43.88047","0.00032"
"21.50000","0.35645","440.29364","0.00356","44.02937","0.00032"
"21.60000","0.35833","442.54068","0.00358","44.25407","0.00033"
"21.70000","0.35994","444.18314","0.00360","44.41831","0.00033"
"21.80000","0.36168","446.19638","0.00362","44.61964","0.00033"
"21.90000","0.36331","447.64761","0.00363","44.76476","0.00033"
"22.00000","0.36492","449.44525","0.00365","44.94453","0.00034"
"22.10000","0.36659","451.28940","0.00367","45.12894","0.00034"
"22.20000","0.36813","452.85873","0.00368","45.28587","0.00034"
"22.30000","0.37001","455.08389","0.00370","45.50839","0.00035"
"22.40000","0.37164","456.60721","0.00372","45.66072","0.00035"
"22.50000","0.37324","458.31226","0.00373","45.83123","0.00036"
"22.60000","0.37510","460.33920","0.00375","46.03392","0.00036"
"22.70000","0.37659","461.94055","0.00377","46.19405","0.00036"
"22.80000","0.37832","463.81238","0.00378","46.38124","0.00037"
"22.90000","0.37978","465.14157","0.00380","46.51416","0.00037"
"23.00000","0.38165","467.31757","0.00382","46.73176","0.00037"
"23.10000","0.38337","469.18317","0.00383","46.91832","0.00038"
"23.20000","0.38486","470.67917","0.00385","47.06792","0.00038"
"23.30000","0.38674","472.90024","0.00387","47.29002","0.00039"
"23.40000","0.38817","474.12271","0.00388","47.41227","0.00039"
"23.50000","0.39005","476.18860","0.00390","47.61886","0.00040"
"23.60000","0.39147","477.65240","0.00391","47.76524","0.00040"
"23.70000","0.39325","479.50372","0.00393","47.95037","0.00040"
"23.80000","0.39506","481.53381","0.00395","48.15338","0.00041"
"23.90000","0.39650","482.88248","0.00396","48.28825","0.00041"
"24.00000","0.39853","485.21313","0.00399","48.52131","0.00041"
"24.10000","0.39984","486.27466","0.00400","48.62746","0.00042"
"24.20000","0.40167","488.25742","0.00402","48.82574","0.00042"
"24.30000","0.40314","489.65396","0.00403","48.96540","0.00042"
"24.40000","0.40491","491.59323","0.00405","49.15932","0.00043"
"24.50000","0.40677","493.61404","0.00407","49.36140","0.00043"
"24.60000","0.40817","494.79407","0.00408","49.47941","0.00043"
"24.70000","0.41012","497.06580","0.00410","49.70658","0.00044"
"24.80000","0.41144","498.05945","0.00411","49.80595","0.00044"
"24.90000","0.41333","500.11826","0.00413","50.01183","0.00044"
"25.00000","0.41488","501.69629","0.00415","50.16963","0.00045"
"25.10000","0.41653","503.54626","0.00417","50.35463","0.00045"
"25.20000","0.41843","505.38025","0.00418","50.53802","0.00045"
"25.30000","0.41984","506.70264","0.00420","50.67027","0.00045"
"25.40000","0.42181","508.97333","0.00422","50.89733","0.00046"
"25.50000","0.42314","510.08090","0.00423","51.00809","0.00046"
"25.60000","0.42493","511.85748","0.00425","51.18575","0.00046"
"25.70000","0.42656","513.57233","0.00427","51.35723","0.00047"
"25.80000","0.42823","515.23346","0.00428","51.52335","0.00047"
"25.90000","0.43014","517.34277","0.00430","51.73428","0.00047"
"26.00000","0.43153","518.40454","0.00432","51.84045","0.00047"
"26.10000","0.43340","520.55933","0.00433","52.05593","0.00048"
"26.20000","0.43488","521.94995","0.00435","52.19500","0.00048"
"26.30000","0.43661","523.69269","0.00437","52.36927","0.00048"
"26.40000","0.43830","525.39984","0.00438","52.53999","0.00049"
"26.50000","0.43984","526.76306","0.00440","52.67631","0.00049"
"26.60000","0.44177","528.91235","0.00442","52.89124","0.00050"
"26.70000","0.44326","530.16937","0.00443","53.01694","0.00050"
"26.80000","0.44501","531.79291","0.00445","53.17929","0.00050"
"26.90000","0.44656","533.38434","0.00447","53.33843","0.00050"
"27.00000","0.44819","534.98663","0.00448","53.49866","0.00051"
"27.10000","0.45002","536.81976","0.00450","53.68198","0.00051"
"27.20000","0.45154","538.24713","0.00452","53.82471","0.00051"
"27.30000","0.45334","540.04926","0.00453","54.00492","0.00052"
"27.40000","0.45488","541.54730","0.00455","54.15473","0.00052"
"27.50000","0.45664","543.27155","0.00457","54.32716","0.00053"
"27.60000","0.45831","544.81757","0.00458","54.48176","0.00053"
"27.70000","0.45984","546.28992","0.00460","54.62899","0.00053"
"27.80000","0.46169","548.04181","0.00462","54.80418","0.00054"
"27.90000","0.46317","549.32965","0.00463","54.93296","0.00054"
"28.00000","0.46496","551.19806","0.00465","55.11980","0.00055"
"28.10000","0.46667","552.88959","0.00467","55.28896","0.00055"
"28.20000","0.46821","554.15338","0.00468","55.41534","0.00056"
"28.30000","0.46998","555.97925","0.00470","55.59792","0.00056"
"28.40000","0.47145","557.18640","0.00471","55.71864","0.00056"
"28.50000","0.47332","559.17950","0.00473","55.91795","0.00057"
"28.60000","0.47498","560.70282","0.00475","56.07028","0.00057"
"28.70000","0.47657","562.17352","0.00477","56.21735","0.00058"
"28.80000","0.47836","564.03656","0.00478","56.40366","0.00058"
"28.90000","0.47983","565.17657","0.00480","56.51766","0.00058"
"29.00000","0.48170","567.10284","0.00482","56.71029","0.00059"
"29.10000","0.48318","568.45441","0.00483","56.84544","0.00059"
"29.20000","0.48496","570.11212","0.00485","57.01121","0.00059"
"29.30000","0.48668","571.87384","0.00487","57.18739","0.00060"
"29.40000","0.48821","573.10675","0.00488","57.31068","0.00060"
"29.50000","0.49013","575.07721","0.00490","57.50772","0.00061"
"29.60000","0.49148","576.06848","0.00491","57.60685","0.00061"
"29.70000","0.49341","578.13086","0.00493","57.81309","0.00061"
"29.80000","0.49485","579.13684","0.00495","57.91368","0.00061"
"29.90000","0.49668","581.02051","0.00497","58.10205","0.00062"
"30.00000","0.49838","582.55664","0.00498","58.25566","0.00062"
"30.10000","0.49982","583.77368","0.00500","58.37737","0.00062"
"30.20000","0.50179","585.93121","0.00502","58.59312","0.00063"
"30.30000","0.50319","586.90167","0.00503","58.69017","0.00063"
"30.40000","0.50502","588.65942","0.00505","58.86594","0.00063"
"30.50000","0.50651","589.96594","0.00507","58.99659","0.00063"
"30.60000","0.50825","591.57574","0.00508","59.15757","0.00063"
"30.70000","0.51009","593.31537","0.00510","59.33154","0.00064"
"30.80000","0.51148","594.43994","0.00511","59.44399","0.00064"
"30.90000","0.51340","596.39227","0.00513","59.63923","0.00064"
"31.00000","0.51475","597.27032","0.00515","59.72703","0.00064"
"31.10000","0.51667","599.13898","0.00517","59.91390","0.00064"
"31.20000","0.51826","600.56720","0.00518","60.05672","0.00064"
"31.30000","0.51991","602.06171","0.00520","60.20617","0.00064"
"31.40000","0.52178","603.88654","0.00522","60.38865","0.00064"
"31.50000","0.52312","604.79535","0.00523","60.47953","0.00064"
"31.60000","0.52507","606.83630","0.00525","60.68363","0.00065"
"31.70000","0.52646","607.75244","0.00526","60.77525","0.00065"
"31.80000","0.52828","609.60620","0.00528","60.96062","0.00065"
"31.90000","0.52995","611.01953","0.00530","61.10195","0.00065"
"32.00000","0.53155","612.43597","0.00532","61.24360","0.00065"
"32.10000","0.53346","614.32849","0.00533","61.43285","0.00065"
"32.20000","0.53484","615.33167","0.00535","61.53316","0.00065"
"32.30000","0.53671","617.10571","0.00537","61.71057","0.00066"
"32.40000","0.53817","618.12201","0.00538","61.81220","0.00065"
"32.50000","0.53990","619.81116","0.00540","61.98112","0.00066"
"32.60000","0.54170","621.46204","0.00542","62.14620","0.00066"
"32.70000","0.54321","622.64972","0.00543","62.26497","0.00066"
"32.80000","0.54509","624.49146","0.00545","62.44915","0.00066"
"32.90000","0.54654","625.51508","0.00547","62.55151","0.00066"
"33.00000","0.54836","627.24774","0.00548","62.72477","0.00066"
"33.10000","0.54990","628.50330","0.00550","62.85033","0.00066"
"33.20000","0.55154","629.78656","0.00552","62.97866","0.00066"
"33.30000","0.55333","631.59534","0.00553","63.15953","0.00066"
"33.40000","0.55484","632.67352","0.00555","63.26735","0.00067"
"33.50000","0.55680","634.66986","0.00557","63.46699","0.00067"
"33.60000","0.55830","635.70074","0.00558","63.57008","0.00067"
"33.70000","0.55991","637.14331","0.00560","63.71433","0.00067"
"33.80000","0.56156","638.40179","0.00562","63.84018","0.00067"
"33.90000","0.56319","639.82196","0.00563","63.98220","0.00067"
"34.00000","0.56506","641.52466","0.00565","64.15247","0.00067"
"34.10000","0.56654","642.75494","0.00567","64.27550","0.00067"
"34.20000","0.56834","644.30914","0.00568","64.43092","0.00067"
"34.30000","0.56996","645.66681","0.00570","64.56668","0.00068"
"34.40000","0.57157","646.93463","0.00572","64.69347","0.00068"
"34.50000","0.57328","648.48083","0.00573","64.84808","0.00068"
"34.60000","0.57478","649.63300","0.00575","64.96330","0.00068"
"34.70000","0.57667","651.29858","0.00577","65.12986","0.00068"
"34.80000","0.57833","652.72467","0.00578","65.27247","0.00068"
"34.90000","0.57996","654.02148","0.00580","65.40215","0.00068"
"35.00000","0.58168","655.59076","0.00582","65.55907","0.00069"
"35.10000","0.58318","656.62402","0.00583","65.66240","0.00069"
"35.20000","0.58500","658.28333","0.00585","65.82833","0.00069"
"35.30000","0.58646","659.17761","0.00586","65.91776","0.00069"
"35.40000","0.58830","660.89874","0.00588","66.08987","0.00069"
"35.50000","0.59001","662.39807","0.00590","66.23981","0.00069"
"35.60000","0.59153","663.40997","0.00592","66.34100","0.00070"
"35.70000","0.59343","665.17761","0.00593","66.51776","0.00070"
"35.80000","0.59479","666.10382","0.00595","66.61038","0.00070"
"35.90000","0.59667","667.81458","0.00597","66.78146","0.00070"
"36.00000","0.59813","668.95782","0.00598","66.89578","0.00070"
"36.10000","0.59993","670.46082","0.00600","67.04608","0.00071"
"36.20000","0.60178","672.17517","0.00602","67.21751","0.00071"
"36.30000","0.60315","672.96753","0.00603","67.29675","0.00071"
"36.40000","0.60513","674.86353","0.00605","67.48635","0.00071"
"36.50000","0.60646","675.73639","0.00606","67.57364","0.00071"
"36.60000","0.60833","677.38977","0.00608","67.73898","0.00072"
"36.70000","0.60991","678.69769","0.00610","67.86977","0.00072"
"36.80000","0.61159","679.99084","0.00612","67.99908","0.00072"
"36.90000","0.61347","681.67249","0.00613","68.16725","0.00073"
"37.00000","0.61478","682.39972","0.00615","68.23997","0.00073"
"37.10000","0.61690","684.56976","0.00617","68.45698","0.00074"
"37.20000","0.61819","685.27197","0.00618","68.52720","0.00074"
"37.30000","0.61995","686.80786","0.00620","68.68079","0.00074"
"37.40000","0.62156","688.05695","0.00622","68.80569","0.00074"
"37.50000","0.62324","689.44977","0.00623","68.94498","0.00075"
"37.60000","0.62519","691.17987","0.00625","69.11799","0.00075"
"37.70000","0.62645","691.84119","0.00626","69.18412","0.00075"
"37.80000","0.62847","693.78064","0.00628","69.37807","0.00076"
"37.90000","0.62983","694.63037","0.00630","69.46304","0.00076"
"38.00000","0.63161","695.99731","0.00632","69.59973","0.00076"
"38.10000","0.63324","697.36243","0.00633","69.73624","0.00077"
"38.20000","0.63484","698.63397","0.00635","69.86340","0.00077"
"38.30000","0.63680","700.39502","0.00637","70.03951","0.00078"
"38.40000","0.63815","701.24615","0.00638","70.12462","0.00078"
"38.50000","0.64011","702.93958","0.00640","70.29396","0.00078"
"38.60000","0.64152","703.99524","0.00642","70.39952","0.00078"
"38.70000","0.64319","705.15808","0.00643","70.51581","0.00079"
"38.80000","0.64491","706.66418","0.00645","70.66642","0.00079"
"38.90000","0.64653","707.88733","0.00647","70.78873","0.00079"
"39.00000","0.64844","709.61060","0.00648","70.96106","0.00080"
"39.10000","0.64986","710.53577","0.00650","71.05357","0.00080"
"39.20000","0.65167","712.09637","0.00652","71.20964","0.00080"
"39.30000","0.65323","713.15576","0.00653","71.31557","0.00080"
"39.40000","0.65483","714.34418","0.00655","71.43442","0.00081"
"39.50000","0.65661","715.91547","0.00657","71.59155","0.00081"
"39.60000","0.65821","717.03967","0.00658","71.70396","0.00081"
"39.70000","0.66002","718.72211","0.00660","71.87221","0.00082"
"39.80000","0.66165","719.83105","0.00662","71.98311","0.00082"
"39.90000","0.66328","721.15833","0.00663","72.11583","0.00082"
"40.00000","0.66498","722.40259","0.00665","72.24026","0.00083"
"40.10000","0.66648","723.31927","0.00666","72.33192","0.00083"
"40.20000","0.66832","725.01471","0.00668","72.50147","0.00083"
"40.30000","0.66996","726.12579","0.00670","72.61258","0.00084"
"40.40000","0.67167","727.49927","0.00672","72.74992","0.00084"
"40.50000","0.67338","728.91302","0.00673","72.89130","0.00084"
"40.60000","0.67485","729.70892","0.00675","72.97089","0.00085"
"40.70000","0.67675","731.38074","0.00677","73.13808","0.00085"
"40.80000","0.67818","732.20740","0.00678","73.22074","0.00085"
"40.90000","0.67995","733.82825","0.00680","73.38283","0.00085"
"41.00000","0.68160","735.02014","0.00682","73.50201","0.00086"
"41.10000","0.68327","736.25470","0.00683","73.62547","0.00086"
"41.20000","0.68515","737.90466","0.00685","73.79047","0.00086"
"41.30000","0.68647","738.60468","0.00686","73.86047","0.00087"
"41.40000","0.68836","740.18671","0.00688","74.01867","0.00087"
"41.50000","0.68979","741.02771","0.00690","74.10277","0.00087"
"41.60000","0.69166","742.64606","0.00692","74.26460","0.00087"
"41.70000","0.69331","743.92761","0.00693","74.39276","0.00088"
"41.80000","0.69483","744.94623","0.00695","74.49462","0.00088"
"41.90000","0.69676","746.56799","0.00697","74.65680","0.00088"
"42.00000","0.69814","747.38684","0.00698","74.73869","0.00088"
"42.10000","0.70009","748.88959","0.00700","74.88896","0.00089"
"42.20000","0.70150","749.85742","0.00702","74.98574","0.00089"
"42.30000","0.70325","751.23096","0.00703","75.12309","0.00089"
"42.40000","0.70499","752.58569","0.00705","75.25857","0.00089"
"42.50000","0.70648","753.41321","0.00706","75.34132","0.00089"
"42.60000","0.70849","755.15869","0.00708","75.51587","0.00090"
"42.70000","0.70978","755.91107","0.00710","75.59111","0.00090"
"42.80000","0.71168","757.47980","0.00712","75.74798","0.00090"
"42.90000","0.71321","758.54163","0.00713","75.85416","0.00090"
"43.00000","0.71493","759.71820","0.00715","75.97182","0.00091"
"43.10000","0.71676","761.25500","0.00717","76.12550","0.00091"
"43.20000","0.71815","761.94843","0.00718","76.19484","0.00091"
"43.30000","0.72010","763.60364","0.00720","76.36037","0.00092"
"43.40000","0.72148","764.30939","0.00721","76.43094","0.00092"
"43.50000","0.72332","765.82422","0.00723","76.58242","0.00092"
"43.60000","0.72491","767.00177","0.00725","76.70018","0.00092"
"43.70000","0.72658","768.28442","0.00727","76.82845","0.00093"
"43.80000","0.72845","769.77814","0.00728","76.97781","0.00093"
"43.90000","0.72985","770.51807","0.00730","77.05180","0.00093"
"44.00000","0.73176","772.11951","0.00732","77.21195","0.00093"
"44.10000","0.73317","772.82690","0.00733","77.28269","0.00094"
"44.20000","0.73492","774.20154","0.00735","77.42015","0.00094"
"44.30000","0.73665","775.46228","0.00737","77.54623","0.00094"
"44.40000","0.73825","776.66846","0.00738","77.66685","0.00094"
"44.50000","0.74008","778.07977","0.00740","77.80798","0.00095"
"44.60000","0.74149","778.80121","0.00741","77.88012","0.00095"
"44.70000","0.74341","780.39294","0.00743","78.03929","0.00095"
"44.80000","0.74491","781.25830","0.00745","78.12583","0.00095"
"44.90000","0.74655","782.46045","0.00747","78.24605","0.00096"
"45.00000","0.74828","783.78711","0.00748","78.37871","0.00096"
"45.10000","0.74986","784.71649","0.00750","78.47165","0.00096"
"45.20000","0.75176","786.25928","0.00752","78.62593","0.00097"
"45.30000","0.75321","787.10419","0.00753","78.71042","0.00097"
"45.40000","0.75496","788.38745","0.00755","78.83875","0.00097"
"45.50000","0.75655","789.38892","0.00757","78.93889","0.00097"
"45.60000","0.75817","790.55902","0.00758","79.05590","0.00097"
"45.70000","0.76005","791.92975","0.00760","79.19298","0.00097"
"45.80000","0.76158","792.88379","0.00762","79.28838","0.00098"
"45.90000","0.76336","794.12469","0.00763","79.41247","0.00098"
"46.00000","0.76488","795.09045","0.00765","79.50905","0.00098"
"46.10000","0.76658","796.36432","0.00767","79.63643","0.00098"
"46.20000","0.76827","797.45508","0.00768","79.74551","0.00098"
"46.30000","0.76983","798.40643","0.00770","79.84064","0.00098"
"46.40000","0.77166","799.80121","0.00772","79.98012","0.00099"
"46.50000","0.77327","800.76025","0.00773","80.07603","0.00099"
"46.60000","0.77499","801.95178","0.00775","80.19518","0.00099"
"46.70000","0.77664","803.14026","0.00777","80.31403","0.00099"
"46.80000","0.77819","803.95862","0.00778","80.39586","0.00099"
"46.90000","0.77996","805.27466","0.00780","80.52747","0.00099"
"47.00000","0.78149","806.21930","0.00781","80.62193","0.00099"
"47.10000","0.78334","807.71185","0.00783","80.77119","0.00100"
"47.20000","0.78494","808.59790","0.00785","80.85979","0.00100"
"47.30000","0.78661","809.69513","0.00787","80.96951","0.00100"
"47.40000","0.78838","810.97998","0.00788","81.09800","0.00100"
"47.50000","0.78986","811.81891","0.00790","81.18189","0.00100"
"47.60000","0.79170","813.18451","0.00792","81.31845","0.00100"
"47.70000","0.79316","813.94336","0.00793","81.39433","0.00100"
"47.80000","0.79496","815.21124","0.00795","81.52113","0.00101"
"47.90000","0.79669","816.47827","0.00797","81.64783","0.00101"
"48.00000","0.79829","817.46893","0.00798","81.74689","0.00101"
"48.10000","0.80010","818.78967","0.00800","81.87897","0.00101"
"48.20000","0.80144","819.30334","0.00801","81.93034","0.00101"
"48.30000","0.80338","820.83575","0.00803","82.08357","0.00101"
"48.40000","0.80488","821.71698","0.00805","82.17170","0.00101"
"48.50000","0.80665","822.89734","0.00807","82.28973","0.00101"
"48.60000","0.80837","824.09613","0.00808","82.40961","0.00101"
"48.70000","0.80985","824.80463","0.00810","82.48046","0.00101"
"48.80000","0.81178","826.52771","0.00812","82.65277","0.00102"
"48.90000","0.81313","826.81415","0.00813","82.68141","0.00102"
"49.00000","0.81500","828.39795","0.00815","82.83980","0.00102"
"49.10000","0.81653","829.15283","0.00817","82.91528","0.00102"
"49.20000","0.81826","830.20990","0.00818","83.02099","0.00102"
"49.30000","0.82013","831.63605","0.00820","83.16360","0.00102"
"49.40000","0.82148","832.17786","0.00821","83.21779","0.00101"
"49.50000","0.82344","833.77802","0.00823","83.37780","0.00101"
"49.60000","0.82478","834.24652","0.00825","83.42465","0.00101"
"49.70000","0.82661","835.53717","0.00827","83.55372","0.00101"
"49.80000","0.82824","836.51422","0.00828","83.65142","0.00101"
"49.90000","0.82989","837.51807","0.00830","83.75181","0.00100"
"50.00000","0.83179","838.87427","0.00832","83.88743","0.00100"
"50.10000","0.83314","839.53796","0.00833","83.95380","0.00100"
"50.20000","0.83511","840.96582","0.00835","84.09658","0.00100"
"50.30000","0.83649","841.62152","0.00836","84.16216","0.00100"
"50.40000","0.83822","842.67139","0.00838","84.26714","0.00100"
"50.50000","0.83993","843.79108","0.00840","84.37910","0.00100"
"50.60000","0.84155","844.72235","0.00842","84.47224","0.00099"
"50.70000","0.84350","846.16888","0.00843","84.61689","0.00100"
"50.80000","0.84484","846.73297","0.00845","84.67329","0.00099"
"50.90000","0.84673","848.17865","0.00847","84.81786","0.00099"
"51.00000","0.84818","848.79602","0.00848","84.87960","0.00099"
"51.10000","0.84989","849.90051","0.00850","84.99005","0.00099"
"51.20000","0.85168","851.13019","0.00852","85.11302","0.00099"
"51.30000","0.85325","851.90442","0.00853","85.19044","0.00099"
"51.40000","0.85508","853.14166","0.00855","85.31416","0.00099"
"51.50000","0.85654","853.80420","0.00857","85.38042","0.00099"
"51.60000","0.85841","855.24243","0.00858","85.52425","0.00099"
"51.70000","0.85993","855.93860","0.00860","85.59386","0.00099"
"51.80000","0.86146","856.55713","0.00861","85.65572","0.00099"
"51.90000","0.86333","857.91626","0.00863","85.79163","0.00099"
"52.00000","0.86493","858.79742","0.00865","85.87975","0.00099"
"52.10000","0.86670","859.98297","0.00867","85.99830","0.00099"
"52.20000","0.86822","860.63062","0.00868","86.06306","0.00099"
"52.30000","0.86993","861.60852","0.00870","86.16085","0.00100"
"52.40000","0.87162","862.80371","0.00872","86.28037","0.00100"
"52.50000","0.87314","863.44879","0.00873","86.34488","0.00100"
"52.60000","0.87494","864.69769","0.00875","86.46977","0.00100"
"52.70000","0.87659","865.56476","0.00877","86.55647","0.00100"
"52.80000","0.87830","866.49677","0.00878","86.64967","0.00101"
"52.90000","0.88003","867.50116","0.00880","86.75011","0.00101"
"53.00000","0.88158","868.21747","0.00882","86.82175","0.00101"
"53.10000","0.88334","869.37610","0.00883","86.93761","0.00101"
"53.20000","0.88479","869.91388","0.00885","86.99139","0.00102"
"53.30000","0.88661","870.87305","0.00887","87.08730","0.00102"
"53.40000","0.88829","871.96826","0.00888","87.19682","0.00102"
"53.50000","0.88995","872.94153","0.00890","87.29415","0.00103"
"53.60000","0.89174","873.93311","0.00892","87.39331","0.00103"
"53.70000","0.89316","874.35425","0.00893","87.43542","0.00103"
"53.80000","0.89505","875.62268","0.00895","87.56227","0.00104"
"53.90000","0.89649","875.87415","0.00896","87.58742","0.00104"
"54.00000","0.89824","876.97638","0.00898","87.69764","0.00104"
"54.10000","0.90001","877.72357","0.00900","87.77235","0.00105"
"54.20000","0.90154","877.98822","0.00902","87.79882","0.00105"
"54.30000","0.90349","879.13397","0.00903","87.91340","0.00105"
"54.40000","0.90479","879.08313","0.00905","87.90831","0.00105"
"54.50000","0.90667","879.82489","0.00907","87.98249","0.00105"
"54.60000","0.90815","878.83734","0.00908","87.88374","0.00105"
"54.70000","0.90995","879.54382","0.00910","87.95438","0.00105"
"54.80000","0.91176","880.09247","0.00912","88.00925","0.00105"
"54.90000","0.91319","880.11194","0.00913","88.01119","0.00105"
"55.00000","0.91515","880.95282","0.00915","88.09528","0.00106"
"55.10000","0.91645","880.68463","0.00916","88.06847","0.00105"
"55.20000","0.91840","880.53857","0.00918","88.05386","0.00105"
"55.30000","0.91989","879.96124","0.00920","87.99612","0.00105"
"55.40000","0.92154","879.79462","0.00922","87.97946","0.00105"
"55.45500","0.92251","752.58459","0.00923","75.25846","0.00010"
"55.47600","0.92298","624.21185","0.00923","62.42118","-0.00084"
"55.57600","0.92451","521.96710","0.00925","52.19671","-0.00156"
"55.67600","0.92649","488.09732","0.00926","48.80973","-0.00178"
"55.77600","0.92772","478.69351","0.00928","47.86935","-0.00185"
"55.87600","0.92963","471.89746","0.00930","47.18975","-0.00189"
"55.97600","0.93109","466.04086","0.00931","46.60409","-0.00194"
"56.07600","0.93289","464.32483","0.00933","46.43248","-0.00195"
"56.17600","0.93465","463.27332","0.00935","46.32733","-0.00197"
"56.27600","0.93610","461.96744","0.00936","46.19674","-0.00198"
"56.37600","0.93807","461.74918","0.00938","46.17492","-0.00198"
"56.47600","0.93941","460.64020","0.00939","46.06402","-0.00199"
"56.57600","0.94130","460.34946","0.00941","46.03495","-0.00200"
"56.67600","0.94282","459.81622","0.00943","45.98162","-0.00201"
"56.77600","0.94450","459.54022","0.00945","45.95402","-0.00201"
"56.87600","0.94630","459.61002","0.00946","45.96100","-0.00202"
"56.97600","0.94771","459.20996","0.00948","45.92100","-0.00202"
"57.07600","0.94975","459.39832","0.00950","45.93983","-0.00202"
"57.17600","0.95103","458.84244","0.00951","45.88424","-0.00203"
"57.27600","0.95293","459.25174","0.00953","45.92517","-0.00203"
"57.37600","0.95452","459.25031","0.00955","45.92503","-0.00203"
"57.47600","0.95614","459.19974","0.00956","45.91998","-0.00203"
"57.57600","0.95803","459.50107","0.00958","45.95011","-0.00203"
"57.67600","0.95940","459.15433","0.00959","45.91543","-0.00204"
"57.77600","0.96136","459.66022","0.00961","45.96602","-0.00204"
"57.87600","0.96277","459.41483","0.00963","45.94148","-0.00204"
"57.97600","0.96456","459.67636","0.00965","45.96764","-0.00205"
"58.07600","0.96622","459.67758","0.00966","45.96776","-0.00206"
"58.17600","0.96780","459.47894","0.00968","45.94790","-0.00205"
"58.27600","0.96972","456.96823","0.00970","45.69682","-0.00208"
"58.37600","0.97115","455.54312","0.00971","45.55431","-0.00208"
"58.47600","0.97297","455.53860","0.00973","45.55386","-0.00207"
"58.57600","0.97448","455.03796","0.00974","45.50380","-0.00209"
"58.67600","0.97614","454.85516","0.00976","45.48552","-0.00209"
"58.77600","0.97797","455.05310","0.00978","45.50531","-0.00209"
"58.87600","0.97953","455.09845","0.00980","45.50985","-0.00209"
"58.97500","0.98128","455.49487","0.00981","45.54949","-0.00208"