File: Tension/Section_2_Group_4/f11a_1.is_tens_RawData/Specimen_RawData_1.csv
Time,Extension,Load,Tensile strain (Extension),Tensile stress,Strain-by-clip-gage
(s),(mm),(N),(mm/mm),(MPa),(mm/mm)
"0.00000","0.00000","7.13018","0.00000","0.71302","0.00001"
"0.10000","0.00059","10.49816","0.00001","1.04982","-0.00001"
"0.20000","0.00258","24.85055","0.00003","2.48506","0.00001"
"0.30000","0.00750","60.96172","0.00008","6.09617","-0.00002"
"0.40000","0.01082","84.42452","0.00011","8.44245","0.00003"
"0.50000","0.01418","107.57475","0.00014","10.75747","-0.00002"
"0.60000","0.01747","129.59637","0.00017","12.95964","0.00001"
"0.70000","0.02090","151.95082","0.00021","15.19508","-0.00001"
"0.80000","0.02420","172.83385","0.00024","17.28338","0.00000"
"0.90000","0.02763","193.81566","0.00028","19.38157","0.00001"
"1.00000","0.03096","213.63535","0.00031","21.36353","-0.00001"
"1.10000","0.03417","232.13606","0.00034","23.21361","0.00001"
"1.20000","0.03766","251.89149","0.00038","25.18915","-0.00001"
"1.30000","0.04089","269.52521","0.00041","26.95252","0.00001"
"1.40000","0.04428","287.60837","0.00044","28.76084","0.00000"
"1.50000","0.04754","304.50827","0.00048","30.45083","0.00000"
"1.60000","0.05090","321.79947","0.00051","32.17995","-0.00001"
"1.70000","0.05419","338.43707","0.00054","33.84371","-0.00001"
"1.80000","0.05749","355.16223","0.00057","35.51622","0.00000"
"1.90000","0.06099","372.92053","0.00061","37.29205","0.00000"
"2.00000","0.06427","389.06598","0.00064","38.90660","0.00000"
"2.10000","0.06754","405.22089","0.00068","40.52209","-0.00001"
"2.20000","0.07088","421.50613","0.00071","42.15061","0.00000"
"2.30000","0.07423","437.58801","0.00074","43.75880","0.00000"
"2.40000","0.07746","452.91214","0.00077","45.29121","0.00000"
"2.50000","0.08081","469.01865","0.00081","46.90186","0.00000"
"2.60000","0.08434","486.15268","0.00084","48.61527","0.00000"
"2.70000","0.08770","501.94916","0.00088","50.19492","0.00000"
"2.80000","0.09092","516.56281","0.00091","51.65628","-0.00001"
"2.90000","0.09420","531.77222","0.00094","53.17722","0.00000"
"3.00000","0.09764","547.98853","0.00098","54.79885","0.00000"
"3.10000","0.10080","562.05078","0.00101","56.20508","0.00000"
"3.20000","0.10421","578.04852","0.00104","57.80485","0.00000"
"3.30000","0.10764","593.89819","0.00108","59.38982","0.00000"
"3.40000","0.11100","608.93585","0.00111","60.89359","0.00000"
"3.50000","0.11412","622.23944","0.00114","62.22395","0.00000"
"3.60000","0.11758","637.98425","0.00118","63.79842","0.00000"
"3.70000","0.12091","652.12988","0.00121","65.21299","0.00000"
"3.80000","0.12416","666.03479","0.00124","66.60348","0.00000"
"3.90000","0.12755","680.86639","0.00128","68.08664","0.00000"
"4.00000","0.13096","695.34125","0.00131","69.53413","0.00000"
"4.10000","0.13429","709.55267","0.00134","70.95527","0.00000"
"4.20000","0.13739","721.74713","0.00137","72.17471","0.00000"
"4.30000","0.14098","737.82129","0.00141","73.78213","0.00000"
"4.40000","0.14427","751.25000","0.00144","75.12500","0.00000"
"4.50000","0.14750","764.18768","0.00147","76.41877","0.00000"
"4.60000","0.15094","778.75525","0.00151","77.87553","0.00000"
"4.70000","0.15422","791.84564","0.00154","79.18456","0.00000"
"4.80000","0.15768","806.29968","0.00158","80.62997","0.00000"
"4.90000","0.16073","817.84210","0.00161","81.78421","0.00000"
"5.00000","0.16438","833.39105","0.00164","83.33910","-0.00001"
"5.10000","0.16766","846.13141","0.00168","84.61314","0.00000"
"5.20000","0.17089","858.48810","0.00171","85.84881","0.00000"
"5.30000","0.17416","871.16736","0.00174","87.11674","0.00000"
"5.40000","0.17751","884.16180","0.00178","88.41618","0.00000"
"5.50000","0.18090","897.21930","0.00181","89.72193","0.00000"
"5.60000","0.18407","909.01349","0.00184","90.90135","0.00000"
"5.70000","0.18764","923.48578","0.00188","92.34858","0.00000"
"5.80000","0.19102","936.06097","0.00191","93.60609","0.00000"
"5.90000","0.19420","947.56635","0.00194","94.75664","0.00000"
"6.00000","0.19748","959.59680","0.00197","95.95968","0.00000"
"6.10000","0.20089","972.37555","0.00201","97.23756","0.00000"
"6.20000","0.20420","984.42072","0.00204","98.44207","0.00000"
"6.30000","0.20747","996.24878","0.00207","99.62488","0.00000"
"6.40000","0.21101","1009.72437","0.00211","100.97243","0.00000"
"6.50000","0.21432","1021.27008","0.00214","102.12701","0.00000"
"6.60000","0.21757","1032.52612","0.00218","103.25261","0.00000"
"6.70000","0.22086","1043.91394","0.00221","104.39140","0.00000"
"6.80000","0.22430","1056.11853","0.00224","105.61185","0.00000"
"6.90000","0.22751","1066.47803","0.00228","106.64780","0.00000"
"7.00000","0.23087","1078.23169","0.00231","107.82317","0.00000"
"7.10000","0.23425","1089.69250","0.00234","108.96925","0.00000"
"7.20000","0.23762","1100.94763","0.00238","110.09476","0.00000"
"7.30000","0.24082","1111.06628","0.00241","111.10663","0.00000"
"7.40000","0.24418","1122.21826","0.00244","112.22182","0.00000"
"7.50000","0.24757","1133.54590","0.00248","113.35459","0.00000"
"7.60000","0.25087","1143.99646","0.00251","114.39964","0.00000"
"7.70000","0.25422","1154.82300","0.00254","115.48230","0.00000"
"7.80000","0.25754","1164.98584","0.00258","116.49858","0.00000"
"7.90000","0.26089","1175.39758","0.00261","117.53976","0.00000"
"8.00000","0.26420","1185.42322","0.00264","118.54232","-0.00001"
"8.10000","0.26767","1196.56421","0.00268","119.65642","0.00000"
"8.20000","0.27103","1206.56543","0.00271","120.65654","0.00000"
"8.30000","0.27422","1215.40295","0.00274","121.54030","0.00000"
"8.40000","0.27762","1225.60400","0.00278","122.56040","0.00000"
"8.50000","0.28085","1234.26685","0.00281","123.42668","0.00000"
"8.60000","0.28422","1244.18665","0.00284","124.41866","0.00000"
"8.70000","0.28748","1253.20630","0.00287","125.32063","0.00000"
"8.80000","0.29100","1263.98413","0.00291","126.39841","0.00000"
"8.90000","0.29430","1272.81543","0.00294","127.28154","0.00000"
"9.00000","0.29751","1281.03210","0.00298","128.10321","0.00000"
"9.10000","0.30095","1290.88159","0.00301","129.08817","0.00000"
"9.20000","0.30419","1298.76208","0.00304","129.87621","0.00001"
"9.30000","0.30748","1307.29028","0.00307","130.72903","0.00000"
"9.40000","0.31085","1316.37244","0.00311","131.63724","0.00000"
"9.50000","0.31431","1325.82361","0.00314","132.58237","-0.00001"
"9.60000","0.31760","1333.93933","0.00318","133.39394","0.00000"
"9.70000","0.32084","1341.73877","0.00321","134.17387","0.00000"
"9.80000","0.32424","1350.56689","0.00324","135.05669","0.00000"
"9.90000","0.32759","1358.69043","0.00328","135.86905","0.00000"
"10.00000","0.33089","1366.53162","0.00331","136.65317","-0.00001"
"10.10000","0.33422","1374.69250","0.00334","137.46925","0.00000"
"10.20000","0.33771","1383.45447","0.00338","138.34544","0.00000"
"10.30000","0.34089","1390.08447","0.00341","139.00845","0.00000"
"10.40000","0.34416","1397.28650","0.00344","139.72865","0.00000"
"10.50000","0.34760","1405.42932","0.00348","140.54294","0.00000"
"10.60000","0.35093","1412.83191","0.00351","141.28319","0.00000"
"10.70000","0.35417","1419.45691","0.00354","141.94569","0.00000"
"10.80000","0.35755","1427.04871","0.00358","142.70486","0.00000"
"10.90000","0.36093","1434.24133","0.00361","143.42413","0.00000"
"11.00000","0.36418","1440.74219","0.00364","144.07422","0.00000"
"11.10000","0.36742","1447.27429","0.00367","144.72743","-0.00001"
"11.20000","0.37099","1455.73596","0.00371","145.57359","0.00001"
"11.30000","0.37432","1462.48999","0.00374","146.24899","-0.00001"
"11.40000","0.37751","1468.27759","0.00378","146.82776","0.00000"
"11.50000","0.38089","1475.42322","0.00381","147.54233","0.00000"
"11.60000","0.38422","1481.78064","0.00384","148.17807","-0.00001"
"11.70000","0.38752","1488.10364","0.00388","148.81036","0.00000"
"11.80000","0.39089","1495.12476","0.00391","149.51248","-0.00001"
"11.90000","0.39435","1502.35217","0.00394","150.23521","0.00001"
"12.00000","0.39778","1509.50208","0.00398","150.95021","0.00000"
"12.10000","0.40085","1513.96362","0.00401","151.39636","0.00000"
"12.20000","0.40424","1521.12622","0.00404","152.11263","0.00000"
"12.30000","0.40755","1527.06982","0.00408","152.70699","-0.00001"
"12.40000","0.41086","1533.13123","0.00411","153.31313","0.00000"
"12.50000","0.41417","1539.36572","0.00414","153.93657","0.00000"
"12.60000","0.41766","1546.58020","0.00418","154.65802","0.00000"
"12.70000","0.42102","1552.96570","0.00421","155.29657","0.00000"
"12.80000","0.42412","1557.55701","0.00424","155.75571","0.00000"
"12.90000","0.42751","1564.19128","0.00428","156.41913","0.00000"
"13.00000","0.43092","1570.69299","0.00431","157.06931","0.00000"
"13.10000","0.43421","1576.40479","0.00434","157.64047","-0.00001"
"13.20000","0.43751","1582.26416","0.00438","158.22641","0.00000"
"13.30000","0.44096","1588.80127","0.00441","158.88013","0.00000"
"13.40000","0.44430","1594.63757","0.00444","159.46376","0.00000"
"13.50000","0.44745","1599.29968","0.00447","159.92996","0.00000"
"13.60000","0.45097","1606.55469","0.00451","160.65547","-0.00001"
"13.70000","0.45434","1612.77283","0.00454","161.27728","0.00000"
"13.80000","0.45762","1618.04468","0.00458","161.80447","0.00000"
"13.90000","0.46088","1623.43213","0.00461","162.34322","0.00000"
"14.00000","0.46423","1629.22607","0.00464","162.92261","0.00000"
"14.10000","0.46756","1634.75439","0.00468","163.47543","0.00000"
"14.20000","0.47081","1640.18884","0.00471","164.01889","0.00001"
"14.30000","0.47425","1646.83105","0.00474","164.68311","-0.00001"
"14.40000","0.47764","1652.89624","0.00478","165.28963","0.00000"
"14.50000","0.48090","1657.94080","0.00481","165.79408","0.00000"
"14.60000","0.48419","1663.28125","0.00484","166.32812","-0.00001"
"14.70000","0.48749","1668.71021","0.00487","166.87102","0.00000"
"14.80000","0.49084","1674.25500","0.00491","167.42551","0.00000"
"14.90000","0.49414","1679.75647","0.00494","167.97565","0.00000"
"15.00000","0.49766","1686.49744","0.00498","168.64975","0.00000"
"15.10000","0.50099","1691.72791","0.00501","169.17279","0.00000"
"15.20000","0.50420","1696.13550","0.00504","169.61356","0.00000"
"15.30000","0.50758","1701.78394","0.00508","170.17839","0.00000"
"15.40000","0.51089","1706.62622","0.00511","170.66263","0.00000"
"15.50000","0.51420","1711.91931","0.00514","171.19193","0.00000"
"15.60000","0.51759","1717.91614","0.00518","171.79161","-0.00001"
"15.70000","0.52098","1723.29138","0.00521","172.32913","0.00000"
"15.80000","0.52433","1728.76831","0.00524","172.87683","0.00000"
"15.90000","0.52752","1733.14868","0.00528","173.31487","0.00000"
"16.00000","0.53090","1738.92212","0.00531","173.89221","0.00000"
"16.10000","0.53423","1744.24353","0.00534","174.42435","-0.00001"
"16.20000","0.53752","1749.34766","0.00538","174.93477","0.00000"
"16.30000","0.54092","1755.64368","0.00541","175.56436","0.00000"
"16.40000","0.54428","1761.12561","0.00544","176.11256","0.00000"
"16.50000","0.54755","1766.25757","0.00548","176.62576","0.00001"
"16.60000","0.55080","1771.57654","0.00551","177.15765","-0.00001"
"16.70000","0.55421","1778.17358","0.00554","177.81735","0.00000"
"16.80000","0.55760","1784.26318","0.00558","178.42632","0.00000"
"16.90000","0.56083","1789.54822","0.00561","178.95482","-0.00001"
"17.00000","0.56426","1796.38452","0.00564","179.63846","0.00000"
"17.10000","0.56761","1802.11975","0.00568","180.21198","0.00000"
"17.20000","0.57090","1807.95813","0.00571","180.79581","0.00001"
"17.30000","0.57418","1813.59558","0.00574","181.35956","0.00000"
"17.40000","0.57765","1820.66406","0.00578","182.06641","0.00000"
"17.50000","0.58104","1826.90588","0.00581","182.69058","0.00000"
"17.60000","0.58420","1832.17639","0.00584","183.21764","0.00000"
"17.70000","0.58760","1838.98694","0.00588","183.89870","0.00000"
"17.80000","0.59089","1844.77197","0.00591","184.47720","0.00000"
"17.90000","0.59416","1850.44702","0.00594","185.04471","-0.00001"
"18.00000","0.59743","1856.60889","0.00597","185.66089","0.00000"
"18.10000","0.60102","1864.56909","0.00601","186.45691","0.00000"
"18.20000","0.60432","1870.54309","0.00604","187.05431","0.00000"
"18.30000","0.60745","1875.52930","0.00607","187.55293","0.00000"
"18.40000","0.61091","1882.74780","0.00611","188.27478","0.00000"
"18.50000","0.61414","1888.02112","0.00614","188.80211","0.00000"
"18.60000","0.61755","1894.50085","0.00618","189.45009","0.00000"
"18.70000","0.62079","1900.35828","0.00621","190.03583","0.00000"
"18.80000","0.62440","1908.12537","0.00624","190.81253","0.00000"
"18.90000","0.62770","1913.79504","0.00628","191.37950","-0.00001"
"19.00000","0.63083","1918.64282","0.00631","191.86429","0.00000"
"19.10000","0.63428","1925.57849","0.00634","192.55785","0.00000"
"19.20000","0.63754","1931.06921","0.00638","193.10692","0.00000"
"19.30000","0.64090","1937.19080","0.00641","193.71909","0.00000"
"19.40000","0.64420","1943.22546","0.00644","194.32254","0.00000"
"19.50000","0.64765","1949.74023","0.00648","194.97403","0.00001"
"19.60000","0.65096","1955.52429","0.00651","195.55243","-0.00001"
"19.70000","0.65413","1960.07080","0.00654","196.00708","0.00000"
"19.80000","0.65759","1966.94055","0.00658","196.69406","0.00000"
"19.90000","0.66099","1972.86511","0.00661","197.28651","0.00000"
"20.00000","0.66424","1977.79028","0.00664","197.77902","0.00000"
"20.10000","0.66752","1983.22498","0.00668","198.32249","0.00000"
"20.20000","0.67095","1989.56787","0.00671","198.95679","0.00000"
"20.30000","0.67416","1994.16504","0.00674","199.41650","0.00000"
"20.40000","0.67743","1999.78870","0.00677","199.97887","-0.00001"
"20.50000","0.68093","2006.92310","0.00681","200.69231","0.00001"
"20.60000","0.68437","2013.45886","0.00684","201.34589","0.00000"
"20.70000","0.68755","2018.01843","0.00688","201.80185","0.00000"
"20.80000","0.69091","2024.22534","0.00691","202.42253","0.00000"
"20.90000","0.69427","2030.08069","0.00694","203.00807","-0.00001"
"21.00000","0.69754","2035.47888","0.00698","203.54788","0.00000"
"21.10000","0.70087","2041.43933","0.00701","204.14394","0.00000"
"21.20000","0.70429","2048.12280","0.00704","204.81229","0.00000"
"21.30000","0.70775","2054.59473","0.00708","205.45947","0.00001"
"21.40000","0.71086","2059.10645","0.00711","205.91064","-0.00001"
"21.50000","0.71422","2065.51172","0.00714","206.55118","0.00000"
"21.60000","0.71751","2071.14746","0.00718","207.11475","0.00000"
"21.70000","0.72084","2077.11377","0.00721","207.71138","0.00000"
"21.80000","0.72419","2083.44824","0.00724","208.34482","0.00001"
"21.90000","0.72756","2089.81958","0.00728","208.98196","0.00000"
"22.00000","0.73099","2096.63306","0.00731","209.66330","0.00000"
"22.10000","0.73417","2101.65454","0.00734","210.16545","0.00000"
"22.20000","0.73760","2108.58887","0.00738","210.85889","0.00000"
"22.30000","0.74088","2114.25098","0.00741","211.42509","0.00000"
"22.40000","0.74422","2120.36768","0.00744","212.03677","0.00000"
"22.50000","0.74756","2126.85864","0.00748","212.68587","0.00000"
"22.60000","0.75095","2133.18701","0.00751","213.31870","0.00000"
"22.70000","0.75429","2139.23022","0.00754","213.92302","0.00000"
"22.80000","0.75747","2144.59863","0.00757","214.45987","0.00001"
"22.90000","0.76101","2152.20557","0.00761","215.22055","-0.00001"
"23.00000","0.76427","2158.01685","0.00764","215.80168","0.00000"
"23.10000","0.76757","2164.14722","0.00768","216.41472","0.00000"
"23.20000","0.77090","2170.60718","0.00771","217.06071","-0.00001"
"23.30000","0.77422","2176.81323","0.00774","217.68132","0.00001"
"23.40000","0.77751","2182.83545","0.00778","218.28354","0.00000"
"23.50000","0.78084","2189.20874","0.00781","218.92087","0.00000"
"23.60000","0.78433","2196.51685","0.00784","219.65169","0.00000"
"23.70000","0.78762","2202.69312","0.00788","220.26932","0.00000"
"23.80000","0.79085","2208.38501","0.00791","220.83850","0.00001"
"23.90000","0.79419","2214.96240","0.00794","221.49625","0.00000"
"24.00000","0.79759","2221.51660","0.00798","222.15166","0.00000"
"24.10000","0.80079","2226.78809","0.00801","222.67880","0.00000"
"24.20000","0.80419","2234.08813","0.00804","223.40881","-0.00001"
"24.30000","0.80767","2241.38525","0.00808","224.13852","0.00001"
"24.40000","0.81101","2248.05396","0.00811","224.80539","0.00000"
"24.50000","0.81426","2253.79639","0.00814","225.37964","0.00000"
"24.60000","0.81754","2260.01025","0.00818","226.00102","0.00000"
"24.70000","0.82095","2266.90137","0.00821","226.69014","0.00000"
"24.80000","0.82416","2272.46753","0.00824","227.24675","0.00001"
"24.90000","0.82757","2279.83447","0.00828","227.98344","0.00000"
"25.00000","0.83095","2286.68164","0.00831","228.66817","0.00000"
"25.10000","0.83435","2293.42749","0.00834","229.34274","0.00000"
"25.20000","0.83741","2298.38721","0.00837","229.83871","0.00000"
"25.30000","0.84097","2306.53516","0.00841","230.65352","0.00000"
"25.40000","0.84424","2312.37183","0.00844","231.23718","0.00000"
"25.50000","0.84745","2318.13281","0.00847","231.81328","0.00000"
"25.60000","0.85089","2325.73901","0.00851","232.57390","0.00000"
"25.70000","0.85426","2332.40527","0.00854","233.24052","-0.00001"
"25.80000","0.85763","2339.22070","0.00858","233.92207","0.00000"
"25.90000","0.86070","2344.19507","0.00861","234.41951","0.00000"
"26.00000","0.86432","2352.90405","0.00864","235.29041","0.00000"
"26.10000","0.86764","2359.31445","0.00868","235.93144","0.00000"
"26.20000","0.87083","2364.87549","0.00871","236.48755","0.00000"
"26.30000","0.87428","2372.39014","0.00874","237.23901","0.00000"
"26.40000","0.87754","2378.44531","0.00878","237.84453","0.00000"
"26.50000","0.88100","2385.85938","0.00881","238.58594","0.00000"
"26.60000","0.88411","2390.88403","0.00884","239.08841","0.00000"
"26.70000","0.88772","2399.57788","0.00888","239.95779","0.00000"
"26.80000","0.89101","2405.70605","0.00891","240.57060","0.00000"
"26.90000","0.89422","2411.40601","0.00894","241.14059","0.00000"
"27.00000","0.89752","2418.01392","0.00898","241.80139","0.00000"
"27.10000","0.90084","2424.31470","0.00901","242.43147","0.00000"
"27.20000","0.90421","2431.06909","0.00904","243.10690","0.00000"
"27.30000","0.90741","2437.13379","0.00907","243.71338","0.00000"
"27.40000","0.91097","2445.55615","0.00911","244.55562","0.00000"
"27.50000","0.91434","2452.21509","0.00914","245.22151","0.00000"
"27.60000","0.91751","2457.83350","0.00918","245.78336","0.00001"
"27.70000","0.92084","2464.70972","0.00921","246.47098","0.00000"
"27.80000","0.92425","2471.83569","0.00924","247.18356","0.00000"
"27.90000","0.92754","2477.94043","0.00928","247.79404","0.00000"
"28.00000","0.93084","2484.39893","0.00931","248.43990","0.00000"
"28.10000","0.93437","2492.34985","0.00934","249.23499","0.00001"
"28.20000","0.93767","2498.58521","0.00938","249.85852","0.00000"
"28.30000","0.94091","2504.51855","0.00941","250.45186","0.00000"
"28.40000","0.94422","2511.33667","0.00944","251.13367","0.00000"
"28.50000","0.94769","2518.85083","0.00948","251.88509","0.00000"
"28.60000","0.95084","2524.24536","0.00951","252.42453","0.00001"
"28.70000","0.95420","2531.51367","0.00954","253.15137","0.00000"
"28.80000","0.95753","2538.02612","0.00958","253.80261","0.00000"
"28.90000","0.96095","2545.25903","0.00961","254.52591","0.00000"
"29.00000","0.96418","2551.18579","0.00964","255.11858","0.00000"
"29.10000","0.96753","2558.09424","0.00968","255.80942","0.00001"
"29.20000","0.97096","2565.55835","0.00971","256.55585","0.00000"
"29.30000","0.97420","2571.32495","0.00974","257.13251","0.00000"
"29.40000","0.97757","2578.37598","0.00978","257.83759","0.00000"
"29.50000","0.98089","2584.90063","0.00981","258.49005","-0.00001"
"29.60000","0.98422","2591.67114","0.00984","259.16711","0.00000"
"29.70000","0.98751","2598.19507","0.00988","259.81952","0.00000"
"29.80000","0.99101","2605.77588","0.00991","260.57758","0.00000"
"29.90000","0.99435","2612.51929","0.00994","261.25192","0.00000"
"30.00000","0.99754","2618.29614","0.00998","261.82962","0.00000"
"30.10000","1.00096","2625.61450","0.01001","262.56146","0.00001"
"30.20000","1.00417","2631.36426","0.01004","263.13641","0.00000"
"30.30000","1.00757","2638.65527","0.01008","263.86554","0.00000"
"30.40000","1.01083","2645.02783","0.01011","264.50278","0.00000"
"30.50000","1.01433","2653.09131","0.01014","265.30914","0.00000"
"30.60000","1.01763","2659.38818","0.01018","265.93881","0.00001"
"30.70000","1.02086","2665.46045","0.01021","266.54605","0.00000"
"30.80000","1.02427","2672.82739","0.01024","267.28275","0.00001"
"30.90000","1.02750","2678.62817","0.01027","267.86282","0.00000"
"31.00000","1.03082","2685.34863","0.01031","268.53485","0.00000"
"31.10000","1.03415","2692.47998","0.01034","269.24799","0.00000"
"31.20000","1.03769","2700.63208","0.01038","270.06320","0.00000"
"31.30000","1.04094","2706.76196","0.01041","270.67621","0.00000"
"31.40000","1.04413","2712.55884","0.01044","271.25589","0.00000"
"31.50000","1.04759","2720.43433","0.01048","272.04343","0.00000"
"31.60000","1.05093","2727.01318","0.01051","272.70132","0.00000"
"31.70000","1.05422","2733.51270","0.01054","273.35126","0.00000"
"31.80000","1.05757","2740.53735","0.01058","274.05374","0.00000"
"31.90000","1.06105","2748.33057","0.01061","274.83307","0.00000"
"32.00000","1.06423","2753.68701","0.01064","275.36871","0.00000"
"32.10000","1.06751","2760.25122","0.01068","276.02512","0.00000"
"32.20000","1.07094","2767.82373","0.01071","276.78238","0.00000"
"32.30000","1.07431","2774.83936","0.01074","277.48395","0.00000"
"32.40000","1.07749","2780.58398","0.01077","278.05841","0.00001"
"32.50000","1.08088","2788.01782","0.01081","278.80179","0.00000"
"32.60000","1.08427","2794.94214","0.01084","279.49420","0.00000"
"32.70000","1.08750","2801.04932","0.01087","280.10492","0.00000"
"32.80000","1.09074","2807.35596","0.01091","280.73560","0.00000"
"32.90000","1.09433","2816.07495","0.01094","281.60748","0.00000"
"33.00000","1.09765","2822.73145","0.01098","282.27313","-0.00001"
"33.10000","1.10082","2828.31348","0.01101","282.83136","0.00001"
"33.20000","1.10422","2835.76099","0.01104","283.57611","0.00000"
"33.30000","1.10757","2842.18164","0.01108","284.21817","0.00000"
"33.40000","1.11085","2848.42822","0.01111","284.84283","0.00000"
"33.50000","1.11422","2855.70410","0.01114","285.57040","0.00000"
"33.60000","1.11770","2863.37573","0.01118","286.33759","0.00000"
"33.70000","1.12110","2870.71216","0.01121","287.07123","0.00000"
"33.80000","1.12416","2875.43726","0.01124","287.54373","0.00000"
"33.90000","1.12760","2883.10400","0.01128","288.31039","0.00000"
"34.00000","1.13086","2889.23560","0.01131","288.92355","0.00000"
"34.10000","1.13417","2895.94897","0.01134","289.59491","0.00000"
"34.20000","1.13748","2902.64087","0.01137","290.26410","0.00000"
"34.30000","1.14097","2910.55225","0.01141","291.05524","-0.00001"
"34.40000","1.14436","2917.68042","0.01144","291.76804","0.00000"
"34.50000","1.14741","2922.46240","0.01147","292.24625","0.00000"
"34.60000","1.15087","2930.47510","0.01151","293.04752","0.00000"
"34.70000","1.15432","2937.67065","0.01154","293.76706","0.00000"
"34.80000","1.15754","2943.52222","0.01158","294.35223","0.00000"
"34.90000","1.16085","2950.20703","0.01161","295.02069","0.00000"
"35.00000","1.16427","2957.44434","0.01164","295.74445","0.00000"
"35.10000","1.16762","2964.25586","0.01168","296.42560","0.00000"
"35.20000","1.17078","2969.91626","0.01171","296.99164","0.00000"
"35.30000","1.17432","2978.09546","0.01174","297.80954","0.00000"
"35.40000","1.17768","2984.98193","0.01178","298.49820","0.00000"
"35.50000","1.18093","2991.10767","0.01181","299.11078","-0.00001"
"35.60000","1.18420","2997.53931","0.01184","299.75394","0.00000"
"35.70000","1.18757","3004.66235","0.01188","300.46625","0.00000"
"35.80000","1.19086","3010.89087","0.01191","301.08908","0.00000"
"35.90000","1.19413","3017.31152","0.01194","301.73114","0.00000"
"36.00000","1.19761","3025.15845","0.01198","302.51584","0.00000"
"36.10000","1.20100","3032.28931","0.01201","303.22894","0.00000"
"36.20000","1.20426","3038.31128","0.01204","303.83112","0.00000"
"36.30000","1.20754","3044.60425","0.01208","304.46042","0.00000"
"36.40000","1.21082","3051.05029","0.01211","305.10504","0.00000"
"36.50000","1.21417","3057.74927","0.01214","305.77493","0.00000"
"36.60000","1.21748","3064.50000","0.01217","306.45001","-0.00001"
"36.70000","1.22097","3072.16357","0.01221","307.21637","0.00000"
"36.80000","1.22431","3078.86475","0.01224","307.88647","0.00000"
"36.90000","1.22752","3084.87036","0.01228","308.48703","0.00000"
"37.00000","1.23093","3092.19946","0.01231","309.21994","-0.00001"
"37.10000","1.23427","3098.75854","0.01234","309.87585","0.00000"
"37.20000","1.23756","3105.04639","0.01238","310.50464","0.00000"
"37.30000","1.24093","3111.99072","0.01241","311.19907","0.00000"
"37.40000","1.24430","3118.62720","0.01244","311.86273","0.00000"
"37.50000","1.24764","3125.46265","0.01248","312.54626","0.00000"
"37.60000","1.25081","3130.88232","0.01251","313.08823","0.00000"
"37.70000","1.25422","3138.24780","0.01254","313.82477","0.00000"
"37.80000","1.25756","3144.86353","0.01258","314.48636","0.00001"
"37.90000","1.26084","3151.17798","0.01261","315.11780","0.00000"
"38.00000","1.26426","3158.44678","0.01264","315.84467","0.00000"
"38.10000","1.26758","3164.79053","0.01268","316.47906","0.00000"
"38.20000","1.27089","3171.16113","0.01271","317.11612","0.00000"
"38.30000","1.27412","3177.25269","0.01274","317.72528","0.00001"
"38.40000","1.27759","3184.84351","0.01278","318.48434","0.00000"
"38.50000","1.28096","3191.58618","0.01281","319.15863","0.00000"
"38.60000","1.28418","3197.43457","0.01284","319.74347","0.00000"
"38.70000","1.28761","3204.65381","0.01288","320.46539","0.00000"
"38.80000","1.29095","3211.03369","0.01291","321.10336","0.00000"
"38.90000","1.29422","3217.00122","0.01294","321.70013","0.00000"
"39.00000","1.29750","3223.10669","0.01297","322.31067","0.00000"
"39.10000","1.30098","3230.82202","0.01301","323.08221","0.00000"
"39.20000","1.30438","3237.58374","0.01304","323.75836","0.00000"
"39.30000","1.30753","3243.09766","0.01308","324.30975","0.00000"
"39.40000","1.31092","3250.13745","0.01311","325.01373","0.00000"
"39.50000","1.31421","3256.31348","0.01314","325.63135","0.00000"
"39.60000","1.31749","3262.34839","0.01317","326.23483","0.00000"
"39.70000","1.32078","3268.95190","0.01321","326.89520","0.00000"
"39.80000","1.32437","3277.16992","0.01324","327.71698","0.00000"
"39.90000","1.32765","3283.11206","0.01328","328.31122","0.00000"
"40.00000","1.33079","3288.29858","0.01331","328.82986","0.00000"
"40.10000","1.33425","3295.73462","0.01334","329.57346","0.00000"
"40.20000","1.33752","3301.48706","0.01338","330.14871","0.00000"
"40.30000","1.34084","3307.63647","0.01341","330.76364","0.00000"
"40.40000","1.34415","3314.35278","0.01344","331.43527","0.00001"
"40.50000","1.34768","3321.98657","0.01348","332.19867","0.00000"
"40.60000","1.35101","3328.31372","0.01351","332.83136","0.00000"
"40.70000","1.35415","3333.50781","0.01354","333.35077","0.00000"
"40.80000","1.35763","3341.09961","0.01358","334.10995","0.00000"
"40.90000","1.36092","3347.23486","0.01361","334.72348","0.00000"
"41.00000","1.36423","3353.32568","0.01364","335.33258","0.00000"
"41.10000","1.36754","3359.97827","0.01368","335.99783","0.00000"
"41.20000","1.37096","3366.71802","0.01371","336.67181","0.00000"
"41.30000","1.37428","3372.97705","0.01374","337.29770","0.00000"
"41.40000","1.37745","3378.22705","0.01377","337.82269","0.00000"
"41.50000","1.38094","3385.78003","0.01381","338.57800","0.00000"
"41.60000","1.38434","3392.35400","0.01384","339.23541","0.00000"
"41.70000","1.38753","3397.40747","0.01388","339.74075","0.00000"
"41.80000","1.39082","3403.87671","0.01391","340.38766","0.00000"
"41.90000","1.39427","3410.99609","0.01394","341.09961","0.00000"
"42.00000","1.39748","3416.39600","0.01397","341.63959","0.00000"
"42.10000","1.40079","3422.58960","0.01401","342.25897","0.00000"
"42.20000","1.40425","3429.90186","0.01404","342.99017","0.00000"
"42.30000","1.40773","3437.29590","0.01408","343.72958","0.00000"
"42.40000","1.41089","3442.27173","0.01411","344.22717","0.00000"
"42.50000","1.41424","3448.93213","0.01414","344.89322","0.00000"
"42.60000","1.41761","3455.28101","0.01418","345.52811","0.00000"
"42.70000","1.42087","3460.83423","0.01421","346.08344","0.00000"
"42.80000","1.42421","3467.27563","0.01424","346.72757","0.00000"
"42.90000","1.42767","3474.50122","0.01428","347.45013","0.00000"
"43.00000","1.43107","3481.12695","0.01431","348.11270","0.00000"
"43.10000","1.43416","3485.64160","0.01434","348.56415","0.00000"
"43.20000","1.43755","3492.53418","0.01438","349.25342","0.00000"
"43.30000","1.44082","3498.41479","0.01441","349.84149","0.00000"
"43.40000","1.44421","3504.94238","0.01444","350.49423","0.00000"
"43.50000","1.44753","3511.31641","0.01448","351.13165","0.00000"
"43.60000","1.45088","3517.61279","0.01451","351.76129","0.00000"
"43.70000","1.45432","3524.57910","0.01454","352.45792","0.00000"
"43.80000","1.45746","3529.63257","0.01457","352.96326","0.00000"
"43.90000","1.46094","3536.88232","0.01461","353.68823","0.00000"
"44.00000","1.46424","3542.88525","0.01464","354.28851","0.00000"
"44.10000","1.46754","3548.64087","0.01468","354.86407","0.00000"
"44.20000","1.47094","3555.37646","0.01471","355.53766","0.00000"
"44.30000","1.47430","3561.57227","0.01474","356.15723","0.00000"
"44.40000","1.47758","3567.39844","0.01478","356.73984","0.00000"
"44.50000","1.48082","3573.22656","0.01481","357.32266","0.00000"
"44.60000","1.48434","3580.76978","0.01484","358.07697","0.00000"
"44.70000","1.48761","3586.54883","0.01488","358.65488","0.00000"
"44.80000","1.49089","3592.43555","0.01491","359.24356","0.00000"
"44.90000","1.49420","3598.75366","0.01494","359.87537","0.00000"
"45.00000","1.49757","3605.15479","0.01498","360.51547","0.00000"
"45.10000","1.50082","3610.83740","0.01501","361.08374","0.00000"
"45.20000","1.50417","3617.28296","0.01504","361.72830","0.00000"
"45.30000","1.50771","3624.99512","0.01508","362.49951","0.00000"
"45.40000","1.51096","3630.26270","0.01511","363.02628","0.00000"
"45.50000","1.51418","3635.78906","0.01514","363.57892","0.00000"
"45.60000","1.51754","3642.27002","0.01518","364.22699","0.00000"
"45.70000","1.52089","3648.49756","0.01521","364.84976","0.00000"
"45.80000","1.52412","3654.12573","0.01524","365.41257","0.00000"
"45.90000","1.52752","3661.10571","0.01528","366.11057","0.00000"
"46.00000","1.53100","3668.04370","0.01531","366.80438","0.00000"
"46.10000","1.53433","3674.24219","0.01534","367.42422","0.00000"
"46.20000","1.53754","3679.70142","0.01538","367.97015","0.00000"
"46.30000","1.54089","3686.10962","0.01541","368.61096","0.00000"
"46.40000","1.54434","3693.06885","0.01544","369.30688","0.00001"
"46.50000","1.54750","3698.03931","0.01548","369.80392","0.00000"
"46.60000","1.55092","3704.96240","0.01551","370.49625","0.00000"
"46.70000","1.55430","3711.42627","0.01554","371.14264","0.00000"
"46.80000","1.55766","3717.63745","0.01558","371.76373","0.00000"
"46.90000","1.56076","3722.37402","0.01561","372.23740","0.00000"
"47.00000","1.56429","3729.99634","0.01564","372.99963","0.00000"
"47.10000","1.56758","3735.81079","0.01568","373.58109","0.00000"
"47.20000","1.57078","3741.11084","0.01571","374.11108","0.00000"
"47.30000","1.57422","3748.24365","0.01574","374.82437","-0.00001"
"47.40000","1.57755","3754.39307","0.01578","375.43930","0.00001"
"47.50000","1.58092","3760.96777","0.01581","376.09677","0.00000"
"47.60000","1.58404","3765.87744","0.01584","376.58774","0.00000"
"47.70000","1.58768","3774.31055","0.01588","377.43106","0.00000"
"47.80000","1.59101","3780.30811","0.01591","378.03082","0.00000"
"47.90000","1.59417","3785.01855","0.01594","378.50186","0.00000"
"48.00000","1.59762","3792.11792","0.01598","379.21179","0.00000"
"48.10000","1.60086","3797.42896","0.01601","379.74289","0.00000"
"48.20000","1.60433","3804.41138","0.01604","380.44113","0.00000"
"48.30000","1.60743","3809.28320","0.01607","380.92831","0.00000"
"48.40000","1.61106","3817.56201","0.01611","381.75620","0.00000"
"48.50000","1.61434","3823.25879","0.01614","382.32587","0.00000"
"48.60000","1.61751","3828.35938","0.01618","382.83594","0.00000"
"48.70000","1.62083","3834.83911","0.01621","383.48392","0.00001"
"48.80000","1.62415","3840.88501","0.01624","384.08850","-0.00001"
"48.90000","1.62758","3847.56543","0.01628","384.75653","0.00000"
"49.00000","1.63076","3852.84766","0.01631","385.28476","0.00000"
"49.10000","1.63432","3860.79395","0.01634","386.07941","0.00000"
"49.20000","1.63768","3866.87842","0.01638","386.68784","0.00000"
"49.30000","1.64084","3872.07007","0.01641","387.20700","0.00000"
"49.40000","1.64419","3878.25513","0.01644","387.82550","0.00001"
"49.50000","1.64758","3884.55127","0.01648","388.45514","0.00000"
"49.60000","1.65088","3890.28857","0.01651","389.02887","0.00000"
"49.70000","1.65421","3896.69727","0.01654","389.66974","0.00000"
"49.80000","1.65769","3903.79761","0.01658","390.37976","0.00000"
"49.90000","1.66097","3909.35913","0.01661","390.93591","0.00001"
"50.00000","1.66420","3914.95947","0.01664","391.49594","0.00000"
"50.10000","1.66755","3921.40308","0.01668","392.14032","0.00000"
"50.20000","1.67102","3928.36768","0.01671","392.83676","0.00000"
"50.30000","1.67417","3933.05078","0.01674","393.30508","0.00000"
"50.40000","1.67754","3939.59497","0.01678","393.95950","0.00001"
"50.50000","1.68087","3945.63965","0.01681","394.56396","0.00000"
"50.60000","1.68424","3952.06201","0.01684","395.20621","0.00000"
"50.70000","1.68751","3957.60303","0.01688","395.76031","0.00000"
"50.80000","1.69092","3964.39258","0.01691","396.43927","0.00000"
"50.90000","1.69433","3970.97778","0.01694","397.09778","0.00000"
"51.00000","1.69754","3976.12329","0.01698","397.61234","0.00000"
"51.10000","1.70091","3982.52197","0.01701","398.25220","0.00000"
"51.20000","1.70417","3987.93848","0.01704","398.79385","0.00000"
"51.30000","1.70754","3994.27002","0.01708","399.42700","0.00000"
"51.40000","1.71082","4000.13916","0.01711","400.01392","0.00000"
"51.50000","1.71432","4007.47217","0.01714","400.74722","0.00000"
"51.60000","1.71772","4013.78955","0.01718","401.37897","0.00000"
"51.70000","1.72087","4018.52246","0.01721","401.85223","0.00001"
"51.80000","1.72431","4025.46143","0.01724","402.54614","0.00000"
"51.90000","1.72751","4030.36035","0.01728","403.03604","0.00000"
"52.00000","1.73089","4036.65527","0.01731","403.66553","0.00000"
"52.10000","1.73420","4042.56445","0.01734","404.25644","0.00000"
"52.20000","1.73766","4049.42212","0.01738","404.94220","0.00000"
"52.30000","1.74095","4054.79419","0.01741","405.47943","0.00000"
"52.40000","1.74418","4060.12915","0.01744","406.01291","0.00000"
"52.50000","1.74760","4066.75830","0.01748","406.67584","0.00001"
"52.60000","1.75083","4072.00610","0.01751","407.20062","0.00000"
"52.70000","1.75417","4078.15234","0.01754","407.81525","0.00000"
"52.80000","1.75750","4084.22119","0.01758","408.42212","0.00000"
"52.90000","1.76098","4091.23682","0.01761","409.12369","-0.00001"
"53.00000","1.76423","4096.42822","0.01764","409.64282","0.00000"
"53.10000","1.76746","4102.03613","0.01767","410.20361","-0.00001"
"53.20000","1.77096","4109.07324","0.01771","410.90732","0.00000"
"53.30000","1.77434","4115.26855","0.01774","411.52686","0.00000"
"53.40000","1.77758","4120.34521","0.01778","412.03452","0.00000"
"53.50000","1.78090","4126.26562","0.01781","412.62656","0.00001"
"53.60000","1.78434","4132.55371","0.01784","413.25537","0.00000"
"53.70000","1.78753","4137.44092","0.01788","413.74408","0.00001"
"53.80000","1.79082","4143.35303","0.01791","414.33530","0.00000"
"53.90000","1.79428","4150.27930","0.01794","415.02792","0.00000"
"54.00000","1.79767","4156.65771","0.01798","415.66577","0.00001"
"54.10000","1.80082","4161.21582","0.01801","416.12158","0.00000"
"54.20000","1.80423","4167.92773","0.01804","416.79279","0.00001"
"54.30000","1.80759","4173.48926","0.01808","417.34894","0.00000"
"54.40000","1.81083","4178.75146","0.01811","417.87515","0.00000"
"54.50000","1.81412","4184.72266","0.01814","418.47226","0.00000"
"54.60000","1.81767","4191.93018","0.01818","419.19302","-0.00001"
"54.70000","1.82100","4198.06445","0.01821","419.80646","0.00000"
"54.80000","1.82414","4202.62793","0.01824","420.26279","0.00000"
"54.90000","1.82758","4209.50000","0.01828","420.95001","0.00000"
"55.00000","1.83087","4214.97461","0.01831","421.49747","0.00000"
"55.10000","1.83416","4220.55176","0.01834","422.05518","0.00000"
"55.20000","1.83756","4227.28906","0.01838","422.72891","0.00000"
"55.30000","1.84103","4234.05713","0.01841","423.40570","0.00000"
"55.40000","1.84442","4240.58789","0.01844","424.05878","0.00000"
"55.50000","1.84744","4244.34717","0.01847","424.43472","0.00001"
"55.60000","1.85095","4251.65771","0.01851","425.16577","-0.00001"
"55.70000","1.85418","4256.73730","0.01854","425.67374","0.00000"
"55.80000","1.85752","4262.75244","0.01858","426.27524","0.00000"
"55.90000","1.86083","4268.34766","0.01861","426.83478","0.00000"
"56.00000","1.86432","4275.18018","0.01864","427.51801","0.00001"
"56.10000","1.86771","4281.42822","0.01868","428.14282","0.00000"
"56.20000","1.87075","4285.28076","0.01871","428.52808","0.00000"
"56.30000","1.87418","4291.88232","0.01874","429.18823","0.00000"
"56.40000","1.87763","4298.65137","0.01878","429.86514","0.00000"
"56.50000","1.88084","4303.82275","0.01881","430.38226","0.00001"
"56.60000","1.88419","4309.91895","0.01884","430.99188","0.00000"
"56.70000","1.88760","4316.38867","0.01888","431.63885","0.00000"
"56.80000","1.89094","4322.40625","0.01891","432.24063","0.00000"
"56.90000","1.89411","4327.38574","0.01894","432.73859","0.00000"
"57.00000","1.89768","4335.06494","0.01898","433.50650","0.00001"
"57.10000","1.90106","4341.05713","0.01901","434.10571","0.00000"
"57.20000","1.90427","4346.24902","0.01904","434.62491","0.00000"
"57.30000","1.90753","4351.58740","0.01908","435.15875","0.00000"
"57.40000","1.91093","4357.92480","0.01911","435.79248","-0.00001"
"57.50000","1.91419","4363.21826","0.01914","436.32184","0.00001"
"57.60000","1.91749","4368.95654","0.01917","436.89566","0.00000"
"57.70000","1.92094","4375.82080","0.01921","437.58209","0.00000"
"57.80000","1.92432","4382.32080","0.01924","438.23209","0.00001"
"57.90000","1.92757","4387.46143","0.01928","438.74615","-0.00001"
"58.00000","1.93087","4393.12793","0.01931","439.31281","0.00001"
"58.10000","1.93415","4398.72754","0.01934","439.87274","0.00000"
"58.20000","1.93747","4404.49512","0.01937","440.44952","0.00000"
"58.30000","1.94084","4410.63330","0.01941","441.06332","0.00000"
"58.40000","1.94432","4417.42236","0.01944","441.74225","0.00000"
"58.50000","1.94765","4423.10840","0.01948","442.31085","0.00001"
"58.60000","1.95084","4428.21484","0.01951","442.82147","0.00000"
"58.70000","1.95429","4434.60254","0.01954","443.46027","0.00000"
"58.80000","1.95759","4439.95605","0.01958","443.99561","0.00001"
"58.90000","1.96088","4445.43994","0.01961","444.54401","0.00000"
"59.00000","1.96427","4451.93945","0.01964","445.19394","0.00000"
"59.10000","1.96763","4457.72998","0.01968","445.77301","0.00000"
"59.20000","1.97098","4463.63818","0.01971","446.36383","0.00000"
"59.30000","1.97414","4468.27881","0.01974","446.82788","0.00000"
"59.40000","1.97756","4474.83301","0.01978","447.48331","0.00000"
"59.50000","1.98091","4480.90283","0.01981","448.09027","0.00000"
"59.60000","1.98419","4486.38184","0.01984","448.63818","0.00000"
"59.70000","1.98761","4492.79883","0.01988","449.27988","-0.00001"
"59.80000","1.99092","4498.06201","0.01991","449.80621","0.00001"
"59.90000","1.99420","4503.46973","0.01994","450.34698","0.00000"
"60.00000","1.99746","4508.94727","0.01997","450.89471","0.00000"
"60.10000","2.00093","4515.72510","0.02001","451.57251","0.00000"
"60.20000","2.00430","4521.79199","0.02004","452.17920","0.00000"
"60.30000","2.00753","4526.91602","0.02008","452.69159","0.00000"
"60.40000","2.01093","4533.37012","0.02011","453.33701","0.00000"
"60.50000","2.01426","4539.02393","0.02014","453.90240","0.00001"
"60.60000","2.01754","4544.30664","0.02018","454.43066","0.00000"
"60.70000","2.02085","4550.10107","0.02021","455.01010","0.00000"
"60.80000","2.02435","4557.10498","0.02024","455.71051","0.00000"
"60.90000","2.02768","4562.82812","0.02028","456.28281","0.00000"
"61.00000","2.03086","4567.72217","0.02031","456.77222","0.00000"
"61.10000","2.03424","4573.85938","0.02034","457.38593","0.00000"
"61.20000","2.03754","4579.34277","0.02038","457.93427","0.00000"
"61.30000","2.04081","4584.70312","0.02041","458.47031","0.00000"
"61.40000","2.04415","4590.49365","0.02044","459.04938","0.00000"
"61.50000","2.04774","4597.61865","0.02048","459.76187","0.00001"
"61.60000","2.05099","4602.64404","0.02051","460.26440","0.00000"
"61.70000","2.05409","4607.04785","0.02054","460.70477","0.00000"
"61.80000","2.05757","4613.74756","0.02058","461.37476","0.00001"
"61.90000","2.06084","4618.99658","0.02061","461.89966","0.00000"
"62.00000","2.06418","4624.80615","0.02064","462.48062","0.00000"
"62.10000","2.06749","4630.70312","0.02067","463.07031","0.00001"
"62.20000","2.07101","4637.69775","0.02071","463.76978","0.00000"
"62.30000","2.07434","4643.25488","0.02074","464.32550","0.00001"
"62.40000","2.07749","4647.69238","0.02077","464.76923","0.00000"
"62.50000","2.08100","4654.58838","0.02081","465.45883","0.00000"
"62.60000","2.08430","4659.93896","0.02084","465.99390","0.00000"
"62.70000","2.08756","4664.84033","0.02088","466.48404","-0.00001"
"62.80000","2.09087","4670.27246","0.02091","467.02725","0.00001"
"62.90000","2.09426","4675.91943","0.02094","467.59195","-0.00001"
"63.00000","2.09757","4681.36523","0.02098","468.13654","0.00000"
"63.10000","2.10075","4686.08789","0.02101","468.60880","0.00000"
"63.20000","2.10428","4693.02637","0.02104","469.30264","0.00000"
"63.30000","2.10770","4699.22119","0.02108","469.92212","0.00000"
"63.40000","2.11084","4703.20557","0.02111","470.32056","0.00000"
"63.50000","2.11415","4708.33691","0.02114","470.83368","0.00000"
"63.60000","2.11760","4714.73438","0.02118","471.47345","0.00000"
"63.70000","2.12081","4719.35059","0.02121","471.93506","0.00000"
"63.80000","2.12415","4725.08398","0.02124","472.50839","0.00000"
"63.90000","2.12765","4731.70654","0.02128","473.17065","0.00000"
"64.00000","2.13108","4738.01270","0.02131","473.80127","0.00000"
"64.10000","2.13422","4742.20557","0.02134","474.22055","0.00001"
"64.20000","2.13758","4748.05762","0.02138","474.80576","0.00000"
"64.30000","2.14093","4753.83350","0.02141","475.38336","0.00000"
"64.40000","2.14417","4758.85742","0.02144","475.88574","0.00000"
"64.50000","2.14752","4765.06836","0.02148","476.50684","0.00000"
"64.60000","2.15098","4771.72998","0.02151","477.17300","0.00001"
"64.70000","2.15439","4777.88574","0.02154","477.78857","-0.00001"
"64.80000","2.15747","4781.83545","0.02157","478.18353","0.00001"
"64.90000","2.16088","4788.17725","0.02161","478.81772","0.00000"
"65.00000","2.16420","4793.78174","0.02164","479.37817","0.00000"
"65.10000","2.16754","4799.46680","0.02168","479.94669","0.00001"
"65.20000","2.17090","4805.19678","0.02171","480.51968","0.00000"
"65.30000","2.17422","4810.74658","0.02174","481.07465","0.00000"
"65.40000","2.17762","4816.61865","0.02178","481.66187","0.00000"
"65.50000","2.18082","4820.80859","0.02181","482.08087","0.00000"
"65.60000","2.18429","4827.50781","0.02184","482.75079","0.00000"
"65.70000","2.18758","4832.85742","0.02188","483.28574","0.00000"
"65.80000","2.19087","4838.26270","0.02191","483.82626","0.00000"
"65.90000","2.19424","4844.11328","0.02194","484.41132","0.00000"
"66.00000","2.19763","4850.05127","0.02198","485.00513","0.00000"
"66.10000","2.20092","4855.13477","0.02201","485.51349","0.00000"
"66.20000","2.20413","4858.81982","0.02204","485.88199","0.00000"
"66.30000","2.20770","4865.90430","0.02208","486.59042","0.00000"
"66.40000","2.21097","4870.42383","0.02211","487.04239","0.00000"
"66.50000","2.21421","4874.94336","0.02214","487.49432","0.00000"
"66.60000","2.21753","4880.16016","0.02218","488.01602","0.00001"
"66.70000","2.22087","4885.57666","0.02221","488.55768","0.00000"
"66.80000","2.22416","4890.73340","0.02224","489.07333","0.00000"
"66.90000","2.22753","4896.42334","0.02228","489.64233","0.00000"
"67.00000","2.23103","4902.92480","0.02231","490.29248","-0.00001"
"67.10000","2.23430","4907.86816","0.02234","490.78680","0.00001"
"67.20000","2.23751","4912.62061","0.02238","491.26205","0.00000"
"67.30000","2.24087","4918.47900","0.02241","491.84790","0.00001"
"67.40000","2.24423","4923.91650","0.02244","492.39166","0.00000"
"67.50000","2.24743","4928.54346","0.02247","492.85434","0.00000"
"67.60000","2.25086","4934.69727","0.02251","493.46973","0.00000"
"67.70000","2.25433","4941.07031","0.02254","494.10703","0.00000"
"67.80000","2.25768","4946.50879","0.02258","494.65088","0.00000"
"67.90000","2.26087","4950.15283","0.02261","495.01529","0.00000"
"68.00000","2.26420","4955.39941","0.02264","495.53995","0.00000"
"68.10000","2.26768","4960.59961","0.02268","496.05997","0.00000"
"68.20000","2.27084","4964.08887","0.02271","496.40887","0.00000"
"68.30000","2.27428","4969.05273","0.02274","496.90527","0.00000"
"68.40000","2.27765","4973.29736","0.02278","497.32974","0.00000"
"68.50000","2.28097","4976.87402","0.02281","497.68741","0.00000"
"68.60000","2.28405","4980.26514","0.02284","498.02652","0.00000"
"68.70000","2.28764","4987.07910","0.02288","498.70792","0.00000"
"68.80000","2.29095","4991.12842","0.02291","499.11285","0.00000"
"68.90000","2.29409","4991.65771","0.02294","499.16577","0.00000"
"69.00000","2.29756","4993.67383","0.02298","499.36737","0.00000"
"69.10000","2.30090","4994.15234","0.02301","499.41522","0.00000"
"69.20000","2.30426","4989.43311","0.02304","498.94330","0.00000"
"69.30000","2.30738","4968.21484","0.02307","496.82147","0.00000"
"69.40000","2.31104","4905.61133","0.02311","490.56113","0.00001"
"69.41600","2.31160","4738.45020","0.02312","473.84503","0.00000"
"69.41800","2.31167","4582.88721","0.02312","458.28873","0.00000"
"69.42000","2.31173","4385.43311","0.02312","438.54330","0.00000"
"69.42200","2.31180","4156.74463","0.02312","415.67447","0.00000"
"69.42400","2.31187","3905.44727","0.02312","390.54474","0.00001"
"69.42500","2.31190","3773.65771","0.02312","377.36578","0.00001"
"69.42600","2.31194","3638.88843","0.02312","363.88885","0.00001"
"69.42700","2.31197","3501.90112","0.02312","350.19012","0.00001"
"69.42800","2.31201","3363.39575","0.02312","336.33957","0.00001"
"69.42900","2.31205","3224.02271","0.02312","322.40228","0.00001"
"69.43000","2.31209","3084.37671","0.02312","308.43768","0.00001"
"69.43100","2.31214","2945.00171","0.02312","294.50018","0.00001"