File: nofiller_4ply.is_comp_RawData/Specimen_RawData_1_1.csv
Test : Rate 1,"1.50000",mm/min
Test : Rate 2,"-5.00000",mm/min

Time,Extension,Load
(s),(mm),(N)
"0.00000","0.00000","0.04953"
"0.10000","0.00057","0.05640"
"0.20000","0.00419","0.08473"
"0.30000","0.00731","0.07751"
"0.40000","0.01003","0.06616"
"0.50000","0.01252","0.05152"
"0.60000","0.01496","0.08114"
"0.70000","0.01745","0.07936"
"0.80000","0.02000","0.09416"
"0.90000","0.02255","0.06194"
"1.00000","0.02505","0.05760"
"1.10000","0.02743","0.06613"
"1.20000","0.03003","0.09158"
"1.30000","0.03258","0.05732"
"1.40000","0.03508","0.06927"
"1.50000","0.03757","0.08316"
"1.60000","0.04001","0.06650"
"1.70000","0.04256","0.05463"
"1.80000","0.04516","0.07148"
"1.90000","0.04760","0.08601"
"2.00000","0.05004","0.09176"
"2.10000","0.05253","0.06502"
"2.20000","0.05502","0.08353"
"2.30000","0.05763","0.03930"
"2.40000","0.06007","0.09130"
"2.50000","0.06250","0.10514"
"2.60000","0.06505","0.04278"
"2.70000","0.06755","0.08168"
"2.80000","0.07010","0.06590"
"2.90000","0.07253","0.05892"
"3.00000","0.07503","0.09394"
"3.10000","0.07758","0.07124"
"3.20000","0.08013","0.05739"
"3.30000","0.08245","0.06298"
"3.40000","0.08500","0.06866"
"3.50000","0.08755","0.11413"
"3.60000","0.09010","0.10388"
"3.70000","0.09254","0.07975"
"3.80000","0.09503","0.08439"
"3.90000","0.09752","0.08859"
"4.00000","0.10007","0.08542"
"4.10000","0.10257","0.08747"
"4.20000","0.10512","0.07933"
"4.30000","0.10755","0.08718"
"4.40000","0.11010","0.09000"
"4.50000","0.11254","0.06689"
"4.60000","0.11509","0.09401"
"4.70000","0.11758","0.08274"
"4.80000","0.12008","0.09943"
"4.90000","0.12263","0.10769"
"5.00000","0.12501","0.08645"
"5.10000","0.12756","0.07358"
"5.20000","0.12999","0.14662"
"5.30000","0.13254","0.09545"
"5.40000","0.13498","0.09465"
"5.50000","0.13753","0.09076"
"5.60000","0.14002","0.07166"
"5.70000","0.14257","0.09054"
"5.80000","0.14507","0.11500"
"5.90000","0.14750","0.07400"
"6.00000","0.15005","0.10107"
"6.10000","0.15255","0.07317"
"6.20000","0.15498","0.09640"
"6.30000","0.15748","0.07000"
"6.40000","0.16008","0.08291"
"6.50000","0.16263","0.10700"
"6.60000","0.16507","0.08994"
"6.70000","0.16756","0.08548"
"6.80000","0.17000","0.09181"
"6.90000","0.17261","0.10374"
"7.00000","0.17510","0.06494"
"7.10000","0.17754","0.08551"
"7.20000","0.18003","0.10844"
"7.30000","0.18252","0.13567"
"7.40000","0.18507","0.09373"
"7.50000","0.18762","0.10448"
"7.60000","0.18995","0.09073"
"7.70000","0.19255","0.10048"
"7.80000","0.19510","0.09283"
"7.90000","0.19754","0.14290"
"8.00000","0.19998","0.11381"
"8.10000","0.20253","0.07305"
"8.20000","0.20496","0.09723"
"8.30000","0.20763","0.11939"
"8.40000","0.21006","0.09586"
"8.50000","0.21244","0.10804"
"8.60000","0.21511","0.10127"
"8.70000","0.21766","0.08491"
"8.80000","0.22004","0.13308"
"8.90000","0.22253","0.11801"
"9.00000","0.22508","0.10427"
"9.10000","0.22763","0.09743"
"9.20000","0.23018","0.09955"
"9.30000","0.23245","0.14263"
"9.40000","0.23505","0.15233"
"9.50000","0.23755","0.10327"
"9.60000","0.24010","0.13603"
"9.70000","0.24259","0.12599"
"9.80000","0.24503","0.10480"
"9.90000","0.24752","0.12597"
"10.00000","0.25013","0.11962"
"10.10000","0.25256","0.06989"
"10.20000","0.25494","0.12160"
"10.30000","0.25761","0.13400"
"10.40000","0.26004","0.08954"
"10.50000","0.26259","0.11930"
"10.60000","0.26503","0.11459"
"10.70000","0.26747","0.12272"
"10.80000","0.27002","0.16144"
"10.90000","0.27262","0.10965"
"11.00000","0.27506","0.10656"
"11.10000","0.27755","0.11916"
"11.20000","0.27999","0.15197"
"11.30000","0.28254","0.13216"
"11.40000","0.28515","0.17083"
"11.50000","0.28753","0.10364"
"11.60000","0.29002","0.10886"
"11.70000","0.29263","0.14000"
"11.80000","0.29512","0.13714"
"11.90000","0.29756","0.12055"
"12.00000","0.29999","0.11567"
"12.10000","0.30249","0.14866"
"12.20000","0.30504","0.10213"
"12.30000","0.30759","0.11073"
"12.40000","0.30997","0.12024"
"12.50000","0.31252","0.08190"
"12.60000","0.31512","0.14534"
"12.70000","0.31756","0.09239"
"12.80000","0.31994","0.11233"
"12.90000","0.32255","0.11982"
"13.00000","0.32498","0.15273"
"13.10000","0.32759","0.11493"
"13.20000","0.33008","0.12209"
"13.30000","0.33258","0.11918"
"13.40000","0.33501","0.13655"
"13.50000","0.33756","0.12008"
"13.60000","0.34000","0.11959"
"13.70000","0.34255","0.12862"
"13.80000","0.34504","0.15348"
"13.90000","0.34759","0.14254"
"14.00000","0.35009","0.15400"
"14.10000","0.35252","0.11538"
"14.20000","0.35507","0.12308"
"14.30000","0.35757","0.10217"
"14.40000","0.36006","0.13247"
"14.50000","0.36250","0.09453"
"14.60000","0.36505","0.11535"
"14.70000","0.36748","0.14046"
"14.80000","0.37003","0.13789"
"14.90000","0.37253","0.14892"
"15.00000","0.37502","0.19189"
"15.10000","0.37757","0.11422"
"15.20000","0.38006","0.14416"
"15.30000","0.38250","0.11830"
"15.40000","0.38499","0.13105"
"15.50000","0.38760","0.11839"
"15.60000","0.39015","0.14413"
"15.70000","0.39259","0.15316"
"15.80000","0.39497","0.13460"
"15.90000","0.39752","0.15942"
"16.00000","0.40012","0.14137"
"16.10000","0.40256","0.15901"
"16.20000","0.40511","0.19230"
"16.30000","0.40755","0.13651"
"16.40000","0.41004","0.11343"
"16.50000","0.41265","0.12099"
"16.60000","0.41503","0.11343"
"16.70000","0.41746","0.16008"
"16.80000","0.42013","0.11840"
"16.90000","0.42262","0.11709"
"17.00000","0.42506","0.12258"
"17.10000","0.42755","0.11476"
"17.20000","0.43004","0.12961"
"17.30000","0.43259","0.10027"
"17.40000","0.43509","0.17010"
"17.50000","0.43752","0.13166"
"17.60000","0.44002","0.11849"
"17.70000","0.44257","0.16654"
"17.80000","0.44512","0.17103"
"17.90000","0.44750","0.16641"
"18.00000","0.45005","0.10017"
"18.10000","0.45254","0.17449"
"18.20000","0.45515","0.14013"
"18.30000","0.45764","0.15086"
"18.40000","0.45996","0.15468"
"18.50000","0.46263","0.15535"
"18.60000","0.46506","0.13601"
"18.70000","0.46761","0.12397"
"18.80000","0.47005","0.13663"
"18.90000","0.47249","0.14220"
"19.00000","0.47509","0.14818"
"19.10000","0.47759","0.17205"
"19.20000","0.48008","0.15693"
"19.30000","0.48252","0.19519"
"19.40000","0.48507","0.14732"
"19.50000","0.48762","0.13898"
"19.60000","0.49011","0.15121"
"19.70000","0.49249","0.16400"
"19.80000","0.49504","0.18106"
"19.90000","0.49759","0.14864"
"20.00000","0.50008","0.14856"
"20.10000","0.50252","0.15872"
"20.20000","0.50501","0.13682"
"20.30000","0.50751","0.14581"
"20.40000","0.51006","0.15836"
"20.50000","0.51261","0.20335"
"20.60000","0.51504","0.16318"
"20.70000","0.51754","0.13963"
"20.80000","0.52009","0.14780"
"20.90000","0.52258","0.17426"
"21.00000","0.52502","0.14820"
"21.10000","0.52751","0.16480"
"21.20000","0.53000","0.15027"
"21.30000","0.53261","0.18176"
"21.40000","0.53499","0.17982"
"21.50000","0.53748","0.19067"
"21.60000","0.54003","0.13192"
"21.70000","0.54258","0.18388"
"21.80000","0.54502","0.19191"
"21.90000","0.54751","0.16126"
"22.00000","0.55006","0.19341"
"22.10000","0.55256","0.11344"
"22.20000","0.55511","0.17249"
"22.30000","0.55760","0.16343"
"22.40000","0.56004","0.17108"
"22.50000","0.56259","0.16838"
"22.60000","0.56508","0.16570"
"22.70000","0.56752","0.17113"
"22.80000","0.57007","0.15170"
"22.90000","0.57250","0.18182"
"23.00000","0.57517","0.17014"
"23.10000","0.57749","0.18011"
"23.20000","0.58004","0.16596"
"23.30000","0.58253","0.16257"
"23.40000","0.58508","0.15675"
"23.50000","0.58752","0.17065"
"23.60000","0.59007","0.14886"
"23.70000","0.59256","0.18733"
"23.80000","0.59506","0.18734"
"23.90000","0.59761","0.17332"
"24.00000","0.59999","0.16730"
"24.10000","0.60254","0.17217"
"24.20000","0.60509","0.18689"
"24.30000","0.60758","0.13246"
"24.40000","0.60996","0.15920"
"24.50000","0.61251","0.15577"
"24.60000","0.61512","0.17206"
"24.70000","0.61761","0.13626"
"24.80000","0.62010","0.17210"
"24.90000","0.62248","0.15749"
"25.00000","0.62509","0.18099"
"25.10000","0.62764","0.11888"
"25.20000","0.63002","0.19962"
"25.30000","0.63257","0.16735"
"25.40000","0.63501","0.18275"
"25.50000","0.63756","0.16888"
"25.60000","0.64011","0.18760"
"25.70000","0.64249","0.16281"
"25.80000","0.64498","0.18985"
"25.90000","0.64759","0.18288"
"26.00000","0.65008","0.16499"
"26.10000","0.65257","0.15700"
"26.20000","0.65501","0.15952"
"26.30000","0.65750","0.22004"
"26.40000","0.66011","0.20578"
"26.50000","0.66260","0.18506"
"26.60000","0.66498","0.19247"
"26.70000","0.66753","0.15730"
"26.80000","0.67014","0.19688"
"26.90000","0.67258","0.15490"
"27.00000","0.67496","0.19661"
"27.10000","0.67751","0.18889"
"27.20000","0.68000","0.14962"
"27.30000","0.68266","0.15826"
"27.40000","0.68504","0.14974"
"27.50000","0.68748","0.23074"
"27.60000","0.69009","0.19249"
"27.70000","0.69258","0.17534"
"27.80000","0.69507","0.16603"
"27.90000","0.69745","0.19620"
"28.00000","0.70000","0.17392"
"28.10000","0.70261","0.18179"
"28.20000","0.70510","0.16561"
"28.30000","0.70748","0.21732"
"28.40000","0.71003","0.18525"
"28.50000","0.71258","0.18674"
"28.60000","0.71508","0.17673"
"28.70000","0.71757","0.15574"
"28.80000","0.72001","0.20640"
"28.90000","0.72256","0.19221"
"29.00000","0.72516","0.18500"
"29.10000","0.72760","0.19393"
"29.20000","0.73004","0.17172"
"29.30000","0.73253","0.16817"
"29.40000","0.73502","0.19034"
"29.50000","0.73757","0.21700"
"29.60000","0.74007","0.21038"
"29.70000","0.74250","0.20761"
"29.80000","0.74505","0.19958"
"29.90000","0.74755","0.18523"
"30.00000","0.75010","0.21985"
"30.10000","0.75253","0.22761"
"30.20000","0.75503","0.19706"
"30.30000","0.75758","0.20608"
"30.40000","0.76013","0.21072"
"30.50000","0.76245","0.17525"
"30.60000","0.76500","0.21434"
"30.70000","0.76761","0.20335"
"30.80000","0.77010","0.18638"
"30.90000","0.77254","0.18007"
"31.00000","0.77503","0.19334"
"31.10000","0.77752","0.17408"
"31.20000","0.78002","0.16932"
"31.30000","0.78257","0.19812"
"31.40000","0.78512","0.23471"
"31.50000","0.78755","0.18236"
"31.60000","0.79016","0.21867"
"31.70000","0.79260","0.18716"
"31.80000","0.79509","0.16902"
"31.90000","0.79764","0.18983"
"32.00000","0.80008","0.19153"
"32.10000","0.80263","0.21277"
"32.20000","0.80501","0.19031"
"32.30000","0.80750","0.21927"
"32.40000","0.81005","0.18936"
"32.50000","0.81254","0.19785"
"32.60000","0.81498","0.18309"
"32.70000","0.81753","0.19016"
"32.80000","0.81997","0.17730"
"32.90000","0.82257","0.22492"
"33.00000","0.82507","0.22449"
"33.10000","0.82756","0.21342"
"33.20000","0.83005","0.17660"
"33.30000","0.83260","0.19320"
"33.40000","0.83504","0.23550"
"33.50000","0.83748","0.22183"
"33.60000","0.84008","0.20456"
"33.70000","0.84258","0.20928"
"33.80000","0.84513","0.21999"
"33.90000","0.84756","0.22286"
"34.00000","0.85000","0.20915"
"34.10000","0.85261","0.16823"
"34.20000","0.85510","0.19092"
"34.30000","0.85754","0.22448"
"34.40000","0.86009","0.21650"
"34.50000","0.86252","0.24218"
"34.60000","0.86507","0.23037"
"34.70000","0.86757","0.23559"
"34.80000","0.86995","0.19075"
"34.90000","0.87255","0.24705"
"35.00000","0.87510","0.20534"
"35.10000","0.87754","0.22291"
"35.20000","0.87998","0.21421"
"35.30000","0.88247","0.24646"
"35.40000","0.88496","0.22881"
"35.50000","0.88763","0.18628"
"35.60000","0.89006","0.24277"
"35.70000","0.89250","0.23176"
"35.80000","0.89511","0.24247"
"35.90000","0.89766","0.19456"
"36.00000","0.90004","0.21305"
"36.10000","0.90253","0.21435"
"36.20000","0.90502","0.23467"
"36.30000","0.90757","0.23430"
"36.40000","0.91018","0.22497"
"36.50000","0.91250","0.21960"
"36.60000","0.91505","0.23784"
"36.70000","0.91755","0.24370"
"36.80000","0.92015","0.25653"
"36.90000","0.92259","0.22684"
"37.00000","0.92503","0.20785"
"37.10000","0.92752","0.21179"
"37.20000","0.93013","0.22960"
"37.30000","0.93256","0.22945"
"37.40000","0.93494","0.22168"
"37.50000","0.93761","0.21211"
"37.60000","0.94010","0.22886"
"37.70000","0.94265","0.25399"
"37.80000","0.94503","0.23916"
"37.90000","0.94747","0.27483"
"38.00000","0.95007","0.22101"
"38.10000","0.95262","0.19254"
"38.20000","0.95506","0.26398"
"38.30000","0.95755","0.26936"
"38.40000","0.95999","0.24142"
"38.50000","0.96260","0.23096"
"38.60000","0.96515","0.25293"
"38.70000","0.96753","0.24933"
"38.80000","0.97002","0.24591"
"38.90000","0.97263","0.21800"
"39.00000","0.97512","0.23783"
"39.10000","0.97756","0.22450"
"39.20000","0.97999","0.23603"
"39.30000","0.98249","0.26703"
"39.40000","0.98509","0.22039"
"39.50000","0.98759","0.19075"
"39.60000","0.98997","0.19708"
"39.70000","0.99252","0.24827"
"39.80000","0.99512","0.25027"
"39.90000","0.99762","0.28685"
"40.00000","1.00000","0.22700"
"40.10000","1.00255","0.23173"
"40.20000","1.00498","0.24470"
"40.30000","1.00753","0.21262"
"40.40000","1.01003","0.25385"
"40.50000","1.01252","0.26907"
"40.60000","1.01501","0.28415"
"40.70000","1.01756","0.22046"
"40.80000","1.02006","0.23603"
"40.90000","1.02261","0.26447"
"41.00000","1.02504","0.28228"
"41.10000","1.02759","0.21295"
"41.20000","1.03009","0.23075"
"41.30000","1.03252","0.25222"
"41.40000","1.03502","0.26038"
"41.50000","1.03757","0.22999"
"41.60000","1.04006","0.23130"
"41.70000","1.04250","0.26862"
"41.80000","1.04505","0.23555"
"41.90000","1.04748","0.25656"
"42.00000","1.05003","0.26916"
"42.10000","1.05258","0.24105"
"42.20000","1.05502","0.22817"
"42.30000","1.05757","0.20386"
"42.40000","1.06012","0.22931"
"42.50000","1.06250","0.23313"
"42.60000","1.06499","0.24207"
"42.70000","1.06766","0.22891"
"42.80000","1.07009","0.21036"
"42.90000","1.07253","0.24701"
"43.00000","1.07502","0.28035"
"43.10000","1.07752","0.25785"
"43.20000","1.08012","0.28336"
"43.30000","1.08256","0.24689"
"43.40000","1.08505","0.23009"
"43.50000","1.08749","0.20912"
"43.60000","1.09004","0.24504"
"43.70000","1.09259","0.23480"
"43.80000","1.09503","0.26249"
"43.90000","1.09752","0.25875"
"44.00000","1.10013","0.26096"
"44.10000","1.10262","0.23507"
"44.20000","1.10506","0.26338"
"44.30000","1.10749","0.28056"
"44.40000","1.11004","0.28522"
"44.50000","1.11254","0.25589"
"44.60000","1.11509","0.28965"
"44.70000","1.11752","0.25316"
"44.80000","1.12002","0.23150"
"44.90000","1.12257","0.25469"
"45.00000","1.12512","0.29472"
"45.10000","1.12750","0.24078"
"45.20000","1.13005","0.25659"
"45.30000","1.13254","0.24126"
"45.40000","1.13515","0.24184"
"45.50000","1.13764","0.25193"
"45.60000","1.13996","0.27154"
"45.70000","1.14263","0.25975"
"45.80000","1.14506","0.23416"
"45.90000","1.14756","0.26202"
"46.00000","1.14999","0.27979"
"46.10000","1.15249","0.25502"
"46.20000","1.15504","0.23837"
"46.30000","1.15764","0.28824"
"46.40000","1.16002","0.30795"
"46.50000","1.16246","0.26895"
"46.60000","1.16512","0.27623"
"46.70000","1.16762","0.25770"
"46.80000","1.17011","0.23553"
"46.90000","1.17255","0.27580"
"47.00000","1.17504","0.26341"
"47.10000","1.17759","0.26655"
"47.20000","1.18008","0.23163"
"47.30000","1.18252","0.25187"
"47.40000","1.18501","0.28124"
"47.50000","1.18751","0.25850"
"47.60000","1.19006","0.26536"
"47.70000","1.19261","0.28960"
"47.80000","1.19504","0.28473"
"47.90000","1.19754","0.24028"
"48.00000","1.20014","0.27897"
"48.10000","1.20258","0.26267"
"48.20000","1.20502","0.27228"
"48.30000","1.20751","0.27581"
"48.40000","1.21000","0.26370"
"48.50000","1.21255","0.25354"
"48.60000","1.21499","0.26869"
"48.70000","1.21748","0.27854"
"48.80000","1.22003","0.27326"
"48.90000","1.22264","0.24786"
"49.00000","1.22502","0.24677"
"49.10000","1.22751","0.29266"
"49.20000","1.23006","0.26252"
"49.30000","1.23261","0.30203"
"49.40000","1.23511","0.29927"
"49.50000","1.23760","0.27914"
"49.60000","1.24004","0.28789"
"49.70000","1.24259","0.29439"
"49.80000","1.24502","0.28280"
"49.90000","1.24752","0.30503"
"50.00000","1.25007","0.31927"
"50.10000","1.25250","0.28922"
"50.20000","1.25517","0.25602"
"50.30000","1.25749","0.29036"
"50.40000","1.26004","0.25715"
"50.50000","1.26253","0.31401"
"50.60000","1.26508","0.26897"
"50.70000","1.26752","0.28327"
"50.80000","1.27007","0.28158"
"50.90000","1.27251","0.27662"
"51.00000","1.27506","0.30164"
"51.10000","1.27755","0.30938"
"51.20000","1.27999","0.28227"
"51.30000","1.28254","0.33490"
"51.40000","1.28509","0.31618"
"51.50000","1.28758","0.29498"
"51.60000","1.29002","0.25447"
"51.70000","1.29251","0.28998"
"51.80000","1.29512","0.29435"
"51.90000","1.29761","0.27451"
"52.00000","1.30010","0.30354"
"52.10000","1.30248","0.30867"
"52.20000","1.30509","0.29337"
"52.30000","1.30770","0.28099"
"52.40000","1.31008","0.32048"
"52.50000","1.31257","0.34211"
"52.60000","1.31501","0.30765"
"52.70000","1.31756","0.28204"
"52.80000","1.32011","0.26443"
"52.90000","1.32249","0.28096"
"53.00000","1.32498","0.28106"
"53.10000","1.32759","0.29876"
"53.20000","1.33008","0.31633"
"53.30000","1.33252","0.32988"
"53.40000","1.33501","0.26994"
"53.50000","1.33750","0.30130"
"53.60000","1.34011","0.30961"
"53.70000","1.34260","0.29515"
"53.80000","1.34498","0.31208"
"53.90000","1.34753","0.30633"
"54.00000","1.35020","0.24243"
"54.10000","1.35258","0.28374"
"54.20000","1.35496","0.29885"
"54.30000","1.35756","0.32636"
"54.40000","1.36006","0.29986"
"54.50000","1.36266","0.29640"
"54.60000","1.36504","0.31124"
"54.70000","1.36754","0.26871"
"54.80000","1.37009","0.32351"
"54.90000","1.37264","0.29089"
"55.00000","1.37507","0.29759"
"55.10000","1.37751","0.27187"
"55.20000","1.38000","0.27942"
"55.30000","1.38255","0.32385"
"55.40000","1.38505","0.32652"
"55.50000","1.38748","0.30438"
"55.60000","1.38998","0.32724"
"55.70000","1.39258","0.32380"
"55.80000","1.39513","0.27608"
"55.90000","1.39757","0.27747"
"56.00000","1.40001","0.33180"
"56.10000","1.40256","0.31421"
"56.20000","1.40511","0.31944"
"56.30000","1.40760","0.32355"
"56.40000","1.41004","0.29630"
"56.50000","1.41253","0.33354"
"56.60000","1.41508","0.31829"
"56.70000","1.41763","0.27911"
"56.80000","1.42007","0.27955"
"56.90000","1.42256","0.29591"
"57.00000","1.42505","0.31620"
"57.10000","1.42755","0.32093"
"57.20000","1.43010","0.31426"
"57.30000","1.43248","0.25926"
"57.40000","1.43503","0.29217"
"57.50000","1.43758","0.32610"
"57.60000","1.44013","0.33837"
"57.70000","1.44245","0.31940"
"57.80000","1.44500","0.33038"
"57.90000","1.44755","0.32847"
"58.00000","1.45010","0.31524"
"58.10000","1.45248","0.31797"
"58.20000","1.45503","0.30459"
"58.30000","1.45752","0.30713"
"58.40000","1.46002","0.30654"
"58.50000","1.46257","0.33336"
"58.60000","1.46512","0.30714"
"58.70000","1.46755","0.28304"
"58.80000","1.47010","0.30964"
"58.90000","1.47254","0.27613"
"59.00000","1.47503","0.31221"
"59.10000","1.47758","0.30187"
"59.20000","1.48008","0.34600"
"59.30000","1.48263","0.28405"
"59.40000","1.48501","0.29828"
"59.50000","1.48750","0.35814"
"59.60000","1.48999","0.34074"
"59.70000","1.49254","0.32724"
"59.80000","1.49498","0.30075"
"59.90000","1.49753","0.30033"
"60.00000","1.50002","0.34836"
"60.10000","1.50257","0.30612"
"60.20000","1.50507","0.31077"
"60.30000","1.50750","0.31641"
"60.40000","1.51005","0.31017"
"60.50000","1.51255","0.33312"
"60.60000","1.51504","0.29776"
"60.70000","1.51748","0.31785"
"60.80000","1.52008","0.29792"
"60.90000","1.52258","0.32935"
"61.00000","1.52507","0.33409"
"61.10000","1.52756","0.27189"
"61.20000","1.52994","0.31811"
"61.30000","1.53261","0.34976"
"61.40000","1.53516","0.35172"
"61.50000","1.53754","0.29429"
"61.60000","1.54009","0.31144"
"61.70000","1.54252","0.34188"
"61.80000","1.54507","0.33789"
"61.90000","1.54762","0.32210"
"62.00000","1.54995","0.34268"
"62.10000","1.55255","0.34664"
"62.20000","1.55510","0.31192"
"62.30000","1.55754","0.30970"
"62.40000","1.55998","0.35096"
"62.50000","1.56253","0.34964"
"62.60000","1.56496","0.33124"
"62.70000","1.56763","0.30635"
"62.80000","1.57006","0.34291"
"62.90000","1.57244","0.34257"
"63.00000","1.57511","0.32837"
"63.10000","1.57766","0.31493"
"63.20000","1.58004","0.32953"
"63.30000","1.58247","0.34922"
"63.40000","1.58502","0.35849"
"63.50000","1.58757","0.35233"
"63.60000","1.59018","0.34649"
"63.70000","1.59250","0.35778"
"63.80000","1.59505","0.34596"
"63.90000","1.59755","0.35766"
"64.00000","1.60010","0.33756"
"64.10000","1.60259","0.36592"
"64.20000","1.60503","0.32922"
"64.30000","1.60752","0.30549"
"64.40000","1.61013","0.32724"
"64.50000","1.61256","0.30107"
"64.60000","1.61494","0.34074"
"64.70000","1.61755","0.40048"
"64.80000","1.62010","0.31279"
"64.90000","1.62265","0.34913"
"65.00000","1.62497","0.33734"
"65.10000","1.62747","0.32238"
"65.20000","1.63007","0.30442"
"65.30000","1.63262","0.35189"
"65.40000","1.63506","0.32812"
"65.50000","1.63755","0.34698"
"65.60000","1.63999","0.37617"
"65.70000","1.64254","0.34715"
"65.80000","1.64515","0.32437"
"65.90000","1.64753","0.33737"
"66.00000","1.65002","0.35418"
"66.10000","1.65263","0.32967"
"66.20000","1.65512","0.38094"
"66.30000","1.65756","0.37890"
"66.40000","1.66005","0.33330"
"66.50000","1.66249","0.32025"
"66.60000","1.66509","0.35134"
"66.70000","1.66759","0.30116"
"66.80000","1.66997","0.37931"
"66.90000","1.67252","0.29476"
"67.00000","1.67512","0.37700"
"67.10000","1.67756","0.35957"
"67.20000","1.68000","0.36246"
"67.30000","1.68255","0.37561"
"67.40000","1.68504","0.35294"
"67.50000","1.68759","0.35345"
"67.60000","1.69008","0.37987"
"67.70000","1.69258","0.39480"
"67.80000","1.69501","0.37953"
"67.90000","1.69751","0.34502"
"68.00000","1.70000","0.36242"
"68.10000","1.70255","0.35609"
"68.20000","1.70504","0.35048"
"68.30000","1.70759","0.35474"
"68.40000","1.71009","0.36017"
"68.50000","1.71252","0.38165"
"68.60000","1.71507","0.36258"
"68.70000","1.71757","0.35864"
"68.80000","1.72006","0.35520"
"68.90000","1.72250","0.32836"
"69.00000","1.72499","0.35969"
"69.10000","1.72748","0.36017"
"69.20000","1.73003","0.36495"
"69.30000","1.73258","0.35085"
"69.40000","1.73508","0.35860"
"69.50000","1.73757","0.34226"
"69.60000","1.74012","0.39536"
"69.70000","1.74256","0.35393"
"69.80000","1.74499","0.40958"
"69.90000","1.74766","0.37150"
"70.00000","1.75009","0.40270"
"70.10000","1.75253","0.34993"
"70.20000","1.75502","0.36794"
"70.30000","1.75752","0.36422"
"70.40000","1.76007","0.40699"
"70.50000","1.76256","0.36712"
"70.60000","1.76505","0.36887"
"70.70000","1.76749","0.36211"
"70.80000","1.77004","0.41730"
"70.90000","1.77259","0.33810"
"71.00000","1.77503","0.36633"
"71.10000","1.77752","0.41091"
"71.20000","1.78013","0.39075"
"71.30000","1.78262","0.34432"
"71.40000","1.78506","0.36149"
"71.50000","1.78755","0.38109"
"71.60000","1.79004","0.38651"
"71.70000","1.79254","0.34852"
"71.80000","1.79509","0.36038"
"71.90000","1.79752","0.37008"
"72.00000","1.79996","0.38172"
"72.10000","1.80257","0.35403"
"72.20000","1.80512","0.37764"
"72.30000","1.80750","0.37579"
"72.40000","1.81005","0.38734"
"72.50000","1.81254","0.36992"
"72.60000","1.81515","0.41528"
"72.70000","1.81764","0.32571"
"72.80000","1.81996","0.39150"
"72.90000","1.82263","0.38512"
"73.00000","1.82506","0.38767"
"73.10000","1.82761","0.40869"
"73.20000","1.83005","0.36969"
"73.30000","1.83249","0.37878"
"73.40000","1.83498","0.39054"
"73.50000","1.83759","0.37323"
"73.60000","1.84002","0.38151"
"73.70000","1.84246","0.42810"
"73.80000","1.84512","0.37372"
"73.90000","1.84756","0.38856"
"74.00000","1.85011","0.36825"
"74.10000","1.85255","0.36419"
"74.20000","1.85504","0.38722"
"74.30000","1.85753","0.40526"
"74.40000","1.86014","0.37049"
"74.50000","1.86252","0.39599"
"74.60000","1.86501","0.38151"
"74.70000","1.86751","0.35976"
"74.80000","1.87000","0.40633"
"74.90000","1.87266","0.37668"
"75.00000","1.87504","0.39108"
"75.10000","1.87754","0.39801"
"75.20000","1.88014","0.42944"
"75.30000","1.88258","0.43683"
"75.40000","1.88502","0.38603"
"75.50000","1.88751","0.43350"
"75.60000","1.89000","0.40227"
"75.70000","1.89255","0.38013"
"75.80000","1.89505","0.38494"
"75.90000","1.89743","0.39033"
"76.00000","1.90003","0.43983"
"76.10000","1.90258","0.38163"
"76.20000","1.90502","0.35593"
"76.30000","1.90751","0.41168"
"76.40000","1.91006","0.40859"
"76.50000","1.91256","0.42037"
"76.60000","1.91511","0.38846"
"76.70000","1.91760","0.38957"
"76.80000","1.92004","0.36999"
"76.90000","1.92253","0.39281"
"77.00000","1.92502","0.41939"
"77.10000","1.92752","0.39148"
"77.20000","1.93012","0.40236"
"77.30000","1.93256","0.41266"
"77.40000","1.93517","0.43561"
"77.50000","1.93749","0.40008"
"77.60000","1.94004","0.39508"
"77.70000","1.94253","0.40925"
"77.80000","1.94508","0.43613"
"77.90000","1.94752","0.38359"
"78.00000","1.95007","0.44296"
"78.10000","1.95256","0.38255"
"78.20000","1.95506","0.38045"
"78.30000","1.95761","0.40076"
"78.40000","1.95999","0.40750"
"78.50000","1.96248","0.40679"
"78.60000","1.96509","0.39174"
"78.70000","1.96758","0.38892"
"78.80000","1.97002","0.39357"
"78.90000","1.97251","0.41537"
"79.00000","1.97512","0.36927"
"79.10000","1.97761","0.40084"
"79.20000","1.98005","0.43746"
"79.30000","1.98248","0.42516"
"79.40000","1.98509","0.42450"
"79.50000","1.98764","0.36352"
"79.60000","1.99008","0.40526"
"79.70000","1.99257","0.41920"
"79.80000","1.99501","0.44062"
"79.90000","1.99756","0.41526"
"80.00000","2.00011","0.44279"
"80.10000","2.00249","0.42748"
"80.20000","2.00498","0.40871"
"80.30000","2.00759","0.40099"
"80.40000","2.01008","0.38879"
"80.50000","2.01252","0.40928"
"80.60000","2.01507","0.40455"
"80.70000","2.01750","0.40944"
"80.80000","2.02011","0.41319"
"80.90000","2.02260","0.43766"
"81.00000","2.02498","0.40676"
"81.10000","2.02753","0.41826"
"81.20000","2.03014","0.43942"
"81.30000","2.03258","0.42068"
"81.40000","2.03501","0.44533"
"81.50000","2.03751","0.40396"
"81.60000","2.04006","0.44946"
"81.70000","2.04266","0.42003"
"81.80000","2.04504","0.44008"
"81.90000","2.04748","0.41481"
"82.00000","2.05009","0.44738"
"82.10000","2.05264","0.43178"
"82.20000","2.05507","0.41267"
"82.30000","2.05751","0.42035"
"82.40000","2.06000","0.40244"
"82.50000","2.06261","0.40188"
"82.60000","2.06505","0.43962"
"82.70000","2.06748","0.40368"
"82.80000","2.06998","0.43190"
"82.90000","2.07258","0.41763"
"83.00000","2.07508","0.36377"
"83.10000","2.07757","0.38203"
"83.20000","2.08001","0.38863"
"83.30000","2.08256","0.42353"
"83.40000","2.08511","0.39962"
"83.50000","2.08760","0.44746"
"83.60000","2.09004","0.47002"
"83.70000","2.09253","0.42175"
"83.80000","2.09502","0.43858"
"83.90000","2.09763","0.41250"
"84.00000","2.10007","0.42164"
"84.10000","2.10256","0.41477"
"84.20000","2.10505","0.44857"
"84.30000","2.10755","0.41214"
"84.40000","2.11010","0.39698"
"84.50000","2.11253","0.44179"
"84.60000","2.11503","0.43930"
"84.70000","2.11758","0.42462"
"84.80000","2.12013","0.43391"
"84.90000","2.12245","0.41754"
"85.00000","2.12506","0.43807"
"85.10000","2.12755","0.41622"
"85.20000","2.13010","0.43066"
"85.30000","2.13248","0.43601"
"85.40000","2.13497","0.42114"
"85.50000","2.13752","0.43839"
"85.60000","2.14007","0.44103"
"85.70000","2.14257","0.46816"
"85.80000","2.14506","0.42169"
"85.90000","2.14755","0.44129"
"86.00000","2.15005","0.40933"
"86.10000","2.15254","0.42491"
"86.20000","2.15503","0.41045"
"86.30000","2.15758","0.42424"
"86.40000","2.16008","0.42606"
"86.50000","2.16263","0.42338"
"86.60000","2.16501","0.42146"
"86.70000","2.16756","0.43501"
"86.80000","2.17005","0.45498"
"86.90000","2.17254","0.44210"
"87.00000","2.17498","0.44064"
"87.10000","2.17753","0.41514"
"87.20000","2.17997","0.45506"
"87.30000","2.18257","0.45747"
"87.40000","2.18512","0.48088"
"87.50000","2.18750","0.40974"
"87.60000","2.19005","0.39164"
"87.70000","2.19260","0.43804"
"87.80000","2.19504","0.40934"
"87.90000","2.19748","0.44874"
"88.00000","2.20008","0.41713"
"88.10000","2.20258","0.42407"
"88.20000","2.20507","0.41331"
"88.30000","2.20756","0.39528"
"88.40000","2.20994","0.41219"
"88.50000","2.21261","0.49063"
"88.60000","2.21510","0.45033"
"88.70000","2.21754","0.47354"
"88.80000","2.22009","0.42618"
"88.90000","2.22252","0.45419"
"89.00000","2.22507","0.44625"
"89.10000","2.22762","0.42545"
"89.20000","2.22995","0.45829"
"89.30000","2.23261","0.45864"
"89.40000","2.23510","0.45891"
"89.50000","2.23754","0.44239"
"89.60000","2.24003","0.45671"
"89.70000","2.24247","0.45362"
"89.80000","2.24496","0.45502"
"89.90000","2.24763","0.44235"
"90.00000","2.25006","0.43162"
"90.10000","2.25250","0.45828"
"90.20000","2.25511","0.48148"
"90.30000","2.25766","0.46672"
"90.40000","2.26004","0.46997"
"90.50000","2.26247","0.43678"
"90.60000","2.26502","0.42366"
"90.70000","2.26757","0.47174"
"90.80000","2.27018","0.44431"
"90.90000","2.27245","0.47083"
"91.00000","2.27505","0.42877"
"91.10000","2.27755","0.48574"
"91.20000","2.28015","0.46136"
"91.30000","2.28259","0.40483"
"91.40000","2.28503","0.42905"
"91.50000","2.28752","0.43003"
"91.60000","2.29018","0.45929"
"91.70000","2.29256","0.45161"
"91.80000","2.29494","0.45194"
"91.90000","2.29761","0.48022"
"92.00000","2.30004","0.45836"
"92.10000","2.30265","0.44088"
"92.20000","2.30503","0.45390"
"92.30000","2.30747","0.43088"
"92.40000","2.31002","0.45133"
"92.50000","2.31262","0.44038"
"92.60000","2.31506","0.43955"
"92.70000","2.31755","0.47334"
"92.80000","2.31999","0.43337"
"92.90000","2.32254","0.46708"
"93.00000","2.32515","0.48913"
"93.10000","2.32753","0.47723"
"93.20000","2.33002","0.47483"
"93.30000","2.33263","0.45228"
"93.40000","2.33506","0.45835"
"93.50000","2.33750","0.47072"
"93.60000","2.33999","0.45052"
"93.70000","2.34249","0.48011"
"93.80000","2.34509","0.46258"
"93.90000","2.34759","0.47192"
"94.00000","2.34997","0.50713"
"94.10000","2.35252","0.49194"
"94.20000","2.35518","0.49302"
"94.30000","2.35756","0.46150"
"94.40000","2.36000","0.46996"
"94.50000","2.36255","0.45348"
"94.60000","2.36504","0.47845"
"94.70000","2.36759","0.48657"
"94.80000","2.37003","0.47330"
"94.90000","2.37258","0.49405"
"95.00000","2.37501","0.47494"
"95.10000","2.37756","0.48084"
"95.20000","2.38000","0.49750"
"95.30000","2.38255","0.48306"
"95.40000","2.38499","0.45725"
"95.50000","2.38759","0.51400"
"95.60000","2.39009","0.46738"
"95.70000","2.39252","0.47009"
"95.80000","2.39507","0.44286"
"95.90000","2.39757","0.48628"
"96.00000","2.40000","0.53516"
"96.10000","2.40250","0.45242"
"96.20000","2.40499","0.49837"
"96.30000","2.40748","0.48571"
"96.40000","2.41009","0.50431"
"96.50000","2.41258","0.48801"
"96.60000","2.41502","0.50195"
"96.70000","2.41757","0.48340"
"96.80000","2.42012","0.50443"
"96.90000","2.42256","0.47606"
"97.00000","2.42499","0.49466"
"97.10000","2.42760","0.46931"
"97.20000","2.43009","0.48145"
"97.30000","2.43259","0.49932"
"97.40000","2.43502","0.49142"
"97.50000","2.43752","0.48591"
"97.60000","2.44012","0.49113"
"97.70000","2.44256","0.45314"
"97.80000","2.44505","0.50196"
"97.90000","2.44749","0.46496"
"98.00000","2.45004","0.47391"
"98.10000","2.45265","0.48574"
"98.20000","2.45503","0.50665"
"98.30000","2.45752","0.48204"
"98.40000","2.46013","0.48706"
"98.50000","2.46262","0.50012"
"98.60000","2.46506","0.51577"
"98.70000","2.46749","0.46912"
"98.80000","2.47004","0.50161"
"98.90000","2.47259","0.49040"
"99.00000","2.47509","0.49584"
"99.10000","2.47752","0.48921"
"99.20000","2.48002","0.50144"
"99.30000","2.48257","0.46439"
"99.40000","2.48517","0.49440"
"99.50000","2.48750","0.43486"
"99.60000","2.49005","0.55059"
"99.70000","2.49254","0.51775"
"99.80000","2.49509","0.51915"
"99.90000","2.49764","0.48548"
"100.00000","2.49996","0.48634"
"100.00200","2.50002","0.48486"
"100.00400","2.50008","0.48390"
"100.10400","2.49622","0.48740"
"100.20400","2.48410","0.48874"
"100.30400","2.47520","0.51534"
"100.40400","2.46687","0.47862"
"100.50400","2.45843","0.51570"
"100.60400","2.45021","0.49587"
"100.70400","2.44188","0.43237"
"100.80400","2.43338","0.48496"
"100.90400","2.42505","0.46493"
"101.00400","2.41678","0.47321"
"101.10400","2.40856","0.46178"
"101.20400","2.40017","0.48782"
"101.30400","2.39184","0.45534"
"101.40400","2.38340","0.48834"
"101.50400","2.37513","0.47215"
"101.60400","2.36680","0.45641"
"101.70400","2.35841","0.44475"
"101.80400","2.35008","0.45317"
"101.90400","2.34181","0.41709"
"102.00400","2.33353","0.47060"
"102.10400","2.32509","0.46721"
"102.20400","2.31676","0.43159"
"102.30400","2.30837","0.44653"
"102.40400","2.30010","0.46307"
"102.50400","2.29183","0.50060"
"102.60400","2.28338","0.46183"
"102.70400","2.27511","0.44003"
"102.80400","2.26672","0.47937"
"102.90400","2.25845","0.46391"
"103.00400","2.25006","0.42874"
"103.10400","2.24173","0.46381"
"103.20400","2.23346","0.43573"
"103.30400","2.22519","0.45524"
"103.40400","2.21680","0.45561"
"103.50400","2.20836","0.44056"
"103.60400","2.20008","0.43374"
"103.70400","2.19181","0.40165"
"103.80400","2.18348","0.44486"
"103.90400","2.17515","0.39945"
"104.00400","2.16682","0.45748"
"104.10400","2.15843","0.38920"
"104.20400","2.15010","0.44478"
"104.30400","2.14172","0.37337"
"104.40400","2.13339","0.45871"
"104.50400","2.12517","0.42874"
"104.60400","2.11690","0.41930"
"104.70400","2.10851","0.45843"
"104.80400","2.10007","0.43309"
"104.90400","2.09168","0.41871"
"105.00400","2.08341","0.41631"
"105.10400","2.07513","0.40862"
"105.20400","2.06680","0.40957"
"105.30400","2.05842","0.38194"
"105.40400","2.05014","0.40962"
"105.50400","2.04176","0.38969"
"105.60400","2.03343","0.39854"
"105.70400","2.02504","0.41164"
"105.80400","2.01677","0.41184"
"105.90400","2.00849","0.38149"
"106.00400","2.00011","0.38159"
"106.10400","1.99178","0.39713"
"106.20400","1.98339","0.36263"
"106.30400","1.97512","0.37374"
"106.40400","1.96679","0.43579"
"106.50400","1.95840","0.37203"
"106.60400","1.95007","0.38631"
"106.70400","1.94180","0.38359"
"106.80400","1.93352","0.37720"
"106.90400","1.92502","0.35312"
"107.00400","1.91681","0.38472"
"107.10400","1.90836","0.39322"
"107.20400","1.90020","0.37104"
"107.30400","1.89182","0.37906"
"107.40400","1.88349","0.37326"
"107.50400","1.87510","0.35227"
"107.60400","1.86677","0.39485"
"107.70400","1.85850","0.35915"
"107.80400","1.85005","0.38692"
"107.90400","1.84172","0.34140"
"108.00400","1.83345","0.33921"
"108.10400","1.82518","0.34110"
"108.20400","1.81685","0.37649"
"108.30400","1.80840","0.31975"
"108.40400","1.80002","0.34253"
"108.50400","1.79180","0.38025"
"108.60400","1.78347","0.36233"
"108.70400","1.77514","0.33651"
"108.80400","1.76675","0.36067"
"108.90400","1.75837","0.35500"
"109.00400","1.75015","0.34439"
"109.10400","1.74176","0.35638"
"109.20400","1.73343","0.39356"
"109.30400","1.72505","0.37636"
"109.40400","1.71683","0.34351"
"109.50400","1.70850","0.32040"
"109.60400","1.70006","0.36611"
"109.70400","1.69178","0.32254"
"109.80400","1.68351","0.34080"
"109.90400","1.67518","0.32862"
"110.00400","1.66679","0.28931"
"110.10400","1.65841","0.34756"
"110.20400","1.65013","0.33801"
"110.30400","1.64175","0.29419"
"110.40400","1.63347","0.34379"
"110.50400","1.62503","0.31453"
"110.60400","1.61681","0.31580"
"110.70400","1.60854","0.26812"
"110.80400","1.60010","0.32465"
"110.90400","1.59177","0.34831"
"111.00400","1.58332","0.31145"
"111.10400","1.57511","0.34003"
"111.20400","1.56678","0.28078"
"111.30400","1.55845","0.32146"
"111.40400","1.55012","0.29956"
"111.50400","1.54173","0.30259"
"111.60400","1.53340","0.31892"
"111.70400","1.52507","0.32628"
"111.80400","1.51668","0.29701"
"111.90400","1.50841","0.29587"
"112.00400","1.50019","0.26857"
"112.10400","1.49186","0.30225"
"112.20400","1.48348","0.29868"
"112.30400","1.47498","0.32570"
"112.40400","1.46676","0.29558"
"112.50400","1.45849","0.27674"
"112.60400","1.45016","0.28597"
"112.70400","1.44177","0.30313"
"112.80400","1.43338","0.25203"
"112.90400","1.42517","0.28682"
"113.00400","1.41672","0.27875"
"113.10400","1.40845","0.27911"
"113.20400","1.40006","0.26908"
"113.30400","1.39179","0.30350"
"113.40400","1.38352","0.29849"
"113.50400","1.37507","0.27813"
"113.60400","1.36674","0.27234"
"113.70400","1.35830","0.27675"
"113.80400","1.35008","0.29279"
"113.90400","1.34175","0.25082"
"114.00400","1.33348","0.31154"
"114.10400","1.32515","0.26846"
"114.20400","1.31688","0.28094"
"114.30400","1.30843","0.28319"
"114.40400","1.30005","0.23635"
"114.50400","1.29166","0.27192"
"114.60400","1.28333","0.26557"
"114.70400","1.27523","0.26959"
"114.80400","1.26684","0.24925"
"114.90400","1.25857","0.25777"
"115.00400","1.25007","0.26754"
"115.10400","1.24179","0.27300"
"115.20400","1.23341","0.22875"
"115.30400","1.22502","0.23199"
"115.40400","1.21675","0.29419"
"115.50400","1.20847","0.23527"
"115.60400","1.20020","0.28366"
"115.70400","1.19187","0.25862"
"115.80400","1.18343","0.22810"
"115.90400","1.17504","0.27755"
"116.00400","1.16682","0.25245"
"116.10400","1.15849","0.25034"
"116.20400","1.15011","0.23972"
"116.30400","1.14172","0.25661"
"116.40400","1.13345","0.22404"
"116.50400","1.12512","0.26746"
"116.60400","1.11667","0.23900"
"116.70400","1.10840","0.22537"
"116.80400","1.10013","0.26317"
"116.90400","1.09174","0.23919"
"117.00400","1.08341","0.17623"
"117.10400","1.07508","0.22387"
"117.20400","1.06675","0.20861"
"117.30400","1.05842","0.16795"
"117.40400","1.05015","0.22577"
"117.50400","1.04182","0.19707"
"117.60400","1.03343","0.27414"
"117.70400","1.02516","0.22968"
"117.80400","1.01677","0.21419"
"117.90400","1.00844","0.22832"
"118.00400","1.00005","0.20646"
"118.10400","0.99184","0.21273"
"118.20400","0.98356","0.22609"
"118.30400","0.97518","0.21201"
"118.40400","0.96679","0.18627"
"118.50400","0.95840","0.22077"
"118.60400","0.95013","0.23766"
"118.70400","0.94180","0.21021"
"118.80400","0.93347","0.22309"
"118.90400","0.92508","0.18857"
"119.00400","0.91681","0.24202"
"119.10400","0.90842","0.21146"
"119.20400","0.90009","0.18347"
"119.30400","0.89165","0.20756"
"119.40400","0.88338","0.18267"
"119.50400","0.87516","0.19631"
"119.60400","0.86677","0.18269"
"119.70400","0.85850","0.15531"
"119.80400","0.85006","0.18644"
"119.90400","0.84178","0.20930"
"120.00400","0.83345","0.21515"
"120.10400","0.82512","0.16775"
"120.20400","0.81679","0.16742"
"120.30400","0.80846","0.16504"
"120.40400","0.80019","0.19732"
"120.50400","0.79175","0.20331"
"120.60400","0.78336","0.19616"
"120.70400","0.77503","0.20492"
"120.80400","0.76681","0.17106"
"120.90400","0.75854","0.16636"
"121.00400","0.75015","0.15754"
"121.10400","0.74177","0.19052"
"121.20400","0.73344","0.16574"
"121.30400","0.72505","0.19161"
"121.40400","0.71672","0.15039"
"121.50400","0.70845","0.16951"
"121.60400","0.70012","0.16885"
"121.70400","0.69190","0.14017"
"121.80400","0.68346","0.13089"
"121.90400","0.67501","0.13644"
"122.00400","0.66668","0.16099"
"122.10400","0.65835","0.15266"
"122.20400","0.65014","0.18067"
"122.30400","0.64175","0.14523"
"122.40400","0.63348","0.15651"
"122.50400","0.62509","0.13917"
"122.60400","0.61682","0.13638"
"122.70400","0.60837","0.10901"
"122.80400","0.60004","0.14709"
"122.90400","0.59177","0.16436"
"123.00400","0.58350","0.11666"
"123.10400","0.57522","0.16514"
"123.20400","0.56672","0.18396"
"123.30400","0.55845","0.09814"
"123.40400","0.55012","0.13487"
"123.50400","0.54185","0.14194"
"123.60400","0.53346","0.13987"
"123.70400","0.52513","0.12541"
"123.80400","0.51686","0.14063"
"123.90400","0.50853","0.15722"
"124.00400","0.50014","0.11619"
"124.10400","0.49170","0.13375"
"124.20400","0.48348","0.12135"
"124.30400","0.47515","0.11611"
"124.40400","0.46682","0.10898"
"124.50400","0.45838","0.11327"
"124.60400","0.45005","0.11872"
"124.70400","0.44177","0.13564"
"124.80400","0.43344","0.10240"
"124.90400","0.42511","0.07167"
"125.00400","0.41673","0.09783"
"125.10400","0.40840","0.10841"
"125.20400","0.40007","0.07879"
"125.30400","0.39174","0.05522"
"125.40400","0.38335","0.08054"
"125.50400","0.37502","0.11444"
"125.60400","0.36686","0.08584"
"125.70400","0.35847","0.08044"
"125.80400","0.35014","0.11723"
"125.90400","0.34170","0.11714"
"126.00400","0.33343","0.10333"
"126.10400","0.32515","0.10435"
"126.20400","0.31682","0.09889"
"126.30400","0.30844","0.08610"
"126.40400","0.30011","0.08419"
"126.50400","0.29183","0.08535"
"126.60400","0.28339","0.08785"
"126.70400","0.27512","0.07643"
"126.80400","0.26667","0.09174"
"126.90400","0.25851","0.06146"
"127.00400","0.25018","0.10816"
"127.10400","0.24180","0.09712"
"127.20400","0.23341","0.12111"
"127.30400","0.22502","0.05285"
"127.40400","0.21675","0.03587"
"127.50400","0.20848","0.07039"
"127.60400","0.20020","0.08438"
"127.70400","0.19182","0.04991"
"127.80400","0.18349","0.07560"
"127.90400","0.17516","0.08017"
"128.00400","0.16671","0.04310"
"128.10400","0.15833","0.08598"
"128.20400","0.15005","0.09031"
"128.30400","0.14189","0.07909"
"128.40400","0.13351","0.06531"
"128.50400","0.12518","0.03977"
"128.60400","0.11668","0.04796"
"128.70400","0.10840","0.11029"
"128.80400","0.10002","0.09447"
"128.90400","0.09174","0.06124"
"129.00400","0.08341","0.07731"
"129.10400","0.07514","0.04398"
"129.20400","0.06687","0.04534"
"129.30400","0.05837","0.07813"
"129.40400","0.05009","0.07302"
"129.50400","0.04176","0.08752"
"129.60400","0.03343","0.11011"
"129.70400","0.02510","0.09530"
"129.80400","0.01672","0.08585"
"129.90400","0.00844","0.04380"
"130.00400","0.00011","0.08528"
"130.10400","-0.00816","0.07531"
"130.20400","-0.01660","0.07103"
"130.30400","-0.02499","0.05334"
"130.40400","-0.03321","0.08371"
"130.50400","-0.04154","0.07647"
"130.60400","-0.04987","0.08110"
"130.70400","-0.05825","0.04365"
"130.80400","-0.06664","0.07639"
"130.90400","-0.07486","0.07218"
"131.00400","-0.08313","0.07406"
"131.10400","-0.09157","0.09174"
"131.20400","-0.09990","0.08766"
"131.30400","-0.10823","0.06508"
"131.40400","-0.11651","0.06550"
"131.50400","-0.12489","0.08325"
"131.60400","-0.13334","0.09091"
"131.70400","-0.14150","0.08339"
"131.80400","-0.14983","0.07036"
"131.90400","-0.15821","0.06501"
"132.00400","-0.16660","0.05874"
"132.10400","-0.17493","0.05064"
"132.20400","-0.18320","0.07395"
"132.30400","-0.19148","0.04176"
"132.40400","-0.19981","0.03504"
"132.50400","-0.20825","0.07263"
"132.60400","-0.21658","0.12586"
"132.70400","-0.22497","0.07043"
"132.80400","-0.23330","0.03461"
"132.90400","-0.24163","0.06880"
"133.00400","-0.24990","0.07560"
"133.10400","-0.25817","0.07175"
"133.20400","-0.26656","0.06412"
"133.30400","-0.27489","0.11884"
"133.40400","-0.28333","0.07033"
"133.50400","-0.29149","0.07876"
"133.60400","-0.29988","0.07390"
"133.70400","-0.30815","0.09152"
"133.80400","-0.31654","0.01654"
"133.90400","-0.32487","0.06674"
"134.00400","-0.33314","0.04944"
"134.10400","-0.34170","0.05947"
"134.20400","-0.34992","0.09597"
"134.30400","-0.35830","0.08069"
"134.40400","-0.36646","0.09003"
"134.50400","-0.37479","0.07185"
"134.60400","-0.38318","0.06442"
"134.70400","-0.39157","0.08480"
"134.80400","-0.39990","0.05824"
"134.90400","-0.40834","0.05433"
"135.00400","-0.41661","0.05903"
"135.10400","-0.42483","0.07341"
"135.20400","-0.43316","0.11136"
"135.30400","-0.44149","0.13418"
"135.40400","-0.44988","0.04444"
"135.50400","-0.45826","0.09380"
"135.60400","-0.46676","0.05635"
"135.70400","-0.47498","0.08039"
"135.80400","-0.48320","0.09810"
"135.90400","-0.49153","0.05864"
"136.00400","-0.49986","0.03925"
"136.10400","-0.50824","0.03256"
"136.20400","-0.51657","0.06622"
"136.30400","-0.52502","0.04362"
"136.40400","-0.53329","0.10663"
"136.50400","-0.54156","0.05729"
"136.60400","-0.54984","0.03564"
"136.70400","-0.55817","0.05244"
"136.80400","-0.56661","0.06094"
"136.90400","-0.57488","0.10100"
"137.00400","-0.58316","0.07107"
"137.10400","-0.59154","0.06970"
"137.20400","-0.59987","0.09087"
"137.30400","-0.60826","0.07755"
"137.40400","-0.61648","0.10031"
"137.50400","-0.62481","0.09336"
"137.60400","-0.63314","0.09811"
"137.70400","-0.64164","0.07198"
"137.80400","-0.64991","0.05031"
"137.90400","-0.65818","0.07287"
"138.00400","-0.66657","0.08702"
"138.10400","-0.67490","0.10036"
"138.20400","-0.68334","0.07964"
"138.30400","-0.69162","0.10262"
"138.40400","-0.69995","0.09461"
"138.50400","-0.70822","0.05546"
"138.60400","-0.71666","0.06673"
"138.70400","-0.72494","0.08163"
"138.80400","-0.73321","0.06962"
"138.90400","-0.74154","0.07687"
"139.00400","-0.74998","0.06825"
"139.10400","-0.75826","0.07880"
"139.20400","-0.76653","0.12238"
"139.30400","-0.77486","0.06751"
"139.40400","-0.78319","0.08056"
"139.50400","-0.79163","0.11498"
"139.60400","-0.79985","0.06500"
"139.70400","-0.80818","0.03916"
"139.80400","-0.81657","0.06445"
"139.90400","-0.82490","0.06958"
"140.00400","-0.83323","0.07133"
"140.10400","-0.84156","0.06950"
"140.20400","-0.84994","0.03660"
"140.30400","-0.85822","0.07447"
"140.40400","-0.86660","0.05099"
"140.50400","-0.87488","0.07014"
"140.60400","-0.88315","0.07212"
"140.70400","-0.89159","0.05748"
"140.80400","-0.89992","0.06152"
"140.90400","-0.90837","0.06507"
"141.00400","-0.91647","0.10207"
"141.10400","-0.92486","0.10132"
"141.20400","-0.93319","0.05616"
"141.30400","-0.94163","0.07724"
"141.40400","-0.94990","0.10291"
"141.50400","-0.95823","0.06450"
"141.60400","-0.96668","0.05455"
"141.70400","-0.97501","0.03728"
"141.80400","-0.98328","0.09111"
"141.90400","-0.99138","0.07479"
"142.00400","-0.99977","0.08066"
"142.10400","-1.00821","0.07059"
"142.20400","-1.01660","0.05841"
"142.30400","-1.02493","0.06570"
"142.40400","-1.03332","0.08919"
"142.50400","-1.04159","0.05642"
"142.60400","-1.04981","0.05741"
"142.70400","-1.05814","0.11202"
"142.80400","-1.06652","0.05406"
"142.90400","-1.07491","0.05872"
"143.00400","-1.08324","0.07372"
"143.10400","-1.09174","0.07451"
"143.20400","-1.09990","0.10170"
"143.30400","-1.10823","0.04983"
"143.40400","-1.11662","0.08494"
"143.50400","-1.12495","0.04639"
"143.60400","-1.13322","0.02954"
"143.70400","-1.14155","0.09319"
"143.80400","-1.14999","0.08473"
"143.90400","-1.15827","0.07906"
"144.00400","-1.16654","0.06885"
"144.10400","-1.17476","0.05408"
"144.20400","-1.18320","0.07125"
"144.30400","-1.19159","0.07977"
"144.40400","-1.19992","0.09004"
"144.50400","-1.20825","0.09692"
"144.60400","-1.21652","0.10199"
"144.70400","-1.22491","0.07239"
"144.80400","-1.23324","0.08708"
"144.90400","-1.24157","0.08842"
"145.00400","-1.24990","0.06159"
"145.10400","-1.25823","0.03205"
"145.20400","-1.26661","0.06660"
"145.30400","-1.27483","0.05958"
"145.40400","-1.28316","0.07183"
"145.50400","-1.29155","0.06187"
"145.60400","-1.29988","0.09275"
"145.70400","-1.30826","0.10453"
"145.80400","-1.31654","0.06605"
"145.90400","-1.32487","0.10099"
"146.00400","-1.33314","0.07794"
"146.10400","-1.34158","0.07022"
"146.20400","-1.34991","0.05936"
"146.30400","-1.35830","0.07409"
"146.40400","-1.36657","0.08800"
"146.50400","-1.37496","0.05415"
"146.60400","-1.38323","0.08398"
"146.70400","-1.39151","0.05612"
"146.80400","-1.39989","0.05626"
"146.90400","-1.40828","0.08332"
"147.00400","-1.41661","0.07662"
"147.10400","-1.42483","0.08172"
"147.20400","-1.43321","0.08925"
"147.30400","-1.44154","0.07911"
"147.40400","-1.44987","0.07010"
"147.50400","-1.45820","0.07630"
"147.60400","-1.46653","0.09743"
"147.70400","-1.47492","0.08284"
"147.80400","-1.48314","0.06020"
"147.90400","-1.49152","0.10754"
"148.00400","-1.49974","0.07803"
"148.10400","-1.50813","0.10811"
"148.20400","-1.51651","0.08263"
"148.30400","-1.52496","0.09552"
"148.40400","-1.53334","0.03928"
"148.48000","-1.53952","0.09527"