File: Tension/Section_1_Group3/avocado_tension_per3.is_tens_RawData/Specimen_RawData_1.csv
Time,Extension,Load,Tensile strain (Extension),Axial Video,Tensile stress,Transverse Video
(s),(mm),(N),(mm/mm),(mm/mm),(MPa),(mm/mm)
"0.00000","0.00000","-0.34384","0.00000","0.00004","-0.03438","0.00011"
"0.20000","0.00279","9.93276","0.00003","0.00005","0.99328","0.00011"
"0.40000","0.01104","36.54967","0.00011","0.00009","3.65497","0.00007"
"0.60000","0.01782","55.97193","0.00018","0.00011","5.59719","0.00004"
"0.80000","0.02440","75.54806","0.00024","0.00013","7.55481","-0.00002"
"1.00000","0.03127","96.97630","0.00031","0.00017","9.69763","-0.00013"
"1.20000","0.03781","117.17064","0.00038","0.00021","11.71706","-0.00022"
"1.40000","0.04439","138.30482","0.00044","0.00026","13.83048","-0.00025"
"1.60000","0.05126","160.82047","0.00051","0.00030","16.08205","-0.00030"
"1.80000","0.05769","181.80406","0.00058","0.00036","18.18041","-0.00037"
"2.00000","0.06441","203.63913","0.00064","0.00042","20.36391","-0.00036"
"2.20000","0.07104","225.16765","0.00071","0.00048","22.51677","-0.00036"
"2.40000","0.07790","247.46791","0.00078","0.00059","24.74679","-0.00033"
"2.60000","0.08452","268.93646","0.00085","0.00070","26.89365","-0.00036"
"2.80000","0.09113","290.01663","0.00091","0.00085","29.00166","-0.00030"
"3.00000","0.09784","311.71335","0.00098","0.00093","31.17134","-0.00029"
"3.20000","0.10434","332.56335","0.00104","0.00102","33.25634","-0.00016"
"3.40000","0.11127","354.64908","0.00111","0.00109","35.46491","-0.00013"
"3.60000","0.11773","374.71265","0.00118","0.00114","37.47126","-0.00019"
"3.80000","0.12440","395.50107","0.00124","0.00117","39.55011","-0.00021"
"4.00000","0.13118","416.76978","0.00131","0.00121","41.67698","-0.00026"
"4.20000","0.13775","437.02182","0.00138","0.00128","43.70218","-0.00030"
"4.40000","0.14450","457.77728","0.00145","0.00132","45.77773","-0.00031"
"4.60000","0.15110","477.66409","0.00151","0.00140","47.76641","-0.00026"
"4.80000","0.15796","498.51001","0.00158","0.00146","49.85100","-0.00030"
"5.00000","0.16444","517.61847","0.00164","0.00155","51.76185","-0.00024"
"5.20000","0.17112","537.33832","0.00171","0.00162","53.73383","-0.00024"
"5.40000","0.17778","556.72864","0.00178","0.00170","55.67286","-0.00030"
"5.60000","0.18439","576.02429","0.00184","0.00176","57.60243","-0.00028"
"5.80000","0.19112","595.33563","0.00191","0.00182","59.53356","-0.00033"
"6.00000","0.19779","614.43811","0.00198","0.00188","61.44381","-0.00033"
"6.20000","0.20449","633.28052","0.00204","0.00193","63.32805","-0.00038"
"6.40000","0.21128","652.50757","0.00211","0.00194","65.25076","-0.00038"
"6.60000","0.21781","670.49072","0.00218","0.00198","67.04907","-0.00038"
"6.80000","0.22441","688.54120","0.00224","0.00203","68.85412","-0.00047"
"7.00000","0.23106","706.50092","0.00231","0.00208","70.65009","-0.00049"
"7.20000","0.23787","725.06628","0.00238","0.00212","72.50663","-0.00050"
"7.40000","0.24442","742.39520","0.00244","0.00220","74.23952","-0.00056"
"7.60000","0.25102","759.53931","0.00251","0.00229","75.95393","-0.00059"
"7.80000","0.25791","777.97992","0.00258","0.00235","77.79799","-0.00059"
"8.00000","0.26446","794.73804","0.00264","0.00243","79.47380","-0.00064"
"8.20000","0.27121","812.46503","0.00271","0.00245","81.24651","-0.00061"
"8.40000","0.27780","829.20715","0.00278","0.00246","82.92072","-0.00068"
"8.60000","0.28454","846.38483","0.00285","0.00248","84.63848","-0.00069"
"8.80000","0.29121","863.20062","0.00291","0.00251","86.32006","-0.00070"
"9.00000","0.29771","879.08954","0.00298","0.00258","87.90895","-0.00069"
"9.20000","0.30445","895.94525","0.00304","0.00263","89.59453","-0.00068"
"9.40000","0.31096","911.63123","0.00311","0.00268","91.16312","-0.00072"
"9.60000","0.31793","929.17981","0.00318","0.00275","92.91798","-0.00075"
"9.80000","0.32449","944.85413","0.00324","0.00282","94.48541","-0.00075"
"10.00000","0.33118","961.00757","0.00331","0.00289","96.10075","-0.00079"
"10.20000","0.33795","977.02368","0.00338","0.00297","97.70237","-0.00074"
"10.40000","0.34446","991.90308","0.00344","0.00301","99.19031","-0.00076"
"10.60000","0.35109","1007.25964","0.00351","0.00301","100.72597","-0.00081"
"10.80000","0.35766","1022.19556","0.00358","0.00301","102.21956","-0.00077"
"11.00000","0.36456","1038.31555","0.00365","0.00302","103.83156","-0.00080"
"11.20000","0.37109","1052.73914","0.00371","0.00306","105.27391","-0.00079"
"11.40000","0.37779","1067.53381","0.00378","0.00306","106.75338","-0.00078"
"11.60000","0.38455","1082.24219","0.00385","0.00309","108.22422","-0.00077"
"11.80000","0.39111","1096.18372","0.00391","0.00316","109.61837","-0.00075"
"12.00000","0.39792","1111.03723","0.00398","0.00327","111.10372","-0.00075"
"12.20000","0.40444","1124.42041","0.00404","0.00332","112.44204","-0.00078"
"12.40000","0.41116","1138.43384","0.00411","0.00340","113.84338","-0.00085"
"12.60000","0.41778","1151.71704","0.00418","0.00346","115.17171","-0.00084"
"12.80000","0.42446","1164.98145","0.00424","0.00352","116.49815","-0.00086"
"13.00000","0.43110","1177.92065","0.00431","0.00354","117.79207","-0.00088"
"13.20000","0.43775","1190.64441","0.00438","0.00354","119.06444","-0.00087"
"13.40000","0.44463","1204.12756","0.00445","0.00357","120.41276","-0.00087"
"13.60000","0.45117","1216.13879","0.00451","0.00359","121.61388","-0.00085"
"13.80000","0.45781","1228.34399","0.00458","0.00363","122.83440","-0.00087"
"14.00000","0.46455","1240.77551","0.00465","0.00366","124.07755","-0.00085"
"14.20000","0.47108","1252.15076","0.00471","0.00371","125.21507","-0.00086"
"14.40000","0.47777","1263.91821","0.00478","0.00379","126.39182","-0.00086"
"14.60000","0.48442","1275.84070","0.00484","0.00388","127.58407","-0.00082"
"14.80000","0.49114","1287.45386","0.00491","0.00395","128.74539","-0.00083"
"15.00000","0.49784","1299.36096","0.00498","0.00402","129.93610","-0.00086"
"15.20000","0.50448","1310.88184","0.00504","0.00409","131.08818","-0.00084"
"15.40000","0.51127","1322.76318","0.00511","0.00412","132.27632","-0.00084"
"15.60000","0.51773","1333.20251","0.00518","0.00416","133.32025","-0.00084"
"15.80000","0.52456","1345.07825","0.00525","0.00419","134.50783","-0.00082"
"16.00000","0.53112","1355.98718","0.00531","0.00421","135.59872","-0.00082"
"16.20000","0.53771","1366.77063","0.00538","0.00428","136.67706","-0.00088"
"16.40000","0.54457","1378.76953","0.00545","0.00436","137.87695","-0.00085"
"16.60000","0.55105","1388.97119","0.00551","0.00445","138.89713","-0.00086"
"16.80000","0.55779","1399.98816","0.00558","0.00452","139.99881","-0.00085"
"17.00000","0.56448","1410.73181","0.00564","0.00461","141.07318","-0.00079"
"17.20000","0.57132","1422.31189","0.00571","0.00467","142.23119","-0.00079"
"17.40000","0.57785","1432.75537","0.00578","0.00471","143.27554","-0.00079"
"17.60000","0.58441","1443.37854","0.00584","0.00476","144.33786","-0.00075"
"17.80000","0.59117","1454.51831","0.00591","0.00480","145.45183","-0.00083"
"18.00000","0.59765","1464.66833","0.00598","0.00483","146.46683","-0.00078"
"18.20000","0.60457","1476.04382","0.00605","0.00484","147.60439","-0.00076"
"18.40000","0.61108","1486.15198","0.00611","0.00488","148.61520","-0.00080"
"18.60000","0.61783","1496.73486","0.00618","0.00493","149.67349","-0.00079"
"18.80000","0.62456","1507.34570","0.00625","0.00500","150.73457","-0.00086"
"19.00000","0.63116","1517.42346","0.00631","0.00504","151.74234","-0.00079"
"19.20000","0.63780","1527.74475","0.00638","0.00509","152.77448","-0.00079"
"19.40000","0.64440","1537.83838","0.00644","0.00515","153.78384","-0.00085"
"19.60000","0.65124","1548.67700","0.00651","0.00516","154.86771","-0.00083"
"19.80000","0.65778","1558.54285","0.00658","0.00520","155.85428","-0.00087"
"20.00000","0.66443","1568.69385","0.00664","0.00521","156.86938","-0.00080"
"20.20000","0.67119","1579.44946","0.00671","0.00521","157.94495","-0.00084"
"20.40000","0.67775","1589.20325","0.00678","0.00526","158.92032","-0.00085"
"20.60000","0.68451","1599.73389","0.00685","0.00528","159.97339","-0.00090"
"20.80000","0.69118","1610.14648","0.00691","0.00532","161.01465","-0.00090"
"21.00000","0.69789","1620.80005","0.00698","0.00537","162.08000","-0.00090"
"21.20000","0.70447","1631.39514","0.00704","0.00540","163.13951","-0.00090"
"21.40000","0.71110","1642.22754","0.00711","0.00544","164.22275","-0.00097"
"21.60000","0.71777","1653.25574","0.00718","0.00549","165.32558","-0.00098"
"21.80000","0.72438","1663.95569","0.00724","0.00551","166.39557","-0.00094"
"22.00000","0.73119","1675.73096","0.00731","0.00549","167.57309","-0.00091"
"22.20000","0.73784","1686.74683","0.00738","0.00551","168.67468","-0.00098"
"22.40000","0.74447","1697.61401","0.00744","0.00551","169.76140","-0.00103"
"22.60000","0.75126","1709.38098","0.00751","0.00555","170.93810","-0.00105"
"22.80000","0.75778","1719.81604","0.00758","0.00561","171.98160","-0.00112"
"23.00000","0.76443","1730.84717","0.00764","0.00565","173.08472","-0.00114"
"23.20000","0.77104","1741.92957","0.00771","0.00570","174.19296","-0.00116"
"23.40000","0.77786","1753.44666","0.00778","0.00576","175.34467","-0.00111"
"23.60000","0.78450","1764.54932","0.00784","0.00579","176.45493","-0.00116"
"23.80000","0.79110","1775.04065","0.00791","0.00583","177.50406","-0.00125"
"24.00000","0.79789","1786.70740","0.00798","0.00582","178.67075","-0.00121"
"24.20000","0.80438","1797.03479","0.00804","0.00589","179.70348","-0.00128"
"24.40000","0.81122","1808.74219","0.00811","0.00592","180.87422","-0.00130"
"24.60000","0.81780","1819.52307","0.00818","0.00596","181.95230","-0.00131"
"24.80000","0.82446","1830.44714","0.00824","0.00602","183.04471","-0.00127"
"25.00000","0.83118","1841.61157","0.00831","0.00608","184.16116","-0.00129"
"25.20000","0.83776","1852.08044","0.00838","0.00612","185.20804","-0.00128"
"25.40000","0.84449","1863.37646","0.00844","0.00619","186.33765","-0.00135"
"25.60000","0.85104","1873.81396","0.00851","0.00626","187.38139","-0.00139"
"25.80000","0.85797","1885.78186","0.00858","0.00633","188.57819","-0.00146"
"26.00000","0.86448","1896.08264","0.00864","0.00638","189.60826","-0.00146"
"26.20000","0.87113","1906.75354","0.00871","0.00639","190.67535","-0.00146"
"26.40000","0.87788","1917.93982","0.00878","0.00644","191.79398","-0.00150"
"26.60000","0.88439","1928.23267","0.00884","0.00647","192.82327","-0.00146"
"26.80000","0.89109","1939.13098","0.00891","0.00651","193.91310","-0.00149"
"27.00000","0.89775","1950.15540","0.00898","0.00654","195.01553","-0.00143"
"27.20000","0.90453","1961.57117","0.00905","0.00659","196.15712","-0.00146"
"27.40000","0.91118","1972.23792","0.00911","0.00665","197.22379","-0.00149"
"27.60000","0.91780","1982.66846","0.00918","0.00669","198.26685","-0.00149"
"27.80000","0.92449","1993.59595","0.00924","0.00677","199.35959","-0.00148"
"28.00000","0.93107","2004.07227","0.00931","0.00684","200.40723","-0.00153"
"28.20000","0.93788","2015.65918","0.00938","0.00693","201.56592","-0.00153"
"28.40000","0.94442","2025.78040","0.00944","0.00698","202.57803","-0.00158"
"28.60000","0.95104","2036.49219","0.00951","0.00706","203.64922","-0.00156"
"28.80000","0.95793","2047.93127","0.00958","0.00709","204.79312","-0.00155"
"29.00000","0.96442","2057.95679","0.00964","0.00711","205.79568","-0.00154"
"29.20000","0.97113","2068.74561","0.00971","0.00713","206.87456","-0.00158"
"29.40000","0.97778","2079.53247","0.00978","0.00715","207.95325","-0.00158"
"29.60000","0.98456","2090.68872","0.00985","0.00718","209.06888","-0.00163"
"29.80000","0.99114","2100.89648","0.00991","0.00721","210.08965","-0.00167"
"30.00000","0.99776","2111.56299","0.00998","0.00725","211.15630","-0.00168"
"30.20000","1.00450","2122.40186","0.01005","0.00730","212.24019","-0.00164"
"30.40000","1.01099","2132.41504","0.01011","0.00736","213.24150","-0.00166"
"30.60000","1.01783","2143.67188","0.01018","0.00742","214.36719","-0.00166"
"30.80000","1.02447","2154.33960","0.01024","0.00748","215.43396","-0.00170"
"31.00000","1.03115","2165.12939","0.01031","0.00753","216.51294","-0.00170"
"31.20000","1.03795","2176.33887","0.01038","0.00760","217.63388","-0.00168"
"31.40000","1.04442","2186.02319","0.01044","0.00764","218.60233","-0.00172"
"31.60000","1.05110","2196.37451","0.01051","0.00767","219.63745","-0.00171"
"31.80000","1.05772","2206.76709","0.01058","0.00772","220.67671","-0.00174"
"32.00000","1.06458","2218.00928","0.01065","0.00775","221.80093","-0.00179"
"32.20000","1.07107","2227.82080","0.01071","0.00778","222.78207","-0.00183"
"32.40000","1.07781","2238.43945","0.01078","0.00782","223.84395","-0.00184"
"32.60000","1.08456","2249.39941","0.01085","0.00783","224.93994","-0.00187"
"32.80000","1.09105","2258.94336","0.01091","0.00792","225.89433","-0.00191"
"33.00000","1.09783","2269.60938","0.01098","0.00795","226.96094","-0.00195"
"33.20000","1.10447","2279.70044","0.01104","0.00804","227.97005","-0.00191"
"33.40000","1.11118","2289.91406","0.01111","0.00810","228.99141","-0.00195"
"33.60000","1.11781","2299.93457","0.01118","0.00814","229.99345","-0.00192"
"33.80000","1.12443","2309.65283","0.01124","0.00819","230.96529","-0.00194"
"34.00000","1.13110","2319.10938","0.01131","0.00828","231.91093","-0.00195"
"34.20000","1.13773","2328.51587","0.01138","0.00831","232.85159","-0.00194"
"34.40000","1.14458","2338.37646","0.01145","0.00837","233.83765","-0.00197"
"34.60000","1.15114","2347.50757","0.01151","0.00838","234.75076","-0.00195"
"34.80000","1.15776","2356.64258","0.01158","0.00844","235.66426","-0.00199"
"35.00000","1.16455","2366.96875","0.01165","0.00849","236.69687","-0.00207"
"35.20000","1.17108","2376.07642","0.01171","0.00854","237.60764","-0.00206"
"35.40000","1.17775","2385.85400","0.01178","0.00859","238.58540","-0.00207"
"35.60000","1.18445","2395.55493","0.01184","0.00860","239.55550","-0.00202"
"35.80000","1.19118","2405.39233","0.01191","0.00865","240.53923","-0.00203"
"36.00000","1.19782","2415.34009","0.01198","0.00870","241.53401","-0.00206"
"36.20000","1.20441","2424.72827","0.01204","0.00879","242.47282","-0.00214"
"36.40000","1.21120","2435.14819","0.01211","0.00883","243.51482","-0.00219"
"36.60000","1.21768","2444.20239","0.01218","0.00882","244.42024","-0.00221"
"36.80000","1.22454","2454.85474","0.01225","0.00886","245.48547","-0.00219"
"37.00000","1.23116","2464.52808","0.01231","0.00888","246.45280","-0.00213"
"37.20000","1.23776","2474.10864","0.01238","0.00888","247.41086","-0.00215"
"37.40000","1.24451","2484.40845","0.01245","0.00891","248.44084","-0.00213"
"37.60000","1.25105","2493.75732","0.01251","0.00895","249.37573","-0.00214"
"37.80000","1.25780","2503.88135","0.01258","0.00898","250.38814","-0.00218"
"38.00000","1.26438","2513.52393","0.01264","0.00900","251.35239","-0.00222"
"38.20000","1.27126","2524.22681","0.01271","0.00904","252.42268","-0.00222"
"38.40000","1.27783","2533.61694","0.01278","0.00904","253.36169","-0.00221"
"38.60000","1.28439","2542.88477","0.01284","0.00907","254.28848","-0.00223"
"38.80000","1.29126","2553.72681","0.01291","0.00912","255.37268","-0.00222"
"39.00000","1.29765","2562.55933","0.01298","0.00914","256.25592","-0.00227"
"39.20000","1.30446","2572.95142","0.01304","0.00919","257.29514","-0.00231"
"39.40000","1.31109","2582.59766","0.01311","0.00918","258.25977","-0.00231"
"39.60000","1.31793","2592.93799","0.01318","0.00919","259.29379","-0.00230"
"39.80000","1.32445","2602.14258","0.01324","0.00921","260.21426","-0.00234"
"40.00000","1.33109","2611.72046","0.01331","0.00924","261.17206","-0.00236"
"40.20000","1.33779","2621.67554","0.01338","0.00926","262.16754","-0.00230"
"40.40000","1.34434","2631.28345","0.01344","0.00928","263.12836","-0.00228"
"40.60000","1.35130","2642.19482","0.01351","0.00932","264.21948","-0.00225"
"40.80000","1.35778","2651.39990","0.01358","0.00936","265.13998","-0.00230"
"41.00000","1.36441","2661.17334","0.01364","0.00940","266.11734","-0.00230"
"41.20000","1.37117","2671.49683","0.01371","0.00946","267.14969","-0.00234"
"41.40000","1.37779","2681.49341","0.01378","0.00954","268.14935","-0.00235"
"41.60000","1.38439","2691.21094","0.01384","0.00961","269.12109","-0.00235"
"41.80000","1.39111","2701.44263","0.01391","0.00968","270.14426","-0.00231"
"42.00000","1.39787","2711.59595","0.01398","0.00975","271.15961","-0.00233"
"42.20000","1.40452","2721.35791","0.01405","0.00974","272.13580","-0.00240"
"42.40000","1.41112","2730.84570","0.01411","0.00982","273.08456","-0.00237"
"42.60000","1.41782","2740.97388","0.01418","0.00984","274.09738","-0.00239"
"42.80000","1.42438","2750.48193","0.01424","0.00986","275.04819","-0.00240"
"43.00000","1.43115","2760.99487","0.01431","0.00991","276.09949","-0.00240"
"43.20000","1.43783","2771.27759","0.01438","0.00991","277.12775","-0.00241"
"43.40000","1.44442","2780.82886","0.01444","0.00998","278.08289","-0.00240"
"43.60000","1.45120","2791.26025","0.01451","0.01005","279.12604","-0.00237"
"43.80000","1.45775","2800.82031","0.01458","0.01012","280.08203","-0.00240"
"44.00000","1.46448","2811.06738","0.01464","0.01017","281.10675","-0.00240"
"44.20000","1.47110","2820.80908","0.01471","0.01022","282.08090","-0.00240"
"44.40000","1.47790","2831.42236","0.01478","0.01026","283.14224","-0.00239"
"44.60000","1.48447","2841.03833","0.01484","0.01032","284.10382","-0.00237"
"44.80000","1.49106","2850.61548","0.01491","0.01038","285.06155","-0.00231"
"45.00000","1.49795","2861.39624","0.01498","0.01043","286.13962","-0.00227"
"45.20000","1.50432","2870.30005","0.01504","0.01050","287.03000","-0.00234"
"45.40000","1.51108","2880.76782","0.01511","0.01053","288.07678","-0.00239"
"45.60000","1.51774","2890.82349","0.01518","0.01059","289.08234","-0.00242"
"45.80000","1.52455","2901.34058","0.01525","0.01061","290.13406","-0.00244"
"46.00000","1.53125","2911.53125","0.01531","0.01066","291.15314","-0.00241"
"46.20000","1.53779","2920.87354","0.01538","0.01071","292.08734","-0.00244"
"46.40000","1.54447","2930.89893","0.01544","0.01074","293.08990","-0.00244"
"46.60000","1.55100","2940.23315","0.01551","0.01077","294.02332","-0.00244"
"46.80000","1.55796","2951.25366","0.01558","0.01086","295.12537","-0.00247"
"47.00000","1.56438","2960.44751","0.01564","0.01091","296.04474","-0.00249"
"47.20000","1.57104","2970.22729","0.01571","0.01094","297.02274","-0.00251"
"47.40000","1.57788","2980.95166","0.01578","0.01098","298.09515","-0.00249"
"47.60000","1.58441","2990.14624","0.01584","0.01101","299.01462","-0.00250"
"47.80000","1.59118","3000.39233","0.01591","0.01103","300.03925","-0.00245"
"48.00000","1.59778","3010.22632","0.01598","0.01109","301.02264","-0.00244"
"48.20000","1.60459","3020.61914","0.01605","0.01115","302.06192","-0.00244"
"48.40000","1.61111","3030.21094","0.01611","0.01116","303.02109","-0.00244"
"48.60000","1.61778","3040.14160","0.01618","0.01120","304.01416","-0.00244"
"48.80000","1.62443","3049.97510","0.01624","0.01125","304.99750","-0.00248"
"49.00000","1.63105","3059.88281","0.01631","0.01128","305.98828","-0.00247"
"49.20000","1.63784","3070.32178","0.01638","0.01134","307.03217","-0.00251"
"49.40000","1.64448","3080.14624","0.01644","0.01138","308.01462","-0.00253"
"49.60000","1.65114","3089.81641","0.01651","0.01141","308.98163","-0.00257"
"49.80000","1.65795","3100.51074","0.01658","0.01143","310.05109","-0.00262"
"50.00000","1.66446","3109.70166","0.01664","0.01148","310.97015","-0.00269"
"50.20000","1.67110","3119.44067","0.01671","0.01152","311.94406","-0.00268"
"50.40000","1.67778","3129.36792","0.01678","0.01156","312.93680","-0.00266"
"50.60000","1.68454","3139.59351","0.01685","0.01162","313.95935","-0.00266"
"50.80000","1.69110","3149.31616","0.01691","0.01166","314.93161","-0.00269"
"51.00000","1.69767","3158.95166","0.01698","0.01165","315.89517","-0.00270"
"51.20000","1.70457","3169.81079","0.01705","0.01170","316.98108","-0.00274"
"51.40000","1.71110","3179.17578","0.01711","0.01173","317.91757","-0.00271"
"51.60000","1.71791","3189.65430","0.01718","0.01178","318.96542","-0.00274"
"51.80000","1.72450","3199.27710","0.01725","0.01181","319.92770","-0.00278"
"52.00000","1.73115","3209.18555","0.01731","0.01185","320.91855","-0.00285"
"52.20000","1.73793","3219.79639","0.01738","0.01192","321.97964","-0.00287"
"52.40000","1.74435","3228.80225","0.01744","0.01194","322.88022","-0.00293"
"52.60000","1.75109","3239.08887","0.01751","0.01201","323.90887","-0.00281"
"52.80000","1.75764","3248.68140","0.01758","0.01204","324.86813","-0.00286"
"53.00000","1.76461","3259.83862","0.01765","0.01208","325.98386","-0.00289"
"53.20000","1.77118","3269.67163","0.01771","0.01212","326.96716","-0.00297"
"53.40000","1.77782","3279.62109","0.01778","0.01218","327.96210","-0.00294"
"53.60000","1.78463","3290.37646","0.01785","0.01220","329.03766","-0.00295"
"53.80000","1.79109","3299.87134","0.01791","0.01222","329.98712","-0.00299"
"54.00000","1.79778","3309.96411","0.01798","0.01223","330.99640","-0.00296"
"54.20000","1.80436","3319.72607","0.01804","0.01229","331.97260","-0.00296"
"54.40000","1.81118","3330.43457","0.01811","0.01234","333.04346","-0.00298"
"54.60000","1.81778","3340.33105","0.01818","0.01236","334.03311","-0.00304"
"54.80000","1.82442","3350.50708","0.01824","0.01243","335.05072","-0.00309"
"55.00000","1.83121","3361.04224","0.01831","0.01248","336.10422","-0.00304"
"55.20000","1.83778","3370.70190","0.01838","0.01252","337.07019","-0.00304"
"55.40000","1.84462","3381.41699","0.01845","0.01256","338.14169","-0.00307"
"55.60000","1.85112","3390.89966","0.01851","0.01261","339.08997","-0.00309"
"55.80000","1.85778","3400.95312","0.01858","0.01270","340.09531","-0.00312"
"56.00000","1.86450","3411.23535","0.01865","0.01277","341.12354","-0.00306"
"56.20000","1.87109","3421.03833","0.01871","0.01281","342.10382","-0.00305"
"56.40000","1.87771","3431.04590","0.01878","0.01287","343.10458","-0.00311"
"56.60000","1.88444","3441.38696","0.01884","0.01293","344.13870","-0.00323"
"56.80000","1.89130","3452.10254","0.01891","0.01297","345.21027","-0.00325"
"57.00000","1.89790","3461.94775","0.01898","0.01300","346.19476","-0.00323"
"57.20000","1.90447","3471.48145","0.01904","0.01304","347.14813","-0.00324"
"57.40000","1.91119","3481.71973","0.01911","0.01311","348.17197","-0.00325"
"57.60000","1.91771","3490.98145","0.01918","0.01318","349.09814","-0.00327"
"57.80000","1.92444","3501.30713","0.01924","0.01321","350.13071","-0.00334"
"58.00000","1.93112","3511.56299","0.01931","0.01322","351.15631","-0.00335"
"58.20000","1.93775","3521.30347","0.01938","0.01328","352.13034","-0.00340"
"58.40000","1.94455","3531.84204","0.01945","0.01333","353.18420","-0.00334"
"58.60000","1.95116","3541.48975","0.01951","0.01337","354.14899","-0.00338"
"58.80000","1.95790","3551.90967","0.01958","0.01343","355.19098","-0.00337"
"59.00000","1.96439","3561.22437","0.01964","0.01349","356.12244","-0.00344"
"59.20000","1.97125","3572.13354","0.01971","0.01356","357.21335","-0.00347"
"59.40000","1.97783","3581.57349","0.01978","0.01363","358.15735","-0.00345"
"59.60000","1.98436","3590.76196","0.01984","0.01366","359.07620","-0.00347"
"59.80000","1.99124","3601.57788","0.01991","0.01367","360.15778","-0.00352"
"60.00000","1.99766","3610.63379","0.01998","0.01374","361.06339","-0.00356"
"60.20000","2.00446","3621.06421","0.02004","0.01377","362.10641","-0.00352"
"60.40000","2.01116","3631.15625","0.02011","0.01381","363.11563","-0.00352"
"60.60000","2.01800","3641.70850","0.02018","0.01385","364.17084","-0.00355"
"60.80000","2.02453","3651.02002","0.02025","0.01389","365.10199","-0.00359"
"61.00000","2.03111","3660.57788","0.02031","0.01394","366.05780","-0.00361"
"61.20000","2.03785","3670.80835","0.02038","0.01400","367.08084","-0.00360"
"61.40000","2.04430","3679.84399","0.02044","0.01405","367.98441","-0.00361"
"61.60000","2.05122","3690.91968","0.02051","0.01409","369.09198","-0.00364"
"61.80000","2.05774","3700.51831","0.02058","0.01414","370.05182","-0.00368"
"62.00000","2.06446","3710.60229","0.02064","0.01419","371.06024","-0.00371"
"62.20000","2.07127","3721.07446","0.02071","0.01422","372.10745","-0.00371"
"62.40000","2.07786","3730.42896","0.02078","0.01426","373.04291","-0.00371"
"62.60000","2.08450","3740.25513","0.02085","0.01429","374.02551","-0.00375"
"62.80000","2.09103","3749.54004","0.02091","0.01433","374.95401","-0.00376"
"63.00000","2.09792","3760.28052","0.02098","0.01437","376.02805","-0.00374"
"63.20000","2.10442","3769.54590","0.02104","0.01441","376.95459","-0.00383"
"63.40000","2.11108","3779.34009","0.02111","0.01444","377.93402","-0.00385"
"63.60000","2.11784","3789.43604","0.02118","0.01451","378.94360","-0.00382"
"63.80000","2.12440","3798.73633","0.02124","0.01452","379.87363","-0.00382"
"64.00000","2.13122","3809.07764","0.02131","0.01459","380.90778","-0.00380"
"64.20000","2.13785","3818.66650","0.02138","0.01463","381.86664","-0.00385"
"64.40000","2.14451","3828.49976","0.02145","0.01467","382.84998","-0.00390"
"64.60000","2.15118","3838.35889","0.02151","0.01475","383.83588","-0.00395"
"64.80000","2.15777","3847.73657","0.02158","0.01476","384.77365","-0.00390"
"65.00000","2.16442","3857.35034","0.02164","0.01479","385.73505","-0.00394"
"65.20000","2.17104","3866.96484","0.02171","0.01481","386.69647","-0.00394"
"65.40000","2.17785","3877.39282","0.02178","0.01483","387.73929","-0.00394"
"65.60000","2.18453","3887.09497","0.02185","0.01488","388.70950","-0.00399"
"65.80000","2.19108","3896.27588","0.02191","0.01490","389.62759","-0.00396"
"66.00000","2.19792","3906.87036","0.02198","0.01494","390.68704","-0.00398"
"66.20000","2.20441","3916.02710","0.02204","0.01498","391.60272","-0.00407"
"66.40000","2.21115","3926.01343","0.02211","0.01503","392.60135","-0.00413"
"66.60000","2.21776","3935.35913","0.02218","0.01508","393.53592","-0.00409"
"66.80000","2.22450","3945.13989","0.02224","0.01514","394.51398","-0.00409"
"67.00000","2.23120","3955.16162","0.02231","0.01519","395.51617","-0.00415"
"67.20000","2.23773","3964.30566","0.02238","0.01526","396.43057","-0.00416"
"67.40000","2.24453","3974.73682","0.02245","0.01534","397.47369","-0.00419"
"67.60000","2.25104","3983.86792","0.02251","0.01537","398.38678","-0.00424"
"67.80000","2.25795","3994.34131","0.02258","0.01541","399.43414","-0.00428"
"68.00000","2.26449","4003.67334","0.02264","0.01544","400.36734","-0.00422"
"68.20000","2.27110","4013.32935","0.02271","0.01546","401.33295","-0.00427"
"68.40000","2.27786","4023.47510","0.02278","0.01547","402.34750","-0.00429"
"68.60000","2.28441","4032.79956","0.02284","0.01555","403.27997","-0.00434"
"68.80000","2.29118","4042.87793","0.02291","0.01560","404.28778","-0.00438"
"69.00000","2.29774","4052.42334","0.02298","0.01564","405.24234","-0.00435"
"69.20000","2.30461","4062.99487","0.02305","0.01568","406.29950","-0.00442"
"69.40000","2.31116","4072.36182","0.02311","0.01573","407.23618","-0.00440"
"69.60000","2.31779","4082.11792","0.02318","0.01580","408.21179","-0.00444"
"69.80000","2.32451","4092.18042","0.02325","0.01590","409.21805","-0.00450"
"70.00000","2.33103","4101.46436","0.02331","0.01599","410.14642","-0.00451"
"70.20000","2.33783","4111.73877","0.02338","0.01605","411.17389","-0.00453"
"70.40000","2.34446","4121.29053","0.02344","0.01611","412.12906","-0.00452"
"70.60000","2.35116","4131.03271","0.02351","0.01613","413.10327","-0.00454"
"70.80000","2.35784","4140.73047","0.02358","0.01618","414.07306","-0.00457"
"71.00000","2.36445","4150.43408","0.02364","0.01618","415.04340","-0.00455"
"71.20000","2.37115","4160.22217","0.02371","0.01617","416.02222","-0.00460"
"71.40000","2.37775","4169.85303","0.02378","0.01622","416.98529","-0.00460"
"71.60000","2.38456","4180.08594","0.02385","0.01626","418.00861","-0.00462"
"71.80000","2.39111","4189.33105","0.02391","0.01629","418.93311","-0.00472"
"72.00000","2.39773","4198.91309","0.02398","0.01632","419.89130","-0.00475"
"72.20000","2.40456","4209.43848","0.02405","0.01638","420.94385","-0.00476"
"72.40000","2.41104","4218.58984","0.02411","0.01643","421.85898","-0.00475"
"72.60000","2.41780","4228.57910","0.02418","0.01649","422.85791","-0.00480"
"72.80000","2.42449","4238.42383","0.02424","0.01654","423.84238","-0.00480"
"73.00000","2.43123","4248.35303","0.02431","0.01662","424.83530","-0.00482"
"73.20000","2.43781","4257.68896","0.02438","0.01666","425.76889","-0.00484"
"73.40000","2.44440","4267.18555","0.02444","0.01671","426.71857","-0.00488"
"73.60000","2.45115","4277.25732","0.02451","0.01677","427.72574","-0.00486"
"73.80000","2.45766","4286.35889","0.02458","0.01678","428.63589","-0.00486"
"74.00000","2.46452","4296.75732","0.02465","0.01683","429.67572","-0.00489"
"74.20000","2.47116","4306.27148","0.02471","0.01681","430.62714","-0.00493"
"74.40000","2.47778","4315.68115","0.02478","0.01687","431.56812","-0.00502"
"74.60000","2.48465","4326.27783","0.02485","0.01689","432.62778","-0.00499"
"74.80000","2.49107","4335.11084","0.02491","0.01693","433.51108","-0.00503"
"75.00000","2.49774","4344.74854","0.02498","0.01699","434.47485","-0.00504"
"75.20000","2.50437","4354.44238","0.02504","0.01705","435.44424","-0.00510"
"75.40000","2.51124","4364.99219","0.02511","0.01712","436.49921","-0.00505"
"75.60000","2.51776","4373.99170","0.02518","0.01716","437.39917","-0.00512"
"75.80000","2.52444","4383.76562","0.02524","0.01722","438.37656","-0.00514"
"76.00000","2.53122","4393.83398","0.02531","0.01725","439.38339","-0.00514"
"76.20000","2.53770","4402.92480","0.02538","0.01732","440.29248","-0.00518"
"76.40000","2.54454","4413.32227","0.02545","0.01734","441.33221","-0.00517"
"76.60000","2.55111","4422.55127","0.02551","0.01737","442.25513","-0.00518"
"76.80000","2.55779","4432.23096","0.02558","0.01739","443.22308","-0.00520"
"77.00000","2.56452","4442.30322","0.02565","0.01741","444.23032","-0.00525"
"77.20000","2.57110","4451.55029","0.02571","0.01748","445.15503","-0.00521"
"77.40000","2.57776","4461.22754","0.02578","0.01752","446.12274","-0.00525"
"77.60000","2.58440","4470.87939","0.02584","0.01757","447.08795","-0.00527"
"77.80000","2.59125","4481.56152","0.02591","0.01766","448.15616","-0.00531"
"78.00000","2.59780","4490.77100","0.02598","0.01774","449.07709","-0.00531"
"78.20000","2.60444","4500.35205","0.02604","0.01781","450.03522","-0.00528"
"78.40000","2.61126","4510.77930","0.02611","0.01782","451.07794","-0.00537"
"78.60000","2.61772","4519.74072","0.02618","0.01788","451.97406","-0.00541"
"78.80000","2.62443","4529.56201","0.02624","0.01791","452.95621","-0.00544"
"79.00000","2.63111","4539.02002","0.02631","0.01796","453.90201","-0.00545"
"79.20000","2.63779","4548.55566","0.02638","0.01802","454.85556","-0.00547"
"79.40000","2.64453","4558.43604","0.02645","0.01807","455.84360","-0.00544"
"79.60000","2.65109","4567.59180","0.02651","0.01810","456.75919","-0.00551"
"79.80000","2.65787","4577.69775","0.02658","0.01815","457.76978","-0.00551"
"80.00000","2.66437","4586.70312","0.02664","0.01817","458.67032","-0.00547"
"80.20000","2.67123","4596.93457","0.02671","0.01822","459.69345","-0.00544"
"80.40000","2.67781","4606.37158","0.02678","0.01830","460.63715","-0.00544"
"80.60000","2.68439","4615.58643","0.02684","0.01838","461.55865","-0.00552"
"80.80000","2.69122","4625.81250","0.02691","0.01842","462.58124","-0.00557"
"81.00000","2.69770","4634.62793","0.02698","0.01851","463.46280","-0.00563"
"81.20000","2.70446","4644.53369","0.02704","0.01858","464.45337","-0.00572"
"81.40000","2.71108","4654.01611","0.02711","0.01862","465.40161","-0.00574"
"81.60000","2.71793","4664.43066","0.02718","0.01867","466.44305","-0.00571"
"81.80000","2.72450","4673.73535","0.02725","0.01869","467.37354","-0.00577"
"82.00000","2.73106","4682.53027","0.02731","0.01873","468.25302","-0.00583"
"82.20000","2.73787","4692.28711","0.02738","0.01873","469.22870","-0.00579"
"82.40000","2.74432","4700.67920","0.02744","0.01877","470.06793","-0.00576"
"82.60000","2.75118","4710.75342","0.02751","0.01879","471.07535","-0.00578"
"82.80000","2.75775","4719.90430","0.02758","0.01885","471.99042","-0.00579"
"83.00000","2.76455","4729.68506","0.02765","0.01890","472.96851","-0.00581"
"83.20000","2.77113","4738.88232","0.02771","0.01894","473.88824","-0.00585"
"83.40000","2.77776","4748.24854","0.02778","0.01899","474.82486","-0.00587"
"83.60000","2.78448","4757.74463","0.02784","0.01906","475.77448","-0.00592"
"83.80000","2.79104","4766.74170","0.02791","0.01912","476.67416","-0.00595"
"84.00000","2.79794","4777.19482","0.02798","0.01915","477.71948","-0.00591"
"84.20000","2.80442","4786.03955","0.02804","0.01922","478.60394","-0.00596"
"84.40000","2.81108","4795.40137","0.02811","0.01924","479.54013","-0.00598"
"84.60000","2.81784","4805.28711","0.02818","0.01927","480.52872","-0.00604"
"84.80000","2.82441","4814.11865","0.02824","0.01929","481.41187","-0.00604"
"85.00000","2.83107","4823.51367","0.02831","0.01930","482.35138","-0.00607"
"85.20000","2.83781","4833.38086","0.02838","0.01931","483.33807","-0.00607"
"85.40000","2.84452","4842.51123","0.02845","0.01934","484.25113","-0.00604"
"85.60000","2.85114","4851.62207","0.02851","0.01937","485.16220","-0.00603"
"85.80000","2.85778","4860.59473","0.02858","0.01942","486.05948","-0.00598"
"86.00000","2.86444","4869.60400","0.02864","0.01948","486.96039","-0.00600"
"86.20000","2.87105","4878.36084","0.02871","0.01954","487.83609","-0.00605"
"86.40000","2.87785","4888.26562","0.02878","0.01962","488.82657","-0.00604"
"86.60000","2.88451","4897.52002","0.02885","0.01966","489.75201","-0.00606"
"86.80000","2.89105","4906.28906","0.02891","0.01972","490.62891","-0.00604"
"87.00000","2.89791","4916.51904","0.02898","0.01977","491.65192","-0.00605"
"87.20000","2.90437","4924.74365","0.02904","0.01978","492.47437","-0.00611"
"87.40000","2.91114","4934.53857","0.02911","0.01981","493.45386","-0.00613"
"87.60000","2.91779","4943.83398","0.02918","0.01986","494.38339","-0.00612"
"87.80000","2.92458","4953.59717","0.02925","0.01992","495.35971","-0.00615"
"88.00000","2.93116","4962.72559","0.02931","0.01996","496.27255","-0.00615"
"88.20000","2.93770","4971.28613","0.02938","0.01998","497.12860","-0.00615"
"88.40000","2.94459","4981.44287","0.02945","0.02003","498.14429","-0.00614"
"88.60000","2.95097","4989.76709","0.02951","0.02007","498.97672","-0.00614"
"88.80000","2.95781","4999.60254","0.02958","0.02016","499.96027","-0.00606"
"89.00000","2.96444","5008.62598","0.02964","0.02021","500.86261","-0.00607"
"89.20000","2.97116","5017.80078","0.02971","0.02029","501.78009","-0.00609"
"89.40000","2.97794","5026.43896","0.02978","0.02042","502.64389","-0.00603"
"89.60000","2.98442","5035.01465","0.02984","0.02057","503.50146","-0.00601"
"89.80000","2.99108","5044.26514","0.02991","0.02068","504.42651","-0.00591"
"90.00000","2.99770","5053.47754","0.02998","0.02077","505.34775","-0.00592"
"90.20000","3.00466","5063.54834","0.03005","0.02084","506.35483","-0.00593"
"90.40000","3.01106","5071.98291","0.03011","0.02090","507.19830","-0.00602"
"90.60000","3.01772","5081.05420","0.03018","0.02093","508.10541","-0.00600"
"90.80000","3.02452","5090.79150","0.03025","0.02097","509.07916","-0.00597"
"91.00000","3.03105","5099.34326","0.03031","0.02101","509.93433","-0.00604"
"91.20000","3.03788","5109.13672","0.03038","0.02109","510.91367","-0.00605"
"91.40000","3.04446","5117.91406","0.03044","0.02114","511.79141","-0.00604"
"91.60000","3.05120","5127.28662","0.03051","0.02119","512.72864","-0.00600"
"91.80000","3.05783","5136.11133","0.03058","0.02125","513.61115","-0.00603"
"92.00000","3.06448","5144.89404","0.03064","0.02127","514.48938","-0.00611"
"92.20000","3.07106","5153.66406","0.03071","0.02131","515.36639","-0.00609"
"92.40000","3.07771","5162.70605","0.03078","0.02134","516.27063","-0.00609"
"92.60000","3.08453","5172.30273","0.03085","0.02140","517.23029","-0.00610"
"92.80000","3.09114","5181.20654","0.03091","0.02137","518.12067","-0.00620"
"93.00000","3.09780","5190.28760","0.03098","0.02141","519.02875","-0.00622"
"93.20000","3.10462","5199.91846","0.03105","0.02145","519.99182","-0.00626"
"93.40000","3.11109","5208.24121","0.03111","0.02153","520.82410","-0.00621"
"93.60000","3.11774","5217.42725","0.03118","0.02162","521.74274","-0.00623"
"93.80000","3.12446","5226.44873","0.03124","0.02166","522.64490","-0.00626"
"94.00000","3.13119","5235.58643","0.03131","0.02175","523.55865","-0.00626"
"94.20000","3.13778","5244.07178","0.03138","0.02182","524.40717","-0.00627"
"94.40000","3.14435","5252.74707","0.03144","0.02188","525.27472","-0.00629"
"94.60000","3.15121","5262.46289","0.03151","0.02193","526.24628","-0.00634"
"94.80000","3.15773","5271.02686","0.03158","0.02202","527.10266","-0.00637"
"95.00000","3.16460","5280.85205","0.03165","0.02206","528.08521","-0.00633"
"95.20000","3.17118","5289.67871","0.03171","0.02211","528.96790","-0.00634"
"95.40000","3.17778","5298.22168","0.03178","0.02214","529.82214","-0.00634"
"95.60000","3.18463","5307.82178","0.03185","0.02218","530.78217","-0.00633"
"95.80000","3.19104","5315.76562","0.03191","0.02224","531.57654","-0.00635"
"96.00000","3.19773","5324.68506","0.03198","0.02227","532.46851","-0.00638"
"96.20000","3.20429","5333.03271","0.03204","0.02232","533.30328","-0.00651"
"96.40000","3.21128","5343.05469","0.03211","0.02239","534.30548","-0.00656"
"96.60000","3.21784","5351.59131","0.03218","0.02247","535.15912","-0.00657"
"96.80000","3.22448","5360.35840","0.03224","0.02250","536.03583","-0.00656"
"97.00000","3.23128","5369.83105","0.03231","0.02255","536.98309","-0.00662"
"97.20000","3.23773","5377.88965","0.03238","0.02260","537.78894","-0.00665"
"97.40000","3.24448","5387.01807","0.03244","0.02261","538.70178","-0.00664"
"97.60000","3.25106","5395.00195","0.03251","0.02263","539.50018","-0.00662"
"97.80000","3.25782","5403.40527","0.03258","0.02265","540.34052","-0.00664"
"98.00000","3.26446","5411.61621","0.03264","0.02267","541.16162","-0.00671"
"98.20000","3.27113","5420.07812","0.03271","0.02267","542.00781","-0.00673"
"98.40000","3.27787","5429.20361","0.03278","0.02270","542.92035","-0.00672"
"98.60000","3.28445","5437.67676","0.03284","0.02278","543.76770","-0.00681"
"98.80000","3.29133","5447.24121","0.03291","0.02284","544.72412","-0.00682"
"99.00000","3.29779","5455.32764","0.03298","0.02291","545.53278","-0.00686"
"99.20000","3.30442","5464.09766","0.03304","0.02296","546.40979","-0.00690"
"99.40000","3.31116","5472.99902","0.03311","0.02302","547.29993","-0.00687"
"99.60000","3.31774","5481.51758","0.03318","0.02309","548.15173","-0.00691"
"99.80000","3.32441","5490.09424","0.03324","0.02312","549.00940","-0.00687"
"100.00000","3.33113","5498.64453","0.03331","0.02320","549.86444","-0.00688"
"100.20000","3.33793","5507.61768","0.03338","0.02324","550.76178","-0.00687"
"100.40000","3.34458","5516.39258","0.03345","0.02326","551.63928","-0.00689"
"100.60000","3.35110","5523.61865","0.03351","0.02329","552.36188","-0.00690"
"100.80000","3.35785","5532.18896","0.03358","0.02332","553.21887","-0.00684"
"101.00000","3.36442","5539.03857","0.03364","0.02340","553.90387","-0.00687"
"101.20000","3.37113","5546.71338","0.03371","0.02343","554.67133","-0.00694"
"101.40000","3.37779","5553.67432","0.03378","0.02347","555.36743","-0.00698"
"101.60000","3.38436","5560.85986","0.03384","0.02351","556.08600","-0.00701"
"101.80000","3.39125","5568.95557","0.03391","0.02358","556.89557","-0.00701"
"102.00000","3.39779","5575.52686","0.03398","0.02364","557.55267","-0.00707"
"102.20000","3.40457","5583.01416","0.03405","0.02370","558.30139","-0.00710"
"102.40000","3.41111","5590.21338","0.03411","0.02375","559.02136","-0.00704"
"102.60000","3.41793","5598.74268","0.03418","0.02377","559.87427","-0.00705"
"102.80000","3.42450","5604.66699","0.03424","0.02379","560.46667","-0.00707"
"103.00000","3.43100","5610.32520","0.03431","0.02382","561.03253","-0.00704"
"103.20000","3.43790","5615.96973","0.03438","0.02384","561.59698","-0.00701"
"103.40000","3.44431","5613.24707","0.03444","0.02384","561.32471","-0.00701"
"103.60000","3.45114","5612.20752","0.03451","0.02385","561.22076","-0.00704"
"103.65900","3.45316","5255.94189","0.03453","0.02385","525.59418","-0.00706"
"103.66200","3.45324","4907.46484","0.03453","0.02385","490.74649","-0.00706"
"103.66400","3.45330","4633.26709","0.03453","0.02385","463.32672","-0.00706"
"103.66600","3.45337","4336.54443","0.03453","0.02385","433.65445","-0.00706"
"103.66800","3.45344","4025.25073","0.03453","0.02385","402.52509","-0.00706"
"103.67000","3.45351","3706.28198","0.03454","0.02385","370.62820","-0.00707"
"103.67200","3.45360","3385.49805","0.03454","0.02384","338.54980","-0.00707"
"103.67300","3.45364","3225.97705","0.03454","0.02384","322.59772","-0.00707"