File: Tension/Section_2_Group_2/epoxy_low_Sample_1_redonewiththepowerofAnton_1.is_tens_RawData/Specimen_RawData_1.csv
Time,Extension,Load,Tensile strain (Extension),Tensile stress,Strain-by-clip-gage
(s),(mm),(N),(mm/mm),(MPa),(mm/mm)
"0.00000","0.00000","631.62756","0.00000","63.16276","-0.00023"
"0.20000","0.00235","652.10175","0.00002","65.21017","-0.00023"
"0.40000","0.01094","730.24921","0.00011","73.02492","-0.00023"
"0.60000","0.01757","785.65314","0.00018","78.56532","-0.00021"
"0.80000","0.02412","844.48883","0.00024","84.44888","-0.00023"
"1.00000","0.03078","900.05237","0.00031","90.00523","-0.00018"
"1.20000","0.03759","954.56372","0.00038","95.45638","-0.00026"
"1.40000","0.04416","1001.81763","0.00044","100.18176","-0.00025"
"1.60000","0.05076","1056.46130","0.00051","105.64613","-0.00016"
"1.80000","0.05762","1106.55542","0.00058","110.65554","-0.00018"
"2.00000","0.06415","1154.21143","0.00064","115.42114","-0.00026"
"2.20000","0.07094","1203.83093","0.00071","120.38309","-0.00024"
"2.40000","0.07754","1250.83728","0.00078","125.08372","-0.00022"
"2.60000","0.08423","1297.88843","0.00084","129.78885","-0.00025"
"2.80000","0.09094","1344.95715","0.00091","134.49571","-0.00021"
"3.00000","0.09749","1389.55664","0.00097","138.95566","-0.00020"
"3.20000","0.10418","1435.25842","0.00104","143.52585","-0.00024"
"3.40000","0.11066","1478.84241","0.00111","147.88425","-0.00023"
"3.60000","0.11764","1526.54456","0.00118","152.65445","-0.00021"
"3.80000","0.12423","1569.92822","0.00124","156.99283","-0.00022"
"4.00000","0.13095","1614.21484","0.00131","161.42148","-0.00022"
"4.20000","0.13767","1658.56812","0.00138","165.85681","-0.00022"
"4.40000","0.14414","1699.97266","0.00144","169.99727","-0.00023"
"4.60000","0.15079","1743.12073","0.00151","174.31207","-0.00022"
"4.80000","0.15741","1785.95422","0.00157","178.59543","-0.00022"
"5.00000","0.16427","1830.57947","0.00164","183.05795","-0.00022"
"5.20000","0.17082","1872.24487","0.00171","187.22449","-0.00022"
"5.40000","0.17749","1914.61462","0.00177","191.46146","-0.00023"
"5.60000","0.18429","1958.68018","0.00184","195.86801","-0.00023"
"5.80000","0.19081","1999.55481","0.00191","199.95547","-0.00022"
"6.00000","0.19766","2044.11780","0.00198","204.41177","-0.00022"
"6.20000","0.20419","2085.20898","0.00204","208.52090","-0.00021"
"6.40000","0.21088","2127.35034","0.00211","212.73503","-0.00021"
"6.60000","0.21754","2168.92358","0.00218","216.89236","-0.00023"
"6.80000","0.22417","2210.59351","0.00224","221.05936","-0.00023"
"7.00000","0.23079","2252.33813","0.00231","225.23381","-0.00023"
"7.20000","0.23747","2296.36621","0.00237","229.63663","-0.00023"
"7.40000","0.24433","2344.30469","0.00244","234.43047","-0.00021"
"7.60000","0.25096","2390.57568","0.00251","239.05757","-0.00021"
"7.80000","0.25756","2436.68530","0.00258","243.66853","-0.00022"
"8.00000","0.26428","2484.11768","0.00264","248.41177","-0.00023"
"8.20000","0.27078","2529.49658","0.00271","252.94966","-0.00023"
"8.40000","0.27747","2577.00439","0.00277","257.70044","-0.00023"
"8.60000","0.28417","2624.76318","0.00284","262.47632","-0.00023"
"8.80000","0.29084","2671.48584","0.00291","267.14859","-0.00022"
"9.00000","0.29760","2719.29175","0.00298","271.92917","-0.00021"
"9.20000","0.30422","2765.29053","0.00304","276.52905","-0.00022"
"9.40000","0.31101","2813.11646","0.00311","281.31165","-0.00020"
"9.60000","0.31746","2857.31860","0.00317","285.73187","-0.00029"
"9.80000","0.32427","2905.49609","0.00324","290.54962","-0.00025"
"10.00000","0.33086","2951.49805","0.00331","295.14981","-0.00019"
"10.20000","0.33748","2996.89502","0.00337","299.68951","-0.00023"
"10.40000","0.34431","3044.93970","0.00344","304.49396","-0.00019"
"10.60000","0.35075","3088.32715","0.00351","308.83270","-0.00020"
"10.80000","0.35748","3135.04443","0.00357","313.50446","-0.00026"
"11.00000","0.36419","3181.95044","0.00364","318.19504","-0.00029"
"11.20000","0.37108","3230.03760","0.00371","323.00375","-0.00023"
"11.40000","0.37758","3274.10449","0.00378","327.41046","-0.00017"
"11.60000","0.38417","3318.58740","0.00384","331.85873","-0.00019"
"11.80000","0.39093","3364.98584","0.00391","336.49860","-0.00022"
"12.00000","0.39738","3407.94995","0.00397","340.79498","-0.00024"
"12.20000","0.40425","3455.55542","0.00404","345.55554","-0.00024"
"12.40000","0.41081","3499.56348","0.00411","349.95636","-0.00024"
"12.60000","0.41754","3544.81299","0.00418","354.48129","-0.00022"
"12.80000","0.42432","3591.07666","0.00424","359.10767","-0.00021"
"13.00000","0.43090","3634.46948","0.00431","363.44696","-0.00021"
"13.20000","0.43754","3678.81958","0.00438","367.88196","-0.00022"
"13.40000","0.44410","3722.35205","0.00444","372.23520","-0.00023"
"13.60000","0.45097","3769.18457","0.00451","376.91846","-0.00024"
"13.80000","0.45748","3811.71191","0.00457","381.17120","-0.00024"
"14.00000","0.46413","3855.79883","0.00464","385.57990","-0.00022"
"14.20000","0.47095","3901.45361","0.00471","390.14536","-0.00021"
"14.40000","0.47748","3943.50024","0.00477","394.35004","-0.00021"
"14.60000","0.48423","3987.87744","0.00484","398.78775","-0.00021"
"14.80000","0.49089","4031.72412","0.00491","403.17242","-0.00025"
"15.00000","0.49759","4075.49292","0.00498","407.54929","-0.00024"
"15.20000","0.50425","4119.19189","0.00504","411.91919","-0.00030"
"15.40000","0.51081","4160.84326","0.00511","416.08432","-0.00021"
"15.60000","0.51752","4203.04150","0.00518","420.30414","-0.00016"
"15.80000","0.52410","4243.92773","0.00524","424.39276","-0.00023"
"16.00000","0.53091","4287.82666","0.00531","428.78265","-0.00024"
"16.20000","0.53755","4330.09131","0.00538","433.00912","-0.00025"
"16.40000","0.54417","4371.74268","0.00544","437.17426","-0.00027"
"16.60000","0.55101","4415.73438","0.00551","441.57343","-0.00019"
"16.80000","0.55748","4455.47314","0.00557","445.54730","-0.00018"
"17.00000","0.56418","4497.18945","0.00564","449.71893","-0.00023"
"17.20000","0.57081","4538.53076","0.00571","453.85309","-0.00023"
"17.40000","0.57759","4581.03174","0.00578","458.10318","-0.00023"
"17.60000","0.58423","4622.14307","0.00584","462.21429","-0.00022"
"17.80000","0.59080","4661.99170","0.00591","466.19916","-0.00022"
"18.00000","0.59761","4704.73877","0.00598","470.47388","-0.00022"
"18.20000","0.60413","4743.69043","0.00604","474.36905","-0.00023"
"18.40000","0.61093","4785.57178","0.00611","478.55719","-0.00022"
"18.60000","0.61751","4825.28418","0.00618","482.52841","-0.00021"
"18.80000","0.62420","4865.71338","0.00624","486.57135","-0.00022"
"19.00000","0.63094","4906.79004","0.00631","490.67902","-0.00022"
"19.20000","0.63747","4945.02881","0.00637","494.50287","-0.00023"
"19.40000","0.64421","4985.64844","0.00644","498.56485","-0.00024"
"19.60000","0.65076","5023.54053","0.00651","502.35406","-0.00022"
"19.80000","0.65770","5065.70068","0.00658","506.57007","-0.00019"
"20.00000","0.66422","5103.40283","0.00664","510.34027","-0.00021"
"20.20000","0.67083","5141.15576","0.00671","514.11560","-0.00023"
"20.40000","0.67760","5181.25830","0.00678","518.12585","-0.00023"
"20.60000","0.68411","5217.72998","0.00684","521.77301","-0.00024"
"20.80000","0.69084","5256.80029","0.00691","525.68005","-0.00024"
"21.00000","0.69749","5294.80664","0.00697","529.48065","-0.00021"
"21.20000","0.70424","5333.15527","0.00704","533.31555","-0.00020"
"21.40000","0.71091","5370.90771","0.00711","537.09076","-0.00021"
"21.60000","0.71750","5407.52344","0.00718","540.75232","-0.00022"
"21.80000","0.72422","5445.15381","0.00724","544.51538","-0.00024"
"22.00000","0.73077","5480.80127","0.00731","548.08014","-0.00024"
"22.20000","0.73762","5519.73779","0.00738","551.97375","-0.00022"
"22.40000","0.74419","5554.69678","0.00744","555.46967","-0.00021"
"22.60000","0.75075","5589.39844","0.00751","558.93982","-0.00021"
"22.80000","0.75764","5628.34912","0.00758","562.83490","-0.00021"
"23.00000","0.76413","5662.17920","0.00764","566.21790","-0.00023"
"23.20000","0.77085","5698.19238","0.00771","569.81921","-0.00024"
"23.40000","0.77751","5733.61035","0.00778","573.36102","-0.00024"
"23.60000","0.78429","5769.65381","0.00784","576.96539","-0.00022"
"23.80000","0.79086","5803.06885","0.00791","580.30688","-0.00021"
"24.00000","0.79742","5836.25195","0.00797","583.62518","-0.00021"
"24.20000","0.80426","5873.09277","0.00804","587.30927","-0.00022"
"24.40000","0.81067","5904.88672","0.00811","590.48865","-0.00023"
"24.60000","0.81756","5941.56982","0.00818","594.15698","-0.00024"
"24.80000","0.82419","5975.46484","0.00824","597.54651","-0.00024"
"25.00000","0.83088","6008.79492","0.00831","600.87952","-0.00022"
"25.20000","0.83770","6044.30811","0.00838","604.43079","-0.00021"
"25.40000","0.84413","6074.68115","0.00844","607.46814","-0.00021"
"25.60000","0.85075","6107.34766","0.00851","610.73474","-0.00023"
"25.80000","0.85739","6140.62256","0.00857","614.06226","-0.00023"
"26.00000","0.86433","6176.93018","0.00864","617.69299","-0.00023"
"26.20000","0.87084","6207.84082","0.00871","620.78406","-0.00023"
"26.40000","0.87755","6240.55371","0.00878","624.05536","-0.00021"
"26.60000","0.88431","6274.31934","0.00884","627.43195","-0.00020"
"26.80000","0.89074","6303.84619","0.00891","630.38464","-0.00022"
"27.00000","0.89758","6338.23193","0.00898","633.82318","-0.00023"
"27.20000","0.90417","6369.90674","0.00904","636.99066","-0.00023"
"27.40000","0.91087","6401.92725","0.00911","640.19275","-0.00024"
"27.60000","0.91754","6434.11816","0.00918","643.41180","-0.00023"
"27.80000","0.92416","6464.92627","0.00924","646.49261","-0.00022"
"28.00000","0.93084","6496.86182","0.00931","649.68616","-0.00021"
"28.20000","0.93741","6527.60400","0.00937","652.76038","-0.00022"
"28.40000","0.94425","6561.36035","0.00944","656.13605","-0.00023"
"28.60000","0.95089","6592.26025","0.00951","659.22601","-0.00023"
"28.80000","0.95751","6622.51562","0.00958","662.25159","-0.00023"
"29.00000","0.96429","6654.52979","0.00964","665.45300","-0.00023"
"29.20000","0.97076","6682.55908","0.00971","668.25592","-0.00021"
"29.40000","0.97746","6713.05566","0.00977","671.30554","-0.00021"
"29.60000","0.98416","6744.00781","0.00984","674.40076","-0.00022"
"29.80000","0.99087","6774.70850","0.00991","677.47083","-0.00023"
"30.00000","0.99759","6805.46533","0.00998","680.54651","-0.00024"
"30.20000","1.00412","6833.56982","0.01004","683.35699","-0.00024"
"30.40000","1.01099","6865.22510","0.01011","686.52252","-0.00022"
"30.60000","1.01741","6891.59766","0.01017","689.15979","-0.00021"
"30.80000","1.02424","6922.57666","0.01024","692.25769","-0.00021"
"31.00000","1.03087","6951.59668","0.01031","695.15967","-0.00022"
"31.20000","1.03747","6979.70557","0.01037","697.97058","-0.00023"
"31.40000","1.04425","7010.49170","0.01044","701.04919","-0.00023"
"31.60000","1.05075","7037.05762","0.01051","703.70575","-0.00023"
"31.80000","1.05751","7066.46387","0.01058","706.64636","-0.00022"
"32.00000","1.06411","7094.40283","0.01064","709.44031","-0.00021"
"32.20000","1.07096","7124.89648","0.01071","712.48962","-0.00021"
"32.40000","1.07754","7151.94141","0.01078","715.19415","-0.00022"
"32.60000","1.08413","7178.52539","0.01084","717.85254","-0.00023"
"32.80000","1.09096","7208.40088","0.01091","720.84009","-0.00023"
"33.00000","1.09737","7232.87305","0.01097","723.28729","-0.00023"
"33.20000","1.10416","7261.84570","0.01104","726.18457","-0.00022"
"33.40000","1.11079","7289.12207","0.01111","728.91223","-0.00021"
"33.60000","1.11759","7317.59912","0.01118","731.75989","-0.00022"
"33.80000","1.12420","7344.36377","0.01124","734.43640","-0.00022"
"34.00000","1.13081","7370.45312","0.01131","737.04529","-0.00023"
"34.20000","1.13755","7397.91455","0.01138","739.79144","-0.00023"
"34.40000","1.14406","7422.08447","0.01144","742.20844","-0.00023"
"34.60000","1.15102","7451.61768","0.01151","745.16174","-0.00022"
"34.80000","1.15749","7475.41553","0.01157","747.54156","-0.00021"
"35.00000","1.16410","7500.13135","0.01164","750.01312","-0.00021"
"35.20000","1.17091","7527.72754","0.01171","752.77277","-0.00022"
"35.40000","1.17746","7551.90186","0.01177","755.19019","-0.00023"
"35.60000","1.18418","7578.24414","0.01184","757.82440","-0.00023"
"35.80000","1.19083","7603.05371","0.01191","760.30536","-0.00022"
"36.00000","1.19758","7628.55908","0.01198","762.85590","-0.00022"
"36.20000","1.20426","7653.51123","0.01204","765.35114","-0.00022"
"36.40000","1.21084","7676.63184","0.01211","767.66321","-0.00022"
"36.60000","1.21756","7701.05566","0.01218","770.10559","-0.00022"
"36.80000","1.22409","7723.20947","0.01224","772.32092","-0.00022"
"37.00000","1.23089","7748.15918","0.01231","774.81592","-0.00023"
"37.20000","1.23757","7771.42334","0.01238","777.14233","-0.00024"
"37.40000","1.24414","7793.09326","0.01244","779.30933","-0.00023"
"37.60000","1.25095","7818.37695","0.01251","781.83771","-0.00021"
"37.80000","1.25744","7839.07910","0.01257","783.90790","-0.00021"
"38.00000","1.26420","7862.59473","0.01264","786.25946","-0.00022"
"38.20000","1.27083","7884.85693","0.01271","788.48572","-0.00023"
"38.40000","1.27764","7908.31152","0.01278","790.83118","-0.00024"
"38.60000","1.28420","7929.23340","0.01284","792.92334","-0.00023"
"38.80000","1.29074","7949.77002","0.01291","794.97699","-0.00022"
"39.00000","1.29764","7974.27441","0.01298","797.42743","-0.00021"
"39.20000","1.30406","7992.83887","0.01304","799.28387","-0.00021"
"39.40000","1.31085","8015.91797","0.01311","801.59180","-0.00022"
"39.60000","1.31746","8036.52344","0.01317","803.65234","-0.00023"
"39.80000","1.32424","8058.12842","0.01324","805.81287","-0.00024"
"40.00000","1.33101","8080.30566","0.01331","808.03058","-0.00024"
"40.20000","1.33751","8098.43701","0.01338","809.84369","-0.00022"
"40.40000","1.34419","8118.98633","0.01344","811.89862","-0.00021"
"40.60000","1.35071","8137.61377","0.01351","813.76135","-0.00021"
"40.80000","1.35767","8160.69824","0.01358","816.06982","-0.00022"
"41.00000","1.36415","8178.13428","0.01364","817.81342","-0.00023"
"41.20000","1.37076","8196.23145","0.01371","819.62317","-0.00024"
"41.40000","1.37760","8217.50098","0.01378","821.75012","-0.00023"
"41.60000","1.38411","8234.61816","0.01384","823.46179","-0.00022"
"41.80000","1.39091","8254.87207","0.01391","825.48718","-0.00021"
"42.00000","1.39749","8272.89355","0.01397","827.28937","-0.00021"
"42.20000","1.40425","8292.51660","0.01404","829.25165","-0.00022"
"42.40000","1.41091","8311.15332","0.01411","831.11536","-0.00023"
"42.60000","1.41753","8328.34375","0.01418","832.83435","-0.00024"
"42.80000","1.42416","8345.96387","0.01424","834.59637","-0.00023"
"43.00000","1.43067","8361.86914","0.01431","836.18689","-0.00022"
"43.20000","1.43754","8381.85742","0.01438","838.18573","-0.00021"
"43.40000","1.44425","8399.69238","0.01444","839.96924","-0.00021"
"43.60000","1.45087","8415.62793","0.01451","841.56281","-0.00022"
"43.80000","1.45771","8433.93750","0.01458","843.39374","-0.00023"
"44.00000","1.46416","8447.76855","0.01464","844.77686","-0.00023"
"44.20000","1.47084","8464.41699","0.01471","846.44171","-0.00023"
"44.40000","1.47743","8479.88965","0.01477","847.98895","-0.00022"
"44.60000","1.48426","8497.22070","0.01484","849.72205","-0.00021"
"44.80000","1.49090","8512.50391","0.01491","851.25037","-0.00021"
"45.00000","1.49737","8525.09277","0.01497","852.50928","-0.00022"
"45.20000","1.50430","8542.88574","0.01504","854.28857","-0.00023"
"45.40000","1.51082","8555.74414","0.01511","855.57440","-0.00024"
"45.60000","1.51766","8572.12988","0.01518","857.21301","-0.00023"
"45.80000","1.52425","8551.48535","0.01524","855.14856","-0.00023"
"46.00000","1.53085","8570.48730","0.01531","857.04871","-0.00021"
"46.20000","1.53770","8591.06934","0.01538","859.10693","-0.00021"
"46.40000","1.54412","8604.64844","0.01544","860.46484","-0.00022"
"46.60000","1.55084","8621.20215","0.01551","862.12024","-0.00024"
"46.80000","1.55728","8634.74121","0.01557","863.47412","-0.00024"
"47.00000","1.56432","8654.30078","0.01564","865.43005","-0.00023"
"47.20000","1.57096","8669.22266","0.01571","866.92224","-0.00023"
"47.40000","1.57763","8683.33594","0.01578","868.33362","-0.00021"
"47.60000","1.58441","8698.98242","0.01584","869.89825","-0.00021"
"47.80000","1.59077","8708.97656","0.01591","870.89764","-0.00022"
"48.00000","1.59750","8723.23438","0.01597","872.32343","-0.00023"
"48.20000","1.60406","8735.55957","0.01604","873.55597","-0.00024"
"48.40000","1.61089","8749.97363","0.01611","874.99738","-0.00023"
"48.60000","1.61751","8762.22656","0.01618","876.22266","-0.00022"
"48.80000","1.62417","8773.83984","0.01624","877.38397","-0.00021"
"49.00000","1.63101","8787.44336","0.01631","878.74432","-0.00021"
"49.20000","1.63749","8796.45020","0.01637","879.64502","-0.00022"
"49.40000","1.64439","8810.47656","0.01644","881.04767","-0.00023"
"49.60000","1.65087","8819.85840","0.01651","881.98584","-0.00024"
"49.80000","1.65751","8830.58789","0.01658","883.05878","-0.00023"
"50.00000","1.66423","8842.59668","0.01664","884.25964","-0.00022"
"50.20000","1.67078","8852.08984","0.01671","885.20898","-0.00021"
"50.40000","1.67753","8863.56543","0.01678","886.35657","-0.00021"
"50.60000","1.68416","8873.74902","0.01684","887.37488","-0.00022"
"50.80000","1.69098","8885.51953","0.01691","888.55194","-0.00023"
"51.00000","1.69768","8896.34961","0.01698","889.63495","-0.00024"
"51.20000","1.70423","8904.51855","0.01704","890.45184","-0.00023"
"51.40000","1.71099","8915.25195","0.01711","891.52521","-0.00021"
"51.60000","1.71742","8922.16699","0.01717","892.21667","-0.00019"
"51.80000","1.72414","8931.70703","0.01724","893.17072","-0.00020"
"52.00000","1.73085","8941.85840","0.01731","894.18585","-0.00023"
"52.20000","1.73746","8950.09082","0.01737","895.00909","-0.00024"
"52.40000","1.74426","8960.79980","0.01744","896.07996","-0.00024"
"52.60000","1.75083","8968.68066","0.01751","896.86804","-0.00023"
"52.80000","1.75773","8980.42676","0.01758","898.04266","-0.00021"
"53.00000","1.76418","8986.41992","0.01764","898.64197","-0.00020"
"53.20000","1.77099","8996.17871","0.01771","899.61786","-0.00021"
"53.40000","1.77756","9003.89062","0.01778","900.38904","-0.00023"
"53.60000","1.78407","9010.26465","0.01784","901.02649","-0.00024"
"53.80000","1.79099","9021.96582","0.01791","902.19659","-0.00024"
"54.00000","1.79736","9026.96875","0.01797","902.69690","-0.00023"
"54.20000","1.80418","9036.79395","0.01804","903.67938","-0.00021"
"54.40000","1.81089","9045.36426","0.01811","904.53644","-0.00021"
"54.60000","1.81778","9055.32715","0.01818","905.53271","-0.00021"
"54.80000","1.82434","9061.86719","0.01824","906.18671","-0.00022"
"55.00000","1.83082","9067.20996","0.01831","906.72101","-0.00024"
"55.20000","1.83757","9075.52441","0.01838","907.55243","-0.00024"
"55.40000","1.84401","9080.00977","0.01844","908.00098","-0.00023"
"55.60000","1.85099","9090.64746","0.01851","909.06476","-0.00021"
"55.80000","1.85750","9096.43359","0.01857","909.64337","-0.00021"
"56.00000","1.86416","9103.74707","0.01864","910.37469","-0.00021"
"56.20000","1.87100","9113.71582","0.01871","911.37158","-0.00022"
"56.40000","1.87759","9119.86914","0.01878","911.98694","-0.00024"
"56.60000","1.88426","9127.54980","0.01884","912.75500","-0.00024"
"56.80000","1.89079","9133.63574","0.01891","913.36359","-0.00023"
"57.00000","1.89765","9143.14746","0.01898","914.31476","-0.00022"
"57.20000","1.90419","9149.23340","0.01904","914.92334","-0.00021"
"57.40000","1.91078","9155.41113","0.01911","915.54114","-0.00021"
"57.60000","1.91761","9164.41504","0.01918","916.44153","-0.00022"
"57.80000","1.92408","9168.80469","0.01924","916.88049","-0.00023"
"58.00000","1.93095","9178.25586","0.01931","917.82556","-0.00024"
"58.20000","1.93763","9185.54102","0.01938","918.55408","-0.00024"
"58.40000","1.94428","9191.68750","0.01944","919.16876","-0.00022"
"58.60000","1.95099","9198.09473","0.01951","919.80945","-0.00021"
"58.80000","1.95747","9201.76172","0.01957","920.17615","-0.00021"
"59.00000","1.96414","9207.70020","0.01964","920.77002","-0.00022"
"59.20000","1.97074","9213.73340","0.01971","921.37335","-0.00024"
"59.40000","1.97757","9221.60938","0.01978","922.16095","-0.00024"
"59.60000","1.98423","9227.19336","0.01984","922.71936","-0.00023"
"59.80000","1.99083","9230.79199","0.01991","923.07922","-0.00022"
"60.00000","1.99772","9238.25293","0.01998","923.82532","-0.00021"
"60.20000","2.00412","9239.41406","0.02004","923.94141","-0.00021"
"60.40000","2.01088","9244.21289","0.02011","924.42126","-0.00023"
"60.60000","2.01748","9247.77832","0.02017","924.77783","-0.00024"
"60.80000","2.02425","9252.19824","0.02024","925.21985","-0.00024"
"61.00000","2.03094","9256.03027","0.02031","925.60303","-0.00023"
"61.20000","2.03746","9256.83203","0.02037","925.68323","-0.00022"
"61.40000","2.04426","9261.52930","0.02044","926.15295","-0.00021"
"61.60000","2.05078","9262.78125","0.02051","926.27814","-0.00022"
"61.80000","2.05762","9267.16602","0.02058","926.71661","-0.00023"
"62.00000","2.06419","9268.76562","0.02064","926.87659","-0.00024"
"62.20000","2.07089","9270.39160","0.02071","927.03918","-0.00024"
"62.40000","2.07766","9273.55469","0.02078","927.35547","-0.00022"
"62.60000","2.08406","9271.28613","0.02084","927.12860","-0.00021"
"62.80000","2.09089","9274.52344","0.02091","927.45233","-0.00021"
"63.00000","2.09746","9274.99414","0.02097","927.49939","-0.00021"
"63.20000","2.10432","9278.36328","0.02104","927.83630","-0.00023"
"63.40000","2.11088","9278.60352","0.02111","927.86035","-0.00024"
"63.60000","2.11749","9279.15723","0.02117","927.91571","-0.00023"
"63.80000","2.12433","9282.80664","0.02124","928.28064","-0.00022"
"64.00000","2.13075","9282.00488","0.02131","928.20050","-0.00021"
"64.20000","2.13752","9285.74219","0.02138","928.57422","-0.00021"
"64.40000","2.14419","9288.09570","0.02144","928.80957","-0.00021"
"64.60000","2.15085","9289.73633","0.02151","928.97363","-0.00023"
"64.80000","2.15763","9292.48730","0.02158","929.24872","-0.00024"
"65.00000","2.16414","9291.13281","0.02164","929.11328","-0.00024"
"65.20000","2.17088","9292.28711","0.02171","929.22870","-0.00023"
"65.40000","2.17749","9292.21875","0.02177","929.22186","-0.00021"
"65.60000","2.18429","9293.73438","0.02184","929.37341","-0.00020"
"65.80000","2.19082","9292.07324","0.02191","929.20734","-0.00021"
"66.00000","2.19743","9291.28711","0.02197","929.12872","-0.00023"
"66.20000","2.20434","9294.10352","0.02204","929.41034","-0.00024"
"66.40000","2.21079","9291.19629","0.02211","929.11963","-0.00024"
"66.60000","2.21756","9290.74902","0.02218","929.07489","-0.00022"
"66.80000","2.22425","9290.27344","0.02224","929.02734","-0.00021"
"67.00000","2.23094","9289.06055","0.02231","928.90607","-0.00021"
"67.20000","2.23753","9287.60938","0.02238","928.76093","-0.00022"
"67.40000","2.24407","9285.14551","0.02244","928.51453","-0.00023"
"67.60000","2.25095","9285.94336","0.02251","928.59436","-0.00023"
"67.80000","2.25736","9281.81836","0.02257","928.18182","-0.00023"
"68.00000","2.26426","9283.72852","0.02264","928.37286","-0.00023"
"68.20000","2.27086","9283.87988","0.02271","928.38800","-0.00021"
"68.40000","2.27750","9282.57812","0.02278","928.25781","-0.00021"
"68.60000","2.28438","9284.07227","0.02284","928.40723","-0.00022"
"68.80000","2.29078","9279.79492","0.02291","927.97949","-0.00023"
"69.00000","2.29743","9277.61523","0.02297","927.76154","-0.00023"
"69.20000","2.30408","9276.26562","0.02304","927.62659","-0.00023"
"69.40000","2.31097","9277.61230","0.02311","927.76123","-0.00022"
"69.60000","2.31750","9275.70996","0.02318","927.57098","-0.00022"
"69.80000","2.32414","9273.44922","0.02324","927.34491","-0.00022"
"70.00000","2.33095","9273.61328","0.02331","927.36133","-0.00022"
"70.20000","2.33743","9269.88867","0.02337","926.98889","-0.00023"
"70.40000","2.34431","9269.70605","0.02344","926.97058","-0.00023"
"70.60000","2.35087","9265.96191","0.02351","926.59619","-0.00023"
"70.80000","2.35751","9262.89453","0.02358","926.28943","-0.00022"
"71.00000","2.36424","9261.32129","0.02364","926.13214","-0.00022"
"71.20000","2.37079","9255.94043","0.02371","925.59406","-0.00021"
"71.40000","2.37749","9252.91211","0.02377","925.29120","-0.00022"
"71.60000","2.38413","9248.51562","0.02384","924.85156","-0.00022"
"71.80000","2.39097","9245.79199","0.02391","924.57922","-0.00023"
"72.00000","2.39753","9239.77246","0.02398","923.97723","-0.00023"
"72.20000","2.40414","9234.38281","0.02404","923.43829","-0.00023"
"72.40000","2.41100","9232.02344","0.02411","923.20233","-0.00022"
"72.60000","2.41740","9224.10742","0.02417","922.41077","-0.00021"
"72.80000","2.42413","9219.49121","0.02424","921.94910","-0.00022"
"73.00000","2.43081","9214.00195","0.02431","921.40021","-0.00022"
"73.20000","2.43755","9208.16309","0.02438","920.81628","-0.00023"
"73.40000","2.44433","9202.53125","0.02444","920.25311","-0.00023"
"73.60000","2.45078","9193.21582","0.02451","919.32159","-0.00024"
"73.80000","2.45761","9189.29785","0.02458","918.92981","-0.00022"
"74.00000","2.46409","9182.48145","0.02464","918.24817","-0.00021"
"74.20000","2.47098","9180.58008","0.02471","918.05798","-0.00021"
"74.40000","2.47752","9176.77539","0.02478","917.67755","-0.00022"
"74.60000","2.48407","9172.80957","0.02484","917.28094","-0.00023"
"74.80000","2.49098","9174.61328","0.02491","917.46130","-0.00023"
"75.00000","2.49739","9170.99902","0.02497","917.09991","-0.00023"
"75.20000","2.50415","9171.37207","0.02504","917.13721","-0.00022"
"75.40000","2.51081","9171.71484","0.02511","917.17151","-0.00021"
"75.60000","2.51765","9172.53906","0.02518","917.25391","-0.00021"
"75.80000","2.52424","9170.46680","0.02524","917.04669","-0.00022"
"76.00000","2.53078","9166.53027","0.02531","916.65302","-0.00023"
"76.20000","2.53761","9165.94238","0.02538","916.59424","-0.00023"
"76.40000","2.54398","9159.85938","0.02544","915.98596","-0.00023"
"76.60000","2.55086","9158.35938","0.02551","915.83594","-0.00022"
"76.80000","2.55748","9153.58398","0.02557","915.35840","-0.00021"
"77.00000","2.56428","9149.79102","0.02564","914.97913","-0.00022"
"77.20000","2.57090","9145.79688","0.02571","914.57971","-0.00023"
"77.40000","2.57744","9140.41699","0.02577","914.04169","-0.00023"
"77.60000","2.58422","9137.87402","0.02584","913.78741","-0.00023"
"77.80000","2.59077","9133.07812","0.02591","913.30780","-0.00023"
"78.00000","2.59768","9131.79980","0.02598","913.17999","-0.00022"
"78.20000","2.60414","9125.00000","0.02604","912.50000","-0.00021"
"78.40000","2.61073","9118.00781","0.02611","911.80078","-0.00022"
"78.60000","2.61763","9114.94824","0.02618","911.49481","-0.00022"
"78.80000","2.62410","9107.02637","0.02624","910.70264","-0.00023"
"79.00000","2.63080","9102.25781","0.02631","910.22577","-0.00023"
"79.20000","2.63752","9098.10742","0.02638","909.81073","-0.00023"
"79.40000","2.64427","9093.87793","0.02644","909.38782","-0.00022"
"79.60000","2.65094","9087.79395","0.02651","908.77942","-0.00022"
"79.80000","2.65745","9079.55176","0.02657","907.95520","-0.00021"
"80.00000","2.66418","9074.03320","0.02664","907.40332","-0.00022"
"80.20000","2.67072","9067.77344","0.02671","906.77734","-0.00023"
"80.40000","2.67754","9064.76758","0.02678","906.47675","-0.00023"
"80.60000","2.68424","9059.95996","0.02684","905.99597","-0.00023"
"80.80000","2.69079","9052.94141","0.02691","905.29413","-0.00023"
"81.00000","2.69764","9050.02832","0.02698","905.00281","-0.00021"
"81.20000","2.70411","9043.35449","0.02704","904.33545","-0.00021"
"81.40000","2.71091","9039.93164","0.02711","903.99316","-0.00022"
"81.60000","2.71751","9034.74805","0.02718","903.47479","-0.00023"
"81.80000","2.72425","9030.85156","0.02724","903.08514","-0.00024"
"82.00000","2.73086","9025.89160","0.02731","902.58917","-0.00024"
"82.20000","2.73739","9019.93945","0.02737","901.99396","-0.00022"
"82.40000","2.74433","9018.17480","0.02744","901.81750","-0.00021"
"82.60000","2.75071","9010.19824","0.02751","901.01984","-0.00021"
"82.80000","2.75755","9006.47852","0.02758","900.64783","-0.00022"
"83.00000","2.76415","9000.84863","0.02764","900.08484","-0.00023"
"83.20000","2.77087","8995.61035","0.02771","899.56104","-0.00024"
"83.40000","2.77771","8991.83887","0.02778","899.18390","-0.00024"
"83.60000","2.78416","8982.32324","0.02784","898.23230","-0.00022"
"83.80000","2.79085","8975.65820","0.02791","897.56580","-0.00021"
"84.00000","2.79737","8967.06250","0.02797","896.70624","-0.00021"
"84.20000","2.80436","8963.49414","0.02804","896.34943","-0.00022"
"84.40000","2.81080","8954.28320","0.02811","895.42834","-0.00023"
"84.60000","2.81739","8945.29590","0.02817","894.52960","-0.00024"
"84.80000","2.82430","8940.54883","0.02824","894.05487","-0.00024"
"85.00000","2.83078","8929.36914","0.02831","892.93689","-0.00022"
"85.20000","2.83762","8922.30762","0.02838","892.23077","-0.00021"
"85.40000","2.84414","8911.77246","0.02844","891.17725","-0.00021"
"85.60000","2.85085","8902.44727","0.02851","890.24475","-0.00022"
"85.80000","2.85764","8894.67285","0.02858","889.46729","-0.00023"
"86.00000","2.86414","8882.49805","0.02864","888.24982","-0.00024"
"86.20000","2.87081","8872.20605","0.02871","887.22058","-0.00023"
"86.40000","2.87739","8860.71973","0.02877","886.07196","-0.00022"
"86.60000","2.88430","8853.46387","0.02884","885.34637","-0.00021"
"86.80000","2.89091","8842.39062","0.02891","884.23907","-0.00021"
"87.00000","2.89751","8831.91504","0.02898","883.19153","-0.00022"
"87.20000","2.90435","8825.65820","0.02904","882.56580","-0.00023"
"87.40000","2.91081","8816.04297","0.02911","881.60431","-0.00024"
"87.60000","2.91753","8808.70410","0.02918","880.87042","-0.00023"
"87.80000","2.92415","8800.48242","0.02924","880.04822","-0.00022"
"88.00000","2.93091","8793.86621","0.02931","879.38660","-0.00021"
"88.20000","2.93757","8785.76953","0.02938","878.57697","-0.00021"
"88.40000","2.94405","8774.97461","0.02944","877.49744","-0.00022"
"88.60000","2.95097","8769.33887","0.02951","876.93390","-0.00024"
"88.80000","2.95745","8758.36426","0.02957","875.83643","-0.00024"
"89.00000","2.96440","8751.55273","0.02964","875.15527","-0.00023"
"89.20000","2.97092","8740.49707","0.02971","874.04968","-0.00022"
"89.40000","2.97748","8729.40527","0.02977","872.94055","-0.00021"
"89.60000","2.98436","8721.98438","0.02984","872.19843","-0.00021"
"89.80000","2.99078","8708.95898","0.02991","870.89587","-0.00022"
"90.00000","2.99747","8699.48340","0.02997","869.94836","-0.00024"
"90.20000","3.00400","8689.55371","0.03004","868.95538","-0.00024"
"90.40000","3.01099","8684.73438","0.03011","868.47345","-0.00023"
"90.60000","3.01770","8676.74316","0.03018","867.67432","-0.00022"
"90.80000","3.02431","8667.33008","0.03024","866.73303","-0.00020"
"91.00000","3.03101","8658.73535","0.03031","865.87354","-0.00021"
"91.20000","3.03739","8646.52051","0.03037","864.65204","-0.00022"
"91.40000","3.04422","8638.18066","0.03044","863.81805","-0.00024"
"91.60000","3.05078","8625.86914","0.03051","862.58691","-0.00025"
"91.80000","3.05750","8612.54297","0.03057","861.25427","-0.00024"
"92.00000","3.06420","8599.82324","0.03064","859.98230","-0.00021"
"92.20000","3.07086","8584.68359","0.03071","858.46838","-0.00020"
"92.40000","3.07765","8571.08691","0.03078","857.10870","-0.00021"
"92.60000","3.08414","8553.89355","0.03084","855.38934","-0.00022"
"92.80000","3.09106","8541.04492","0.03091","854.10449","-0.00024"
"93.00000","3.09755","8523.14648","0.03098","852.31464","-0.00024"
"93.20000","3.10416","8506.26660","0.03104","850.62665","-0.00023"
"93.40000","3.11091","8492.47461","0.03111","849.24744","-0.00021"
"93.60000","3.11743","8476.55664","0.03117","847.65564","-0.00021"
"93.80000","3.12415","8464.91797","0.03124","846.49182","-0.00021"
"94.00000","3.13082","8453.93262","0.03131","845.39325","-0.00022"
"94.20000","3.13763","8444.95508","0.03138","844.49548","-0.00024"
"94.40000","3.14436","8436.75391","0.03144","843.67542","-0.00024"
"94.60000","3.15087","8426.07812","0.03151","842.60779","-0.00023"
"94.80000","3.15760","8418.43555","0.03158","841.84357","-0.00021"
"95.00000","3.16408","8408.89551","0.03164","840.88953","-0.00020"
"95.20000","3.17086","8401.98828","0.03171","840.19885","-0.00021"
"95.40000","3.17753","8394.36621","0.03178","839.43665","-0.00023"
"95.60000","3.18408","8384.83203","0.03184","838.48322","-0.00024"
"95.80000","3.19100","8380.23145","0.03191","838.02313","-0.00024"
"96.00000","3.19755","8372.12695","0.03198","837.21271","-0.00023"
"96.20000","3.20433","8367.13086","0.03204","836.71307","-0.00021"
"96.40000","3.21083","8360.42285","0.03211","836.04230","-0.00020"
"96.60000","3.21761","8356.48730","0.03218","835.64874","-0.00021"
"96.80000","3.22425","8352.42871","0.03224","835.24286","-0.00023"
"97.00000","3.23079","8347.03613","0.03231","834.70361","-0.00024"
"97.20000","3.23765","8345.78711","0.03238","834.57874","-0.00024"
"97.40000","3.24399","8339.02539","0.03244","833.90253","-0.00022"
"97.60000","3.25084","8338.35742","0.03251","833.83575","-0.00022"
"97.80000","3.25758","8336.83105","0.03258","833.68311","-0.00021"
"98.00000","3.26439","8335.12207","0.03264","833.51221","-0.00020"
"98.20000","3.27099","8331.58984","0.03271","833.15900","-0.00023"
"98.40000","3.27751","8326.10742","0.03278","832.61072","-0.00024"
"98.60000","3.28425","8323.58789","0.03284","832.35876","-0.00023"
"98.80000","3.29072","8318.15039","0.03291","831.81506","-0.00023"
"99.00000","3.29763","8317.13086","0.03298","831.71307","-0.00022"
"99.20000","3.30415","8311.88965","0.03304","831.18896","-0.00020"
"99.40000","3.31082","8308.66211","0.03311","830.86621","-0.00021"
"99.60000","3.31772","8308.30469","0.03318","830.83044","-0.00023"
"99.80000","3.32421","8303.17871","0.03324","830.31787","-0.00024"
"100.00000","3.33095","8301.14746","0.03331","830.11475","-0.00024"
"100.20000","3.33748","8297.36523","0.03337","829.73651","-0.00023"
"100.40000","3.34427","8296.07227","0.03344","829.60724","-0.00021"
"100.60000","3.35082","8292.80957","0.03351","829.28094","-0.00020"
"100.80000","3.35749","8291.40137","0.03357","829.14014","-0.00021"
"101.00000","3.36420","8289.31250","0.03364","828.93127","-0.00023"
"101.20000","3.37074","8285.12402","0.03371","828.51239","-0.00024"
"101.40000","3.37762","8285.10449","0.03378","828.51044","-0.00024"
"101.60000","3.38429","8283.71973","0.03384","828.37195","-0.00022"
"101.80000","3.39088","8281.76953","0.03391","828.17694","-0.00021"
"102.00000","3.39762","8282.26172","0.03398","828.22620","-0.00020"
"102.20000","3.40415","8280.15723","0.03404","828.01575","-0.00022"
"102.40000","3.41079","8278.89844","0.03411","827.88983","-0.00023"
"102.60000","3.41743","8279.13477","0.03417","827.91345","-0.00024"
"102.80000","3.42427","8280.62695","0.03424","828.06268","-0.00024"
"103.00000","3.43094","8280.70605","0.03431","828.07062","-0.00022"
"103.20000","3.43748","8278.71484","0.03437","827.87146","-0.00021"
"103.40000","3.44437","8280.75586","0.03444","828.07556","-0.00021"
"103.60000","3.45080","8277.11816","0.03451","827.71179","-0.00022"
"103.80000","3.45758","8276.15625","0.03458","827.61560","-0.00023"
"104.00000","3.46418","8273.67285","0.03464","827.36731","-0.00024"
"104.20000","3.47087","8270.46484","0.03471","827.04651","-0.00023"
"104.40000","3.47762","8267.83887","0.03478","826.78387","-0.00022"
"104.60000","3.48412","8262.24512","0.03484","826.22449","-0.00021"
"104.80000","3.49085","8258.82031","0.03491","825.88202","-0.00021"
"105.00000","3.49746","8255.00781","0.03497","825.50079","-0.00022"
"105.20000","3.50437","8253.21484","0.03504","825.32147","-0.00023"
"105.40000","3.51091","8247.86914","0.03511","824.78693","-0.00023"
"105.60000","3.51749","8242.58887","0.03517","824.25891","-0.00023"
"105.80000","3.52429","8240.14551","0.03524","824.01453","-0.00022"
"106.00000","3.53074","8233.95117","0.03531","823.39514","-0.00021"
"106.20000","3.53760","8232.12109","0.03538","823.21210","-0.00021"
"106.40000","3.54414","8226.07227","0.03544","822.60724","-0.00022"
"106.60000","3.55096","8222.37891","0.03551","822.23792","-0.00024"
"106.80000","3.55762","8217.74512","0.03558","821.77454","-0.00024"
"107.00000","3.56420","8211.88867","0.03564","821.18884","-0.00023"
"107.20000","3.57091","8208.62695","0.03571","820.86267","-0.00022"
"107.40000","3.57739","8203.81836","0.03577","820.38184","-0.00021"
"107.60000","3.58424","8203.28320","0.03584","820.32831","-0.00021"
"107.80000","3.59088","8200.49902","0.03591","820.04993","-0.00022"
"108.00000","3.59752","8196.74512","0.03598","819.67450","-0.00024"
"108.20000","3.60431","8194.49805","0.03604","819.44983","-0.00024"
"108.40000","3.61080","8188.38086","0.03611","818.83807","-0.00023"
"108.60000","3.61754","8184.11475","0.03618","818.41150","-0.00022"
"108.80000","3.62416","8179.89258","0.03624","817.98926","-0.00021"
"109.00000","3.63098","8177.80664","0.03631","817.78064","-0.00022"
"109.20000","3.63752","8173.13916","0.03638","817.31390","-0.00022"
"109.40000","3.64412","8169.33936","0.03644","816.93396","-0.00023"
"109.60000","3.65095","8168.54395","0.03651","816.85437","-0.00024"
"109.80000","3.65743","8163.92773","0.03657","816.39276","-0.00023"
"110.00000","3.66422","8163.09082","0.03664","816.30908","-0.00022"
"110.20000","3.67088","8161.85986","0.03671","816.18597","-0.00021"
"110.40000","3.67757","8160.46289","0.03678","816.04626","-0.00021"
"110.60000","3.68426","8159.83545","0.03684","815.98352","-0.00022"
"110.80000","3.69081","8157.07129","0.03691","815.70715","-0.00023"
"111.00000","3.69754","8156.33301","0.03698","815.63330","-0.00024"
"111.20000","3.70406","8153.62061","0.03704","815.36206","-0.00023"
"111.40000","3.71094","8153.93604","0.03711","815.39362","-0.00022"
"111.60000","3.71755","8152.10645","0.03718","815.21063","-0.00021"
"111.80000","3.72416","8149.20215","0.03724","814.92023","-0.00021"
"112.00000","3.73110","8149.84814","0.03731","814.98480","-0.00022"
"112.20000","3.73746","8144.29199","0.03737","814.42920","-0.00023"
"112.40000","3.74411","8141.33643","0.03744","814.13367","-0.00023"
"112.60000","3.75080","8138.95605","0.03751","813.89563","-0.00023"
"112.80000","3.75761","8136.74414","0.03758","813.67444","-0.00022"
"113.00000","3.76422","8133.43164","0.03764","813.34314","-0.00021"
"113.20000","3.77081","8128.79736","0.03771","812.87976","-0.00022"
"113.40000","3.77762","8126.52100","0.03778","812.65210","-0.00022"
"113.60000","3.78408","8121.12012","0.03784","812.11200","-0.00023"
"113.80000","3.79100","8120.16895","0.03791","812.01691","-0.00023"
"114.00000","3.79753","8115.25195","0.03798","811.52521","-0.00023"
"114.20000","3.80415","8110.50293","0.03804","811.05029","-0.00022"
"114.40000","3.81097","8108.38916","0.03811","810.83893","-0.00022"
"114.60000","3.81748","8102.12207","0.03817","810.21222","-0.00021"
"114.80000","3.82413","8097.28418","0.03824","809.72839","-0.00022"
"115.00000","3.83083","8093.11182","0.03831","809.31116","-0.00023"
"115.20000","3.83763","8089.94531","0.03838","808.99451","-0.00023"
"115.40000","3.84419","8084.16309","0.03844","808.41632","-0.00023"
"115.60000","3.85080","8078.92236","0.03851","807.89221","-0.00022"
"115.80000","3.85764","8076.60010","0.03858","807.66003","-0.00022"
"116.00000","3.86411","8070.50830","0.03864","807.05084","-0.00021"
"116.20000","3.87085","8067.94482","0.03871","806.79449","-0.00022"
"116.40000","3.87750","8064.97852","0.03878","806.49786","-0.00023"
"116.60000","3.88416","8061.63867","0.03884","806.16388","-0.00024"
"116.80000","3.89096","8060.73096","0.03891","806.07312","-0.00023"
"117.00000","3.89747","8056.45459","0.03897","805.64545","-0.00022"
"117.20000","3.90424","8055.44873","0.03904","805.54486","-0.00022"
"117.40000","3.91078","8053.35059","0.03911","805.33508","-0.00021"
"117.60000","3.91765","8054.74756","0.03918","805.47473","-0.00022"
"117.80000","3.92417","8052.43701","0.03924","805.24371","-0.00023"
"118.00000","3.93072","8049.97314","0.03931","804.99731","-0.00024"
"118.20000","3.93764","8051.72021","0.03938","805.17200","-0.00023"
"118.40000","3.94409","8047.19336","0.03944","804.71936","-0.00022"
"118.60000","3.95086","8044.97754","0.03951","804.49774","-0.00022"
"118.80000","3.95751","8040.75732","0.03958","804.07574","-0.00022"
"119.00000","3.96428","8036.80664","0.03964","803.68066","-0.00022"
"119.20000","3.97100","8032.85107","0.03971","803.28510","-0.00023"
"119.40000","3.97747","8025.39062","0.03977","802.53906","-0.00023"
"119.60000","3.98420","8020.31396","0.03984","802.03137","-0.00023"
"119.80000","3.99070","8012.62012","0.03991","801.26202","-0.00022"
"120.00000","3.99755","8008.83984","0.03998","800.88397","-0.00022"
"120.20000","4.00416","8002.06982","0.04004","800.20697","-0.00022"
"120.40000","4.01088","7996.58545","0.04011","799.65857","-0.00022"
"120.60000","4.01762","7992.24658","0.04018","799.22467","-0.00022"
"120.80000","4.02412","7985.73486","0.04024","798.57349","-0.00023"
"121.00000","4.03089","7982.92920","0.04031","798.29291","-0.00023"
"121.20000","4.03745","7977.73730","0.04037","797.77374","-0.00023"
"121.40000","4.04431","7975.26074","0.04044","797.52606","-0.00022"
"121.60000","4.05085","7970.27783","0.04051","797.02777","-0.00021"
"121.80000","4.05743","7966.58105","0.04057","796.65808","-0.00021"
"122.00000","4.06421","7965.87598","0.04064","796.58759","-0.00022"
"122.20000","4.07076","7962.12354","0.04071","796.21234","-0.00023"
"122.40000","4.07755","7960.17578","0.04078","796.01758","-0.00023"
"122.60000","4.08418","7956.51807","0.04084","795.65179","-0.00023"
"122.80000","4.09091","7953.17139","0.04091","795.31714","-0.00022"
"123.00000","4.09764","7950.26807","0.04098","795.02679","-0.00021"
"123.20000","4.10416","7944.50049","0.04104","794.45007","-0.00021"
"123.40000","4.11080","7940.34326","0.04111","794.03430","-0.00023"
"123.60000","4.11745","7937.16455","0.04117","793.71643","-0.00024"
"123.80000","4.12427","7935.67139","0.04124","793.56714","-0.00024"
"124.00000","4.13090","7932.61133","0.04131","793.26111","-0.00023"
"124.20000","4.13744","7928.77588","0.04137","792.87756","-0.00021"
"124.40000","4.14432","7928.68213","0.04144","792.86823","-0.00020"
"124.60000","4.15076","7924.05957","0.04151","792.40594","-0.00021"
"124.80000","4.15754","7920.98877","0.04158","792.09888","-0.00023"
"125.00000","4.16420","7916.56689","0.04164","791.65668","-0.00024"
"125.20000","4.17092","7912.62158","0.04171","791.26215","-0.00024"
"125.40000","4.17754","7908.18164","0.04178","790.81818","-0.00022"
"125.60000","4.18409","7902.35254","0.04184","790.23523","-0.00021"
"125.80000","4.19091","7900.52393","0.04191","790.05237","-0.00021"
"126.00000","4.19741","7895.32080","0.04197","789.53210","-0.00022"
"126.20000","4.20423","7893.02295","0.04204","789.30231","-0.00023"
"126.40000","4.21085","7889.36377","0.04211","788.93640","-0.00023"
"126.60000","4.21750","7884.94775","0.04217","788.49475","-0.00024"
"126.80000","4.22438","7884.21533","0.04224","788.42151","-0.00023"
"127.00000","4.23076","7878.06152","0.04231","787.80615","-0.00021"
"127.20000","4.23743","7874.91504","0.04237","787.49152","-0.00021"
"127.40000","4.24411","7871.61719","0.04244","787.16174","-0.00021"
"127.60000","4.25102","7870.73291","0.04251","787.07330","-0.00022"
"127.80000","4.25747","7864.32568","0.04257","786.43256","-0.00023"
"128.00000","4.26411","7859.07715","0.04264","785.90771","-0.00023"
"128.20000","4.27095","7855.96973","0.04271","785.59698","-0.00023"
"128.40000","4.27743","7848.69434","0.04277","784.86945","-0.00022"
"128.60000","4.28432","7845.05615","0.04284","784.50562","-0.00021"
"128.80000","4.29082","7838.14941","0.04291","783.81494","-0.00021"
"129.00000","4.29753","7832.84814","0.04298","783.28479","-0.00023"
"129.20000","4.30429","7827.75293","0.04304","782.77527","-0.00024"
"129.40000","4.31083","7819.60840","0.04311","781.96082","-0.00024"
"129.60000","4.31746","7813.10352","0.04317","781.31036","-0.00023"
"129.80000","4.32410","7807.54248","0.04324","780.75427","-0.00021"
"130.00000","4.33094","7803.75000","0.04331","780.37500","-0.00021"
"130.20000","4.33754","7797.24561","0.04338","779.72455","-0.00021"
"130.40000","4.34418","7790.17188","0.04344","779.01721","-0.00022"
"130.60000","4.35100","7785.47510","0.04351","778.54749","-0.00025"
"130.80000","4.35747","7777.84570","0.04357","777.78455","-0.00025"
"131.00000","4.36419","7772.89062","0.04364","777.28906","-0.00022"
"131.20000","4.37085","7768.40527","0.04371","776.84052","-0.00019"
"131.40000","4.37752","7763.56689","0.04378","776.35669","-0.00021"
"131.60000","4.38422","7759.80127","0.04384","775.98010","-0.00023"
"131.80000","4.39077","7754.16992","0.04391","775.41699","-0.00022"
"132.00000","4.39759","7751.37012","0.04398","775.13702","-0.00023"
"132.06900","4.39996","7750.71436","0.04400","775.07141","-0.00024"