File: Tension/Section_2_Group_4/f12a.is_tens_RawData/Specimen_RawData_1.csv
Time,Extension,Load,Tensile strain (Extension),Tensile stress,Strain-by-clip-gage
(s),(mm),(N),(mm/mm),(MPa),(mm/mm)
"0.00000","0.00000","-0.40452","0.00000","-0.04045","0.00000"
"0.10000","0.00097","4.56329","0.00001","0.45633","0.00000"
"0.20000","0.00243","13.55934","0.00002","1.35593","0.00001"
"0.30000","0.00726","40.91833","0.00007","4.09183","0.00001"
"0.40000","0.01097","54.16204","0.00011","5.41620","0.00001"
"0.50000","0.01440","64.60490","0.00014","6.46049","0.00001"
"0.60000","0.01744","76.32552","0.00017","7.63255","-0.00001"
"0.70000","0.02107","92.00838","0.00021","9.20084","-0.00002"
"0.80000","0.02430","106.53151","0.00024","10.65315","0.00000"
"0.90000","0.02758","122.46962","0.00028","12.24696","0.00000"
"1.00000","0.03090","137.94681","0.00031","13.79468","0.00002"
"1.10000","0.03426","153.41362","0.00034","15.34136","-0.00001"
"1.20000","0.03769","169.24272","0.00038","16.92427","-0.00001"
"1.30000","0.04080","183.50533","0.00041","18.35053","-0.00001"
"1.40000","0.04429","199.92981","0.00044","19.99298","0.00000"
"1.50000","0.04775","215.81525","0.00048","21.58152","0.00001"
"1.60000","0.05093","230.17519","0.00051","23.01752","0.00000"
"1.70000","0.05422","245.18179","0.00054","24.51818","0.00000"
"1.80000","0.05760","260.32700","0.00058","26.03270","0.00000"
"1.90000","0.06094","275.24820","0.00061","27.52482","0.00000"
"2.00000","0.06420","289.69955","0.00064","28.96996","0.00000"
"2.10000","0.06776","305.63974","0.00068","30.56397","0.00001"
"2.20000","0.07107","320.13531","0.00071","32.01353","-0.00001"
"2.30000","0.07432","334.13306","0.00074","33.41331","0.00001"
"2.40000","0.07756","348.24518","0.00078","34.82452","-0.00001"
"2.50000","0.08098","363.02103","0.00081","36.30210","0.00000"
"2.60000","0.08425","376.94772","0.00084","37.69477","0.00001"
"2.70000","0.08756","391.24167","0.00088","39.12417","0.00000"
"2.80000","0.09100","405.81827","0.00091","40.58183","0.00000"
"2.90000","0.09440","420.18228","0.00094","42.01823","0.00000"
"3.00000","0.09757","433.13434","0.00098","43.31343","0.00000"
"3.10000","0.10095","447.27325","0.00101","44.72733","0.00000"
"3.20000","0.10425","460.91080","0.00104","46.09108","0.00000"
"3.30000","0.10759","474.41446","0.00108","47.44144","0.00000"
"3.40000","0.11098","488.44250","0.00111","48.84425","-0.00001"
"3.50000","0.11427","501.38724","0.00114","50.13873","0.00000"
"3.60000","0.11767","514.96423","0.00118","51.49642","0.00000"
"3.70000","0.12088","527.34937","0.00121","52.73494","0.00000"
"3.80000","0.12431","541.04919","0.00124","54.10492","0.00000"
"3.90000","0.12774","554.59369","0.00128","55.45937","0.00000"
"4.00000","0.13094","566.71991","0.00131","56.67199","0.00000"
"4.10000","0.13437","580.14844","0.00134","58.01484","0.00000"
"4.20000","0.13758","591.72076","0.00138","59.17208","-0.00001"
"4.30000","0.14100","604.97119","0.00141","60.49712","0.00000"
"4.40000","0.14422","616.60828","0.00144","61.66083","0.00000"
"4.50000","0.14769","629.92035","0.00148","62.99203","0.00000"
"4.60000","0.15101","642.07684","0.00151","64.20769","0.00000"
"4.70000","0.15426","653.75732","0.00154","65.37573","0.00000"
"4.80000","0.15763","666.25836","0.00158","66.62584","0.00000"
"4.90000","0.16088","677.63312","0.00161","67.76331","0.00000"
"5.00000","0.16423","689.71301","0.00164","68.97130","0.00000"
"5.10000","0.16755","701.60034","0.00168","70.16003","0.00000"
"5.20000","0.17107","714.53198","0.00171","71.45320","0.00000"
"5.30000","0.17434","725.90088","0.00174","72.59009","0.00000"
"5.40000","0.17753","736.53680","0.00178","73.65368","0.00000"
"5.50000","0.18099","748.84747","0.00181","74.88475","0.00000"
"5.60000","0.18432","760.05939","0.00184","76.00594","0.00000"
"5.70000","0.18761","771.03137","0.00188","77.10313","-0.00001"
"5.80000","0.19093","782.29553","0.00191","78.22955","0.00001"
"5.90000","0.19444","794.69214","0.00194","79.46922","0.00000"
"6.00000","0.19769","805.07025","0.00198","80.50703","0.00000"
"6.10000","0.20089","815.52521","0.00201","81.55252","0.00000"
"6.20000","0.20429","826.86005","0.00204","82.68600","-0.00001"
"6.30000","0.20763","837.79199","0.00208","83.77920","0.00000"
"6.40000","0.21089","848.12793","0.00211","84.81279","0.00000"
"6.50000","0.21425","858.95032","0.00214","85.89503","0.00000"
"6.60000","0.21771","870.09882","0.00218","87.00988","0.00000"
"6.70000","0.22097","880.14490","0.00221","88.01449","-0.00001"
"6.80000","0.22418","889.82086","0.00224","88.98209","0.00000"
"6.90000","0.22769","901.23468","0.00228","90.12347","0.00000"
"7.00000","0.23101","911.33368","0.00231","91.13337","0.00000"
"7.10000","0.23424","920.88647","0.00234","92.08865","0.00001"
"7.20000","0.23759","931.28857","0.00238","93.12886","-0.00001"
"7.30000","0.24097","941.44873","0.00241","94.14487","0.00000"
"7.40000","0.24426","951.16876","0.00244","95.11687","0.00000"
"7.50000","0.24758","961.31189","0.00248","96.13119","0.00000"
"7.60000","0.25108","972.00806","0.00251","97.20081","0.00000"
"7.70000","0.25447","982.05872","0.00254","98.20587","-0.00001"
"7.80000","0.25759","990.12042","0.00258","99.01204","0.00000"
"7.90000","0.26093","999.97858","0.00261","99.99786","0.00000"
"8.00000","0.26426","1009.23285","0.00264","100.92329","0.00000"
"8.10000","0.26758","1018.44019","0.00268","101.84402","0.00000"
"8.20000","0.27088","1027.52808","0.00271","102.75281","0.00000"
"8.30000","0.27441","1037.87598","0.00274","103.78760","0.00000"
"8.40000","0.27781","1047.12524","0.00278","104.71252","0.00000"
"8.50000","0.28087","1054.61316","0.00281","105.46132","0.00000"
"8.60000","0.28421","1063.75427","0.00284","106.37543","0.00000"
"8.70000","0.28763","1072.97717","0.00288","107.29771","-0.00001"
"8.80000","0.29088","1081.04456","0.00291","108.10445","0.00000"
"8.90000","0.29421","1089.87964","0.00294","108.98796","0.00000"
"9.00000","0.29767","1099.06152","0.00298","109.90615","-0.00001"
"9.10000","0.30108","1107.87073","0.00301","110.78707","0.00000"
"9.20000","0.30419","1115.13635","0.00304","111.51363","0.00000"
"9.30000","0.30767","1124.13867","0.00308","112.41386","0.00000"
"9.40000","0.31105","1132.60645","0.00311","113.26064","0.00000"
"9.50000","0.31433","1140.35828","0.00314","114.03583","0.00000"
"9.60000","0.31759","1147.69922","0.00318","114.76992","0.00001"
"9.70000","0.32100","1156.22546","0.00321","115.62254","-0.00001"
"9.80000","0.32435","1164.02039","0.00324","116.40204","0.00000"
"9.90000","0.32749","1170.84875","0.00327","117.08488","0.00000"
"10.00000","0.33098","1179.48572","0.00331","117.94857","0.00000"
"10.10000","0.33438","1187.28943","0.00334","118.72894","0.00000"
"10.20000","0.33762","1194.05652","0.00338","119.40565","0.00000"
"10.30000","0.34093","1201.25879","0.00341","120.12588","0.00000"
"10.40000","0.34419","1208.05042","0.00344","120.80504","0.00000"
"10.50000","0.34758","1215.50610","0.00348","121.55061","0.00000"
"10.60000","0.35087","1222.43384","0.00351","122.24339","0.00000"
"10.70000","0.35437","1230.54297","0.00354","123.05430","0.00000"
"10.80000","0.35772","1237.53284","0.00358","123.75328","0.00000"
"10.90000","0.36096","1243.92273","0.00361","124.39227","0.00000"
"11.00000","0.36431","1250.77979","0.00364","125.07798","-0.00001"
"11.10000","0.36763","1257.32703","0.00368","125.73270","0.00000"
"11.20000","0.37094","1263.96338","0.00371","126.39634","0.00000"
"11.30000","0.37429","1270.90649","0.00374","127.09065","0.00000"
"11.40000","0.37773","1278.00073","0.00378","127.80007","0.00000"
"11.50000","0.38106","1284.71130","0.00381","128.47113","-0.00001"
"11.60000","0.38423","1290.18469","0.00384","129.01846","0.00000"
"11.70000","0.38758","1296.84290","0.00388","129.68430","0.00000"
"11.80000","0.39092","1303.33447","0.00391","130.33345","0.00000"
"11.90000","0.39423","1309.59241","0.00394","130.95924","0.00000"
"12.00000","0.39762","1316.30725","0.00398","131.63072","0.00000"
"12.10000","0.40103","1323.05981","0.00401","132.30598","0.00000"
"12.20000","0.40432","1329.03394","0.00404","132.90340","0.00000"
"12.30000","0.40754","1334.52563","0.00408","133.45256","0.00000"
"12.40000","0.41098","1341.26636","0.00411","134.12663","0.00000"
"12.50000","0.41431","1347.07947","0.00414","134.70795","0.00000"
"12.60000","0.41753","1352.63806","0.00418","135.26381","0.00000"
"12.70000","0.42100","1359.56152","0.00421","135.95615","0.00000"
"12.80000","0.42436","1365.32800","0.00424","136.53281","0.00000"
"12.90000","0.42764","1370.92749","0.00428","137.09274","0.00000"
"13.00000","0.43089","1376.32043","0.00431","137.63205","0.00000"
"13.10000","0.43434","1382.80786","0.00434","138.28079","0.00000"
"13.20000","0.43777","1388.98425","0.00438","138.89842","0.00000"
"13.30000","0.44092","1393.77734","0.00441","139.37773","0.00000"
"13.40000","0.44432","1400.01111","0.00444","140.00111","0.00000"
"13.50000","0.44762","1405.55615","0.00448","140.55562","-0.00001"
"13.60000","0.45093","1411.03564","0.00451","141.10356","0.00000"
"13.70000","0.45416","1416.35876","0.00454","141.63588","0.00000"
"13.80000","0.45775","1423.75244","0.00458","142.37524","0.00000"
"13.90000","0.46106","1429.29749","0.00461","142.92975","0.00000"
"14.00000","0.46421","1434.04858","0.00464","143.40486","0.00000"
"14.10000","0.46764","1440.76123","0.00468","144.07613","0.00000"
"14.20000","0.47087","1445.69971","0.00471","144.56998","0.00000"
"14.30000","0.47422","1451.78174","0.00474","145.17818","0.00000"
"14.40000","0.47748","1457.46826","0.00477","145.74683","0.00000"
"14.50000","0.48112","1465.08313","0.00481","146.50832","0.00000"
"14.60000","0.48442","1470.51978","0.00484","147.05197","0.00000"
"14.70000","0.48757","1475.33875","0.00488","147.53387","0.00000"
"14.80000","0.49100","1481.51074","0.00491","148.15108","0.00000"
"14.90000","0.49427","1486.80298","0.00494","148.68030","0.00000"
"15.00000","0.49767","1492.59570","0.00498","149.25957","-0.00001"
"15.10000","0.50093","1497.89111","0.00501","149.78911","0.00001"
"15.20000","0.50439","1504.19666","0.00504","150.41966","0.00000"
"15.30000","0.50771","1509.71594","0.00508","150.97159","0.00000"
"15.40000","0.51086","1514.40527","0.00511","151.44052","0.00000"
"15.50000","0.51425","1520.62195","0.00514","152.06219","0.00000"
"15.60000","0.51765","1526.68823","0.00518","152.66882","0.00000"
"15.70000","0.52095","1532.03613","0.00521","153.20361","0.00000"
"15.80000","0.52422","1537.69958","0.00524","153.76996","0.00000"
"15.90000","0.52769","1544.34070","0.00528","154.43407","0.00000"
"16.00000","0.53094","1549.47278","0.00531","154.94728","-0.00001"
"16.10000","0.53420","1555.18335","0.00534","155.51834","0.00000"
"16.20000","0.53765","1561.93213","0.00538","156.19321","0.00000"
"16.30000","0.54109","1568.34387","0.00541","156.83438","0.00000"
"16.40000","0.54430","1573.56165","0.00544","157.35617","0.00000"
"16.50000","0.54761","1579.51746","0.00548","157.95175","0.00000"
"16.60000","0.55099","1585.76636","0.00551","158.57663","0.00000"
"16.70000","0.55424","1591.28625","0.00554","159.12863","0.00000"
"16.80000","0.55758","1597.57788","0.00558","159.75778","0.00000"
"16.90000","0.56101","1604.34729","0.00561","160.43472","0.00000"
"17.00000","0.56448","1611.20374","0.00564","161.12038","0.00000"
"17.10000","0.56759","1615.90479","0.00568","161.59048","0.00000"
"17.20000","0.57095","1622.32727","0.00571","162.23273","0.00000"
"17.30000","0.57422","1628.09607","0.00574","162.80960","0.00000"
"17.40000","0.57761","1634.55212","0.00578","163.45522","0.00000"
"17.50000","0.58094","1640.66479","0.00581","164.06648","0.00000"
"17.60000","0.58432","1647.05420","0.00584","164.70541","0.00000"
"17.70000","0.58773","1653.67651","0.00588","165.36765","0.00000"
"17.80000","0.59088","1658.75818","0.00591","165.87582","0.00000"
"17.90000","0.59428","1665.43530","0.00594","166.54353","0.00000"
"18.00000","0.59758","1671.32019","0.00598","167.13202","0.00000"
"18.10000","0.60093","1677.47461","0.00601","167.74747","0.00000"
"18.20000","0.60429","1683.95093","0.00604","168.39510","0.00000"
"18.30000","0.60771","1690.43787","0.00608","169.04379","0.00000"
"18.40000","0.61103","1696.66956","0.00611","169.66696","0.00000"
"18.50000","0.61421","1701.91602","0.00614","170.19160","-0.00001"
"18.60000","0.61771","1708.98340","0.00618","170.89835","0.00000"
"18.70000","0.62096","1714.64062","0.00621","171.46407","0.00000"
"18.80000","0.62434","1721.13330","0.00624","172.11333","-0.00001"
"18.90000","0.62761","1726.89368","0.00628","172.68936","0.00000"
"19.00000","0.63098","1733.10266","0.00631","173.31027","-0.00001"
"19.10000","0.63426","1738.87390","0.00634","173.88739","0.00000"
"19.20000","0.63754","1744.78735","0.00638","174.47873","0.00000"
"19.30000","0.64105","1751.94568","0.00641","175.19456","0.00000"
"19.40000","0.64433","1757.72070","0.00644","175.77206","0.00000"
"19.50000","0.64759","1763.35632","0.00648","176.33563","0.00000"
"19.60000","0.65093","1769.49292","0.00651","176.94930","0.00000"
"19.70000","0.65430","1775.56482","0.00654","177.55649","0.00000"
"19.80000","0.65754","1780.97864","0.00658","178.09787","0.00000"
"19.90000","0.66086","1787.08508","0.00661","178.70851","0.00000"
"20.00000","0.66439","1794.10339","0.00664","179.41034","0.00000"
"20.10000","0.66776","1800.06543","0.00668","180.00655","0.00000"
"20.20000","0.67097","1805.25635","0.00671","180.52563","0.00000"
"20.30000","0.67427","1811.06274","0.00674","181.10628","-0.00001"
"20.40000","0.67773","1817.45032","0.00678","181.74503","0.00000"
"20.50000","0.68086","1822.30847","0.00681","182.23085","0.00000"
"20.60000","0.68428","1828.83459","0.00684","182.88345","0.00000"
"20.70000","0.68770","1835.13928","0.00688","183.51393","0.00000"
"20.80000","0.69104","1841.21619","0.00691","184.12161","-0.00001"
"20.90000","0.69418","1846.02380","0.00694","184.60239","0.00001"
"21.00000","0.69762","1852.71106","0.00698","185.27110","0.00000"
"21.10000","0.70096","1858.29309","0.00701","185.82932","0.00000"
"21.20000","0.70422","1863.60327","0.00704","186.36032","0.00000"
"21.30000","0.70759","1869.82153","0.00708","186.98215","0.00000"
"21.40000","0.71104","1876.19055","0.00711","187.61905","0.00000"
"21.50000","0.71439","1881.98840","0.00714","188.19884","0.00000"
"21.60000","0.71747","1886.46033","0.00717","188.64603","0.00000"
"21.70000","0.72101","1893.63123","0.00721","189.36313","0.00000"
"21.80000","0.72434","1899.10425","0.00724","189.91043","0.00000"
"21.90000","0.72755","1904.29761","0.00728","190.42976","0.00000"
"22.00000","0.73101","1910.89868","0.00731","191.08987","0.00000"
"22.10000","0.73430","1916.24243","0.00734","191.62424","0.00000"
"22.20000","0.73773","1922.52478","0.00738","192.25247","0.00000"
"22.30000","0.74082","1926.89966","0.00741","192.68997","0.00000"
"22.40000","0.74438","1934.02393","0.00744","193.40239","0.00000"
"22.50000","0.74770","1939.68689","0.00748","193.96869","0.00000"
"22.60000","0.75096","1944.81592","0.00751","194.48160","0.00000"
"22.70000","0.75424","1950.21741","0.00754","195.02174","0.00000"
"22.80000","0.75765","1956.06067","0.00758","195.60606","0.00000"
"22.90000","0.76096","1961.36511","0.00761","196.13651","0.00000"
"23.00000","0.76415","1966.25305","0.00764","196.62531","0.00000"
"23.10000","0.76769","1973.10315","0.00768","197.31032","0.00000"
"23.20000","0.77105","1978.67004","0.00771","197.86700","0.00000"
"23.30000","0.77425","1983.39111","0.00774","198.33911","0.00000"
"23.40000","0.77754","1988.81311","0.00778","198.88132","0.00000"
"23.50000","0.78093","1994.76624","0.00781","199.47662","0.00000"
"23.60000","0.78427","2000.23425","0.00784","200.02342","0.00000"
"23.70000","0.78753","2005.56238","0.00788","200.55624","0.00000"
"23.80000","0.79111","2012.56836","0.00791","201.25684","0.00000"
"23.90000","0.79441","2017.68860","0.00794","201.76886","0.00000"
"24.00000","0.79764","2022.51343","0.00798","202.25134","0.00000"
"24.10000","0.80092","2027.68945","0.00801","202.76895","0.00000"
"24.20000","0.80435","2033.62292","0.00804","203.36229","0.00000"
"24.30000","0.80757","2038.23730","0.00808","203.82373","0.00000"
"24.40000","0.81094","2044.00891","0.00811","204.40089","0.00000"
"24.50000","0.81431","2049.43677","0.00814","204.94368","0.00000"
"24.60000","0.81770","2055.22852","0.00818","205.52286","0.00000"
"24.70000","0.82090","2059.71460","0.00821","205.97147","0.00000"
"24.80000","0.82426","2065.02417","0.00824","206.50241","0.00000"
"24.90000","0.82760","2070.45776","0.00828","207.04578","0.00000"
"25.00000","0.83090","2075.48706","0.00831","207.54871","0.00000"
"25.10000","0.83429","2081.09106","0.00834","208.10910","0.00000"
"25.20000","0.83762","2085.95459","0.00838","208.59546","0.00000"
"25.30000","0.84098","2090.80493","0.00841","209.08049","0.00000"
"25.40000","0.84424","2095.55469","0.00844","209.55547","0.00000"
"25.50000","0.84771","2101.31860","0.00848","210.13187","0.00000"
"25.60000","0.85110","2106.41333","0.00851","210.64133","0.00000"
"25.70000","0.85429","2110.56787","0.00854","211.05679","0.00000"
"25.80000","0.85769","2116.09326","0.00858","211.60933","0.00000"
"25.90000","0.86090","2120.56860","0.00861","212.05685","0.00000"
"26.00000","0.86429","2126.16797","0.00864","212.61679","0.00000"
"26.10000","0.86757","2131.30762","0.00868","213.13077","0.00000"
"26.20000","0.87105","2137.45898","0.00871","213.74590","0.00000"
"26.30000","0.87434","2142.69800","0.00874","214.26981","0.00000"
"26.40000","0.87757","2147.34082","0.00878","214.73409","0.00000"
"26.50000","0.88099","2153.30908","0.00881","215.33090","0.00000"
"26.60000","0.88421","2157.98486","0.00884","215.79849","0.00000"
"26.70000","0.88755","2163.48975","0.00888","216.34897","0.00000"
"26.80000","0.89089","2169.23486","0.00891","216.92349","0.00000"
"26.90000","0.89440","2175.73657","0.00894","217.57365","0.00000"
"27.00000","0.89770","2180.82153","0.00898","218.08215","0.00000"
"27.10000","0.90088","2185.56470","0.00901","218.55647","0.00000"
"27.20000","0.90433","2191.90601","0.00904","219.19060","0.00000"
"27.30000","0.90763","2197.01782","0.00908","219.70178","0.00000"
"27.40000","0.91093","2202.47314","0.00911","220.24731","0.00000"
"27.50000","0.91429","2208.37622","0.00914","220.83762","0.00000"
"27.60000","0.91776","2214.73511","0.00918","221.47351","0.00000"
"27.70000","0.92102","2219.63330","0.00921","221.96333","0.00000"
"27.80000","0.92421","2224.74121","0.00924","222.47412","0.00000"
"27.90000","0.92763","2230.81177","0.00928","223.08118","0.00000"
"28.00000","0.93101","2236.58618","0.00931","223.65862","0.00000"
"28.10000","0.93420","2241.42139","0.00934","224.14214","0.00000"
"28.20000","0.93759","2247.55835","0.00938","224.75583","0.00000"
"28.30000","0.94103","2253.48779","0.00941","225.34879","0.00000"
"28.40000","0.94428","2258.61108","0.00944","225.86111","0.00000"
"28.50000","0.94750","2263.69458","0.00947","226.36946","0.00000"
"28.60000","0.95104","2270.62036","0.00951","227.06204","0.00000"
"28.70000","0.95434","2276.11279","0.00954","227.61128","0.00000"
"28.80000","0.95758","2281.00732","0.00958","228.10074","0.00000"
"28.90000","0.96091","2286.73267","0.00961","228.67326","0.00000"
"29.00000","0.96428","2292.45972","0.00964","229.24597","0.00000"
"29.10000","0.96760","2297.89087","0.00968","229.78909","0.00000"
"29.20000","0.97093","2303.76538","0.00971","230.37654","0.00000"
"29.30000","0.97443","2310.37280","0.00974","231.03728","0.00000"
"29.40000","0.97781","2316.41504","0.00978","231.64151","0.00000"
"29.50000","0.98091","2320.38794","0.00981","232.03879","0.00000"
"29.60000","0.98432","2326.64575","0.00984","232.66458","0.00000"
"29.70000","0.98757","2331.48926","0.00988","233.14893","0.00000"
"29.80000","0.99094","2337.41138","0.00991","233.74113","0.00000"
"29.90000","0.99422","2342.85620","0.00994","234.28561","0.00000"
"30.00000","0.99769","2349.20215","0.00998","234.92021","0.00000"
"30.10000","1.00113","2355.59131","0.01001","235.55913","0.00000"
"30.20000","1.00416","2359.31641","0.01004","235.93164","0.00000"
"30.30000","1.00754","2365.70679","0.01008","236.57068","-0.00001"
"30.40000","1.01101","2371.93213","0.01011","237.19321","0.00000"
"30.50000","1.01422","2376.81372","0.01014","237.68137","0.00000"
"30.60000","1.01757","2382.73486","0.01018","238.27348","0.00000"
"30.70000","1.02102","2389.09766","0.01021","238.90976","0.00000"
"30.80000","1.02439","2394.65259","0.01024","239.46526","0.00000"
"30.90000","1.02754","2399.06006","0.01028","239.90601","0.00000"
"31.00000","1.03103","2405.79907","0.01031","240.57991","0.00000"
"31.10000","1.03442","2411.55103","0.01034","241.15511","0.00000"
"31.20000","1.03766","2416.58569","0.01038","241.65857","0.00000"
"31.30000","1.04093","2421.84131","0.01041","242.18413","0.00000"
"31.40000","1.04432","2427.82324","0.01044","242.78232","0.00000"
"31.50000","1.04766","2433.23413","0.01048","243.32341","0.00000"
"31.60000","1.05082","2438.05371","0.01051","243.80537","0.00000"
"31.70000","1.05429","2444.61084","0.01054","244.46109","0.00000"
"31.80000","1.05769","2450.62329","0.01058","245.06233","0.00000"
"31.90000","1.06096","2455.84351","0.01061","245.58435","0.00000"
"32.00000","1.06428","2461.21631","0.01064","246.12163","0.00000"
"32.10000","1.06756","2466.39282","0.01068","246.63928","0.00000"
"32.20000","1.07093","2471.94531","0.01071","247.19453","0.00000"
"32.30000","1.07424","2477.44336","0.01074","247.74434","0.00000"
"32.40000","1.07768","2483.69556","0.01078","248.36955","0.00000"
"32.50000","1.08104","2489.43530","0.01081","248.94353","0.00000"
"32.60000","1.08422","2494.06396","0.01084","249.40640","0.00000"
"32.70000","1.08764","2500.11230","0.01088","250.01123","0.00000"
"32.80000","1.09098","2505.54590","0.01091","250.55460","0.00000"
"32.90000","1.09425","2510.68945","0.01094","251.06894","0.00000"
"33.00000","1.09763","2516.58081","0.01098","251.65808","-0.00001"
"33.10000","1.10105","2522.45215","0.01101","252.24521","0.00000"
"33.20000","1.10440","2528.20557","0.01104","252.82056","0.00000"
"33.30000","1.10757","2532.74536","0.01108","253.27454","0.00000"
"33.40000","1.11095","2538.58838","0.01111","253.85884","0.00000"
"33.50000","1.11426","2543.88574","0.01114","254.38858","0.00000"
"33.60000","1.11755","2549.17456","0.01118","254.91745","0.00000"
"33.70000","1.12099","2555.24438","0.01121","255.52444","0.00000"
"33.80000","1.12435","2560.54077","0.01124","256.05408","0.00000"
"33.90000","1.12764","2565.72925","0.01128","256.57294","0.00000"
"34.00000","1.13085","2570.61279","0.01131","257.06128","0.00000"
"34.10000","1.13431","2576.88306","0.01134","257.68829","0.00000"
"34.20000","1.13766","2582.31470","0.01138","258.23148","0.00000"
"34.30000","1.14087","2587.15332","0.01141","258.71533","0.00000"
"34.40000","1.14431","2593.33618","0.01144","259.33362","0.00000"
"34.50000","1.14767","2598.83521","0.01148","259.88351","0.00000"
"34.60000","1.15097","2603.91675","0.01151","260.39166","0.00000"
"34.70000","1.15423","2608.94458","0.01154","260.89447","0.00000"
"34.80000","1.15769","2615.18970","0.01158","261.51898","-0.00001"
"34.90000","1.16112","2621.06982","0.01161","262.10699","0.00000"
"35.00000","1.16427","2625.51440","0.01164","262.55145","0.00000"
"35.10000","1.16767","2631.32471","0.01168","263.13248","0.00000"
"35.20000","1.17093","2636.18579","0.01171","263.61859","0.00000"
"35.30000","1.17422","2641.42798","0.01174","264.14279","0.00000"
"35.40000","1.17748","2646.63721","0.01177","264.66373","0.00000"
"35.50000","1.18112","2653.81738","0.01181","265.38174","0.00000"
"35.60000","1.18438","2658.69336","0.01184","265.86932","0.00000"
"35.70000","1.18751","2662.82275","0.01188","266.28229","0.00000"
"35.80000","1.19098","2669.26392","0.01191","266.92639","-0.00001"
"35.90000","1.19421","2673.84937","0.01194","267.38495","0.00000"
"36.00000","1.19759","2679.38013","0.01198","267.93802","0.00000"
"36.10000","1.20081","2684.47070","0.01201","268.44708","0.00000"
"36.20000","1.20446","2691.60278","0.01204","269.16028","0.00000"
"36.30000","1.20778","2696.61011","0.01208","269.66101","0.00000"
"36.40000","1.21090","2700.86084","0.01211","270.08609","0.00000"
"36.50000","1.21436","2706.85767","0.01214","270.68576","0.00000"
"36.60000","1.21758","2711.59497","0.01218","271.15948","0.00000"
"36.70000","1.22097","2717.12183","0.01221","271.71219","0.00000"
"36.80000","1.22425","2722.34692","0.01224","272.23468","0.00000"
"36.90000","1.22769","2728.37646","0.01228","272.83765","0.00000"
"37.00000","1.23101","2733.71167","0.01231","273.37115","0.00000"
"37.10000","1.23417","2737.96069","0.01234","273.79608","0.00000"
"37.20000","1.23764","2744.36694","0.01238","274.43671","0.00000"
"37.30000","1.24103","2750.03540","0.01241","275.00354","0.00000"
"37.40000","1.24426","2754.57324","0.01244","275.45734","0.00000"
"37.50000","1.24755","2759.82861","0.01248","275.98285","0.00000"
"37.60000","1.25101","2765.72412","0.01251","276.57242","-0.00001"
"37.70000","1.25426","2770.58667","0.01254","277.05865","0.00000"
"37.80000","1.25753","2775.52124","0.01258","277.55212","0.00000"
"37.90000","1.26100","2781.66504","0.01261","278.16650","0.00000"
"38.00000","1.26444","2787.54614","0.01264","278.75461","0.00000"
"38.10000","1.26762","2791.95264","0.01268","279.19525","0.00000"
"38.20000","1.27094","2797.18628","0.01271","279.71863","0.00000"
"38.30000","1.27432","2802.61279","0.01274","280.26129","-0.00001"
"38.40000","1.27757","2807.39331","0.01278","280.73932","0.00000"
"38.50000","1.28093","2812.83472","0.01281","281.28348","0.00000"
"38.60000","1.28436","2818.96045","0.01284","281.89606","0.00000"
"38.70000","1.28780","2824.48779","0.01288","282.44879","0.00000"
"38.80000","1.29091","2828.35205","0.01291","282.83521","0.00000"
"38.90000","1.29429","2833.91064","0.01294","283.39105","0.00000"
"39.00000","1.29755","2838.73853","0.01298","283.87384","0.00000"
"39.10000","1.30096","2844.39331","0.01301","284.43933","0.00000"
"39.20000","1.30425","2849.51343","0.01304","284.95135","0.00000"
"39.30000","1.30763","2854.99170","0.01308","285.49918","0.00000"
"39.40000","1.31107","2860.94238","0.01311","286.09424","0.00000"
"39.50000","1.31419","2864.93555","0.01314","286.49356","0.00000"
"39.60000","1.31764","2870.90234","0.01318","287.09024","-0.00001"
"39.70000","1.32090","2875.74097","0.01321","287.57410","0.00000"
"39.80000","1.32423","2881.04346","0.01324","288.10434","-0.00001"
"39.90000","1.32764","2886.76929","0.01328","288.67694","0.00000"
"40.00000","1.33106","2892.30688","0.01331","289.23068","0.00000"
"40.10000","1.33438","2897.42432","0.01334","289.74243","-0.00001"
"40.20000","1.33758","2901.89575","0.01338","290.18958","0.00000"
"40.30000","1.34109","2908.18115","0.01341","290.81812","-0.00001"
"40.40000","1.34434","2912.90649","0.01344","291.29065","0.00000"
"40.50000","1.34764","2917.73950","0.01348","291.77396","0.00000"
"40.60000","1.35092","2922.78931","0.01351","292.27893","0.00000"
"40.70000","1.35430","2928.36035","0.01354","292.83603","0.00000"
"40.80000","1.35757","2933.10352","0.01358","293.31036","-0.00001"
"40.90000","1.36089","2938.35059","0.01361","293.83505","0.00000"
"41.00000","1.36438","2944.35278","0.01364","294.43527","0.00000"
"41.10000","1.36765","2949.36768","0.01368","294.93677","0.00000"
"41.20000","1.37093","2954.23560","0.01371","295.42355","0.00000"
"41.30000","1.37426","2959.38306","0.01374","295.93829","0.00000"
"41.40000","1.37764","2964.75513","0.01378","296.47552","0.00000"
"41.50000","1.38086","2969.22949","0.01381","296.92294","0.00000"
"41.60000","1.38421","2974.61938","0.01384","297.46194","0.00000"
"41.70000","1.38772","2980.76709","0.01388","298.07672","0.00000"
"41.80000","1.39111","2986.11841","0.01391","298.61185","-0.00001"
"41.90000","1.39428","2990.21655","0.01394","299.02167","0.00000"
"42.00000","1.39758","2995.38940","0.01398","299.53894","0.00000"
"42.10000","1.40105","3000.98120","0.01401","300.09811","-0.00001"
"42.20000","1.40418","3005.03027","0.01404","300.50302","0.00000"
"42.30000","1.40761","3010.99683","0.01408","301.09967","0.00000"
"42.40000","1.41103","3016.62891","0.01411","301.66290","0.00000"
"42.50000","1.41440","3022.09106","0.01414","302.20911","0.00000"
"42.60000","1.41749","3025.86450","0.01417","302.58646","0.00000"
"42.70000","1.42101","3032.13867","0.01421","303.21387","0.00000"
"42.80000","1.42430","3036.83423","0.01424","303.68341","-0.00001"
"42.90000","1.42751","3041.14478","0.01428","304.11447","0.00000"
"43.00000","1.43093","3047.07397","0.01431","304.70740","0.00000"
"43.10000","1.43435","3052.44873","0.01434","305.24487","0.00000"
"43.20000","1.43769","3057.68872","0.01438","305.76886","0.00000"
"43.30000","1.44080","3061.40381","0.01441","306.14038","-0.00001"
"43.40000","1.44434","3068.02661","0.01444","306.80267","0.00000"
"43.50000","1.44770","3072.99365","0.01448","307.29938","0.00000"
"43.60000","1.45090","3077.27124","0.01451","307.72711","0.00000"
"43.70000","1.45432","3083.12598","0.01454","308.31259","0.00000"
"43.80000","1.45763","3087.93188","0.01458","308.79318","-0.00001"
"43.90000","1.46109","3093.74487","0.01461","309.37448","0.00000"
"44.00000","1.46416","3097.34619","0.01464","309.73462","0.00000"
"44.10000","1.46779","3104.21606","0.01468","310.42160","-0.00001"
"44.20000","1.47103","3108.80981","0.01471","310.88098","0.00000"
"44.30000","1.47427","3113.26172","0.01474","311.32617","0.00000"
"44.40000","1.47758","3118.34009","0.01478","311.83401","0.00000"
"44.50000","1.48096","3123.70972","0.01481","312.37097","0.00000"
"44.60000","1.48434","3129.02148","0.01484","312.90216","-0.00001"
"44.70000","1.48747","3133.02539","0.01487","313.30255","0.00001"
"44.80000","1.49103","3139.64966","0.01491","313.96497","0.00000"
"44.90000","1.49441","3144.78979","0.01494","314.47897","0.00000"
"45.00000","1.49757","3148.93311","0.01498","314.89331","0.00000"
"45.10000","1.50088","3153.97681","0.01501","315.39767","-0.00001"
"45.20000","1.50428","3159.35352","0.01504","315.93536","0.00000"
"45.30000","1.50759","3164.23926","0.01508","316.42392","0.00000"
"45.40000","1.51089","3169.24756","0.01511","316.92474","0.00000"
"45.50000","1.51443","3175.36475","0.01514","317.53647","0.00000"
"45.60000","1.51773","3179.97632","0.01518","317.99762","-0.00001"
"45.70000","1.52099","3184.44922","0.01521","318.44492","0.00000"
"45.80000","1.52428","3189.24756","0.01524","318.92474","0.00000"
"45.90000","1.52771","3194.71167","0.01528","319.47116","-0.00001"
"46.00000","1.53089","3198.69141","0.01531","319.86914","0.00000"
"46.10000","1.53425","3204.11597","0.01534","320.41159","-0.00001"
"46.20000","1.53762","3209.26782","0.01538","320.92679","0.00000"
"46.30000","1.54102","3214.85815","0.01541","321.48581","0.00000"
"46.40000","1.54421","3218.93872","0.01544","321.89386","0.00000"
"46.50000","1.54759","3224.25513","0.01548","322.42551","0.00000"
"46.60000","1.55099","3229.69751","0.01551","322.96976","-0.00001"
"46.70000","1.55425","3234.33496","0.01554","323.43350","0.00000"
"46.80000","1.55762","3239.58252","0.01558","323.95825","0.00000"
"46.90000","1.56093","3244.25732","0.01561","324.42572","0.00000"
"47.00000","1.56431","3249.59912","0.01564","324.95990","0.00000"
"47.10000","1.56757","3254.18604","0.01568","325.41861","-0.00001"
"47.20000","1.57107","3260.20459","0.01571","326.02045","0.00000"
"47.30000","1.57442","3265.21387","0.01574","326.52139","0.00000"
"47.40000","1.57759","3269.30200","0.01578","326.93021","-0.00001"
"47.50000","1.58104","3275.11279","0.01581","327.51129","0.00000"
"47.60000","1.58424","3279.26343","0.01584","327.92633","-0.00001"
"47.70000","1.58760","3284.53735","0.01588","328.45374","0.00000"
"47.80000","1.59086","3289.38257","0.01591","328.93826","0.00000"
"47.90000","1.59437","3295.35596","0.01594","329.53558","-0.00001"
"48.00000","1.59768","3300.29395","0.01598","330.02939","0.00000"
"48.10000","1.60092","3304.87256","0.01601","330.48724","-0.00001"
"48.20000","1.60433","3310.23755","0.01604","331.02374","0.00000"
"48.30000","1.60755","3314.58081","0.01608","331.45807","0.00000"
"48.40000","1.61089","3319.67407","0.01611","331.96741","-0.00001"
"48.50000","1.61423","3324.66113","0.01614","332.46613","0.00000"
"48.60000","1.61775","3330.68994","0.01618","333.06900","-0.00001"
"48.70000","1.62099","3335.08545","0.01621","333.50854","0.00000"
"48.80000","1.62417","3339.11255","0.01624","333.91125","0.00000"
"48.90000","1.62768","3344.98804","0.01628","334.49881","-0.00001"
"49.00000","1.63098","3349.64160","0.01631","334.96417","0.00000"
"49.10000","1.63424","3354.18237","0.01634","335.41824","-0.00001"
"49.20000","1.63763","3359.54810","0.01638","335.95480","0.00000"
"49.30000","1.64111","3365.27148","0.01641","336.52716","0.00000"
"49.40000","1.64432","3369.41260","0.01644","336.94125","0.00000"
"49.50000","1.64756","3374.00098","0.01648","337.40009","0.00000"
"49.60000","1.65097","3379.53613","0.01651","337.95361","-0.00001"
"49.70000","1.65436","3385.02686","0.01654","338.50269","0.00000"
"49.80000","1.65755","3388.97827","0.01658","338.89783","0.00000"
"49.90000","1.66094","3394.51050","0.01661","339.45105","0.00000"
"50.00000","1.66437","3399.83765","0.01664","339.98376","0.00000"
"50.10000","1.66755","3404.12378","0.01668","340.41238","-0.00001"
"50.20000","1.67083","3409.01025","0.01671","340.90103","0.00000"
"50.30000","1.67439","3415.13599","0.01674","341.51361","0.00000"
"50.40000","1.67768","3419.99316","0.01678","341.99933","-0.00001"
"50.50000","1.68091","3424.38062","0.01681","342.43805","0.00000"
"50.60000","1.68426","3429.63477","0.01684","342.96347","0.00000"
"50.70000","1.68761","3434.46729","0.01688","343.44672","0.00000"
"50.80000","1.69091","3439.10913","0.01691","343.91092","0.00000"
"50.90000","1.69424","3444.25488","0.01694","344.42548","-0.00001"
"51.00000","1.69778","3450.15259","0.01698","345.01526","0.00000"
"51.10000","1.70117","3455.55200","0.01701","345.55521","0.00000"
"51.20000","1.70419","3458.49658","0.01704","345.84967","0.00000"
"51.30000","1.70767","3464.45190","0.01708","346.44519","0.00000"
"51.40000","1.71089","3468.74414","0.01711","346.87442","-0.00001"
"51.50000","1.71424","3473.90015","0.01714","347.39001","0.00000"
"51.60000","1.71757","3478.78198","0.01718","347.87820","-0.00001"
"51.70000","1.72102","3484.16821","0.01721","348.41681","0.00000"
"51.80000","1.72446","3489.73193","0.01724","348.97321","0.00000"
"51.90000","1.72748","3492.86450","0.01727","349.28644","-0.00001"
"52.00000","1.73088","3498.37720","0.01731","349.83771","0.00000"
"52.10000","1.73439","3504.19775","0.01734","350.41977","0.00000"
"52.20000","1.73756","3508.12402","0.01738","350.81241","0.00000"
"52.30000","1.74088","3513.12769","0.01741","351.31277","0.00001"
"52.40000","1.74435","3518.57739","0.01744","351.85773","-0.00001"
"52.50000","1.74769","3523.53369","0.01748","352.35336","0.00000"
"52.60000","1.75086","3527.40112","0.01751","352.74011","-0.00001"
"52.70000","1.75436","3533.37598","0.01754","353.33759","0.00000"
"52.80000","1.75773","3538.38916","0.01758","353.83893","0.00000"
"52.90000","1.76101","3542.88452","0.01761","354.28845","-0.00001"
"53.00000","1.76426","3547.35522","0.01764","354.73553","0.00000"
"53.10000","1.76764","3552.34106","0.01768","355.23410","0.00000"
"53.20000","1.77096","3556.95410","0.01771","355.69540","0.00000"
"53.30000","1.77416","3561.36646","0.01774","356.13666","0.00000"
"53.40000","1.77765","3566.98267","0.01778","356.69827","0.00000"
"53.50000","1.78104","3572.19604","0.01781","357.21960","0.00000"
"53.60000","1.78430","3576.46680","0.01784","357.64667","0.00000"
"53.70000","1.78763","3581.20020","0.01788","358.12003","-0.00001"
"53.80000","1.79088","3585.40088","0.01791","358.54010","0.00001"
"53.90000","1.79426","3590.23999","0.01794","359.02399","-0.00001"
"54.00000","1.79755","3595.00903","0.01798","359.50092","0.00000"
"54.10000","1.80102","3600.67383","0.01801","360.06738","0.00000"
"54.20000","1.80439","3605.48657","0.01804","360.54865","0.00000"
"54.30000","1.80758","3609.50415","0.01808","360.95041","0.00000"
"54.40000","1.81097","3614.44800","0.01811","361.44479","0.00000"
"54.50000","1.81432","3619.18066","0.01814","361.91806","0.00000"
"54.60000","1.81760","3623.40894","0.01818","362.34088","0.00000"
"54.70000","1.82098","3628.72485","0.01821","362.87250","-0.00001"
"54.80000","1.82437","3633.62256","0.01824","363.36224","0.00000"
"54.90000","1.82772","3638.51636","0.01828","363.85162","0.00000"
"55.00000","1.83089","3642.19238","0.01831","364.21924","0.00000"
"55.10000","1.83427","3647.15161","0.01834","364.71515","0.00000"
"55.20000","1.83762","3652.21948","0.01838","365.22195","0.00000"
"55.30000","1.84092","3656.56836","0.01841","365.65683","0.00000"
"55.40000","1.84431","3661.84717","0.01844","366.18472","-0.00001"
"55.50000","1.84767","3666.44043","0.01848","366.64404","0.00000"
"55.60000","1.85096","3670.86572","0.01851","367.08658","0.00000"
"55.70000","1.85419","3675.16943","0.01854","367.51694","0.00000"
"55.80000","1.85763","3680.69751","0.01858","368.06976","0.00000"
"55.90000","1.86099","3685.46631","0.01861","368.54663","0.00000"
"56.00000","1.86421","3689.82227","0.01864","368.98224","0.00000"
"56.10000","1.86766","3695.14941","0.01868","369.51495","0.00000"
"56.20000","1.87103","3700.16235","0.01871","370.01624","-0.00001"
"56.30000","1.87431","3704.43994","0.01874","370.44400","0.00000"
"56.40000","1.87758","3708.75220","0.01878","370.87521","-0.00001"
"56.50000","1.88107","3714.59863","0.01881","371.45987","0.00000"
"56.60000","1.88445","3719.44189","0.01884","371.94418","0.00000"
"56.70000","1.88757","3723.05615","0.01888","372.30560","-0.00001"
"56.80000","1.89097","3728.30396","0.01891","372.83038","0.00000"
"56.90000","1.89428","3732.73608","0.01894","373.27362","-0.00001"
"57.00000","1.89756","3737.15161","0.01898","373.71515","0.00000"
"57.10000","1.90081","3741.51807","0.01901","374.15179","0.00000"
"57.20000","1.90443","3747.76392","0.01904","374.77640","0.00000"
"57.30000","1.90772","3752.22754","0.01908","375.22275","0.00001"
"57.40000","1.91085","3755.82886","0.01911","375.58289","-0.00001"
"57.50000","1.91431","3761.47363","0.01914","376.14737","0.00000"
"57.60000","1.91756","3765.61206","0.01918","376.56122","0.00000"
"57.70000","1.92093","3770.48706","0.01921","377.04871","0.00000"
"57.80000","1.92419","3774.99097","0.01924","377.49908","0.00000"
"57.90000","1.92777","3780.96875","0.01928","378.09686","0.00000"
"58.00000","1.93112","3785.65332","0.01931","378.56534","0.00000"
"58.10000","1.93418","3788.91113","0.01934","378.89111","0.00000"
"58.20000","1.93767","3794.77222","0.01938","379.47723","-0.00001"
"58.30000","1.94099","3799.22168","0.01941","379.92218","0.00000"
"58.40000","1.94425","3803.65698","0.01944","380.36569","0.00000"
"58.50000","1.94757","3808.46606","0.01948","380.84662","-0.00001"
"58.60000","1.95102","3813.94727","0.01951","381.39471","0.00000"
"58.70000","1.95436","3818.82422","0.01954","381.88242","-0.00001"
"58.80000","1.95752","3822.66724","0.01958","382.26672","0.00000"
"58.90000","1.96096","3828.01172","0.01961","382.80118","-0.00001"
"59.00000","1.96438","3833.05176","0.01964","383.30518","0.00000"
"59.10000","1.96762","3837.22412","0.01968","383.72241","0.00000"
"59.20000","1.97090","3841.84302","0.01971","384.18430","-0.00001"
"59.30000","1.97437","3847.32788","0.01974","384.73279","0.00000"
"59.40000","1.97755","3851.13135","0.01978","385.11313","0.00000"
"59.50000","1.98083","3855.68359","0.01981","385.56836","0.00000"
"59.60000","1.98433","3861.30396","0.01984","386.13040","0.00000"
"59.70000","1.98776","3866.60693","0.01988","386.66071","-0.00001"
"59.80000","1.99093","3870.11353","0.01991","387.01135","0.00000"
"59.90000","1.99426","3874.65088","0.01994","387.46509","0.00000"
"60.00000","1.99767","3879.55127","0.01998","387.95514","0.00000"
"60.10000","2.00092","3883.47290","0.02001","388.34729","0.00000"
"60.20000","2.00425","3888.09668","0.02004","388.80966","0.00000"
"60.30000","2.00771","3893.61597","0.02008","389.36160","0.00000"
"60.40000","2.01116","3898.73340","0.02011","389.87335","0.00000"
"60.50000","2.01422","3901.84888","0.02014","390.18488","0.00000"
"60.60000","2.01763","3906.93945","0.02018","390.69394","0.00000"
"60.70000","2.02090","3911.14795","0.02021","391.11481","-0.00001"
"60.80000","2.02425","3915.95630","0.02024","391.59564","0.00000"
"60.90000","2.02763","3920.68994","0.02028","392.06900","0.00000"
"61.00000","2.03095","3925.23584","0.02031","392.52359","-0.00001"
"61.10000","2.03437","3930.37988","0.02034","393.03799","0.00000"
"61.20000","2.03754","3934.07056","0.02038","393.40704","-0.00001"
"61.30000","2.04095","3939.00415","0.02041","393.90042","0.00000"
"61.40000","2.04428","3943.56396","0.02044","394.35638","-0.00001"
"61.50000","2.04757","3947.79297","0.02048","394.77930","0.00000"
"61.60000","2.05097","3952.87085","0.02051","395.28708","0.00000"
"61.70000","2.05438","3957.67700","0.02054","395.76770","-0.00001"
"61.80000","2.05770","3961.99829","0.02058","396.19983","0.00000"
"61.90000","2.06091","3965.91162","0.02061","396.59116","-0.00001"
"62.00000","2.06441","3971.18042","0.02064","397.11804","0.00000"
"62.10000","2.06766","3975.30396","0.02068","397.53040","-0.00001"
"62.20000","2.07097","3979.53662","0.02071","397.95367","0.00000"
"62.30000","2.07430","3984.06494","0.02074","398.40649","0.00000"
"62.40000","2.07759","3987.89819","0.02078","398.78983","0.00000"
"62.50000","2.08086","3991.75073","0.02081","399.17508","0.00000"
"62.60000","2.08420","3996.49878","0.02084","399.64987","0.00000"
"62.70000","2.08774","4002.13818","0.02088","400.21381","-0.00001"
"62.80000","2.09101","4006.18652","0.02091","400.61865","0.00000"
"62.90000","2.09425","4009.90015","0.02094","400.99002","0.00000"
"63.00000","2.09762","4014.53760","0.02098","401.45377","0.00000"
"63.10000","2.10097","4018.97656","0.02101","401.89764","0.00000"
"63.20000","2.10419","4022.70996","0.02104","402.27100","-0.00001"
"63.30000","2.10758","4027.73096","0.02108","402.77310","0.00000"
"63.40000","2.11107","4033.10742","0.02111","403.31073","-0.00001"
"63.50000","2.11443","4037.93896","0.02114","403.79388","0.00000"
"63.60000","2.11762","4041.38330","0.02118","404.13834","0.00000"
"63.70000","2.12092","4045.70996","0.02121","404.57098","0.00000"
"63.80000","2.12437","4050.96069","0.02124","405.09607","0.00000"
"63.90000","2.12753","4054.59814","0.02128","405.45981","-0.00001"
"64.00000","2.13097","4059.92163","0.02131","405.99216","0.00000"
"64.10000","2.13436","4064.81299","0.02134","406.48129","0.00000"
"64.20000","2.13772","4069.45654","0.02138","406.94565","0.00000"
"64.30000","2.14081","4072.72388","0.02141","407.27240","0.00000"
"64.40000","2.14434","4078.33716","0.02144","407.83371","-0.00001"
"64.50000","2.14765","4082.54590","0.02148","408.25458","0.00000"
"64.60000","2.15086","4086.32373","0.02151","408.63239","0.00000"
"64.70000","2.15427","4091.13647","0.02154","409.11365","0.00000"
"64.80000","2.15765","4095.93921","0.02158","409.59393","0.00000"
"64.90000","2.16102","4100.50781","0.02161","410.05078","0.00000"
"65.00000","2.16411","4103.65723","0.02164","410.36572","0.00000"
"65.10000","2.16770","4109.49316","0.02168","410.94931","0.00000"
"65.20000","2.17104","4113.96045","0.02171","411.39606","0.00000"
"65.30000","2.17423","4117.25537","0.02174","411.72552","0.00000"
"65.40000","2.17768","4121.97803","0.02178","412.19781","0.00000"
"65.50000","2.18094","4125.90967","0.02181","412.59097","0.00000"
"65.60000","2.18440","4131.14697","0.02184","413.11469","0.00000"
"65.70000","2.18749","4134.03906","0.02187","413.40390","0.00000"
"65.80000","2.19111","4139.98486","0.02191","413.99847","0.00000"
"65.90000","2.19439","4144.25195","0.02194","414.42520","0.00000"
"66.00000","2.19761","4148.10938","0.02198","414.81094","0.00000"
"66.10000","2.20091","4152.37939","0.02201","415.23795","0.00000"
"66.20000","2.20426","4156.88525","0.02204","415.68854","0.00000"
"66.30000","2.20762","4161.48633","0.02208","416.14862","0.00000"
"66.40000","2.21080","4165.12598","0.02211","416.51260","0.00000"
"66.50000","2.21435","4170.83740","0.02214","417.08374","0.00000"
"66.60000","2.21774","4175.64014","0.02218","417.56403","0.00000"
"66.70000","2.22091","4179.48535","0.02221","417.94855","0.00000"
"66.80000","2.22425","4184.13965","0.02224","418.41397","0.00000"
"66.90000","2.22762","4188.78564","0.02228","418.87857","-0.00001"
"67.00000","2.23093","4193.24512","0.02231","419.32452","0.00000"
"67.10000","2.23424","4197.77295","0.02234","419.77728","0.00000"
"67.20000","2.23777","4203.47949","0.02238","420.34796","0.00000"
"67.30000","2.24104","4207.63623","0.02241","420.76361","0.00000"
"67.40000","2.24429","4212.09570","0.02244","421.20956","0.00000"
"67.50000","2.24759","4216.42285","0.02248","421.64227","0.00000"
"67.60000","2.25106","4221.82666","0.02251","422.18268","0.00000"
"67.70000","2.25422","4225.22705","0.02254","422.52271","0.00000"
"67.80000","2.25760","4230.19629","0.02258","423.01962","0.00000"
"67.90000","2.26095","4234.67773","0.02261","423.46777","0.00000"
"68.00000","2.26433","4239.56836","0.02264","423.95685","-0.00001"
"68.10000","2.26757","4243.45361","0.02268","424.34537","0.00000"
"68.20000","2.27095","4248.54785","0.02271","424.85480","0.00000"
"68.30000","2.27436","4253.49756","0.02274","425.34976","0.00000"
"68.40000","2.27759","4257.42676","0.02278","425.74268","-0.00001"
"68.50000","2.28096","4262.35107","0.02281","426.23511","0.00000"
"68.60000","2.28426","4266.54639","0.02284","426.65463","0.00000"
"68.70000","2.28758","4270.82129","0.02288","427.08212","0.00000"
"68.80000","2.29088","4275.11670","0.02291","427.51166","0.00000"
"68.90000","2.29443","4280.31543","0.02294","428.03156","0.00000"
"69.00000","2.29776","4282.76270","0.02298","428.27628","0.00000"
"69.10000","2.30091","4285.80176","0.02301","428.58017","-0.00001"
"69.20000","2.30437","4289.47998","0.02304","428.94800","0.00000"
"69.30000","2.30756","4292.72412","0.02308","429.27240","0.00000"
"69.40000","2.31097","4297.26904","0.02311","429.72690","0.00000"
"69.50000","2.31422","4300.59570","0.02314","430.05957","0.00000"
"69.60000","2.31773","4304.97021","0.02318","430.49701","0.00000"
"69.70000","2.32103","4308.59326","0.02321","430.85931","0.00000"
"69.80000","2.32423","4311.22803","0.02324","431.12280","0.00000"
"69.90000","2.32767","4313.23926","0.02328","431.32391","0.00000"
"70.00000","2.33090","4316.28760","0.02331","431.62875","0.00000"
"70.10000","2.33420","4317.56396","0.02334","431.75641","0.00000"
"70.20000","2.33760","4317.07275","0.02338","431.70728","-0.00001"
"70.30000","2.34106","4311.93311","0.02341","431.19330","0.00000"
"70.40000","2.34431","4305.03809","0.02344","430.50381","0.00000"
"70.50000","2.34754","4279.45117","0.02348","427.94513","0.00000"
"70.60000","2.35100","4189.54297","0.02351","418.95428","0.00000"
"70.70000","2.35437","4118.94092","0.02354","411.89410","0.00000"
"70.75800","2.35628","3945.92700","0.02356","394.59271","0.00000"
"70.76000","2.35634","3811.39111","0.02356","381.13910","0.00000"
"70.76200","2.35640","3642.93604","0.02356","364.29361","0.00000"
"70.76400","2.35646","3449.16504","0.02356","344.91650","0.00000"
"70.76600","2.35652","3237.03516","0.02357","323.70352","0.00000"
"70.76800","2.35659","3012.57886","0.02357","301.25787","0.00001"
"70.77000","2.35667","2781.04175","0.02357","278.10419","0.00001"
"70.77200","2.35675","2546.94653","0.02357","254.69466","0.00002"
"70.77300","2.35679","2430.15674","0.02357","243.01567","0.00002"