File: Tension/Section_2_Group_2/hybrid_low_Sample1_redone.is_tens_RawData/Specimen_RawData_1.csv
Time,Extension,Load,Tensile strain (Extension),Tensile stress,Strain-by-clip-gage
(s),(mm),(N),(mm/mm),(MPa),(mm/mm)
"0.00000","0.00000","-400.07666","0.00000","-40.00767","-0.00027"
"0.10000","0.00065","-395.79929","0.00001","-39.57993","-0.00032"
"0.20000","0.00290","-378.65204","0.00003","-37.86520","-0.00028"
"0.30000","0.00772","-342.53745","0.00008","-34.25375","-0.00031"
"0.40000","0.01115","-317.63690","0.00011","-31.76369","-0.00032"
"0.50000","0.01436","-294.64780","0.00014","-29.46478","-0.00029"
"0.60000","0.01787","-269.40295","0.00018","-26.94030","-0.00032"
"0.70000","0.02107","-246.69659","0.00021","-24.66966","-0.00029"
"0.80000","0.02446","-222.56505","0.00024","-22.25650","-0.00028"
"0.90000","0.02774","-199.37909","0.00028","-19.93791","-0.00032"
"1.00000","0.03114","-175.54883","0.00031","-17.55488","-0.00030"
"1.10000","0.03441","-152.78381","0.00034","-15.27838","-0.00032"
"1.20000","0.03769","-129.85287","0.00038","-12.98529","-0.00030"
"1.30000","0.04118","-105.43084","0.00041","-10.54308","-0.00030"
"1.40000","0.04445","-82.92190","0.00044","-8.29219","-0.00030"
"1.50000","0.04772","-60.32911","0.00048","-6.03291","-0.00029"
"1.60000","0.05106","-37.39706","0.00051","-3.73971","-0.00033"
"1.70000","0.05444","-14.29403","0.00054","-1.42940","-0.00029"
"1.80000","0.05767","7.79434","0.00058","0.77943","-0.00029"
"1.90000","0.06101","30.68105","0.00061","3.06810","-0.00031"
"2.00000","0.06454","54.76113","0.00065","5.47611","-0.00027"
"2.10000","0.06792","77.43597","0.00068","7.74360","-0.00034"
"2.20000","0.07112","98.63977","0.00071","9.86398","-0.00030"
"2.30000","0.07440","120.70687","0.00074","12.07069","-0.00031"
"2.40000","0.07785","143.75491","0.00078","14.37549","-0.00029"
"2.50000","0.08100","164.59651","0.00081","16.45965","-0.00029"
"2.60000","0.08441","187.57440","0.00084","18.75744","-0.00031"
"2.70000","0.08784","210.42114","0.00088","21.04211","-0.00029"
"2.80000","0.09119","232.66376","0.00091","23.26638","-0.00033"
"2.90000","0.09433","253.49625","0.00094","25.34962","-0.00029"
"3.00000","0.09779","276.77139","0.00098","27.67714","-0.00030"
"3.10000","0.10108","298.34445","0.00101","29.83445","-0.00031"
"3.20000","0.10436","319.96628","0.00104","31.99663","-0.00029"
"3.30000","0.10773","342.37427","0.00108","34.23743","-0.00033"
"3.40000","0.11115","365.04675","0.00111","36.50468","-0.00029"
"3.50000","0.11451","387.21912","0.00115","38.72191","-0.00030"
"3.60000","0.11761","407.02084","0.00118","40.70208","-0.00030"
"3.70000","0.12116","430.92938","0.00121","43.09294","-0.00029"
"3.80000","0.12444","452.25803","0.00124","45.22580","-0.00032"
"3.90000","0.12769","473.54172","0.00128","47.35417","-0.00030"
"4.00000","0.13112","496.26981","0.00131","49.62698","-0.00031"
"4.10000","0.13444","518.03455","0.00134","51.80346","-0.00030"
"4.20000","0.13792","541.31586","0.00138","54.13158","-0.00030"
"4.30000","0.14093","560.53235","0.00141","56.05323","-0.00031"
"4.40000","0.14453","584.77448","0.00145","58.47745","-0.00030"
"4.50000","0.14781","606.13538","0.00148","60.61354","-0.00031"
"4.60000","0.15110","627.52374","0.00151","62.75237","-0.00030"
"4.70000","0.15435","648.74042","0.00154","64.87404","-0.00030"
"4.80000","0.15776","671.18201","0.00158","67.11820","-0.00031"
"4.90000","0.16112","693.19019","0.00161","69.31902","-0.00027"
"5.00000","0.16431","713.97668","0.00164","71.39767","-0.00029"
"5.10000","0.16781","737.46893","0.00168","73.74689","-0.00030"
"5.20000","0.17120","759.78503","0.00171","75.97850","-0.00029"
"5.30000","0.17439","780.35266","0.00174","78.03526","-0.00032"
"5.40000","0.17770","802.11682","0.00178","80.21169","-0.00029"
"5.50000","0.18109","824.50342","0.00181","82.45034","-0.00032"
"5.60000","0.18439","846.12164","0.00184","84.61217","-0.00028"
"5.70000","0.18765","867.37061","0.00188","86.73706","-0.00031"
"5.80000","0.19122","891.32928","0.00191","89.13293","-0.00031"
"5.90000","0.19456","913.44995","0.00195","91.34499","-0.00030"
"6.00000","0.19778","934.42358","0.00198","93.44236","-0.00032"
"6.10000","0.20107","956.04004","0.00201","95.60400","-0.00028"
"6.20000","0.20449","978.72986","0.00204","97.87299","-0.00032"
"6.30000","0.20770","999.39246","0.00208","99.93925","-0.00029"
"6.40000","0.21107","1021.75848","0.00211","102.17585","-0.00030"
"6.50000","0.21442","1043.85962","0.00214","104.38596","-0.00032"
"6.60000","0.21784","1066.76245","0.00218","106.67625","-0.00028"
"6.70000","0.22106","1087.70789","0.00221","108.77079","-0.00032"
"6.80000","0.22440","1109.84216","0.00224","110.98421","-0.00029"
"6.90000","0.22778","1132.35840","0.00228","113.23584","-0.00031"
"7.00000","0.23106","1153.74036","0.00231","115.37404","-0.00031"
"7.10000","0.23440","1175.74719","0.00234","117.57472","-0.00029"
"7.20000","0.23776","1197.92322","0.00238","119.79232","-0.00032"
"7.30000","0.24110","1220.07471","0.00241","122.00747","-0.00028"
"7.40000","0.24436","1241.44604","0.00244","124.14461","-0.00031"
"7.50000","0.24789","1265.33240","0.00248","126.53324","-0.00030"
"7.60000","0.25120","1286.86890","0.00251","128.68689","-0.00030"
"7.70000","0.25444","1307.87402","0.00254","130.78740","-0.00032"
"7.80000","0.25783","1330.58069","0.00258","133.05807","-0.00029"
"7.90000","0.26105","1351.27795","0.00261","135.12779","-0.00031"
"8.00000","0.26445","1374.13037","0.00264","137.41304","-0.00029"
"8.10000","0.26767","1395.14050","0.00268","139.51405","-0.00030"
"8.20000","0.27120","1418.88196","0.00271","141.88820","-0.00031"
"8.30000","0.27449","1440.45422","0.00274","144.04543","-0.00030"
"8.40000","0.27773","1461.54517","0.00278","146.15451","-0.00032"
"8.50000","0.28114","1484.25745","0.00281","148.42575","-0.00029"
"8.60000","0.28435","1505.15247","0.00284","150.51524","-0.00030"
"8.70000","0.28769","1527.24097","0.00288","152.72409","-0.00031"
"8.80000","0.29102","1549.10413","0.00291","154.91042","-0.00030"
"8.90000","0.29451","1572.56531","0.00295","157.25653","-0.00032"
"9.00000","0.29783","1594.32178","0.00298","159.43217","-0.00030"
"9.10000","0.30103","1615.02319","0.00301","161.50232","-0.00030"
"9.20000","0.30441","1637.44653","0.00304","163.74466","-0.00030"
"9.30000","0.30781","1659.88354","0.00308","165.98836","-0.00029"
"9.40000","0.31108","1681.26111","0.00311","168.12611","-0.00032"
"9.50000","0.31439","1703.24109","0.00314","170.32411","-0.00030"
"9.60000","0.31793","1727.20166","0.00318","172.72017","-0.00031"
"9.70000","0.32111","1747.54016","0.00321","174.75401","-0.00030"
"9.80000","0.32439","1769.11853","0.00324","176.91185","-0.00029"
"9.90000","0.32779","1791.55249","0.00328","179.15524","-0.00031"
"10.00000","0.33111","1813.32544","0.00331","181.33255","-0.00029"
"10.10000","0.33439","1834.55444","0.00334","183.45544","-0.00030"
"10.20000","0.33774","1856.66479","0.00338","185.66647","-0.00031"
"10.30000","0.34115","1879.03845","0.00341","187.90384","-0.00028"
"10.40000","0.34443","1900.16296","0.00344","190.01630","-0.00033"
"10.50000","0.34762","1920.89099","0.00348","192.08910","-0.00030"
"10.60000","0.35118","1944.91284","0.00351","194.49129","-0.00031"
"10.70000","0.35448","1966.47461","0.00354","196.64746","-0.00030"
"10.80000","0.35770","1987.45752","0.00358","198.74576","-0.00029"
"10.90000","0.36107","2009.85925","0.00361","200.98593","-0.00031"
"11.00000","0.36439","2031.56616","0.00364","203.15662","-0.00029"
"11.10000","0.36777","2053.81763","0.00368","205.38176","-0.00032"
"11.20000","0.37109","2075.82764","0.00371","207.58276","-0.00030"
"11.30000","0.37459","2099.35474","0.00375","209.93547","-0.00030"
"11.40000","0.37796","2121.42163","0.00378","212.14217","-0.00031"
"11.50000","0.38103","2140.74731","0.00381","214.07474","-0.00028"
"11.60000","0.38441","2163.16504","0.00384","216.31650","-0.00032"
"11.70000","0.38773","2184.62207","0.00388","218.46220","-0.00029"
"11.80000","0.39106","2206.35767","0.00391","220.63577","-0.00031"
"11.90000","0.39430","2227.51025","0.00394","222.75102","-0.00031"
"12.00000","0.39784","2251.44971","0.00398","225.14497","-0.00029"
"12.10000","0.40123","2273.86914","0.00401","227.38692","-0.00031"
"12.20000","0.40433","2293.48315","0.00404","229.34831","-0.00029"
"12.30000","0.40771","2316.26196","0.00408","231.62619","-0.00031"
"12.40000","0.41111","2338.70654","0.00411","233.87065","-0.00030"
"12.50000","0.41441","2360.33179","0.00414","236.03317","-0.00030"
"12.60000","0.41768","2381.74023","0.00418","238.17403","-0.00031"
"12.70000","0.42116","2405.04980","0.00421","240.50497","-0.00029"
"12.80000","0.42453","2427.02173","0.00425","242.70218","-0.00031"
"12.90000","0.42766","2447.05908","0.00428","244.70590","-0.00030"
"13.00000","0.43117","2470.57129","0.00431","247.05713","-0.00030"
"13.10000","0.43453","2492.80933","0.00435","249.28093","-0.00031"
"13.20000","0.43779","2514.01465","0.00438","251.40146","-0.00029"
"13.30000","0.44107","2535.46338","0.00441","253.54634","-0.00032"
"13.40000","0.44447","2558.04346","0.00444","255.80435","-0.00030"
"13.50000","0.44776","2579.29272","0.00448","257.92926","-0.00030"
"13.60000","0.45098","2600.32202","0.00451","260.03220","-0.00032"
"13.70000","0.45449","2623.84790","0.00454","262.38480","-0.00028"
"13.80000","0.45782","2645.53882","0.00458","264.55389","-0.00032"
"13.90000","0.46107","2666.73145","0.00461","266.67316","-0.00029"
"14.00000","0.46442","2688.90186","0.00464","268.89020","-0.00031"
"14.10000","0.46769","2710.05518","0.00468","271.00552","-0.00032"
"14.20000","0.47105","2732.21240","0.00471","273.22125","-0.00028"
"14.30000","0.47438","2754.18750","0.00474","275.41876","-0.00033"
"14.40000","0.47786","2777.29907","0.00478","277.72992","-0.00028"
"14.50000","0.48119","2799.20898","0.00481","279.92090","-0.00031"
"14.60000","0.48439","2819.87964","0.00484","281.98798","-0.00031"
"14.70000","0.48779","2842.68457","0.00488","284.26846","-0.00029"
"14.80000","0.49113","2864.29541","0.00491","286.42953","-0.00032"
"14.90000","0.49442","2885.74927","0.00494","288.57492","-0.00028"
"15.00000","0.49775","2907.75562","0.00498","290.77557","-0.00031"
"15.10000","0.50121","2930.51367","0.00501","293.05136","-0.00030"
"15.20000","0.50454","2952.32202","0.00505","295.23221","-0.00030"
"15.30000","0.50769","2972.36133","0.00508","297.23615","-0.00031"
"15.40000","0.51109","2994.97461","0.00511","299.49747","-0.00029"
"15.50000","0.51440","3016.51709","0.00514","301.65170","-0.00032"
"15.60000","0.51771","3038.06689","0.00518","303.80670","-0.00030"
"15.70000","0.52112","3060.74170","0.00521","306.07416","-0.00031"
"15.80000","0.52452","3082.94238","0.00525","308.29425","-0.00031"
"15.90000","0.52777","3104.09766","0.00528","310.40976","-0.00028"
"16.00000","0.53098","3124.69702","0.00531","312.46970","-0.00031"
"16.10000","0.53446","3148.10913","0.00534","314.81091","-0.00029"
"16.20000","0.53776","3169.40576","0.00538","316.94058","-0.00031"
"16.30000","0.54099","3190.43701","0.00541","319.04370","-0.00031"
"16.40000","0.54443","3213.25732","0.00544","321.32574","-0.00029"
"16.50000","0.54780","3235.24658","0.00548","323.52466","-0.00031"
"16.60000","0.55112","3256.96313","0.00551","325.69632","-0.00029"
"16.70000","0.55438","3278.10522","0.00554","327.81052","-0.00031"
"16.80000","0.55784","3301.21729","0.00558","330.12173","-0.00030"
"16.90000","0.56127","3323.81055","0.00561","332.38104","-0.00030"
"17.00000","0.56442","3343.50537","0.00564","334.35052","-0.00031"
"17.10000","0.56779","3365.51587","0.00568","336.55157","-0.00029"
"17.20000","0.57107","3386.65869","0.00571","338.66586","-0.00031"
"17.30000","0.57437","3408.24829","0.00574","340.82483","-0.00030"
"17.40000","0.57762","3429.21606","0.00578","342.92160","-0.00030"
"17.50000","0.58127","3454.27466","0.00581","345.42746","-0.00031"
"17.60000","0.58451","3474.98804","0.00585","347.49881","-0.00029"
"17.70000","0.58765","3494.91675","0.00588","349.49167","-0.00031"
"17.80000","0.59111","3518.00244","0.00591","351.80023","-0.00029"
"17.90000","0.59436","3538.71362","0.00594","353.87137","-0.00030"
"18.00000","0.59774","3560.83472","0.00598","356.08347","-0.00031"
"18.10000","0.60098","3581.73926","0.00601","358.17392","-0.00030"
"18.20000","0.60458","3605.92749","0.00605","360.59274","-0.00031"
"18.30000","0.60790","3627.32666","0.00608","362.73267","-0.00029"
"18.40000","0.61104","3646.82642","0.00611","364.68265","-0.00031"
"18.50000","0.61450","3669.91992","0.00615","366.99200","-0.00030"
"18.60000","0.61773","3690.40405","0.00618","369.04041","-0.00030"
"18.70000","0.62110","3712.15820","0.00621","371.21582","-0.00031"
"18.80000","0.62437","3733.29810","0.00624","373.32980","-0.00030"
"18.90000","0.62787","3756.44946","0.00628","375.64496","-0.00031"
"19.00000","0.63118","3778.00879","0.00631","377.80087","-0.00030"
"19.10000","0.63434","3797.70288","0.00634","379.77029","-0.00030"
"19.20000","0.63780","3820.82324","0.00638","382.08234","-0.00031"
"19.30000","0.64115","3842.39038","0.00641","384.23904","-0.00029"
"19.40000","0.64444","3863.35303","0.00644","386.33530","-0.00031"
"19.50000","0.64769","3884.08423","0.00648","388.40842","-0.00030"
"19.60000","0.65114","3906.70215","0.00651","390.67023","-0.00030"
"19.70000","0.65440","3927.03003","0.00654","392.70300","-0.00031"
"19.80000","0.65762","3947.56421","0.00658","394.75641","-0.00030"
"19.90000","0.66116","3971.02002","0.00661","397.10199","-0.00031"
"20.00000","0.66458","3993.19385","0.00665","399.31940","-0.00030"
"20.10000","0.66774","4012.70874","0.00668","401.27087","-0.00031"
"20.20000","0.67111","4034.59033","0.00671","403.45905","-0.00030"
"20.30000","0.67444","4055.85425","0.00674","405.58542","-0.00030"
"20.40000","0.67772","4076.57666","0.00678","407.65765","-0.00031"
"20.50000","0.68106","4097.93311","0.00681","409.79330","-0.00030"
"20.60000","0.68451","4120.52148","0.00685","412.05215","-0.00031"
"20.70000","0.68797","4142.88623","0.00688","414.28864","-0.00030"
"20.80000","0.69103","4161.30078","0.00691","416.13007","-0.00030"
"20.90000","0.69443","4183.39844","0.00694","418.33984","-0.00031"
"21.00000","0.69773","4203.84668","0.00698","420.38467","-0.00030"
"21.10000","0.70104","4224.83594","0.00701","422.48358","-0.00031"
"21.20000","0.70439","4246.24512","0.00704","424.62451","-0.00030"
"21.30000","0.70779","4267.90527","0.00708","426.79053","-0.00030"
"21.40000","0.71120","4289.76172","0.00711","428.97617","-0.00030"
"21.50000","0.71438","4309.17236","0.00714","430.91724","-0.00030"
"21.60000","0.71776","4330.77197","0.00718","433.07721","-0.00030"
"21.70000","0.72104","4351.13135","0.00721","435.11313","-0.00030"
"21.80000","0.72441","4372.35596","0.00724","437.23560","-0.00031"
"21.90000","0.72774","4393.35986","0.00728","439.33600","-0.00031"
"22.00000","0.73119","4415.27881","0.00731","441.52789","-0.00030"
"22.10000","0.73452","4435.91943","0.00735","443.59195","-0.00031"
"22.20000","0.73764","4454.67383","0.00738","445.46738","-0.00030"
"22.30000","0.74125","4478.20801","0.00741","447.82080","-0.00030"
"22.40000","0.74443","4497.40430","0.00744","449.74042","-0.00031"
"22.50000","0.74776","4518.25928","0.00748","451.82593","-0.00030"
"22.60000","0.75111","4539.25488","0.00751","453.92548","-0.00031"
"22.70000","0.75443","4559.75635","0.00754","455.97565","-0.00030"
"22.80000","0.75771","4579.80322","0.00758","457.98032","-0.00031"
"22.90000","0.76100","4600.09375","0.00761","460.00937","-0.00030"
"23.00000","0.76454","4623.05908","0.00765","462.30591","-0.00030"
"23.10000","0.76780","4642.71143","0.00768","464.27115","-0.00031"
"23.20000","0.77105","4662.36670","0.00771","466.23666","-0.00029"
"23.30000","0.77443","4683.73633","0.00774","468.37363","-0.00031"
"23.40000","0.77776","4704.07959","0.00778","470.40796","-0.00030"
"23.50000","0.78099","4723.60010","0.00781","472.36002","-0.00030"
"23.60000","0.78437","4744.84424","0.00784","474.48444","-0.00031"
"23.70000","0.78787","4766.98633","0.00788","476.69864","-0.00029"
"23.80000","0.79126","4787.93799","0.00791","478.79379","-0.00031"
"23.90000","0.79444","4806.80078","0.00794","480.68008","-0.00030"
"24.00000","0.79774","4826.96338","0.00798","482.69635","-0.00031"
"24.10000","0.80121","4848.63281","0.00801","484.86328","-0.00030"
"24.20000","0.80429","4866.06006","0.00804","486.60602","-0.00030"
"24.30000","0.80776","4888.18213","0.00808","488.81821","-0.00031"
"24.40000","0.81117","4909.13428","0.00811","490.91342","-0.00030"
"24.50000","0.81451","4929.26562","0.00815","492.92657","-0.00031"
"24.60000","0.81763","4947.33154","0.00818","494.73315","-0.00030"
"24.70000","0.82115","4969.71143","0.00821","496.97113","-0.00030"
"24.80000","0.82443","4989.05859","0.00824","498.90585","-0.00031"
"24.90000","0.82768","5008.29395","0.00828","500.82941","-0.00030"
"25.00000","0.83109","5029.43604","0.00831","502.94360","-0.00031"
"25.10000","0.83453","5050.50684","0.00835","505.05069","-0.00030"
"25.20000","0.83784","5069.94189","0.00838","506.99420","-0.00030"
"25.30000","0.84091","5087.36963","0.00841","508.73697","-0.00031"
"25.40000","0.84454","5110.75439","0.00845","511.07544","-0.00030"
"25.50000","0.84778","5129.70508","0.00848","512.97052","-0.00031"
"25.60000","0.85106","5149.09277","0.00851","514.90930","-0.00030"
"25.70000","0.85447","5170.03516","0.00854","517.00354","-0.00031"
"25.80000","0.85772","5188.55615","0.00858","518.85559","-0.00030"
"25.90000","0.86127","5210.90869","0.00861","521.09088","-0.00030"
"26.00000","0.86428","5227.16846","0.00864","522.71686","-0.00031"
"26.10000","0.86791","5250.37891","0.00868","525.03790","-0.00030"
"26.20000","0.87119","5269.44727","0.00871","526.94470","-0.00031"
"26.30000","0.87443","5288.13379","0.00874","528.81335","-0.00030"
"26.40000","0.87773","5307.56396","0.00878","530.75641","-0.00030"
"26.50000","0.88108","5327.15283","0.00881","532.71527","-0.00031"
"26.60000","0.88442","5346.90381","0.00884","534.69037","-0.00030"
"26.70000","0.88763","5365.43359","0.00888","536.54333","-0.00031"
"26.80000","0.89121","5387.61816","0.00891","538.76184","-0.00030"
"26.90000","0.89453","5406.72119","0.00895","540.67212","-0.00030"
"27.00000","0.89769","5424.61523","0.00898","542.46155","-0.00030"
"27.10000","0.90103","5444.32178","0.00901","544.43219","-0.00030"
"27.20000","0.90443","5464.32422","0.00904","546.43243","-0.00031"
"27.30000","0.90773","5483.27783","0.00908","548.32776","-0.00030"
"27.40000","0.91104","5502.62158","0.00911","550.26215","-0.00030"
"27.50000","0.91459","5524.15283","0.00915","552.41528","-0.00030"
"27.60000","0.91788","5542.82520","0.00918","554.28253","-0.00030"
"27.70000","0.92111","5560.92480","0.00921","556.09247","-0.00031"
"27.80000","0.92440","5579.69727","0.00924","557.96973","-0.00030"
"27.90000","0.92786","5600.18848","0.00928","560.01886","-0.00030"
"28.00000","0.93100","5617.25977","0.00931","561.72595","-0.00030"
"28.10000","0.93438","5637.45361","0.00934","563.74536","-0.00030"
"28.20000","0.93781","5657.18164","0.00938","565.71814","-0.00030"
"28.30000","0.94115","5676.40527","0.00941","567.64050","-0.00030"
"28.40000","0.94433","5693.88867","0.00944","569.38885","-0.00031"
"28.50000","0.94774","5713.69678","0.00948","571.36969","-0.00030"
"28.60000","0.95113","5733.42188","0.00951","573.34216","-0.00030"
"28.70000","0.95439","5751.42969","0.00954","575.14294","-0.00030"
"28.80000","0.95776","5770.86572","0.00958","577.08655","-0.00030"
"28.90000","0.96109","5789.47412","0.00961","578.94739","-0.00031"
"29.00000","0.96445","5808.40430","0.00964","580.84045","-0.00030"
"29.10000","0.96768","5826.23535","0.00968","582.62354","-0.00030"
"29.20000","0.97123","5847.37451","0.00971","584.73743","-0.00030"
"29.30000","0.97454","5865.79932","0.00975","586.57996","-0.00030"
"29.40000","0.97771","5882.78418","0.00978","588.27844","-0.00031"
"29.50000","0.98119","5903.06641","0.00981","590.30664","-0.00030"
"29.60000","0.98436","5919.90039","0.00984","591.99005","-0.00030"
"29.70000","0.98778","5939.51074","0.00988","593.95105","-0.00031"
"29.80000","0.99099","5956.79688","0.00991","595.67969","-0.00030"
"29.90000","0.99454","5977.66504","0.00995","597.76648","-0.00031"
"30.00000","0.99782","5995.52148","0.00998","599.55212","-0.00030"
"30.10000","1.00104","6012.75049","0.01001","601.27502","-0.00030"
"30.20000","1.00449","6032.35938","0.01004","603.23596","-0.00031"
"30.30000","1.00771","6049.07861","0.01008","604.90784","-0.00030"
"30.40000","1.01104","6067.53223","0.01011","606.75323","-0.00031"
"30.50000","1.01438","6085.98682","0.01014","608.59869","-0.00030"
"30.60000","1.01788","6105.80762","0.01018","610.58075","-0.00031"
"30.70000","1.02112","6122.76855","0.01021","612.27686","-0.00030"
"30.80000","1.02434","6139.69727","0.01024","613.96973","-0.00030"
"30.90000","1.02779","6159.02783","0.01028","615.90277","-0.00031"
"31.00000","1.03117","6177.61963","0.01031","617.76196","-0.00030"
"31.10000","1.03439","6194.35254","0.01034","619.43524","-0.00031"
"31.20000","1.03773","6212.62549","0.01038","621.26257","-0.00030"
"31.30000","1.04126","6232.57520","0.01041","623.25751","-0.00030"
"31.40000","1.04442","6248.31787","0.01044","624.83179","-0.00031"
"31.50000","1.04772","6266.04053","0.01048","626.60406","-0.00030"
"31.60000","1.05116","6285.02734","0.01051","628.50275","-0.00031"
"31.70000","1.05449","6302.68994","0.01054","630.26898","-0.00029"
"31.80000","1.05771","6319.19434","0.01058","631.91943","-0.00031"
"31.90000","1.06110","6337.70801","0.01061","633.77081","-0.00030"
"32.00000","1.06446","6355.45166","0.01064","635.54517","-0.00031"
"32.10000","1.06772","6372.34668","0.01068","637.23468","-0.00031"
"32.20000","1.07096","6389.06152","0.01071","638.90613","-0.00029"
"32.30000","1.07453","6409.19189","0.01075","640.91919","-0.00031"
"32.40000","1.07782","6426.35596","0.01078","642.63562","-0.00030"
"32.50000","1.08101","6442.34180","0.01081","644.23419","-0.00030"
"32.60000","1.08444","6461.26953","0.01084","646.12695","-0.00030"
"32.70000","1.08771","6477.60352","0.01088","647.76038","-0.00030"
"32.80000","1.09108","6495.52344","0.01091","649.55237","-0.00031"
"32.90000","1.09441","6512.90039","0.01094","651.29004","-0.00030"
"33.00000","1.09793","6532.17822","0.01098","653.21783","-0.00031"
"33.10000","1.10130","6549.90771","0.01101","654.99078","-0.00030"
"33.20000","1.10436","6563.74170","0.01104","656.37415","-0.00030"
"33.30000","1.10780","6582.27734","0.01108","658.22772","-0.00031"
"33.40000","1.11103","6598.12549","0.01111","659.81256","-0.00030"
"33.50000","1.11440","6615.56592","0.01114","661.55658","-0.00031"
"33.60000","1.11766","6632.21484","0.01118","663.22150","-0.00030"
"33.70000","1.12121","6651.48145","0.01121","665.14813","-0.00030"
"33.80000","1.12454","6668.27197","0.01125","666.82721","-0.00030"
"33.90000","1.12762","6682.22705","0.01128","668.22272","-0.00030"
"34.00000","1.13108","6700.51953","0.01131","670.05194","-0.00031"
"34.10000","1.13446","6717.69092","0.01134","671.76910","-0.00030"
"34.20000","1.13771","6733.63721","0.01138","673.36371","-0.00030"
"34.30000","1.14106","6750.65088","0.01141","675.06506","-0.00030"
"34.40000","1.14449","6768.26855","0.01144","676.82684","-0.00030"
"34.50000","1.14783","6784.70410","0.01148","678.47040","-0.00031"
"34.60000","1.15096","6799.22461","0.01151","679.92249","-0.00030"
"34.70000","1.15451","6818.38477","0.01155","681.83850","-0.00030"
"34.80000","1.15792","6835.45312","0.01158","683.54529","-0.00030"
"34.90000","1.16113","6850.45654","0.01161","685.04565","-0.00030"
"35.00000","1.16441","6866.26953","0.01164","686.62695","-0.00031"
"35.10000","1.16779","6883.09229","0.01168","688.30920","-0.00030"
"35.20000","1.17105","6898.44043","0.01171","689.84406","-0.00031"
"35.30000","1.17432","6914.15723","0.01174","691.41571","-0.00030"
"35.40000","1.17785","6932.66748","0.01178","693.26672","-0.00030"
"35.50000","1.18120","6948.89258","0.01181","694.88928","-0.00030"
"35.60000","1.18443","6963.71143","0.01184","696.37115","-0.00030"
"35.70000","1.18778","6979.78809","0.01188","697.97882","-0.00031"
"35.80000","1.19103","6994.76904","0.01191","699.47693","-0.00031"
"35.90000","1.19436","7010.56348","0.01194","701.05634","-0.00030"
"36.00000","1.19768","7026.51221","0.01198","702.65125","-0.00031"
"36.10000","1.20118","7044.18262","0.01201","704.41827","-0.00029"
"36.20000","1.20451","7060.01660","0.01205","706.00165","-0.00030"
"36.30000","1.20768","7074.15283","0.01208","707.41528","-0.00030"
"36.40000","1.21113","7091.34863","0.01211","709.13489","-0.00031"
"36.50000","1.21445","7106.74463","0.01214","710.67444","-0.00031"
"36.60000","1.21775","7121.94873","0.01218","712.19489","-0.00030"
"36.70000","1.22111","7137.94775","0.01221","713.79480","-0.00031"
"36.80000","1.22454","7154.05664","0.01225","715.40564","-0.00030"
"36.90000","1.22785","7169.45215","0.01228","716.94519","-0.00031"
"37.00000","1.23101","7182.74658","0.01231","718.27466","-0.00031"
"37.10000","1.23447","7199.77637","0.01234","719.97766","-0.00030"
"37.20000","1.23775","7214.23096","0.01238","721.42310","-0.00031"
"37.30000","1.24103","7229.14404","0.01241","722.91443","-0.00029"
"37.40000","1.24443","7245.28076","0.01244","724.52808","-0.00031"
"37.50000","1.24783","7261.05029","0.01248","726.10504","-0.00030"
"37.60000","1.25110","7275.49414","0.01251","727.54944","-0.00030"
"37.70000","1.25430","7289.25928","0.01254","728.92590","-0.00031"
"37.80000","1.25784","7306.76855","0.01258","730.67688","-0.00029"
"37.90000","1.26115","7321.24023","0.01261","732.12402","-0.00031"
"38.00000","1.26435","7334.78516","0.01264","733.47852","-0.00030"
"38.10000","1.26782","7351.07080","0.01268","735.10706","-0.00030"
"38.20000","1.27115","7365.60010","0.01271","736.56000","-0.00031"
"38.30000","1.27444","7379.55127","0.01274","737.95514","-0.00030"
"38.40000","1.27770","7393.51904","0.01278","739.35193","-0.00032"
"38.50000","1.28119","7410.05371","0.01281","741.00537","-0.00030"
"38.60000","1.28460","7425.20264","0.01285","742.52026","-0.00031"
"38.70000","1.28771","7437.53467","0.01288","743.75348","-0.00030"
"38.80000","1.29113","7452.73682","0.01291","745.27368","-0.00030"
"38.90000","1.29443","7466.82227","0.01294","746.68225","-0.00031"
"39.00000","1.29769","7480.66553","0.01298","748.06653","-0.00030"
"39.10000","1.30101","7495.02783","0.01301","749.50281","-0.00031"
"39.20000","1.30457","7511.83203","0.01305","751.18323","-0.00030"
"39.30000","1.30787","7525.50293","0.01308","752.55029","-0.00030"
"39.40000","1.31100","7537.61377","0.01311","753.76135","-0.00030"
"39.50000","1.31442","7552.83008","0.01314","755.28302","-0.00029"
"39.60000","1.31771","7566.27393","0.01318","756.62738","-0.00031"
"39.70000","1.32105","7580.42480","0.01321","758.04248","-0.00030"
"39.80000","1.32433","7594.14160","0.01324","759.41418","-0.00030"
"39.90000","1.32795","7611.10205","0.01328","761.11023","-0.00030"
"40.00000","1.33122","7624.59570","0.01331","762.45959","-0.00029"
"40.10000","1.33437","7636.70264","0.01334","763.67029","-0.00031"
"40.20000","1.33785","7652.25977","0.01338","765.22595","-0.00030"
"40.30000","1.34102","7664.36182","0.01341","766.43616","-0.00031"
"40.40000","1.34445","7679.14600","0.01344","767.91461","-0.00030"
"40.50000","1.34774","7692.68701","0.01348","769.26868","-0.00029"
"40.60000","1.35118","7707.30908","0.01351","770.73090","-0.00031"
"40.70000","1.35451","7720.78955","0.01355","772.07898","-0.00030"
"40.80000","1.35763","7731.85547","0.01358","773.18555","-0.00032"
"40.90000","1.36116","7747.55273","0.01361","774.75525","-0.00030"
"41.00000","1.36452","7761.18213","0.01365","776.11823","-0.00029"
"41.10000","1.36770","7772.76465","0.01368","777.27649","-0.00030"
"41.20000","1.37106","7786.54443","0.01371","778.65442","-0.00029"
"41.30000","1.37447","7800.57324","0.01374","780.05731","-0.00031"
"41.40000","1.37770","7812.76807","0.01378","781.27679","-0.00031"
"41.50000","1.38098","7825.36768","0.01381","782.53674","-0.00029"
"41.60000","1.38449","7840.48193","0.01384","784.04822","-0.00031"
"41.70000","1.38795","7854.74023","0.01388","785.47400","-0.00029"
"41.80000","1.39109","7865.73975","0.01391","786.57397","-0.00032"
"41.90000","1.39442","7878.36914","0.01394","787.83691","-0.00030"
"42.00000","1.39782","7891.36133","0.01398","789.13611","-0.00030"
"42.10000","1.40103","7902.44580","0.01401","790.24457","-0.00031"
"42.20000","1.40439","7915.54541","0.01404","791.55457","-0.00028"
"42.30000","1.40789","7929.89795","0.01408","792.98981","-0.00031"
"42.40000","1.41127","7942.56982","0.01411","794.25696","-0.00030"
"42.50000","1.41437","7952.08008","0.01414","795.20801","-0.00031"
"42.60000","1.41778","7965.60107","0.01418","796.56012","-0.00032"
"42.70000","1.42101","7976.47217","0.01421","797.64722","-0.00028"
"42.80000","1.42438","7989.07227","0.01424","798.90723","-0.00032"
"42.90000","1.42774","8001.63232","0.01428","800.16321","-0.00029"
"43.00000","1.43112","8013.97803","0.01431","801.39783","-0.00032"
"43.10000","1.43450","8026.46484","0.01435","802.64648","-0.00032"
"43.20000","1.43766","8036.42139","0.01438","803.64215","-0.00030"
"43.30000","1.44112","8049.93750","0.01441","804.99377","-0.00031"
"43.40000","1.44439","8061.15186","0.01444","806.11517","-0.00028"
"43.50000","1.44777","8073.37598","0.01448","807.33759","-0.00031"
"43.60000","1.45112","8085.44775","0.01451","808.54480","-0.00029"
"43.70000","1.45455","8096.64111","0.01455","809.66412","-0.00031"
"43.80000","1.45783","8107.47363","0.01458","810.74738","-0.00031"
"43.90000","1.46100","8113.63379","0.01461","811.36340","-0.00029"
"44.00000","1.46459","8127.62988","0.01465","812.76300","-0.00032"
"44.10000","1.46777","8137.10693","0.01468","813.71069","-0.00029"
"44.20000","1.47110","8105.36426","0.01471","810.53644","-0.00031"
"44.30000","1.47442","8117.78809","0.01474","811.77881","-0.00031"
"44.40000","1.47775","8129.45361","0.01478","812.94537","-0.00030"
"44.50000","1.48102","8137.24463","0.01481","813.72449","-0.00031"
"44.60000","1.48432","8143.97803","0.01484","814.39783","-0.00029"
"44.70000","1.48792","8156.47607","0.01488","815.64758","-0.00031"
"44.80000","1.49115","8166.48242","0.01491","816.64825","-0.00030"
"44.90000","1.49438","8176.48096","0.01494","817.64807","-0.00030"
"45.00000","1.49782","8189.02686","0.01498","818.90271","-0.00031"
"45.10000","1.50111","8198.77344","0.01501","819.87732","-0.00030"
"45.20000","1.50429","8207.13379","0.01504","820.71338","-0.00031"
"45.30000","1.50772","8219.22363","0.01508","821.92236","-0.00030"
"45.40000","1.51120","8231.15820","0.01511","823.11584","-0.00030"
"45.50000","1.51457","8242.05566","0.01515","824.20557","-0.00031"
"45.60000","1.51777","8251.50586","0.01518","825.15057","-0.00030"
"45.70000","1.52108","8262.26953","0.01521","826.22693","-0.00031"
"45.80000","1.52451","8274.15234","0.01525","827.41522","-0.00030"
"45.90000","1.52763","8281.69922","0.01528","828.16992","-0.00030"
"46.00000","1.53112","8294.13574","0.01531","829.41357","-0.00030"
"46.10000","1.53453","8305.24707","0.01535","830.52472","-0.00030"
"46.20000","1.53785","8312.85449","0.01538","831.28546","-0.00032"
"46.30000","1.54094","8318.36133","0.01541","831.83612","-0.00030"
"46.40000","1.54455","8328.05273","0.01545","832.80530","-0.00031"
"46.50000","1.54773","8333.95215","0.01548","833.39520","-0.00030"
"46.60000","1.55096","8329.59180","0.01551","832.95917","-0.00030"
"46.70000","1.55441","8337.69629","0.01554","833.76965","-0.00031"
"46.80000","1.55783","8347.85938","0.01558","834.78595","-0.00030"
"46.90000","1.56119","8357.63281","0.01561","835.76331","-0.00032"
"47.00000","1.56422","8364.08887","0.01564","836.40887","-0.00030"
"47.10000","1.56795","8378.29590","0.01568","837.82959","-0.00030"
"47.20000","1.57116","8386.14062","0.01571","838.61407","-0.00031"
"47.30000","1.57438","8393.31348","0.01574","839.33136","-0.00030"
"47.40000","1.57789","8404.70410","0.01578","840.47040","-0.00032"
"47.50000","1.58102","8411.30176","0.01581","841.13019","-0.00030"
"47.60000","1.58460","8423.48828","0.01585","842.34882","-0.00030"
"47.70000","1.58755","8428.99707","0.01588","842.89972","-0.00030"
"47.80000","1.59133","8443.48047","0.01591","844.34802","-0.00030"
"47.90000","1.59454","8451.38770","0.01595","845.13879","-0.00031"
"48.00000","1.59773","8459.45996","0.01598","845.94598","-0.00029"
"48.10000","1.60108","8469.33496","0.01601","846.93347","-0.00030"
"48.20000","1.60437","8478.03125","0.01604","847.80310","-0.00030"
"48.30000","1.60776","8487.98535","0.01608","848.79852","-0.00030"
"48.40000","1.61089","8494.95410","0.01611","849.49542","-0.00032"
"48.50000","1.61453","8506.47070","0.01615","850.64709","-0.00030"
"48.60000","1.61788","8515.29102","0.01618","851.52911","-0.00031"
"48.70000","1.62103","8522.43555","0.01621","852.24353","-0.00029"
"48.80000","1.62443","8532.09863","0.01624","853.20984","-0.00030"
"48.90000","1.62780","8540.55176","0.01628","854.05518","-0.00031"
"49.00000","1.63104","8547.96680","0.01631","854.79669","-0.00030"
"49.10000","1.63438","8556.69727","0.01634","855.66974","-0.00031"
"49.20000","1.63794","8567.54980","0.01638","856.75500","-0.00030"
"49.30000","1.64116","8574.70020","0.01641","857.47003","-0.00030"
"49.40000","1.64442","8582.13184","0.01644","858.21320","-0.00031"
"49.50000","1.64778","8590.40137","0.01648","859.04016","-0.00030"
"49.60000","1.65119","8598.07031","0.01651","859.80701","-0.00031"
"49.70000","1.65432","8601.38281","0.01654","860.13831","-0.00029"
"49.80000","1.65775","8608.63672","0.01658","860.86365","-0.00030"
"49.90000","1.66111","8614.00977","0.01661","861.40100","-0.00031"
"50.00000","1.66447","8618.44531","0.01664","861.84454","-0.00030"
"50.10000","1.66765","8620.16797","0.01668","862.01678","-0.00032"
"50.20000","1.67112","8618.36719","0.01671","861.83673","-0.00030"
"50.30000","1.67451","8615.58594","0.01675","861.55859","-0.00030"
"50.37600","1.67691","8477.37402","0.01677","847.73743","-0.00032"
"50.38100","1.67708","8340.14648","0.01677","834.01465","-0.00032"
"50.38600","1.67726","8186.42773","0.01677","818.64276","-0.00027"
"50.39100","1.67745","8033.52002","0.01677","803.35199","-0.00024"
"50.39600","1.67766","7892.57227","0.01678","789.25720","-0.00027"
"50.40200","1.67791","7747.77100","0.01678","774.77710","-0.00037"
"50.40900","1.67822","7617.17627","0.01678","761.71765","-0.00042"
"50.42000","1.67869","7489.84131","0.01679","748.98413","-0.00039"
"50.52000","1.68180","7422.29199","0.01682","742.22919","-0.00040"
"50.62000","1.68505","7363.61133","0.01685","736.36115","-0.00032"
"50.70300","1.68788","7238.33984","0.01688","723.83398","-0.00020"
"50.80300","1.69115","7188.59375","0.01691","718.85938","-0.00029"
"50.90300","1.69473","7083.65674","0.01695","708.36566","-0.00031"
"51.00300","1.69800","7047.88037","0.01698","704.78802","-0.00040"
"51.10300","1.70115","7024.02295","0.01701","702.40228","-0.00031"
"51.17600","1.70373","6898.81299","0.01704","689.88129","-0.00024"
"51.27600","1.70700","6870.68262","0.01707","687.06824","-0.00031"
"51.37600","1.71038","6871.13232","0.01710","687.11322","-0.00033"
"51.47600","1.71352","6846.97461","0.01714","684.69745","-0.00032"
"51.57400","1.71700","6721.13965","0.01717","672.11395","-0.00030"
"51.60100","1.71796","6595.84473","0.01718","659.58447","-0.00032"
"51.68600","1.72076","6470.70312","0.01721","647.07031","-0.00027"
"51.78600","1.72396","6454.70020","0.01724","645.47003","-0.00029"
"51.88600","1.72736","6446.66016","0.01727","644.66602","-0.00030"
"51.98600","1.73057","6435.34375","0.01731","643.53436","-0.00033"
"52.08600","1.73390","6432.09912","0.01734","643.20990","-0.00032"
"52.18600","1.73721","6432.98047","0.01737","643.29803","-0.00029"
"52.28600","1.74078","6430.86230","0.01741","643.08624","-0.00028"
"52.38600","1.74402","6419.61377","0.01744","641.96136","-0.00029"
"52.48600","1.74721","6421.36279","0.01747","642.13629","-0.00031"
"52.58600","1.75064","6429.56494","0.01751","642.95648","-0.00032"
"52.68600","1.75400","6439.80225","0.01754","643.98022","-0.00031"
"52.78600","1.75724","6450.34375","0.01757","645.03436","-0.00029"
"52.88600","1.76060","6462.43604","0.01761","646.24359","-0.00029"
"52.98600","1.76416","6475.76807","0.01764","647.57678","-0.00030"
"53.08600","1.76738","6478.07031","0.01767","647.80701","-0.00032"
"53.18600","1.77060","6419.27930","0.01771","641.92792","-0.00031"
"53.28600","1.77400","6367.37939","0.01774","636.73792","-0.00031"
"53.36200","1.77652","6237.47461","0.01777","623.74744","-0.00031"
"53.37000","1.77678","6107.04443","0.01777","610.70447","-0.00027"
"53.37800","1.77707","5980.27490","0.01777","598.02747","-0.00027"
"53.38800","1.77747","5855.17285","0.01777","585.51727","-0.00033"
"53.40900","1.77834","5728.61963","0.01778","572.86194","-0.00036"
"53.50900","1.78133","5706.00684","0.01781","570.60071","-0.00031"
"53.60900","1.78477","5699.98096","0.01785","569.99811","-0.00028"
"53.70900","1.78808","5700.86182","0.01788","570.08618","-0.00031"
"53.80900","1.79131","5706.43945","0.01791","570.64392","-0.00028"
"53.90900","1.79464","5715.54688","0.01795","571.55469","-0.00031"
"54.00900","1.79819","5728.46875","0.01798","572.84686","-0.00031"
"54.10900","1.80151","5740.06592","0.01802","574.00659","-0.00032"
"54.20900","1.80461","5750.75879","0.01805","575.07587","-0.00029"
"54.30900","1.80812","5765.85889","0.01808","576.58588","-0.00029"
"54.40900","1.81134","5778.69043","0.01811","577.86902","-0.00030"
"54.50900","1.81467","5793.42139","0.01815","579.34216","-0.00029"
"54.60900","1.81808","5809.18701","0.01818","580.91870","-0.00032"
"54.70900","1.82150","5825.02686","0.01821","582.50269","-0.00031"
"54.80900","1.82495","5842.04199","0.01825","584.20422","-0.00029"
"54.90900","1.82793","5854.37842","0.01828","585.43787","-0.00030"
"55.00900","1.83150","5872.42969","0.01831","587.24298","-0.00029"
"55.10900","1.83469","5886.84766","0.01835","588.68475","-0.00029"
"55.20900","1.83804","5902.84180","0.01838","590.28418","-0.00032"
"55.30900","1.84133","5918.37744","0.01841","591.83777","-0.00031"
"55.40900","1.84482","5935.74414","0.01845","593.57440","-0.00030"
"55.50900","1.84814","5951.37793","0.01848","595.13782","-0.00031"
"55.60900","1.85125","5965.10498","0.01851","596.51050","-0.00029"
"55.70900","1.85478","5982.94775","0.01855","598.29480","-0.00030"
"55.80900","1.85814","5998.84033","0.01858","599.88403","-0.00030"
"55.90900","1.86137","6014.11328","0.01861","601.41132","-0.00031"
"56.00900","1.86469","6030.01025","0.01865","603.00104","-0.00031"
"56.10900","1.86809","6046.58740","0.01868","604.65875","-0.00030"
"56.20900","1.87140","6062.06641","0.01871","606.20667","-0.00031"
"56.30900","1.87464","6076.91504","0.01875","607.69153","-0.00028"
"56.40900","1.87821","6094.83594","0.01878","609.48358","-0.00030"
"56.50900","1.88156","6110.68408","0.01882","611.06842","-0.00029"
"56.60900","1.88476","6124.93359","0.01885","612.49335","-0.00030"
"56.70900","1.88804","6140.01123","0.01888","614.00110","-0.00031"
"56.80900","1.89145","6156.15479","0.01891","615.61548","-0.00029"
"56.90900","1.89465","6170.03174","0.01895","617.00317","-0.00031"
"57.00900","1.89799","6185.54785","0.01898","618.55481","-0.00029"
"57.10900","1.90147","6202.20508","0.01901","620.22052","-0.00030"
"57.20900","1.90486","6218.00879","0.01905","621.80090","-0.00030"
"57.30900","1.90803","6231.44336","0.01908","623.14435","-0.00030"
"57.40900","1.91139","6246.85303","0.01911","624.68530","-0.00031"
"57.50900","1.91469","6261.54150","0.01915","626.15417","-0.00029"
"57.60900","1.91799","6276.10107","0.01918","627.61011","-0.00031"
"57.70900","1.92134","6291.51367","0.01921","629.15137","-0.00029"
"57.80900","1.92479","6307.66602","0.01925","630.76660","-0.00030"
"57.90900","1.92813","6322.75488","0.01928","632.27551","-0.00030"
"58.00900","1.93129","6335.96240","0.01931","633.59625","-0.00030"
"58.10900","1.93479","6352.30713","0.01935","635.23071","-0.00031"
"58.20900","1.93811","6366.80859","0.01938","636.68085","-0.00030"
"58.30900","1.94139","6380.91357","0.01941","638.09137","-0.00030"
"58.40900","1.94481","6396.35986","0.01945","639.63599","-0.00030"
"58.50900","1.94811","6410.10547","0.01948","641.01056","-0.00030"
"58.60900","1.95147","6424.98047","0.01951","642.49805","-0.00031"
"58.70900","1.95463","6437.76709","0.01955","643.77673","-0.00030"
"58.80900","1.95812","6453.64160","0.01958","645.36414","-0.00030"
"58.90900","1.96141","6467.52100","0.01961","646.75208","-0.00030"
"59.00900","1.96471","6481.30469","0.01965","648.13049","-0.00030"
"59.10900","1.96810","6495.94971","0.01968","649.59497","-0.00030"
"59.20900","1.97138","6509.25098","0.01971","650.92511","-0.00030"
"59.30900","1.97468","6522.77002","0.01975","652.27698","-0.00031"
"59.40900","1.97793","6535.84277","0.01978","653.58429","-0.00030"
"59.50900","1.98150","6552.06689","0.01981","655.20667","-0.00030"
"59.60900","1.98480","6565.32861","0.01985","656.53284","-0.00030"
"59.70900","1.98798","6577.49463","0.01988","657.74945","-0.00029"
"59.80900","1.99143","6591.96240","0.01991","659.19623","-0.00031"
"59.90900","1.99477","6604.98438","0.01995","660.49841","-0.00030"
"60.00900","1.99802","6617.22559","0.01998","661.72253","-0.00030"
"60.10900","2.00135","6630.36084","0.02001","663.03607","-0.00031"
"60.20900","2.00489","6645.30566","0.02005","664.53058","-0.00029"
"60.30900","2.00819","6657.76074","0.02008","665.77606","-0.00030"
"60.40900","2.01135","6668.99219","0.02011","666.89923","-0.00030"
"60.50900","2.01473","6682.10840","0.02015","668.21082","-0.00030"
"60.60900","2.01804","6694.35498","0.02018","669.43549","-0.00030"
"60.70900","2.02130","6706.15820","0.02021","670.61584","-0.00030"
"60.80900","2.02466","6718.78076","0.02025","671.87805","-0.00031"
"60.90900","2.02821","6731.82471","0.02028","673.18250","-0.00029"
"61.00900","2.03147","6742.25635","0.02031","674.22565","-0.00031"
"61.10900","2.03463","6752.29736","0.02035","675.22974","-0.00030"
"61.20900","2.03812","6759.27393","0.02038","675.92737","-0.00030"
"61.30900","2.04135","6767.65381","0.02041","676.76538","-0.00031"
"61.40900","2.04467","6779.07520","0.02045","677.90753","-0.00030"
"61.50900","2.04800","6791.06055","0.02048","679.10608","-0.00031"
"61.60900","2.05147","6803.69873","0.02051","680.36987","-0.00030"
"61.70900","2.05481","6815.62891","0.02055","681.56287","-0.00030"
"61.80900","2.05799","6826.22803","0.02058","682.62280","-0.00030"
"61.90900","2.06155","6839.95117","0.02062","683.99512","-0.00030"
"62.00900","2.06480","6836.75195","0.02065","683.67517","-0.00031"
"62.10900","2.06806","6845.72607","0.02068","684.57263","-0.00030"
"62.20900","2.07142","6856.74561","0.02071","685.67456","-0.00030"
"62.30900","2.07471","6866.80078","0.02075","686.68005","-0.00030"
"62.40900","2.07808","6877.30664","0.02078","687.73065","-0.00030"
"62.50900","2.08126","6886.10205","0.02081","688.61023","-0.00031"
"62.60900","2.08484","6899.02734","0.02085","689.90271","-0.00030"
"62.70900","2.08820","6909.74512","0.02088","690.97449","-0.00030"
"62.80900","2.09133","6918.54492","0.02091","691.85449","-0.00030"
"62.90900","2.09468","6930.05420","0.02095","693.00543","-0.00030"
"63.00900","2.09812","6941.81787","0.02098","694.18176","-0.00031"
"63.10900","2.10132","6951.50098","0.02101","695.15009","-0.00029"
"63.20900","2.10463","6962.48047","0.02105","696.24805","-0.00031"
"63.30900","2.10814","6975.11963","0.02108","697.51196","-0.00030"
"63.40900","2.11157","6986.48779","0.02112","698.64880","-0.00030"
"63.50900","2.11470","6995.23486","0.02115","699.52350","-0.00031"
"63.60900","2.11810","7006.25488","0.02118","700.62549","-0.00029"
"63.70900","2.12145","7016.64893","0.02121","701.66492","-0.00031"
"63.80900","2.12470","7026.30273","0.02125","702.63025","-0.00030"
"63.90900","2.12805","7036.80762","0.02128","703.68079","-0.00030"
"64.00900","2.13149","7047.79980","0.02131","704.77997","-0.00030"
"64.10900","2.13484","7057.51758","0.02135","705.75177","-0.00030"
"64.20900","2.13795","7065.75146","0.02138","706.57513","-0.00031"
"64.30900","2.14142","7076.37500","0.02141","707.63751","-0.00030"
"64.40900","2.14471","7084.71240","0.02145","708.47125","-0.00030"
"64.50900","2.14801","7093.71875","0.02148","709.37189","-0.00030"
"64.60900","2.15140","7103.85303","0.02151","710.38531","-0.00030"
"64.70900","2.15471","7112.92236","0.02155","711.29224","-0.00031"
"64.80900","2.15810","7122.23877","0.02158","712.22388","-0.00030"
"64.90900","2.16132","7130.16162","0.02161","713.01617","-0.00031"
"65.00900","2.16480","7131.53564","0.02165","713.15356","-0.00030"
"65.10900","2.16812","7126.32910","0.02168","712.63293","-0.00030"
"65.20900","2.17137","7132.77148","0.02171","713.27716","-0.00030"
"65.30900","2.17475","7140.66162","0.02175","714.06616","-0.00030"
"65.40900","2.17811","7146.44434","0.02178","714.64441","-0.00031"
"65.50900","2.18141","7152.65430","0.02181","715.26544","-0.00030"
"65.56600","2.18323","6961.20947","0.02183","696.12097","-0.00030"
"65.56800","2.18329","6742.34570","0.02183","674.23456","-0.00030"
"65.56900","2.18332","6607.42383","0.02183","660.74237","-0.00030"
"65.57000","2.18335","6458.47021","0.02183","645.84705","-0.00030"
"65.57100","2.18339","6297.37695","0.02183","629.73767","-0.00030"
"65.57200","2.18342","6125.84473","0.02183","612.58447","-0.00029"
"65.57300","2.18345","5945.39648","0.02183","594.53967","-0.00029"
"65.57400","2.18349","5757.42334","0.02183","575.74231","-0.00029"
"65.57500","2.18353","5563.26953","0.02184","556.32697","-0.00028"
"65.57600","2.18357","5364.17139","0.02184","536.41711","-0.00028"
"65.57700","2.18361","5161.29150","0.02184","516.12915","-0.00027"
"65.57800","2.18365","4955.71484","0.02184","495.57147","-0.00027"
"65.57900","2.18370","4748.43701","0.02184","474.84369","-0.00028"
"65.58000","2.18375","4540.39014","0.02184","454.03900","-0.00029"
"65.58100","2.18380","4332.42578","0.02184","433.24258","-0.00030"
"65.58200","2.18385","4125.32861","0.02184","412.53287","-0.00032"