File: Tension/Section_1_Group_4/6_days/Sample_8_6_days_tension.is_tens_RawData/Specimen_RawData_1.csv
Time,Extension,Load,Tensile strain (Extension),Axial Video,Tensile stress,Transverse Video
(s),(mm),(N),(mm/mm),(mm/mm),(MPa),(mm/mm)
"0.00000","0.00000","-0.07999","0.00000","0.00002","-0.00800","0.00000"
"0.20000","0.00229","6.76046","0.00002","0.00002","0.67605","0.00005"
"0.40000","0.01072","38.16722","0.00011","0.00010","3.81672","0.00007"
"0.60000","0.01753","67.13298","0.00018","0.00015","6.71330","0.00011"
"0.80000","0.02433","96.80522","0.00024","0.00018","9.68052","0.00015"
"1.00000","0.03088","125.52158","0.00031","0.00024","12.55216","0.00015"
"1.20000","0.03758","155.14893","0.00038","0.00029","15.51489","0.00015"
"1.40000","0.04413","184.23962","0.00044","0.00033","18.42396","0.00010"
"1.60000","0.05093","214.12994","0.00051","0.00037","21.41299","0.00014"
"1.80000","0.05745","242.72591","0.00057","0.00040","24.27259","0.00010"
"2.00000","0.06417","271.86707","0.00064","0.00044","27.18671","0.00009"
"2.20000","0.07087","300.55463","0.00071","0.00047","30.05546","0.00005"
"2.40000","0.07746","328.44916","0.00077","0.00052","32.84492","0.00003"
"2.60000","0.08428","357.38022","0.00084","0.00056","35.73802","0.00005"
"2.80000","0.09091","384.96274","0.00091","0.00057","38.49627","0.00000"
"3.00000","0.09756","412.27945","0.00098","0.00062","41.22794","0.00005"
"3.20000","0.10426","439.60800","0.00104","0.00065","43.96080","0.00003"
"3.40000","0.11084","465.91702","0.00111","0.00069","46.59170","0.00005"
"3.60000","0.11745","492.04626","0.00117","0.00073","49.20463","0.00000"
"3.80000","0.12411","518.44220","0.00124","0.00076","51.84422","0.00000"
"4.00000","0.13090","544.87732","0.00131","0.00080","54.48773","0.00004"
"4.20000","0.13752","570.31128","0.00138","0.00084","57.03113","0.00000"
"4.40000","0.14417","595.25562","0.00144","0.00087","59.52556","0.00003"
"4.60000","0.15105","621.31067","0.00151","0.00090","62.13107","0.00000"
"4.80000","0.15751","644.80359","0.00158","0.00094","64.48036","0.00000"
"5.00000","0.16417","668.92072","0.00164","0.00096","66.89207","0.00000"
"5.20000","0.17080","692.70624","0.00171","0.00100","69.27062","0.00000"
"5.40000","0.17751","716.57544","0.00178","0.00104","71.65755","0.00001"
"5.60000","0.18424","740.31543","0.00184","0.00107","74.03154","0.00001"
"5.80000","0.19079","762.64996","0.00191","0.00109","76.26500","0.00000"
"6.00000","0.19756","785.69250","0.00198","0.00112","78.56925","0.00000"
"6.20000","0.20415","807.49646","0.00204","0.00115","80.74965","0.00000"
"6.40000","0.21098","830.17621","0.00211","0.00118","83.01762","0.00000"
"6.60000","0.21752","851.23230","0.00218","0.00121","85.12323","0.00000"
"6.80000","0.22415","872.41736","0.00224","0.00125","87.24174","0.00000"
"7.00000","0.23095","894.27466","0.00231","0.00128","89.42747","0.00000"
"7.20000","0.23746","914.01038","0.00237","0.00133","91.40104","0.00000"
"7.40000","0.24416","934.42072","0.00244","0.00136","93.44207","0.00000"
"7.60000","0.25078","953.99097","0.00251","0.00139","95.39909","0.00000"
"7.80000","0.25763","974.38318","0.00258","0.00140","97.43832","0.00000"
"8.00000","0.26422","993.56018","0.00264","0.00144","99.35602","0.00000"
"8.20000","0.27088","1012.59369","0.00271","0.00148","101.25937","0.00000"
"8.40000","0.27760","1031.90820","0.00278","0.00151","103.19082","0.00000"
"8.60000","0.28412","1049.93408","0.00284","0.00153","104.99341","0.00000"
"8.80000","0.29092","1069.03894","0.00291","0.00156","106.90389","0.00005"
"9.00000","0.29745","1086.77576","0.00297","0.00158","108.67757","0.00005"
"9.20000","0.30417","1105.24390","0.00304","0.00161","110.52439","0.00005"
"9.40000","0.31093","1123.66211","0.00311","0.00162","112.36621","0.00005"
"9.60000","0.31753","1140.91956","0.00318","0.00164","114.09196","0.00005"
"9.80000","0.32417","1157.99463","0.00324","0.00167","115.79946","0.00010"
"10.00000","0.33085","1175.15564","0.00331","0.00169","117.51556","0.00005"
"10.20000","0.33766","1192.74683","0.00338","0.00172","119.27468","0.00005"
"10.40000","0.34414","1208.63611","0.00344","0.00174","120.86361","0.00005"
"10.60000","0.35077","1225.18750","0.00351","0.00177","122.51875","0.00010"
"10.80000","0.35761","1242.64136","0.00358","0.00179","124.26414","0.00008"
"11.00000","0.36413","1258.24377","0.00364","0.00181","125.82438","0.00005"
"11.20000","0.37088","1274.75488","0.00371","0.00184","127.47549","0.00000"
"11.40000","0.37753","1290.77100","0.00378","0.00186","129.07710","0.00000"
"11.60000","0.38424","1306.54260","0.00384","0.00189","130.65427","0.00000"
"11.80000","0.39089","1322.19897","0.00391","0.00191","132.21989","0.00000"
"12.00000","0.39747","1337.21802","0.00397","0.00193","133.72180","0.00000"
"12.20000","0.40417","1352.96716","0.00404","0.00196","135.29672","0.00000"
"12.40000","0.41075","1368.01257","0.00411","0.00198","136.80125","0.00000"
"12.60000","0.41760","1384.14990","0.00418","0.00199","138.41499","0.00000"
"12.80000","0.42418","1398.57800","0.00424","0.00201","139.85780","0.00000"
"13.00000","0.43080","1413.32080","0.00431","0.00202","141.33208","0.00000"
"13.20000","0.43770","1429.65027","0.00438","0.00205","142.96503","0.00000"
"13.40000","0.44413","1443.27637","0.00444","0.00207","144.32764","0.00000"
"13.60000","0.45082","1458.16724","0.00451","0.00208","145.81673","0.00000"
"13.80000","0.45747","1472.90051","0.00457","0.00210","147.29005","-0.00005"
"14.00000","0.46424","1488.08423","0.00464","0.00212","148.80843","-0.00006"
"14.20000","0.47084","1502.72583","0.00471","0.00214","150.27258","-0.00005"
"14.40000","0.47751","1517.60938","0.00478","0.00216","151.76094","-0.00005"
"14.60000","0.48426","1532.81348","0.00484","0.00218","153.28134","-0.00006"
"14.80000","0.49075","1546.71399","0.00491","0.00220","154.67140","-0.00009"
"15.00000","0.49765","1562.57935","0.00498","0.00222","156.25793","-0.00008"
"15.20000","0.50417","1576.11206","0.00504","0.00224","157.61121","-0.00005"
"15.40000","0.51085","1590.08594","0.00511","0.00225","159.00859","-0.00010"
"15.60000","0.51757","1604.54663","0.00518","0.00228","160.45467","-0.00010"
"15.80000","0.52415","1617.95117","0.00524","0.00229","161.79512","-0.00010"
"16.00000","0.53077","1631.81335","0.00531","0.00232","163.18134","-0.00010"
"16.20000","0.53747","1646.04224","0.00537","0.00234","164.60422","-0.00010"
"16.40000","0.54431","1660.61841","0.00544","0.00236","166.06184","-0.00015"
"16.60000","0.55086","1673.90198","0.00551","0.00238","167.39020","-0.00015"
"16.80000","0.55752","1687.38855","0.00558","0.00240","168.73886","-0.00019"
"17.00000","0.56428","1701.73230","0.00564","0.00243","170.17323","-0.00015"
"17.20000","0.57080","1714.50378","0.00571","0.00244","171.45038","-0.00015"
"17.40000","0.57752","1727.97522","0.00578","0.00245","172.79752","-0.00015"
"17.60000","0.58416","1741.18994","0.00584","0.00247","174.11899","-0.00016"
"17.80000","0.59082","1754.33752","0.00591","0.00249","175.43375","-0.00010"
"18.00000","0.59761","1768.17493","0.00598","0.00250","176.81749","-0.00015"
"18.20000","0.60416","1780.71802","0.00604","0.00251","178.07181","-0.00015"
"18.40000","0.61089","1794.14771","0.00611","0.00253","179.41476","-0.00015"
"18.60000","0.61743","1806.41650","0.00617","0.00254","180.64165","-0.00015"
"18.80000","0.62431","1820.10889","0.00624","0.00255","182.01089","-0.00015"
"19.00000","0.63085","1831.81616","0.00631","0.00257","183.18161","-0.00015"
"19.20000","0.63744","1843.11438","0.00637","0.00258","184.31143","-0.00015"
"19.40000","0.64426","1854.37561","0.00644","0.00260","185.43756","-0.00015"
"19.60000","0.65075","1864.11829","0.00651","0.00262","186.41183","-0.00012"
"19.80000","0.65750","1875.28992","0.00658","0.00264","187.52899","-0.00010"
"20.00000","0.66416","1886.38696","0.00664","0.00265","188.63870","-0.00012"
"20.20000","0.67092","1897.56079","0.00671","0.00266","189.75607","-0.00010"
"20.40000","0.67758","1908.29651","0.00678","0.00267","190.82965","-0.00010"
"20.60000","0.68415","1918.07520","0.00684","0.00269","191.80753","-0.00014"
"20.80000","0.69089","1928.94641","0.00691","0.00270","192.89464","-0.00017"
"21.00000","0.69738","1938.32922","0.00697","0.00271","193.83292","-0.00015"
"21.20000","0.70423","1949.65137","0.00704","0.00273","194.96513","-0.00011"
"21.40000","0.71079","1959.18140","0.00711","0.00275","195.91814","-0.00010"
"21.60000","0.71756","1969.47888","0.00718","0.00276","196.94789","-0.00015"
"21.80000","0.72425","1979.31116","0.00724","0.00277","197.93112","-0.00019"
"22.00000","0.73082","1987.94885","0.00731","0.00278","198.79489","-0.00015"
"22.20000","0.73753","1997.41089","0.00738","0.00279","199.74109","-0.00019"
"22.40000","0.74411","2005.96936","0.00744","0.00280","200.59694","-0.00015"
"22.60000","0.75096","2015.40588","0.00751","0.00282","201.54059","-0.00015"
"22.80000","0.75746","2023.13098","0.00757","0.00282","202.31310","-0.00015"
"23.00000","0.76413","2031.40210","0.00764","0.00283","203.14021","-0.00015"
"23.20000","0.77088","2040.05164","0.00771","0.00284","204.00516","-0.00015"
"23.40000","0.77747","2047.76453","0.00777","0.00286","204.77646","-0.00015"
"23.60000","0.78419","2056.20874","0.00784","0.00287","205.62088","-0.00015"
"23.80000","0.79083","2064.30542","0.00791","0.00288","206.43054","-0.00015"
"24.00000","0.79751","2072.08643","0.00798","0.00289","207.20865","-0.00015"
"24.20000","0.80424","2080.45239","0.00804","0.00289","208.04524","-0.00010"
"24.40000","0.81086","2087.72949","0.00811","0.00291","208.77295","-0.00014"
"24.60000","0.81749","2095.19043","0.00817","0.00292","209.51904","-0.00015"
"24.80000","0.82410","2102.59448","0.00824","0.00292","210.25945","-0.00015"
"25.00000","0.83091","2111.20410","0.00831","0.00293","211.12041","-0.00015"
"25.20000","0.83757","2119.17627","0.00838","0.00293","211.91763","-0.00014"
"25.40000","0.84408","2126.12744","0.00844","0.00294","212.61275","-0.00010"
"25.60000","0.85095","2134.95166","0.00851","0.00296","213.49516","-0.00010"
"25.80000","0.85745","2141.73242","0.00857","0.00297","214.17325","-0.00012"
"26.00000","0.86423","2149.57959","0.00864","0.00297","214.95796","-0.00010"
"26.20000","0.87085","2156.69043","0.00871","0.00297","215.66904","-0.00010"
"26.40000","0.87755","2163.81006","0.00878","0.00298","216.38101","-0.00008"
"26.60000","0.88420","2171.02124","0.00884","0.00301","217.10213","-0.00010"
"26.80000","0.89079","2177.01294","0.00891","0.00303","217.70129","-0.00010"
"27.00000","0.89759","2184.38477","0.00898","0.00302","218.43848","-0.00015"
"27.20000","0.90405","2189.62183","0.00904","0.00303","218.96219","-0.00015"
"27.40000","0.91093","2197.09399","0.00911","0.00304","219.70940","-0.00015"
"27.60000","0.91748","2202.67407","0.00917","0.00304","220.26741","-0.00015"
"27.80000","0.92417","2208.83472","0.00924","0.00305","220.88347","-0.00010"
"28.00000","0.93102","2216.00146","0.00931","0.00305","221.60014","-0.00015"
"28.20000","0.93745","2220.60156","0.00937","0.00306","222.06015","-0.00010"
"28.40000","0.94413","2226.80811","0.00944","0.00307","222.68082","-0.00013"
"28.60000","0.95077","2232.71216","0.00951","0.00307","223.27121","-0.00015"
"28.80000","0.95767","2239.68896","0.00958","0.00309","223.96890","-0.00015"
"29.00000","0.96413","2244.50708","0.00964","0.00310","224.45071","-0.00014"
"29.20000","0.97079","2250.08887","0.00971","0.00310","225.00888","-0.00010"
"29.40000","0.97758","2256.27881","0.00978","0.00311","225.62788","-0.00010"
"29.60000","0.98407","2260.68726","0.00984","0.00312","226.06873","-0.00006"
"29.80000","0.99095","2267.13403","0.00991","0.00313","226.71341","-0.00005"
"30.00000","0.99749","2271.73535","0.00997","0.00314","227.17354","-0.00005"
"30.20000","1.00419","2276.82666","0.01004","0.00314","227.68266","-0.00005"
"30.40000","1.01090","2282.06836","0.01011","0.00314","228.20683","-0.00005"
"30.60000","1.01752","2286.80737","0.01018","0.00314","228.68074","-0.00005"
"30.80000","1.02413","2291.64722","0.01024","0.00315","229.16472","-0.00005"
"31.00000","1.03075","2296.49707","0.01031","0.00316","229.64970","-0.00005"
"31.20000","1.03759","2302.29077","0.01038","0.00318","230.22908","-0.00005"
"31.40000","1.04421","2306.68286","0.01044","0.00317","230.66829","0.00000"
"31.60000","1.05084","2311.15308","0.01051","0.00317","231.11531","0.00000"
"31.80000","1.05761","2316.19116","0.01058","0.00318","231.61911","-0.00005"
"32.00000","1.06416","2320.37573","0.01064","0.00319","232.03757","-0.00005"
"32.20000","1.07081","2325.30518","0.01071","0.00319","232.53052","-0.00010"
"32.40000","1.07754","2330.54541","0.01078","0.00319","233.05453","-0.00007"
"32.60000","1.08418","2334.82080","0.01084","0.00321","233.48209","-0.00008"
"32.80000","1.09088","2339.93335","0.01091","0.00320","233.99333","-0.00008"
"33.00000","1.09745","2343.90991","0.01097","0.00321","234.39099","-0.00005"
"33.20000","1.10423","2349.05176","0.01104","0.00322","234.90518","-0.00010"
"33.40000","1.11079","2352.90381","0.01111","0.00323","235.29037","-0.00010"
"33.60000","1.11764","2358.57666","0.01118","0.00324","235.85767","-0.00010"
"33.80000","1.12421","2362.65186","0.01124","0.00324","236.26518","-0.00008"
"34.00000","1.13080","2366.78003","0.01131","0.00325","236.67801","-0.00010"
"34.20000","1.13769","2372.62622","0.01138","0.00325","237.26262","-0.00011"
"34.40000","1.14411","2375.78052","0.01144","0.00325","237.57805","-0.00014"
"34.60000","1.15080","2379.90503","0.01151","0.00325","237.99051","-0.00015"
"34.80000","1.15738","2383.22241","0.01157","0.00326","238.32224","-0.00010"
"35.00000","1.16430","2387.59741","0.01164","0.00326","238.75974","-0.00005"
"35.20000","1.17091","2389.49414","0.01171","0.00326","238.94942","-0.00010"
"35.40000","1.17758","2391.04321","0.01178","0.00328","239.10432","-0.00010"
"35.60000","1.18431","2393.58594","0.01184","0.00328","239.35860","-0.00013"
"35.80000","1.19076","2395.20215","0.01191","0.00328","239.52022","-0.00013"
"36.00000","1.19759","2399.33252","0.01198","0.00327","239.93326","-0.00010"
"36.20000","1.20410","2402.21924","0.01204","0.00327","240.22192","-0.00010"
"36.40000","1.21084","2405.90381","0.01211","0.00328","240.59038","-0.00014"
"36.60000","1.21752","2410.13062","0.01218","0.00329","241.01306","-0.00013"
"36.80000","1.22419","2414.20874","0.01224","0.00329","241.42087","-0.00012"
"37.00000","1.23091","2418.93701","0.01231","0.00329","241.89371","-0.00011"
"37.20000","1.23748","2422.57056","0.01237","0.00329","242.25705","-0.00020"
"37.40000","1.24437","2427.92651","0.01244","0.00330","242.79265","-0.00015"
"37.60000","1.25082","2431.19141","0.01251","0.00331","243.11914","-0.00010"
"37.80000","1.25749","2435.33447","0.01257","0.00331","243.53345","-0.00010"
"38.00000","1.26422","2439.78906","0.01264","0.00332","243.97891","-0.00013"
"38.20000","1.27079","2443.23608","0.01271","0.00332","244.32361","-0.00015"
"38.40000","1.27751","2447.34253","0.01278","0.00333","244.73425","-0.00020"
"38.60000","1.28417","2450.98462","0.01284","0.00333","245.09846","-0.00020"
"38.80000","1.29092","2454.66577","0.01291","0.00334","245.46658","-0.00025"
"39.00000","1.29760","2458.72803","0.01298","0.00334","245.87280","-0.00025"
"39.20000","1.30423","2462.01709","0.01304","0.00334","246.20171","-0.00025"
"39.40000","1.31090","2465.86987","0.01311","0.00335","246.58699","-0.00025"
"39.60000","1.31745","2469.46826","0.01317","0.00335","246.94682","-0.00024"
"39.80000","1.32421","2473.68213","0.01324","0.00336","247.36821","-0.00025"
"40.00000","1.33084","2477.44409","0.01331","0.00338","247.74442","-0.00024"
"40.20000","1.33741","2480.68848","0.01337","0.00339","248.06885","-0.00030"
"40.40000","1.34428","2485.86450","0.01344","0.00340","248.58646","-0.00030"
"40.60000","1.35087","2489.13159","0.01351","0.00340","248.91316","-0.00029"
"40.80000","1.35766","2493.49072","0.01358","0.00340","249.34908","-0.00025"
"41.00000","1.36421","2496.49146","0.01364","0.00341","249.64914","-0.00027"
"41.20000","1.37092","2499.70752","0.01371","0.00342","249.97075","-0.00029"
"41.40000","1.37755","2502.01367","0.01378","0.00342","250.20137","-0.00020"
"41.60000","1.38411","2503.76880","0.01384","0.00342","250.37688","-0.00030"
"41.80000","1.39092","2506.42041","0.01391","0.00342","250.64204","-0.00025"
"42.00000","1.39736","2507.53174","0.01397","0.00343","250.75317","-0.00025"
"42.20000","1.40423","2506.74927","0.01404","0.00344","250.67493","-0.00025"
"42.40000","1.41090","2507.65356","0.01411","0.00343","250.76535","-0.00026"
"42.60000","1.41767","2509.27441","0.01418","0.00343","250.92744","-0.00025"
"42.80000","1.42432","2511.00610","0.01424","0.00343","251.10062","-0.00025"
"43.00000","1.43082","2512.27295","0.01431","0.00343","251.22729","-0.00025"
"43.20000","1.43750","2514.95923","0.01438","0.00344","251.49593","-0.00025"
"43.40000","1.44406","2516.29028","0.01444","0.00345","251.62903","-0.00030"
"43.60000","1.45097","2519.32593","0.01451","0.00345","251.93259","-0.00029"
"43.80000","1.45745","2519.71777","0.01457","0.00345","251.97177","-0.00030"
"44.00000","1.46415","2521.29932","0.01464","0.00345","252.12993","-0.00027"
"44.20000","1.47099","2523.84570","0.01471","0.00346","252.38457","-0.00025"
"44.40000","1.47753","2524.29053","0.01478","0.00346","252.42905","-0.00026"
"44.60000","1.48428","2525.67700","0.01484","0.00345","252.56770","-0.00025"
"44.80000","1.49083","2526.54468","0.01491","0.00345","252.65446","-0.00025"
"45.00000","1.49758","2528.27075","0.01498","0.00345","252.82707","-0.00030"
"45.20000","1.50416","2528.98755","0.01504","0.00346","252.89876","-0.00025"
"45.40000","1.51084","2530.17822","0.01511","0.00346","253.01782","-0.00030"
"45.60000","1.51749","2531.45288","0.01517","0.00346","253.14529","-0.00026"
"45.80000","1.52413","2532.89966","0.01524","0.00346","253.28996","-0.00024"
"46.00000","1.53101","2535.02734","0.01531","0.00347","253.50273","-0.00030"
"46.20000","1.53760","2533.92578","0.01538","0.00346","253.39258","-0.00025"
"46.40000","1.54419","2532.44238","0.01544","0.00347","253.24423","-0.00020"
"46.60000","1.55094","2531.71558","0.01551","0.00347","253.17155","-0.00025"
"46.80000","1.55749","2529.46924","0.01557","0.00346","252.94693","-0.00026"
"47.00000","1.56413","2528.95972","0.01564","0.00347","252.89597","-0.00020"
"47.20000","1.57080","2529.55957","0.01571","0.00346","252.95596","-0.00020"
"47.40000","1.57756","2529.36865","0.01578","0.00345","252.93686","-0.00022"
"47.60000","1.58423","2527.91846","0.01584","0.00347","252.79184","-0.00020"
"47.80000","1.59084","2526.91675","0.01591","0.00346","252.69168","-0.00020"
"48.00000","1.59769","2527.57031","0.01598","0.00345","252.75703","-0.00020"
"48.20000","1.60412","2527.25122","0.01604","0.00345","252.72513","-0.00020"
"48.40000","1.61089","2529.54492","0.01611","0.00346","252.95450","-0.00020"
"48.60000","1.61750","2531.95117","0.01617","0.00346","253.19511","-0.00020"
"48.80000","1.62415","2535.58667","0.01624","0.00346","253.55867","-0.00020"
"49.00000","1.63095","2540.44434","0.01631","0.00346","254.04443","-0.00020"
"49.20000","1.63747","2544.01392","0.01637","0.00348","254.40140","-0.00020"
"49.40000","1.64418","2548.32373","0.01644","0.00349","254.83237","-0.00020"
"49.60000","1.65080","2551.43750","0.01651","0.00350","255.14375","-0.00020"
"49.80000","1.65770","2554.84937","0.01658","0.00350","255.48494","-0.00018"
"50.00000","1.66423","2556.40552","0.01664","0.00349","255.64055","-0.00020"
"50.20000","1.67082","2557.18018","0.01671","0.00351","255.71802","-0.00020"
"50.40000","1.67762","2557.96387","0.01678","0.00351","255.79639","-0.00020"
"50.60000","1.68408","2556.47949","0.01684","0.00351","255.64795","-0.00020"
"50.80000","1.69089","2556.48853","0.01691","0.00351","255.64885","-0.00015"
"51.00000","1.69746","2555.07446","0.01697","0.00352","255.50745","-0.00015"
"51.20000","1.70428","2555.57227","0.01704","0.00351","255.55722","-0.00015"
"51.40000","1.71093","2555.58545","0.01711","0.00351","255.55855","-0.00015"
"51.60000","1.71757","2555.36035","0.01718","0.00352","255.53604","-0.00018"
"51.80000","1.72424","2555.14917","0.01724","0.00351","255.51492","-0.00015"
"52.00000","1.73075","2553.84375","0.01731","0.00351","255.38437","-0.00015"
"52.20000","1.73759","2553.77441","0.01738","0.00351","255.37744","-0.00015"
"52.40000","1.74414","2551.97412","0.01744","0.00351","255.19742","-0.00015"
"52.60000","1.75081","2551.26562","0.01751","0.00351","255.12656","-0.00015"
"52.80000","1.75762","2551.41797","0.01758","0.00351","255.14180","-0.00015"
"53.00000","1.76419","2550.13452","0.01764","0.00351","255.01346","-0.00015"
"53.20000","1.77086","2549.37939","0.01771","0.00350","254.93794","-0.00016"
"53.40000","1.77752","2549.97827","0.01778","0.00350","254.99783","-0.00020"
"53.60000","1.78428","2551.05786","0.01784","0.00349","255.10579","-0.00015"
"53.80000","1.79085","2550.81714","0.01791","0.00350","255.08171","-0.00015"
"54.00000","1.79745","2550.52686","0.01797","0.00350","255.05269","-0.00017"
"54.20000","1.80427","2551.79932","0.01804","0.00349","255.17993","-0.00014"
"54.40000","1.81077","2552.05713","0.01811","0.00350","255.20572","-0.00010"
"54.60000","1.81755","2554.44263","0.01818","0.00351","255.44426","-0.00014"
"54.80000","1.82423","2556.49805","0.01824","0.00351","255.64981","-0.00020"
"55.00000","1.83087","2558.17139","0.01831","0.00352","255.81714","-0.00015"
"55.20000","1.83764","2560.56543","0.01838","0.00352","256.05655","-0.00015"
"55.40000","1.84416","2561.45605","0.01844","0.00352","256.14560","-0.00010"
"55.60000","1.85083","2563.75146","0.01851","0.00352","256.37515","-0.00020"
"55.80000","1.85742","2564.82056","0.01857","0.00353","256.48206","-0.00018"
"56.00000","1.86428","2567.64966","0.01864","0.00354","256.76495","-0.00020"
"56.20000","1.87086","2569.46777","0.01871","0.00354","256.94678","-0.00018"
"56.40000","1.87747","2570.71973","0.01877","0.00354","257.07196","-0.00015"
"56.60000","1.88435","2570.99512","0.01884","0.00353","257.09952","-0.00016"
"56.80000","1.89080","2567.13452","0.01891","0.00352","256.71344","-0.00018"
"57.00000","1.89750","2564.72900","0.01897","0.00353","256.47290","-0.00020"
"57.20000","1.90415","2561.63672","0.01904","0.00352","256.16367","-0.00015"
"57.40000","1.91090","2559.55469","0.01911","0.00352","255.95547","-0.00020"
"57.60000","1.91753","2557.03687","0.01918","0.00352","255.70369","-0.00015"
"57.80000","1.92415","2554.90698","0.01924","0.00353","255.49069","-0.00010"
"58.00000","1.93089","2553.09229","0.01931","0.00353","255.30923","-0.00010"
"58.20000","1.93742","2548.92529","0.01937","0.00352","254.89253","-0.00010"
"58.40000","1.94437","2545.16968","0.01944","0.00352","254.51697","-0.00014"
"58.60000","1.95086","2539.33765","0.01951","0.00351","253.93376","-0.00015"
"58.80000","1.95747","2534.79004","0.01957","0.00350","253.47900","-0.00012"
"59.00000","1.96425","2533.48120","0.01964","0.00350","253.34811","-0.00015"
"59.20000","1.97082","2532.08398","0.01971","0.00349","253.20840","-0.00016"
"59.40000","1.97748","2531.21948","0.01977","0.00350","253.12195","-0.00015"
"59.60000","1.98413","2530.65552","0.01984","0.00350","253.06555","-0.00016"
"59.80000","1.99094","2530.87573","0.01991","0.00350","253.08757","-0.00015"
"60.00000","1.99755","2530.60498","0.01998","0.00350","253.06050","-0.00012"
"60.20000","2.00416","2529.50854","0.02004","0.00350","252.95085","-0.00011"
"60.40000","2.01091","2527.53809","0.02011","0.00350","252.75381","-0.00010"
"60.60000","2.01746","2521.12158","0.02017","0.00351","252.11215","-0.00010"
"60.80000","2.02423","2510.59180","0.02024","0.00350","251.05917","-0.00010"
"61.00000","2.03083","2499.66113","0.02031","0.00348","249.96611","-0.00005"
"61.20000","2.03745","2490.65723","0.02037","0.00347","249.06572","-0.00005"
"61.40000","2.04429","2484.21460","0.02044","0.00346","248.42146","-0.00005"
"61.60000","2.05081","2473.81860","0.02051","0.00344","247.38187","-0.00006"
"61.80000","2.05754","2462.43433","0.02058","0.00343","246.24344","-0.00006"
"62.00000","2.06416","2453.86353","0.02064","0.00341","245.38635","-0.00005"
"62.20000","2.07094","2448.07568","0.02071","0.00340","244.80757","-0.00005"
"62.40000","2.07752","2442.85962","0.02078","0.00339","244.28596","-0.00004"
"62.60000","2.08407","2435.20703","0.02084","0.00339","243.52071","-0.00005"
"62.80000","2.09094","2424.30298","0.02091","0.00337","242.43030","-0.00010"
"63.00000","2.09740","2414.13013","0.02097","0.00337","241.41301","-0.00012"
"63.20000","2.10420","2410.63745","0.02104","0.00336","241.06375","-0.00010"
"63.40000","2.11082","2408.09717","0.02111","0.00336","240.80972","-0.00005"
"63.60000","2.11757","2406.07031","0.02118","0.00336","240.60703","-0.00005"
"63.80000","2.12433","2405.06079","0.02124","0.00336","240.50607","-0.00006"
"64.00000","2.13080","2402.58423","0.02131","0.00335","240.25842","-0.00005"
"64.20000","2.13748","2401.39844","0.02137","0.00336","240.13985","-0.00009"
"64.40000","2.14405","2399.81152","0.02144","0.00336","239.98116","-0.00010"
"64.60000","2.15094","2398.43237","0.02151","0.00335","239.84323","-0.00010"
"64.80000","2.15746","2395.65259","0.02157","0.00336","239.56526","-0.00005"
"65.00000","2.16420","2393.39966","0.02164","0.00336","239.33997","-0.00003"
"65.20000","2.17096","2391.29297","0.02171","0.00336","239.12930","0.00000"
"65.40000","2.17748","2386.11182","0.02177","0.00336","238.61118","-0.00005"
"65.60000","2.18422","2380.81787","0.02184","0.00334","238.08179","-0.00005"
"65.80000","2.19080","2377.23413","0.02191","0.00334","237.72342","-0.00005"
"66.00000","2.19760","2375.55444","0.02198","0.00333","237.55545","-0.00004"
"66.20000","2.20413","2372.69238","0.02204","0.00333","237.26924","0.00000"
"66.40000","2.21081","2367.24146","0.02211","0.00332","236.72415","0.00000"
"66.60000","2.21755","2363.32568","0.02218","0.00331","236.33257","0.00000"
"66.80000","2.22412","2357.74683","0.02224","0.00331","235.77469","0.00005"
"67.00000","2.23089","2352.43311","0.02231","0.00331","235.24332","0.00004"
"67.20000","2.23755","2346.63110","0.02238","0.00331","234.66312","0.00000"
"67.40000","2.24419","2339.98047","0.02244","0.00330","233.99805","0.00000"
"67.60000","2.25094","2335.40381","0.02251","0.00329","233.54037","-0.00001"
"67.80000","2.25752","2328.33936","0.02258","0.00328","232.83394","0.00000"
"68.00000","2.26411","2320.06885","0.02264","0.00328","232.00688","0.00007"
"68.20000","2.27081","2310.05469","0.02271","0.00327","231.00546","0.00006"
"68.40000","2.27757","2301.49951","0.02278","0.00325","230.14995","0.00001"
"68.60000","2.28424","2294.20557","0.02284","0.00324","229.42056","0.00000"
"68.80000","2.29076","2285.30566","0.02291","0.00322","228.53056","0.00000"
"69.00000","2.29765","2277.75024","0.02298","0.00322","227.77502","0.00000"
"69.20000","2.30410","2263.29736","0.02304","0.00322","226.32974","0.00005"
"69.40000","2.31089","2247.61011","0.02311","0.00321","224.76102","0.00010"
"69.60000","2.31754","2232.93262","0.02318","0.00319","223.29326","0.00010"
"69.80000","2.32418","2220.05591","0.02324","0.00317","222.00558","0.00015"
"70.00000","2.33087","2209.54761","0.02331","0.00315","220.95476","0.00014"
"70.20000","2.33745","2198.23755","0.02337","0.00314","219.82376","0.00015"
"70.40000","2.34426","2191.09814","0.02344","0.00312","219.10982","0.00011"
"70.60000","2.35076","2184.08716","0.02351","0.00310","218.40872","0.00011"
"70.80000","2.35759","2177.55371","0.02358","0.00308","217.75537","0.00010"
"71.00000","2.36415","2169.91064","0.02364","0.00309","216.99106","0.00007"
"71.20000","2.37081","2160.12207","0.02371","0.00308","216.01221","0.00010"
"71.40000","2.37767","2149.04443","0.02378","0.00306","214.90445","0.00010"
"71.60000","2.38410","2133.46631","0.02384","0.00304","213.34663","0.00020"
"71.80000","2.39079","2118.29663","0.02391","0.00302","211.82967","0.00015"
"72.00000","2.39746","2103.86523","0.02397","0.00301","210.38652","0.00015"
"72.20000","2.40432","2091.44995","0.02404","0.00298","209.14499","0.00010"
"72.40000","2.41081","2080.73975","0.02411","0.00298","208.07397","0.00011"
"72.60000","2.41747","2072.57007","0.02417","0.00297","207.25700","0.00015"
"72.80000","2.42424","2062.56128","0.02424","0.00296","206.25613","0.00010"
"73.00000","2.43076","2050.73926","0.02431","0.00295","205.07393","0.00015"
"73.20000","2.43768","2036.96326","0.02438","0.00293","203.69632","0.00013"
"73.40000","2.44414","2019.57935","0.02444","0.00292","201.95793","0.00015"
"73.60000","2.45081","2007.01599","0.02451","0.00290","200.70160","0.00020"
"73.80000","2.45755","1991.96191","0.02458","0.00288","199.19620","0.00025"
"74.00000","2.46422","1963.33643","0.02464","0.00286","196.33365","0.00026"
"74.20000","2.47079","1932.56812","0.02471","0.00282","193.25681","0.00025"
"74.40000","2.47747","1910.37939","0.02477","0.00278","191.03793","0.00020"
"74.60000","2.48429","1885.80969","0.02484","0.00276","188.58096","0.00020"
"74.80000","2.49087","1859.10254","0.02491","0.00273","185.91025","0.00020"
"75.00000","2.49750","1836.94116","0.02497","0.00270","183.69412","0.00022"
"75.20000","2.50426","1816.34375","0.02504","0.00266","181.63437","0.00025"
"75.40000","2.51080","1797.81201","0.02511","0.00264","179.78120","0.00029"
"75.60000","2.51753","1784.56433","0.02518","0.00261","178.45644","0.00030"
"75.80000","2.52423","1768.37122","0.02524","0.00260","176.83713","0.00030"
"76.00000","2.53085","1748.36719","0.02531","0.00257","174.83672","0.00035"
"76.20000","2.53756","1726.69250","0.02538","0.00255","172.66925","0.00034"
"76.40000","2.54412","1703.96997","0.02544","0.00253","170.39700","0.00040"
"76.60000","2.55087","1682.49304","0.02551","0.00251","168.24930","0.00045"
"76.80000","2.55747","1660.44202","0.02557","0.00248","166.04420","0.00044"
"77.00000","2.56432","1641.53162","0.02564","0.00246","164.15317","0.00049"
"77.20000","2.57088","1621.68127","0.02571","0.00244","162.16812","0.00044"
"77.40000","2.57744","1598.22559","0.02577","0.00242","159.82256","0.00049"
"77.60000","2.58432","1577.55310","0.02584","0.00240","157.75531","0.00050"
"77.80000","2.59076","1554.64966","0.02591","0.00238","155.46497","0.00052"
"78.00000","2.59747","1527.31274","0.02597","0.00236","152.73128","0.00054"
"78.20000","2.60407","1496.90100","0.02604","0.00233","149.69009","0.00054"
"78.40000","2.61096","1469.73096","0.02611","0.00229","146.97310","0.00055"
"78.60000","2.61760","1443.07104","0.02618","0.00226","144.30710","0.00059"
"78.80000","2.62423","1418.60010","0.02624","0.00223","141.86002","0.00059"
"79.00000","2.63092","1396.63318","0.02631","0.00221","139.66331","0.00063"
"79.20000","2.63741","1374.83081","0.02637","0.00219","137.48308","0.00063"
"79.40000","2.64429","1353.23413","0.02644","0.00216","135.32341","0.00067"
"79.60000","2.65080","1326.79236","0.02651","0.00213","132.67923","0.00066"
"79.80000","2.65748","1295.19336","0.02657","0.00210","129.51933","0.00069"
"80.00000","2.66422","1269.81152","0.02664","0.00207","126.98116","0.00074"
"80.20000","2.67085","1242.69238","0.02671","0.00205","124.26924","0.00079"
"80.40000","2.67755","1221.41174","0.02678","0.00203","122.14117","0.00083"
"80.60000","2.68417","1205.99646","0.02684","0.00202","120.59965","0.00084"
"80.80000","2.69101","1193.74744","0.02691","0.00201","119.37474","0.00088"
"81.00000","2.69751","1180.77356","0.02698","0.00200","118.07735","0.00084"
"81.20000","2.70419","1168.94604","0.02704","0.00199","116.89461","0.00085"
"81.40000","2.71087","1156.31738","0.02711","0.00198","115.63174","0.00089"
"81.60000","2.71743","1145.24841","0.02717","0.00197","114.52484","0.00088"
"81.80000","2.72416","1135.85718","0.02724","0.00197","113.58572","0.00089"
"82.00000","2.73085","1123.31128","0.02731","0.00196","112.33113","0.00094"
"82.20000","2.73755","1109.61304","0.02738","0.00195","110.96130","0.00094"
"82.40000","2.74429","1098.85010","0.02744","0.00194","109.88501","0.00092"
"82.60000","2.75088","1087.30640","0.02751","0.00193","108.73064","0.00094"
"82.80000","2.75753","1077.17419","0.02758","0.00192","107.71742","0.00090"
"83.00000","2.76415","1068.50000","0.02764","0.00191","106.85000","0.00089"
"83.20000","2.77089","1059.85217","0.02771","0.00192","105.98521","0.00089"
"83.40000","2.77751","1048.20471","0.02778","0.00191","104.82047","0.00094"
"83.60000","2.78409","1038.35498","0.02784","0.00190","103.83549","0.00094"
"83.80000","2.79096","1030.32166","0.02791","0.00190","103.03217","0.00099"
"84.00000","2.79752","1020.93518","0.02798","0.00188","102.09352","0.00099"
"84.20000","2.80428","1013.67395","0.02804","0.00187","101.36739","0.00089"
"84.40000","2.81088","1005.25543","0.02811","0.00187","100.52554","0.00099"
"84.60000","2.81759","997.49762","0.02818","0.00186","99.74976","0.00099"
"84.80000","2.82423","990.76154","0.02824","0.00186","99.07616","0.00099"
"85.00000","2.83079","983.80792","0.02831","0.00186","98.38079","0.00099"
"85.20000","2.83757","978.63275","0.02838","0.00186","97.86327","0.00102"
"85.40000","2.84402","972.26825","0.02844","0.00185","97.22682","0.00099"
"85.60000","2.85092","968.93469","0.02851","0.00185","96.89347","0.00103"
"85.80000","2.85754","965.80182","0.02858","0.00185","96.58018","0.00104"
"86.00000","2.86430","964.44098","0.02864","0.00184","96.44410","0.00101"
"86.20000","2.87100","962.67316","0.02871","0.00184","96.26732","0.00099"
"86.40000","2.87752","959.52618","0.02878","0.00183","95.95262","0.00099"
"86.60000","2.88420","957.16528","0.02884","0.00182","95.71653","0.00096"
"86.80000","2.89071","953.44519","0.02891","0.00182","95.34452","0.00099"
"87.00000","2.89760","950.25488","0.02898","0.00182","95.02549","0.00098"
"87.20000","2.90408","945.79132","0.02904","0.00182","94.57913","0.00100"
"87.40000","2.91085","941.53046","0.02911","0.00182","94.15305","0.00102"
"87.60000","2.91765","938.38635","0.02918","0.00182","93.83864","0.00099"
"87.80000","2.92420","934.72253","0.02924","0.00184","93.47225","0.00099"
"88.00000","2.93098","933.18121","0.02931","0.00181","93.31812","0.00099"
"88.20000","2.93750","931.81824","0.02938","0.00181","93.18182","0.00098"
"88.40000","2.94422","932.41052","0.02944","0.00182","93.24105","0.00104"
"88.60000","2.95083","932.24738","0.02951","0.00182","93.22474","0.00100"
"88.80000","2.95748","931.49298","0.02957","0.00181","93.14930","0.00100"
"89.00000","2.96417","930.86615","0.02964","0.00181","93.08662","0.00099"
"89.20000","2.97082","929.19489","0.02971","0.00181","92.91949","0.00100"
"89.40000","2.97765","928.70593","0.02978","0.00179","92.87059","0.00100"
"89.60000","2.98426","927.58258","0.02984","0.00179","92.75826","0.00098"
"89.80000","2.99088","927.15295","0.02991","0.00180","92.71529","0.00104"
"90.00000","2.99763","927.16907","0.02998","0.00180","92.71690","0.00099"
"90.20000","3.00413","925.90314","0.03004","0.00180","92.59032","0.00103"
"90.40000","3.01080","925.47406","0.03011","0.00179","92.54741","0.00104"
"90.60000","3.01750","924.15149","0.03017","0.00179","92.41515","0.00102"
"90.80000","3.02419","922.04382","0.03024","0.00179","92.20438","0.00104"
"91.00000","3.03090","920.43689","0.03031","0.00179","92.04369","0.00103"
"91.20000","3.03750","918.09528","0.03038","0.00179","91.80952","0.00104"
"91.40000","3.04435","917.53461","0.03044","0.00179","91.75346","0.00099"
"91.60000","3.05083","915.99841","0.03051","0.00179","91.59984","0.00099"
"91.80000","3.05761","914.94489","0.03058","0.00178","91.49449","0.00104"
"92.00000","3.06415","914.28961","0.03064","0.00177","91.42896","0.00104"
"92.20000","3.07078","913.04333","0.03071","0.00178","91.30434","0.00104"
"92.40000","3.07761","912.06812","0.03078","0.00178","91.20681","0.00099"
"92.60000","3.08412","909.16382","0.03084","0.00177","90.91638","0.00102"
"92.80000","3.09082","908.75885","0.03091","0.00178","90.87589","0.00102"
"93.00000","3.09752","908.83197","0.03098","0.00177","90.88319","0.00104"
"93.20000","3.10440","908.15118","0.03104","0.00177","90.81512","0.00106"
"93.40000","3.11091","906.14008","0.03111","0.00178","90.61401","0.00104"
"93.60000","3.11747","905.12726","0.03117","0.00177","90.51273","0.00104"
"93.80000","3.12425","904.05029","0.03124","0.00177","90.40503","0.00103"
"94.00000","3.13076","900.73486","0.03131","0.00178","90.07349","0.00101"
"94.20000","3.13756","898.01233","0.03138","0.00176","89.80123","0.00099"
"94.40000","3.14414","894.62640","0.03144","0.00176","89.46264","0.00096"
"94.54700","3.14919","893.50323","0.03149","0.00175","89.35033","0.00099"