File: Tension/Section_2_Group_4/f4a.is_tens_RawData/Specimen_RawData_1.csv
Time,Extension,Load,Tensile strain (Extension),Tensile stress,Strain-by-clip-gage
(s),(mm),(N),(mm/mm),(MPa),(mm/mm)
"0.00000","0.00000","-7.86660","0.00000","-0.78666","0.00001"
"0.20000","0.00204","5.93326","0.00002","0.59333","0.00000"
"0.40000","0.01045","69.72922","0.00010","6.97292","0.00001"
"0.60000","0.01733","118.84447","0.00017","11.88445","-0.00003"
"0.80000","0.02401","164.22995","0.00024","16.42299","0.00005"
"1.00000","0.03082","208.85741","0.00031","20.88574","0.00000"
"1.20000","0.03735","249.29529","0.00037","24.92953","0.00003"
"1.40000","0.04396","288.93256","0.00044","28.89326","0.00005"
"1.60000","0.05066","328.19653","0.00051","32.81965","-0.00003"
"1.80000","0.05715","364.81985","0.00057","36.48199","0.00000"
"2.00000","0.06407","403.01849","0.00064","40.30185","-0.00001"
"2.20000","0.07057","437.26315","0.00071","43.72631","-0.00002"
"2.40000","0.07733","472.87308","0.00077","47.28731","0.00001"
"2.60000","0.08412","509.12881","0.00084","50.91288","0.00001"
"2.80000","0.09069","543.01428","0.00091","54.30143","0.00001"
"3.00000","0.09734","577.10962","0.00097","57.71096","0.00000"
"3.20000","0.10392","609.91986","0.00104","60.99199","-0.00002"
"3.40000","0.11077","644.50244","0.00111","64.45024","-0.00001"
"3.60000","0.11726","675.92346","0.00117","67.59235","0.00000"
"3.80000","0.12393","708.40527","0.00124","70.84053","0.00001"
"4.00000","0.13068","741.05908","0.00131","74.10591","0.00001"
"4.20000","0.13724","772.14246","0.00137","77.21425","0.00000"
"4.40000","0.14408","804.95288","0.00144","80.49529","0.00000"
"4.60000","0.15071","836.03217","0.00151","83.60322","0.00001"
"4.80000","0.15738","866.64941","0.00157","86.66494","0.00000"
"5.00000","0.16403","897.24689","0.00164","89.72469","0.00000"
"5.20000","0.17062","926.74701","0.00171","92.67470","0.00000"
"5.40000","0.17726","956.56281","0.00177","95.65628","0.00000"
"5.60000","0.18390","986.12390","0.00184","98.61239","0.00001"
"5.80000","0.19071","1016.65259","0.00191","101.66526","0.00000"
"6.00000","0.19738","1045.68286","0.00197","104.56828","0.00000"
"6.20000","0.20397","1073.89185","0.00204","107.38918","0.00000"
"6.40000","0.21081","1103.67896","0.00211","110.36790","0.00000"
"6.60000","0.21725","1130.36499","0.00217","113.03650","0.00001"
"6.80000","0.22399","1158.87683","0.00224","115.88768","0.00001"
"7.00000","0.23060","1186.57849","0.00231","118.65785","0.00000"
"7.20000","0.23734","1214.51978","0.00237","121.45198","0.00000"
"7.40000","0.24403","1241.93774","0.00244","124.19377","0.00001"
"7.60000","0.25063","1268.74060","0.00251","126.87406","0.00000"
"7.80000","0.25737","1295.84460","0.00257","129.58446","0.00000"
"8.00000","0.26394","1321.53931","0.00264","132.15393","-0.00001"
"8.20000","0.27079","1349.01379","0.00271","134.90138","0.00000"
"8.40000","0.27732","1374.19910","0.00277","137.41991","0.00001"
"8.60000","0.28396","1399.48474","0.00284","139.94847","0.00000"
"8.80000","0.29072","1425.80127","0.00291","142.58012","0.00000"
"9.00000","0.29724","1449.67419","0.00297","144.96742","0.00000"
"9.20000","0.30403","1475.41345","0.00304","147.54135","0.00000"
"9.40000","0.31056","1499.21179","0.00311","149.92117","0.00001"
"9.60000","0.31743","1524.81067","0.00317","152.48106","0.00000"
"9.80000","0.32403","1548.45410","0.00324","154.84541","-0.00001"
"10.00000","0.33069","1571.88232","0.00331","157.18823","0.00000"
"10.20000","0.33734","1595.17883","0.00337","159.51788","0.00001"
"10.40000","0.34386","1617.30847","0.00344","161.73085","0.00001"
"10.60000","0.35069","1641.48804","0.00351","164.14880","0.00000"
"10.80000","0.35732","1664.03577","0.00357","166.40358","0.00000"
"11.00000","0.36395","1686.24805","0.00364","168.62480","0.00000"
"11.20000","0.37072","1708.97192","0.00371","170.89719","0.00000"
"11.40000","0.37732","1730.43555","0.00377","173.04355","0.00001"
"11.60000","0.38400","1751.68738","0.00384","175.16873","0.00000"
"11.80000","0.39062","1772.52869","0.00391","177.25287","0.00000"
"12.00000","0.39742","1794.09290","0.00397","179.40929","0.00000"
"12.20000","0.40395","1813.66284","0.00404","181.36629","0.00000"
"12.40000","0.41058","1833.58655","0.00411","183.35866","0.00000"
"12.60000","0.41740","1854.47144","0.00417","185.44714","0.00000"
"12.80000","0.42390","1873.02527","0.00424","187.30252","0.00000"
"13.00000","0.43068","1893.05188","0.00431","189.30519","0.00000"
"13.20000","0.43734","1912.35864","0.00437","191.23587","0.00001"
"13.40000","0.44403","1931.18921","0.00444","193.11893","0.00000"
"13.60000","0.45067","1949.82593","0.00451","194.98259","0.00000"
"13.80000","0.45731","1967.93994","0.00457","196.79399","0.00000"
"14.00000","0.46400","1986.03308","0.00464","198.60330","0.00000"
"14.20000","0.47050","2002.75354","0.00471","200.27536","0.00001"
"14.40000","0.47740","2021.88770","0.00477","202.18877","0.00000"
"14.60000","0.48400","2038.98828","0.00484","203.89883","0.00000"
"14.80000","0.49060","2055.74292","0.00491","205.57430","0.00000"
"15.00000","0.49747","2074.48071","0.00497","207.44807","0.00000"
"15.20000","0.50393","2089.83838","0.00504","208.98384","0.00000"
"15.40000","0.51059","2105.95850","0.00511","210.59586","0.00000"
"15.60000","0.51726","2122.30811","0.00517","212.23080","0.00000"
"15.80000","0.52409","2139.33301","0.00524","213.93330","0.00000"
"16.00000","0.53061","2154.27271","0.00531","215.42728","0.00001"
"16.20000","0.53728","2169.69385","0.00537","216.96939","0.00000"
"16.40000","0.54406","2186.22119","0.00544","218.62212","0.00000"
"16.60000","0.55056","2200.10278","0.00551","220.01028","0.00000"
"16.80000","0.55744","2216.47510","0.00557","221.64751","0.00000"
"17.00000","0.56397","2229.91772","0.00564","222.99178","0.00001"
"17.20000","0.57066","2244.44116","0.00571","224.44412","0.00000"
"17.40000","0.57735","2259.82031","0.00577","225.98203","0.00000"
"17.60000","0.58394","2274.49536","0.00584","227.44954","0.00000"
"17.80000","0.59057","2290.14673","0.00591","229.01468","0.00001"
"18.00000","0.59729","2306.12671","0.00597","230.61267","0.00000"
"18.20000","0.60411","2323.08325","0.00604","232.30832","0.00000"
"18.40000","0.61064","2338.18579","0.00611","233.81857","0.00000"
"18.60000","0.61727","2354.31445","0.00617","235.43144","0.00000"
"18.80000","0.62409","2371.88818","0.00624","237.18881","0.00000"
"19.00000","0.63059","2387.51538","0.00631","238.75154","0.00000"
"19.20000","0.63730","2404.35156","0.00637","240.43515","0.00000"
"19.40000","0.64396","2421.34399","0.00644","242.13440","0.00000"
"19.60000","0.65063","2437.92749","0.00651","243.79276","0.00000"
"19.80000","0.65739","2455.27466","0.00657","245.52747","0.00000"
"20.00000","0.66392","2471.19458","0.00664","247.11946","0.00000"
"20.20000","0.67072","2488.92163","0.00671","248.89217","0.00000"
"20.40000","0.67722","2504.98682","0.00677","250.49869","0.00000"
"20.60000","0.68409","2523.01978","0.00684","252.30197","0.00000"
"20.80000","0.69064","2538.91187","0.00691","253.89119","0.00001"
"21.00000","0.69723","2554.95703","0.00697","255.49570","0.00000"
"21.20000","0.70407","2572.88062","0.00704","257.28806","0.00000"
"21.40000","0.71053","2588.21240","0.00711","258.82123","0.00000"
"21.60000","0.71732","2605.80103","0.00717","260.58011","0.00000"
"21.80000","0.72393","2622.13379","0.00724","262.21338","0.00000"
"22.00000","0.73074","2639.47632","0.00731","263.94763","0.00000"
"22.20000","0.73737","2655.93164","0.00737","265.59317","0.00000"
"22.40000","0.74390","2671.09668","0.00744","267.10968","0.00000"
"22.60000","0.75069","2688.30273","0.00751","268.83026","0.00001"
"22.80000","0.75720","2703.62134","0.00757","270.36212","0.00000"
"23.00000","0.76402","2721.05518","0.00764","272.10553","0.00000"
"23.20000","0.77059","2736.93677","0.00771","273.69366","0.00000"
"23.40000","0.77736","2753.67603","0.00777","275.36761","0.00000"
"23.60000","0.78403","2770.46094","0.00784","277.04608","0.00000"
"23.80000","0.79064","2786.34473","0.00791","278.63446","0.00001"
"24.00000","0.79730","2802.40820","0.00797","280.24081","0.00000"
"24.20000","0.80389","2818.16577","0.00804","281.81659","0.00000"
"24.40000","0.81077","2835.77637","0.00811","283.57764","0.00001"
"24.60000","0.81727","2850.99658","0.00817","285.09967","0.00000"
"24.80000","0.82392","2866.96411","0.00824","286.69641","0.00000"
"25.00000","0.83069","2883.91309","0.00831","288.39130","0.00000"
"25.20000","0.83730","2899.52856","0.00837","289.95285","-0.00001"
"25.40000","0.84395","2915.60498","0.00844","291.56049","0.00000"
"25.60000","0.85065","2931.78613","0.00851","293.17862","0.00001"
"25.80000","0.85735","2947.86914","0.00857","294.78693","0.00000"
"26.00000","0.86406","2964.00610","0.00864","296.40060","0.00000"
"26.20000","0.87064","2979.24902","0.00871","297.92490","0.00000"
"26.40000","0.87728","2994.72095","0.00877","299.47211","0.00000"
"26.60000","0.88390","3010.16504","0.00884","301.01651","0.00001"
"26.80000","0.89071","3027.06421","0.00891","302.70642","0.00000"
"27.00000","0.89736","3042.62378","0.00897","304.26239","0.00000"
"27.20000","0.90391","3057.22607","0.00904","305.72260","0.00000"
"27.40000","0.91075","3073.85522","0.00911","307.38553","0.00000"
"27.60000","0.91724","3087.81763","0.00917","308.78177","0.00000"
"27.80000","0.92402","3103.52051","0.00924","310.35205","0.00000"
"28.00000","0.93065","3118.39209","0.00931","311.83920","0.00000"
"28.20000","0.93739","3133.50195","0.00937","313.35019","0.00000"
"28.40000","0.94399","3148.33789","0.00944","314.83380","0.00001"
"28.60000","0.95058","3162.60229","0.00951","316.26022","0.00000"
"28.80000","0.95741","3178.73218","0.00957","317.87323","0.00000"
"29.00000","0.96384","3192.30029","0.00964","319.23004","0.00000"
"29.20000","0.97070","3209.02612","0.00971","320.90262","0.00001"
"29.40000","0.97728","3223.98242","0.00977","322.39825","0.00001"
"29.60000","0.98398","3239.68335","0.00984","323.96832","0.00001"
"29.80000","0.99077","3256.31494","0.00991","325.63150","0.00000"
"30.00000","0.99727","3270.68726","0.00997","327.06873","0.00000"
"30.20000","1.00395","3286.48877","0.01004","328.64886","0.00000"
"30.40000","1.01056","3301.89722","0.01011","330.18973","0.00000"
"30.60000","1.01749","3319.32275","0.01017","331.93228","0.00000"
"30.80000","1.02392","3333.54590","0.01024","333.35458","0.00000"
"31.00000","1.03056","3349.12866","0.01031","334.91287","0.00000"
"31.20000","1.03735","3366.13330","0.01037","336.61334","0.00001"
"31.40000","1.04389","3380.85962","0.01044","338.08597","0.00001"
"31.60000","1.05076","3398.10767","0.01051","339.81076","0.00000"
"31.80000","1.05730","3413.29321","0.01057","341.32932","0.00000"
"32.00000","1.06402","3429.41504","0.01064","342.94150","0.00000"
"32.20000","1.07067","3445.54224","0.01071","344.55423","0.00001"
"32.40000","1.07732","3461.48315","0.01077","346.14832","0.00000"
"32.60000","1.08391","3477.11328","0.01084","347.71133","0.00000"
"32.80000","1.09056","3493.20361","0.01091","349.32037","0.00000"
"33.00000","1.09742","3510.41260","0.01097","351.04126","0.00001"
"33.20000","1.10402","3525.86914","0.01104","352.58691","0.00001"
"33.40000","1.11062","3541.59277","0.01111","354.15927","0.00000"
"33.60000","1.11743","3558.60889","0.01117","355.86090","0.00000"
"33.80000","1.12394","3573.73364","0.01124","357.37335","0.00000"
"34.00000","1.13063","3589.91479","0.01131","358.99149","0.00001"
"34.20000","1.13732","3606.29932","0.01137","360.62994","0.00001"
"34.40000","1.14402","3622.41895","0.01144","362.24188","0.00000"
"34.60000","1.15064","3638.40430","0.01151","363.84042","0.00000"
"34.80000","1.15723","3653.94727","0.01157","365.39471","0.00001"
"35.00000","1.16405","3671.10010","0.01164","367.11002","0.00001"
"35.20000","1.17059","3686.21045","0.01171","368.62103","0.00000"
"35.40000","1.17745","3703.73584","0.01177","370.37360","0.00000"
"35.60000","1.18403","3719.27100","0.01184","371.92709","-0.00001"
"35.80000","1.19062","3734.70190","0.01191","373.47018","0.00001"
"36.00000","1.19742","3752.01318","0.01197","375.20132","0.00001"
"36.20000","1.20388","3766.79297","0.01204","376.67929","0.00000"
"36.40000","1.21055","3782.91187","0.01211","378.29120","0.00000"
"36.60000","1.21717","3799.16553","0.01217","379.91656","0.00000"
"36.80000","1.22416","3817.39355","0.01224","381.73935","0.00000"
"37.00000","1.23072","3832.89868","0.01231","383.28986","0.00001"
"37.20000","1.23734","3848.31323","0.01237","384.83133","0.00000"
"37.40000","1.24410","3865.27295","0.01244","386.52728","0.00000"
"37.60000","1.25056","3879.95532","0.01251","387.99554","0.00000"
"37.80000","1.25734","3897.14014","0.01257","389.71402","0.00001"
"38.00000","1.26390","3912.84790","0.01264","391.28479","0.00001"
"38.20000","1.27063","3929.23120","0.01271","392.92313","0.00000"
"38.40000","1.27734","3945.62085","0.01277","394.56207","0.00000"
"38.60000","1.28397","3961.24951","0.01284","396.12494","0.00001"
"38.80000","1.29071","3977.76074","0.01291","397.77606","0.00001"
"39.00000","1.29727","3993.17529","0.01297","399.31754","0.00000"
"39.20000","1.30419","4011.19116","0.01304","401.11911","0.00000"
"39.40000","1.31063","4025.91797","0.01311","402.59180","0.00000"
"39.60000","1.31728","4041.73462","0.01317","404.17346","0.00001"
"39.80000","1.32402","4058.47046","0.01324","405.84705","0.00001"
"40.00000","1.33059","4073.79980","0.01331","407.37997","0.00000"
"40.20000","1.33727","4089.92773","0.01337","408.99277","0.00000"
"40.40000","1.34397","4106.30176","0.01344","410.63019","0.00000"
"40.60000","1.35073","4122.84766","0.01351","412.28476","0.00000"
"40.80000","1.35742","4139.41602","0.01357","413.94159","0.00001"
"41.00000","1.36401","4154.73047","0.01364","415.47305","0.00000"
"41.20000","1.37070","4171.13525","0.01371","417.11353","0.00000"
"41.40000","1.37723","4186.58691","0.01377","418.65869","0.00001"
"41.60000","1.38402","4203.50293","0.01384","420.35028","0.00001"
"41.80000","1.39062","4219.31396","0.01391","421.93140","0.00000"
"42.00000","1.39721","4234.75439","0.01397","423.47543","0.00000"
"42.20000","1.40410","4252.43896","0.01404","425.24390","0.00000"
"42.40000","1.41068","4267.51709","0.01411","426.75171","0.00001"
"42.60000","1.41741","4284.10205","0.01417","428.41022","0.00001"
"42.80000","1.42396","4299.63086","0.01424","429.96307","0.00000"
"43.00000","1.43077","4316.53857","0.01431","431.65387","0.00000"
"43.20000","1.43734","4332.02637","0.01437","433.20264","0.00000"
"43.40000","1.44387","4347.21582","0.01444","434.72159","0.00001"
"43.60000","1.45071","4364.37842","0.01451","436.43784","0.00000"
"43.80000","1.45715","4378.82324","0.01457","437.88232","0.00000"
"44.00000","1.46404","4396.46143","0.01464","439.64615","0.00000"
"44.20000","1.47070","4412.62744","0.01471","441.26276","0.00000"
"44.40000","1.47744","4429.08984","0.01477","442.90900","0.00001"
"44.60000","1.48409","4445.38818","0.01484","444.53882","0.00000"
"44.80000","1.49063","4460.63672","0.01491","446.06366","0.00000"
"45.00000","1.49732","4476.84619","0.01497","447.68463","0.00000"
"45.20000","1.50381","4491.61426","0.01504","449.16144","0.00000"
"45.40000","1.51080","4510.04395","0.01511","451.00439","0.00001"
"45.60000","1.51725","4524.80029","0.01517","452.48004","0.00000"
"45.80000","1.52394","4540.91406","0.01524","454.09140","0.00000"
"46.00000","1.53079","4558.49756","0.01531","455.84976","0.00001"
"46.20000","1.53732","4573.62646","0.01537","457.36264","0.00001"
"46.40000","1.54409","4590.18945","0.01544","459.01895","0.00001"
"46.60000","1.55064","4605.28125","0.01551","460.52814","0.00000"
"46.80000","1.55737","4621.61572","0.01557","462.16156","0.00000"
"47.00000","1.56394","4637.14355","0.01564","463.71436","0.00000"
"47.20000","1.57059","4653.13965","0.01571","465.31396","0.00001"
"47.40000","1.57733","4669.73975","0.01577","466.97397","0.00000"
"47.60000","1.58391","4685.24268","0.01584","468.52426","0.00000"
"47.80000","1.59077","4702.51025","0.01591","470.25104","0.00000"
"48.00000","1.59741","4718.58740","0.01597","471.85873","0.00000"
"48.20000","1.60398","4733.83789","0.01604","473.38379","0.00001"
"48.40000","1.61073","4750.49561","0.01611","475.04956","0.00000"
"48.60000","1.61727","4765.59912","0.01617","476.55991","0.00000"
"48.80000","1.62390","4781.31299","0.01624","478.13129","0.00000"
"49.00000","1.63062","4797.80762","0.01631","479.78076","0.00000"
"49.20000","1.63739","4814.42676","0.01637","481.44269","0.00001"
"49.40000","1.64401","4830.38037","0.01644","483.03802","0.00001"
"49.60000","1.65061","4845.85840","0.01651","484.58585","0.00000"
"49.80000","1.65748","4863.59668","0.01657","486.35968","0.00000"
"50.00000","1.66391","4877.78613","0.01664","487.77863","0.00000"
"50.20000","1.67068","4894.70605","0.01671","489.47061","0.00000"
"50.40000","1.67731","4910.52100","0.01677","491.05209","0.00001"
"50.60000","1.68397","4926.16650","0.01684","492.61664","0.00000"
"50.80000","1.69073","4942.92139","0.01691","494.29214","0.00000"
"51.00000","1.69725","4957.95215","0.01697","495.79523","0.00001"
"51.20000","1.70396","4974.21045","0.01704","497.42105","0.00000"
"51.40000","1.71063","4990.59033","0.01711","499.05902","0.00000"
"51.60000","1.71752","5008.29395","0.01718","500.82941","0.00000"
"51.80000","1.72398","5023.20215","0.01724","502.32022","0.00000"
"52.00000","1.73061","5038.91553","0.01731","503.89154","0.00001"
"52.20000","1.73741","5056.13428","0.01737","505.61343","0.00001"
"52.40000","1.74385","5070.53906","0.01744","507.05389","0.00000"
"52.60000","1.75070","5087.86572","0.01751","508.78656","0.00000"
"52.80000","1.75726","5103.50293","0.01757","510.35028","0.00001"
"53.00000","1.76410","5120.84717","0.01764","512.08472","0.00001"
"53.20000","1.77072","5136.73438","0.01771","513.67346","0.00000"
"53.40000","1.77735","5152.49805","0.01777","515.24982","0.00000"
"53.60000","1.78402","5168.85352","0.01784","516.88538","0.00000"
"53.80000","1.79053","5183.74414","0.01791","518.37439","0.00000"
"54.00000","1.79741","5200.92822","0.01797","520.09283","0.00000"
"54.20000","1.80399","5216.19189","0.01804","521.61920","0.00000"
"54.40000","1.81061","5231.55273","0.01811","523.15527","0.00000"
"54.60000","1.81740","5248.17920","0.01817","524.81793","0.00000"
"54.80000","1.82395","5263.25000","0.01824","526.32501","0.00001"
"55.00000","1.83067","5279.59473","0.01831","527.95947","0.00001"
"55.20000","1.83731","5295.78760","0.01837","529.57874","0.00000"
"55.40000","1.84409","5312.61426","0.01844","531.26141","0.00000"
"55.60000","1.85063","5327.71191","0.01851","532.77118","0.00000"
"55.80000","1.85725","5343.47461","0.01857","534.34747","0.00001"
"56.00000","1.86406","5360.19043","0.01864","536.01904","0.00001"
"56.20000","1.87055","5375.08496","0.01871","537.50848","0.00001"
"56.40000","1.87734","5392.10010","0.01877","539.21002","0.00000"
"56.60000","1.88403","5408.29199","0.01884","540.82922","0.00000"
"56.80000","1.89067","5423.54932","0.01891","542.35492","0.00001"
"57.00000","1.89737","5439.96631","0.01897","543.99664","0.00000"
"57.20000","1.90396","5455.23682","0.01904","545.52368","0.00000"
"57.40000","1.91066","5471.28662","0.01911","547.12866","0.00000"
"57.60000","1.91717","5486.22559","0.01917","548.62256","0.00001"
"57.80000","1.92407","5503.55518","0.01924","550.35553","0.00001"
"58.00000","1.93069","5519.62207","0.01931","551.96222","0.00000"
"58.20000","1.93728","5535.04785","0.01937","553.50476","0.00000"
"58.40000","1.94414","5552.62109","0.01944","555.26208","0.00000"
"58.60000","1.95058","5567.16895","0.01951","556.71692","0.00001"
"58.80000","1.95732","5583.55811","0.01957","558.35583","0.00000"
"59.00000","1.96394","5599.24707","0.01964","559.92468","0.00000"
"59.20000","1.97069","5616.04932","0.01971","561.60492","0.00000"
"59.40000","1.97733","5631.87744","0.01977","563.18774","0.00000"
"59.60000","1.98399","5647.51953","0.01984","564.75195","0.00001"
"59.80000","1.99072","5663.54004","0.01991","566.35400","0.00000"
"60.00000","1.99717","5678.00342","0.01997","567.80035","0.00000"
"60.20000","2.00412","5695.98096","0.02004","569.59808","0.00000"
"60.40000","2.01069","5711.36768","0.02011","571.13678","0.00000"
"60.60000","2.01727","5726.64551","0.02017","572.66455","0.00001"
"60.80000","2.02403","5743.58496","0.02024","574.35852","0.00001"
"61.00000","2.03058","5758.82812","0.02031","575.88281","0.00000"
"61.20000","2.03732","5775.13916","0.02037","577.51392","0.00000"
"61.40000","2.04397","5790.86670","0.02044","579.08667","0.00000"
"61.60000","2.05075","5807.16650","0.02051","580.71667","0.00001"
"61.80000","2.05729","5822.09180","0.02057","582.20917","0.00001"
"62.00000","2.06397","5837.63281","0.02064","583.76331","0.00000"
"62.20000","2.07074","5854.06104","0.02071","585.40613","0.00000"
"62.40000","2.07720","5868.41748","0.02077","586.84174","0.00001"
"62.60000","2.08402","5885.06152","0.02084","588.50616","0.00000"
"62.80000","2.09066","5900.48828","0.02091","590.04883","0.00000"
"63.00000","2.09726","5915.14453","0.02097","591.51447","0.00000"
"63.20000","2.10408","5932.38086","0.02104","593.23810","0.00000"
"63.40000","2.11060","5947.24756","0.02111","594.72473","0.00001"
"63.60000","2.11734","5963.40674","0.02117","596.34070","0.00001"
"63.80000","2.12392","5978.43896","0.02124","597.84387","0.00000"
"64.00000","2.13079","5995.48975","0.02131","599.54895","0.00000"
"64.20000","2.13729","6009.60547","0.02137","600.96057","0.00000"
"64.40000","2.14385","6024.49121","0.02144","602.44910","0.00001"
"64.60000","2.15073","6041.46680","0.02151","604.14667","0.00001"
"64.80000","2.15719","6055.60840","0.02157","605.56085","0.00000"
"65.00000","2.16400","6072.00098","0.02164","607.20007","-0.00001"
"65.20000","2.17064","6087.43262","0.02171","608.74329","0.00001"
"65.40000","2.17740","6103.36523","0.02177","610.33655","0.00001"
"65.60000","2.18406","6118.83838","0.02184","611.88385","0.00000"
"65.80000","2.19057","6133.17773","0.02191","613.31775","0.00000"
"66.00000","2.19730","6149.14014","0.02197","614.91400","0.00000"
"66.20000","2.20385","6164.00195","0.02204","616.40021","0.00001"
"66.40000","2.21074","6180.83643","0.02211","618.08362","0.00001"
"66.60000","2.21728","6195.60693","0.02217","619.56067","0.00000"
"66.80000","2.22401","6211.36182","0.02224","621.13617","0.00000"
"67.00000","2.23072","6227.12061","0.02231","622.71204","0.00000"
"67.20000","2.23725","6241.60840","0.02237","624.16083","0.00001"
"67.40000","2.24401","6257.97217","0.02244","625.79724","0.00001"
"67.60000","2.25055","6272.49268","0.02251","627.24927","0.00000"
"67.80000","2.25743","6289.23047","0.02257","628.92303","0.00000"
"68.00000","2.26392","6303.62939","0.02264","630.36292","0.00001"
"68.20000","2.27054","6318.67285","0.02271","631.86731","0.00001"
"68.40000","2.27736","6335.13721","0.02277","633.51373","0.00000"
"68.60000","2.28392","6349.36377","0.02284","634.93640","0.00000"
"68.80000","2.29068","6365.02783","0.02291","636.50281","0.00000"
"69.00000","2.29732","6379.52979","0.02297","637.95300","0.00001"
"69.20000","2.30400","6394.29834","0.02304","639.42981","0.00001"
"69.40000","2.31077","6410.29395","0.02311","641.02942","0.00000"
"69.60000","2.31729","6424.48291","0.02317","642.44830","0.00000"
"69.80000","2.32392","6439.27686","0.02324","643.92767","0.00000"
"70.00000","2.33056","6454.34863","0.02331","645.43488","0.00001"
"70.20000","2.33740","6470.06982","0.02337","647.00696","0.00000"
"70.40000","2.34405","6485.31396","0.02344","648.53137","0.00000"
"70.60000","2.35055","6499.29443","0.02351","649.92944","0.00000"
"70.80000","2.35744","6516.09961","0.02357","651.60999","0.00000"
"71.00000","2.36390","6530.12598","0.02364","653.01257","0.00001"
"71.20000","2.37067","6546.03467","0.02371","654.60345","0.00000"
"71.40000","2.37730","6561.51318","0.02377","656.15131","0.00000"
"71.60000","2.38399","6576.94482","0.02384","657.69446","0.00000"
"71.80000","2.39070","6592.26025","0.02391","659.22601","0.00001"
"72.00000","2.39724","6606.59277","0.02397","660.65930","0.00001"
"72.20000","2.40406","6622.80762","0.02404","662.28076","0.00000"
"72.40000","2.41052","6636.71191","0.02411","663.67120","0.00000"
"72.60000","2.41738","6653.65527","0.02417","665.36554","0.00001"
"72.80000","2.42397","6668.36523","0.02424","666.83655","0.00001"
"73.00000","2.43059","6682.29248","0.02431","668.22925","0.00001"
"73.20000","2.43748","6698.25537","0.02437","669.82556","0.00000"
"73.40000","2.44392","6710.80859","0.02444","671.08087","-0.00001"
"73.60000","2.45058","6725.36621","0.02451","672.53662","0.00000"
"73.80000","2.45723","6740.20947","0.02457","674.02094","0.00001"
"74.00000","2.46413","6756.00830","0.02464","675.60083","0.00000"
"74.20000","2.47061","6769.89795","0.02471","676.98981","0.00000"
"74.40000","2.47725","6784.82666","0.02477","678.48267","0.00000"
"74.60000","2.48403","6800.57568","0.02484","680.05756","0.00001"
"74.80000","2.49054","6814.42334","0.02491","681.44232","0.00001"
"75.00000","2.49746","6830.94873","0.02497","683.09485","0.00000"
"75.20000","2.50394","6844.78369","0.02504","684.47839","0.00000"
"75.40000","2.51063","6859.39258","0.02511","685.93927","0.00000"
"75.60000","2.51735","6874.74023","0.02517","687.47400","0.00001"
"75.80000","2.52398","6889.54980","0.02524","688.95496","0.00001"
"76.00000","2.53059","6904.28174","0.02531","690.42816","0.00000"
"76.20000","2.53724","6919.27148","0.02537","691.92712","-0.00001"
"76.40000","2.54407","6935.02734","0.02544","693.50275","0.00000"
"76.60000","2.55068","6949.02979","0.02551","694.90295","0.00001"
"76.80000","2.55728","6962.77490","0.02557","696.27747","0.00000"
"77.00000","2.56410","6978.28906","0.02564","697.82892","0.00000"
"77.20000","2.57057","6991.34717","0.02571","699.13470","0.00000"
"77.40000","2.57732","7005.14893","0.02577","700.51489","0.00001"
"77.60000","2.58400","7019.82910","0.02584","701.98291","0.00001"
"77.80000","2.59065","7034.35596","0.02591","703.43561","0.00000"
"78.00000","2.59733","7049.07861","0.02597","704.90784","0.00000"
"78.20000","2.60389","7062.86719","0.02604","706.28674","0.00000"
"78.40000","2.61071","7078.08008","0.02611","707.80798","0.00001"
"78.60000","2.61728","7091.16016","0.02617","709.11603","0.00000"
"78.80000","2.62415","7105.04639","0.02624","710.50464","0.00000"
"79.00000","2.63068","7118.66846","0.02631","711.86682","0.00000"
"79.20000","2.63722","7130.68262","0.02637","713.06824","0.00000"
"79.40000","2.64412","7143.83496","0.02644","714.38348","0.00001"
"79.56600","2.64941","6974.50732","0.02649","697.45074","0.00000"
"79.57000","2.64955","6526.57959","0.02650","652.65796","0.00000"
"79.57200","2.64963","6213.80713","0.02650","621.38074","0.00000"
"79.57400","2.64970","5861.75049","0.02650","586.17505","0.00001"
"79.57600","2.64979","5481.94287","0.02650","548.19427","0.00002"
"79.57800","2.64987","5084.41846","0.02650","508.44183","0.00004"
"79.58000","2.64997","4677.73828","0.02650","467.77383","0.00005"
"79.58200","2.65008","4269.19287","0.02650","426.91928","0.00007"