File: Tension/Section_2_Group_2/hybrid_high_Sample_2redone.is_tens_RawData/Specimen_RawData_1.csv
Time,Extension,Load,Tensile strain (Extension),Tensile stress,Strain-by-clip-gage
(s),(mm),(N),(mm/mm),(MPa),(mm/mm)
"0.00000","0.00000","247.43324","0.00000","24.74332","-0.00004"
"0.10000","0.00052","250.70132","0.00001","25.07013","-0.00005"
"0.20000","0.00252","266.19550","0.00003","26.61955","-0.00004"
"0.30000","0.00739","304.57437","0.00007","30.45744","-0.00005"
"0.40000","0.01077","329.79752","0.00011","32.97975","-0.00004"
"0.50000","0.01413","354.63010","0.00014","35.46301","-0.00004"
"0.60000","0.01756","379.37039","0.00018","37.93704","-0.00006"
"0.70000","0.02087","403.08597","0.00021","40.30860","-0.00004"
"0.80000","0.02404","425.73199","0.00024","42.57320","-0.00005"
"0.90000","0.02757","450.91943","0.00028","45.09194","-0.00005"
"1.00000","0.03085","473.88086","0.00031","47.38808","-0.00004"
"1.10000","0.03413","496.58362","0.00034","49.65836","-0.00005"
"1.20000","0.03748","519.80121","0.00037","51.98012","-0.00004"
"1.30000","0.04084","542.99341","0.00041","54.29934","-0.00006"
"1.40000","0.04417","565.54407","0.00044","56.55441","-0.00005"
"1.50000","0.04747","588.11169","0.00047","58.81117","-0.00005"
"1.60000","0.05099","611.81848","0.00051","61.18185","-0.00005"
"1.70000","0.05435","634.36597","0.00054","63.43660","-0.00005"
"1.80000","0.05748","654.68835","0.00057","65.46883","-0.00005"
"1.90000","0.06086","676.96454","0.00061","67.69646","-0.00005"
"2.00000","0.06411","698.05603","0.00064","69.80560","-0.00005"
"2.10000","0.06749","720.15546","0.00067","72.01555","-0.00005"
"2.20000","0.07072","740.80029","0.00071","74.08003","-0.00005"
"2.30000","0.07425","763.53223","0.00074","76.35323","-0.00005"
"2.40000","0.07765","785.08844","0.00078","78.50884","-0.00005"
"2.50000","0.08075","804.03278","0.00081","80.40327","-0.00005"
"2.60000","0.08414","825.38080","0.00084","82.53808","-0.00005"
"2.70000","0.08751","846.06195","0.00088","84.60619","-0.00005"
"2.80000","0.09080","866.19641","0.00091","86.61964","-0.00005"
"2.90000","0.09412","886.36456","0.00094","88.63646","-0.00005"
"3.00000","0.09756","907.39532","0.00098","90.73953","-0.00005"
"3.10000","0.10097","927.92755","0.00101","92.79276","-0.00005"
"3.20000","0.10407","946.30737","0.00104","94.63074","-0.00005"
"3.30000","0.10757","967.69769","0.00108","96.76977","-0.00005"
"3.40000","0.11093","987.83051","0.00111","98.78305","-0.00005"
"3.50000","0.11422","1007.41254","0.00114","100.74126","-0.00005"
"3.60000","0.11746","1026.45496","0.00117","102.64549","-0.00005"
"3.70000","0.12088","1046.78601","0.00121","104.67860","-0.00005"
"3.80000","0.12423","1066.60608","0.00124","106.66061","-0.00005"
"3.90000","0.12738","1084.74036","0.00127","108.47404","-0.00005"
"4.00000","0.13088","1105.50500","0.00131","110.55050","-0.00005"
"4.10000","0.13424","1125.09778","0.00134","112.50978","-0.00005"
"4.20000","0.13754","1144.04272","0.00138","114.40427","-0.00005"
"4.30000","0.14085","1162.96277","0.00141","116.29628","-0.00005"
"4.40000","0.14410","1181.45398","0.00144","118.14540","-0.00005"
"4.50000","0.14749","1200.95850","0.00147","120.09585","-0.00005"
"4.60000","0.15075","1219.48901","0.00151","121.94890","-0.00005"
"4.70000","0.15425","1239.72083","0.00154","123.97208","-0.00005"
"4.80000","0.15758","1258.78491","0.00158","125.87849","-0.00005"
"4.90000","0.16083","1277.05237","0.00161","127.70524","-0.00005"
"5.00000","0.16419","1296.26074","0.00164","129.62607","-0.00005"
"5.10000","0.16751","1314.78247","0.00168","131.47824","-0.00004"
"5.20000","0.17084","1333.53687","0.00171","133.35368","-0.00005"
"5.30000","0.17415","1352.31543","0.00174","135.23154","-0.00005"
"5.40000","0.17761","1371.96851","0.00178","137.19685","-0.00005"
"5.50000","0.18094","1390.96509","0.00181","139.09651","-0.00005"
"5.60000","0.18416","1408.80896","0.00184","140.88089","-0.00004"
"5.70000","0.18749","1427.79858","0.00187","142.77986","-0.00005"
"5.80000","0.19081","1446.43713","0.00191","144.64371","-0.00004"
"5.90000","0.19414","1465.47388","0.00194","146.54739","-0.00005"
"6.00000","0.19752","1485.02063","0.00198","148.50206","-0.00005"
"6.10000","0.20093","1504.55090","0.00201","150.45509","-0.00005"
"6.20000","0.20420","1523.10132","0.00204","152.31013","-0.00005"
"6.30000","0.20741","1541.26465","0.00207","154.12646","-0.00004"
"6.40000","0.21085","1561.40381","0.00211","156.14038","-0.00005"
"6.50000","0.21418","1580.35547","0.00214","158.03555","-0.00005"
"6.60000","0.21744","1598.65710","0.00217","159.86571","-0.00005"
"6.70000","0.22087","1618.51965","0.00221","161.85196","-0.00005"
"6.80000","0.22425","1637.62329","0.00224","163.76233","-0.00005"
"6.90000","0.22757","1656.43469","0.00228","165.64346","-0.00005"
"7.00000","0.23077","1674.15222","0.00231","167.41522","-0.00005"
"7.10000","0.23428","1694.52429","0.00234","169.45242","-0.00005"
"7.20000","0.23766","1713.60425","0.00238","171.36043","-0.00005"
"7.30000","0.24080","1730.67603","0.00241","173.06760","-0.00005"
"7.40000","0.24420","1750.40295","0.00244","175.04030","-0.00005"
"7.50000","0.24749","1768.76575","0.00247","176.87657","-0.00005"
"7.60000","0.25081","1787.31702","0.00251","178.73170","-0.00005"
"7.70000","0.25405","1805.58789","0.00254","180.55879","-0.00006"
"7.80000","0.25762","1826.76685","0.00258","182.67668","-0.00005"
"7.90000","0.26096","1845.61707","0.00261","184.56171","-0.00004"
"8.00000","0.26411","1862.80383","0.00264","186.28038","-0.00005"
"8.10000","0.26749","1882.06616","0.00267","188.20662","-0.00005"
"8.20000","0.27081","1900.54321","0.00271","190.05432","-0.00006"
"8.30000","0.27414","1919.31555","0.00274","191.93155","-0.00005"
"8.40000","0.27738","1937.18579","0.00277","193.71858","-0.00004"
"8.50000","0.28103","1958.56555","0.00281","195.85655","-0.00005"
"8.60000","0.28429","1976.46509","0.00284","197.64651","-0.00005"
"8.70000","0.28748","1993.85303","0.00287","199.38530","-0.00005"
"8.80000","0.29089","2013.21436","0.00291","201.32144","-0.00005"
"8.90000","0.29412","2030.92505","0.00294","203.09250","-0.00005"
"9.00000","0.29754","2050.37695","0.00298","205.03769","-0.00004"
"9.10000","0.30076","2068.17896","0.00301","206.81790","-0.00005"
"9.20000","0.30429","2088.73218","0.00304","208.87321","-0.00005"
"9.30000","0.30762","2107.52051","0.00308","210.75204","-0.00005"
"9.40000","0.31074","2124.35474","0.00311","212.43547","-0.00005"
"9.50000","0.31420","2144.21240","0.00314","214.42123","-0.00004"
"9.60000","0.31757","2163.41382","0.00318","216.34138","-0.00005"
"9.70000","0.32080","2181.01685","0.00321","218.10168","-0.00004"
"9.80000","0.32413","2199.80615","0.00324","219.98062","-0.00006"
"9.90000","0.32757","2219.55615","0.00328","221.95561","-0.00005"
"10.00000","0.33083","2237.65137","0.00331","223.76514","-0.00005"
"10.10000","0.33407","2255.57764","0.00334","225.55777","-0.00005"
"10.20000","0.33752","2275.51562","0.00338","227.55156","-0.00004"
"10.30000","0.34098","2295.18652","0.00341","229.51865","-0.00005"
"10.40000","0.34418","2312.53296","0.00344","231.25330","-0.00005"
"10.50000","0.34747","2331.02759","0.00347","233.10275","-0.00005"
"10.60000","0.35091","2350.62109","0.00351","235.06210","-0.00005"
"10.70000","0.35416","2368.37329","0.00354","236.83733","-0.00004"
"10.80000","0.35747","2386.79907","0.00357","238.67990","-0.00005"
"10.90000","0.36095","2406.89355","0.00361","240.68936","-0.00004"
"11.00000","0.36436","2425.92749","0.00364","242.59274","-0.00005"
"11.10000","0.36748","2442.49243","0.00367","244.24924","-0.00005"
"11.20000","0.37086","2461.57324","0.00371","246.15732","-0.00005"
"11.30000","0.37406","2478.85474","0.00374","247.88547","-0.00005"
"11.40000","0.37750","2498.50146","0.00377","249.85014","-0.00004"
"11.50000","0.38080","2516.83740","0.00381","251.68375","-0.00006"
"11.60000","0.38422","2536.38599","0.00384","253.63860","-0.00005"
"11.70000","0.38761","2555.69116","0.00388","255.56912","-0.00005"
"11.80000","0.39075","2572.35303","0.00391","257.23529","-0.00005"
"11.90000","0.39418","2592.00073","0.00394","259.20007","-0.00005"
"12.00000","0.39746","2609.88379","0.00397","260.98837","-0.00005"
"12.10000","0.40084","2628.93433","0.00401","262.89343","-0.00004"
"12.20000","0.40421","2647.80298","0.00404","264.78030","-0.00006"
"12.30000","0.40765","2667.22803","0.00408","266.72281","-0.00005"
"12.40000","0.41095","2685.24316","0.00411","268.52432","-0.00005"
"12.50000","0.41409","2701.88184","0.00414","270.18817","-0.00005"
"12.60000","0.41763","2722.28931","0.00418","272.22894","-0.00005"
"12.70000","0.42081","2739.35254","0.00421","273.93524","-0.00006"
"12.80000","0.42421","2758.58154","0.00424","275.85815","-0.00004"
"12.90000","0.42749","2776.47217","0.00427","277.64722","-0.00006"
"13.00000","0.43087","2795.57056","0.00431","279.55707","-0.00005"
"13.10000","0.43413","2813.30688","0.00434","281.33069","-0.00005"
"13.20000","0.43741","2831.36377","0.00437","283.13638","-0.00005"
"13.30000","0.44095","2851.88696","0.00441","285.18869","-0.00005"
"13.40000","0.44422","2869.77954","0.00444","286.97797","-0.00005"
"13.50000","0.44749","2887.66968","0.00447","288.76697","-0.00005"
"13.60000","0.45085","2906.48950","0.00451","290.64896","-0.00005"
"13.70000","0.45420","2924.79126","0.00454","292.47913","-0.00005"
"13.80000","0.45743","2942.03467","0.00457","294.20346","-0.00005"
"13.90000","0.46076","2960.51123","0.00461","296.05112","-0.00005"
"14.00000","0.46427","2980.70386","0.00464","298.07037","-0.00005"
"14.10000","0.46765","2999.37158","0.00468","299.93716","-0.00005"
"14.20000","0.47084","3016.34741","0.00471","301.63474","-0.00005"
"14.30000","0.47415","3034.49805","0.00474","303.44980","-0.00006"
"14.40000","0.47760","3054.11670","0.00478","305.41168","-0.00005"
"14.50000","0.48076","3070.86084","0.00481","307.08609","-0.00005"
"14.60000","0.48416","3090.15430","0.00484","309.01544","-0.00004"
"14.70000","0.48757","3109.11914","0.00488","310.91193","-0.00005"
"14.80000","0.49095","3127.95386","0.00491","312.79538","-0.00005"
"14.90000","0.49406","3144.07715","0.00494","314.40771","-0.00005"
"15.00000","0.49758","3164.38452","0.00498","316.43845","-0.00005"
"15.10000","0.50083","3181.61035","0.00501","318.16104","-0.00004"
"15.20000","0.50411","3199.39355","0.00504","319.93936","-0.00005"
"15.30000","0.50750","3218.49365","0.00507","321.84937","-0.00004"
"15.40000","0.51091","3237.34033","0.00511","323.73404","-0.00005"
"15.50000","0.51428","3256.03369","0.00514","325.60336","-0.00005"
"15.60000","0.51734","3271.83716","0.00517","327.18372","-0.00005"
"15.70000","0.52094","3293.05615","0.00521","329.30560","-0.00005"
"15.80000","0.52419","3310.26758","0.00524","331.02676","-0.00004"
"15.90000","0.52747","3327.93921","0.00527","332.79391","-0.00005"
"16.00000","0.53089","3347.41577","0.00531","334.74158","-0.00005"
"16.10000","0.53417","3364.93921","0.00534","336.49393","-0.00005"
"16.20000","0.53766","3384.81250","0.00538","338.48126","-0.00005"
"16.30000","0.54070","3400.30640","0.00541","340.03064","-0.00004"
"16.40000","0.54437","3421.94922","0.00544","342.19492","-0.00005"
"16.50000","0.54760","3439.00317","0.00548","343.90033","-0.00004"
"16.60000","0.55082","3455.99365","0.00551","345.59937","-0.00005"
"16.70000","0.55411","3474.06372","0.00554","347.40637","-0.00005"
"16.80000","0.55749","3492.65674","0.00557","349.26569","-0.00005"
"16.90000","0.56086","3510.99438","0.00561","351.09943","-0.00005"
"17.00000","0.56402","3527.91553","0.00564","352.79156","-0.00004"
"17.10000","0.56759","3548.61572","0.00568","354.86157","-0.00005"
"17.20000","0.57098","3567.18872","0.00571","356.71887","-0.00004"
"17.30000","0.57414","3583.62354","0.00574","358.36237","-0.00005"
"17.40000","0.57747","3602.02563","0.00577","360.20258","-0.00005"
"17.50000","0.58083","3620.16235","0.00581","362.01624","-0.00005"
"17.60000","0.58415","3638.13525","0.00584","363.81354","-0.00005"
"17.70000","0.58744","3656.17920","0.00587","365.61792","-0.00004"
"17.80000","0.59101","3676.43506","0.00591","367.64349","-0.00005"
"17.90000","0.59429","3693.95093","0.00594","369.39508","-0.00004"
"18.00000","0.59753","3711.30151","0.00598","371.13016","-0.00005"
"18.10000","0.60082","3729.16748","0.00601","372.91675","-0.00005"
"18.20000","0.60424","3748.09253","0.00604","374.80927","-0.00005"
"18.30000","0.60744","3764.87524","0.00607","376.48752","-0.00005"
"18.40000","0.61081","3783.68677","0.00611","378.36868","-0.00005"
"18.50000","0.61419","3802.11499","0.00614","380.21149","-0.00005"
"18.60000","0.61759","3820.91211","0.00618","382.09122","-0.00004"
"18.70000","0.62076","3837.21191","0.00621","383.72119","-0.00006"
"18.80000","0.62418","3855.99854","0.00624","385.59985","-0.00005"
"18.90000","0.62751","3874.11035","0.00628","387.41104","-0.00005"
"19.00000","0.63082","3891.85474","0.00631","389.18549","-0.00005"
"19.10000","0.63419","3910.24951","0.00634","391.02496","-0.00004"
"19.20000","0.63751","3928.03882","0.00638","392.80389","-0.00005"
"19.30000","0.64085","3946.02539","0.00641","394.60254","-0.00004"
"19.40000","0.64409","3963.21191","0.00644","396.32120","-0.00005"
"19.50000","0.64764","3983.22388","0.00648","398.32239","-0.00005"
"19.60000","0.65095","4000.88281","0.00651","400.08829","-0.00005"
"19.70000","0.65414","4017.54053","0.00654","401.75406","-0.00005"
"19.80000","0.65760","4036.81958","0.00658","403.68195","-0.00004"
"19.90000","0.66077","4053.09985","0.00661","405.31000","-0.00005"
"20.00000","0.66421","4072.19800","0.00664","407.21979","-0.00004"
"20.10000","0.66743","4089.03174","0.00667","408.90317","-0.00005"
"20.20000","0.67095","4108.94043","0.00671","410.89404","-0.00005"
"20.30000","0.67424","4126.22949","0.00674","412.62296","-0.00005"
"20.40000","0.67748","4143.18066","0.00677","414.31805","-0.00005"
"20.50000","0.68091","4161.93359","0.00681","416.19336","-0.00005"
"20.60000","0.68408","4178.11084","0.00684","417.81110","-0.00005"
"20.70000","0.68743","4196.18896","0.00687","419.61890","-0.00004"
"20.80000","0.69079","4214.54102","0.00691","421.45410","-0.00006"
"20.90000","0.69429","4233.88574","0.00694","423.38858","-0.00005"
"21.00000","0.69755","4251.10107","0.00698","425.11011","-0.00005"
"21.10000","0.70075","4267.79932","0.00701","426.77994","-0.00005"
"21.20000","0.70419","4286.70068","0.00704","428.67007","-0.00004"
"21.30000","0.70754","4304.51904","0.00708","430.45190","-0.00005"
"21.40000","0.71081","4321.59473","0.00711","432.15948","-0.00004"
"21.50000","0.71416","4339.61768","0.00714","433.96176","-0.00006"
"21.60000","0.71770","4359.42139","0.00718","435.94214","-0.00004"
"21.70000","0.72089","4375.50635","0.00721","437.55063","-0.00005"
"21.80000","0.72414","4392.55908","0.00724","439.25592","-0.00005"
"21.90000","0.72754","4411.16162","0.00728","441.11615","-0.00004"
"22.00000","0.73088","4428.93408","0.00731","442.89340","-0.00006"
"22.10000","0.73410","4445.58740","0.00734","444.55875","-0.00004"
"22.20000","0.73751","4464.35303","0.00738","446.43530","-0.00005"
"22.30000","0.74088","4482.24072","0.00741","448.22406","-0.00004"
"22.40000","0.74415","4499.37549","0.00744","449.93756","-0.00005"
"22.50000","0.74736","4516.08057","0.00747","451.60806","-0.00005"
"22.60000","0.75095","4536.56299","0.00751","453.65631","-0.00005"
"22.70000","0.75426","4553.73486","0.00754","455.37347","-0.00005"
"22.80000","0.75744","4569.62598","0.00757","456.96259","-0.00004"
"22.90000","0.76083","4588.25439","0.00761","458.82544","-0.00005"
"23.00000","0.76416","4605.26025","0.00764","460.52603","-0.00005"
"23.10000","0.76749","4622.84033","0.00767","462.28403","-0.00005"
"23.20000","0.77081","4640.45947","0.00771","464.04596","-0.00005"
"23.30000","0.77434","4659.95703","0.00774","465.99570","-0.00005"
"23.40000","0.77770","4677.81006","0.00778","467.78101","-0.00005"
"23.50000","0.78077","4692.61719","0.00781","469.26172","-0.00004"
"23.60000","0.78420","4711.44873","0.00784","471.14487","-0.00005"
"23.70000","0.78744","4728.12402","0.00787","472.81241","-0.00005"
"23.80000","0.79084","4746.44482","0.00791","474.64447","-0.00005"
"23.90000","0.79410","4763.45166","0.00794","476.34515","-0.00005"
"24.00000","0.79766","4783.11719","0.00798","478.31171","-0.00004"
"24.10000","0.80100","4800.41553","0.00801","480.04156","-0.00005"
"24.20000","0.80407","4815.20020","0.00804","481.52002","-0.00005"
"24.30000","0.80750","4833.83887","0.00807","483.38388","-0.00005"
"24.40000","0.81088","4851.60449","0.00811","485.16046","-0.00005"
"24.50000","0.81414","4868.36719","0.00814","486.83673","-0.00005"
"24.60000","0.81744","4885.63477","0.00817","488.56348","-0.00005"
"24.70000","0.82090","4904.11621","0.00821","490.41162","-0.00005"
"24.80000","0.82426","4921.71436","0.00824","492.17145","-0.00005"
"24.90000","0.82742","4937.39795","0.00827","493.73981","-0.00005"
"25.00000","0.83093","4956.73926","0.00831","495.67392","-0.00005"
"25.10000","0.83429","4974.25439","0.00834","497.42545","-0.00004"
"25.20000","0.83753","4990.66211","0.00838","499.06622","-0.00005"
"25.30000","0.84081","5007.51562","0.00841","500.75156","-0.00005"
"25.40000","0.84425","5025.68408","0.00844","502.56842","-0.00005"
"25.50000","0.84751","5041.93066","0.00848","504.19305","-0.00005"
"25.60000","0.85075","5058.46484","0.00851","505.84650","-0.00005"
"25.70000","0.85425","5077.34814","0.00854","507.73480","-0.00005"
"25.80000","0.85760","5094.87988","0.00858","509.48798","-0.00005"
"25.90000","0.86084","5111.05859","0.00861","511.10587","-0.00005"
"26.00000","0.86415","5128.08984","0.00864","512.80896","-0.00005"
"26.10000","0.86746","5145.13574","0.00867","514.51355","-0.00005"
"26.20000","0.87081","5162.44531","0.00871","516.24451","-0.00005"
"26.30000","0.87407","5179.12305","0.00874","517.91229","-0.00005"
"26.40000","0.87761","5198.51904","0.00878","519.85193","-0.00005"
"26.50000","0.88092","5215.53760","0.00881","521.55377","-0.00004"
"26.60000","0.88413","5231.20898","0.00884","523.12091","-0.00005"
"26.70000","0.88755","5248.96631","0.00888","524.89661","-0.00005"
"26.80000","0.89085","5265.35547","0.00891","526.53552","-0.00005"
"26.90000","0.89417","5282.14746","0.00894","528.21472","-0.00006"
"27.00000","0.89753","5299.47949","0.00898","529.94794","-0.00005"
"27.10000","0.90098","5317.49023","0.00901","531.74902","-0.00005"
"27.20000","0.90431","5334.37891","0.00904","533.43787","-0.00004"
"27.30000","0.90744","5348.99268","0.00907","534.89929","-0.00005"
"27.40000","0.91084","5366.61572","0.00911","536.66156","-0.00005"
"27.50000","0.91414","5383.01465","0.00914","538.30145","-0.00005"
"27.60000","0.91745","5399.73291","0.00917","539.97327","-0.00005"
"27.70000","0.92088","5417.66309","0.00921","541.76630","-0.00005"
"27.80000","0.92423","5434.56250","0.00924","543.45624","-0.00005"
"27.90000","0.92751","5450.83398","0.00928","545.08337","-0.00004"
"28.00000","0.93073","5466.45020","0.00931","546.64502","-0.00005"
"28.10000","0.93421","5484.89404","0.00934","548.48938","-0.00005"
"28.20000","0.93755","5501.57910","0.00938","550.15790","-0.00005"
"28.30000","0.94074","5516.86719","0.00941","551.68671","-0.00005"
"28.40000","0.94420","5535.00537","0.00944","553.50055","-0.00004"
"28.50000","0.94758","5551.97998","0.00948","555.19800","-0.00006"
"28.60000","0.95088","5568.11914","0.00951","556.81189","-0.00005"
"28.70000","0.95410","5583.69385","0.00954","558.36938","-0.00005"
"28.80000","0.95760","5602.00195","0.00958","560.20020","-0.00005"
"28.90000","0.96100","5619.03711","0.00961","561.90369","-0.00004"
"29.00000","0.96413","5633.60840","0.00964","563.36084","-0.00005"
"29.10000","0.96754","5650.92090","0.00968","565.09210","-0.00005"
"29.20000","0.97083","5666.59473","0.00971","566.65948","-0.00005"
"29.30000","0.97412","5682.40674","0.00974","568.24066","-0.00005"
"29.40000","0.97740","5698.55957","0.00977","569.85596","-0.00005"
"29.50000","0.98102","5717.78955","0.00981","571.77893","-0.00005"
"29.60000","0.98430","5733.40527","0.00984","573.34052","-0.00005"
"29.70000","0.98742","5747.56738","0.00987","574.75671","-0.00005"
"29.80000","0.99086","5764.97803","0.00991","576.49780","-0.00005"
"29.90000","0.99412","5780.21826","0.00994","578.02185","-0.00005"
"30.00000","0.99744","5796.30176","0.00997","579.63019","-0.00005"
"30.10000","1.00070","5812.16309","0.01001","581.21631","-0.00005"
"30.20000","1.00434","5831.54150","0.01004","583.15417","-0.00005"
"30.30000","1.00764","5847.24414","0.01008","584.72443","-0.00005"
"30.40000","1.01079","5861.45361","0.01011","586.14539","-0.00005"
"30.50000","1.01424","5878.83594","0.01014","587.88361","-0.00004"
"30.60000","1.01745","5893.51172","0.01017","589.35120","-0.00005"
"30.70000","1.02087","5910.28662","0.01021","591.02869","-0.00005"
"30.80000","1.02415","5926.12793","0.01024","592.61279","-0.00005"
"30.90000","1.02761","5943.16406","0.01028","594.31641","-0.00005"
"31.00000","1.03093","5959.27148","0.01031","595.92712","-0.00005"
"31.10000","1.03406","5972.90430","0.01034","597.29041","-0.00005"
"31.20000","1.03757","5990.75342","0.01038","599.07532","-0.00004"
"31.30000","1.04089","6006.35107","0.01041","600.63513","-0.00006"
"31.40000","1.04414","6021.16699","0.01044","602.11670","-0.00005"
"31.50000","1.04746","6037.10254","0.01047","603.71027","-0.00005"
"31.60000","1.05090","6053.82764","0.01051","605.38275","-0.00005"
"31.70000","1.05415","6068.62842","0.01054","606.86285","-0.00005"
"31.80000","1.05737","6083.45459","0.01057","608.34546","-0.00005"
"31.90000","1.06090","6101.28760","0.01061","610.12878","-0.00005"
"32.00000","1.06434","6117.99268","0.01064","611.79926","-0.00005"
"32.10000","1.06751","6131.87939","0.01068","613.18793","-0.00005"
"32.20000","1.07087","6147.76514","0.01071","614.77649","-0.00005"
"32.30000","1.07422","6163.25439","0.01074","616.32544","-0.00005"
"32.40000","1.07748","6177.88232","0.01077","617.78821","-0.00005"
"32.50000","1.08083","6193.37598","0.01081","619.33759","-0.00005"
"32.60000","1.08430","6210.43018","0.01084","621.04303","-0.00005"
"32.70000","1.08772","6226.49170","0.01088","622.64917","-0.00005"
"32.80000","1.09078","6239.09473","0.01091","623.90948","-0.00005"
"32.90000","1.09417","6254.88379","0.01094","625.48840","-0.00005"
"33.00000","1.09743","6269.50098","0.01097","626.95007","-0.00005"
"33.10000","1.10079","6284.93896","0.01101","628.49390","-0.00005"
"33.20000","1.10412","6300.17383","0.01104","630.01740","-0.00005"
"33.30000","1.10754","6316.48145","0.01108","631.64813","-0.00005"
"33.40000","1.11095","6332.41406","0.01111","633.24139","-0.00006"
"33.50000","1.11409","6345.49951","0.01114","634.54993","-0.00005"
"33.60000","1.11754","6361.92871","0.01118","636.19287","-0.00005"
"33.70000","1.12081","6376.25537","0.01121","637.62555","-0.00005"
"33.80000","1.12416","6391.26367","0.01124","639.12634","-0.00005"
"33.90000","1.12751","6406.68555","0.01128","640.66858","-0.00005"
"34.00000","1.13096","6422.77734","0.01131","642.27771","-0.00005"
"34.10000","1.13425","6437.51855","0.01134","643.75183","-0.00005"
"34.20000","1.13739","6450.57617","0.01137","645.05762","-0.00004"
"34.30000","1.14104","6468.87061","0.01141","646.88708","-0.00005"
"34.40000","1.14418","6481.81152","0.01144","648.18115","-0.00005"
"34.50000","1.14749","6496.49854","0.01147","649.64984","-0.00006"
"34.60000","1.15083","6511.62842","0.01151","651.16284","-0.00004"
"34.70000","1.15421","6526.76904","0.01154","652.67688","-0.00005"
"34.80000","1.15748","6540.68213","0.01157","654.06824","-0.00005"
"34.90000","1.16078","6555.06543","0.01161","655.50653","-0.00004"
"35.00000","1.16428","6571.27002","0.01164","657.12701","-0.00005"
"35.10000","1.16755","6585.02441","0.01168","658.50244","-0.00004"
"35.20000","1.17082","6598.91748","0.01171","659.89172","-0.00005"
"35.30000","1.17419","6613.74121","0.01174","661.37415","-0.00005"
"35.40000","1.17755","6628.20801","0.01178","662.82080","-0.00005"
"35.50000","1.18070","6640.54443","0.01181","664.05444","-0.00005"
"35.60000","1.18410","6655.80029","0.01184","665.58002","-0.00004"
"35.70000","1.18763","6672.20361","0.01188","667.22034","-0.00005"
"35.80000","1.19096","6686.44775","0.01191","668.64478","-0.00004"
"35.90000","1.19417","6699.59131","0.01194","669.95911","-0.00004"
"36.00000","1.19748","6713.79785","0.01197","671.37976","-0.00004"
"36.10000","1.20097","6729.62305","0.01201","672.96228","-0.00004"
"36.20000","1.20409","6741.54248","0.01204","674.15424","-0.00005"
"36.30000","1.20751","6757.17969","0.01208","675.71796","-0.00004"
"36.40000","1.21092","6772.06445","0.01211","677.20642","-0.00005"
"36.50000","1.21428","6786.37158","0.01214","678.63715","-0.00004"
"36.60000","1.21735","6797.85986","0.01217","679.78601","-0.00005"
"36.70000","1.22095","6814.85449","0.01221","681.48547","-0.00005"
"36.80000","1.22415","6826.97070","0.01224","682.69708","-0.00005"
"36.90000","1.22740","6840.01904","0.01227","684.00189","-0.00005"
"37.00000","1.23085","6854.63232","0.01231","685.46326","-0.00005"
"37.10000","1.23423","6867.62402","0.01234","686.76239","-0.00005"
"37.20000","1.23759","6881.40625","0.01238","688.14062","-0.00004"
"37.30000","1.24066","6892.61328","0.01241","689.26135","-0.00005"
"37.40000","1.24430","6909.58447","0.01244","690.95844","-0.00005"
"37.50000","1.24753","6921.70166","0.01248","692.17017","-0.00005"
"37.60000","1.25078","6934.16162","0.01251","693.41614","-0.00005"
"37.70000","1.25421","6949.02148","0.01254","694.90216","-0.00005"
"37.80000","1.25752","6962.07129","0.01258","696.20715","-0.00005"
"37.90000","1.26099","6977.03125","0.01261","697.70312","-0.00005"
"38.00000","1.26401","6987.17139","0.01264","698.71716","-0.00005"
"38.10000","1.26773","7004.80176","0.01268","700.48016","-0.00005"
"38.20000","1.27092","7016.73535","0.01271","701.67352","-0.00005"
"38.30000","1.27417","7028.22070","0.01274","702.82208","-0.00005"
"38.40000","1.27749","7040.77539","0.01277","704.07751","-0.00005"
"38.50000","1.28080","7048.78271","0.01281","704.87830","-0.00005"
"38.60000","1.28424","7061.92236","0.01284","706.19226","-0.00005"
"38.70000","1.28734","7072.57227","0.01287","707.25720","-0.00005"
"38.80000","1.29092","7087.97217","0.01291","708.79724","-0.00005"
"38.90000","1.29432","7101.08154","0.01294","710.10815","-0.00005"
"39.00000","1.29742","7111.63037","0.01297","711.16302","-0.00005"
"39.10000","1.30084","7125.42236","0.01301","712.54224","-0.00004"
"39.20000","1.30421","7138.21191","0.01304","713.82117","-0.00005"
"39.30000","1.30746","7150.11963","0.01307","715.01196","-0.00004"
"39.40000","1.31081","7163.19092","0.01311","716.31909","-0.00005"
"39.50000","1.31431","7177.46826","0.01314","717.74683","-0.00005"
"39.60000","1.31759","7189.18457","0.01318","718.91846","-0.00005"
"39.70000","1.32084","7201.21484","0.01321","720.12146","-0.00004"
"39.80000","1.32416","7213.64746","0.01324","721.36475","-0.00004"
"39.90000","1.32762","7227.39404","0.01328","722.73938","-0.00005"
"40.00000","1.33078","7237.95215","0.01331","723.79523","-0.00005"
"40.10000","1.33417","7251.21729","0.01334","725.12170","-0.00006"
"40.20000","1.33755","7263.56934","0.01338","726.35693","-0.00004"
"40.30000","1.34091","7276.24072","0.01341","727.62408","-0.00004"
"40.40000","1.34408","7286.74902","0.01344","728.67493","-0.00004"
"40.50000","1.34752","7300.00293","0.01348","730.00031","-0.00005"
"40.60000","1.35089","7312.70312","0.01351","731.27032","-0.00006"
"40.70000","1.35417","7323.94775","0.01354","732.39478","-0.00005"
"40.80000","1.35751","7336.11279","0.01358","733.61127","-0.00004"
"40.90000","1.36080","7347.50342","0.01361","734.75037","-0.00004"
"41.00000","1.36415","7359.77441","0.01364","735.97742","-0.00004"
"41.10000","1.36742","7371.34082","0.01367","737.13409","-0.00005"
"41.20000","1.37101","7385.98340","0.01371","738.59833","-0.00006"
"41.30000","1.37432","7397.69580","0.01374","739.76959","-0.00005"
"41.40000","1.37746","7406.94678","0.01377","740.69470","-0.00005"
"41.50000","1.38097","7420.68359","0.01381","742.06836","-0.00004"
"41.60000","1.38410","7430.00342","0.01384","743.00037","-0.00004"
"41.70000","1.38753","7442.82666","0.01388","744.28265","-0.00006"
"41.80000","1.39076","7453.55713","0.01391","745.35571","-0.00004"
"41.90000","1.39429","7467.16260","0.01394","746.71625","-0.00006"
"42.00000","1.39757","7477.87354","0.01398","747.78735","-0.00004"
"42.10000","1.40079","7488.11963","0.01401","748.81195","-0.00005"
"42.20000","1.40424","7500.38770","0.01404","750.03876","-0.00006"
"42.30000","1.40743","7509.18457","0.01407","750.91846","-0.00005"
"42.40000","1.41078","7519.91650","0.01411","751.99164","-0.00006"
"42.50000","1.41414","7529.85986","0.01414","752.98596","-0.00004"
"42.60000","1.41762","7541.38672","0.01418","754.13867","-0.00004"
"42.70000","1.42089","7550.02637","0.01421","755.00262","-0.00005"
"42.80000","1.42411","7557.94727","0.01424","755.79474","-0.00005"
"42.90000","1.42755","7569.01416","0.01428","756.90143","-0.00006"
"43.00000","1.43093","7580.07764","0.01431","758.00775","-0.00005"
"43.10000","1.43416","7589.62012","0.01434","758.96204","-0.00005"
"43.20000","1.43753","7600.78857","0.01438","760.07886","-0.00004"
"43.30000","1.44105","7612.79443","0.01441","761.27942","-0.00005"
"43.40000","1.44418","7620.58496","0.01444","762.05847","-0.00006"
"43.50000","1.44744","7630.46680","0.01447","763.04669","-0.00005"
"43.60000","1.45089","7642.19482","0.01451","764.21948","-0.00006"
"43.70000","1.45423","7652.82568","0.01454","765.28259","-0.00004"
"43.80000","1.45743","7661.89941","0.01457","766.18994","-0.00005"
"43.90000","1.46085","7673.66797","0.01461","767.36682","-0.00005"
"44.00000","1.46421","7683.97754","0.01464","768.39777","-0.00005"
"44.10000","1.46747","7693.59375","0.01467","769.35938","-0.00005"
"44.20000","1.47071","7702.94531","0.01471","770.29456","-0.00005"
"44.30000","1.47431","7715.99805","0.01474","771.59979","-0.00005"
"44.40000","1.47761","7725.88770","0.01478","772.58875","-0.00004"
"44.50000","1.48078","7733.96289","0.01481","773.39630","-0.00005"
"44.60000","1.48419","7745.02246","0.01484","774.50226","-0.00005"
"44.70000","1.48746","7754.01514","0.01487","775.40149","-0.00005"
"44.80000","1.49082","7764.64795","0.01491","776.46478","-0.00005"
"44.90000","1.49413","7774.86133","0.01494","777.48615","-0.00005"
"45.00000","1.49770","7787.77734","0.01498","778.77771","-0.00005"
"45.10000","1.50109","7798.45947","0.01501","779.84595","-0.00005"
"45.20000","1.50406","7804.87207","0.01504","780.48718","-0.00006"
"45.30000","1.50755","7816.38525","0.01508","781.63855","-0.00004"
"45.40000","1.51075","7824.45752","0.01511","782.44574","-0.00005"
"45.50000","1.51415","7835.07324","0.01514","783.50732","-0.00004"
"45.60000","1.51740","7843.97949","0.01517","784.39795","-0.00005"
"45.70000","1.52095","7855.88867","0.01521","785.58887","-0.00006"
"45.80000","1.52435","7866.05469","0.01524","786.60547","-0.00004"
"45.90000","1.52737","7870.90137","0.01527","787.09015","-0.00006"
"46.00000","1.53084","7880.14209","0.01531","788.01422","-0.00003"
"46.10000","1.53424","7887.96094","0.01534","788.79608","-0.00005"
"46.20000","1.53744","7894.38770","0.01537","789.43878","-0.00006"
"46.30000","1.54079","7904.03857","0.01541","790.40387","-0.00005"
"46.40000","1.54423","7914.40234","0.01544","791.44025","-0.00007"
"46.50000","1.54756","7922.42676","0.01548","792.24268","-0.00003"
"46.60000","1.55072","7928.63428","0.01551","792.86340","-0.00005"
"46.70000","1.55428","7940.15820","0.01554","794.01581","-0.00004"
"46.80000","1.55767","7949.90527","0.01558","794.99054","-0.00005"
"46.90000","1.56088","7958.15967","0.01561","795.81598","-0.00006"
"47.00000","1.56416","7967.16455","0.01564","796.71643","-0.00004"
"47.10000","1.56757","7977.14453","0.01568","797.71448","-0.00005"
"47.20000","1.57081","7985.43115","0.01571","798.54309","-0.00004"
"47.30000","1.57407","7994.41943","0.01574","799.44196","-0.00005"
"47.40000","1.57760","8005.91260","0.01578","800.59125","-0.00006"
"47.50000","1.58093","8015.37061","0.01581","801.53705","-0.00005"
"47.60000","1.58415","8023.68018","0.01584","802.36804","-0.00005"
"47.70000","1.58754","8033.67285","0.01588","803.36731","-0.00004"
"47.80000","1.59078","8042.26318","0.01591","804.22632","-0.00005"
"47.90000","1.59411","8051.22314","0.01594","805.12231","-0.00004"
"48.00000","1.59742","8060.31543","0.01597","806.03156","-0.00005"
"48.10000","1.60096","8071.62891","0.01601","807.16290","-0.00005"
"48.20000","1.60427","8080.30518","0.01604","808.03052","-0.00005"
"48.30000","1.60744","8086.57031","0.01607","808.65704","-0.00005"
"48.40000","1.61093","8095.49609","0.01611","809.54962","-0.00005"
"48.50000","1.61418","8102.54688","0.01614","810.25470","-0.00005"
"48.60000","1.61749","8110.83008","0.01617","811.08301","-0.00005"
"48.70000","1.62089","8119.82666","0.01621","811.98267","-0.00006"
"48.80000","1.62428","8128.68994","0.01624","812.86902","-0.00005"
"48.88300","1.62706","7997.29102","0.01627","799.72913","-0.00005"
"48.90400","1.62780","7867.72461","0.01628","786.77246","-0.00005"
"49.00400","1.63091","7786.42090","0.01631","778.64209","-0.00005"
"49.10400","1.63437","7782.69189","0.01634","778.26917","-0.00005"
"49.20400","1.63762","7782.97168","0.01638","778.29718","-0.00005"
"49.30400","1.64093","7786.80273","0.01641","778.68030","-0.00006"
"49.40400","1.64436","7793.31982","0.01644","779.33197","-0.00005"
"49.50400","1.64768","7799.31543","0.01648","779.93152","-0.00004"
"49.60400","1.65096","7805.29980","0.01651","780.52997","-0.00005"
"49.70400","1.65421","7780.83643","0.01654","778.08362","-0.00004"
"49.80400","1.65777","7687.24658","0.01658","768.72467","-0.00005"
"49.90400","1.66105","7690.26660","0.01661","769.02667","-0.00006"
"50.00400","1.66425","7650.45215","0.01664","765.04523","-0.00005"
"50.10400","1.66770","7657.82666","0.01668","765.78265","-0.00005"
"50.20400","1.67102","7664.52979","0.01671","766.45300","-0.00004"
"50.30400","1.67430","7671.17139","0.01674","767.11713","-0.00005"
"50.40400","1.67758","7673.32471","0.01678","767.33246","-0.00005"
"50.50400","1.68109","7681.03662","0.01681","768.10364","-0.00005"
"50.60400","1.68446","7690.00146","0.01684","769.00012","-0.00006"
"50.70400","1.68759","7693.42627","0.01688","769.34265","-0.00005"
"50.80400","1.69101","7703.25439","0.01691","770.32544","-0.00004"
"50.90400","1.69431","7712.19287","0.01694","771.21930","-0.00005"
"51.00400","1.69756","7721.03516","0.01698","772.10352","-0.00005"
"51.10400","1.70091","7730.31250","0.01701","773.03125","-0.00005"
"51.20400","1.70449","7741.77930","0.01704","774.17792","-0.00005"
"51.30400","1.70775","7750.74268","0.01708","775.07428","-0.00005"
"51.40400","1.71086","7758.99658","0.01711","775.89966","-0.00005"
"51.50400","1.71432","7706.15869","0.01714","770.61584","-0.00005"
"51.52800","1.71523","7580.43066","0.01715","758.04309","-0.00004"
"51.62800","1.71856","7528.04736","0.01719","752.80475","-0.00004"
"51.72800","1.72172","7498.53271","0.01722","749.85327","-0.00005"
"51.81000","1.72447","7372.04395","0.01724","737.20441","-0.00005"
"51.82200","1.72493","7240.21143","0.01725","724.02112","-0.00005"
"51.82700","1.72512","7106.97021","0.01725","710.69702","-0.00005"
"51.83200","1.72531","6959.10156","0.01725","695.91016","-0.00006"
"51.83700","1.72552","6812.45996","0.01726","681.24597","-0.00006"
"51.84200","1.72573","6677.55322","0.01726","667.75531","-0.00007"
"51.84800","1.72600","6539.26709","0.01726","653.92670","-0.00009"
"51.85600","1.72637","6399.92188","0.01726","639.99219","-0.00006"
"51.86900","1.72697","6272.08057","0.01727","627.20807","-0.00001"
"51.96900","1.73000","6215.52002","0.01730","621.55200","0.00004"
"52.06900","1.73311","6187.54492","0.01733","618.75452","-0.00001"
"52.16900","1.73653","6176.30908","0.01737","617.63092","-0.00007"
"52.26900","1.73976","6169.97510","0.01740","616.99750","-0.00011"
"52.36900","1.74331","6171.66162","0.01743","617.16614","-0.00009"
"52.46900","1.74636","6171.86768","0.01746","617.18677","-0.00002"
"52.56900","1.75003","6179.41650","0.01750","617.94165","-0.00004"
"52.66900","1.75325","6184.07666","0.01753","618.40765","-0.00001"
"52.76900","1.75644","6189.52539","0.01756","618.95251","-0.00007"
"52.86900","1.75976","6197.57275","0.01760","619.75726","-0.00008"
"52.96900","1.76314","6206.47168","0.01763","620.64716","-0.00005"
"53.06900","1.76644","6215.32617","0.01766","621.53259","-0.00006"
"53.16900","1.76969","6223.47363","0.01770","622.34735","-0.00004"
"53.26900","1.77326","6234.08887","0.01773","623.40887","-0.00004"
"53.36900","1.77658","6241.90234","0.01777","624.19025","-0.00006"
"53.46900","1.77974","6217.19824","0.01780","621.71985","-0.00006"
"53.56900","1.78313","6200.93408","0.01783","620.09338","-0.00006"
"53.66900","1.78650","6104.74658","0.01787","610.47467","-0.00005"
"53.70200","1.78779","5978.49170","0.01788","597.84918","-0.00007"
"53.80200","1.79091","5946.31006","0.01791","594.63098","-0.00008"
"53.90200","1.79429","5937.42676","0.01794","593.74268","-0.00004"
"54.00200","1.79763","5938.23438","0.01798","593.82343","-0.00005"
"54.10200","1.80087","5941.34570","0.01801","594.13458","-0.00003"
"54.20200","1.80420","5945.06055","0.01804","594.50604","-0.00005"
"54.30200","1.80768","5949.34814","0.01808","594.93481","-0.00006"
"54.40200","1.81108","5954.06836","0.01811","595.40686","-0.00005"
"54.50200","1.81417","5956.66504","0.01814","595.66650","-0.00007"
"54.60200","1.81759","5963.78174","0.01818","596.37817","-0.00004"
"54.70200","1.82086","5970.09570","0.01821","597.00958","-0.00006"
"54.80200","1.82422","5977.63232","0.01824","597.76324","-0.00006"
"54.90200","1.82756","5985.76611","0.01828","598.57660","-0.00004"
"55.00200","1.83094","5994.34375","0.01831","599.43439","-0.00006"
"55.10200","1.83434","6003.35596","0.01834","600.33557","-0.00004"
"55.20200","1.83749","6010.07959","0.01837","601.00793","-0.00006"
"55.30200","1.84097","6020.26025","0.01841","602.02600","-0.00005"
"55.40200","1.84426","6024.05957","0.01844","602.40594","-0.00006"
"55.50200","1.84754","6019.61182","0.01848","601.96118","-0.00006"
"55.56900","1.84972","5848.06299","0.01850","584.80627","-0.00006"
"55.57100","1.84979","5695.05469","0.01850","569.50549","-0.00006"
"55.57300","1.84986","5501.06445","0.01850","550.10645","-0.00006"
"55.57500","1.84994","5276.52490","0.01850","527.65247","-0.00008"
"55.57700","1.85002","5029.89941","0.01850","502.98993","-0.00010"
"55.57800","1.85006","4900.46387","0.01850","490.04639","-0.00011"
"55.57900","1.85011","4767.96240","0.01850","476.79623","-0.00012"
"55.58000","1.85015","4633.13818","0.01850","463.31381","-0.00012"
"55.58100","1.85020","4496.71875","0.01850","449.67188","-0.00011"
"55.58200","1.85024","4359.39160","0.01850","435.93915","-0.00010"
"55.58300","1.85029","4221.76318","0.01850","422.17633","-0.00009"
"55.58400","1.85034","4084.36768","0.01850","408.43677","-0.00007"
"55.58500","1.85040","3947.68896","0.01850","394.76889","-0.00006"
"55.58600","1.85045","3812.19531","0.01850","381.21954","-0.00005"
"55.58700","1.85051","3678.33667","0.01851","367.83368","-0.00006"
"55.58800","1.85057","3546.52148","0.01851","354.65216","-0.00007"