File: Tension/Section_1_Group_4/6_days/Sample_7_6_days_tension.is_tens_RawData/Specimen_RawData_1.csv
Time,Extension,Load,Tensile strain (Extension),Axial Video,Tensile stress,Transverse Video
(s),(mm),(N),(mm/mm),(mm/mm),(MPa),(mm/mm)
"0.00000","0.00000","-0.31406","0.00000","0.00000","-0.03141","0.00000"
"0.30000","0.00767","32.04918","0.00008","0.00002","3.20492","0.00005"
"0.60000","0.01779","74.93745","0.00018","0.00011","7.49374","0.00005"
"0.90000","0.02792","117.75370","0.00028","0.00015","11.77537","-0.00003"
"1.20000","0.03774","158.72630","0.00038","0.00021","15.87263","-0.00014"
"1.50000","0.04797","201.46790","0.00048","0.00032","20.14679","-0.00019"
"1.80000","0.05774","243.27049","0.00058","0.00038","24.32705","-0.00014"
"2.10000","0.06769","285.87936","0.00068","0.00046","28.58794","-0.00019"
"2.40000","0.07770","328.16977","0.00078","0.00052","32.81698","-0.00015"
"2.70000","0.08780","370.21780","0.00088","0.00055","37.02178","-0.00015"
"3.00000","0.09781","411.38562","0.00098","0.00059","41.13856","-0.00018"
"3.30000","0.10800","452.74426","0.00108","0.00063","45.27443","-0.00016"
"3.60000","0.11774","491.43503","0.00118","0.00067","49.14350","-0.00015"
"3.90000","0.12782","531.11176","0.00128","0.00072","53.11118","-0.00011"
"4.20000","0.13780","569.71667","0.00138","0.00077","56.97167","-0.00010"
"4.50000","0.14780","607.57043","0.00148","0.00083","60.75704","-0.00010"
"4.80000","0.15776","644.76447","0.00158","0.00089","64.47645","-0.00005"
"5.10000","0.16780","681.94452","0.00168","0.00094","68.19445","-0.00006"
"5.40000","0.17779","718.22919","0.00178","0.00098","71.82292","-0.00010"
"5.70000","0.18778","753.81372","0.00188","0.00102","75.38137","-0.00010"
"6.00000","0.19788","789.34607","0.00198","0.00106","78.93461","-0.00018"
"6.30000","0.20790","824.22046","0.00208","0.00109","82.42204","-0.00024"
"6.60000","0.21781","857.96686","0.00218","0.00113","85.79668","-0.00029"
"6.90000","0.22778","891.38477","0.00228","0.00116","89.13847","-0.00034"
"7.20000","0.23773","923.93060","0.00238","0.00121","92.39306","-0.00034"
"7.50000","0.24770","956.46893","0.00248","0.00127","95.64690","-0.00034"
"7.80000","0.25790","989.51672","0.00258","0.00132","98.95168","-0.00030"
"8.10000","0.26778","1020.74182","0.00268","0.00137","102.07418","-0.00034"
"8.40000","0.27792","1052.55591","0.00278","0.00142","105.25559","-0.00029"
"8.70000","0.28794","1083.28662","0.00288","0.00145","108.32866","-0.00029"
"9.00000","0.29772","1112.38635","0.00298","0.00149","111.23863","-0.00019"
"9.30000","0.30765","1141.71716","0.00308","0.00152","114.17171","-0.00016"
"9.60000","0.31777","1171.83252","0.00318","0.00156","117.18325","-0.00016"
"9.90000","0.32780","1200.71252","0.00328","0.00159","120.07125","-0.00019"
"10.20000","0.33793","1229.79749","0.00338","0.00162","122.97975","-0.00026"
"10.50000","0.34786","1257.63586","0.00348","0.00167","125.76359","-0.00029"
"10.80000","0.35787","1285.49622","0.00358","0.00172","128.54962","-0.00034"
"11.10000","0.36778","1312.28491","0.00368","0.00175","131.22849","-0.00039"
"11.40000","0.37780","1339.22253","0.00378","0.00179","133.92226","-0.00044"
"11.70000","0.38775","1365.42896","0.00388","0.00184","136.54289","-0.00040"
"12.00000","0.39783","1391.77148","0.00398","0.00188","139.17715","-0.00044"
"12.30000","0.40785","1417.38452","0.00408","0.00191","141.73845","-0.00044"
"12.60000","0.41785","1442.37268","0.00418","0.00195","144.23727","-0.00044"
"12.90000","0.42777","1466.63232","0.00428","0.00197","146.66324","-0.00040"
"13.20000","0.43790","1491.79211","0.00438","0.00200","149.17921","-0.00032"
"13.50000","0.44783","1515.38318","0.00448","0.00203","151.53831","-0.00029"
"13.80000","0.45780","1538.60791","0.00458","0.00206","153.86079","-0.00024"
"14.10000","0.46778","1561.50659","0.00468","0.00209","156.15067","-0.00019"
"14.40000","0.47771","1583.63342","0.00478","0.00212","158.36334","-0.00019"
"14.70000","0.48783","1606.48804","0.00488","0.00215","160.64880","-0.00029"
"15.00000","0.49784","1628.22693","0.00498","0.00217","162.82269","-0.00034"
"15.30000","0.50785","1649.75488","0.00508","0.00220","164.97549","-0.00039"
"15.60000","0.51795","1671.54468","0.00518","0.00223","167.15446","-0.00041"
"15.90000","0.52780","1691.47009","0.00528","0.00226","169.14700","-0.00044"
"16.20000","0.53771","1711.47156","0.00538","0.00228","171.14716","-0.00042"
"16.50000","0.54777","1731.85559","0.00548","0.00230","173.18556","-0.00041"
"16.80000","0.55773","1751.34094","0.00558","0.00233","175.13409","-0.00038"
"17.10000","0.56793","1771.48950","0.00568","0.00233","177.14896","-0.00037"
"17.40000","0.57789","1790.22083","0.00578","0.00235","179.02208","-0.00029"
"17.70000","0.58789","1808.52258","0.00588","0.00237","180.85226","-0.00024"
"18.00000","0.59783","1825.80432","0.00598","0.00240","182.58043","-0.00024"
"18.30000","0.60779","1842.66992","0.00608","0.00240","184.26700","-0.00024"
"18.60000","0.61769","1859.00439","0.00618","0.00242","185.90044","-0.00024"
"18.90000","0.62780","1875.98694","0.00628","0.00244","187.59869","-0.00024"
"19.20000","0.63782","1891.78491","0.00638","0.00248","189.17850","-0.00029"
"19.50000","0.64790","1907.50586","0.00648","0.00250","190.75058","-0.00031"
"19.80000","0.65776","1921.82605","0.00658","0.00252","192.18260","-0.00031"
"20.10000","0.66793","1936.98792","0.00668","0.00255","193.69879","-0.00034"
"20.40000","0.67782","1950.28711","0.00678","0.00258","195.02872","-0.00034"
"20.70000","0.68783","1963.56458","0.00688","0.00258","196.35646","-0.00039"
"21.00000","0.69775","1976.31494","0.00698","0.00259","197.63150","-0.00043"
"21.30000","0.70774","1989.17090","0.00708","0.00261","198.91708","-0.00040"
"21.60000","0.71778","2001.76501","0.00718","0.00262","200.17650","-0.00039"
"21.90000","0.72792","2014.73755","0.00728","0.00263","201.47375","-0.00034"
"22.20000","0.73776","2025.56738","0.00738","0.00264","202.55673","-0.00034"
"22.50000","0.74799","2038.62476","0.00748","0.00266","203.86247","-0.00029"
"22.80000","0.75786","2048.97046","0.00758","0.00267","204.89705","-0.00029"
"23.10000","0.76773","2058.27148","0.00768","0.00268","205.82715","-0.00029"
"23.40000","0.77774","2067.80054","0.00778","0.00267","206.78006","-0.00029"
"23.70000","0.78780","2077.48340","0.00788","0.00267","207.74834","-0.00029"
"24.00000","0.79781","2086.68799","0.00798","0.00267","208.66879","-0.00029"
"24.30000","0.80791","2096.00781","0.00808","0.00270","209.60078","-0.00024"
"24.60000","0.81791","2104.68286","0.00818","0.00271","210.46829","-0.00029"
"24.90000","0.82784","2113.07837","0.00828","0.00272","211.30783","-0.00034"
"25.20000","0.83779","2122.07080","0.00838","0.00272","212.20708","-0.00039"
"25.50000","0.84776","2131.24902","0.00848","0.00274","213.12491","-0.00039"
"25.80000","0.85777","2140.40503","0.00858","0.00274","214.04050","-0.00040"
"26.10000","0.86775","2149.26440","0.00868","0.00276","214.92644","-0.00039"
"26.40000","0.87790","2159.13672","0.00878","0.00276","215.91367","-0.00039"
"26.70000","0.88779","2167.83252","0.00888","0.00278","216.78325","-0.00044"
"27.00000","0.89790","2177.28491","0.00898","0.00279","217.72849","-0.00042"
"27.30000","0.90792","2186.34009","0.00908","0.00279","218.63400","-0.00039"
"27.60000","0.91780","2194.72070","0.00918","0.00282","219.47208","-0.00034"
"27.90000","0.92774","2203.30029","0.00928","0.00282","220.33003","-0.00034"
"28.20000","0.93783","2212.59448","0.00938","0.00285","221.25945","-0.00029"
"28.50000","0.94767","2220.87549","0.00948","0.00285","222.08755","-0.00024"
"28.80000","0.95788","2231.32812","0.00958","0.00286","223.13281","-0.00019"
"29.10000","0.96781","2240.22192","0.00968","0.00288","224.02219","-0.00014"
"29.40000","0.97792","2250.20776","0.00978","0.00291","225.02078","-0.00019"
"29.70000","0.98786","2259.27637","0.00988","0.00292","225.92764","-0.00017"
"30.00000","0.99785","2268.46216","0.00998","0.00293","226.84622","-0.00022"
"30.30000","1.00765","2276.30420","0.01008","0.00294","227.63042","-0.00024"
"30.60000","1.01779","2285.87207","0.01018","0.00295","228.58720","-0.00029"
"30.90000","1.02787","2294.97607","0.01028","0.00296","229.49760","-0.00029"
"31.20000","1.03791","2303.84009","0.01038","0.00297","230.38400","-0.00029"
"31.50000","1.04781","2311.97388","0.01048","0.00299","231.19739","-0.00034"
"31.80000","1.05795","2321.06348","0.01058","0.00298","232.10635","-0.00035"
"32.10000","1.06775","2328.35645","0.01068","0.00300","232.83565","-0.00034"
"32.40000","1.07775","2336.13599","0.01078","0.00302","233.61360","-0.00031"
"32.70000","1.08778","2344.47632","0.01088","0.00303","234.44763","-0.00030"
"33.00000","1.09776","2352.84839","0.01098","0.00303","235.28484","-0.00028"
"33.30000","1.10783","2361.96875","0.01108","0.00302","236.19687","-0.00024"
"33.60000","1.11792","2371.18481","0.01118","0.00304","237.11848","-0.00019"
"33.90000","1.12779","2378.97534","0.01128","0.00307","237.89754","-0.00018"
"34.20000","1.13788","2388.31445","0.01138","0.00308","238.83145","-0.00018"
"34.50000","1.14784","2396.35205","0.01148","0.00309","239.63521","-0.00021"
"34.80000","1.15774","2403.86450","0.01158","0.00311","240.38644","-0.00019"
"35.10000","1.16775","2411.86987","0.01168","0.00313","241.18698","-0.00024"
"35.40000","1.17779","2419.79004","0.01178","0.00315","241.97900","-0.00024"
"35.70000","1.18786","2428.11304","0.01188","0.00314","242.81131","-0.00029"
"36.00000","1.19782","2436.30249","0.01198","0.00318","243.63025","-0.00034"
"36.30000","1.20793","2445.32031","0.01208","0.00319","244.53203","-0.00039"
"36.60000","1.21787","2453.06787","0.01218","0.00320","245.30679","-0.00041"
"36.90000","1.22776","2460.86987","0.01228","0.00321","246.08699","-0.00044"
"37.20000","1.23774","2469.06934","0.01238","0.00322","246.90694","-0.00044"
"37.50000","1.24776","2471.98389","0.01248","0.00324","247.19839","-0.00044"
"37.80000","1.25779","2479.48926","0.01258","0.00325","247.94893","-0.00044"
"38.10000","1.26797","2488.14502","0.01268","0.00325","248.81450","-0.00044"
"38.40000","1.27782","2495.42847","0.01278","0.00327","249.54285","-0.00044"
"38.70000","1.28790","2504.00073","0.01288","0.00329","250.40007","-0.00044"
"39.00000","1.29784","2511.30640","0.01298","0.00329","251.13065","-0.00039"
"39.30000","1.30778","2518.62231","0.01308","0.00331","251.86223","-0.00030"
"39.60000","1.31771","2525.66968","0.01318","0.00333","252.56697","-0.00024"
"39.90000","1.32783","2534.02173","0.01328","0.00333","253.40218","-0.00024"
"40.20000","1.33778","2540.95630","0.01338","0.00335","254.09563","-0.00026"
"40.50000","1.34789","2548.82520","0.01348","0.00334","254.88252","-0.00032"
"40.80000","1.35783","2555.70142","0.01358","0.00334","255.57014","-0.00034"
"41.10000","1.36794","2563.66699","0.01368","0.00336","256.36670","-0.00039"
"41.40000","1.37778","2570.43530","0.01378","0.00335","257.04352","-0.00044"
"41.70000","1.38782","2577.09644","0.01388","0.00337","257.70966","-0.00044"
"42.00000","1.39773","2583.52271","0.01398","0.00338","258.35226","-0.00044"
"42.30000","1.40770","2590.59570","0.01408","0.00339","259.05957","-0.00044"
"42.60000","1.41785","2598.59229","0.01418","0.00341","259.85922","-0.00049"
"42.90000","1.42797","2606.47974","0.01428","0.00341","260.64798","-0.00044"
"43.20000","1.43782","2612.52100","0.01438","0.00342","261.25211","-0.00039"
"43.50000","1.44796","2619.73853","0.01448","0.00344","261.97385","-0.00038"
"43.80000","1.45779","2625.44922","0.01458","0.00345","262.54492","-0.00034"
"44.10000","1.46765","2631.09473","0.01468","0.00347","263.10947","-0.00028"
"44.40000","1.47779","2637.01538","0.01478","0.00347","263.70154","-0.00024"
"44.70000","1.48790","2640.67334","0.01488","0.00347","264.06732","-0.00024"
"45.00000","1.49791","2643.78906","0.01498","0.00348","264.37891","-0.00019"
"45.30000","1.50782","2646.47998","0.01508","0.00350","264.64801","-0.00024"
"45.60000","1.51787","2649.64966","0.01518","0.00351","264.96497","-0.00026"
"45.90000","1.52781","2650.04736","0.01528","0.00351","265.00473","-0.00028"
"46.20000","1.53779","2650.23633","0.01538","0.00352","265.02362","-0.00028"
"46.50000","1.54778","2649.87598","0.01548","0.00352","264.98761","-0.00029"
"46.80000","1.55779","2646.03467","0.01558","0.00352","264.60345","-0.00027"
"47.10000","1.56778","2643.37573","0.01568","0.00351","264.33759","-0.00029"
"47.40000","1.57793","2641.87476","0.01578","0.00351","264.18747","-0.00034"
"47.70000","1.58775","2634.96631","0.01588","0.00351","263.49664","-0.00034"
"48.00000","1.59791","2620.96777","0.01598","0.00349","262.09677","-0.00034"
"48.30000","1.60792","2607.97656","0.01608","0.00346","260.79767","-0.00039"
"48.60000","1.61778","2597.45703","0.01618","0.00345","259.74570","-0.00034"
"48.90000","1.62774","2591.02979","0.01628","0.00343","259.10297","-0.00041"
"49.20000","1.63775","2585.46362","0.01638","0.00343","258.54636","-0.00039"
"49.50000","1.64772","2578.98315","0.01648","0.00343","257.89832","-0.00039"
"49.80000","1.65792","2573.39282","0.01658","0.00341","257.33929","-0.00034"
"50.10000","1.66795","2564.94531","0.01668","0.00341","256.49454","-0.00034"
"50.40000","1.67791","2551.80005","0.01678","0.00340","255.18001","-0.00029"
"50.70000","1.68781","2535.29077","0.01688","0.00338","253.52908","-0.00019"
"51.00000","1.69777","2519.96094","0.01698","0.00336","251.99609","-0.00017"
"51.30000","1.70767","2512.13672","0.01708","0.00335","251.21367","-0.00020"
"51.60000","1.71776","2511.21118","0.01718","0.00334","251.12112","-0.00019"
"51.90000","1.72795","2514.24414","0.01728","0.00334","251.42441","-0.00020"
"52.20000","1.73784","2516.40405","0.01738","0.00336","251.64041","-0.00024"
"52.50000","1.74782","2518.77759","0.01748","0.00337","251.87776","-0.00029"
"52.80000","1.75788","2521.36182","0.01758","0.00338","252.13618","-0.00029"
"53.10000","1.76774","2523.58081","0.01768","0.00339","252.35808","-0.00034"
"53.40000","1.77771","2525.99951","0.01778","0.00340","252.59995","-0.00039"
"53.70000","1.78788","2528.87866","0.01788","0.00341","252.88786","-0.00039"
"54.00000","1.79775","2530.80591","0.01798","0.00342","253.08060","-0.00035"
"54.30000","1.80788","2534.14575","0.01808","0.00342","253.41458","-0.00034"
"54.60000","1.81779","2534.40161","0.01818","0.00344","253.44016","-0.00029"
"54.90000","1.82783","2535.09985","0.01828","0.00345","253.50998","-0.00028"
"55.20000","1.83785","2536.38379","0.01838","0.00347","253.63838","-0.00019"
"55.50000","1.84787","2536.07153","0.01848","0.00347","253.60715","-0.00018"
"55.80000","1.85773","2536.30493","0.01858","0.00347","253.63049","-0.00019"
"56.10000","1.86780","2537.84888","0.01868","0.00348","253.78488","-0.00015"
"56.40000","1.87772","2542.02368","0.01878","0.00349","254.20236","-0.00015"
"56.70000","1.88787","2548.22754","0.01888","0.00350","254.82275","-0.00014"
"57.00000","1.89783","2553.21021","0.01898","0.00353","255.32101","-0.00015"
"57.30000","1.90796","2558.21802","0.01908","0.00354","255.82181","-0.00019"
"57.60000","1.91780","2563.15942","0.01918","0.00354","256.31595","-0.00024"
"57.90000","1.92776","2568.97070","0.01928","0.00355","256.89706","-0.00025"
"58.20000","1.93770","2574.58569","0.01938","0.00356","257.45856","-0.00024"
"58.50000","1.94777","2580.02344","0.01948","0.00360","258.00235","-0.00019"
"58.80000","1.95780","2583.77905","0.01958","0.00361","258.37790","-0.00015"
"59.10000","1.96797","2589.43896","0.01968","0.00361","258.94391","-0.00011"
"59.40000","1.97776","2594.58228","0.01978","0.00362","259.45822","-0.00008"
"59.70000","1.98789","2599.32886","0.01988","0.00364","259.93289","0.00000"
"60.00000","1.99773","2603.57568","0.01998","0.00366","260.35757","0.00008"
"60.30000","2.00772","2608.96729","0.02008","0.00367","260.89673","0.00005"
"60.60000","2.01775","2613.62500","0.02018","0.00368","261.36249","0.00006"
"60.90000","2.02784","2619.03882","0.02028","0.00368","261.90387","0.00005"
"61.20000","2.03782","2623.43823","0.02038","0.00367","262.34381","0.00007"
"61.50000","2.04785","2630.27856","0.02048","0.00370","263.02786","0.00005"
"61.80000","2.05776","2637.90527","0.02058","0.00372","263.79053","0.00000"
"62.10000","2.06792","2645.76050","0.02068","0.00372","264.57605","-0.00005"
"62.40000","2.07779","2625.80786","0.02078","0.00371","262.58078","-0.00010"
"62.70000","2.08779","2614.09424","0.02088","0.00371","261.40942","-0.00007"
"63.00000","2.09777","2610.12817","0.02098","0.00371","261.01282","-0.00010"
"63.30000","2.10775","2614.51929","0.02108","0.00371","261.45193","-0.00008"
"63.60000","2.11784","2623.40063","0.02118","0.00372","262.34006","-0.00005"
"63.90000","2.12787","2632.84888","0.02128","0.00373","263.28488","-0.00005"
"64.20000","2.13786","2643.00342","0.02138","0.00375","264.30035","0.00000"
"64.50000","2.14789","2652.89746","0.02148","0.00378","265.28973","0.00005"
"64.80000","2.15783","2662.26660","0.02158","0.00380","266.22665","0.00014"
"65.10000","2.16767","2671.80493","0.02168","0.00382","267.18048","0.00019"
"65.40000","2.17771","2683.02295","0.02178","0.00383","268.30231","0.00020"
"65.70000","2.18776","2694.92725","0.02188","0.00386","269.49274","0.00024"
"66.00000","2.19793","2706.64160","0.02198","0.00388","270.66415","0.00020"
"66.30000","2.20774","2716.99146","0.02208","0.00388","271.69916","0.00020"
"66.60000","2.21792","2729.42456","0.02218","0.00391","272.94244","0.00019"
"66.90000","2.22778","2740.33276","0.02228","0.00393","274.03326","0.00015"
"67.20000","2.23771","2751.92871","0.02238","0.00395","275.19287","0.00010"
"67.50000","2.24774","2764.36841","0.02248","0.00399","276.43683","0.00012"
"67.80000","2.25781","2777.03027","0.02258","0.00402","277.70303","0.00010"
"68.10000","2.26775","2788.53223","0.02268","0.00404","278.85321","0.00011"
"68.40000","2.27800","2802.16772","0.02278","0.00406","280.21677","0.00014"
"68.70000","2.28774","2812.90479","0.02288","0.00408","281.29047","0.00015"
"69.00000","2.29783","2825.40771","0.02298","0.00410","282.54077","0.00019"
"69.30000","2.30781","2837.43701","0.02308","0.00413","283.74371","0.00024"
"69.60000","2.31780","2848.42139","0.02318","0.00415","284.84213","0.00034"
"69.90000","2.32775","2859.35083","0.02328","0.00417","285.93509","0.00034"
"70.20000","2.33785","2870.62817","0.02338","0.00418","287.06281","0.00039"
"70.50000","2.34775","2880.83887","0.02348","0.00419","288.08389","0.00040"
"70.80000","2.35782","2891.99438","0.02358","0.00420","289.19943","0.00039"
"71.10000","2.36785","2902.45068","0.02368","0.00422","290.24506","0.00039"
"71.40000","2.37791","2911.80688","0.02378","0.00424","291.18069","0.00037"
"71.70000","2.38776","2897.26807","0.02388","0.00423","289.72681","0.00042"
"72.00000","2.39780","2900.08179","0.02398","0.00424","290.00818","0.00044"
"72.30000","2.40770","2777.87549","0.02408","0.00408","277.78754","0.00039"
"72.60000","2.41772","2774.81421","0.02418","0.00408","277.48141","0.00044"
"72.90000","2.42788","2778.13354","0.02428","0.00409","277.81335","0.00044"
"73.20000","2.43784","2783.70752","0.02438","0.00410","278.37076","0.00041"
"73.50000","2.44781","2791.27246","0.02448","0.00412","279.12726","0.00039"
"73.80000","2.45798","2800.13989","0.02458","0.00414","280.01398","0.00039"
"74.10000","2.46775","2808.13574","0.02468","0.00416","280.81357","0.00039"
"74.40000","2.47764","2815.04907","0.02478","0.00419","281.50491","0.00044"
"74.70000","2.48777","2823.09692","0.02488","0.00421","282.30969","0.00044"
"75.00000","2.49779","2830.41284","0.02498","0.00423","283.04129","0.00045"
"75.30000","2.50792","2838.60156","0.02508","0.00423","283.86017","0.00044"
"75.60000","2.51791","2845.99072","0.02518","0.00425","284.59906","0.00044"
"75.90000","2.52783","2852.20654","0.02528","0.00426","285.22064","0.00049"
"76.20000","2.53775","2858.37329","0.02538","0.00428","285.83734","0.00049"
"76.50000","2.54781","2702.27783","0.02548","0.00410","270.22778","0.00051"
"76.80000","2.55778","2644.98901","0.02558","0.00404","264.49890","0.00058"
"77.10000","2.56781","2549.01294","0.02568","0.00394","254.90129","0.00073"
"77.40000","2.57785","2482.92700","0.02578","0.00383","248.29269","0.00079"
"77.70000","2.58789","2388.02759","0.02588","0.00374","238.80276","0.00078"
"78.00000","2.59778","2182.09180","0.02598","0.00350","218.20918","0.00073"
"78.30000","2.60792","2072.93481","0.02608","0.00331","207.29349","0.00074"
"78.60000","2.61784","2030.79919","0.02618","0.00326","203.07993","0.00083"
"78.90000","2.62778","2012.55945","0.02628","0.00327","201.25595","0.00087"
"79.20000","2.63780","2003.96179","0.02638","0.00326","200.39618","0.00083"
"79.50000","2.64774","2000.08826","0.02648","0.00326","200.00882","0.00078"
"79.80000","2.65776","1998.13306","0.02658","0.00323","199.81331","0.00078"
"80.10000","2.66785","1997.83875","0.02668","0.00325","199.78387","0.00080"
"80.40000","2.67781","1999.17444","0.02678","0.00325","199.91745","0.00078"
"80.70000","2.68796","2001.50891","0.02688","0.00326","200.15089","0.00078"
"81.00000","2.69784","2003.16809","0.02698","0.00326","200.31680","0.00078"
"81.30000","2.70774","2005.21497","0.02708","0.00325","200.52150","0.00078"
"81.60000","2.71772","2007.90869","0.02718","0.00326","200.79086","0.00073"
"81.90000","2.72773","2008.88196","0.02728","0.00327","200.88820","0.00073"
"82.20000","2.73788","2009.91699","0.02738","0.00326","200.99170","0.00073"
"82.50000","2.74795","2009.74292","0.02748","0.00326","200.97429","0.00073"
"82.80000","2.75785","2010.53857","0.02758","0.00326","201.05386","0.00068"
"83.10000","2.76785","2014.88953","0.02768","0.00327","201.48895","0.00070"
"83.40000","2.77779","2019.16248","0.02778","0.00327","201.91624","0.00068"
"83.70000","2.78774","2022.28333","0.02788","0.00329","202.22833","0.00068"
"84.00000","2.79780","2024.91003","0.02798","0.00329","202.49100","0.00072"
"84.30000","2.80779","2029.50159","0.02808","0.00330","202.95016","0.00071"
"84.60000","2.81792","2034.51453","0.02818","0.00330","203.45145","0.00068"
"84.90000","2.82779","2039.61304","0.02828","0.00332","203.96130","0.00073"
"85.20000","2.83787","2045.84082","0.02838","0.00332","204.58408","0.00073"
"85.50000","2.84781","2051.48657","0.02848","0.00332","205.14865","0.00077"
"85.80000","2.85784","2057.05664","0.02858","0.00333","205.70566","0.00074"
"86.10000","2.86775","2060.25269","0.02868","0.00334","206.02527","0.00073"
"86.40000","2.87776","2064.21191","0.02878","0.00334","206.42119","0.00074"
"86.70000","2.88775","2067.45166","0.02888","0.00334","206.74516","0.00073"
"87.00000","2.89788","2071.38013","0.02898","0.00334","207.13802","0.00073"
"87.30000","2.90776","2074.18262","0.02908","0.00335","207.41826","0.00068"
"87.60000","2.91798","2079.50952","0.02918","0.00336","207.95096","0.00063"
"87.90000","2.92788","2082.45947","0.02928","0.00336","208.24594","0.00063"
"88.20000","2.93775","2085.43677","0.02938","0.00337","208.54367","0.00068"
"88.50000","2.94772","2089.21680","0.02948","0.00337","208.92168","0.00063"
"88.80000","2.95781","2093.83374","0.02958","0.00337","209.38338","0.00058"
"89.10000","2.96775","2097.40234","0.02968","0.00338","209.74023","0.00058"
"89.40000","2.97796","2100.55396","0.02978","0.00340","210.05539","0.00063"
"89.70000","2.98787","2101.84912","0.02988","0.00339","210.18491","0.00063"
"90.00000","2.99788","2104.29663","0.02998","0.00340","210.42966","0.00058"
"90.30000","3.00780","2105.59253","0.03008","0.00340","210.55925","0.00058"
"90.60000","3.01777","2109.34961","0.03018","0.00341","210.93497","0.00058"
"90.90000","3.02774","2113.97021","0.03028","0.00341","211.39702","0.00058"
"91.20000","3.03778","2118.75220","0.03038","0.00342","211.87521","0.00059"
"91.50000","3.04786","2124.14746","0.03048","0.00342","212.41475","0.00059"
"91.80000","3.05782","2129.50049","0.03058","0.00343","212.95004","0.00058"
"92.10000","3.06782","2133.70825","0.03068","0.00345","213.37082","0.00056"
"92.40000","3.07795","2137.05225","0.03078","0.00346","213.70523","0.00055"
"92.70000","3.08781","2135.07666","0.03088","0.00345","213.50766","0.00058"
"93.00000","3.09777","2133.60352","0.03098","0.00345","213.36035","0.00063"
"93.30000","3.10780","2133.66699","0.03108","0.00346","213.36670","0.00063"
"93.60000","3.11767","2133.37939","0.03118","0.00346","213.33794","0.00063"
"93.90000","3.12790","2136.51245","0.03128","0.00347","213.65125","0.00063"
"94.20000","3.13784","2138.35107","0.03138","0.00347","213.83511","0.00068"
"94.50000","3.14787","2141.17529","0.03148","0.00348","214.11752","0.00070"
"94.80000","3.15790","2142.63062","0.03158","0.00349","214.26306","0.00073"
"95.10000","3.16784","2145.28882","0.03168","0.00348","214.52888","0.00073"
"95.40000","3.17766","2148.06006","0.03178","0.00349","214.80600","0.00078"
"95.70000","3.18779","2152.70801","0.03188","0.00350","215.27080","0.00078"
"96.00000","3.19780","2156.90088","0.03198","0.00351","215.69009","0.00082"
"96.30000","3.20792","2162.07104","0.03208","0.00352","216.20711","0.00078"
"96.60000","3.21784","2166.70972","0.03218","0.00353","216.67097","0.00078"
"96.90000","3.22795","2171.71460","0.03228","0.00353","217.17146","0.00078"
"97.20000","3.23775","2176.73145","0.03238","0.00354","217.67314","0.00078"
"97.50000","3.24778","2181.06641","0.03248","0.00356","218.10664","0.00078"
"97.80000","3.25775","2182.46045","0.03258","0.00356","218.24605","0.00079"
"98.10000","3.26778","2183.68701","0.03268","0.00356","218.36870","0.00083"
"98.40000","3.27780","2182.22485","0.03278","0.00355","218.22249","0.00082"
"98.70000","3.28795","2182.13257","0.03288","0.00356","218.21326","0.00078"
"99.00000","3.29774","2176.18408","0.03298","0.00357","217.61841","0.00080"
"99.30000","3.30791","2172.37061","0.03308","0.00356","217.23706","0.00077"
"99.60000","3.31788","2165.46460","0.03318","0.00357","216.54646","0.00077"
"99.90000","3.32775","2147.53149","0.03328","0.00356","214.75314","0.00072"
"100.20000","3.33772","2123.02393","0.03338","0.00354","212.30240","0.00063"
"100.50000","3.34780","2106.01538","0.03348","0.00351","210.60153","0.00059"
"100.80000","3.35783","2099.10767","0.03358","0.00351","209.91077","0.00063"
"101.10000","3.36786","2095.52246","0.03368","0.00350","209.55225","0.00063"
"101.40000","3.37788","2091.13696","0.03378","0.00350","209.11369","0.00063"
"101.70000","3.38791","2090.69189","0.03388","0.00351","209.06918","0.00064"
"102.00000","3.39779","2085.87891","0.03398","0.00351","208.58789","0.00068"
"102.30000","3.40778","2080.06079","0.03408","0.00350","208.00607","0.00068"
"102.60000","3.41771","2054.71704","0.03418","0.00350","205.47171","0.00068"
"102.90000","3.42774","2048.40552","0.03428","0.00349","204.84055","0.00060"
"103.20000","3.43798","2049.79248","0.03438","0.00350","204.97925","0.00058"
"103.50000","3.44785","2051.41675","0.03448","0.00350","205.14168","0.00053"
"103.80000","3.45787","2053.38306","0.03458","0.00351","205.33830","0.00053"
"104.10000","3.46789","2054.67749","0.03468","0.00352","205.46774","0.00052"
"104.40000","3.47777","2051.76147","0.03478","0.00353","205.17615","0.00053"
"104.70000","3.48772","2048.62695","0.03488","0.00353","204.86270","0.00049"
"105.00000","3.49781","2048.64258","0.03498","0.00352","204.86426","0.00049"
"105.30000","3.50774","2049.31616","0.03508","0.00352","204.93161","0.00044"
"105.60000","3.51790","2053.66064","0.03518","0.00353","205.36606","0.00044"
"105.90000","3.52785","2056.27710","0.03528","0.00353","205.62772","0.00049"
"106.20000","3.53790","2060.41260","0.03538","0.00354","206.04126","0.00044"
"106.50000","3.54782","2065.33398","0.03548","0.00355","206.53340","0.00044"
"106.80000","3.55784","2071.84985","0.03558","0.00356","207.18498","0.00045"
"107.10000","3.56770","2077.91040","0.03568","0.00355","207.79105","0.00049"
"107.40000","3.57774","2084.13672","0.03578","0.00356","208.41367","0.00049"
"107.70000","3.58781","2090.59204","0.03588","0.00357","209.05920","0.00049"
"108.00000","3.59795","2097.04126","0.03598","0.00358","209.70413","0.00049"
"108.30000","3.60779","2100.31909","0.03608","0.00359","210.03191","0.00049"
"108.60000","3.61798","2105.15991","0.03618","0.00359","210.51599","0.00049"
"108.90000","3.62780","2104.88916","0.03628","0.00359","210.48892","0.00053"
"109.20000","3.63769","2105.08838","0.03638","0.00360","210.50883","0.00049"
"109.50000","3.64774","2106.47070","0.03648","0.00360","210.64706","0.00054"
"109.80000","3.65787","2108.63696","0.03658","0.00361","210.86369","0.00056"
"110.10000","3.66787","2109.33301","0.03668","0.00361","210.93330","0.00058"
"110.40000","3.67791","2108.52417","0.03678","0.00361","210.85242","0.00059"
"110.70000","3.68786","2106.98730","0.03688","0.00361","210.69873","0.00058"
"111.00000","3.69784","2106.58301","0.03698","0.00362","210.65829","0.00053"
"111.30000","3.70780","2106.07153","0.03708","0.00363","210.60715","0.00053"
"111.60000","3.71780","2104.89282","0.03718","0.00362","210.48929","0.00053"
"111.90000","3.72774","2080.29370","0.03728","0.00362","208.02937","0.00053"
"112.20000","3.73777","2069.69629","0.03738","0.00359","206.96964","0.00049"
"112.50000","3.74787","2067.23438","0.03748","0.00358","206.72343","0.00046"
"112.80000","3.75779","2065.62305","0.03758","0.00357","206.56230","0.00039"
"113.10000","3.76787","2067.44141","0.03768","0.00358","206.74414","0.00044"
"113.40000","3.77794","2070.35596","0.03778","0.00357","207.03560","0.00043"
"113.70000","3.78776","2072.69800","0.03788","0.00357","207.26981","0.00044"
"114.00000","3.79776","2075.85962","0.03798","0.00358","207.58597","0.00039"
"114.30000","3.80777","2078.83521","0.03808","0.00359","207.88351","0.00041"
"114.60000","3.81769","2082.46948","0.03818","0.00359","208.24695","0.00044"
"114.90000","3.82794","2087.50879","0.03828","0.00359","208.75089","0.00044"
"115.20000","3.83793","2091.74243","0.03838","0.00359","209.17424","0.00044"
"115.50000","3.84791","2095.61987","0.03848","0.00360","209.56198","0.00044"
"115.80000","3.85787","2097.12012","0.03858","0.00360","209.71201","0.00049"
"116.10000","3.86778","2098.54517","0.03868","0.00361","209.85452","0.00053"
"116.40000","3.87764","2099.16162","0.03878","0.00361","209.91617","0.00053"
"116.70000","3.88776","2101.74927","0.03888","0.00360","210.17493","0.00053"
"117.00000","3.89794","2105.32812","0.03898","0.00361","210.53281","0.00053"
"117.30000","3.90790","2110.14551","0.03908","0.00361","211.01456","0.00054"
"117.60000","3.91779","2115.86963","0.03918","0.00362","211.58696","0.00058"
"117.90000","3.92791","2123.58984","0.03928","0.00362","212.35898","0.00058"
"118.20000","3.93774","2129.27612","0.03938","0.00363","212.92761","0.00058"
"118.50000","3.94775","2137.20312","0.03948","0.00363","213.72031","0.00058"
"118.80000","3.95783","2144.94238","0.03958","0.00365","214.49423","0.00058"
"119.10000","3.96777","2151.19702","0.03968","0.00365","215.11971","0.00053"
"119.40000","3.97784","2157.63672","0.03978","0.00366","215.76367","0.00054"
"119.70000","3.98786","2164.02588","0.03988","0.00367","216.40259","0.00053"
"120.00000","3.99777","2169.84741","0.03998","0.00369","216.98474","0.00057"
"120.30000","4.00791","2174.89111","0.04008","0.00370","217.48911","0.00058"
"120.60000","4.01790","2177.91431","0.04018","0.00370","217.79143","0.00058"
"120.90000","4.02773","2180.37183","0.04028","0.00371","218.03719","0.00058"
"121.20000","4.03776","2183.31934","0.04038","0.00371","218.33194","0.00053"
"121.50000","4.04772","2185.05127","0.04048","0.00370","218.50513","0.00053"
"121.80000","4.05781","2187.86646","0.04058","0.00371","218.78665","0.00058"
"122.10000","4.06788","2190.90332","0.04068","0.00372","219.09033","0.00056"
"122.40000","4.07799","2195.00049","0.04078","0.00373","219.50005","0.00058"
"122.70000","4.08786","2198.02393","0.04088","0.00373","219.80240","0.00058"
"123.00000","4.09779","2202.33496","0.04098","0.00373","220.23349","0.00058"
"123.30000","4.10770","2206.07080","0.04108","0.00374","220.60709","0.00060"
"123.60000","4.11775","2209.39282","0.04118","0.00375","220.93929","0.00063"
"123.90000","4.12774","2211.88843","0.04128","0.00374","221.18884","0.00058"
"124.20000","4.13801","2216.93726","0.04138","0.00375","221.69373","0.00058"
"124.50000","4.14774","2218.71313","0.04148","0.00376","221.87131","0.00058"
"124.80000","4.15791","2224.02271","0.04158","0.00375","222.40227","0.00058"
"125.10000","4.16779","2228.58398","0.04168","0.00375","222.85840","0.00054"
"125.40000","4.17774","2233.65991","0.04178","0.00377","223.36600","0.00053"
"125.70000","4.18769","2239.40283","0.04188","0.00377","223.94028","0.00053"
"126.00000","4.19786","2245.44385","0.04198","0.00378","224.54439","0.00056"
"126.30000","4.20775","2248.88501","0.04208","0.00379","224.88850","0.00053"
"126.60000","4.21791","2252.02979","0.04218","0.00380","225.20297","0.00054"
"126.90000","4.22774","2253.94165","0.04228","0.00380","225.39417","0.00057"
"127.20000","4.23789","2259.46021","0.04238","0.00379","225.94601","0.00055"
"127.50000","4.24782","2263.30957","0.04248","0.00379","226.33096","0.00058"
"127.80000","4.25785","2263.85864","0.04258","0.00381","226.38586","0.00054"
"128.10000","4.26774","2266.15015","0.04268","0.00381","226.61502","0.00053"
"128.40000","4.27774","2269.08008","0.04278","0.00379","226.90800","0.00053"
"128.70000","4.28781","2273.50366","0.04288","0.00380","227.35037","0.00052"
"129.00000","4.29786","2279.06006","0.04298","0.00380","227.90601","0.00054"
"129.30000","4.30783","2282.96582","0.04308","0.00381","228.29659","0.00054"
"129.60000","4.31791","2287.93335","0.04318","0.00382","228.79333","0.00049"
"129.90000","4.32782","2292.25488","0.04328","0.00382","229.22549","0.00053"
"130.20000","4.33770","2297.17749","0.04338","0.00384","229.71774","0.00052"
"130.50000","4.34772","2303.03491","0.04348","0.00384","230.30350","0.00053"
"130.80000","4.35778","2308.01733","0.04358","0.00386","230.80173","0.00053"
"131.10000","4.36790","2312.93018","0.04368","0.00386","231.29301","0.00054"
"131.40000","4.37783","2316.31982","0.04378","0.00386","231.63199","0.00053"
"131.70000","4.38785","2320.84302","0.04388","0.00387","232.08430","0.00053"
"132.00000","4.39785","2326.28418","0.04398","0.00388","232.62842","0.00053"
"132.30000","4.40772","2329.59790","0.04408","0.00390","232.95979","0.00058"
"132.60000","4.41773","2333.22559","0.04418","0.00389","233.32256","0.00054"
"132.90000","4.42779","2337.59619","0.04428","0.00390","233.75961","0.00053"
"133.20000","4.43776","2342.40845","0.04438","0.00389","234.24084","0.00053"
"133.50000","4.44797","2348.48267","0.04448","0.00391","234.84827","0.00048"
"133.80000","4.45776","2353.91382","0.04458","0.00392","235.39139","0.00053"
"134.10000","4.46780","2361.48291","0.04468","0.00391","236.14828","0.00049"
"134.40000","4.47785","2368.65601","0.04478","0.00392","236.86560","0.00048"
"134.70000","4.48781","2371.01196","0.04488","0.00393","237.10120","0.00051"
"135.00000","4.49775","2372.93774","0.04498","0.00393","237.29378","0.00049"
"135.30000","4.50783","2378.25781","0.04508","0.00395","237.82578","0.00054"
"135.60000","4.51771","2380.80103","0.04518","0.00395","238.08011","0.00053"
"135.90000","4.52788","2385.77271","0.04528","0.00395","238.57727","0.00053"
"136.20000","4.53781","2389.49414","0.04538","0.00394","238.94942","0.00049"
"136.50000","4.54789","2394.59326","0.04548","0.00396","239.45932","0.00050"
"136.80000","4.55779","2398.92432","0.04558","0.00395","239.89243","0.00051"
"137.10000","4.56785","2404.36035","0.04568","0.00396","240.43604","0.00049"
"137.40000","4.57768","2407.22437","0.04578","0.00399","240.72244","0.00049"
"137.70000","4.58771","2407.95068","0.04588","0.00399","240.79507","0.00051"
"138.00000","4.59784","2409.57544","0.04598","0.00397","240.95755","0.00050"
"138.30000","4.60790","2412.43872","0.04608","0.00397","241.24387","0.00049"
"138.60000","4.61773","2413.41992","0.04618","0.00398","241.34200","0.00049"
"138.90000","4.62796","2417.55176","0.04628","0.00399","241.75517","0.00052"
"139.20000","4.63774","2420.23608","0.04638","0.00399","242.02361","0.00049"
"139.50000","4.64769","2424.18335","0.04648","0.00399","242.41833","0.00049"
"139.80000","4.65777","2429.96558","0.04658","0.00399","242.99655","0.00049"
"140.10000","4.66779","2435.90649","0.04668","0.00401","243.59065","0.00048"
"140.40000","4.67785","2442.48755","0.04678","0.00403","244.24875","0.00051"
"140.70000","4.68794","2448.24292","0.04688","0.00402","244.82430","0.00046"
"141.00000","4.69778","2450.29736","0.04698","0.00402","245.02974","0.00049"
"141.30000","4.70781","2454.47144","0.04708","0.00402","245.44714","0.00053"
"141.60000","4.71781","2458.61353","0.04718","0.00402","245.86136","0.00049"
"141.90000","4.72777","2460.63184","0.04728","0.00403","246.06319","0.00049"
"142.12400","4.73534","2460.88574","0.04735","0.00402","246.08858","0.00049"