File: Tension/Section_1_Group_2/PEanut_25%.is_tens_RawData/Specimen_RawData_2.csv
Time,Extension,Load,Tensile strain (Extension),Tensile stress,Strain-by-clip-gage
(s),(mm),(N),(mm/mm),(MPa),(mm/mm)
"0.00000","1.80608","2234.80273","0.01806","223.48027","0.11236"
"0.10000","1.80622","2233.82300","0.01806","223.38229","0.11237"
"0.20000","1.80652","2233.95312","0.01807","223.39531","0.11236"
"0.30000","1.80730","2234.55908","0.01807","223.45590","0.11239"
"0.40000","1.81057","2242.43286","0.01811","224.24329","0.11237"
"0.50000","1.81227","2245.55737","0.01812","224.55574","0.11238"
"0.60000","1.81405","2249.00171","0.01814","224.90018","0.11238"
"0.70000","1.81584","2252.37793","0.01816","225.23779","0.11238"
"0.80000","1.81734","2254.89502","0.01817","225.48950","0.11237"
"0.90000","1.81925","2258.45825","0.01819","225.84583","0.11239"
"1.00000","1.82068","2260.46777","0.01821","226.04678","0.11238"
"1.10000","1.82254","2263.70850","0.01823","226.37085","0.11238"
"1.20000","1.82401","2265.78589","0.01824","226.57858","0.11239"
"1.30000","1.82564","2268.25781","0.01826","226.82578","0.11238"
"1.40000","1.82746","2271.31860","0.01827","227.13187","0.11238"
"1.50000","1.82908","2273.60181","0.01829","227.36018","0.11238"
"1.60000","1.83089","2276.56128","0.01831","227.65613","0.11238"
"1.70000","1.83235","2278.31885","0.01832","227.83188","0.11239"
"1.80000","1.83414","2280.97485","0.01834","228.09749","0.11239"
"1.90000","1.83572","2283.11621","0.01836","228.31161","0.11238"
"2.00000","1.83731","2285.18970","0.01837","228.51897","0.11239"
"2.10000","1.83916","2288.00537","0.01839","228.80054","0.11239"
"2.20000","1.84073","2290.03149","0.01841","229.00314","0.11238"
"2.30000","1.84249","2292.60034","0.01842","229.26004","0.11239"
"2.40000","1.84410","2294.80127","0.01844","229.48013","0.11239"
"2.50000","1.84574","2296.94556","0.01846","229.69455","0.11239"
"2.60000","1.84746","2299.23560","0.01847","229.92355","0.11239"
"2.70000","1.84892","2300.97461","0.01849","230.09746","0.11238"
"2.80000","1.85082","2303.67651","0.01851","230.36765","0.11239"
"2.90000","1.85249","2306.02222","0.01852","230.60222","0.11239"
"3.00000","1.85410","2308.01807","0.01854","230.80180","0.11238"
"3.10000","1.85586","2310.27808","0.01856","231.02780","0.11239"
"3.20000","1.85736","2312.05542","0.01857","231.20554","0.11239"
"3.30000","1.85914","2314.47534","0.01859","231.44754","0.11239"
"3.40000","1.86067","2316.30518","0.01861","231.63052","0.11239"
"3.50000","1.86246","2318.66382","0.01862","231.86638","0.11239"
"3.60000","1.86421","2320.97827","0.01864","232.09782","0.11239"
"3.70000","1.86565","2322.40405","0.01866","232.24040","0.11239"
"3.80000","1.86762","2325.37427","0.01868","232.53743","0.11239"
"3.90000","1.86905","2326.77686","0.01869","232.67769","0.11239"
"4.00000","1.87081","2329.20435","0.01871","232.92044","0.11239"
"4.10000","1.87228","2330.63184","0.01872","233.06319","0.11239"
"4.20000","1.87410","2333.05566","0.01874","233.30557","0.11239"
"4.30000","1.87590","2335.49097","0.01876","233.54910","0.11239"
"4.40000","1.87730","2336.68140","0.01877","233.66814","0.11240"
"4.50000","1.87927","2339.50317","0.01879","233.95032","0.11239"
"4.60000","1.88063","2340.63745","0.01881","234.06375","0.11239"
"4.70000","1.88254","2343.31665","0.01883","234.33167","0.11239"
"4.80000","1.88402","2344.74927","0.01884","234.47493","0.11239"
"4.90000","1.88571","2346.68994","0.01886","234.66899","0.11239"
"5.00000","1.88757","2349.14551","0.01888","234.91455","0.11240"
"5.10000","1.88895","2350.24121","0.01889","235.02412","0.11239"
"5.20000","1.89103","2353.32104","0.01891","235.33211","0.11240"
"5.30000","1.89229","2354.03638","0.01892","235.40364","0.11240"
"5.40000","1.89413","2356.46826","0.01894","235.64682","0.11240"
"5.50000","1.89567","2357.91089","0.01896","235.79109","0.11240"
"5.60000","1.89736","2359.84277","0.01897","235.98428","0.11240"
"5.70000","1.89928","2362.42163","0.01899","236.24216","0.11240"
"5.80000","1.90064","2363.22388","0.01901","236.32239","0.11240"
"5.90000","1.90260","2365.95337","0.01903","236.59534","0.11240"
"6.00000","1.90396","2366.94019","0.01904","236.69402","0.11240"
"6.10000","1.90575","2369.17847","0.01906","236.91785","0.11240"
"6.20000","1.90741","2370.86646","0.01907","237.08664","0.11240"
"6.30000","1.90899","2372.43604","0.01909","237.24361","0.11240"
"6.40000","1.91093","2374.94580","0.01911","237.49458","0.11240"
"6.50000","1.91235","2375.90430","0.01912","237.59042","0.11240"
"6.60000","1.91425","2378.39087","0.01914","237.83908","0.11240"
"6.70000","1.91566","2379.51929","0.01916","237.95193","0.11240"
"6.80000","1.91737","2381.37964","0.01917","238.13797","0.11240"
"6.90000","1.91913","2383.25513","0.01919","238.32552","0.11240"
"7.00000","1.92070","2384.65381","0.01921","238.46538","0.11241"
"7.10000","1.92260","2387.05664","0.01923","238.70566","0.11240"
"7.20000","1.92406","2388.14282","0.01924","238.81429","0.11240"
"7.30000","1.92582","2389.96777","0.01926","238.99678","0.11240"
"7.40000","1.92746","2391.60889","0.01927","239.16089","0.11240"
"7.50000","1.92906","2393.11279","0.01929","239.31128","0.11240"
"7.60000","1.93081","2394.97876","0.01931","239.49788","0.11240"
"7.70000","1.93233","2396.23975","0.01932","239.62398","0.11240"
"7.80000","1.93420","2398.53149","0.01934","239.85315","0.11240"
"7.90000","1.93580","2399.86328","0.01936","239.98633","0.11240"
"8.00000","1.93743","2401.42993","0.01937","240.14299","0.11240"
"8.10000","1.93909","2402.90894","0.01939","240.29089","0.11240"
"8.20000","1.94064","2404.30127","0.01941","240.43013","0.11241"
"8.30000","1.94249","2406.45190","0.01942","240.64519","0.11240"
"8.40000","1.94403","2407.63721","0.01944","240.76372","0.11240"
"8.50000","1.94581","2409.64429","0.01946","240.96443","0.11241"
"8.60000","1.94744","2411.15576","0.01947","241.11557","0.11240"
"8.70000","1.94907","2412.60815","0.01949","241.26082","0.11240"
"8.80000","1.95084","2414.56836","0.01951","241.45683","0.11241"
"8.90000","1.95231","2415.46436","0.01952","241.54643","0.11240"
"9.00000","1.95415","2417.40552","0.01954","241.74055","0.11240"
"9.10000","1.95572","2418.79932","0.01956","241.87993","0.11240"
"9.20000","1.95739","2420.27686","0.01957","242.02768","0.11240"
"9.30000","1.95922","2422.38037","0.01959","242.23804","0.11240"
"9.40000","1.96064","2423.15259","0.01961","242.31526","0.11239"
"9.50000","1.96251","2425.30835","0.01963","242.53084","0.11241"
"9.60000","1.96399","2426.20703","0.01964","242.62070","0.11240"
"9.70000","1.96580","2428.17725","0.01966","242.81772","0.11240"
"9.80000","1.96749","2429.72217","0.01967","242.97221","0.11241"
"9.90000","1.96902","2430.73975","0.01969","243.07397","0.11241"
"10.00000","1.97089","2432.82178","0.01971","243.28218","0.11241"
"10.10000","1.97233","2433.73267","0.01972","243.37326","0.11241"
"10.20000","1.97421","2435.66821","0.01974","243.56682","0.11241"
"10.30000","1.97569","2436.66870","0.01976","243.66687","0.11241"
"10.40000","1.97743","2438.46411","0.01977","243.84641","0.11241"
"10.50000","1.97920","2439.99194","0.01979","243.99919","0.11241"
"10.60000","1.98067","2440.91187","0.01981","244.09119","0.11241"
"10.70000","1.98264","2443.09033","0.01983","244.30904","0.11241"
"10.80000","1.98397","2443.62256","0.01984","244.36226","0.11241"
"10.90000","1.98583","2445.34912","0.01986","244.53491","0.11241"
"11.00000","1.98737","2446.35840","0.01987","244.63583","0.11241"
"11.10000","1.98913","2448.02246","0.01989","244.80225","0.11240"
"11.20000","1.99092","2449.51929","0.01991","244.95193","0.11241"
"11.30000","1.99228","2450.19629","0.01992","245.01962","0.11241"
"11.40000","1.99427","2452.31250","0.01994","245.23125","0.11241"
"11.50000","1.99566","2452.79639","0.01996","245.27963","0.11241"
"11.60000","1.99748","2454.43530","0.01997","245.44353","0.11240"
"11.70000","1.99904","2455.58838","0.01999","245.55884","0.11241"
"11.80000","2.00071","2456.91211","0.02001","245.69121","0.11240"
"11.90000","2.00259","2458.83569","0.02003","245.88358","0.11241"
"12.00000","2.00395","2459.27148","0.02004","245.92715","0.11241"
"12.10000","2.00588","2461.23022","0.02006","246.12302","0.11241"
"12.20000","2.00730","2461.87939","0.02007","246.18794","0.11241"
"12.30000","2.00909","2463.47485","0.02009","246.34749","0.11241"
"12.40000","2.01081","2464.77368","0.02011","246.47737","0.11241"
"12.50000","2.01238","2465.99023","0.02012","246.59903","0.11241"
"12.60000","2.01425","2467.66357","0.02014","246.76636","0.11241"
"12.70000","2.01562","2468.01733","0.02016","246.80173","0.11241"
"12.80000","2.01753","2470.04932","0.02018","247.00493","0.11241"
"12.90000","2.01898","2470.73438","0.02019","247.07344","0.11241"
"13.00000","2.02071","2472.27856","0.02021","247.22786","0.11241"
"13.10000","2.02247","2473.71826","0.02022","247.37183","0.11241"
"13.20000","2.02403","2474.76221","0.02024","247.47623","0.11241"
"13.30000","2.02595","2476.63184","0.02026","247.66318","0.11241"
"13.40000","2.02736","2477.27441","0.02027","247.72745","0.11241"
"13.50000","2.02913","2478.87500","0.02029","247.88750","0.11241"
"13.60000","2.03067","2479.55420","0.02031","247.95541","0.11241"
"13.70000","2.03234","2480.85303","0.02032","248.08530","0.11241"
"13.80000","2.03423","2482.69067","0.02034","248.26907","0.11241"
"13.90000","2.03571","2483.47339","0.02036","248.34734","0.11242"
"14.00000","2.03753","2484.99219","0.02038","248.49922","0.11241"
"14.10000","2.03907","2485.90015","0.02039","248.59001","0.11241"
"14.20000","2.04078","2487.03516","0.02041","248.70352","0.11242"
"14.30000","2.04245","2488.50391","0.02042","248.85039","0.11241"
"14.40000","2.04401","2489.37598","0.02044","248.93759","0.11241"
"14.50000","2.04583","2490.95996","0.02046","249.09599","0.11241"
"14.60000","2.04735","2491.86377","0.02047","249.18637","0.11241"
"14.70000","2.04922","2493.41162","0.02049","249.34116","0.11241"
"14.80000","2.05083","2494.17358","0.02051","249.41736","0.11241"
"14.90000","2.05238","2494.54517","0.02052","249.45451","0.11242"
"15.00000","2.05412","2495.14795","0.02054","249.51480","0.11241"
"15.10000","2.05566","2494.99854","0.02056","249.49985","0.11241"
"15.20000","2.05752","2496.43652","0.02058","249.64365","0.11241"
"15.30000","2.05906","2344.62915","0.02059","234.46292","0.11240"
"15.30300","2.05912","2188.01831","0.02059","218.80183","0.11240"
"15.30600","2.05919","2000.37976","0.02059","200.03798","0.11239"
"15.30800","2.05924","1864.73853","0.02059","186.47385","0.11238"
"15.31000","2.05929","1724.47876","0.02059","172.44788","0.11236"
"15.31200","2.05935","1582.34851","0.02059","158.23485","0.11234"
"15.31400","2.05941","1440.64355","0.02059","144.06436","0.11231"