File: Tension/Section_1_Group_2/PEanut_25%.is_tens_RawData/Specimen_RawData_1.csv
Time,Extension,Load,Tensile strain (Extension),Tensile stress,Strain-by-clip-gage
(s),(mm),(N),(mm/mm),(MPa),(mm/mm)
"0.00000","0.00000","-0.56634","0.00000","-0.05663","0.00000"
"0.20000","0.00059","0.57951","0.00001","0.05795","0.00000"
"0.40000","0.00541","14.72034","0.00005","1.47203","0.00000"
"0.60000","0.00874","24.26149","0.00009","2.42615","0.00001"
"0.80000","0.01190","32.93430","0.00012","3.29343","0.00000"
"1.00000","0.01522","41.96778","0.00015","4.19678","0.00001"
"1.20000","0.01860","51.01776","0.00019","5.10178","0.00001"
"1.40000","0.02206","60.46778","0.00022","6.04678","0.00001"
"1.60000","0.02539","69.28687","0.00025","6.92869","0.00001"
"1.80000","0.02868","78.14341","0.00029","7.81434","0.00001"
"2.00000","0.03193","86.57802","0.00032","8.65780","0.00001"
"2.20000","0.03521","95.28188","0.00035","9.52819","0.00001"
"2.40000","0.03865","104.27899","0.00039","10.42790","0.00001"
"2.60000","0.04208","113.09183","0.00042","11.30918","0.00002"
"2.80000","0.04545","122.06372","0.00045","12.20637","0.00002"
"3.00000","0.04869","130.44041","0.00049","13.04404","0.00002"
"3.20000","0.05193","138.75235","0.00052","13.87523","0.00002"
"3.40000","0.05522","147.13110","0.00055","14.71311","0.00002"
"3.60000","0.05858","155.81683","0.00059","15.58168","0.00002"
"3.80000","0.06209","164.77216","0.00062","16.47721","0.00002"
"4.00000","0.06551","173.45895","0.00066","17.34590","0.00003"
"4.20000","0.06877","181.64297","0.00069","18.16430","0.00003"
"4.40000","0.07196","189.47202","0.00072","18.94720","0.00003"
"4.60000","0.07521","197.64462","0.00075","19.76446","0.00003"
"4.80000","0.07850","205.96651","0.00078","20.59665","0.00004"
"5.00000","0.08200","214.85110","0.00082","21.48511","0.00004"
"5.20000","0.08549","223.67076","0.00085","22.36708","0.00005"
"5.40000","0.08879","231.75471","0.00089","23.17547","0.00005"
"5.60000","0.09200","239.58035","0.00092","23.95803","0.00005"
"5.80000","0.09526","247.61247","0.00095","24.76125","0.00006"
"6.00000","0.09855","255.54619","0.00099","25.55462","0.00006"
"6.20000","0.10187","263.80234","0.00102","26.38023","0.00006"
"6.40000","0.10542","272.56033","0.00105","27.25603","0.00007"
"6.60000","0.10881","280.82373","0.00109","28.08237","0.00008"
"6.80000","0.11207","288.82156","0.00112","28.88216","0.00008"
"7.00000","0.11525","296.25952","0.00115","29.62595","0.00009"
"7.20000","0.11858","304.46335","0.00119","30.44633","0.00010"
"7.40000","0.12202","312.68640","0.00122","31.26864","0.00010"
"7.60000","0.12530","320.59470","0.00125","32.05947","0.00011"
"7.80000","0.12875","328.80820","0.00129","32.88082","0.00012"
"8.00000","0.13205","336.73117","0.00132","33.67312","0.00013"
"8.20000","0.13529","344.36880","0.00135","34.43688","0.00014"
"8.40000","0.13853","351.85135","0.00139","35.18513","0.00015"
"8.60000","0.14206","360.44315","0.00142","36.04432","0.00016"
"8.80000","0.14537","368.31604","0.00145","36.83160","0.00017"
"9.00000","0.14872","376.18347","0.00149","37.61835","0.00019"
"9.20000","0.15203","383.83127","0.00152","38.38313","0.00020"
"9.40000","0.15525","391.26254","0.00155","39.12626","0.00021"
"9.60000","0.15854","398.90152","0.00159","39.89015","0.00022"
"9.80000","0.16183","406.37939","0.00162","40.63794","0.00023"
"10.00000","0.16551","415.20340","0.00166","41.52034","0.00024"
"10.20000","0.16886","422.88788","0.00169","42.28879","0.00025"
"10.40000","0.17206","430.06308","0.00172","43.00631","0.00026"
"10.60000","0.17532","437.51981","0.00175","43.75198","0.00027"
"10.80000","0.17849","444.60394","0.00178","44.46040","0.00028"
"11.00000","0.18192","452.43463","0.00182","45.24346","0.00029"
"11.20000","0.18528","460.00964","0.00185","46.00097","0.00031"
"11.40000","0.18888","468.37354","0.00189","46.83735","0.00032"
"11.60000","0.19217","475.72305","0.00192","47.57230","0.00033"
"11.80000","0.19534","482.57428","0.00195","48.25743","0.00034"
"12.00000","0.19858","489.64325","0.00199","48.96432","0.00035"
"12.20000","0.20189","497.12393","0.00202","49.71239","0.00036"
"12.40000","0.20524","504.45880","0.00205","50.44588","0.00037"
"12.60000","0.20865","512.16888","0.00209","51.21689","0.00038"
"12.80000","0.21217","520.13098","0.00212","52.01310","0.00040"
"13.00000","0.21539","527.03235","0.00215","52.70324","0.00041"
"13.20000","0.21857","533.86023","0.00219","53.38602","0.00043"
"13.40000","0.22188","541.23590","0.00222","54.12359","0.00044"
"13.60000","0.22535","548.85248","0.00225","54.88525","0.00046"
"13.80000","0.22870","556.18103","0.00229","55.61810","0.00048"
"14.00000","0.23206","563.47662","0.00232","56.34766","0.00050"
"14.20000","0.23540","570.68304","0.00235","57.06831","0.00053"
"14.40000","0.23858","577.52283","0.00239","57.75228","0.00055"
"14.60000","0.24191","584.63293","0.00242","58.46329","0.00057"
"14.80000","0.24535","592.17908","0.00245","59.21791","0.00059"
"15.00000","0.24886","599.69354","0.00249","59.96935","0.00061"
"15.20000","0.25209","606.48145","0.00252","60.64814","0.00063"
"15.40000","0.25535","613.44135","0.00255","61.34414","0.00065"
"15.60000","0.25858","620.21930","0.00259","62.02193","0.00067"
"15.80000","0.26188","627.17096","0.00262","62.71709","0.00070"
"16.00000","0.26524","634.25861","0.00265","63.42586","0.00072"
"16.20000","0.26871","641.77777","0.00269","64.17778","0.00074"
"16.40000","0.27223","649.38824","0.00272","64.93883","0.00077"
"16.60000","0.27542","655.91785","0.00275","65.59178","0.00079"
"16.80000","0.27865","662.67908","0.00279","66.26791","0.00081"
"17.00000","0.28187","669.20264","0.00282","66.92027","0.00083"
"17.20000","0.28520","676.01160","0.00285","67.60116","0.00085"
"17.40000","0.28863","683.19904","0.00289","68.31990","0.00087"
"17.60000","0.29217","690.72607","0.00292","69.07261","0.00089"
"17.80000","0.29550","697.57562","0.00295","69.75756","0.00091"
"18.00000","0.29865","703.94672","0.00299","70.39467","0.00093"
"18.20000","0.30200","710.77173","0.00302","71.07717","0.00095"
"18.40000","0.30523","717.22534","0.00305","71.72253","0.00097"
"18.60000","0.30861","724.28345","0.00309","72.42834","0.00099"
"18.80000","0.31201","731.17981","0.00312","73.11798","0.00101"
"19.00000","0.31547","738.42279","0.00315","73.84228","0.00104"
"19.20000","0.31868","744.65533","0.00319","74.46553","0.00106"
"19.40000","0.32192","751.07385","0.00322","75.10738","0.00107"
"19.60000","0.32530","757.92657","0.00325","75.79266","0.00109"
"19.80000","0.32861","764.49078","0.00329","76.44908","0.00111"
"20.00000","0.33200","771.30438","0.00332","77.13044","0.00114"
"20.20000","0.33540","778.19354","0.00335","77.81935","0.00115"
"20.40000","0.33874","784.64661","0.00339","78.46466","0.00117"
"20.60000","0.34191","790.85016","0.00342","79.08501","0.00119"
"20.80000","0.34519","797.34418","0.00345","79.73442","0.00121"
"21.00000","0.34865","804.22778","0.00349","80.42278","0.00123"
"21.20000","0.35208","811.17572","0.00352","81.11757","0.00125"
"21.40000","0.35543","817.70715","0.00355","81.77071","0.00127"
"21.60000","0.35872","824.05096","0.00359","82.40510","0.00128"
"21.80000","0.36201","830.37708","0.00362","83.03770","0.00130"
"22.00000","0.36520","836.31689","0.00365","83.63169","0.00132"
"22.20000","0.36861","843.07959","0.00369","84.30796","0.00134"
"22.40000","0.37207","849.92407","0.00372","84.99241","0.00136"
"22.60000","0.37549","856.55450","0.00375","85.65545","0.00138"
"22.80000","0.37870","862.45013","0.00379","86.24501","0.00140"
"23.00000","0.38199","868.85168","0.00382","86.88517","0.00142"
"23.20000","0.38521","874.76337","0.00385","87.47633","0.00144"
"23.40000","0.38849","880.97437","0.00388","88.09743","0.00146"
"23.60000","0.39198","887.68378","0.00392","88.76838","0.00148"
"23.80000","0.39551","894.61273","0.00396","89.46127","0.00150"
"24.00000","0.39884","900.92645","0.00399","90.09264","0.00152"
"24.20000","0.40195","906.49249","0.00402","90.64925","0.00154"
"24.40000","0.40530","912.73114","0.00405","91.27312","0.00156"
"24.60000","0.40855","918.77374","0.00409","91.87737","0.00158"
"24.80000","0.41189","924.82111","0.00412","92.48211","0.00160"
"25.00000","0.41538","931.51227","0.00415","93.15123","0.00163"
"25.20000","0.41883","937.93262","0.00419","93.79326","0.00165"
"25.40000","0.42214","943.99768","0.00422","94.39977","0.00167"
"25.60000","0.42517","949.23724","0.00425","94.92372","0.00169"
"25.80000","0.42866","955.59790","0.00429","95.55979","0.00171"
"26.00000","0.43194","961.46594","0.00432","96.14659","0.00173"
"26.20000","0.43536","967.84131","0.00435","96.78413","0.00175"
"26.40000","0.43868","973.77264","0.00439","97.37727","0.00177"
"26.60000","0.44201","979.81866","0.00442","97.98186","0.00179"
"26.80000","0.44530","985.54303","0.00445","98.55431","0.00181"
"27.00000","0.44851","991.28839","0.00449","99.12884","0.00183"
"27.20000","0.45200","997.66150","0.00452","99.76615","0.00185"
"27.40000","0.45547","1003.71826","0.00455","100.37183","0.00188"
"27.60000","0.45877","1009.56885","0.00459","100.95689","0.00190"
"27.80000","0.46199","1015.16602","0.00462","101.51660","0.00192"
"28.00000","0.46530","1020.73193","0.00465","102.07320","0.00194"
"28.20000","0.46852","1026.25232","0.00469","102.62523","0.00196"
"28.40000","0.47190","1032.03247","0.00472","103.20325","0.00198"
"28.60000","0.47548","1038.77917","0.00475","103.87791","0.00200"
"28.80000","0.47889","1044.70349","0.00479","104.47035","0.00202"
"29.00000","0.48214","1050.15674","0.00482","105.01567","0.00204"
"29.20000","0.48525","1055.16028","0.00485","105.51603","0.00206"
"29.40000","0.48856","1060.91162","0.00489","106.09116","0.00208"
"29.60000","0.49181","1066.24329","0.00492","106.62433","0.00211"
"29.80000","0.49530","1072.33630","0.00495","107.23363","0.00213"
"30.00000","0.49881","1078.30774","0.00499","107.83077","0.00215"
"30.20000","0.50217","1083.93372","0.00502","108.39337","0.00217"
"30.40000","0.50533","1089.15210","0.00505","108.91521","0.00219"
"30.60000","0.50857","1094.21301","0.00509","109.42130","0.00221"
"30.80000","0.51191","1099.67566","0.00512","109.96757","0.00223"
"31.00000","0.51525","1105.26086","0.00515","110.52608","0.00225"
"31.20000","0.51872","1111.00818","0.00519","111.10081","0.00228"
"31.40000","0.52207","1116.53198","0.00522","111.65320","0.00230"
"31.60000","0.52534","1121.85974","0.00525","112.18597","0.00232"
"31.80000","0.52860","1126.94666","0.00529","112.69466","0.00234"
"32.00000","0.53195","1132.36035","0.00532","113.23604","0.00236"
"32.20000","0.53538","1137.90698","0.00535","113.79070","0.00238"
"32.40000","0.53872","1143.38989","0.00539","114.33899","0.00240"
"32.60000","0.54210","1148.71790","0.00542","114.87179","0.00243"
"32.80000","0.54534","1153.77393","0.00545","115.37740","0.00245"
"33.00000","0.54862","1158.77100","0.00549","115.87710","0.00247"
"33.20000","0.55187","1163.67346","0.00552","116.36735","0.00249"
"33.40000","0.55537","1169.34473","0.00555","116.93447","0.00251"
"33.60000","0.55874","1174.58447","0.00559","117.45845","0.00253"
"33.80000","0.56209","1179.73682","0.00562","117.97368","0.00255"
"34.00000","0.56537","1184.62476","0.00565","118.46248","0.00257"
"34.20000","0.56859","1189.37830","0.00569","118.93783","0.00259"
"34.40000","0.57186","1194.27002","0.00572","119.42700","0.00261"
"34.60000","0.57525","1199.48865","0.00575","119.94887","0.00264"
"34.80000","0.57878","1205.09534","0.00579","120.50954","0.00266"
"35.00000","0.58212","1210.15186","0.00582","121.01518","0.00268"
"35.20000","0.58539","1214.96533","0.00585","121.49654","0.00270"
"35.40000","0.58865","1219.67053","0.00589","121.96706","0.00272"
"35.60000","0.59192","1224.42456","0.00592","122.44246","0.00274"
"35.80000","0.59523","1229.23987","0.00595","122.92399","0.00276"
"36.00000","0.59866","1234.52917","0.00599","123.45292","0.00279"
"36.20000","0.60226","1240.05542","0.00602","124.00554","0.00281"
"36.40000","0.60546","1244.53064","0.00605","124.45306","0.00283"
"36.60000","0.60867","1249.04773","0.00609","124.90477","0.00285"
"36.80000","0.61191","1253.63513","0.00612","125.36351","0.00287"
"37.00000","0.61522","1258.21667","0.00615","125.82167","0.00289"
"37.20000","0.61855","1263.09778","0.00619","126.30978","0.00291"
"37.40000","0.62203","1268.34326","0.00622","126.83433","0.00294"
"37.60000","0.62548","1273.43298","0.00625","127.34330","0.00296"
"37.80000","0.62871","1277.81519","0.00629","127.78152","0.00298"
"38.00000","0.63189","1282.12476","0.00632","128.21248","0.00300"
"38.20000","0.63528","1286.97754","0.00635","128.69775","0.00302"
"38.40000","0.63866","1291.85352","0.00639","129.18535","0.00304"
"38.60000","0.64203","1296.46179","0.00642","129.64618","0.00307"
"38.80000","0.64538","1301.18201","0.00645","130.11819","0.00309"
"39.00000","0.64869","1305.55347","0.00649","130.55534","0.00311"
"39.20000","0.65196","1310.13818","0.00652","131.01382","0.00313"
"39.40000","0.65521","1314.50745","0.00655","131.45074","0.00315"
"39.60000","0.65874","1319.65601","0.00659","131.96561","0.00317"
"39.80000","0.66219","1324.53162","0.00662","132.45316","0.00320"
"40.00000","0.66537","1328.55469","0.00665","132.85547","0.00322"
"40.20000","0.66869","1333.10388","0.00669","133.31039","0.00324"
"40.40000","0.67189","1337.04016","0.00672","133.70401","0.00326"
"40.60000","0.67520","1341.46936","0.00675","134.14694","0.00328"
"40.80000","0.67856","1346.11609","0.00679","134.61160","0.00330"
"41.00000","0.68212","1351.23669","0.00682","135.12367","0.00333"
"41.20000","0.68558","1355.99756","0.00686","135.59976","0.00335"
"41.40000","0.68870","1359.73218","0.00689","135.97322","0.00337"
"41.60000","0.69194","1363.94470","0.00692","136.39447","0.00339"
"41.80000","0.69523","1368.15015","0.00695","136.81502","0.00341"
"42.00000","0.69853","1372.36133","0.00699","137.23613","0.00343"
"42.20000","0.70197","1376.98962","0.00702","137.69896","0.00345"
"42.40000","0.70548","1381.86621","0.00705","138.18661","0.00348"
"42.60000","0.70882","1386.29065","0.00709","138.62906","0.00350"
"42.80000","0.71197","1389.87439","0.00712","138.98744","0.00352"
"43.00000","0.71527","1393.98718","0.00715","139.39871","0.00354"
"43.20000","0.71862","1398.36084","0.00719","139.83609","0.00356"
"43.40000","0.72199","1402.61206","0.00722","140.26120","0.00358"
"43.60000","0.72536","1406.97168","0.00725","140.69717","0.00360"
"43.80000","0.72878","1411.43311","0.00729","141.14331","0.00362"
"44.00000","0.73202","1415.20715","0.00732","141.52072","0.00365"
"44.20000","0.73522","1419.09875","0.00735","141.90988","0.00366"
"44.40000","0.73862","1423.41284","0.00739","142.34128","0.00369"
"44.60000","0.74200","1427.70703","0.00742","142.77071","0.00371"
"44.80000","0.74540","1431.97522","0.00745","143.19753","0.00373"
"45.00000","0.74873","1436.11621","0.00749","143.61162","0.00375"
"45.20000","0.75198","1439.87097","0.00752","143.98709","0.00377"
"45.40000","0.75524","1443.77905","0.00755","144.37790","0.00379"
"45.60000","0.75852","1447.62390","0.00759","144.76239","0.00381"
"45.80000","0.76205","1452.27661","0.00762","145.22766","0.00384"
"46.00000","0.76545","1456.45154","0.00765","145.64516","0.00386"
"46.20000","0.76877","1460.49402","0.00769","146.04941","0.00388"
"46.40000","0.77202","1464.21460","0.00772","146.42146","0.00390"
"46.60000","0.77526","1467.81750","0.00775","146.78175","0.00392"
"46.80000","0.77855","1471.59741","0.00779","147.15974","0.00394"
"47.00000","0.78194","1475.78320","0.00782","147.57832","0.00396"
"47.20000","0.78543","1480.28992","0.00785","148.02899","0.00399"
"47.40000","0.78883","1484.31836","0.00789","148.43184","0.00401"
"47.60000","0.79205","1487.91394","0.00792","148.79140","0.00403"
"47.80000","0.79530","1491.52954","0.00795","149.15295","0.00405"
"48.00000","0.79855","1495.28918","0.00799","149.52892","0.00407"
"48.20000","0.80185","1499.09033","0.00802","149.90903","0.00409"
"48.40000","0.80535","1503.52283","0.00805","150.35228","0.00411"
"48.60000","0.80881","1507.67383","0.00809","150.76738","0.00414"
"48.80000","0.81209","1511.33154","0.00812","151.13315","0.00416"
"49.00000","0.81530","1514.91418","0.00815","151.49142","0.00418"
"49.20000","0.81861","1518.66553","0.00819","151.86655","0.00420"
"49.40000","0.82192","1522.36523","0.00822","152.23653","0.00422"
"49.60000","0.82523","1526.03088","0.00825","152.60309","0.00424"
"49.80000","0.82878","1530.39355","0.00829","153.03935","0.00427"
"50.00000","0.83212","1534.14246","0.00832","153.41425","0.00429"
"50.20000","0.83537","1537.58533","0.00835","153.75853","0.00431"
"50.40000","0.83857","1541.04028","0.00839","154.10403","0.00433"
"50.60000","0.84192","1544.79358","0.00842","154.47935","0.00435"
"50.80000","0.84538","1548.93225","0.00845","154.89322","0.00437"
"51.00000","0.84867","1552.47668","0.00849","155.24767","0.00439"
"51.20000","0.85210","1556.30566","0.00852","155.63057","0.00441"
"51.40000","0.85536","1559.66418","0.00855","155.96642","0.00443"
"51.60000","0.85861","1563.06641","0.00859","156.30664","0.00445"
"51.80000","0.86186","1566.53687","0.00862","156.65369","0.00447"
"52.00000","0.86542","1570.71033","0.00865","157.07103","0.00450"
"52.20000","0.86876","1574.31702","0.00869","157.43170","0.00452"
"52.40000","0.87206","1577.84448","0.00872","157.78445","0.00454"
"52.60000","0.87534","1581.14954","0.00875","158.11496","0.00456"
"52.80000","0.87856","1584.22400","0.00879","158.42239","0.00458"
"53.00000","0.88187","1587.63196","0.00882","158.76320","0.00460"
"53.20000","0.88519","1590.81726","0.00885","159.08173","0.00462"
"53.40000","0.88887","1595.01904","0.00889","159.50191","0.00464"
"53.60000","0.89219","1598.18420","0.00892","159.81842","0.00466"
"53.80000","0.89536","1600.80493","0.00895","160.08049","0.00468"
"54.00000","0.89864","1603.74683","0.00899","160.37468","0.00470"
"54.20000","0.90184","1606.47205","0.00902","160.64720","0.00471"
"54.40000","0.90527","1609.69885","0.00905","160.96988","0.00473"
"54.60000","0.90864","1612.99329","0.00909","161.29933","0.00475"
"54.80000","0.91220","1616.57227","0.00912","161.65723","0.00477"
"55.00000","0.91547","1619.43542","0.00915","161.94354","0.00479"
"55.20000","0.91862","1621.81458","0.00919","162.18146","0.00481"
"55.40000","0.92191","1624.75427","0.00922","162.47543","0.00483"
"55.60000","0.92524","1627.71069","0.00925","162.77107","0.00484"
"55.80000","0.92861","1630.65588","0.00929","163.06558","0.00486"
"56.00000","0.93200","1633.97961","0.00932","163.39796","0.00488"
"56.20000","0.93547","1637.27686","0.00935","163.72769","0.00490"
"56.40000","0.93868","1639.82251","0.00939","163.98225","0.00492"
"56.60000","0.94188","1642.27185","0.00942","164.22719","0.00494"
"56.80000","0.94527","1645.40686","0.00945","164.54068","0.00496"
"57.00000","0.94872","1648.70825","0.00949","164.87082","0.00498"
"57.20000","0.95205","1651.74231","0.00952","165.17422","0.00499"
"57.40000","0.95540","1654.73999","0.00955","165.47400","0.00501"
"57.60000","0.95870","1657.61560","0.00959","165.76157","0.00503"
"57.80000","0.96189","1660.28064","0.00962","166.02806","0.00505"
"58.00000","0.96525","1663.32886","0.00965","166.33289","0.00507"
"58.20000","0.96870","1666.57031","0.00969","166.65703","0.00509"
"58.40000","0.97221","1670.13440","0.00972","167.01344","0.00511"
"58.60000","0.97541","1672.82861","0.00975","167.28287","0.00513"
"58.80000","0.97867","1675.82739","0.00979","167.58273","0.00515"
"59.00000","0.98190","1678.51770","0.00982","167.85178","0.00516"
"59.20000","0.98520","1681.50659","0.00985","168.15067","0.00518"
"59.40000","0.98860","1684.71985","0.00989","168.47198","0.00520"
"59.60000","0.99208","1688.18408","0.00992","168.81841","0.00522"
"59.80000","0.99555","1691.59583","0.00996","169.15958","0.00524"
"60.00000","0.99872","1694.18176","0.00999","169.41818","0.00526"
"60.20000","1.00197","1697.13306","0.01002","169.71330","0.00528"
"60.40000","1.00521","1699.86414","0.01005","169.98642","0.00530"
"60.60000","1.00854","1703.05371","0.01009","170.30537","0.00532"
"60.80000","1.01199","1706.40759","0.01012","170.64076","0.00534"
"61.00000","1.01551","1710.07434","0.01016","171.00743","0.00536"
"61.20000","1.01879","1713.04126","0.01019","171.30412","0.00538"
"61.40000","1.02195","1715.65735","0.01022","171.56573","0.00540"
"61.60000","1.02532","1718.68787","0.01025","171.86879","0.00542"
"61.80000","1.02858","1721.74463","0.01029","172.17447","0.00544"
"62.00000","1.03201","1725.16858","0.01032","172.51686","0.00546"
"62.20000","1.03535","1728.19666","0.01035","172.81967","0.00548"
"62.40000","1.03877","1731.60010","0.01039","173.16000","0.00550"
"62.60000","1.04198","1734.31238","0.01042","173.43124","0.00552"
"62.80000","1.04523","1737.31079","0.01045","173.73108","0.00554"
"63.00000","1.04866","1740.69995","0.01049","174.06999","0.00556"
"63.20000","1.05198","1743.85229","0.01052","174.38522","0.00558"
"63.40000","1.05537","1747.10168","0.01055","174.71017","0.00560"
"63.60000","1.05873","1750.21289","0.01059","175.02129","0.00562"
"63.80000","1.06201","1753.14844","0.01062","175.31485","0.00564"
"64.00000","1.06523","1755.95752","0.01065","175.59575","0.00566"
"64.20000","1.06855","1759.01709","0.01069","175.90170","0.00568"
"64.40000","1.07200","1762.47583","0.01072","176.24759","0.00570"
"64.60000","1.07548","1766.06982","0.01075","176.60698","0.00572"
"64.80000","1.07878","1768.92822","0.01079","176.89282","0.00574"
"65.00000","1.08201","1771.73962","0.01082","177.17397","0.00576"
"65.20000","1.08533","1774.74768","0.01085","177.47476","0.00578"
"65.40000","1.08850","1777.32312","0.01089","177.73232","0.00580"
"65.60000","1.09198","1780.86890","0.01092","178.08688","0.00582"
"65.80000","1.09544","1784.32349","0.01095","178.43234","0.00584"
"66.00000","1.09881","1787.47827","0.01099","178.74783","0.00586"
"66.20000","1.10203","1790.35291","0.01102","179.03529","0.00588"
"66.40000","1.10532","1793.26111","0.01105","179.32611","0.00590"
"66.60000","1.10855","1796.20215","0.01109","179.62021","0.00592"
"66.80000","1.11187","1799.21069","0.01112","179.92107","0.00594"
"67.00000","1.11531","1802.62268","0.01115","180.26227","0.00596"
"67.20000","1.11885","1806.20032","0.01119","180.62003","0.00599"
"67.40000","1.12215","1809.21631","0.01122","180.92163","0.00601"
"67.60000","1.12524","1811.76270","0.01125","181.17627","0.00603"
"67.80000","1.12862","1814.75562","0.01129","181.47556","0.00605"
"68.00000","1.13191","1817.71252","0.01132","181.77126","0.00607"
"68.20000","1.13525","1820.91785","0.01135","182.09178","0.00609"
"68.40000","1.13876","1824.40881","0.01139","182.44089","0.00611"
"68.60000","1.14210","1827.42163","0.01142","182.74216","0.00613"
"68.80000","1.14543","1830.50781","0.01145","183.05078","0.00615"
"69.00000","1.14852","1832.84082","0.01149","183.28409","0.00617"
"69.20000","1.15202","1836.45117","0.01152","183.64511","0.00620"
"69.40000","1.15534","1839.51501","0.01155","183.95151","0.00622"
"69.60000","1.15872","1842.74243","0.01159","184.27425","0.00624"
"69.80000","1.16202","1845.71948","0.01162","184.57195","0.00626"
"70.00000","1.16532","1848.50854","0.01165","184.85086","0.00628"
"70.20000","1.16861","1851.33716","0.01169","185.13371","0.00630"
"70.40000","1.17186","1854.21143","0.01172","185.42114","0.00632"
"70.60000","1.17538","1857.79480","0.01175","185.77948","0.00634"
"70.80000","1.17880","1861.03210","0.01179","186.10321","0.00637"
"71.00000","1.18211","1864.04846","0.01182","186.40485","0.00639"
"71.20000","1.18530","1866.65747","0.01185","186.66574","0.00641"
"71.40000","1.18860","1869.57703","0.01189","186.95770","0.00643"
"71.60000","1.19185","1872.26660","0.01192","187.22665","0.00645"
"71.80000","1.19522","1875.37109","0.01195","187.53711","0.00647"
"72.00000","1.19885","1879.29529","0.01199","187.92953","0.00649"
"72.20000","1.20219","1882.15564","0.01202","188.21556","0.00651"
"72.40000","1.20542","1885.00916","0.01205","188.50092","0.00653"
"72.60000","1.20859","1887.45032","0.01209","188.74503","0.00655"
"72.80000","1.21194","1890.53711","0.01212","189.05371","0.00657"
"73.00000","1.21520","1893.23633","0.01215","189.32364","0.00659"
"73.20000","1.21867","1896.60754","0.01219","189.66075","0.00662"
"73.40000","1.22213","1899.97388","0.01222","189.99739","0.00664"
"73.60000","1.22546","1902.77905","0.01225","190.27791","0.00666"
"73.80000","1.22863","1905.18091","0.01229","190.51810","0.00668"
"74.00000","1.23189","1907.93018","0.01232","190.79301","0.00670"
"74.20000","1.23525","1910.90149","0.01235","191.09015","0.00672"
"74.40000","1.23862","1913.95435","0.01239","191.39543","0.00674"
"74.60000","1.24208","1917.30615","0.01242","191.73062","0.00677"
"74.80000","1.24539","1920.10901","0.01245","192.01089","0.00679"
"75.00000","1.24867","1922.96191","0.01249","192.29619","0.00681"
"75.20000","1.25191","1925.41589","0.01252","192.54160","0.00683"
"75.40000","1.25529","1928.56067","0.01255","192.85606","0.00685"
"75.60000","1.25876","1931.82104","0.01259","193.18210","0.00687"
"75.80000","1.26208","1934.59949","0.01262","193.45995","0.00689"
"76.00000","1.26543","1937.44751","0.01265","193.74475","0.00691"
"76.20000","1.26863","1939.83484","0.01269","193.98349","0.00693"
"76.40000","1.27194","1942.53906","0.01272","194.25391","0.00695"
"76.60000","1.27521","1945.20764","0.01275","194.52077","0.00697"
"76.80000","1.27872","1948.64612","0.01279","194.86461","0.00699"
"77.00000","1.28211","1951.57642","0.01282","195.15764","0.00702"
"77.20000","1.28543","1954.37769","0.01285","195.43777","0.00704"
"77.40000","1.28869","1957.14343","0.01289","195.71434","0.00706"
"77.60000","1.29189","1959.53088","0.01292","195.95309","0.00708"
"77.80000","1.29518","1962.20813","0.01295","196.22081","0.00710"
"78.00000","1.29860","1965.14648","0.01299","196.51465","0.00712"
"78.20000","1.30215","1968.66406","0.01302","196.86641","0.00715"
"78.40000","1.30547","1971.34497","0.01305","197.13449","0.00718"
"78.60000","1.30871","1973.91064","0.01309","197.39107","0.00720"
"78.80000","1.31198","1976.40588","0.01312","197.64059","0.00722"
"79.00000","1.31526","1978.96692","0.01315","197.89670","0.00724"
"79.20000","1.31857","1981.71143","0.01319","198.17114","0.00726"
"79.40000","1.32201","1984.65417","0.01322","198.46542","0.00728"
"79.60000","1.32556","1988.02539","0.01326","198.80254","0.00730"
"79.80000","1.32874","1990.15100","0.01329","199.01511","0.00732"
"80.00000","1.33196","1992.70044","0.01332","199.27005","0.00734"
"80.20000","1.33524","1995.40686","0.01335","199.54068","0.00736"
"80.40000","1.33861","1998.20068","0.01339","199.82007","0.00738"
"80.60000","1.34193","2000.95850","0.01342","200.09586","0.00740"
"80.80000","1.34539","2004.02734","0.01345","200.40274","0.00743"
"81.00000","1.34878","2006.85425","0.01349","200.68542","0.00745"
"81.20000","1.35200","2009.25488","0.01352","200.92549","0.00747"
"81.40000","1.35520","2011.50330","0.01355","201.15033","0.00749"
"81.60000","1.35863","2014.49207","0.01359","201.44920","0.00751"
"81.80000","1.36203","2017.32959","0.01362","201.73296","0.00753"
"82.00000","1.36538","2020.00232","0.01365","202.00023","0.00755"
"82.20000","1.36871","2022.78564","0.01369","202.27856","0.00757"
"82.40000","1.37199","2025.12366","0.01372","202.51236","0.00759"
"82.60000","1.37526","2027.75000","0.01375","202.77499","0.00761"
"82.80000","1.37855","2030.21838","0.01379","203.02184","0.00763"
"83.00000","1.38210","2033.68738","0.01382","203.36874","0.00766"
"83.20000","1.38555","2036.68384","0.01386","203.66838","0.00768"
"83.40000","1.38869","2038.79602","0.01389","203.87961","0.00770"
"83.60000","1.39201","2041.43640","0.01392","204.14365","0.00772"
"83.80000","1.39520","2043.50208","0.01395","204.35020","0.00774"
"84.00000","1.39851","2046.07861","0.01399","204.60786","0.00776"
"84.20000","1.40191","2048.96289","0.01402","204.89629","0.00778"
"84.40000","1.40549","2052.44653","0.01405","205.24466","0.00781"
"84.60000","1.40894","2055.28418","0.01409","205.52841","0.00783"
"84.80000","1.41202","2057.23022","0.01412","205.72302","0.00785"
"85.00000","1.41527","2059.63330","0.01415","205.96333","0.00787"
"85.20000","1.41855","2062.08862","0.01419","206.20886","0.00789"
"85.40000","1.42188","2064.85571","0.01422","206.48557","0.00791"
"85.60000","1.42533","2067.76978","0.01425","206.77698","0.00793"
"85.80000","1.42881","2070.79907","0.01429","207.07991","0.00796"
"86.00000","1.43214","2073.39282","0.01432","207.33928","0.00798"
"86.20000","1.43527","2075.33228","0.01435","207.53323","0.00800"
"86.40000","1.43862","2078.09497","0.01439","207.80949","0.00802"
"86.60000","1.44197","2080.77637","0.01442","208.07764","0.00804"
"86.80000","1.44534","2083.57080","0.01445","208.35709","0.00806"
"87.00000","1.44871","2086.26978","0.01449","208.62698","0.00809"
"87.20000","1.45209","2088.98828","0.01452","208.89883","0.00811"
"87.40000","1.45531","2091.25610","0.01455","209.12561","0.00813"
"87.60000","1.45855","2093.74365","0.01459","209.37436","0.00815"
"87.80000","1.46194","2096.42529","0.01462","209.64253","0.00817"
"88.00000","1.46536","2099.28418","0.01465","209.92842","0.00819"
"88.20000","1.46875","2102.18018","0.01469","210.21802","0.00822"
"88.40000","1.47203","2104.67285","0.01472","210.46729","0.00824"
"88.60000","1.47529","2107.10864","0.01475","210.71086","0.00826"
"88.80000","1.47855","2109.45728","0.01479","210.94572","0.00828"
"89.00000","1.48187","2111.93506","0.01482","211.19351","0.00830"
"89.20000","1.48542","2115.14502","0.01485","211.51450","0.00832"
"89.40000","1.48882","2117.81104","0.01489","211.78110","0.00835"
"89.60000","1.49212","2120.39160","0.01492","212.03915","0.00837"
"89.80000","1.49533","2122.60229","0.01495","212.26022","0.00839"
"90.00000","1.49856","2124.91333","0.01499","212.49133","0.00841"
"90.20000","1.50187","2127.44092","0.01502","212.74409","0.00843"
"90.40000","1.50529","2130.19458","0.01505","213.01945","0.00845"
"90.60000","1.50881","2133.39673","0.01509","213.33968","0.00848"
"90.80000","1.51218","2136.01758","0.01512","213.60176","0.00850"
"91.00000","1.51535","2138.14282","0.01515","213.81429","0.00852"
"91.20000","1.51861","2140.59399","0.01519","214.05940","0.00854"
"91.40000","1.52188","2142.93628","0.01522","214.29362","0.00856"
"91.60000","1.52519","2145.43799","0.01525","214.54379","0.00858"
"91.80000","1.52872","2148.52490","0.01529","214.85249","0.00860"
"92.00000","1.53216","2151.23633","0.01532","215.12363","0.00863"
"92.20000","1.53542","2153.47900","0.01535","215.34790","0.00865"
"92.40000","1.53861","2155.55981","0.01539","215.55598","0.00867"
"92.60000","1.54194","2158.10278","0.01542","215.81027","0.00869"
"92.80000","1.54526","2160.53369","0.01545","216.05338","0.00871"
"93.00000","1.54859","2163.06348","0.01549","216.30635","0.00873"
"93.20000","1.55211","2166.19214","0.01552","216.61922","0.00876"
"93.40000","1.55543","2168.65698","0.01555","216.86569","0.00878"
"93.60000","1.55867","2170.91675","0.01559","217.09167","0.00880"
"93.80000","1.56190","2173.17578","0.01562","217.31758","0.00882"
"94.00000","1.56529","2175.85571","0.01565","217.58557","0.00884"
"94.20000","1.56876","2178.77002","0.01569","217.87700","0.00886"
"94.40000","1.57203","2181.31055","0.01572","218.13106","0.00888"
"94.60000","1.57543","2183.82690","0.01575","218.38269","0.00891"
"94.80000","1.57866","2186.02466","0.01579","218.60246","0.00893"
"95.00000","1.58191","2188.20679","0.01582","218.82068","0.00895"
"95.20000","1.58520","2190.72461","0.01585","219.07246","0.00897"
"95.40000","1.58877","2193.81567","0.01589","219.38156","0.00899"
"95.60000","1.59211","2196.23560","0.01592","219.62357","0.00901"
"95.80000","1.59538","2198.70850","0.01595","219.87085","0.00904"
"96.00000","1.59866","2200.96216","0.01599","220.09622","0.00906"
"96.20000","1.60187","2203.04785","0.01602","220.30478","0.00908"
"96.40000","1.60518","2205.60254","0.01605","220.56026","0.00910"
"96.60000","1.60856","2208.27197","0.01609","220.82719","0.00912"
"96.80000","1.61223","2211.63916","0.01612","221.16391","0.00915"
"97.00000","1.61552","2214.03687","0.01616","221.40369","0.00917"
"97.20000","1.61869","2216.09424","0.01619","221.60942","0.00919"
"97.40000","1.62197","2218.32178","0.01622","221.83218","0.00921"
"97.60000","1.62517","2220.47876","0.01625","222.04788","0.00923"
"97.80000","1.62862","2223.25830","0.01629","222.32584","0.00925"
"98.00000","1.63199","2225.78076","0.01632","222.57808","0.00927"
"98.20000","1.63554","2228.94580","0.01636","222.89458","0.00930"
"98.40000","1.63879","2231.24463","0.01639","223.12447","0.00932"
"98.60000","1.64192","2233.06128","0.01642","223.30612","0.00934"
"98.80000","1.64526","2235.53491","0.01645","223.55350","0.00936"
"99.00000","1.64860","2237.96509","0.01649","223.79651","0.00938"
"99.20000","1.65196","2240.51367","0.01652","224.05136","0.00941"
"99.40000","1.65535","2243.10742","0.01655","224.31075","0.00943"
"99.60000","1.65877","2245.76660","0.01659","224.57666","0.00945"
"99.80000","1.66199","2247.93115","0.01662","224.79312","0.00947"
"100.00000","1.66521","2250.05469","0.01665","225.00546","0.00949"
"100.20000","1.66862","2252.63647","0.01669","225.26364","0.00951"
"100.40000","1.67212","2255.30420","0.01672","225.53043","0.00954"
"100.60000","1.67541","2257.81348","0.01675","225.78134","0.00956"
"100.80000","1.67871","2260.14209","0.01679","226.01421","0.00958"
"101.00000","1.68199","2262.29004","0.01682","226.22900","0.00960"
"101.20000","1.68518","2264.38281","0.01685","226.43828","0.00962"
"101.40000","1.68859","2266.88330","0.01689","226.68832","0.00964"
"101.60000","1.69207","2269.78003","0.01692","226.97800","0.00967"
"101.80000","1.69556","2272.73535","0.01696","227.27353","0.00969"
"102.00000","1.69875","2274.83350","0.01699","227.48335","0.00971"
"102.20000","1.70199","2276.93970","0.01702","227.69397","0.00973"
"102.40000","1.70521","2278.97412","0.01705","227.89742","0.00975"
"102.60000","1.70853","2281.26562","0.01709","228.12656","0.00977"
"102.80000","1.71194","2283.92578","0.01712","228.39258","0.00980"
"103.00000","1.71542","2286.69824","0.01715","228.66983","0.00982"
"103.20000","1.71888","2289.44287","0.01719","228.94429","0.00984"
"103.40000","1.72201","2291.14648","0.01722","229.11465","0.00986"
"103.60000","1.72529","2293.52441","0.01725","229.35245","0.00988"
"103.80000","1.72854","2295.62866","0.01729","229.56287","0.00991"
"104.00000","1.73190","2298.03638","0.01732","229.80363","0.00993"
"104.20000","1.73534","2300.70996","0.01735","230.07100","0.00995"
"104.40000","1.73882","2303.44897","0.01739","230.34489","0.00998"
"104.60000","1.74210","2305.73218","0.01742","230.57321","0.01000"
"104.80000","1.74526","2307.62329","0.01745","230.76233","0.01002"
"105.00000","1.74868","2310.35034","0.01749","231.03503","0.01004"
"105.20000","1.75195","2312.33862","0.01752","231.23386","0.01006"
"105.40000","1.75535","2314.93677","0.01755","231.49368","0.01008"
"105.60000","1.75872","2317.42383","0.01759","231.74239","0.01011"
"105.80000","1.76208","2319.70947","0.01762","231.97095","0.01013"
"106.00000","1.76529","2321.77075","0.01765","232.17708","0.01015"
"106.20000","1.76854","2323.89233","0.01769","232.38924","0.01017"
"106.40000","1.77200","2326.66504","0.01772","232.66650","0.01019"
"106.60000","1.77535","2328.96777","0.01775","232.89677","0.01021"
"106.80000","1.77872","2331.57837","0.01779","233.15784","0.01024"
"107.00000","1.78204","2333.82324","0.01782","233.38232","0.01026"
"107.20000","1.78532","2335.90015","0.01785","233.59001","0.01028"
"107.40000","1.78854","2337.91553","0.01789","233.79155","0.01030"
"107.60000","1.79190","2340.19971","0.01792","234.01997","0.01032"
"107.80000","1.79539","2342.92871","0.01795","234.29288","0.01035"
"108.00000","1.79881","2345.43262","0.01799","234.54326","0.01037"
"108.20000","1.80212","2347.63306","0.01802","234.76331","0.01039"
"108.40000","1.80534","2349.44141","0.01805","234.94414","0.01041"