File: Tension/Section_2_Group_4/f7a_1.is_tens_RawData/Specimen_RawData_1.csv
Time,Extension,Load,Tensile strain (Extension),Tensile stress,Strain-by-clip-gage
(s),(mm),(N),(mm/mm),(MPa),(mm/mm)
"0.00000","0.00000","-1.29782","0.00000","-0.12978","0.00003"
"0.20000","0.00313","18.70145","0.00003","1.87015","0.00000"
"0.40000","0.01097","67.20304","0.00011","6.72030","0.00001"
"0.60000","0.01790","107.22872","0.00018","10.72287","0.00001"
"0.80000","0.02453","143.38257","0.00025","14.33826","-0.00002"
"1.00000","0.03124","177.84801","0.00031","17.78480","0.00003"
"1.20000","0.03793","210.07262","0.00038","21.00726","0.00000"
"1.40000","0.04449","241.31122","0.00044","24.13112","-0.00001"
"1.60000","0.05114","272.79086","0.00051","27.27909","0.00002"
"1.80000","0.05769","303.44067","0.00058","30.34407","-0.00001"
"2.00000","0.06458","335.90582","0.00065","33.59058","0.00000"
"2.20000","0.07108","365.56610","0.00071","36.55661","0.00000"
"2.40000","0.07783","396.31259","0.00078","39.63126","-0.00001"
"2.60000","0.08461","426.92752","0.00085","42.69275","0.00001"
"2.80000","0.09115","455.24576","0.00091","45.52457","0.00000"
"3.00000","0.09791","484.58160","0.00098","48.45816","0.00000"
"3.20000","0.10447","512.50470","0.00104","51.25047","0.00000"
"3.40000","0.11121","541.16992","0.00111","54.11699","0.00000"
"3.60000","0.11779","568.55212","0.00118","56.85521","0.00000"
"3.80000","0.12444","596.33313","0.00124","59.63331","0.00000"
"4.00000","0.13112","623.92426","0.00131","62.39243","-0.00001"
"4.20000","0.13778","651.00128","0.00138","65.10013","-0.00001"
"4.40000","0.14464","678.74158","0.00145","67.87416","0.00000"
"4.60000","0.15122","704.83557","0.00151","70.48356","0.00000"
"4.80000","0.15783","730.71039","0.00158","73.07104","0.00000"
"5.00000","0.16455","757.22144","0.00165","75.72215","0.00000"
"5.20000","0.17110","781.96936","0.00171","78.19694","-0.00001"
"5.40000","0.17775","807.17615","0.00178","80.71761","0.00000"
"5.60000","0.18442","832.18890","0.00184","83.21889","0.00000"
"5.80000","0.19120","857.34540","0.00191","85.73454","-0.00001"
"6.00000","0.19786","881.54694","0.00198","88.15469","0.00000"
"6.20000","0.20448","905.36328","0.00204","90.53633","0.00000"
"6.40000","0.21127","930.13916","0.00211","93.01392","0.00000"
"6.60000","0.21771","952.49841","0.00218","95.24984","0.00001"
"6.80000","0.22455","976.79480","0.00225","97.67948","0.00000"
"7.00000","0.23112","999.25128","0.00231","99.92513","-0.00001"
"7.20000","0.23781","1022.00677","0.00238","102.20068","0.00000"
"7.40000","0.24459","1045.38599","0.00245","104.53860","0.00000"
"7.60000","0.25108","1066.61560","0.00251","106.66156","0.00000"
"7.80000","0.25779","1088.86401","0.00258","108.88640","0.00000"
"8.00000","0.26447","1111.09412","0.00264","111.10941","0.00000"
"8.20000","0.27138","1134.29138","0.00271","113.42914","0.00001"
"8.40000","0.27787","1154.61438","0.00278","115.46144","0.00001"
"8.60000","0.28445","1175.09351","0.00284","117.50935","0.00000"
"8.80000","0.29125","1197.09851","0.00291","119.70985","0.00000"
"9.00000","0.29768","1216.20422","0.00298","121.62042","0.00000"
"9.20000","0.30458","1238.25403","0.00305","123.82540","0.00000"
"9.40000","0.31113","1257.84338","0.00311","125.78434","0.00001"
"9.60000","0.31794","1278.75488","0.00318","127.87549","0.00000"
"9.80000","0.32457","1298.58838","0.00325","129.85884","-0.00001"
"10.00000","0.33121","1318.02307","0.00331","131.80231","0.00000"
"10.20000","0.33784","1337.46631","0.00338","133.74663","0.00001"
"10.40000","0.34437","1356.30908","0.00344","135.63091","0.00000"
"10.60000","0.35125","1377.20325","0.00351","137.72032","-0.00001"
"10.80000","0.35779","1395.42871","0.00358","139.54288","-0.00001"
"11.00000","0.36445","1414.23193","0.00364","141.42319","0.00000"
"11.20000","0.37122","1433.46655","0.00371","143.34665","0.00000"
"11.40000","0.37777","1451.23010","0.00378","145.12302","0.00000"
"11.60000","0.38450","1470.05750","0.00385","147.00575","-0.00001"
"11.80000","0.39118","1488.68323","0.00391","148.86832","-0.00001"
"12.00000","0.39794","1507.26257","0.00398","150.72626","0.00000"
"12.20000","0.40447","1524.25977","0.00404","152.42598","0.00000"
"12.40000","0.41110","1541.53430","0.00411","154.15343","0.00000"
"12.60000","0.41786","1559.58496","0.00418","155.95850","0.00000"
"12.80000","0.42438","1576.20496","0.00424","157.62050","0.00000"
"13.00000","0.43120","1594.43433","0.00431","159.44344","0.00000"
"13.20000","0.43785","1611.63977","0.00438","161.16397","0.00001"
"13.40000","0.44449","1628.13184","0.00444","162.81319","0.00000"
"13.60000","0.45125","1645.38770","0.00451","164.53877","0.00000"
"13.80000","0.45780","1660.86316","0.00458","166.08632","0.00000"
"14.00000","0.46446","1676.91724","0.00464","167.69173","0.00000"
"14.20000","0.47105","1692.79749","0.00471","169.27975","0.00000"
"14.40000","0.47790","1709.86572","0.00478","170.98657","0.00000"
"14.60000","0.48449","1725.34399","0.00484","172.53439","0.00000"
"14.80000","0.49112","1740.90308","0.00491","174.09030","0.00000"
"15.00000","0.49798","1757.47009","0.00498","175.74701","0.00000"
"15.20000","0.50443","1771.38879","0.00504","177.13889","0.00000"
"15.40000","0.51117","1786.80835","0.00511","178.68083","-0.00001"
"15.60000","0.51780","1801.54932","0.00518","180.15494","-0.00001"
"15.80000","0.52453","1816.52368","0.00525","181.65237","0.00000"
"16.00000","0.53117","1831.28979","0.00531","183.12898","0.00001"
"16.20000","0.53780","1845.51929","0.00538","184.55193","-0.00001"
"16.40000","0.54453","1860.24573","0.00545","186.02457","0.00000"
"16.60000","0.55108","1873.80872","0.00551","187.38087","-0.00001"
"16.80000","0.55800","1889.24963","0.00558","188.92496","0.00000"
"17.00000","0.56448","1901.99609","0.00564","190.19962","0.00001"
"17.20000","0.57112","1915.52063","0.00571","191.55206","0.00000"
"17.40000","0.57791","1930.00134","0.00578","193.00014","0.00000"
"17.60000","0.58445","1942.38428","0.00584","194.23843","0.00000"
"17.80000","0.59109","1955.29102","0.00591","195.52910","0.00000"
"18.00000","0.59778","1968.31128","0.00598","196.83113","0.00000"
"18.20000","0.60457","1982.12659","0.00605","198.21266","0.00000"
"18.40000","0.61119","1994.49683","0.00611","199.44968","0.00000"
"18.60000","0.61778","2006.47095","0.00618","200.64709","0.00000"
"18.80000","0.62456","2019.23218","0.00625","201.92322","0.00001"
"19.00000","0.63111","2030.57715","0.00631","203.05771","0.00000"
"19.20000","0.63789","2043.08350","0.00638","204.30835","0.00000"
"19.40000","0.64446","2054.34717","0.00644","205.43472","0.00000"
"19.60000","0.65108","2065.60474","0.00651","206.56047","0.00000"
"19.80000","0.65793","2078.32617","0.00658","207.83261","0.00000"
"20.00000","0.66446","2088.83276","0.00664","208.88327","0.00000"
"20.20000","0.67115","2100.00195","0.00671","210.00020","-0.00001"
"20.40000","0.67777","2110.69141","0.00678","211.06914","0.00000"
"20.60000","0.68461","2122.25244","0.00685","212.22525","0.00000"
"20.80000","0.69112","2131.83423","0.00691","213.18343","0.00000"
"21.00000","0.69774","2141.94019","0.00698","214.19402","0.00000"
"21.20000","0.70455","2153.07690","0.00705","215.30769","0.00000"
"21.40000","0.71104","2161.76196","0.00711","216.17619","0.00000"
"21.60000","0.71786","2172.25537","0.00718","217.22554","0.00001"
"21.80000","0.72450","2181.83813","0.00724","218.18381","0.00000"
"22.00000","0.73119","2190.91504","0.00731","219.09151","0.00000"
"22.20000","0.73792","2200.75952","0.00738","220.07596","0.00000"
"22.40000","0.74444","2208.73438","0.00744","220.87344","-0.00001"
"22.60000","0.75112","2217.55420","0.00751","221.75542","0.00000"
"22.80000","0.75770","2225.79053","0.00758","222.57906","0.00000"
"23.00000","0.76458","2235.40356","0.00765","223.54036","0.00000"
"23.20000","0.77111","2242.91431","0.00771","224.29143","0.00000"
"23.40000","0.77783","2251.05591","0.00778","225.10559","0.00000"
"23.60000","0.78456","2259.56372","0.00785","225.95638","0.00000"
"23.80000","0.79110","2266.46411","0.00791","226.64641","0.00000"
"24.00000","0.79783","2274.53979","0.00798","227.45398","0.00000"
"24.20000","0.80444","2281.72144","0.00804","228.17215","0.00000"
"24.40000","0.81124","2289.59033","0.00811","228.95903","0.00000"
"24.60000","0.81782","2296.05615","0.00818","229.60562","0.00000"
"24.80000","0.82446","2302.54932","0.00824","230.25493","0.00000"
"25.00000","0.83113","2309.20459","0.00831","230.92046","0.00000"
"25.20000","0.83776","2315.47046","0.00838","231.54704","0.00000"
"25.40000","0.84455","2322.37061","0.00845","232.23706","0.00000"
"25.60000","0.85116","2327.83374","0.00851","232.78337","0.00000"
"25.80000","0.85784","2333.17773","0.00858","233.31778","0.00000"
"26.00000","0.86461","2339.00293","0.00865","233.90030","0.00000"
"26.20000","0.87111","2343.22754","0.00871","234.32275","0.00000"
"26.40000","0.87778","2348.23438","0.00878","234.82344","0.00000"
"26.60000","0.88443","2353.63086","0.00884","235.36308","0.00000"
"26.80000","0.89121","2359.30859","0.00891","235.93086","0.00000"
"27.00000","0.89786","2364.11401","0.00898","236.41141","0.00000"
"27.20000","0.90444","2368.43433","0.00904","236.84343","0.00000"
"27.40000","0.91127","2374.38013","0.00911","237.43802","0.00000"
"27.60000","0.91770","2378.04736","0.00918","237.80473","0.00000"
"27.80000","0.92452","2383.60327","0.00925","238.36032","0.00000"
"28.00000","0.93117","2388.35596","0.00931","238.83560","0.00000"
"28.20000","0.93785","2392.78052","0.00938","239.27805","0.00000"
"28.40000","0.94451","2397.52856","0.00945","239.75285","0.00000"
"28.60000","0.95110","2401.47607","0.00951","240.14761","0.00000"
"28.80000","0.95786","2406.41772","0.00958","240.64177","0.00000"
"29.00000","0.96439","2410.15991","0.00964","241.01599","0.00000"
"29.20000","0.97124","2415.64575","0.00971","241.56458","0.00000"
"29.40000","0.97781","2419.31494","0.00978","241.93149","0.00000"
"29.60000","0.98444","2422.94385","0.00984","242.29439","0.00000"
"29.80000","0.99130","2428.03857","0.00991","242.80386","0.00000"
"30.00000","0.99773","2430.56567","0.00998","243.05656","-0.00001"
"30.20000","1.00443","2434.44897","0.01004","243.44490","0.00000"
"30.40000","1.01110","2438.45630","0.01011","243.84563","0.00000"
"30.60000","1.01797","2443.17163","0.01018","244.31717","0.00000"
"30.80000","1.02442","2445.93945","0.01024","244.59395","0.00000"
"31.00000","1.03110","2449.46411","0.01031","244.94641","0.00000"
"31.20000","1.03788","2453.56299","0.01038","245.35629","0.00000"
"31.40000","1.04438","2455.86133","0.01044","245.58614","0.00000"
"31.60000","1.05128","2460.27173","0.01051","246.02718","0.00000"
"31.80000","1.05778","2462.77026","0.01058","246.27702","0.00000"
"32.00000","1.06445","2465.73975","0.01064","246.57397","0.00000"
"32.20000","1.07121","2469.80664","0.01071","246.98067","0.00000"
"32.40000","1.07784","2472.50391","0.01078","247.25040","0.00000"
"32.60000","1.08443","2474.98779","0.01084","247.49878","0.00000"
"32.80000","1.09112","2478.10620","0.01091","247.81062","0.00000"
"33.00000","1.09792","2481.59253","0.01098","248.15926","0.00000"
"33.20000","1.10451","2484.00708","0.01105","248.40071","0.00000"
"33.40000","1.11113","2486.33105","0.01111","248.63310","0.00000"
"33.60000","1.11791","2489.70117","0.01118","248.97012","0.00000"
"33.80000","1.12443","2491.34009","0.01124","249.13400","-0.00001"
"34.00000","1.13117","2494.34644","0.01131","249.43465","-0.00001"
"34.20000","1.13784","2496.88965","0.01138","249.68896","0.00000"
"34.40000","1.14446","2498.99121","0.01144","249.89912","0.00000"
"34.60000","1.15120","2502.13696","0.01151","250.21370","0.00000"
"34.80000","1.15776","2503.92505","0.01158","250.39250","0.00000"
"35.00000","1.16452","2506.47095","0.01165","250.64709","-0.00001"
"35.20000","1.17115","2508.42163","0.01171","250.84216","0.00000"
"35.40000","1.17798","2511.25220","0.01178","251.12521","0.00000"
"35.60000","1.18450","2512.83521","0.01184","251.28352","0.00000"
"35.80000","1.19106","2514.23218","0.01191","251.42322","0.00000"
"36.00000","1.19795","2517.75830","0.01198","251.77583","0.00000"
"36.20000","1.20438","2518.55591","0.01204","251.85559","0.00000"
"36.40000","1.21111","2520.82837","0.01211","252.08284","0.00000"
"36.60000","1.21775","2522.61328","0.01218","252.26132","0.00000"
"36.80000","1.22462","2525.48584","0.01225","252.54858","0.00000"
"37.00000","1.23121","2527.08203","0.01231","252.70821","0.00000"
"37.20000","1.23779","2528.20581","0.01238","252.82059","0.00000"
"37.40000","1.24453","2530.65698","0.01245","253.06570","0.00000"
"37.60000","1.25107","2531.64648","0.01251","253.16464","-0.00001"
"37.80000","1.25794","2534.52661","0.01258","253.45267","0.00000"
"38.00000","1.26444","2535.20117","0.01264","253.52011","0.00000"
"38.20000","1.27108","2536.74194","0.01271","253.67419","0.00000"
"38.40000","1.27787","2539.09473","0.01278","253.90947","0.00000"
"38.60000","1.28445","2540.16626","0.01284","254.01663","-0.00001"
"38.80000","1.29118","2542.07153","0.01291","254.20715","-0.00001"
"39.00000","1.29781","2543.47168","0.01298","254.34717","0.00000"
"39.20000","1.30469","2545.86646","0.01305","254.58664","0.00000"
"39.40000","1.31114","2546.28320","0.01311","254.62833","0.00000"
"39.60000","1.31778","2547.47583","0.01318","254.74759","0.00000"
"39.80000","1.32448","2549.06763","0.01324","254.90677","0.00000"
"40.00000","1.33107","2550.09082","0.01331","255.00908","0.00000"
"40.20000","1.33784","2551.85864","0.01338","255.18587","0.00000"
"40.40000","1.34449","2553.15698","0.01344","255.31570","-0.00001"
"40.60000","1.35121","2554.49756","0.01351","255.44975","-0.00001"
"40.80000","1.35794","2556.00488","0.01358","255.60049","0.00000"
"41.00000","1.36450","2556.81226","0.01365","255.68123","0.00000"
"41.20000","1.37114","2557.76978","0.01371","255.77698","0.00000"
"41.40000","1.37774","2558.80811","0.01378","255.88081","-0.00001"
"41.60000","1.38455","2560.73755","0.01385","256.07376","-0.00001"
"41.80000","1.39115","2561.57617","0.01391","256.15762","0.00000"
"42.00000","1.39772","2561.92065","0.01398","256.19208","0.00000"
"42.20000","1.40459","2564.10181","0.01405","256.41019","0.00000"
"42.40000","1.41113","2564.39526","0.01411","256.43951","0.00000"
"42.60000","1.41793","2566.34253","0.01418","256.63425","-0.00001"
"42.80000","1.42454","2567.14160","0.01425","256.71417","0.00001"
"43.00000","1.43124","2568.28857","0.01431","256.82886","0.00000"
"43.20000","1.43790","2569.23438","0.01438","256.92343","0.00000"
"43.40000","1.44440","2569.39868","0.01444","256.93988","-0.00001"
"43.60000","1.45115","2570.86450","0.01451","257.08646","0.00000"
"43.80000","1.45764","2571.10303","0.01458","257.11029","0.00000"
"44.00000","1.46460","2573.47998","0.01465","257.34799","0.00000"
"44.20000","1.47120","2573.93750","0.01471","257.39374","0.00000"
"44.40000","1.47791","2574.84277","0.01478","257.48428","-0.00001"
"44.60000","1.48464","2576.02808","0.01485","257.60281","0.00000"
"44.80000","1.49114","2576.11792","0.01491","257.61179","0.00000"
"45.00000","1.49781","2577.02612","0.01498","257.70261","0.00000"
"45.20000","1.50439","2577.62109","0.01504","257.76212","-0.00001"
"45.40000","1.51126","2579.36304","0.01511","257.93631","-0.00001"
"45.60000","1.51778","2579.43555","0.01518","257.94354","0.00000"
"45.80000","1.52447","2580.18726","0.01524","258.01874","0.00000"
"46.00000","1.53128","2581.68604","0.01531","258.16861","0.00000"
"46.20000","1.53780","2581.58887","0.01538","258.15887","-0.00001"
"46.40000","1.54463","2583.27612","0.01545","258.32761","-0.00001"
"46.60000","1.55114","2583.35376","0.01551","258.33539","0.00000"
"46.80000","1.55783","2584.26050","0.01558","258.42606","0.00000"
"47.00000","1.56449","2584.91577","0.01564","258.49158","0.00000"
"47.20000","1.57114","2585.55127","0.01571","258.55511","-0.00001"
"47.40000","1.57779","2585.94287","0.01578","258.59430","0.00000"
"47.60000","1.58443","2586.59131","0.01584","258.65912","0.00001"
"47.80000","1.59129","2588.23022","0.01591","258.82303","0.00000"
"48.00000","1.59788","2588.48608","0.01598","258.84860","0.00000"
"48.20000","1.60451","2588.92114","0.01605","258.89212","-0.00001"
"48.40000","1.61125","2589.85059","0.01611","258.98505","0.00000"
"48.60000","1.61776","2589.90674","0.01618","258.99066","0.00001"
"48.80000","1.62446","2590.65112","0.01624","259.06512","0.00000"
"49.00000","1.63113","2591.42627","0.01631","259.14264","-0.00001"
"49.20000","1.63783","2592.25342","0.01638","259.22534","0.00000"
"49.40000","1.64454","2593.16284","0.01645","259.31628","0.00000"
"49.60000","1.65117","2593.58130","0.01651","259.35812","0.00000"
"49.80000","1.65799","2594.93921","0.01658","259.49393","0.00000"
"50.00000","1.66446","2594.53589","0.01664","259.45358","-0.00001"
"50.20000","1.67124","2595.76709","0.01671","259.57672","-0.00001"
"50.40000","1.67782","2596.03125","0.01678","259.60312","0.00000"
"50.60000","1.68442","2596.12866","0.01684","259.61285","0.00000"
"50.80000","1.69127","2597.90259","0.01691","259.79025","0.00000"
"51.00000","1.69774","2597.49072","0.01698","259.74908","0.00000"
"51.20000","1.70447","2598.26172","0.01704","259.82617","-0.00001"
"51.40000","1.71117","2599.07666","0.01711","259.90765","0.00000"
"51.60000","1.71802","2600.65137","0.01718","260.06512","0.00000"
"51.80000","1.72452","2600.43384","0.01725","260.04340","-0.00001"
"52.00000","1.73110","2600.44702","0.01731","260.04471","0.00000"
"52.20000","1.73789","2601.81177","0.01738","260.18118","0.00000"
"52.40000","1.74437","2601.37646","0.01744","260.13763","0.00000"
"52.60000","1.75124","2602.86499","0.01751","260.28650","0.00000"
"52.80000","1.75778","2602.87549","0.01758","260.28754","0.00000"
"53.00000","1.76451","2603.51196","0.01765","260.35120","-0.00001"
"53.20000","1.77127","2604.72803","0.01771","260.47281","0.00000"
"53.40000","1.77787","2604.84009","0.01778","260.48401","0.00001"
"53.60000","1.78450","2605.24292","0.01785","260.52429","0.00000"
"53.80000","1.79108","2605.34814","0.01791","260.53482","0.00000"
"54.00000","1.79794","2606.66675","0.01798","260.66669","0.00000"
"54.20000","1.80447","2606.64233","0.01804","260.66425","0.00000"
"54.40000","1.81110","2606.92920","0.01811","260.69293","0.00000"
"54.60000","1.81789","2608.15332","0.01818","260.81534","0.00000"
"54.80000","1.82443","2608.04834","0.01824","260.80484","0.00000"
"55.00000","1.83122","2608.92798","0.01831","260.89279","0.00000"
"55.20000","1.83788","2609.44629","0.01838","260.94464","0.00000"
"55.40000","1.84456","2609.96729","0.01845","260.99673","0.00001"
"55.60000","1.85117","2610.24731","0.01851","261.02472","0.00000"
"55.80000","1.85779","2610.54419","0.01858","261.05441","-0.00001"
"56.00000","1.86450","2611.08740","0.01864","261.10873","0.00000"
"56.20000","1.87105","2611.02271","0.01871","261.10226","0.00000"
"56.40000","1.87790","2612.20459","0.01878","261.22046","0.00000"
"56.60000","1.88454","2612.48242","0.01885","261.24823","0.00000"
"56.80000","1.89116","2612.55420","0.01891","261.25543","-0.00001"
"57.00000","1.89792","2613.79395","0.01898","261.37939","0.00000"
"57.20000","1.90447","2613.57007","0.01904","261.35699","0.00000"
"57.40000","1.91114","2613.98291","0.01911","261.39828","0.00000"
"57.60000","1.91774","2614.28564","0.01918","261.42856","0.00000"
"57.80000","1.92458","2615.27271","0.01925","261.52728","0.00000"
"58.00000","1.93120","2615.67432","0.01931","261.56744","0.00000"
"58.20000","1.93776","2615.35034","0.01938","261.53503","0.00000"
"58.40000","1.94460","2616.75781","0.01945","261.67578","0.00000"
"58.60000","1.95108","2616.19775","0.01951","261.61978","-0.00001"
"58.80000","1.95790","2617.43384","0.01958","261.74338","0.00000"
"59.00000","1.96450","2617.57959","0.01964","261.75797","0.00000"
"59.20000","1.97117","2617.84253","0.01971","261.78424","0.00000"
"59.40000","1.97788","2618.52368","0.01978","261.85236","0.00000"
"59.60000","1.98443","2618.37378","0.01984","261.83737","0.00000"
"59.80000","1.99118","2619.11719","0.01991","261.91171","0.00000"
"60.00000","1.99773","2619.06348","0.01998","261.90634","0.00000"
"60.20000","2.00467","2620.57275","0.02005","262.05728","0.00000"
"60.40000","2.01117","2620.10645","0.02011","262.01065","0.00000"
"60.60000","2.01779","2620.04883","0.02018","262.00488","0.00000"
"60.80000","2.02457","2621.01025","0.02025","262.10101","0.00000"
"61.00000","2.03107","2620.61841","0.02031","262.06183","0.00000"
"61.20000","2.03781","2621.33130","0.02038","262.13312","0.00000"
"61.40000","2.04447","2621.68530","0.02044","262.16852","-0.00001"
"61.60000","2.05122","2622.45630","0.02051","262.24564","-0.00001"
"61.80000","2.05785","2622.46924","0.02058","262.24692","0.00000"
"62.00000","2.06449","2622.49365","0.02064","262.24936","0.00000"
"62.20000","2.07120","2622.87744","0.02071","262.28775","0.00000"
"62.40000","2.07775","2622.95752","0.02078","262.29575","0.00000"
"62.60000","2.08460","2623.92017","0.02085","262.39203","-0.00001"
"62.80000","2.09113","2623.66235","0.02091","262.36624","0.00000"
"63.00000","2.09774","2623.54932","0.02098","262.35492","0.00000"
"63.20000","2.10462","2624.88354","0.02105","262.48834","0.00000"
"63.40000","2.11111","2624.25293","0.02111","262.42529","0.00000"
"63.60000","2.11780","2624.60010","0.02118","262.46002","0.00000"
"63.80000","2.12449","2625.06616","0.02124","262.50662","0.00000"
"64.00000","2.13128","2625.80005","0.02131","262.58002","0.00000"
"64.20000","2.13779","2625.28662","0.02138","262.52866","0.00000"
"64.40000","2.14441","2625.27661","0.02144","262.52765","0.00000"
"64.60000","2.15120","2625.91309","0.02151","262.59131","0.00000"
"64.80000","2.15770","2625.53052","0.02158","262.55304","0.00000"
"65.00000","2.16453","2626.43140","0.02165","262.64313","0.00000"
"65.20000","2.17116","2626.66553","0.02171","262.66656","0.00000"
"65.40000","2.17784","2627.00293","0.02178","262.70029","0.00000"
"65.60000","2.18463","2627.87598","0.02185","262.78760","0.00000"
"65.80000","2.19112","2627.24805","0.02191","262.72479","0.00000"
"66.00000","2.19776","2627.03198","0.02198","262.70319","0.00000"
"66.20000","2.20439","2627.14185","0.02204","262.71417","0.00000"
"66.40000","2.21129","2628.47461","0.02211","262.84747","0.00000"
"66.60000","2.21778","2627.83862","0.02218","262.78387","0.00000"
"66.80000","2.22447","2628.06494","0.02224","262.80649","0.00000"
"67.00000","2.23123","2628.96289","0.02231","262.89630","0.00000"
"67.20000","2.23776","2628.22729","0.02238","262.82272","0.00000"
"67.40000","2.24457","2629.03418","0.02245","262.90341","0.00000"
"67.60000","2.25113","2628.84131","0.02251","262.88412","0.00000"
"67.80000","2.25785","2629.13379","0.02258","262.91339","0.00000"
"68.00000","2.26449","2629.37061","0.02264","262.93707","0.00000"
"68.20000","2.27111","2629.22534","0.02271","262.92255","0.00000"
"68.40000","2.27779","2629.34106","0.02278","262.93411","0.00000"
"68.60000","2.28443","2629.46777","0.02284","262.94678","0.00000"
"68.80000","2.29125","2630.31543","0.02291","263.03156","0.00000"
"69.00000","2.29782","2630.05029","0.02298","263.00504","0.00000"
"69.20000","2.30446","2629.91772","0.02304","262.99176","0.00000"
"69.40000","2.31125","2630.86450","0.02311","263.08646","0.00000"
"69.60000","2.31778","2630.24219","0.02318","263.02423","0.00000"
"69.80000","2.32445","2630.25488","0.02324","263.02548","0.00000"
"70.00000","2.33116","2630.62695","0.02331","263.06268","0.00000"
"70.20000","2.33786","2630.72412","0.02338","263.07242","0.00000"
"70.40000","2.34453","2631.00171","0.02345","263.10016","0.00000"
"70.60000","2.35110","2630.67749","0.02351","263.06775","0.00000"
"70.80000","2.35791","2631.38306","0.02358","263.13831","0.00000"
"71.00000","2.36440","2630.93066","0.02364","263.09308","0.00000"
"71.20000","2.37122","2631.38208","0.02371","263.13821","0.00000"
"71.40000","2.37784","2631.27954","0.02378","263.12796","0.00000"
"71.60000","2.38447","2631.01440","0.02384","263.10144","0.00000"
"71.80000","2.39121","2631.62305","0.02391","263.16229","0.00000"
"72.00000","2.39775","2631.25806","0.02398","263.12579","0.00000"
"72.20000","2.40452","2631.76660","0.02405","263.17667","0.00000"
"72.40000","2.41107","2631.49023","0.02411","263.14902","0.00000"
"72.60000","2.41794","2632.35376","0.02418","263.23538","0.00000"
"72.80000","2.42452","2632.35327","0.02425","263.23532","0.00000"
"73.00000","2.43109","2631.58667","0.02431","263.15866","0.00000"
"73.20000","2.43793","2632.57959","0.02438","263.25797","0.00000"
"73.40000","2.44435","2631.53003","0.02444","263.15302","0.00000"
"73.60000","2.45115","2632.26514","0.02451","263.22650","0.00000"
"73.80000","2.45777","2632.14453","0.02458","263.21445","0.00000"
"74.00000","2.46464","2632.96509","0.02465","263.29651","0.00000"
"74.20000","2.47114","2632.36450","0.02471","263.23645","0.00000"
"74.40000","2.47779","2632.30640","0.02478","263.23065","0.00000"
"74.60000","2.48450","2632.39697","0.02485","263.23969","0.00000"
"74.80000","2.49104","2632.06494","0.02491","263.20648","0.00000"
"75.00000","2.49798","2633.22852","0.02498","263.32285","0.00000"
"75.20000","2.50446","2632.34131","0.02504","263.23413","0.00000"
"75.40000","2.51111","2632.28296","0.02511","263.22830","0.00000"
"75.60000","2.51788","2632.72290","0.02518","263.27228","0.00000"
"75.80000","2.52447","2632.59082","0.02524","263.25909","0.00000"
"76.00000","2.53108","2632.24219","0.02531","263.22421","0.00000"
"76.20000","2.53782","2632.82910","0.02538","263.28290","0.00000"
"76.40000","2.54459","2632.99805","0.02545","263.29980","0.00001"
"76.60000","2.55116","2632.83350","0.02551","263.28336","0.00000"
"76.80000","2.55780","2632.42114","0.02558","263.24213","0.00000"
"77.00000","2.56453","2632.58228","0.02565","263.25824","0.00000"
"77.20000","2.57109","2632.17773","0.02571","263.21777","-0.00001"
"77.40000","2.57783","2632.66016","0.02578","263.26602","0.00000"
"77.60000","2.58452","2632.75977","0.02585","263.27597","0.00000"
"77.80000","2.59111","2632.28442","0.02591","263.22845","0.00000"
"78.00000","2.59789","2632.63965","0.02598","263.26398","0.00000"
"78.20000","2.60441","2632.04321","0.02604","263.20432","0.00000"
"78.40000","2.61116","2632.21484","0.02611","263.22150","0.00000"
"78.60000","2.61782","2632.16113","0.02618","263.21613","0.00000"
"78.80000","2.62463","2632.85205","0.02625","263.28522","0.00000"
"79.00000","2.63114","2632.17773","0.02631","263.21777","0.00000"
"79.20000","2.63774","2631.66577","0.02638","263.16656","0.00000"
"79.40000","2.64464","2632.59399","0.02645","263.25940","0.00000"
"79.60000","2.65103","2631.49023","0.02651","263.14902","0.00000"
"79.80000","2.65777","2631.64014","0.02658","263.16400","0.00000"
"80.00000","2.66440","2631.73804","0.02664","263.17380","0.00000"
"80.20000","2.67124","2632.23560","0.02671","263.22357","0.00000"
"80.40000","2.67794","2632.39502","0.02678","263.23950","0.00001"
"80.60000","2.68447","2631.60083","0.02684","263.16010","0.00000"
"80.80000","2.69118","2631.71411","0.02691","263.17142","0.00000"
"81.00000","2.69772","2631.05713","0.02698","263.10571","0.00000"
"81.20000","2.70464","2632.24219","0.02705","263.22421","0.00000"
"81.40000","2.71108","2631.24023","0.02711","263.12402","0.00000"
"81.60000","2.71774","2630.92358","0.02718","263.09235","0.00000"
"81.80000","2.72456","2631.63623","0.02725","263.16364","0.00000"
"82.00000","2.73112","2630.96777","0.02731","263.09677","0.00000"
"82.20000","2.73788","2631.18262","0.02738","263.11826","0.00001"
"82.40000","2.74446","2630.81567","0.02744","263.08157","0.00000"
"82.60000","2.75129","2631.30371","0.02751","263.13037","0.00000"
"82.80000","2.75780","2630.66016","0.02758","263.06601","0.00000"
"83.00000","2.76447","2630.42554","0.02764","263.04254","0.00000"
"83.20000","2.77114","2630.29663","0.02771","263.02966","0.00001"
"83.40000","2.77775","2629.90552","0.02778","262.99054","0.00001"
"83.60000","2.78455","2630.36255","0.02785","263.03625","0.00000"
"83.80000","2.79117","2630.01514","0.02791","263.00153","0.00000"
"84.00000","2.79781","2629.65820","0.02798","262.96582","0.00000"
"84.20000","2.80461","2630.23340","0.02805","263.02335","0.00000"
"84.40000","2.81116","2629.58936","0.02811","262.95892","0.00000"
"84.60000","2.81781","2629.10352","0.02818","262.91034","-0.00001"
"84.80000","2.82447","2628.91821","0.02824","262.89182","0.00000"
"85.00000","2.83124","2629.26514","0.02831","262.92651","0.00001"
"85.20000","2.83780","2628.75269","0.02838","262.87527","0.00000"
"85.40000","2.84436","2628.00146","0.02844","262.80014","0.00000"
"85.60000","2.85125","2628.75879","0.02851","262.87589","-0.00001"
"85.80000","2.85781","2627.95801","0.02858","262.79581","-0.00001"
"86.00000","2.86460","2628.24268","0.02865","262.82428","0.00000"
"86.20000","2.87120","2627.70752","0.02871","262.77075","0.00000"
"86.40000","2.87785","2627.04907","0.02878","262.70490","0.00000"
"86.60000","2.88456","2627.08862","0.02885","262.70886","0.00000"
"86.80000","2.89107","2625.83350","0.02891","262.58334","0.00000"
"87.00000","2.89780","2625.09741","0.02898","262.50974","0.00000"
"87.20000","2.90431","2621.80811","0.02904","262.18082","0.00001"
"87.40000","2.91131","2621.46802","0.02911","262.14679","0.00000"
"87.60000","2.91788","2619.40430","0.02918","261.94043","0.00000"
"87.80000","2.92454","2617.91406","0.02925","261.79141","0.00000"
"88.00000","2.93132","2617.23999","0.02931","261.72400","0.00000"
"88.20000","2.93776","2614.83105","0.02938","261.48309","0.00000"
"88.40000","2.94448","2613.44629","0.02944","261.34464","0.00000"
"88.60000","2.95106","2611.73218","0.02951","261.17322","0.00000"
"88.80000","2.95790","2611.06812","0.02958","261.10681","0.00001"
"89.00000","2.96447","2609.74194","0.02964","260.97418","0.00001"
"89.20000","2.97115","2608.73267","0.02971","260.87326","0.00000"
"89.40000","2.97790","2608.00000","0.02978","260.79999","-0.00001"
"89.60000","2.98445","2606.61816","0.02984","260.66180","-0.00001"
"89.80000","2.99133","2606.64941","0.02991","260.66495","0.00000"
"90.00000","2.99782","2604.82373","0.02998","260.48236","0.00001"
"90.20000","3.00450","2603.84424","0.03004","260.38443","0.00000"
"90.40000","3.01117","2602.75610","0.03011","260.27560","0.00000"
"90.60000","3.01777","2601.34497","0.03018","260.13449","0.00000"
"90.80000","3.02442","2600.23486","0.03024","260.02350","0.00000"
"91.00000","3.03113","2599.08569","0.03031","259.90857","0.00000"
"91.20000","3.03798","2598.56909","0.03038","259.85690","0.00000"
"91.40000","3.04459","2596.73267","0.03045","259.67328","0.00000"
"91.60000","3.05116","2594.41040","0.03051","259.44104","0.00000"
"91.80000","3.05791","2592.76001","0.03058","259.27600","0.00001"
"92.00000","3.06441","2590.37427","0.03064","259.03741","0.00000"
"92.20000","3.07113","2588.84814","0.03071","258.88483","0.00000"
"92.40000","3.07782","2586.71021","0.03078","258.67102","0.00000"
"92.60000","3.08447","2584.29150","0.03084","258.42914","0.00000"
"92.80000","3.09124","2582.68066","0.03091","258.26807","0.00000"
"93.00000","3.09783","2580.16724","0.03098","258.01672","0.00000"
"93.20000","3.10460","2578.32446","0.03105","257.83246","0.00000"
"93.40000","3.11112","2575.39404","0.03111","257.53940","0.00000"
"93.60000","3.11794","2574.01221","0.03118","257.40121","0.00001"
"93.80000","3.12448","2571.34058","0.03124","257.13406","0.00000"
"94.00000","3.13105","2568.62280","0.03131","256.86227","0.00000"
"94.20000","3.13796","2567.68604","0.03138","256.76862","0.00000"
"94.40000","3.14437","2564.71069","0.03144","256.47107","0.00000"
"94.60000","3.15113","2563.29883","0.03151","256.32990","0.00001"
"94.80000","3.15785","2561.90576","0.03158","256.19058","0.00001"
"95.00000","3.16469","2560.85962","0.03165","256.08597","0.00000"
"95.20000","3.17122","2558.32373","0.03171","255.83237","0.00000"
"95.40000","3.17780","2555.28247","0.03178","255.52824","0.00000"
"95.60000","3.18455","2552.93872","0.03185","255.29387","0.00000"
"95.80000","3.19100","2549.05078","0.03191","254.90508","0.00000"
"96.00000","3.19794","2546.54932","0.03198","254.65494","0.00000"
"96.20000","3.20444","2542.47949","0.03204","254.24796","0.00000"
"96.40000","3.21118","2538.51929","0.03211","253.85193","0.00000"
"96.60000","3.21798","2531.84106","0.03218","253.18411","0.00001"
"96.80000","3.22454","2519.75952","0.03225","251.97595","0.00000"
"97.00000","3.23121","2498.29688","0.03231","249.82968","0.00000"
"97.20000","3.23776","2437.01660","0.03238","243.70166","0.00000"
"97.36500","3.24332","2254.83813","0.03243","225.48381","0.00000"
"97.37100","3.24356","1963.07227","0.03244","196.30722","0.00000"
"97.37600","3.24377","1645.84705","0.03244","164.58470","0.00001"
"97.37900","3.24390","1445.94617","0.03244","144.59462","0.00000"