File: Tension/Section_1_Group_2/PEanut_15%.is_tens_RawData/Specimen_RawData_1.csv
Time,Extension,Load,Tensile strain (Extension),Tensile stress,Strain-by-clip-gage
(s),(mm),(N),(mm/mm),(MPa),(mm/mm)
"0.00000","0.00000","0.01741","0.00000","0.00174","0.00000"
"0.20000","0.00035","0.44787","0.00000","0.04479","-0.00001"
"0.40000","0.00467","9.98507","0.00005","0.99851","0.00008"
"0.60000","0.00806","17.53228","0.00008","1.75323","0.00012"
"0.80000","0.01136","24.95742","0.00011","2.49574","0.00016"
"1.00000","0.01477","32.65234","0.00015","3.26523","0.00021"
"1.20000","0.01829","40.42142","0.00018","4.04214","0.00026"
"1.40000","0.02169","47.87320","0.00022","4.78732","0.00030"
"1.60000","0.02483","54.81718","0.00025","5.48172","0.00034"
"1.80000","0.02806","61.67010","0.00028","6.16701","0.00038"
"2.00000","0.03132","68.62984","0.00031","6.86298","0.00042"
"2.20000","0.03474","76.06824","0.00035","7.60682","0.00046"
"2.40000","0.03815","83.28425","0.00038","8.32842","0.00050"
"2.60000","0.04158","90.80157","0.00042","9.08016","0.00054"
"2.80000","0.04491","97.83184","0.00045","9.78318","0.00058"
"3.00000","0.04807","104.34795","0.00048","10.43480","0.00062"
"3.20000","0.05140","111.49805","0.00051","11.14981","0.00066"
"3.40000","0.05474","118.47201","0.00055","11.84720","0.00070"
"3.60000","0.05816","125.57819","0.00058","12.55782","0.00073"
"3.80000","0.06149","132.60774","0.00061","13.26077","0.00077"
"4.00000","0.06489","139.79669","0.00065","13.97967","0.00081"
"4.20000","0.06810","146.27466","0.00068","14.62747","0.00085"
"4.40000","0.07136","153.17398","0.00071","15.31740","0.00088"
"4.60000","0.07485","160.28905","0.00075","16.02890","0.00092"
"4.80000","0.07821","167.29036","0.00078","16.72904","0.00096"
"5.00000","0.08158","174.12424","0.00082","17.41242","0.00099"
"5.20000","0.08483","180.70714","0.00085","18.07071","0.00103"
"5.40000","0.08809","187.24641","0.00088","18.72464","0.00106"
"5.60000","0.09133","193.80688","0.00091","19.38069","0.00109"
"5.80000","0.09472","200.61748","0.00095","20.06175","0.00113"
"6.00000","0.09824","207.81790","0.00098","20.78179","0.00116"
"6.20000","0.10161","214.56671","0.00102","21.45667","0.00120"
"6.40000","0.10487","221.07460","0.00105","22.10746","0.00123"
"6.60000","0.10811","227.39050","0.00108","22.73905","0.00126"
"6.80000","0.11138","233.89734","0.00111","23.38973","0.00129"
"7.00000","0.11463","240.53261","0.00115","24.05326","0.00132"
"7.20000","0.11811","247.39272","0.00118","24.73927","0.00136"
"7.40000","0.12162","254.42093","0.00122","25.44209","0.00139"
"7.60000","0.12498","261.00998","0.00125","26.10100","0.00142"
"7.80000","0.12820","267.13461","0.00128","26.71346","0.00145"
"8.00000","0.13138","273.46115","0.00131","27.34612","0.00148"
"8.20000","0.13477","280.06042","0.00135","28.00604","0.00152"
"8.40000","0.13801","286.21832","0.00138","28.62183","0.00155"
"8.60000","0.14154","293.20990","0.00142","29.32099","0.00158"
"8.80000","0.14496","299.92276","0.00145","29.99228","0.00161"
"9.00000","0.14822","306.05200","0.00148","30.60520","0.00164"
"9.20000","0.15137","312.01047","0.00151","31.20105","0.00167"
"9.40000","0.15477","318.46133","0.00155","31.84613","0.00170"
"9.60000","0.15805","324.73874","0.00158","32.47387","0.00173"
"9.80000","0.16142","331.28992","0.00161","33.12899","0.00176"
"10.00000","0.16486","337.84296","0.00165","33.78429","0.00179"
"10.20000","0.16821","344.25458","0.00168","34.42546","0.00182"
"10.40000","0.17144","350.28079","0.00171","35.02808","0.00185"
"10.60000","0.17464","356.20081","0.00175","35.62008","0.00188"
"10.80000","0.17819","363.03113","0.00178","36.30311","0.00191"
"11.00000","0.18155","369.28607","0.00182","36.92861","0.00194"
"11.20000","0.18483","375.25339","0.00185","37.52534","0.00197"
"11.40000","0.18819","381.68433","0.00188","38.16843","0.00200"
"11.60000","0.19137","387.39001","0.00191","38.73900","0.00202"
"11.80000","0.19474","393.66028","0.00195","39.36603","0.00205"
"12.00000","0.19800","399.50287","0.00198","39.95029","0.00208"
"12.20000","0.20162","406.50586","0.00202","40.65059","0.00211"
"12.40000","0.20499","412.67624","0.00205","41.26762","0.00214"
"12.60000","0.20828","418.60150","0.00208","41.86015","0.00217"
"12.80000","0.21142","424.31494","0.00211","42.43150","0.00219"
"13.00000","0.21468","430.05017","0.00215","43.00502","0.00222"
"13.20000","0.21801","435.98627","0.00218","43.59863","0.00225"
"13.40000","0.22137","442.03726","0.00221","44.20373","0.00228"
"13.60000","0.22500","448.82587","0.00225","44.88259","0.00231"
"13.80000","0.22831","454.74945","0.00228","45.47495","0.00233"
"14.00000","0.23149","460.28741","0.00231","46.02874","0.00236"
"14.20000","0.23472","465.92020","0.00235","46.59202","0.00239"
"14.40000","0.23805","471.90344","0.00238","47.19035","0.00241"
"14.60000","0.24138","477.84601","0.00241","47.78460","0.00244"
"14.80000","0.24480","483.99075","0.00245","48.39907","0.00247"
"15.00000","0.24832","490.37552","0.00248","49.03755","0.00250"
"15.20000","0.25153","495.83093","0.00252","49.58309","0.00252"
"15.40000","0.25478","501.49118","0.00255","50.14912","0.00255"
"15.60000","0.25804","507.16043","0.00258","50.71604","0.00258"
"15.80000","0.26152","513.16626","0.00262","51.31663","0.00260"
"16.00000","0.26479","518.91455","0.00265","51.89146","0.00263"
"16.20000","0.26823","524.81311","0.00268","52.48131","0.00266"
"16.40000","0.27151","530.27368","0.00272","53.02737","0.00268"
"16.60000","0.27478","535.95764","0.00275","53.59576","0.00271"
"16.80000","0.27802","541.33746","0.00278","54.13375","0.00273"
"17.00000","0.28140","547.24762","0.00281","54.72476","0.00276"
"17.20000","0.28492","553.42273","0.00285","55.34227","0.00279"
"17.40000","0.28823","558.89874","0.00288","55.88987","0.00281"
"17.60000","0.29149","564.50043","0.00291","56.45004","0.00284"
"17.80000","0.29474","569.82416","0.00295","56.98241","0.00286"
"18.00000","0.29801","575.19897","0.00298","57.51990","0.00289"
"18.20000","0.30140","580.97925","0.00301","58.09792","0.00291"
"18.40000","0.30490","586.86938","0.00305","58.68694","0.00294"
"18.60000","0.30834","592.73334","0.00308","59.27333","0.00297"
"18.80000","0.31158","597.96429","0.00312","59.79643","0.00299"
"19.00000","0.31484","603.16504","0.00315","60.31651","0.00302"
"19.20000","0.31801","608.26794","0.00318","60.82679","0.00304"
"19.40000","0.32138","613.86108","0.00321","61.38611","0.00306"
"19.60000","0.32472","619.33832","0.00325","61.93383","0.00309"
"19.80000","0.32832","625.25598","0.00328","62.52560","0.00312"
"20.00000","0.33160","630.52515","0.00332","63.05251","0.00314"
"20.20000","0.33482","635.71564","0.00335","63.57156","0.00317"
"20.40000","0.33808","640.80066","0.00338","64.08006","0.00319"
"20.60000","0.34132","645.95465","0.00341","64.59547","0.00321"
"20.80000","0.34470","651.30756","0.00345","65.13075","0.00324"
"21.00000","0.34817","656.84204","0.00348","65.68420","0.00326"
"21.20000","0.35164","662.44342","0.00352","66.24434","0.00329"
"21.40000","0.35486","667.41223","0.00355","66.74123","0.00331"
"21.60000","0.35806","672.36169","0.00358","67.23617","0.00334"
"21.80000","0.36141","677.57312","0.00361","67.75731","0.00336"
"22.00000","0.36476","682.76111","0.00365","68.27611","0.00339"
"22.20000","0.36814","688.01880","0.00368","68.80188","0.00341"
"22.40000","0.37156","693.42731","0.00372","69.34273","0.00344"
"22.60000","0.37496","698.81525","0.00375","69.88152","0.00346"
"22.80000","0.37806","703.44049","0.00378","70.34405","0.00348"
"23.00000","0.38137","708.33624","0.00381","70.83363","0.00351"
"23.20000","0.38476","713.60284","0.00385","71.36028","0.00353"
"23.40000","0.38819","718.79333","0.00388","71.87933","0.00355"
"23.60000","0.39151","723.87305","0.00392","72.38731","0.00358"
"23.80000","0.39485","728.93042","0.00395","72.89304","0.00360"
"24.00000","0.39814","733.79584","0.00398","73.37959","0.00364"
"24.20000","0.40137","738.56348","0.00401","73.85635","0.00366"
"24.40000","0.40467","743.43860","0.00405","74.34386","0.00368"
"24.60000","0.40825","748.96869","0.00408","74.89687","0.00371"
"24.80000","0.41166","754.03601","0.00412","75.40360","0.00373"
"25.00000","0.41487","758.59253","0.00415","75.85925","0.00375"
"25.20000","0.41811","763.21796","0.00418","76.32179","0.00377"
"25.40000","0.42134","767.73352","0.00421","76.77335","0.00380"
"25.60000","0.42466","772.79370","0.00425","77.27937","0.00382"
"25.80000","0.42813","778.02142","0.00428","77.80214","0.00384"
"26.00000","0.43168","783.27795","0.00432","78.32780","0.00387"
"26.20000","0.43506","788.18304","0.00435","78.81831","0.00389"
"26.40000","0.43809","792.10327","0.00438","79.21033","0.00391"
"26.60000","0.44143","796.87268","0.00441","79.68727","0.00393"
"26.80000","0.44465","801.35388","0.00445","80.13539","0.00395"
"27.00000","0.44804","806.18915","0.00448","80.61891","0.00398"
"27.20000","0.45144","811.05719","0.00451","81.10572","0.00400"
"27.40000","0.45496","816.17694","0.00455","81.61769","0.00403"
"27.60000","0.45827","820.93030","0.00458","82.09303","0.00405"
"27.80000","0.46138","824.92371","0.00461","82.49237","0.00407"
"28.00000","0.46472","829.66797","0.00465","82.96680","0.00409"
"28.20000","0.46809","834.39386","0.00468","83.43938","0.00411"
"28.40000","0.47149","839.09473","0.00471","83.90947","0.00414"
"28.60000","0.47482","843.80231","0.00475","84.38023","0.00416"
"28.80000","0.47819","848.30389","0.00478","84.83039","0.00418"
"29.00000","0.48145","852.62616","0.00481","85.26262","0.00420"
"29.20000","0.48467","856.89594","0.00485","85.68959","0.00422"
"29.40000","0.48818","861.82141","0.00488","86.18214","0.00425"
"29.60000","0.49162","866.38049","0.00492","86.63805","0.00427"
"29.80000","0.49496","870.82312","0.00495","87.08231","0.00429"
"30.00000","0.49813","874.88220","0.00498","87.48822","0.00431"
"30.20000","0.50142","879.30475","0.00501","87.93047","0.00433"
"30.40000","0.50463","883.24304","0.00505","88.32430","0.00435"
"30.60000","0.50803","887.75653","0.00508","88.77565","0.00437"
"30.80000","0.51156","892.66626","0.00512","89.26662","0.00440"
"31.00000","0.51497","897.14954","0.00515","89.71495","0.00442"
"31.20000","0.51826","901.51917","0.00518","90.15192","0.00444"
"31.40000","0.52144","905.38245","0.00521","90.53825","0.00446"
"31.60000","0.52467","909.30658","0.00525","90.93066","0.00448"
"31.80000","0.52797","913.57965","0.00528","91.35796","0.00450"
"32.00000","0.53145","918.04620","0.00531","91.80462","0.00452"
"32.20000","0.53494","922.69464","0.00535","92.26946","0.00455"
"32.40000","0.53828","926.78564","0.00538","92.67857","0.00457"
"32.60000","0.54150","930.67438","0.00541","93.06744","0.00459"
"32.80000","0.54475","934.67517","0.00545","93.46751","0.00461"
"33.00000","0.54808","938.85583","0.00548","93.88558","0.00463"
"33.20000","0.55142","942.96729","0.00551","94.29673","0.00465"
"33.40000","0.55485","947.31573","0.00555","94.73158","0.00467"
"33.60000","0.55827","951.71185","0.00558","95.17119","0.00469"
"33.80000","0.56155","955.70319","0.00562","95.57032","0.00471"
"34.00000","0.56472","959.35034","0.00565","95.93504","0.00473"
"34.20000","0.56809","963.44843","0.00568","96.34484","0.00475"
"34.40000","0.57144","967.42035","0.00571","96.74203","0.00477"
"34.60000","0.57483","971.57343","0.00575","97.15734","0.00479"
"34.80000","0.57825","975.70129","0.00578","97.57013","0.00481"
"35.00000","0.58151","979.60571","0.00582","97.96057","0.00483"
"35.20000","0.58472","983.18335","0.00585","98.31834","0.00485"
"35.40000","0.58803","987.02612","0.00588","98.70261","0.00487"
"35.60000","0.59149","991.44513","0.00591","99.14452","0.00489"
"35.80000","0.59487","995.39227","0.00595","99.53923","0.00491"
"36.00000","0.59819","999.13141","0.00598","99.91314","0.00493"
"36.20000","0.60155","1003.23108","0.00602","100.32310","0.00495"
"36.40000","0.60478","1006.75885","0.00605","100.67589","0.00497"
"36.60000","0.60804","1010.44354","0.00608","101.04436","0.00499"
"36.80000","0.61138","1014.36499","0.00611","101.43650","0.00501"
"37.00000","0.61493","1018.55121","0.00615","101.85512","0.00503"
"37.20000","0.61833","1022.53973","0.00618","102.25397","0.00505"
"37.40000","0.62158","1026.08435","0.00622","102.60844","0.00507"
"37.60000","0.62479","1029.48083","0.00625","102.94808","0.00509"
"37.80000","0.62804","1033.07324","0.00628","103.30733","0.00511"
"38.00000","0.63132","1036.74011","0.00631","103.67401","0.00513"
"38.20000","0.63474","1040.66772","0.00635","104.06677","0.00515"
"38.40000","0.63834","1044.95105","0.00638","104.49510","0.00517"
"38.60000","0.64161","1048.56421","0.00642","104.85642","0.00519"
"38.80000","0.64476","1051.85034","0.00645","105.18504","0.00521"
"39.00000","0.64808","1055.56006","0.00648","105.55601","0.00523"
"39.20000","0.65135","1059.06152","0.00651","105.90615","0.00525"
"39.40000","0.65474","1062.93909","0.00655","106.29391","0.00527"
"39.60000","0.65816","1066.70679","0.00658","106.67068","0.00528"
"39.80000","0.66164","1070.76880","0.00662","107.07688","0.00531"
"40.00000","0.66487","1074.15674","0.00665","107.41567","0.00532"
"40.20000","0.66807","1077.42590","0.00668","107.74259","0.00534"
"40.40000","0.67146","1081.16992","0.00671","108.11699","0.00536"
"40.60000","0.67479","1084.86511","0.00675","108.48651","0.00538"
"40.80000","0.67814","1088.61841","0.00678","108.86184","0.00540"
"41.00000","0.68151","1092.33557","0.00682","109.23356","0.00542"
"41.20000","0.68484","1095.90515","0.00685","109.59052","0.00544"
"41.40000","0.68808","1099.30725","0.00688","109.93073","0.00546"
"41.60000","0.69136","1102.93542","0.00691","110.29354","0.00547"
"41.80000","0.69483","1106.79102","0.00695","110.67910","0.00550"
"42.00000","0.69827","1110.74451","0.00698","111.07445","0.00552"
"42.20000","0.70156","1114.30115","0.00702","111.43011","0.00553"
"42.40000","0.70479","1117.73438","0.00705","111.77344","0.00555"
"42.60000","0.70810","1121.29456","0.00708","112.12946","0.00557"
"42.80000","0.71135","1124.76038","0.00711","112.47604","0.00559"
"43.00000","0.71471","1128.54077","0.00715","112.85408","0.00561"
"43.20000","0.71825","1132.57910","0.00718","113.25791","0.00563"
"43.40000","0.72168","1136.44348","0.00722","113.64435","0.00565"
"43.60000","0.72485","1139.81116","0.00725","113.98112","0.00567"
"43.80000","0.72811","1143.13562","0.00728","114.31356","0.00569"
"44.00000","0.73138","1146.71863","0.00731","114.67186","0.00570"
"44.20000","0.73469","1150.40967","0.00735","115.04097","0.00572"
"44.40000","0.73812","1154.21680","0.00738","115.42168","0.00574"
"44.60000","0.74162","1158.43054","0.00742","115.84306","0.00576"
"44.80000","0.74501","1162.18335","0.00745","116.21834","0.00578"
"45.00000","0.74811","1165.12146","0.00748","116.51215","0.00580"
"45.20000","0.75138","1168.70752","0.00751","116.87075","0.00582"
"45.40000","0.75471","1172.22656","0.00755","117.22266","0.00584"
"45.60000","0.75809","1176.01794","0.00758","117.60179","0.00586"
"45.80000","0.76152","1179.91833","0.00762","117.99184","0.00588"
"46.00000","0.76488","1183.48157","0.00765","118.34816","0.00590"
"46.20000","0.76817","1187.16907","0.00768","118.71690","0.00592"
"46.40000","0.77140","1190.42810","0.00771","119.04281","0.00593"
"46.60000","0.77477","1194.21448","0.00775","119.42145","0.00595"
"46.80000","0.77810","1197.80542","0.00778","119.78054","0.00597"
"47.00000","0.78153","1201.63586","0.00782","120.16359","0.00599"
"47.20000","0.78483","1204.98853","0.00785","120.49886","0.00601"
"47.40000","0.78819","1208.62756","0.00788","120.86275","0.00603"
"47.60000","0.79140","1211.93726","0.00791","121.19373","0.00605"
"47.80000","0.79468","1215.40796","0.00795","121.54079","0.00607"
"48.00000","0.79822","1219.47046","0.00798","121.94704","0.00609"
"48.20000","0.80157","1223.16052","0.00802","122.31606","0.00610"
"48.40000","0.80491","1226.69800","0.00805","122.66980","0.00612"
"48.60000","0.80816","1229.97119","0.00808","122.99712","0.00614"
"48.80000","0.81140","1233.39758","0.00811","123.33976","0.00616"
"49.00000","0.81466","1236.79895","0.00815","123.67989","0.00618"
"49.20000","0.81807","1240.52820","0.00818","124.05282","0.00620"
"49.40000","0.82158","1244.46057","0.00822","124.44606","0.00622"
"49.60000","0.82493","1247.96436","0.00825","124.79643","0.00624"
"49.80000","0.82820","1251.54651","0.00828","125.15465","0.00626"
"50.00000","0.83144","1254.70972","0.00831","125.47097","0.00627"
"50.20000","0.83471","1258.09875","0.00835","125.80988","0.00629"
"50.40000","0.83798","1261.36633","0.00838","126.13663","0.00631"
"50.60000","0.84150","1265.40125","0.00842","126.54012","0.00633"
"50.80000","0.84494","1269.17041","0.00845","126.91704","0.00635"
"51.00000","0.84827","1272.58618","0.00848","127.25862","0.00637"
"51.20000","0.85149","1275.87634","0.00851","127.58763","0.00639"
"51.40000","0.85470","1279.00684","0.00855","127.90068","0.00640"
"51.60000","0.85812","1282.70996","0.00858","128.27100","0.00642"
"51.80000","0.86135","1285.87976","0.00861","128.58798","0.00644"
"52.00000","0.86489","1289.84363","0.00865","128.98436","0.00646"
"52.20000","0.86826","1293.44409","0.00868","129.34441","0.00648"
"52.40000","0.87152","1296.61304","0.00872","129.66130","0.00650"
"52.60000","0.87468","1299.52905","0.00875","129.95291","0.00652"
"52.80000","0.87816","1303.39600","0.00878","130.33960","0.00654"
"53.00000","0.88143","1306.76367","0.00881","130.67636","0.00655"
"53.20000","0.88481","1310.19507","0.00885","131.01950","0.00657"
"53.40000","0.88819","1313.69556","0.00888","131.36955","0.00659"
"53.60000","0.89150","1317.02576","0.00891","131.70258","0.00661"
"53.80000","0.89476","1320.06824","0.00895","132.00682","0.00663"
"54.00000","0.89797","1323.41223","0.00898","132.34122","0.00665"
"54.20000","0.90155","1327.12988","0.00902","132.71298","0.00667"
"54.40000","0.90492","1330.63977","0.00905","133.06398","0.00669"
"54.60000","0.90820","1333.80750","0.00908","133.38075","0.00670"
"54.80000","0.91149","1337.09729","0.00911","133.70973","0.00672"
"55.00000","0.91468","1340.00293","0.00915","134.00029","0.00674"
"55.20000","0.91809","1343.43896","0.00918","134.34390","0.00676"
"55.40000","0.92137","1346.72009","0.00921","134.67201","0.00678"
"55.60000","0.92497","1350.60107","0.00925","135.06010","0.00680"
"55.80000","0.92832","1353.97144","0.00928","135.39714","0.00681"
"56.00000","0.93154","1356.99609","0.00932","135.69962","0.00683"
"56.20000","0.93473","1359.98877","0.00935","135.99887","0.00685"
"56.40000","0.93803","1363.09888","0.00938","136.30989","0.00687"
"56.60000","0.94135","1366.33423","0.00941","136.63342","0.00688"
"56.80000","0.94474","1369.69250","0.00945","136.96925","0.00690"
"57.00000","0.94831","1373.49231","0.00948","137.34923","0.00692"
"57.20000","0.95159","1376.46643","0.00952","137.64664","0.00694"
"57.40000","0.95478","1379.37524","0.00955","137.93753","0.00696"
"57.60000","0.95803","1382.53015","0.00958","138.25302","0.00697"
"57.80000","0.96141","1385.81287","0.00961","138.58128","0.00699"
"58.00000","0.96476","1389.11182","0.00965","138.91118","0.00701"
"58.20000","0.96817","1392.40991","0.00968","139.24100","0.00703"
"58.40000","0.97162","1395.95044","0.00972","139.59505","0.00705"
"58.60000","0.97481","1398.78699","0.00975","139.87869","0.00706"
"58.80000","0.97810","1401.84021","0.00978","140.18402","0.00708"
"59.00000","0.98140","1404.96167","0.00981","140.49617","0.00710"
"59.20000","0.98491","1408.58850","0.00985","140.85886","0.00712"
"59.40000","0.98814","1411.63062","0.00988","141.16306","0.00714"
"59.60000","0.99152","1414.83093","0.00992","141.48309","0.00715"
"59.80000","0.99483","1417.92761","0.00995","141.79276","0.00717"
"60.00000","0.99808","1420.92957","0.00998","142.09296","0.00719"
"60.20000","1.00136","1423.88135","0.01001","142.38814","0.00721"
"60.40000","1.00477","1427.35791","0.01005","142.73579","0.00722"
"60.60000","1.00828","1430.94653","0.01008","143.09465","0.00724"
"60.80000","1.01158","1433.94421","0.01012","143.39442","0.00726"
"61.00000","1.01482","1436.87036","0.01015","143.68704","0.00728"
"61.20000","1.01804","1439.82764","0.01018","143.98276","0.00729"
"61.40000","1.02135","1442.85901","0.01021","144.28590","0.00731"
"61.60000","1.02474","1446.13245","0.01025","144.61325","0.00733"
"61.80000","1.02828","1449.73682","0.01028","144.97368","0.00735"
"62.00000","1.03165","1452.83643","0.01032","145.28365","0.00737"
"62.20000","1.03485","1455.66797","0.01035","145.56680","0.00738"
"62.40000","1.03816","1458.70789","0.01038","145.87079","0.00740"
"62.60000","1.04136","1461.49084","0.01041","146.14908","0.00742"
"62.80000","1.04473","1464.75208","0.01045","146.47520","0.00744"
"63.00000","1.04809","1467.91541","0.01048","146.79153","0.00745"
"63.20000","1.05162","1471.45325","0.01052","147.14532","0.00747"
"63.40000","1.05489","1474.30139","0.01055","147.43015","0.00749"
"63.60000","1.05811","1477.02234","0.01058","147.70224","0.00751"
"63.80000","1.06142","1480.00586","0.01061","148.00058","0.00753"
"64.00000","1.06470","1482.96558","0.01065","148.29655","0.00754"
"64.20000","1.06806","1486.08679","0.01068","148.60867","0.00756"
"64.40000","1.07152","1489.31848","0.01072","148.93185","0.00758"
"64.60000","1.07495","1492.51282","0.01075","149.25128","0.00760"
"64.80000","1.07813","1495.07410","0.01078","149.50742","0.00761"
"65.00000","1.08137","1497.98181","0.01081","149.79819","0.00763"
"65.20000","1.08475","1501.20532","0.01085","150.12053","0.00765"
"65.40000","1.08814","1504.26184","0.01088","150.42618","0.00766"
"65.60000","1.09150","1507.27661","0.01092","150.72766","0.00768"
"65.80000","1.09486","1510.28101","0.01095","151.02811","0.00770"
"66.00000","1.09824","1513.40039","0.01098","151.34004","0.00772"
"66.20000","1.10138","1515.73364","0.01101","151.57336","0.00773"
"66.40000","1.10470","1518.64172","0.01105","151.86417","0.00775"
"66.60000","1.10815","1521.89856","0.01108","152.18985","0.00777"
"66.80000","1.11158","1525.12170","0.01112","152.51218","0.00779"
"67.00000","1.11487","1527.85510","0.01115","152.78551","0.00780"
"67.20000","1.11817","1530.79187","0.01118","153.07919","0.00782"
"67.40000","1.12141","1533.31299","0.01121","153.33130","0.00784"
"67.60000","1.12467","1535.98315","0.01125","153.59831","0.00785"
"67.80000","1.12805","1539.04138","0.01128","153.90414","0.00787"
"68.00000","1.13161","1542.45984","0.01132","154.24599","0.00789"
"68.20000","1.13500","1545.36841","0.01135","154.53683","0.00791"
"68.40000","1.13817","1548.02795","0.01138","154.80280","0.00792"
"68.60000","1.14144","1550.79919","0.01141","155.07993","0.00794"
"68.80000","1.14468","1553.28015","0.01145","155.32802","0.00796"
"69.00000","1.14800","1556.24377","0.01148","155.62437","0.00797"
"69.20000","1.15149","1559.47339","0.01151","155.94734","0.00799"
"69.40000","1.15501","1562.49133","0.01155","156.24913","0.00801"
"69.60000","1.15835","1565.43640","0.01158","156.54364","0.00803"
"69.80000","1.16142","1567.77832","0.01161","156.77783","0.00804"
"70.00000","1.16478","1570.63599","0.01165","157.06360","0.00806"
"70.20000","1.16803","1573.18896","0.01168","157.31889","0.00807"
"70.40000","1.17141","1576.19031","0.01171","157.61903","0.00809"
"70.60000","1.17481","1579.24878","0.01175","157.92488","0.00811"
"70.80000","1.17826","1582.19727","0.01178","158.21973","0.00813"
"71.00000","1.18154","1585.00488","0.01182","158.50049","0.00814"
"71.20000","1.18469","1587.30945","0.01185","158.73094","0.00816"
"71.40000","1.18808","1590.16675","0.01188","159.01668","0.00818"
"71.60000","1.19147","1593.02881","0.01191","159.30289","0.00819"
"71.80000","1.19486","1595.98792","0.01195","159.59879","0.00821"
"72.00000","1.19816","1598.59753","0.01198","159.85976","0.00823"
"72.20000","1.20149","1601.37268","0.01201","160.13727","0.00824"
"72.40000","1.20475","1604.05994","0.01205","160.40599","0.00826"
"72.60000","1.20797","1606.43848","0.01208","160.64384","0.00827"
"72.80000","1.21155","1609.80115","0.01212","160.98012","0.00829"
"73.00000","1.21498","1612.66516","0.01215","161.26651","0.00831"
"73.20000","1.21828","1615.39038","0.01218","161.53903","0.00833"
"73.40000","1.22146","1617.68372","0.01221","161.76837","0.00834"
"73.60000","1.22475","1620.36731","0.01225","162.03673","0.00836"
"73.80000","1.22796","1622.65735","0.01228","162.26573","0.00837"
"74.00000","1.23139","1625.61438","0.01231","162.56143","0.00839"
"74.20000","1.23490","1628.64380","0.01235","162.86438","0.00841"
"74.40000","1.23830","1631.55908","0.01238","163.15591","0.00842"
"74.60000","1.24155","1634.05017","0.01242","163.40501","0.00844"
"74.80000","1.24475","1636.47119","0.01245","163.64713","0.00845"
"75.00000","1.24801","1638.96362","0.01248","163.89636","0.00847"
"75.20000","1.25133","1641.57874","0.01251","164.15787","0.00849"
"75.40000","1.25481","1644.58362","0.01255","164.45836","0.00851"
"75.60000","1.25827","1647.46680","0.01258","164.74667","0.00852"
"75.80000","1.26158","1650.08044","0.01262","165.00804","0.00854"
"76.00000","1.26480","1652.40503","0.01265","165.24051","0.00855"
"76.20000","1.26806","1654.95740","0.01268","165.49574","0.00857"
"76.40000","1.27143","1657.65063","0.01271","165.76506","0.00859"
"76.60000","1.27479","1660.22815","0.01275","166.02281","0.00860"
"76.80000","1.27822","1663.16980","0.01278","166.31699","0.00862"
"77.00000","1.28155","1665.65967","0.01282","166.56596","0.00864"
"77.20000","1.28483","1668.21643","0.01285","166.82164","0.00865"
"77.40000","1.28803","1670.45837","0.01288","167.04584","0.00867"
"77.60000","1.29144","1673.16943","0.01291","167.31694","0.00868"
"77.80000","1.29482","1675.78552","0.01295","167.57855","0.00870"
"78.00000","1.29819","1678.43274","0.01298","167.84328","0.00872"
"78.20000","1.30156","1680.92700","0.01302","168.09270","0.00873"
"78.40000","1.30480","1683.10718","0.01305","168.31071","0.00875"
"78.60000","1.30805","1685.26392","0.01308","168.52640","0.00876"
"78.80000","1.31134","1687.65503","0.01311","168.76550","0.00878"
"79.00000","1.31483","1689.44946","0.01315","168.94495","0.00879"
"79.20000","1.31823","1691.60071","0.01318","169.16006","0.00881"
"79.40000","1.32154","1693.84180","0.01322","169.38419","0.00882"
"79.60000","1.32489","1696.12891","0.01325","169.61288","0.00883"
"79.80000","1.32809","1697.98621","0.01328","169.79861","0.00885"
"80.00000","1.33136","1700.10815","0.01331","170.01082","0.00886"
"80.20000","1.33471","1702.54041","0.01335","170.25404","0.00888"
"80.40000","1.33832","1705.41309","0.01338","170.54131","0.00889"
"80.60000","1.34161","1707.46448","0.01342","170.74644","0.00891"
"80.80000","1.34486","1709.60803","0.01345","170.96080","0.00892"
"81.00000","1.34810","1711.60498","0.01348","171.16049","0.00893"
"81.20000","1.35138","1713.76782","0.01351","171.37679","0.00895"
"81.40000","1.35466","1715.96338","0.01355","171.59634","0.00896"
"81.60000","1.35811","1718.37598","0.01358","171.83760","0.00898"
"81.80000","1.36165","1721.13196","0.01362","172.11319","0.00899"
"82.00000","1.36493","1723.33716","0.01365","172.33371","0.00901"
"82.20000","1.36808","1725.06384","0.01368","172.50638","0.00902"
"82.40000","1.37140","1727.23938","0.01371","172.72394","0.00904"
"82.60000","1.37471","1729.22949","0.01375","172.92294","0.00905"
"82.80000","1.37808","1731.62427","0.01378","173.16243","0.00907"
"83.00000","1.38150","1733.91772","0.01382","173.39177","0.00908"
"83.20000","1.38496","1736.43713","0.01385","173.64371","0.00910"
"83.40000","1.38817","1738.18970","0.01388","173.81897","0.00911"
"83.60000","1.39137","1740.01831","0.01391","174.00183","0.00913"
"83.80000","1.39481","1742.56335","0.01395","174.25633","0.00914"
"84.00000","1.39815","1744.84790","0.01398","174.48479","0.00916"
"84.20000","1.40150","1747.06165","0.01402","174.70616","0.00917"
"84.40000","1.40486","1749.43579","0.01405","174.94357","0.00919"
"84.60000","1.40813","1751.38525","0.01408","175.13852","0.00920"
"84.80000","1.41141","1753.45471","0.01411","175.34547","0.00921"
"85.00000","1.41467","1755.36047","0.01415","175.53604","0.00923"
"85.20000","1.41820","1757.58801","0.01418","175.75880","0.00924"
"85.40000","1.42166","1759.40698","0.01422","175.94070","0.00925"
"85.60000","1.42488","1760.99463","0.01425","176.09946","0.00927"
"85.80000","1.42813","1762.82166","0.01428","176.28217","0.00928"
"86.00000","1.43140","1764.77771","0.01431","176.47777","0.00930"
"86.20000","1.43465","1766.66418","0.01435","176.66641","0.00931"
"86.40000","1.43805","1768.80774","0.01438","176.88077","0.00932"
"86.60000","1.44160","1771.22229","0.01442","177.12222","0.00934"
"86.80000","1.44504","1773.46521","0.01445","177.34653","0.00935"
"87.00000","1.44818","1774.96973","0.01448","177.49698","0.00936"
"87.20000","1.45143","1775.70825","0.01451","177.57083","0.00937"
"87.40000","1.45473","1777.46997","0.01455","177.74699","0.00938"
"87.60000","1.45802","1779.23157","0.01458","177.92316","0.00940"
"87.80000","1.46147","1780.82715","0.01461","178.08272","0.00941"
"88.00000","1.46496","1782.81445","0.01465","178.28145","0.00942"
"88.09700","1.46638","1508.78796","0.01466","150.87880","0.00973"
"88.10300","1.46651","1232.70032","0.01467","123.27003","0.00949"
"88.10700","1.46661","1037.55823","0.01467","103.75582","0.00876"